File: DataDrivenSE/datosramanc/CN-Sastre_21.txt
#Acq. time (s)=	20
#Accumulations=	2
#Range (cm-¹)=	50...4000
#Windows=	3
#Autofocus=	Off
#AutoExposure=	Off
#Spike filter=	Multiple accum.
#Delay time (s)=	0
#Binning=	1
#Readout mode=	Signal
#DeNoise=	Off
#ICS correction=	Off
#Dark correction=	Off
#Inst. Process=	Off
#Instrument=	LabRAM HR Evol
#Detector=	Syncerity OE
#Objective=	x100_VIS
#Grating=	600 (500nm)
#ND Filter=	100%
#Laser=	532nm_Edge
#Hole=	100.021
#Range=	Visible
#Project=	Omar
#Sample=
#Site=	21-09-22
#Title=	 CN-Sastre
#Remark=
#Date=	21.09.2022 14:41
#Acquired=	21.09.2022 14:41:46
51.0918	42
54.7807	50
58.4681	86
62.154	184
65.8385	264
69.5216	422
73.2032	718
76.8834	938
80.5621	1224
84.2393	1392
87.9152	1516
91.5874	1580
95.2603	1500
98.9318	1490
102.602	1456
106.27	1582
109.936	1542
113.601	1594
117.266	1546
120.926	1544
124.588	1528
128.246	1486
131.904	1518
135.561	1506
139.215	1546
142.869	1468
146.52	1520
150.171	1506
153.819	1478
157.465	1434
161.112	1432
164.756	1422
168.398	1420
172.041	1420
175.68	1398
179.318	1418
182.955	1448
186.592	1404
190.225	1372
193.857	1342
197.488	1360
201.118	1390
204.746	1416
208.372	1360
211.997	1332
215.621	1348
219.243	1340
222.864	1310
226.483	1326
230.101	1306
233.718	1304
237.331	1282
240.945	1290
244.557	1288
248.168	1338
251.776	1314
255.384	1288
258.991	1366
262.594	1358
266.198	1310
269.799	1262
273.4	1278
277	1320
280.596	1308
284.193	1296
287.786	1308
291.378	1276
294.971	1290
298.561	1300
302.148	1266
305.737	1328
309.322	1340
312.906	1340
316.49	1292
320.071	1340
323.651	1340
327.229	1360
330.806	1348
334.381	1302
337.955	1328
341.528	1330
345.099	1312
348.669	1348
352.238	1352
355.805	1336
359.371	1342
362.935	1344
366.498	1360
370.06	1334
373.62	1352
377.177	1372
380.734	1386
384.29	1392
387.845	1386
391.396	1350
394.948	1352
398.499	1346
402.046	1368
405.594	1382
409.138	1362
412.683	1374
416.225	1334
419.768	1356
423.307	1390
426.844	1352
430.382	1374
433.917	1380
437.451	1362
440.985	1324
444.516	1372
448.045	1352
451.574	1382
455.102	1380
458.628	1358
462.152	1384
465.674	1376
469.196	1406
472.716	1356
476.234	1360
479.752	1362
483.268	1284
486.782	1382
490.295	1310
493.807	1326
497.316	1304
500.825	1308
504.333	1308
507.839	1288
511.344	1292
514.846	1268
518.349	1322
521.85	1382
525.347	1370
528.846	1478
532.341	1470
535.837	1510
539.329	1660
542.822	1702
546.312	1740
549.802	1834
553.289	1780
556.775	1792
560.261	1806
563.744	1806
567.226	1760
570.709	1740
574.188	1718
577.665	1692
581.142	1652
584.617	1572
588.091	1592
591.565	1526
595.036	1494
598.506	1508
601.974	1456
605.442	1400
608.905	1354
612.37	1350
615.833	1330
619.295	1342
622.755	1326
626.215	1260
629.67	1226
633.127	1192
636.582	1206
640.036	1198
643.487	1172
646.938	1136
650.386	1098
653.835	1100
657.282	1084
660.726	1050
664.171	1058
667.613	984
671.053	934
674.494	942
677.931	948
681.369	884
684.804	884
688.238	854
691.67	864
695.103	830
698.533	806
701.961	780
705.389	776
708.814	750
712.239	736
715.662	732
719.084	748
722.505	692
725.924	726
729.342	676
732.759	680
736.174	690
739.589	706
742.999	684
746.411	726
749.821	702
753.23	728
756.636	728
760.043	728
763.448	716
766.85	768
770.252	752
773.652	720
777.052	758
780.448	758
783.846	772
787.24	730
790.635	748
794.027	728
797.417	710
800.808	714
804.196	692
807.582	694
810.968	648
814.354	676
817.736	664
821.118	634
824.498	612
827.877	606
831.254	588
834.631	590
838.006	594
841.38	550
844.752	570
848.123	540
851.493	576
854.86	546
858.228	558
861.594	514
864.959	516
868.321	518
871.683	532
875.044	550
878.402	582
881.761	526
885.116	532
888.472	558
891.825	556
895.179	544
898.529	582
901.88	600
905.228	596
908.575	596
911.922	598
915.266	606
918.609	640
921.951	660
925.293	684
928.633	692
931.97	714
935.307	742
938.642	750
941.977	780
945.31	776
948.641	778
951.972	780
955.301	794
958.629	782
961.955	784
965.279	740
968.603	748
971.926	772
975.248	800
978.566	838
981.886	782
985.204	852
988.519	836
991.834	878
995.147	888
998.46	894
1001.77	906
1005.08	900
1008.39	878
1011.7	946
1015	930
1018.3	940
1021.61	1034
1024.91	990
1028.21	1048
1031.51	1046
1034.81	1046
1038.1	1098
1041.4	1190
1044.69	1158
1047.99	1208
1051.28	1250
1054.57	1282
1057.86	1316
1061.14	1366
1064.43	1404
1067.72	1440
1071	1492
1074.28	1590
1077.57	1566
1080.84	1636
1084.12	1656
1087.4	1664
1090.68	1682
1093.95	1704
1097.22	1688
1100.5	1684
1103.77	1610
1107.04	1592
1110.31	1570
1113.58	1462
1116.84	1434
1120.1	1404
1123.37	1320
1126.63	1250
1129.89	1232
1133.15	1188
1136.41	1132
1139.67	1106
1142.92	1038
1146.18	1068
1149.43	980
1152.68	958
1155.93	954
1159.18	912
1162.43	896
1165.68	858
1168.93	824
1172.17	782
1175.41	782
1178.66	744
1181.9	756
1185.14	696
1188.37	696
1191.61	670
1194.85	644
1198.08	650
1201.31	616
1204.55	596
1207.78	604
1211.01	590
1214.24	574
1217.46	572
1220.69	526
1223.91	598
1227.14	536
1230.36	540
1233.58	518
1236.8	540
1240.02	534
1243.23	518
1246.45	544
1249.67	512
1252.88	514
1256.09	512
1259.3	550
1262.51	538
1265.72	532
1268.93	508
1272.13	550
1275.34	558
1278.54	542
1281.74	556
1284.94	532
1288.15	559
1291.34	556
1294.54	566
1297.74	590
1300.93	582
1304.12	598
1307.32	618
1310.51	638
1313.7	632
1316.89	694
1320.07	712
1323.26	700
1326.45	690
1329.63	780
1332.81	768
1335.99	750
1339.17	806
1342.35	792
1345.53	802
1348.71	764
1351.88	816
1355.06	770
1358.23	798
1361.4	768
1364.57	682
1367.74	708
1370.91	672
1374.08	640
1377.24	672
1380.41	618
1383.57	646
1386.73	582
1389.89	588
1393.05	600
1396.21	606
1399.37	562
1402.52	608
1405.68	586
1408.83	566
1411.98	554
1415.13	538
1418.29	570
1421.43	544
1424.58	574
1427.73	530
1430.87	554
1434.02	542
1437.16	548
1440.3	548
1443.44	508
1446.58	522
1449.72	524
1452.85	536
1455.99	550
1459.12	554
1462.26	556
1465.39	536
1468.52	538
1471.65	530
1474.78	520
1477.9	536
1481.03	560
1484.16	532
1487.28	564
1490.4	550
1493.52	568
1496.64	548
1499.76	554
1502.88	566
1506	532
1509.11	554
1512.22	582
1515.34	556
1518.45	594
1521.56	560
1524.67	588
1527.78	590
1530.88	566
1533.99	592
1537.09	626
1540.2	646
1543.3	656
1546.4	650
1549.5	676
1552.6	646
1555.7	664
1558.79	682
1561.89	692
1564.98	734
1568.08	724
1571.17	726
1574.26	772
1577.35	764
1580.43	772
1583.52	788
1586.61	758
1589.69	758
1592.77	740
1595.86	722
1598.94	718
1602.02	726
1605.1	660
1608.18	668.341
1611.25	633.608
1614.33	653.07
1617.4	653.925
1620.47	593.713
1623.55	610.109
1626.62	570.479
1629.69	592.738
1632.75	550.259
1635.82	560.921
1638.89	539.731
1641.95	536.379
1645.02	531.457
1648.08	518.205
1651.14	532.165
1654.2	520.17
1657.26	512.091
1660.32	524.634
1663.37	501.569
1666.43	510.944
1669.48	498.321
1672.54	495.354
1675.59	489.515
1678.64	490.585
1681.69	493.681
1684.74	486.822
1687.79	491.524
1690.83	499.446
1693.88	489.969
1696.92	494.673
1699.96	473.706
1703.01	478.112
1706.05	480.464
1709.09	486.363
1712.12	496.855
1715.16	473.185
1718.2	490.283
1721.23	470.495
1724.27	476.04
1727.3	487.337
1730.33	470.079
1733.36	474.196
1736.39	463.325
1739.42	450.044
1742.44	449.93
1745.47	459.87
1748.49	473.418
1751.52	455.452
1754.54	486.654
1757.56	438.991
1759.14	458
1762.18	456
1765.21	470
1768.24	462
1771.27	448
1774.3	436
1777.32	456
1780.35	466
1783.38	444
1786.4	470
1789.42	464
1792.44	476
1795.47	470
1798.48	452
1801.5	478
1804.52	480
1807.54	472
1810.55	464
1813.57	458
1816.58	470
1819.59	440
1822.6	438
1825.61	474
1828.62	468
1831.63	468
1834.63	472
1837.64	476
1840.64	484
1843.64	448
1846.64	472
1849.64	450
1852.64	464
1855.64	500
1858.64	466
1861.64	450
1864.63	456
1867.63	472
1870.62	472
1873.61	458
1876.6	472
1879.59	480
1882.58	466
1885.56	468
1888.55	474
1891.54	472
1894.52	480
1897.5	470
1900.48	458
1903.46	456
1906.44	488
1909.42	466
1912.4	486
1915.38	452
1918.35	488
1921.32	484
1924.3	482
1927.27	476
1930.24	502
1933.21	452
1936.18	466
1939.15	494
1942.11	488
1945.08	478
1948.04	490
1951	486
1953.97	462
1956.93	462
1959.89	496
1962.85	474
1965.8	474
1968.76	488
1971.71	460
1974.67	480
1977.62	488
1980.57	458
1983.53	488
1986.48	462
1989.42	456
1992.37	480
1995.32	464
1998.26	452
2001.21	478
2004.15	468
2007.09	436
2010.03	480
2012.98	454
2015.92	474
2018.85	456
2021.79	506
2024.73	476
2027.66	484
2030.59	470
2033.53	474
2036.46	464
2039.39	482
2042.32	486
2045.25	488
2048.17	468
2051.1	470
2054.02	502
2056.95	490
2059.87	470
2062.79	490
2065.71	462
2068.63	482
2071.55	490
2074.47	470
2077.39	510
2080.3	490
2083.22	482
2086.13	492
2089.04	508
2091.95	474
2094.86	488
2097.77	492
2100.68	492
2103.59	488
2106.49	486
2109.4	484
2112.3	494
2115.21	478
2118.11	504
2121.01	478
2123.91	500
2126.8	496
2129.7	500
2132.6	498
2135.49	492
2138.39	484
2141.28	508
2144.17	484
2147.06	506
2149.95	492
2152.84	510
2155.73	484
2158.62	496
2161.5	492
2164.39	514
2167.27	510
2170.15	502
2173.04	496
2175.92	494
2178.79	504
2181.67	476
2184.55	506
2187.43	464
2190.3	496
2193.18	524
2196.05	486
2198.92	488
2201.79	470
2204.66	502
2207.53	488
2210.4	484
2213.27	484
2216.13	482
2219	482
2221.86	492
2224.72	500
2227.59	468
2230.45	464
2233.31	498
2236.16	484
2239.02	496
2241.88	488
2244.73	474
2247.59	470
2250.44	490
2253.29	508
2256.15	484
2259	418
2261.84	494
2264.69	506
2267.54	460
2270.39	488
2273.23	462
2276.07	476
2278.92	484
2281.76	468
2284.6	484
2287.44	504
2290.28	488
2293.12	502
2295.95	520
2298.79	502
2301.62	482
2304.46	516
2307.29	510
2310.12	522
2312.95	520
2315.78	510
2318.61	532
2321.44	522
2324.27	530
2327.09	542
2329.92	548
2332.74	524
2335.56	530
2338.38	540
2341.2	554
2344.02	542
2346.84	536
2349.66	560
2352.48	554
2355.29	552
2358.11	546
2360.92	568
2363.73	542
2366.54	578
2369.35	582
2372.16	604
2374.97	608
2377.78	548
2380.58	598
2383.39	606
2386.19	620
2389	606
2391.8	598
2394.6	600
2397.4	594
2400.2	630
2403	584
2405.79	640
2408.59	614
2411.38	654
2414.18	616
2416.97	644
2419.76	612
2422.55	612
2425.34	630
2428.13	610
2430.92	644
2433.71	630
2436.49	642
2439.28	652
2442.06	636
2444.85	630
2447.63	640
2450.41	646
2453.19	612
2455.97	634
2458.75	646
2461.52	596
2464.3	636
2467.07	634
2469.85	630
2472.62	632
2475.39	642
2478.16	646
2480.94	652
2483.7	640
2486.47	642
2489.24	656
2492	640
2494.77	654
2497.53	618
2500.3	604
2503.06	608
2505.82	600
2508.58	636
2511.34	658
2514.1	652
2516.85	636
2519.61	638
2522.37	634
2525.12	632
2527.87	634
2530.63	630
2533.38	612
2536.13	620
2538.88	674
2541.62	630
2544.37	622
2547.12	644
2549.86	624
2552.61	632
2555.35	638
2558.09	610
2560.84	650
2563.57	634
2566.32	634
2569.05	634
2571.79	624
2574.53	640
2577.26	632
2580	654
2582.73	660
2585.46	658
2588.19	636
2590.93	646
2593.66	646
2596.39	648
2599.11	662
2601.84	652
2604.56	644
2607.29	672
2610.01	646
2612.74	636
2615.46	676
2618.18	664
2620.9	650
2623.62	672
2626.34	654
2629.05	670
2631.77	676
2634.48	684
2637.2	672
2639.91	698
2642.62	664
2645.33	680
2648.05	674
2650.75	674
2653.46	658
2656.17	692
2658.88	682
2661.58	686
2664.29	630
2666.99	702
2669.69	690
2672.39	704
2675.09	724
2677.79	704
2680.49	736
2683.19	690
2685.89	704
2688.58	714
2691.28	688
2693.97	722
2696.67	702
2699.36	706
2702.05	698
2704.74	738
2707.43	696
2710.12	718
2712.8	748
2715.49	680
2718.17	718
2720.86	710
2723.54	672
2726.22	700
2728.91	672
2731.59	724
2734.27	704
2736.95	712
2739.62	702
2742.3	756
2744.98	684
2747.65	694
2750.33	726
2753	710
2755.67	716
2758.34	692
2761.01	718
2763.68	724
2766.35	750
2769.02	686
2771.68	722
2774.35	698
2777.01	724
2779.68	750
2782.34	728
2785	690
2787.66	738
2790.32	726
2792.98	740
2795.64	710
2798.3	702
2800.95	750
2803.61	714
2806.26	718
2808.91	742
2811.57	740
2814.22	754
2816.87	746
2819.52	716
2822.17	756
2824.81	724
2827.46	758
2830.11	726
2832.75	774
2835.39	738
2838.04	784
2840.68	770
2843.32	776
2845.96	790
2848.6	760
2851.24	776
2853.88	734
2856.51	792
2859.15	792
2861.78	782
2864.42	764
2867.05	778
2869.68	800
2872.31	784
2874.94	800
2877.57	748
2880.2	804
2882.82	806
2885.45	814
2888.08	786
2890.7	780
2893.33	802
2895.95	794
2898.57	762
2901.19	786
2903.81	786
2906.43	794
2909.05	818
2911.66	812
2914.28	836
2916.89	832
2919.51	818.056
2922.12	830.216
2924.73	828.34
2927.35	865.203
2929.96	833.129
2932.57	838.429
2935.17	801.844
2937.78	791.429
2940.39	840.026
2943	837.737
2945.6	834.014
2948.2	839.478
2950.81	821.519
2953.41	834.762
2956.01	831.68
2958.61	840.507
2961.21	838.823
2963.81	858.613
2966.41	852.535
2969.01	891.141
2971.6	879.264
2974.2	852.864
2976.79	854.013
2979.39	859.891
2981.98	869.895
2984.57	870.205
2987.16	876.541
2989.75	869.281
2992.34	878.033
2994.93	872.204
2997.51	879.4
3000.1	890.592
3002.68	883.631
3005.27	889.861
3007.85	884.938
3010.43	901.178
3013.01	886.25
3015.59	884.548
3018.18	896.472
3020.75	887.698
3023.33	886.791
3025.91	902.043
3028.48	917.869
3031.06	902.525
3033.64	923.239
3036.21	916.291
3038.78	927.435
3041.35	928.455
3043.92	930.647
3046.49	937.579
3048.11	912
3050.69	956
3053.27	922
3055.85	976
3058.43	952
3061.01	918
3063.58	956
3066.16	950
3068.73	964
3071.31	946
3073.88	936
3076.45	974
3079.02	942
3081.59	958
3084.16	962
3086.73	976
3089.29	994
3091.86	974
3094.43	1008
3096.99	976
3099.55	922
3102.12	986
3104.68	1014
3107.24	972
3109.8	982
3112.36	1016
3114.92	984
3117.48	1044
3120.03	976
3122.59	1006
3125.14	1000
3127.7	1030
3130.25	1020
3132.8	1008
3135.35	1034
3137.9	1058
3140.45	1046
3143	1038
3145.55	1056
3148.1	1060
3150.64	1076
3153.19	1088
3155.73	1070
3158.28	1066
3160.82	1086
3163.36	1062
3165.9	1076
3168.44	1070
3170.98	1082
3173.52	1098
3176.06	1066
3178.59	1128
3181.13	1070
3183.66	1082
3186.2	1102
3188.73	1094
3191.26	1132
3193.79	1112
3196.32	1086
3198.85	1142
3201.38	1122
3203.91	1116
3206.44	1110
3208.96	1102
3211.49	1128
3214.01	1106
3216.54	1128
3219.06	1120
3221.58	1140
3224.1	1118
3226.62	1106
3229.14	1154
3231.66	1104
3234.18	1110
3236.69	1174
3239.21	1158
3241.72	1172
3244.24	1146
3246.75	1164
3249.26	1160
3251.78	1148
3254.29	1138
3256.8	1186
3259.3	1178
3261.81	1186
3264.32	1186
3266.83	1158
3269.33	1172
3271.84	1192
3274.34	1190
3276.84	1198
3279.35	1178
3281.85	1242
3284.35	1192
3286.85	1232
3289.35	1224
3291.84	1244
3294.34	1228
3296.84	1250
3299.33	1254
3301.83	1244
3304.32	1238
3306.81	1264
3309.3	1236
3311.79	1278
3314.29	1272
3316.77	1288
3319.26	1284
3321.75	1316
3324.24	1288
3326.72	1328
3329.21	1264
3331.69	1280
3334.18	1288
3336.66	1302
3339.14	1330
3341.62	1318
3344.1	1320
3346.58	1318
3349.06	1296
3351.54	1308
3354.01	1322
3356.49	1350
3358.96	1344
3361.44	1296
3363.91	1346
3366.38	1322
3368.85	1350
3371.33	1360
3373.8	1310
3376.26	1302
3378.73	1340
3381.2	1338
3383.67	1320
3386.13	1328
3388.6	1372
3391.06	1324
3393.52	1314
3395.99	1386
3398.45	1360
3400.91	1330
3403.37	1354
3405.83	1404
3408.29	1380
3410.74	1340
3413.2	1350
3415.66	1410
3418.11	1380
3420.56	1386
3423.02	1410
3425.47	1378
3427.92	1404
3430.37	1424
3432.82	1418
3435.27	1442
3437.72	1450
3440.17	1440
3442.61	1450
3445.06	1458
3447.51	1460
3449.95	1458
3452.39	1464
3454.83	1500
3457.28	1478
3459.72	1488
3462.16	1470
3464.6	1504
3467.04	1504
3469.47	1526
3471.91	1522
3474.34	1492
3476.78	1486
3479.21	1538
3481.65	1466
3484.08	1502
3486.51	1534
3488.94	1532
3491.37	1492
3493.8	1544
3496.23	1508
3498.66	1530
3501.09	1524
3503.51	1506
3505.94	1496
3508.36	1530
3510.79	1528
3513.21	1496
3515.63	1522
3518.05	1498
3520.47	1538
3522.89	1538
3525.31	1558
3527.73	1552
3530.14	1528
3532.56	1506
3534.98	1510
3537.39	1538
3539.81	1548
3542.22	1562
3544.63	1532
3547.04	1540
3549.45	1586
3551.86	1586
3554.27	1570
3556.68	1550
3559.09	1590
3561.49	1578
3563.9	1566
3566.3	1584
3568.71	1574
3571.11	1614
3573.51	1642
3575.92	1586
3578.32	1596
3580.72	1640
3583.12	1674
3585.51	1612
3587.91	1640
3590.31	1600
3592.71	1632
3595.1	1652
3597.49	1670
3599.89	1660
3602.28	1678
3604.67	1684
3607.06	1670
3609.45	1704
3611.84	1738
3614.23	1680
3616.62	1704
3619.01	1678
3621.39	1696
3623.78	1696
3626.17	1740
3628.55	1710
3630.93	1718
3633.31	1694
3635.7	1716
3638.08	1688
3640.46	1686
3642.84	1704
3645.22	1750
3647.59	1706
3649.97	1732
3652.35	1728
3654.72	1734
3657.1	1742
3659.47	1710
3661.84	1756
3664.21	1736
3666.59	1756
3668.96	1732
3671.33	1740
3673.69	1742
3676.06	1728
3678.43	1772
3680.8	1740
3683.16	1738
3685.53	1752
3687.89	1742
3690.25	1758
3692.62	1748
3694.98	1742
3697.34	1770
3699.7	1746
3702.06	1724
3704.42	1784
3706.78	1786
3709.13	1800
3711.49	1820
3713.85	1798
3716.2	1768
3718.56	1814
3720.91	1796
3723.26	1834
3725.61	1788
3727.96	1824
3730.31	1880
3732.66	1842
3735.01	1838
3737.36	1888
3739.7	1828
3742.05	1864
3744.4	1846
3746.74	1874
3749.09	1874
3751.43	1876
3753.77	1884
3756.11	1894
3758.45	1894
3760.79	1900
3763.13	1930
3765.47	1910
3767.81	1898
3770.14	1944
3772.48	1926
3774.82	1996
3777.15	1932
3779.48	1918
3781.82	1968
3784.15	1954
3786.48	1924
3788.81	1932
3791.14	1882
3793.47	1954
3795.8	1890
3798.13	1986
3800.45	1908
3802.78	1890
3805.1	1916
3807.43	1954
3809.75	1938
3812.07	1964
3814.4	1916
3816.72	1944
3819.04	1960
3821.36	1958
3823.68	1986
3826	1932
3828.31	1914
3830.63	1948
3832.95	1926
3835.26	1892
3837.58	1930
3839.89	1928
3842.2	1958
3844.51	1958
3846.83	1942
3849.14	1938
3851.45	1976
3853.76	1974
3856.06	1946
3858.37	1954
3860.68	1998
3862.98	2000
3865.29	2016
3867.59	1978
3869.9	2036
3872.2	2030
3874.5	2000
3876.8	2036
3879.1	2038
3881.4	2044
3883.7	2026
3886	2072
3888.3	2038
3890.6	2042
3892.89	2014
3895.19	2012
3897.48	2084
3899.78	2100
3902.07	2080
3904.36	2096
3906.65	2088
3908.94	2066
3911.23	2040
3913.52	2128
3915.81	2104
3918.1	2124
3920.39	2114
3922.67	2144
3924.96	2090
3927.24	2182
3929.53	2152
3931.81	2130
3934.09	2130
3936.38	2144
3938.66	2108
3940.94	2188
3943.22	2128
3945.5	2126
3947.77	2138
3950.05	2140
3952.33	2190
3954.6	2130
3956.88	2164
3959.15	2160
3961.43	2136
3963.7	2142
3965.97	2068
3968.24	2106
3970.51	2108
3972.78	2150
3975.05	2184
3977.32	2158
3979.59	2156
3981.85	2184
3984.12	2144
3986.39	2166
3988.65	2216
3990.91	2120
3993.18	2106
3995.44	2124
3997.7	2120
3999.96	2196