File: DataDrivenSE/datosramanc/CN-Sastre_23.txt
#Acq. time (s)=	20
#Accumulations=	2
#Range (cm-¹)=	50...4000
#Windows=	3
#Autofocus=	Off
#AutoExposure=	Off
#Spike filter=	Multiple accum.
#Delay time (s)=	0
#Binning=	1
#Readout mode=	Signal
#DeNoise=	Off
#ICS correction=	Off
#Dark correction=	Off
#Inst. Process=	Off
#Instrument=	LabRAM HR Evol
#Detector=	Syncerity OE
#Objective=	x100_VIS
#Grating=	600 (500nm)
#ND Filter=	100%
#Laser=	532nm_Edge
#Hole=	100.021
#Range=	Visible
#Project=	Omar
#Sample=
#Site=	21-09-22
#Title=	 CN-Sastre
#Remark=
#Date=	21.09.2022 14:58
#Acquired=	21.09.2022 14:58:54
51.0918	40
54.7807	48
58.4681	110
62.154	224
65.8385	324
69.5216	538
73.2032	890
76.8834	1152
80.5621	1472
84.2393	1662
87.9152	1888
91.5874	1874
95.2603	1838
98.9318	1866
102.602	1906
106.27	2020
109.936	1962
113.601	2066
117.266	1984
120.926	1952
124.588	1936
128.246	1874
131.904	1890
135.561	1912
139.215	1934
142.869	1874
146.52	1900
150.171	1880
153.819	1880
157.465	1822
161.112	1812
164.756	1830
168.398	1832
172.041	1766
175.68	1784
179.318	1772
182.955	1798
186.592	1738
190.225	1756
193.857	1738
197.488	1724
201.118	1710
204.746	1704
208.372	1724
211.997	1664
215.621	1682
219.243	1674
222.864	1630
226.483	1624
230.101	1638
233.718	1644
237.331	1634
240.945	1620
244.557	1632
248.168	1610
251.776	1618
255.384	1630
258.991	1638
262.594	1610
266.198	1676
269.799	1650
273.4	1654
277	1636
280.596	1638
284.193	1602
287.786	1612
291.378	1612
294.971	1626
298.561	1644
302.148	1654
305.737	1656
309.322	1704
312.906	1608
316.49	1700
320.071	1654
323.651	1662
327.229	1644
330.806	1652
334.381	1716
337.955	1698
341.528	1712
345.099	1682
348.669	1692
352.238	1702
355.805	1672
359.371	1702
362.935	1722
366.498	1692
370.06	1692
373.62	1744
377.177	1714
380.734	1728
384.29	1768
387.845	1702
391.396	1744
394.948	1790
398.499	1748
402.046	1734
405.594	1780
409.138	1734
412.683	1728
416.225	1738
419.768	1764
423.307	1706
426.844	1758
430.382	1716
433.917	1762
437.451	1742
440.985	1744
444.516	1728
448.045	1732
451.574	1764
455.102	1778
458.628	1772
462.152	1792
465.674	1782
469.196	1758
472.716	1726
476.234	1712
479.752	1704
483.268	1680
486.782	1722
490.295	1664
493.807	1684
497.316	1676
500.825	1676
504.333	1700
507.839	1666
511.344	1684
514.846	1678
518.349	1734
521.85	1750
525.347	1746
528.846	1814
532.341	1910
535.837	2018
539.329	2096
542.822	2202
546.312	2218
549.802	2336
553.289	2352
556.775	2366
560.261	2348
563.744	2290
567.226	2286
570.709	2228
574.188	2188
577.665	2142
581.142	2114
584.617	2020
588.091	2038
591.565	1972
595.036	1888
598.506	1862
601.974	1828
605.442	1780
608.905	1752
612.37	1762
615.833	1684
619.295	1666
622.755	1610
626.215	1592
629.67	1588
633.127	1570
636.582	1522
640.036	1508
643.487	1462
646.938	1444
650.386	1392
653.835	1354
657.282	1320
660.726	1326
664.171	1256
667.613	1238
671.053	1212
674.494	1142
677.931	1126
681.369	1112
684.804	1086
688.238	1088
691.67	1026
695.103	1046
698.533	976
701.961	940
705.389	966
708.814	928
712.239	884
715.662	924
719.084	886
722.505	880
725.924	882
729.342	870
732.759	868
736.174	832
739.589	864
742.999	834
746.411	882
749.821	914
753.23	850
756.636	882
760.043	928
763.448	898
766.85	908
770.252	918
773.652	914
777.052	906
780.448	928
783.846	880
787.24	906
790.635	892
794.027	876
797.417	882
800.808	878
804.196	896
807.582	838
810.968	826
814.354	826
817.736	754
821.118	808
824.498	756
827.877	760
831.254	714
834.631	710
838.006	654
841.38	678
844.752	634
848.123	644
851.493	642
854.86	620
858.228	658
861.594	670
864.959	650
868.321	678
871.683	642
875.044	668
878.402	662
881.761	666
885.116	666
888.472	642
891.825	672
895.179	654
898.529	680
901.88	692
905.228	716
908.575	720
911.922	742
915.266	782
918.609	754
921.951	796
925.293	824
928.633	812
931.97	850
935.307	936
938.642	924
941.977	948
945.31	958
948.641	944
951.972	944
955.301	996
958.629	982
961.955	982
965.279	920
968.603	936
971.926	946
975.248	990
978.566	982
981.886	1022
985.204	994
988.519	1072
991.834	1062
995.147	1014
998.46	1098
1001.77	1110
1005.08	1060
1008.39	1096
1011.7	1104
1015	1158
1018.3	1184
1021.61	1202
1024.91	1226
1028.21	1256
1031.51	1302
1034.81	1326
1038.1	1368
1041.4	1444
1044.69	1450
1047.99	1488
1051.28	1538
1054.57	1540
1057.86	1588
1061.14	1712
1064.43	1732
1067.72	1784
1071	1832
1074.28	1882
1077.57	1904
1080.84	1986
1084.12	2028
1087.4	2052
1090.68	2048
1093.95	2094
1097.22	2042
1100.5	2048
1103.77	2010
1107.04	1966
1110.31	1886
1113.58	1850
1116.84	1776
1120.1	1686
1123.37	1632
1126.63	1530
1129.89	1462
1133.15	1430
1136.41	1352
1139.67	1320
1142.92	1256
1146.18	1222
1149.43	1186
1152.68	1134
1155.93	1110
1159.18	1062
1162.43	1024
1165.68	1010
1168.93	1016
1172.17	956
1175.41	902
1178.66	878
1181.9	864
1185.14	844
1188.37	786
1191.61	776
1194.85	754
1198.08	730
1201.31	734
1204.55	696
1207.78	704
1211.01	676
1214.24	678
1217.46	624
1220.69	646
1223.91	654
1227.14	634
1230.36	606
1233.58	584
1236.8	596
1240.02	570
1243.23	586
1246.45	582
1249.67	554
1252.88	580
1256.09	556
1259.3	574
1262.51	552
1265.72	578
1268.93	592
1272.13	556
1275.34	558
1278.54	568
1281.74	596
1284.94	584
1288.15	600
1291.34	580
1294.54	594
1297.74	590
1300.93	596
1304.12	602
1307.32	582
1310.51	616
1313.7	618
1316.89	606
1320.07	576
1323.26	586
1326.45	600
1329.63	586
1332.81	638
1335.99	612
1339.17	588
1342.35	618
1345.53	606
1348.71	608
1351.88	606
1355.06	598
1358.23	596
1361.4	612
1364.57	614
1367.74	572
1370.91	594
1374.08	604
1377.24	596
1380.41	586
1383.57	584
1386.73	570
1389.89	566
1393.05	562
1396.21	562
1399.37	582
1402.52	582
1405.68	568
1408.83	564
1411.98	574
1415.13	606
1418.29	592
1421.43	594
1424.58	580
1427.73	548
1430.87	574
1434.02	570
1437.16	596
1440.3	568
1443.44	560
1446.58	602
1449.72	612
1452.85	580
1455.99	604
1459.12	568
1462.26	574
1465.39	582
1468.52	584
1471.65	578
1474.78	586
1477.9	610
1481.03	578
1484.16	628
1487.28	592
1490.4	626
1493.52	576
1496.64	558
1499.76	600
1502.88	586
1506	586
1509.11	602
1512.22	600
1515.34	572
1518.45	610
1521.56	604
1524.67	628
1527.78	598
1530.88	604
1533.99	638
1537.09	576
1540.2	602
1543.3	600
1546.4	604
1549.5	608
1552.6	594
1555.7	626
1558.79	608
1561.89	616
1564.98	608
1568.08	606
1571.17	576
1574.26	624
1577.35	630
1580.43	596
1583.52	610
1586.61	616
1589.69	600
1592.77	624
1595.86	584
1598.94	602
1602.02	592
1605.1	622
1608.18	632.016
1611.25	595.016
1614.33	570.938
1617.4	597.729
1620.47	632.691
1623.55	596.261
1626.62	586.213
1629.69	583.206
1632.75	581.872
1635.82	588.951
1638.89	589.362
1641.95	544.289
1645.02	570.804
1648.08	567.955
1651.14	571.414
1654.2	553.121
1657.26	576.118
1660.32	574.127
1663.37	567.776
1666.43	555.626
1669.48	562.906
1672.54	553.996
1675.59	589.996
1678.64	544.841
1681.69	553.095
1684.74	555.804
1687.79	569.754
1690.83	559.156
1693.88	554.073
1696.92	558.227
1699.96	546.041
1703.01	549.377
1706.05	551.317
1709.09	547.245
1712.12	549.89
1715.16	525.346
1718.2	554.62
1721.23	562.403
1724.27	544.634
1727.3	538.183
1730.33	517.609
1733.36	533.588
1736.39	537.988
1739.42	560.371
1742.44	521.839
1745.47	537.935
1748.49	511.899
1751.52	510.52
1754.54	513.746
1757.56	495.841
1759.14	482
1762.18	532
1765.21	488
1768.24	526
1771.27	522
1774.3	546
1777.32	528
1780.35	528
1783.38	512
1786.4	534
1789.42	516
1792.44	534
1795.47	516
1798.48	514
1801.5	522
1804.52	512
1807.54	536
1810.55	522
1813.57	506
1816.58	518
1819.59	524
1822.6	530
1825.61	540
1828.62	538
1831.63	526
1834.63	512
1837.64	528
1840.64	540
1843.64	512
1846.64	516
1849.64	514
1852.64	486
1855.64	532
1858.64	498
1861.64	520
1864.63	526
1867.63	532
1870.62	530
1873.61	500
1876.6	544
1879.59	526
1882.58	516
1885.56	502
1888.55	550
1891.54	522
1894.52	518
1897.5	558
1900.48	530
1903.46	534
1906.44	552
1909.42	548
1912.4	540
1915.38	566
1918.35	532
1921.32	528
1924.3	530
1927.27	532
1930.24	532
1933.21	540
1936.18	540
1939.15	510
1942.11	542
1945.08	548
1948.04	546
1951	532
1953.97	526
1956.93	510
1959.89	520
1962.85	552
1965.8	510
1968.76	538
1971.71	520
1974.67	528
1977.62	518
1980.57	512
1983.53	540
1986.48	514
1989.42	570
1992.37	542
1995.32	536
1998.26	540
2001.21	528
2004.15	528
2007.09	510
2010.03	520
2012.98	536
2015.92	566
2018.85	564
2021.79	554
2024.73	554
2027.66	554
2030.59	538
2033.53	544
2036.46	580
2039.39	542
2042.32	526
2045.25	508
2048.17	570
2051.1	548
2054.02	562
2056.95	548
2059.87	540
2062.79	554
2065.71	552
2068.63	552
2071.55	548
2074.47	566
2077.39	550
2080.3	536
2083.22	566
2086.13	540
2089.04	542
2091.95	550
2094.86	548
2097.77	536
2100.68	568
2103.59	570
2106.49	532
2109.4	552
2112.3	536
2115.21	542
2118.11	558
2121.01	554
2123.91	564
2126.8	536
2129.7	556
2132.6	538
2135.49	572
2138.39	528
2141.28	550
2144.17	542
2147.06	530
2149.95	542
2152.84	544
2155.73	544
2158.62	546
2161.5	556
2164.39	558
2167.27	574
2170.15	532
2173.04	554
2175.92	556
2178.79	566
2181.67	534
2184.55	550
2187.43	554
2190.3	570
2193.18	532
2196.05	564
2198.92	562
2201.79	554
2204.66	568
2207.53	560
2210.4	554
2213.27	550
2216.13	548
2219	570
2221.86	538
2224.72	578
2227.59	524
2230.45	528
2233.31	540
2236.16	538
2239.02	540
2241.88	542
2244.73	546
2247.59	538
2250.44	542
2253.29	570
2256.15	542
2259	554
2261.84	528
2264.69	512
2267.54	546
2270.39	540
2273.23	546
2276.07	536
2278.92	538
2281.76	532
2284.6	544
2287.44	538
2290.28	550
2293.12	586
2295.95	590
2298.79	584
2301.62	572
2304.46	584
2307.29	592
2310.12	610
2312.95	592
2315.78	554
2318.61	572
2321.44	590
2324.27	574
2327.09	618
2329.92	616
2332.74	600
2335.56	584
2338.38	590
2341.2	596
2344.02	618
2346.84	616
2349.66	614
2352.48	628
2355.29	628
2358.11	622
2360.92	638
2363.73	670
2366.54	654
2369.35	634
2372.16	664
2374.97	648
2377.78	658
2380.58	678
2383.39	682
2386.19	676
2389	694
2391.8	668
2394.6	692
2397.4	686
2400.2	700
2403	682
2405.79	674
2408.59	702
2411.38	682
2414.18	692
2416.97	690
2419.76	728
2422.55	718
2425.34	684
2428.13	724
2430.92	728
2433.71	730
2436.49	728
2439.28	696
2442.06	710
2444.85	708
2447.63	708
2450.41	722
2453.19	722
2455.97	674
2458.75	728
2461.52	706
2464.3	716
2467.07	744
2469.85	716
2472.62	686
2475.39	700
2478.16	714
2480.94	712
2483.7	698
2486.47	698
2489.24	710
2492	718
2494.77	720
2497.53	720
2500.3	688
2503.06	698
2505.82	688
2508.58	704
2511.34	702
2514.1	700
2516.85	712
2519.61	708
2522.37	696
2525.12	686
2527.87	738
2530.63	706
2533.38	724
2536.13	696
2538.88	674
2541.62	714
2544.37	722
2547.12	750
2549.86	754
2552.61	718
2555.35	746
2558.09	698
2560.84	702
2563.57	720
2566.32	714
2569.05	710
2571.79	728
2574.53	692
2577.26	716
2580	714
2582.73	702
2585.46	726
2588.19	704
2590.93	760
2593.66	732
2596.39	710
2599.11	666
2601.84	734
2604.56	740
2607.29	716
2610.01	720
2612.74	748
2615.46	738
2618.18	720
2620.9	752
2623.62	738
2626.34	732
2629.05	752
2631.77	752
2634.48	740
2637.2	776
2639.91	730
2642.62	766
2645.33	762
2648.05	756
2650.75	768
2653.46	754
2656.17	762
2658.88	758
2661.58	790
2664.29	746
2666.99	764
2669.69	770
2672.39	764
2675.09	740
2677.79	760
2680.49	780
2683.19	732
2685.89	736
2688.58	754
2691.28	756
2693.97	736
2696.67	758
2699.36	742
2702.05	786
2704.74	770
2707.43	750
2710.12	760
2712.8	794
2715.49	786
2718.17	744
2720.86	778
2723.54	782
2726.22	782
2728.91	774
2731.59	772
2734.27	788
2736.95	780
2739.62	778
2742.3	776
2744.98	798
2747.65	792
2750.33	776
2753	788
2755.67	794
2758.34	818
2761.01	788
2763.68	804
2766.35	846
2769.02	810
2771.68	804
2774.35	810
2777.01	826
2779.68	832
2782.34	848
2785	838
2787.66	772
2790.32	804
2792.98	846
2795.64	828
2798.3	810
2800.95	818
2803.61	820
2806.26	836
2808.91	850
2811.57	846
2814.22	832
2816.87	838
2819.52	868
2822.17	836
2824.81	862
2827.46	874
2830.11	870
2832.75	864
2835.39	878
2838.04	858
2840.68	866
2843.32	898
2845.96	890
2848.6	862
2851.24	886
2853.88	876
2856.51	884
2859.15	834
2861.78	904
2864.42	904
2867.05	882
2869.68	906
2872.31	864
2874.94	898
2877.57	940
2880.2	874
2882.82	924
2885.45	936
2888.08	910
2890.7	910
2893.33	914
2895.95	944
2898.57	914
2901.19	928
2903.81	932
2906.43	894
2909.05	916
2911.66	950
2914.28	928
2916.89	926
2919.51	951.836
2922.12	942.293
2924.73	951.391
2927.35	953.259
2929.96	951.217
2932.57	947.841
2935.17	927.546
2937.78	971.504
2940.39	938.906
2943	963.457
2945.6	959.916
2948.2	968.182
2950.81	973.746
2953.41	985.023
2956.01	957.622
2958.61	974.501
2961.21	979.941
2963.81	967.44
2966.41	976.581
2969.01	1004.33
2971.6	982.588
2974.2	1005.32
2976.79	1002.15
2979.39	1010.93
2981.98	989.735
2984.57	1031.95
2987.16	1003.79
2989.75	1020.83
2992.34	1018.9
2994.93	1031.57
2997.51	1006.28
3000.1	1023.89
3002.68	1012.98
3005.27	1049.4
3007.85	1035.14
3010.43	1041.51
3013.01	1058.32
3015.59	1052.57
3018.18	1044.94
3020.75	1024.29
3023.33	1080.36
3025.91	1064.36
3028.48	1050.7
3031.06	1085.08
3033.64	1062.33
3036.21	1072.79
3038.78	1069.74
3041.35	1103.82
3043.92	1079.73
3046.49	1072.37
3048.11	1104
3050.69	1090
3053.27	1156
3055.85	1088
3058.43	1118
3061.01	1096
3063.58	1140
3066.16	1118
3068.73	1134
3071.31	1124
3073.88	1132
3076.45	1116
3079.02	1142
3081.59	1152
3084.16	1138
3086.73	1138
3089.29	1156
3091.86	1170
3094.43	1088
3096.99	1172
3099.55	1166
3102.12	1160
3104.68	1188
3107.24	1152
3109.8	1162
3112.36	1182
3114.92	1184
3117.48	1134
3120.03	1172
3122.59	1172
3125.14	1204
3127.7	1198
3130.25	1240
3132.8	1244
3135.35	1262
3137.9	1276
3140.45	1212
3143	1264
3145.55	1256
3148.1	1258
3150.64	1222
3153.19	1230
3155.73	1270
3158.28	1252
3160.82	1280
3163.36	1296
3165.9	1278
3168.44	1272
3170.98	1258
3173.52	1262
3176.06	1334
3178.59	1266
3181.13	1274
3183.66	1308
3186.2	1330
3188.73	1310
3191.26	1326
3193.79	1302
3196.32	1326
3198.85	1332
3201.38	1350
3203.91	1306
3206.44	1352
3208.96	1342
3211.49	1330
3214.01	1288
3216.54	1324
3219.06	1350
3221.58	1348
3224.1	1362
3226.62	1370
3229.14	1360
3231.66	1380
3234.18	1348
3236.69	1354
3239.21	1350
3241.72	1410
3244.24	1404
3246.75	1360
3249.26	1352
3251.78	1382
3254.29	1408
3256.8	1382
3259.3	1386
3261.81	1414
3264.32	1422
3266.83	1412
3269.33	1432
3271.84	1428
3274.34	1426
3276.84	1462
3279.35	1464
3281.85	1428
3284.35	1494
3286.85	1440
3289.35	1448
3291.84	1466
3294.34	1474
3296.84	1484
3299.33	1478
3301.83	1500
3304.32	1558
3306.81	1522
3309.3	1478
3311.79	1536
3314.29	1546
3316.77	1540
3319.26	1570
3321.75	1562
3324.24	1478
3326.72	1548
3329.21	1598
3331.69	1526
3334.18	1540
3336.66	1554
3339.14	1542
3341.62	1584
3344.1	1548
3346.58	1566
3349.06	1582
3351.54	1612
3354.01	1566
3356.49	1580
3358.96	1596
3361.44	1576
3363.91	1586
3366.38	1548
3368.85	1568
3371.33	1612
3373.8	1626
3376.26	1606
3378.73	1656
3381.2	1582
3383.67	1612
3386.13	1672
3388.6	1590
3391.06	1648
3393.52	1650
3395.99	1628
3398.45	1654
3400.91	1660
3403.37	1692
3405.83	1652
3408.29	1666
3410.74	1646
3413.2	1696
3415.66	1638
3418.11	1738
3420.56	1728
3423.02	1720
3425.47	1740
3427.92	1740
3430.37	1748
3432.82	1746
3435.27	1756
3437.72	1764
3440.17	1754
3442.61	1754
3445.06	1788
3447.51	1776
3449.95	1770
3452.39	1816
3454.83	1790
3457.28	1778
3459.72	1812
3462.16	1800
3464.6	1834
3467.04	1770
3469.47	1782
3471.91	1850
3474.34	1844
3476.78	1800
3479.21	1810
3481.65	1860
3484.08	1850
3486.51	1838
3488.94	1880
3491.37	1832
3493.8	1852
3496.23	1830
3498.66	1834
3501.09	1892
3503.51	1860
3505.94	1872
3508.36	1880
3510.79	1888
3513.21	1842
3515.63	1860
3518.05	1878
3520.47	1882
3522.89	1876
3525.31	1880
3527.73	1842
3530.14	1876
3532.56	1884
3534.98	1868
3537.39	1910
3539.81	1892
3542.22	1918
3544.63	1882
3547.04	1910
3549.45	1900
3551.86	1926
3554.27	1896
3556.68	1916
3559.09	1962
3561.49	1940
3563.9	1962
3566.3	1996
3568.71	1946
3571.11	1984
3573.51	1980
3575.92	1990
3578.32	2008
3580.72	1980
3583.12	2004
3585.51	2022
3587.91	2018
3590.31	2056
3592.71	2048
3595.1	2022
3597.49	1994
3599.89	2076
3602.28	2090
3604.67	2082
3607.06	2086
3609.45	2098
3611.84	2094
3614.23	2058
3616.62	2142
3619.01	2110
3621.39	2102
3623.78	2124
3626.17	2160
3628.55	2128
3630.93	2112
3633.31	2112
3635.7	2152
3638.08	2146
3640.46	2154
3642.84	2172
3645.22	2146
3647.59	2126
3649.97	2196
3652.35	2146
3654.72	2150
3657.1	2182
3659.47	2150
3661.84	2158
3664.21	2116
3666.59	2154
3668.96	2128
3671.33	2150
3673.69	2176
3676.06	2194
3678.43	2168
3680.8	2184
3683.16	2128
3685.53	2146
3687.89	2184
3690.25	2196
3692.62	2166
3694.98	2186
3697.34	2210
3699.7	2204
3702.06	2174
3704.42	2256
3706.78	2228
3709.13	2230
3711.49	2218
3713.85	2238
3716.2	2216
3718.56	2286
3720.91	2314
3723.26	2282
3725.61	2274
3727.96	2260
3730.31	2242
3732.66	2338
3735.01	2258
3737.36	2316
3739.7	2346
3742.05	2396
3744.4	2352
3746.74	2324
3749.09	2334
3751.43	2318
3753.77	2406
3756.11	2348
3758.45	2380
3760.79	2376
3763.13	2386
3765.47	2376
3767.81	2382
3770.14	2380
3772.48	2382
3774.82	2414
3777.15	2450
3779.48	2436
3781.82	2404
3784.15	2432
3786.48	2434
3788.81	2454
3791.14	2408
3793.47	2460
3795.8	2410
3798.13	2422
3800.45	2434
3802.78	2462
3805.1	2388
3807.43	2424
3809.75	2480
3812.07	2438
3814.4	2446
3816.72	2386
3819.04	2462
3821.36	2452
3823.68	2436
3826	2418
3828.31	2490
3830.63	2452
3832.95	2466
3835.26	2434
3837.58	2486
3839.89	2486
3842.2	2460
3844.51	2462
3846.83	2468
3849.14	2494
3851.45	2500
3853.76	2470
3856.06	2498
3858.37	2480
3860.68	2526
3862.98	2516
3865.29	2486
3867.59	2544
3869.9	2530
3872.2	2546
3874.5	2564
3876.8	2552
3879.1	2550
3881.4	2586
3883.7	2598
3886	2620
3888.3	2610
3890.6	2656
3892.89	2636
3895.19	2634
3897.48	2634
3899.78	2636
3902.07	2654
3904.36	2652
3906.65	2664
3908.94	2622
3911.23	2660
3913.52	2720
3915.81	2700
3918.1	2654
3920.39	2704
3922.67	2690
3924.96	2678
3927.24	2670
3929.53	2716
3931.81	2722
3934.09	2744
3936.38	2708
3938.66	2776
3940.94	2758
3943.22	2714
3945.5	2700
3947.77	2770
3950.05	2714
3952.33	2684
3954.6	2744
3956.88	2738
3959.15	2682
3961.43	2704
3963.7	2702
3965.97	2736
3968.24	2752
3970.51	2740
3972.78	2736
3975.05	2736
3977.32	2738
3979.59	2736
3981.85	2724
3984.12	2810
3986.39	2774
3988.65	2782
3990.91	2748
3993.18	2794
3995.44	2768
3997.7	2796
3999.96	2806