File: DataDrivenSE/datosramanc/CN-Sastre_25 copy.txt
#Acq. time (s)=	20
#Accumulations=	2
#Range (cm-¹)=	50...4000
#Windows=	3
#Autofocus=	Off
#AutoExposure=	Off
#Spike filter=	Multiple accum.
#Delay time (s)=	0
#Binning=	1
#Readout mode=	Signal
#DeNoise=	Off
#ICS correction=	Off
#Dark correction=	Off
#Inst. Process=	Off
#Instrument=	LabRAM HR Evol
#Detector=	Syncerity OE
#Objective=	x100_VIS
#Grating=	600 (500nm)
#ND Filter=	100%
#Laser=	532nm_Edge
#Hole=	100.021
#Range=	Visible
#Project=	Omar
#Sample=
#Site=	21-09-22
#Title=	 CN-Sastre
#Remark=
#Date=	21.09.2022 15:10
#Acquired=	21.09.2022 15:10:23
51.0918	40
54.7807	52
58.4681	110
62.154	206
65.8385	330
69.5216	504
73.2032	742
76.8834	842
80.5621	1062
84.2393	1212
87.9152	1256
91.5874	1284
95.2603	1284
98.9318	1316
102.602	1336
106.27	1388
109.936	1320
113.601	1326
117.266	1342
120.926	1316
124.588	1266
128.246	1270
131.904	1242
135.561	1270
139.215	1258
142.869	1248
146.52	1244
150.171	1312
153.819	1250
157.465	1270
161.112	1228
164.756	1230
168.398	1226
172.041	1208
175.68	1212
179.318	1178
182.955	1242
186.592	1218
190.225	1218
193.857	1224
197.488	1222
201.118	1182
204.746	1214
208.372	1174
211.997	1216
215.621	1230
219.243	1196
222.864	1168
226.483	1178
230.101	1180
233.718	1194
237.331	1156
240.945	1200
244.557	1164
248.168	1156
251.776	1220
255.384	1174
258.991	1178
262.594	1194
266.198	1200
269.799	1220
273.4	1164
277	1162
280.596	1150
284.193	1172
287.786	1210
291.378	1192
294.971	1190
298.561	1164
302.148	1214
305.737	1158
309.322	1180
312.906	1146
316.49	1194
320.071	1180
323.651	1164
327.229	1178
330.806	1180
334.381	1164
337.955	1168
341.528	1154
345.099	1190
348.669	1148
352.238	1148
355.805	1156
359.371	1164
362.935	1152
366.498	1204
370.06	1152
373.62	1188
377.177	1174
380.734	1210
384.29	1174
387.845	1184
391.396	1164
394.948	1186
398.499	1214
402.046	1200
405.594	1158
409.138	1228
412.683	1208
416.225	1174
419.768	1184
423.307	1224
426.844	1218
430.382	1210
433.917	1210
437.451	1216
440.985	1192
444.516	1214
448.045	1222
451.574	1232
455.102	1240
458.628	1248
462.152	1230
465.674	1226
469.196	1220
472.716	1210
476.234	1208
479.752	1252
483.268	1260
486.782	1206
490.295	1208
493.807	1260
497.316	1224
500.825	1256
504.333	1186
507.839	1202
511.344	1208
514.846	1234
518.349	1242
521.85	1252
525.347	1280
528.846	1260
532.341	1288
535.837	1312
539.329	1290
542.822	1322
546.312	1390
549.802	1410
553.289	1346
556.775	1398
560.261	1396
563.744	1436
567.226	1388
570.709	1366
574.188	1368
577.665	1384
581.142	1358
584.617	1338
588.091	1358
591.565	1314
595.036	1322
598.506	1286
601.974	1298
605.442	1234
608.905	1270
612.37	1286
615.833	1290
619.295	1286
622.755	1300
626.215	1324
629.67	1268
633.127	1262
636.582	1286
640.036	1260
643.487	1208
646.938	1260
650.386	1254
653.835	1264
657.282	1276
660.726	1252
664.171	1254
667.613	1272
671.053	1272
674.494	1250
677.931	1264
681.369	1226
684.804	1300
688.238	1234
691.67	1192
695.103	1236
698.533	1210
701.961	1218
705.389	1224
708.814	1186
712.239	1196
715.662	1196
719.084	1212
722.505	1202
725.924	1206
729.342	1214
732.759	1186
736.174	1200
739.589	1206
742.999	1202
746.411	1210
749.821	1202
753.23	1214
756.636	1200
760.043	1212
763.448	1216
766.85	1174
770.252	1240
773.652	1230
777.052	1266
780.448	1240
783.846	1228
787.24	1204
790.635	1226
794.027	1246
797.417	1226
800.808	1252
804.196	1222
807.582	1234
810.968	1192
814.354	1254
817.736	1198
821.118	1236
824.498	1204
827.877	1186
831.254	1212
834.631	1256
838.006	1244
841.38	1246
844.752	1244
848.123	1230
851.493	1218
854.86	1218
858.228	1218
861.594	1252
864.959	1200
868.321	1244
871.683	1212
875.044	1212
878.402	1214
881.761	1234
885.116	1246
888.472	1204
891.825	1202
895.179	1214
898.529	1182
901.88	1236
905.228	1226
908.575	1246
911.922	1262
915.266	1228
918.609	1216
921.951	1218
925.293	1286
928.633	1246
931.97	1300
935.307	1264
938.642	1254
941.977	1300
945.31	1298
948.641	1320
951.972	1302
955.301	1294
958.629	1322
961.955	1298
965.279	1298
968.603	1308
971.926	1332
975.248	1344
978.566	1336
981.886	1326
985.204	1310
988.519	1338
991.834	1326
995.147	1374
998.46	1340
1001.77	1376
1005.08	1312
1008.39	1336
1011.7	1338
1015	1346
1018.3	1376
1021.61	1390
1024.91	1410
1028.21	1400
1031.51	1442
1034.81	1438
1038.1	1480
1041.4	1482
1044.69	1492
1047.99	1468
1051.28	1510
1054.57	1480
1057.86	1480
1061.14	1538
1064.43	1592
1067.72	1546
1071	1628
1074.28	1562
1077.57	1578
1080.84	1596
1084.12	1598
1087.4	1640
1090.68	1660
1093.95	1642
1097.22	1624
1100.5	1640
1103.77	1674
1107.04	1678
1110.31	1638
1113.58	1588
1116.84	1606
1120.1	1612
1123.37	1590
1126.63	1608
1129.89	1604
1133.15	1546
1136.41	1564
1139.67	1526
1142.92	1578
1146.18	1570
1149.43	1596
1152.68	1568
1155.93	1574
1159.18	1570
1162.43	1562
1165.68	1548
1168.93	1548
1172.17	1552
1175.41	1600
1178.66	1588
1181.9	1596
1185.14	1634
1188.37	1596
1191.61	1580
1194.85	1620
1198.08	1598
1201.31	1598
1204.55	1612
1207.78	1624
1211.01	1636
1214.24	1648
1217.46	1658
1220.69	1648
1223.91	1604
1227.14	1642
1230.36	1638
1233.58	1632
1236.8	1652
1240.02	1654
1243.23	1740
1246.45	1716
1249.67	1724
1252.88	1802
1256.09	1810
1259.3	1796
1262.51	1798
1265.72	1818
1268.93	1816
1272.13	1858
1275.34	1892
1278.54	1892
1281.74	1968
1284.94	1964
1288.15	2035
1291.34	2106
1294.54	2144
1297.74	2186
1300.93	2218
1304.12	2308
1307.32	2330
1310.51	2352
1313.7	2538
1316.89	2600
1320.07	2688
1323.26	2720
1326.45	2890
1329.63	2986
1332.81	3088
1335.99	3214
1339.17	3232
1342.35	3292
1345.53	3324
1348.71	3282
1351.88	3224
1355.06	3140
1358.23	3152
1361.4	2992
1364.57	2880
1367.74	2802
1370.91	2694
1374.08	2622
1377.24	2574
1380.41	2462
1383.57	2328
1386.73	2336
1389.89	2246
1393.05	2210
1396.21	2140
1399.37	2148
1402.52	2062
1405.68	2056
1408.83	2050
1411.98	2066
1415.13	2026
1418.29	1986
1421.43	2002
1424.58	1952
1427.73	1978
1430.87	1964
1434.02	1958
1437.16	1950
1440.3	1970
1443.44	1938
1446.58	1918
1449.72	1902
1452.85	1908
1455.99	1880
1459.12	1944
1462.26	1866
1465.39	1912
1468.52	1962
1471.65	1906
1474.78	1924
1477.9	1904
1481.03	1892
1484.16	1898
1487.28	1896
1490.4	1938
1493.52	1954
1496.64	1932
1499.76	1924
1502.88	1930
1506	1972
1509.11	1934
1512.22	1966
1515.34	2036
1518.45	2082
1521.56	2048
1524.67	2048
1527.78	2090
1530.88	2104
1533.99	2128
1537.09	2302
1540.2	2332
1543.3	2348
1546.4	2452
1549.5	2526
1552.6	2596
1555.7	2682
1558.79	2852
1561.89	2916
1564.98	3000
1568.08	3118
1571.17	3224
1574.26	3358
1577.35	3366
1580.43	3350
1583.52	3284
1586.61	3206
1589.69	3148
1592.77	3038
1595.86	2920
1598.94	2916
1602.02	2802
1605.1	2828
1608.18	2658.72
1611.25	2504.73
1614.33	2463.04
1617.4	2318.81
1620.47	2194.09
1623.55	2128.31
1626.62	1988.47
1629.69	1896.87
1632.75	1816.56
1635.82	1677.96
1638.89	1598.36
1641.95	1557.06
1645.02	1490.37
1648.08	1477.8
1651.14	1385.7
1654.2	1317.53
1657.26	1314.27
1660.32	1323.73
1663.37	1296.03
1666.43	1177.93
1669.48	1168.56
1672.54	1119.22
1675.59	1124.14
1678.64	1096.76
1681.69	1036.71
1684.74	1011.49
1687.79	988.118
1690.83	983.881
1693.88	958.223
1696.92	891.445
1699.96	898.435
1703.01	870.411
1706.05	846.177
1709.09	832.103
1712.12	803.361
1715.16	775.873
1718.2	735.026
1721.23	716.794
1724.27	695.02
1727.3	671.462
1730.33	656.305
1733.36	640.002
1736.39	628.249
1739.42	571.677
1742.44	557.3
1745.47	535.303
1748.49	535.75
1751.52	485.157
1754.54	450.014
1757.56	424.02
1759.14	436
1762.18	402
1765.21	420
1768.24	422
1771.27	438
1774.3	412
1777.32	444
1780.35	432
1783.38	430
1786.4	422
1789.42	432
1792.44	426
1795.47	420
1798.48	452
1801.5	438
1804.52	416
1807.54	432
1810.55	432
1813.57	438
1816.58	424
1819.59	406
1822.6	462
1825.61	430
1828.62	410
1831.63	438
1834.63	442
1837.64	428
1840.64	424
1843.64	426
1846.64	430
1849.64	440
1852.64	446
1855.64	430
1858.64	436
1861.64	428
1864.63	450
1867.63	452
1870.62	430
1873.61	446
1876.6	430
1879.59	466
1882.58	434
1885.56	442
1888.55	444
1891.54	446
1894.52	428
1897.5	444
1900.48	422
1903.46	438
1906.44	412
1909.42	438
1912.4	446
1915.38	424
1918.35	428
1921.32	470
1924.3	426
1927.27	434
1930.24	444
1933.21	450
1936.18	448
1939.15	444
1942.11	446
1945.08	458
1948.04	440
1951	452
1953.97	452
1956.93	454
1959.89	440
1962.85	440
1965.8	408
1968.76	438
1971.71	438
1974.67	448
1977.62	428
1980.57	422
1983.53	464
1986.48	454
1989.42	432
1992.37	434
1995.32	466
1998.26	438
2001.21	424
2004.15	430
2007.09	430
2010.03	430
2012.98	454
2015.92	444
2018.85	432
2021.79	456
2024.73	432
2027.66	442
2030.59	460
2033.53	442
2036.46	430
2039.39	460
2042.32	460
2045.25	438
2048.17	460
2051.1	438
2054.02	456
2056.95	434
2059.87	426
2062.79	448
2065.71	444
2068.63	442
2071.55	446
2074.47	420
2077.39	448
2080.3	462
2083.22	472
2086.13	434
2089.04	446
2091.95	440
2094.86	420
2097.77	440
2100.68	434
2103.59	426
2106.49	444
2109.4	444
2112.3	432
2115.21	454
2118.11	434
2121.01	448
2123.91	454
2126.8	458
2129.7	440
2132.6	458
2135.49	476
2138.39	464
2141.28	450
2144.17	452
2147.06	460
2149.95	462
2152.84	450
2155.73	440
2158.62	456
2161.5	470
2164.39	448
2167.27	448
2170.15	430
2173.04	456
2175.92	434
2178.79	482
2181.67	460
2184.55	452
2187.43	472
2190.3	450
2193.18	462
2196.05	456
2198.92	470
2201.79	436
2204.66	478
2207.53	446
2210.4	432
2213.27	448
2216.13	456
2219	426
2221.86	422
2224.72	466
2227.59	444
2230.45	466
2233.31	412
2236.16	430
2239.02	438
2241.88	440
2244.73	410
2247.59	448
2250.44	426
2253.29	428
2256.15	442
2259	450
2261.84	430
2264.69	446
2267.54	450
2270.39	450
2273.23	458
2276.07	442
2278.92	434
2281.76	456
2284.6	438
2287.44	454
2290.28	452
2293.12	454
2295.95	442
2298.79	454
2301.62	444
2304.46	464
2307.29	466
2310.12	444
2312.95	458
2315.78	426
2318.61	440
2321.44	444
2324.27	448
2327.09	512
2329.92	482
2332.74	480
2335.56	478
2338.38	468
2341.2	480
2344.02	480
2346.84	472
2349.66	470
2352.48	460
2355.29	478
2358.11	478
2360.92	502
2363.73	498
2366.54	486
2369.35	482
2372.16	474
2374.97	482
2377.78	502
2380.58	494
2383.39	510
2386.19	516
2389	484
2391.8	484
2394.6	526
2397.4	514
2400.2	486
2403	500
2405.79	478
2408.59	516
2411.38	516
2414.18	502
2416.97	518
2419.76	508
2422.55	512
2425.34	518
2428.13	530
2430.92	526
2433.71	540
2436.49	536
2439.28	506
2442.06	522
2444.85	510
2447.63	510
2450.41	516
2453.19	534
2455.97	522
2458.75	570
2461.52	544
2464.3	548
2467.07	532
2469.85	534
2472.62	548
2475.39	524
2478.16	562
2480.94	564
2483.7	500
2486.47	538
2489.24	558
2492	534
2494.77	548
2497.53	558
2500.3	534
2503.06	534
2505.82	548
2508.58	552
2511.34	524
2514.1	532
2516.85	554
2519.61	520
2522.37	562
2525.12	530
2527.87	534
2530.63	554
2533.38	534
2536.13	570
2538.88	540
2541.62	546
2544.37	550
2547.12	534
2549.86	584
2552.61	550
2555.35	542
2558.09	536
2560.84	566
2563.57	568
2566.32	576
2569.05	578
2571.79	578
2574.53	572
2577.26	568
2580	548
2582.73	580
2585.46	552
2588.19	588
2590.93	582
2593.66	584
2596.39	594
2599.11	572
2601.84	626
2604.56	596
2607.29	628
2610.01	600
2612.74	596
2615.46	626
2618.18	598
2620.9	640
2623.62	628
2626.34	628
2629.05	642
2631.77	666
2634.48	636
2637.2	646
2639.91	688
2642.62	656
2645.33	684
2648.05	670
2650.75	720
2653.46	738
2656.17	678
2658.88	692
2661.58	776
2664.29	740
2666.99	766
2669.69	758
2672.39	762
2675.09	802
2677.79	842
2680.49	812
2683.19	786
2685.89	812
2688.58	838
2691.28	854
2693.97	842
2696.67	810
2699.36	886
2702.05	852
2704.74	822
2707.43	846
2710.12	828
2712.8	844
2715.49	800
2718.17	800
2720.86	794
2723.54	772
2726.22	742
2728.91	764
2731.59	748
2734.27	754
2736.95	720
2739.62	738
2742.3	690
2744.98	704
2747.65	686
2750.33	690
2753	684
2755.67	670
2758.34	658
2761.01	660
2763.68	668
2766.35	646
2769.02	666
2771.68	636
2774.35	684
2777.01	652
2779.68	666
2782.34	632
2785	672
2787.66	662
2790.32	658
2792.98	668
2795.64	664
2798.3	656
2800.95	668
2803.61	690
2806.26	678
2808.91	660
2811.57	680
2814.22	672
2816.87	686
2819.52	658
2822.17	690
2824.81	682
2827.46	652
2830.11	652
2832.75	678
2835.39	668
2838.04	696
2840.68	684
2843.32	650
2845.96	662
2848.6	650
2851.24	664
2853.88	652
2856.51	684
2859.15	654
2861.78	670
2864.42	662
2867.05	686
2869.68	684
2872.31	700
2874.94	672
2877.57	666
2880.2	720
2882.82	698
2885.45	732
2888.08	726
2890.7	692
2893.33	692
2895.95	694
2898.57	696
2901.19	708
2903.81	724
2906.43	676
2909.05	716
2911.66	754
2914.28	704
2916.89	714
2919.51	705.04
2922.12	706.331
2924.73	728.692
2927.35	737.704
2929.96	753.039
2932.57	739.56
2935.17	717.289
2937.78	712.96
2940.39	741.783
2943	720.564
2945.6	717.633
2948.2	747.575
2950.81	752.218
2953.41	733.336
2956.01	760.014
2958.61	748.624
2961.21	751.783
2963.81	742.483
2966.41	748.694
2969.01	754.093
2971.6	716.832
2974.2	749.769
2976.79	755.524
2979.39	746.06
2981.98	723.705
2984.57	745.296
2987.16	743.339
2989.75	760.934
2992.34	743.172
2994.93	755.68
2997.51	754.965
3000.1	723.013
3002.68	759.76
3005.27	747.434
3007.85	749.885
3010.43	753.867
3013.01	763.186
3015.59	765.626
3018.18	765.255
3020.75	734.838
3023.33	738.969
3025.91	759.974
3028.48	743.537
3031.06	746.359
3033.64	760.328
3036.21	764.048
3038.78	760.761
3041.35	768.94
3043.92	772.713
3046.49	746.099
3048.11	764
3050.69	752
3053.27	764
3055.85	740
3058.43	774
3061.01	766
3063.58	780
3066.16	756
3068.73	738
3071.31	758
3073.88	784
3076.45	796
3079.02	772
3081.59	774
3084.16	802
3086.73	772
3089.29	784
3091.86	792
3094.43	780
3096.99	790
3099.55	770
3102.12	746
3104.68	790
3107.24	776
3109.8	802
3112.36	800
3114.92	792
3117.48	804
3120.03	818
3122.59	814
3125.14	812
3127.7	794
3130.25	804
3132.8	816
3135.35	806
3137.9	808
3140.45	824
3143	826
3145.55	826
3148.1	848
3150.64	876
3153.19	874
3155.73	836
3158.28	814
3160.82	840
3163.36	830
3165.9	816
3168.44	830
3170.98	836
3173.52	796
3176.06	844
3178.59	854
3181.13	844
3183.66	872
3186.2	860
3188.73	840
3191.26	876
3193.79	842
3196.32	862
3198.85	848
3201.38	844
3203.91	842
3206.44	880
3208.96	888
3211.49	870
3214.01	846
3216.54	842
3219.06	844
3221.58	880
3224.1	884
3226.62	860
3229.14	824
3231.66	850
3234.18	894
3236.69	860
3239.21	886
3241.72	856
3244.24	902
3246.75	898
3249.26	882
3251.78	892
3254.29	890
3256.8	882
3259.3	876
3261.81	876
3264.32	898
3266.83	882
3269.33	866
3271.84	888
3274.34	896
3276.84	858
3279.35	862
3281.85	884
3284.35	926
3286.85	878
3289.35	884
3291.84	902
3294.34	886
3296.84	882
3299.33	908
3301.83	910
3304.32	906
3306.81	900
3309.3	908
3311.79	948
3314.29	914
3316.77	910
3319.26	912
3321.75	896
3324.24	942
3326.72	930
3329.21	902
3331.69	914
3334.18	930
3336.66	920
3339.14	914
3341.62	946
3344.1	958
3346.58	928
3349.06	938
3351.54	940
3354.01	916
3356.49	920
3358.96	916
3361.44	930
3363.91	940
3366.38	890
3368.85	930
3371.33	936
3373.8	946
3376.26	954
3378.73	930
3381.2	932
3383.67	988
3386.13	970
3388.6	978
3391.06	910
3393.52	936
3395.99	960
3398.45	930
3400.91	972
3403.37	968
3405.83	982
3408.29	936
3410.74	964
3413.2	984
3415.66	930
3418.11	1010
3420.56	984
3423.02	968
3425.47	978
3427.92	996
3430.37	990
3432.82	964
3435.27	1026
3437.72	1002
3440.17	1000
3442.61	994
3445.06	1010
3447.51	1016
3449.95	982
3452.39	1000
3454.83	1034
3457.28	1022
3459.72	1040
3462.16	1018
3464.6	1050
3467.04	1054
3469.47	1034
3471.91	1022
3474.34	1022
3476.78	1032
3479.21	1066
3481.65	1000
3484.08	1042
3486.51	1024
3488.94	1038
3491.37	1010
3493.8	1032
3496.23	1030
3498.66	1048
3501.09	1044
3503.51	1066
3505.94	1054
3508.36	1056
3510.79	1058
3513.21	1016
3515.63	1030
3518.05	1006
3520.47	1042
3522.89	1032
3525.31	1064
3527.73	1058
3530.14	1038
3532.56	1032
3534.98	1082
3537.39	1046
3539.81	1052
3542.22	1036
3544.63	1076
3547.04	1046
3549.45	1032
3551.86	1046
3554.27	1046
3556.68	1056
3559.09	1044
3561.49	1092
3563.9	1110
3566.3	1036
3568.71	1100
3571.11	1050
3573.51	1092
3575.92	1092
3578.32	1092
3580.72	1116
3583.12	1098
3585.51	1108
3587.91	1130
3590.31	1106
3592.71	1124
3595.1	1114
3597.49	1088
3599.89	1114
3602.28	1126
3604.67	1124
3607.06	1124
3609.45	1154
3611.84	1124
3614.23	1150
3616.62	1170
3619.01	1126
3621.39	1118
3623.78	1138
3626.17	1154
3628.55	1158
3630.93	1172
3633.31	1132
3635.7	1124
3638.08	1150
3640.46	1162
3642.84	1136
3645.22	1128
3647.59	1102
3649.97	1204
3652.35	1130
3654.72	1164
3657.1	1162
3659.47	1160
3661.84	1168
3664.21	1162
3666.59	1136
3668.96	1146
3671.33	1132
3673.69	1074
3676.06	1150
3678.43	1152
3680.8	1168
3683.16	1144
3685.53	1202
3687.89	1158
3690.25	1100
3692.62	1180
3694.98	1188
3697.34	1166
3699.7	1162
3702.06	1172
3704.42	1156
3706.78	1174
3709.13	1114
3711.49	1152
3713.85	1180
3716.2	1188
3718.56	1156
3720.91	1184
3723.26	1160
3725.61	1206
3727.96	1206
3730.31	1238
3732.66	1214
3735.01	1202
3737.36	1220
3739.7	1226
3742.05	1222
3744.4	1222
3746.74	1190
3749.09	1226
3751.43	1226
3753.77	1256
3756.11	1246
3758.45	1246
3760.79	1232
3763.13	1260
3765.47	1236
3767.81	1234
3770.14	1262
3772.48	1260
3774.82	1228
3777.15	1232
3779.48	1256
3781.82	1268
3784.15	1246
3786.48	1294
3788.81	1266
3791.14	1270
3793.47	1206
3795.8	1256
3798.13	1232
3800.45	1268
3802.78	1268
3805.1	1212
3807.43	1280
3809.75	1258
3812.07	1242
3814.4	1242
3816.72	1274
3819.04	1266
3821.36	1308
3823.68	1272
3826	1284
3828.31	1254
3830.63	1242
3832.95	1252
3835.26	1276
3837.58	1252
3839.89	1240
3842.2	1230
3844.51	1270
3846.83	1298
3849.14	1272
3851.45	1270
3853.76	1268
3856.06	1302
3858.37	1282
3860.68	1304
3862.98	1286
3865.29	1282
3867.59	1274
3869.9	1296
3872.2	1280
3874.5	1308
3876.8	1308
3879.1	1286
3881.4	1304
3883.7	1312
3886	1336
3888.3	1296
3890.6	1328
3892.89	1352
3895.19	1350
3897.48	1330
3899.78	1270
3902.07	1356
3904.36	1346
3906.65	1340
3908.94	1362
3911.23	1338
3913.52	1368
3915.81	1326
3918.1	1380
3920.39	1332
3922.67	1346
3924.96	1362
3927.24	1372
3929.53	1356
3931.81	1386
3934.09	1334
3936.38	1410
3938.66	1376
3940.94	1388
3943.22	1334
3945.5	1398
3947.77	1344
3950.05	1394
3952.33	1356
3954.6	1328
3956.88	1358
3959.15	1400
3961.43	1370
3963.7	1376
3965.97	1386
3968.24	1368
3970.51	1352
3972.78	1366
3975.05	1346
3977.32	1384
3979.59	1396
3981.85	1388
3984.12	1346
3986.39	1384
3988.65	1334
3990.91	1388
3993.18	1382
3995.44	1384
3997.7	1378
3999.96	1394