File: ploting_and_data_tools/raman/CdSe1_09.txt
#Acq. time (s)=	1
#Accumulations=	1
#Range (eV)=	2...1
#Windows=	11
#Autofocus=	Off
#AutoExposure=	Off
#Spike filter=	Off
#Delay time (s)=	0
#Binning=	1
#Readout mode=	Signal
#DeNoise=	Off
#ICS correction=	Off
#Dark correction=	Off
#Inst. Process=	Off
#Instrument=	LabRAM HR Evol
#Detector=	Syncerity OE
#Objective=	x100_VIS_LWD
#Grating=	600 (500nm)
#ND Filter=	0.1%
#Laser=	442nm_Notch
#Hole=	100.021
#Range=	Visible
#Project=	Paty
#Sample=
#Site=	15-06-22
#Title=	CdSe1
#Remark=
#Date=	15.06.2022 20:22
#Acquired=	15.06.2022 20:22:07
2.74975	28
2.7475	20
2.74525	24
2.743	34
2.74076	34
2.73852	24
2.73629	28
2.73406	22
2.73183	28
2.72961	28
2.72739	16
2.72517	32
2.72296	30
2.72075	28
2.71854	26
2.71634	24
2.71414	24
2.71195	32
2.70976	26
2.70757	26
2.70539	24
2.70321	20
2.70103	28
2.69886	30
2.69669	18
2.69452	32
2.69236	36
2.6902	34
2.68805	30
2.6859	30
2.68375	36
2.68161	32
2.67947	32
2.67733	28
2.6752	26
2.67307	26
2.67094	28
2.66882	28
2.6667	32
2.66458	22
2.66247	30
2.66036	30
2.65826	30
2.65615	28
2.65405	28
2.65196	30
2.64987	38
2.64778	30
2.64569	32
2.64361	28
2.64153	32
2.63946	34
2.63739	34
2.63532	30
2.63325	32
2.63119	36
2.62913	32
2.62708	38
2.62503	34
2.62298	36
2.62094	30
2.61889	36
2.61686	28
2.61482	34
2.61279	34
2.61076	28
2.60873	36
2.60671	36
2.60469	46
2.60268	36
2.60067	30
2.59866	32
2.59665	40
2.59465	30
2.59265	34
2.59065	44
2.58866	36
2.58667	38
2.58468	30
2.5827	34
2.58072	32
2.57874	38
2.57677	38
2.5748	34
2.57283	42
2.57086	36
2.5689	38
2.56694	34
2.56499	38
2.56304	42
2.56109	42
2.55914	42
2.5572	38
2.55526	46
2.55332	42
2.55139	48
2.54946	46
2.54753	48
2.5456	44
2.54368	48
2.54176	50
2.53985	48
2.53794	56
2.53603	58
2.53412	54
2.53222	52
2.53031	46
2.52842	54
2.52652	54
2.52463	60
2.52274	58
2.52085	64
2.51897	60
2.51709	60
2.51521	60
2.51334	70
2.51147	60
2.5096	74
2.50773	62
2.50587	66
2.50401	68
2.50216	72
2.5003	70
2.49845	86
2.4966	76
2.49476	86
2.49291	80
2.49107	90
2.48924	88
2.4874	100
2.48557	88
2.48374	102
2.48192	96.9156
2.48009	108.539
2.47827	109.435
2.47646	120.675
2.47464	112.684
2.47283	138.46
2.47102	127.579
2.46922	139.546
2.46741	153.623
2.46561	159.614
2.46381	166.745
2.46202	175.706
2.46023	181.951
2.45844	198.434
2.45665	190.599
2.45493	196
2.45314	192
2.45136	214
2.44957	228
2.44779	218
2.44601	234
2.44424	250
2.44247	238
2.4407	250
2.43893	256
2.43716	274
2.4354	274
2.43364	274
2.43188	288
2.43013	256
2.42838	270
2.42663	288
2.42488	298
2.42314	312
2.4214	316
2.41966	322
2.41792	316
2.41619	314
2.41446	326
2.41273	340
2.411	352
2.40928	354
2.40756	348
2.40584	374
2.40413	330
2.40241	346
2.4007	366
2.39899	380
2.39729	386
2.39559	376
2.39389	380
2.39219	374
2.39049	370
2.3888	386
2.38711	390
2.38542	390
2.38374	388
2.38205	406
2.38037	406
2.37869	408
2.37702	386
2.37535	392
2.37368	398
2.37201	408
2.37034	402
2.36868	386
2.36702	404
2.36536	406
2.3637	402
2.36205	404
2.3604	402
2.35875	398
2.3571	394
2.35546	396
2.35382	380
2.35218	388
2.35054	368
2.34891	354
2.34727	368
2.34564	356
2.34402	366
2.34239	382
2.34077	386
2.33915	322
2.33753	374
2.33591	368
2.3343	342
2.33269	350
2.33108	326
2.32948	328
2.32787	336
2.32627	326
2.32467	312
2.32307	316
2.32148	308
2.31989	300
2.3183	306
2.31671	294
2.31512	294
2.31354	282
2.31196	290
2.31038	278
2.3088	280
2.30723	280
2.30565	262
2.30408	254
2.30252	274
2.30095	286
2.29939	258
2.29783	238
2.29627	250
2.29471	244
2.29316	248
2.29161	254
2.29006	230
2.28851	230
2.28696	238
2.28542	220
2.28388	216
2.28234	216
2.2808	232
2.27927	214
2.27773	184
2.2762	220
2.27468	204
2.27315	188
2.27163	200
2.27011	204
2.26859	198
2.26707	188
2.26555	188
2.26404	182
2.26253	176.548
2.26102	174.313
2.25951	185.778
2.25801	186.625
2.25651	191.642
2.25501	172.018
2.25351	169.96
2.25201	175.628
2.25052	170.42
2.24902	178.587
2.24753	178.474
2.24605	165.181
2.24456	168.321
2.24308	166.168
2.2416	189.483
2.24011	152
2.23863	162
2.23715	158
2.23567	176
2.23419	166
2.23271	152
2.23124	150
2.22977	168
2.2283	154
2.22683	162
2.22536	140
2.2239	156
2.22244	150
2.22098	134
2.21952	146
2.21807	146
2.21661	136
2.21516	132
2.21371	138
2.21226	136
2.21082	134
2.20937	126
2.20793	126
2.20649	120
2.20505	114
2.20362	128
2.20218	130
2.20075	122
2.19932	132
2.19789	130
2.19647	128
2.19504	118
2.19362	118
2.1922	110
2.19078	128
2.18936	112
2.18795	122
2.18654	120
2.18513	124
2.18372	116
2.18231	108
2.18091	120
2.1795	122
2.1781	116
2.1767	116
2.1753	118
2.17391	130
2.17251	110
2.17112	116
2.16973	108
2.16834	124
2.16696	118
2.16557	124
2.16419	108
2.16281	108
2.16143	104
2.16005	114
2.15868	112
2.1573	118
2.15593	102
2.15456	114
2.1532	116
2.15183	118
2.15046	108
2.1491	110
2.14774	108
2.14638	106
2.14503	120
2.14367	106
2.14232	108
2.14097	98
2.13962	104
2.13827	114
2.13692	124
2.13558	110
2.13423	102
2.13289	110
2.13155	116
2.13022	106
2.12888	98
2.12755	110
2.12621	106
2.12488	106
2.12356	94
2.12223	110
2.1209	102
2.11958	110
2.11826	114
2.11694	104
2.11562	102
2.1143	106
2.11299	104
2.11168	108
2.11037	98
2.10906	116
2.10775	116
2.10644	108
2.10514	114
2.10384	124
2.10253	116
2.10123	108
2.09994	108
2.09864	102
2.09735	116
2.09605	116
2.09476	112
2.09347	104
2.09219	102
2.0909	112
2.08962	100
2.08834	100
2.08705	110
2.08578	114
2.0845	122
2.08322	114
2.08195	116
2.08068	124
2.0794	111.87
2.07814	102.659
2.07687	111.152
2.0756	102.166
2.07434	110.072
2.07307	105.989
2.07181	108.143
2.07055	109.514
2.0693	110.561
2.06804	112.55
2.06679	112.607
2.06553	103.08
2.06428	101.716
2.06303	110.137
2.06178	104.945
2.06069	102
2.05944	100
2.05819	104
2.05694	114
2.05569	122
2.05445	110
2.05321	114
2.05196	110
2.05072	108
2.04949	102
2.04825	98
2.04701	100
2.04578	114
2.04455	112
2.04332	90
2.04209	108
2.04086	106
2.03964	102
2.03841	118
2.03719	96
2.03597	102
2.03475	112
2.03353	102
2.03232	122
2.0311	112
2.02989	106
2.02868	108
2.02747	112
2.02626	106
2.02505	102
2.02384	102
2.02264	108
2.02144	92
2.02024	112
2.01904	114
2.01784	108
2.01664	102
2.01544	106
2.01425	100
2.01306	108
2.01187	120
2.01068	108
2.00949	118
2.0083	102
2.00712	110
2.00594	106
2.00475	116
2.00357	112
2.0024	118
2.00122	96
2.00004	110
1.99887	104
1.99769	112
1.99652	114
1.99535	100
1.99418	108
1.99302	106
1.99185	118
1.99069	108
1.98952	120
1.98836	106
1.9872	112
1.98604	106
1.98488	130
1.98373	102
1.98257	112
1.98142	104
1.98027	132
1.97912	112
1.97797	116
1.97682	114
1.97568	114
1.97453	114
1.97339	118
1.97225	120
1.97111	114
1.96997	124
1.96883	114
1.9677	118
1.96656	116
1.96543	110
1.9643	112
1.96316	116
1.96204	104
1.96091	116
1.95978	116
1.95866	130
1.95753	120
1.95641	122
1.95529	126
1.95417	114
1.95305	112
1.95193	106
1.95082	116
1.9497	114
1.94859	120
1.94748	112
1.94637	114
1.94526	126
1.94415	118
1.94305	110
1.94194	120
1.94084	108
1.93974	116
1.93864	114
1.93754	108
1.93644	120
1.93534	120
1.93425	130
1.93315	126
1.93206	116
1.93097	114
1.92988	120
1.92879	120
1.9277	136
1.92662	104
1.92553	116
1.92445	129.92
1.92337	112.908
1.92228	121.065
1.92121	113.803
1.92013	110
1.91905	122.622
1.91797	115.429
1.9169	124.943
1.91583	121.332
1.91475	118.636
1.91368	120.101
1.91261	118.823
1.91155	121.445
1.91048	118.47
1.90946	124
1.90839	122
1.90732	114
1.90626	112
1.90519	132
1.90413	118
1.90306	116
1.902	126
1.90094	112
1.89988	126
1.89882	122
1.89777	122
1.89671	126
1.89566	124
1.8946	122
1.89355	120
1.8925	124
1.89145	116
1.8904	110
1.88936	124
1.88831	132
1.88727	124
1.88622	118
1.88518	108
1.88414	116
1.8831	120
1.88206	112
1.88102	104
1.87999	126
1.87895	110
1.87792	124
1.87689	126
1.87586	116
1.87483	118
1.8738	116
1.87277	124
1.87174	112
1.87072	112
1.86969	120
1.86867	120
1.86765	124
1.86663	120
1.86561	120
1.86459	122
1.86357	126
1.86256	112
1.86154	120
1.86053	106
1.85952	126
1.85851	106
1.8575	128
1.85649	120
1.85548	110
1.85447	106
1.85347	122
1.85247	122
1.85146	126
1.85046	108
1.84946	110
1.84846	120
1.84746	128
1.84646	110
1.84547	124
1.84447	110
1.84348	116
1.84249	124
1.8415	120
1.84051	130
1.83952	116
1.83853	120
1.83754	116
1.83656	110
1.83557	128
1.83459	126
1.83361	108
1.83262	122
1.83164	126
1.83066	120
1.82969	134
1.82871	116
1.82773	120
1.82676	116
1.82579	112
1.82481	104
1.82384	116
1.82287	114
1.8219	110
1.82094	120
1.81997	110
1.819	102
1.81804	114
1.81708	116
1.81611	114
1.81515	116
1.81419	112
1.81323	94
1.81227	116
1.81132	110
1.81036	110
1.80941	98
1.80845	102
1.8075	124
1.80655	112
1.8056	106
1.80465	96
1.8037	112
1.80275	110
1.80181	118
1.80086	112
1.79992	102
1.79897	112
1.79803	98
1.79709	110
1.79615	108
1.79521	102
1.79428	106
1.79334	110
1.7924	102
1.79147	99.9097
1.79053	95.4189
1.7896	107.782
1.78867	98.7186
1.78774	106.051
1.78681	101.245
1.78588	106.812
1.78496	103.069
1.78403	99.5877
1.7831	105.588
1.78218	101.197
1.78126	101.578
1.78033	105.934
1.77941	97.489
1.77851	114
1.77759	106
1.77667	106
1.77575	100
1.77483	112
1.77391	98
1.77299	110
1.77207	94
1.77115	100
1.77024	100
1.76932	92
1.76841	98
1.7675	96
1.76659	92
1.76568	96
1.76477	96
1.76386	96
1.76295	104
1.76204	104
1.76114	92
1.76023	98
1.75933	96
1.75843	106
1.75753	96
1.75662	92
1.75572	92
1.75483	96
1.75393	88
1.75303	82
1.75214	86
1.75124	98
1.75035	92
1.74945	100
1.74856	104
1.74767	98
1.74678	92
1.74589	98
1.74501	94
1.74412	84
1.74323	96
1.74235	92
1.74146	88
1.74058	88
1.7397	100
1.73882	92
1.73794	88
1.73706	94
1.73618	92
1.7353	96
1.73443	84
1.73355	78
1.73268	90
1.7318	96
1.73093	92
1.73006	100
1.72919	82
1.72832	84
1.72745	92
1.72658	86
1.72571	82
1.72485	80
1.72398	84
1.72312	86
1.72225	84
1.72139	86
1.72053	78
1.71967	86
1.71881	94
1.71795	70
1.71709	82
1.71624	80
1.71538	82
1.71453	84
1.71367	78
1.71282	78
1.71197	82
1.71112	88
1.71027	80
1.70942	86
1.70857	76
1.70772	74
1.70687	82
1.70603	76
1.70518	86
1.70434	72
1.7035	74
1.70265	72
1.70181	76
1.70097	82
1.70013	76
1.69929	70
1.69846	68
1.69762	76
1.69678	68
1.69595	72
1.69511	70
1.69428	70
1.69345	78
1.69262	72
1.69179	68
1.69096	72
1.69013	78
1.6893	74
1.68847	70
1.68765	64
1.68682	64
1.686	64
1.68517	60
1.68435	64
1.68353	70
1.68271	66
1.68189	66
1.68107	72
1.68025	68
1.67943	64
1.67861	72
1.6778	62
1.67698	54.0291
1.67617	60.7282
1.67536	63.9775
1.67454	60.292
1.67373	62.3623
1.67292	65.0495
1.67211	69.6505
1.6713	64.0777
1.6705	64.5153
1.66969	65.1059
1.66888	69.5601
1.66808	60.7977
1.66727	66.8872
1.66647	65.2801
1.66566	64.5031
1.6649	54
1.66409	60
1.66329	58
1.66249	68
1.66168	56
1.66088	64
1.66008	66
1.65928	70
1.65848	66
1.65768	62
1.65688	68
1.65608	54
1.65529	66
1.65449	66
1.6537	66
1.6529	58
1.65211	66
1.65132	58
1.65053	60
1.64973	62
1.64894	64
1.64816	74
1.64737	60
1.64658	66
1.64579	64
1.64501	52
1.64422	62
1.64344	52
1.64265	60
1.64187	60
1.64109	60
1.64031	66
1.63953	60
1.63875	58
1.63797	64
1.63719	54
1.63642	62
1.63564	52
1.63486	58
1.63409	48
1.63331	60
1.63254	52
1.63177	62
1.631	56
1.63023	64
1.62946	48
1.62869	58
1.62792	54
1.62715	48
1.62639	56
1.62562	48
1.62485	66
1.62409	52
1.62333	60
1.62256	56
1.6218	52
1.62104	54
1.62028	46
1.61952	46
1.61876	60
1.618	50
1.61724	50
1.61649	52
1.61573	54
1.61498	40
1.61422	48
1.61347	46
1.61271	60
1.61196	50
1.61121	44
1.61046	42
1.60971	46
1.60896	48
1.60821	48
1.60747	44
1.60672	38
1.60597	58
1.60523	54
1.60448	54
1.60374	50
1.603	48
1.60225	52
1.60151	52
1.60077	46
1.60003	40
1.59929	46
1.59855	44
1.59782	48
1.59708	54
1.59634	46
1.59561	44
1.59487	48
1.59414	48
1.5934	46
1.59267	44
1.59194	50
1.59121	48
1.59048	42
1.58975	54
1.58902	50
1.58829	38
1.58756	48
1.58684	46
1.58611	42
1.58538	44
1.58466	46
1.58394	40
1.58321	50
1.58249	46
1.58177	40
1.58105	40
1.58033	40
1.57961	42
1.57889	42
1.57817	34
1.57745	34
1.57674	42
1.57602	37.9872
1.5753	45.9264
1.57459	37.1885
1.57388	41.0999
1.57316	43.4158
1.57245	44.5579
1.57174	39.9712
1.57103	41.9464
1.57032	39.0829
1.56961	34.596
1.5689	42.7376
1.56819	32.055
1.56748	30.6296
1.56678	33.3492
1.56607	44.4529
1.56544	38
1.56473	42
1.56402	36
1.56331	40
1.56261	40
1.5619	32
1.56119	40
1.56049	46
1.55979	36
1.55908	42
1.55838	40
1.55768	36
1.55698	40
1.55628	38
1.55558	40
1.55488	34
1.55418	44
1.55348	36
1.55278	30
1.55209	42
1.55139	34
1.5507	34
1.55	44
1.54931	40
1.54862	38
1.54792	36
1.54723	28
1.54654	38
1.54585	38
1.54516	40
1.54447	36
1.54378	36
1.5431	34
1.54241	36
1.54172	42
1.54104	30
1.54035	38
1.53967	46
1.53898	36
1.5383	30
1.53762	34
1.53694	30
1.53626	46
1.53558	38
1.5349	38
1.53422	36
1.53354	26
1.53286	34
1.53218	42
1.53151	54
1.53083	46
1.53016	44
1.52948	42
1.52881	44
1.52813	32
1.52746	30
1.52679	38
1.52612	42
1.52545	40
1.52478	38
1.52411	32
1.52344	36
1.52277	38
1.5221	40
1.52144	36
1.52077	26
1.52011	30
1.51944	42
1.51878	32
1.51811	32
1.51745	38
1.51679	34
1.51613	34
1.51547	40
1.51481	32
1.51415	36
1.51349	34
1.51283	40
1.51217	36
1.51151	36
1.51086	44
1.5102	34
1.50954	38
1.50889	32
1.50824	40
1.50758	32
1.50693	34
1.50628	42
1.50563	36
1.50497	38
1.50432	30
1.50367	42
1.50302	34
1.50238	40
1.50173	34
1.50108	34
1.50043	24
1.49979	36
1.49914	28
1.4985	30
1.49785	26
1.49721	32
1.49657	32
1.49592	38
1.49528	36
1.49464	28
1.494	26
1.49336	30
1.49272	32
1.49208	30
1.49144	40
1.49081	36
1.49017	36
1.48953	22
1.4889	32
1.48826	34
1.48763	22
1.48699	33.9901
1.48636	33.4576
1.48573	30.3517
1.4851	31.9379
1.48446	29.2853
1.48383	26.904
1.4832	28.6337
1.48257	33.9657
1.48194	28.2784
1.48132	35.064
1.48069	28.3853
1.48006	30.1138
1.47943	35.5287
1.47881	29.0048
1.47818	29.1857
1.47756	32
1.47694	30
1.47631	26
1.47568	36
1.47505	36
1.47443	26
1.4738	28
1.47318	30
1.47256	36
1.47193	32
1.47131	32
1.47069	30
1.47006	38
1.46944	28
1.46882	36
1.4682	32
1.46758	28
1.46696	32
1.46635	26
1.46573	30
1.46511	24
1.46449	30
1.46388	38
1.46326	30
1.46265	34
1.46203	30
1.46142	34
1.46081	24
1.46019	32
1.45958	26
1.45897	26
1.45836	32
1.45775	32
1.45714	26
1.45653	32
1.45592	24
1.45531	28
1.4547	30
1.4541	26
1.45349	24
1.45288	28
1.45228	22
1.45167	26
1.45107	24
1.45047	28
1.44986	24
1.44926	30
1.44866	28
1.44806	28
1.44746	28
1.44686	28
1.44626	26
1.44566	34
1.44506	28
1.44446	32
1.44386	26
1.44326	26
1.44267	30
1.44207	24
1.44148	28
1.44088	26
1.44029	36
1.43969	26
1.4391	30
1.43851	28
1.43791	28
1.43732	26
1.43673	24
1.43614	28
1.43555	32
1.43496	26
1.43437	26
1.43378	38
1.4332	36
1.43261	32
1.43202	34
1.43143	28
1.43085	26
1.43026	24
1.42968	28
1.42909	26
1.42851	28
1.42793	24
1.42734	24
1.42676	32
1.42618	28
1.4256	24
1.42502	30
1.42444	32
1.42386	26
1.42328	32
1.4227	30
1.42212	30
1.42155	32
1.42097	34
1.42039	24
1.41982	32
1.41924	30
1.41867	32
1.41809	28
1.41752	28
1.41695	38
1.41637	32
1.4158	40
1.41523	26
1.41466	24
1.41409	26
1.41352	26
1.41295	34
1.41238	26
1.41181	26
1.41124	28
1.41067	30
1.41011	32
1.40954	26
1.40897	36
1.40841	26
1.40784	27.9884
1.40728	33.2642
1.40672	22.0017
1.40615	28.3277
1.40559	26.0869
1.40503	30.142
1.40446	32.1212
1.4039	28.6306
1.40334	25.4594
1.40278	29.9551
1.40222	31.3555
1.40166	27.6344
1.4011	28.3
1.40054	27.5542
1.39999	30.9337
1.39947	26
1.3989	30
1.39834	28
1.39779	36
1.39723	28
1.39667	36
1.39611	30
1.39555	26
1.395	28
1.39444	30
1.39388	24
1.39333	24
1.39277	22
1.39222	22
1.39166	32
1.39111	34
1.39056	28
1.39	28
1.38945	30
1.3889	26
1.38835	30
1.3878	32
1.38725	30
1.3867	36
1.38615	28
1.3856	28
1.38505	32
1.3845	32
1.38396	38
1.38341	28
1.38286	26
1.38232	32
1.38177	26
1.38123	26
1.38068	26
1.38014	32
1.3796	28
1.37905	30
1.37851	28
1.37797	28
1.37743	20
1.37688	32
1.37634	32
1.3758	22
1.37526	26
1.37472	24
1.37419	22
1.37365	32
1.37311	32
1.37257	32
1.37204	28
1.3715	32
1.37096	22
1.37043	32
1.36989	30
1.36936	28
1.36882	30
1.36829	32
1.36776	34
1.36722	28
1.36669	30
1.36616	30
1.36563	24
1.3651	38
1.36457	30
1.36404	28
1.36351	32
1.36298	28
1.36245	32
1.36192	36
1.36139	30
1.36087	24
1.36034	36
1.35981	28
1.35929	30
1.35876	32
1.35824	30
1.35771	36
1.35719	28
1.35667	32
1.35614	30
1.35562	32
1.3551	28
1.35458	28
1.35406	26
1.35353	26
1.35301	32
1.35249	38
1.35197	28
1.35146	28
1.35094	24
1.35042	28
1.3499	32
1.34938	36
1.34887	28
1.34835	32
1.34783	22
1.34732	30
1.3468	38
1.34629	30
1.34578	30
1.34526	30
1.34475	28
1.34424	26
1.34372	28
1.34321	28
1.3427	32
1.34219	24
1.34168	28
1.34117	34
1.34066	32
1.34015	28
1.33964	34
1.33913	26
1.33862	30
1.33812	18
1.33761	24
1.3371	28.0907
1.3366	31.1454
1.33609	27.4042
1.33558	31.1768
1.33508	24.3551
1.33457	25.1226
1.33407	27.2933
1.33357	33.925
1.33306	25.868
1.33256	27.2502
1.33206	25.0021
1.33156	29.3339
1.33105	26.742
1.33055	25.7799
1.33005	29.1102
1.32959	36
1.32909	30
1.32859	32
1.32809	24
1.32758	30
1.32708	30
1.32658	30
1.32608	26
1.32558	24
1.32508	34
1.32458	38
1.32408	30
1.32358	32
1.32309	30
1.32259	26
1.32209	32
1.3216	32
1.3211	30
1.3206	26
1.32011	28
1.31961	28
1.31912	34
1.31862	38
1.31813	26
1.31764	30
1.31714	34
1.31665	26
1.31616	28
1.31567	30
1.31518	30
1.31468	32
1.31419	28
1.3137	30
1.31321	26
1.31272	28
1.31224	42
1.31175	34
1.31126	32
1.31077	28
1.31028	30
1.3098	26
1.30931	24
1.30882	28
1.30834	28
1.30785	28
1.30737	24
1.30688	28
1.3064	22
1.30592	28
1.30543	38
1.30495	28
1.30447	34
1.30399	28
1.3035	30
1.30302	26
1.30254	34
1.30206	28
1.30158	28
1.3011	30
1.30062	28
1.30014	34
1.30001	24