File: ploting_and_data_tools/raman/CdSe1_05.txt
#Acq. time (s)=	2
#Accumulations=	1
#Range (eV)=	2...1
#Windows=	11
#Autofocus=	Off
#AutoExposure=	Off
#Spike filter=	Off
#Delay time (s)=	0
#Binning=	1
#Readout mode=	Signal
#DeNoise=	Off
#ICS correction=	Off
#Dark correction=	Off
#Inst. Process=	Off
#Instrument=	LabRAM HR Evol
#Detector=	Syncerity OE
#Objective=	x10_VIS
#Grating=	600 (500nm)
#ND Filter=	0.1%
#Laser=	442nm_Notch
#Hole=	70.0087
#Range=	Visible
#Project=	Paty
#Sample=
#Site=	15-06-22
#Title=	CdSe1
#Remark=
#Date=	15.06.2022 19:59
#Acquired=	15.06.2022 19:59:06
2.74975	26
2.7475	30
2.74525	30
2.743	22
2.74076	36
2.73852	32
2.73629	38
2.73406	40
2.73183	32
2.72961	28
2.72739	28
2.72517	36
2.72296	26
2.72075	26
2.71854	28
2.71634	28
2.71414	30
2.71195	26
2.70976	30
2.70757	32
2.70539	24
2.70321	30
2.70103	38
2.69886	30
2.69669	30
2.69452	36
2.69236	40
2.6902	36
2.68805	30
2.6859	38
2.68375	32
2.68161	40
2.67947	28
2.67733	34
2.6752	36
2.67307	34
2.67094	36
2.66882	28
2.6667	40
2.66458	34
2.66247	34
2.66036	42
2.65826	42
2.65615	30
2.65405	40
2.65196	40
2.64987	42
2.64778	48
2.64569	34
2.64361	38
2.64153	40
2.63946	46
2.63739	40
2.63532	38
2.63325	36
2.63119	36
2.62913	52
2.62708	52
2.62503	40
2.62298	48
2.62094	50
2.61889	48
2.61686	48
2.61482	38
2.61279	46
2.61076	52
2.60873	42
2.60671	46
2.60469	58
2.60268	50
2.60067	56
2.59866	58
2.59665	56
2.59465	46
2.59265	58
2.59065	56
2.58866	58
2.58667	62
2.58468	62
2.5827	62
2.58072	72
2.57874	80
2.57677	74
2.5748	68
2.57283	76
2.57086	70
2.5689	86
2.56694	82
2.56499	82
2.56304	84
2.56109	74
2.55914	92
2.5572	94
2.55526	92
2.55332	90
2.55139	104
2.54946	100
2.54753	106
2.5456	100
2.54368	104
2.54176	120
2.53985	118
2.53794	112
2.53603	132
2.53412	132
2.53222	130
2.53031	140
2.52842	120
2.52652	150
2.52463	150
2.52274	136
2.52085	156
2.51897	154
2.51709	158
2.51521	172
2.51334	176
2.51147	174
2.5096	180
2.50773	188
2.50587	186
2.50401	194
2.50216	208
2.5003	208
2.49845	198
2.4966	220
2.49476	230
2.49291	216
2.49107	240
2.48924	244
2.4874	240
2.48557	246
2.48374	264
2.48192	252.705
2.48009	275.497
2.47827	279.342
2.47646	294.881
2.47464	297.874
2.47283	298.901
2.47102	308.477
2.46922	333.156
2.46741	350.958
2.46561	341.138
2.46381	363.808
2.46202	358.451
2.46023	381.883
2.45844	378.296
2.45665	403.733
2.45493	416
2.45314	422
2.45136	418
2.44957	444
2.44779	452
2.44601	438
2.44424	470
2.44247	472
2.4407	482
2.43893	488
2.43716	494
2.4354	496
2.43364	518
2.43188	518
2.43013	520
2.42838	500
2.42663	514
2.42488	532
2.42314	542
2.4214	518
2.41966	556
2.41792	568
2.41619	568
2.41446	572
2.41273	540
2.411	554
2.40928	590
2.40756	604
2.40584	596
2.40413	594
2.40241	628
2.4007	588
2.39899	624
2.39729	624
2.39559	612
2.39389	596
2.39219	620
2.39049	608
2.3888	634
2.38711	620
2.38542	622
2.38374	610
2.38205	646
2.38037	646
2.37869	634
2.37702	640
2.37535	634
2.37368	624
2.37201	652
2.37034	628
2.36868	620
2.36702	622
2.36536	646
2.3637	624
2.36205	636
2.3604	608
2.35875	616
2.3571	608
2.35546	598
2.35382	600
2.35218	596
2.35054	570
2.34891	586
2.34727	562
2.34564	568
2.34402	560
2.34239	594
2.34077	560
2.33915	532
2.33753	536
2.33591	538
2.3343	530
2.33269	550
2.33108	498
2.32948	544
2.32787	542
2.32627	510
2.32467	496
2.32307	508
2.32148	504
2.31989	488
2.3183	508
2.31671	462
2.31512	454
2.31354	486
2.31196	452
2.31038	462
2.3088	452
2.30723	456
2.30565	446
2.30408	434
2.30252	430
2.30095	446
2.29939	448
2.29783	446
2.29627	432
2.29471	456
2.29316	438
2.29161	428
2.29006	436
2.28851	402
2.28696	434
2.28542	418
2.28388	428
2.28234	412
2.2808	408
2.27927	416
2.27773	424
2.2762	414
2.27468	398
2.27315	444
2.27163	414
2.27011	422
2.26859	390
2.26707	424
2.26555	422
2.26404	402
2.26253	407.839
2.26102	405.619
2.25951	403.453
2.25801	401.079
2.25651	386.751
2.25501	392.484
2.25351	389.87
2.25201	392.764
2.25052	405.177
2.24902	398.818
2.24753	397.691
2.24605	397.878
2.24456	391.71
2.24308	402.468
2.2416	382.547
2.24011	396
2.23863	370
2.23715	412
2.23567	394
2.23419	390
2.23271	396
2.23124	382
2.22977	370
2.2283	356
2.22683	386
2.22536	378
2.2239	386
2.22244	406
2.22098	382
2.21952	402
2.21807	374
2.21661	400
2.21516	372
2.21371	396
2.21226	400
2.21082	394
2.20937	380
2.20793	392
2.20649	380
2.20505	404
2.20362	374
2.20218	388
2.20075	364
2.19932	402
2.19789	412
2.19647	414
2.19504	418
2.19362	418
2.1922	388
2.19078	400
2.18936	418
2.18795	386
2.18654	412
2.18513	404
2.18372	398
2.18231	392
2.18091	414
2.1795	424
2.1781	428
2.1767	418
2.1753	382
2.17391	390
2.17251	394
2.17112	442
2.16973	414
2.16834	410
2.16696	434
2.16557	424
2.16419	430
2.16281	464
2.16143	432
2.16005	440
2.15868	432
2.1573	418
2.15593	448
2.15456	434
2.1532	440
2.15183	460
2.15046	468
2.1491	472
2.14774	442
2.14638	470
2.14503	450
2.14367	446
2.14232	464
2.14097	480
2.13962	460
2.13827	460
2.13692	492
2.13558	480
2.13423	454
2.13289	482
2.13155	462
2.13022	474
2.12888	482
2.12755	496
2.12621	498
2.12488	480
2.12356	462
2.12223	510
2.1209	488
2.11958	506
2.11826	522
2.11694	486
2.11562	496
2.1143	494
2.11299	494
2.11168	504
2.11037	508
2.10906	522
2.10775	508
2.10644	516
2.10514	522
2.10384	570
2.10253	532
2.10123	492
2.09994	538
2.09864	530
2.09735	540
2.09605	532
2.09476	530
2.09347	554
2.09219	562
2.0909	538
2.08962	548
2.08834	516
2.08705	554
2.08578	558
2.0845	526
2.08322	536
2.08195	524
2.08068	564
2.0794	559.097
2.07814	550.019
2.07687	534.08
2.0756	531.055
2.07434	549.16
2.07307	535.929
2.07181	549.28
2.07055	561.505
2.0693	550.123
2.06804	562.146
2.06679	546.004
2.06553	553.375
2.06428	529.423
2.06303	541.546
2.06178	566.587
2.06069	578
2.05944	538
2.05819	530
2.05694	592
2.05569	552
2.05445	566
2.05321	564
2.05196	510
2.05072	556
2.04949	570
2.04825	540
2.04701	558
2.04578	558
2.04455	524
2.04332	542
2.04209	544
2.04086	554
2.03964	530
2.03841	536
2.03719	526
2.03597	560
2.03475	526
2.03353	554
2.03232	572
2.0311	548
2.02989	526
2.02868	542
2.02747	550
2.02626	538
2.02505	552
2.02384	542
2.02264	526
2.02144	570
2.02024	546
2.01904	558
2.01784	544
2.01664	562
2.01544	580
2.01425	560
2.01306	550
2.01187	568
2.01068	574
2.00949	576
2.0083	556
2.00712	588
2.00594	574
2.00475	604
2.00357	574
2.0024	598
2.00122	598
2.00004	574
1.99887	580
1.99769	570
1.99652	614
1.99535	610
1.99418	604
1.99302	622
1.99185	612
1.99069	578
1.98952	652
1.98836	634
1.9872	622
1.98604	626
1.98488	628
1.98373	620
1.98257	610
1.98142	608
1.98027	650
1.97912	616
1.97797	604
1.97682	592
1.97568	632
1.97453	648
1.97339	624
1.97225	630
1.97111	650
1.96997	642
1.96883	638
1.9677	654
1.96656	624
1.96543	614
1.9643	626
1.96316	614
1.96204	648
1.96091	630
1.95978	634
1.95866	628
1.95753	606
1.95641	646
1.95529	624
1.95417	662
1.95305	580
1.95193	612
1.95082	626
1.9497	648
1.94859	650
1.94748	630
1.94637	650
1.94526	608
1.94415	606
1.94305	630
1.94194	610
1.94084	598
1.93974	624
1.93864	624
1.93754	630
1.93644	598
1.93534	642
1.93425	632
1.93315	614
1.93206	640
1.93097	600
1.92988	570
1.92879	592
1.9277	602
1.92662	622
1.92553	600
1.92445	622.843
1.92337	602.635
1.92228	600.321
1.92121	609.909
1.92013	616.986
1.91905	612.407
1.91797	610.801
1.9169	633.052
1.91583	622.56
1.91475	612.673
1.91368	628.912
1.91261	610.561
1.91155	615.08
1.91048	618.585
1.90946	616
1.90839	596
1.90732	638
1.90626	578
1.90519	596
1.90413	622
1.90306	610
1.902	576
1.90094	596
1.89988	564
1.89882	614
1.89777	602
1.89671	590
1.89566	596
1.8946	584
1.89355	584
1.8925	564
1.89145	622
1.8904	618
1.88936	578
1.88831	574
1.88727	578
1.88622	564
1.88518	564
1.88414	568
1.8831	580
1.88206	566
1.88102	564
1.87999	578
1.87895	574
1.87792	596
1.87689	604
1.87586	578
1.87483	558
1.8738	554
1.87277	570
1.87174	562
1.87072	548
1.86969	562
1.86867	556
1.86765	530
1.86663	546
1.86561	528
1.86459	520
1.86357	580
1.86256	538
1.86154	544
1.86053	544
1.85952	544
1.85851	542
1.8575	536
1.85649	538
1.85548	530
1.85447	524
1.85347	534
1.85247	548
1.85146	516
1.85046	512
1.84946	512
1.84846	548
1.84746	526
1.84646	524
1.84547	522
1.84447	504
1.84348	522
1.84249	512
1.8415	534
1.84051	514
1.83952	520
1.83853	512
1.83754	504
1.83656	502
1.83557	504
1.83459	510
1.83361	498
1.83262	522
1.83164	508
1.83066	504
1.82969	490
1.82871	514
1.82773	496
1.82676	506
1.82579	512
1.82481	504
1.82384	510
1.82287	482
1.8219	500
1.82094	522
1.81997	492
1.819	464
1.81804	474
1.81708	472
1.81611	484
1.81515	488
1.81419	486
1.81323	456
1.81227	480
1.81132	464
1.81036	442
1.80941	466
1.80845	456
1.8075	452
1.80655	460
1.8056	462
1.80465	474
1.8037	462
1.80275	460
1.80181	452
1.80086	440
1.79992	466
1.79897	444
1.79803	454
1.79709	456
1.79615	436
1.79521	450
1.79428	412
1.79334	434
1.7924	436
1.79147	459.845
1.79053	415.115
1.7896	410.022
1.78867	420.717
1.78774	411.813
1.78681	428.548
1.78588	421.618
1.78496	421.914
1.78403	424.489
1.7831	409.083
1.78218	426.565
1.78126	408.755
1.78033	415.419
1.77941	410.136
1.77851	424
1.77759	382
1.77667	396
1.77575	406
1.77483	422
1.77391	416
1.77299	402
1.77207	398
1.77115	398
1.77024	382
1.76932	394
1.76841	408
1.7675	390
1.76659	388
1.76568	406
1.76477	368
1.76386	376
1.76295	368
1.76204	382
1.76114	380
1.76023	378
1.75933	362
1.75843	370
1.75753	364
1.75662	360
1.75572	384
1.75483	366
1.75393	364
1.75303	350
1.75214	352
1.75124	350
1.75035	362
1.74945	356
1.74856	350
1.74767	366
1.74678	346
1.74589	326
1.74501	334
1.74412	360
1.74323	356
1.74235	344
1.74146	354
1.74058	348
1.7397	338
1.73882	346
1.73794	350
1.73706	356
1.73618	304
1.7353	334
1.73443	328
1.73355	306
1.73268	318
1.7318	336
1.73093	334
1.73006	318
1.72919	314
1.72832	324
1.72745	318
1.72658	320
1.72571	322
1.72485	328
1.72398	320
1.72312	314
1.72225	320
1.72139	304
1.72053	298
1.71967	294
1.71881	298
1.71795	306
1.71709	316
1.71624	300
1.71538	294
1.71453	284
1.71367	284
1.71282	282
1.71197	308
1.71112	296
1.71027	280
1.70942	296
1.70857	278
1.70772	256
1.70687	272
1.70603	276
1.70518	268
1.70434	256
1.7035	294
1.70265	288
1.70181	270
1.70097	284
1.70013	262
1.69929	264
1.69846	270
1.69762	258
1.69678	250
1.69595	258
1.69511	264
1.69428	246
1.69345	242
1.69262	254
1.69179	244
1.69096	248
1.69013	216
1.6893	244
1.68847	256
1.68765	236
1.68682	222
1.686	242
1.68517	232
1.68435	242
1.68353	222
1.68271	232
1.68189	226
1.68107	224
1.68025	240
1.67943	240
1.67861	218
1.6778	208
1.67698	220.078
1.67617	222.924
1.67536	245.07
1.67454	219.828
1.67373	233.083
1.67292	231.926
1.67211	225.961
1.6713	225.849
1.6705	228.066
1.66969	230.077
1.66888	223.463
1.66808	224.488
1.66727	221.056
1.66647	217.305
1.66566	232.139
1.6649	238
1.66409	210
1.66329	214
1.66249	224
1.66168	232
1.66088	228
1.66008	228
1.65928	230
1.65848	218
1.65768	220
1.65688	206
1.65608	210
1.65529	196
1.65449	200
1.6537	188
1.6529	198
1.65211	192
1.65132	184
1.65053	198
1.64973	196
1.64894	202
1.64816	194
1.64737	196
1.64658	196
1.64579	186
1.64501	192
1.64422	202
1.64344	196
1.64265	170
1.64187	188
1.64109	186
1.64031	186
1.63953	178
1.63875	174
1.63797	188
1.63719	186
1.63642	190
1.63564	190
1.63486	176
1.63409	198
1.63331	168
1.63254	186
1.63177	156
1.631	168
1.63023	174
1.62946	184
1.62869	184
1.62792	164
1.62715	168
1.62639	172
1.62562	172
1.62485	162
1.62409	172
1.62333	164
1.62256	174
1.6218	162
1.62104	158
1.62028	170
1.61952	168
1.61876	158
1.618	180
1.61724	154
1.61649	158
1.61573	152
1.61498	148
1.61422	146
1.61347	144
1.61271	152
1.61196	164
1.61121	146
1.61046	150
1.60971	142
1.60896	144
1.60821	150
1.60747	138
1.60672	140
1.60597	138
1.60523	160
1.60448	148
1.60374	152
1.603	142
1.60225	142
1.60151	144
1.60077	132
1.60003	144
1.59929	124
1.59855	138
1.59782	124
1.59708	134
1.59634	138
1.59561	132
1.59487	124
1.59414	128
1.5934	126
1.59267	132
1.59194	126
1.59121	126
1.59048	122
1.58975	118
1.58902	126
1.58829	122
1.58756	114
1.58684	126
1.58611	124
1.58538	130
1.58466	116
1.58394	114
1.58321	132
1.58249	114
1.58177	102
1.58105	116
1.58033	122
1.57961	116
1.57889	108
1.57817	114
1.57745	106
1.57674	108
1.57602	105.986
1.5753	116.476
1.57459	109.567
1.57388	98.7761
1.57316	99.4158
1.57245	99.3336
1.57174	105.006
1.57103	99.7727
1.57032	105.94
1.56961	99.8595
1.5689	98.4704
1.56819	99.2024
1.56748	95.9482
1.56678	96.7127
1.56607	95.5131
1.56544	110
1.56473	96
1.56402	106
1.56331	90
1.56261	84
1.5619	108
1.56119	102
1.56049	96
1.55979	88
1.55908	82
1.55838	94
1.55768	80
1.55698	84
1.55628	94
1.55558	98
1.55488	96
1.55418	96
1.55348	96
1.55278	84
1.55209	86
1.55139	94
1.5507	88
1.55	88
1.54931	96
1.54862	90
1.54792	70
1.54723	90
1.54654	80
1.54585	80
1.54516	84
1.54447	92
1.54378	92
1.5431	90
1.54241	96
1.54172	94
1.54104	80
1.54035	74
1.53967	84
1.53898	76
1.5383	78
1.53762	86
1.53694	80
1.53626	82
1.53558	86
1.5349	82
1.53422	68
1.53354	78
1.53286	78
1.53218	74
1.53151	70
1.53083	76
1.53016	76
1.52948	68
1.52881	66
1.52813	78
1.52746	72
1.52679	72
1.52612	84
1.52545	76
1.52478	76
1.52411	64
1.52344	72
1.52277	72
1.5221	64
1.52144	62
1.52077	74
1.52011	76
1.51944	74
1.51878	58
1.51811	60
1.51745	72
1.51679	60
1.51613	78
1.51547	54
1.51481	68
1.51415	62
1.51349	68
1.51283	70
1.51217	76
1.51151	70
1.51086	64
1.5102	58
1.50954	72
1.50889	70
1.50824	62
1.50758	68
1.50693	70
1.50628	60
1.50563	56
1.50497	62
1.50432	60
1.50367	62
1.50302	56
1.50238	70
1.50173	66
1.50108	64
1.50043	56
1.49979	48
1.49914	60
1.4985	54
1.49785	60
1.49721	70
1.49657	50
1.49592	58
1.49528	66
1.49464	56
1.494	62
1.49336	62
1.49272	54
1.49208	60
1.49144	54
1.49081	60
1.49017	60
1.48953	58
1.4889	50
1.48826	56
1.48763	44
1.48699	60.0099
1.48636	46.1419
1.48573	56.9628
1.4851	56
1.48446	57.966
1.48383	54.3557
1.4832	51.3263
1.48257	51.0594
1.48194	50.7393
1.48132	52.5088
1.48069	46.5994
1.48006	47.8963
1.47943	42.6535
1.47881	55.7382
1.47818	54
1.47756	54
1.47694	44
1.47631	54
1.47568	46
1.47505	50
1.47443	52
1.4738	42
1.47318	46
1.47256	50
1.47193	54
1.47131	52
1.47069	40
1.47006	46
1.46944	44
1.46882	50
1.4682	46
1.46758	48
1.46696	42
1.46635	50
1.46573	56
1.46511	42
1.46449	38
1.46388	42
1.46326	46
1.46265	56
1.46203	48
1.46142	40
1.46081	52
1.46019	30
1.45958	38
1.45897	32
1.45836	32
1.45775	44
1.45714	42
1.45653	38
1.45592	30
1.45531	28
1.4547	30
1.4541	34
1.45349	38
1.45288	34
1.45228	34
1.45167	30
1.45107	30
1.45047	30
1.44986	30
1.44926	30
1.44866	26
1.44806	34
1.44746	30
1.44686	28
1.44626	26
1.44566	34
1.44506	30
1.44446	26
1.44386	22
1.44326	26
1.44267	34
1.44207	36
1.44148	24
1.44088	26
1.44029	30
1.43969	30
1.4391	28
1.43851	30
1.43791	30
1.43732	22
1.43673	24
1.43614	24
1.43555	34
1.43496	28
1.43437	28
1.43378	36
1.4332	32
1.43261	26
1.43202	30
1.43143	28
1.43085	28
1.43026	26
1.42968	28
1.42909	26
1.42851	28
1.42793	26
1.42734	28
1.42676	22
1.42618	26
1.4256	22
1.42502	32
1.42444	36
1.42386	28
1.42328	22
1.4227	22
1.42212	26
1.42155	26
1.42097	24
1.42039	20
1.41982	18
1.41924	30
1.41867	24
1.41809	30
1.41752	22
1.41695	20
1.41637	28
1.4158	34
1.41523	28
1.41466	30
1.41409	32
1.41352	30
1.41295	34
1.41238	22
1.41181	24
1.41124	30
1.41067	30
1.41011	34
1.40954	24
1.40897	36
1.40841	28
1.40784	28.0245
1.40728	31.5748
1.40672	31.718
1.40615	33.5743
1.40559	29.5226
1.40503	38.5104
1.40446	40.2557
1.4039	35.803
1.40334	32.272
1.40278	33.4589
1.40222	37.9732
1.40166	36.5263
1.4011	40.6535
1.40054	33.4356
1.39999	35.7856
1.39947	42
1.3989	38
1.39834	32
1.39779	38
1.39723	42
1.39667	32
1.39611	48
1.39555	34
1.395	34
1.39444	32
1.39388	36
1.39333	32
1.39277	40
1.39222	38
1.39166	48
1.39111	38
1.39056	44
1.39	42
1.38945	44
1.3889	34
1.38835	36
1.3878	34
1.38725	40
1.3867	36
1.38615	36
1.3856	42
1.38505	36
1.3845	32
1.38396	38
1.38341	38
1.38286	34
1.38232	36
1.38177	36
1.38123	38
1.38068	34
1.38014	32
1.3796	36
1.37905	40
1.37851	30
1.37797	30
1.37743	34
1.37688	42
1.37634	34
1.3758	34
1.37526	42
1.37472	42
1.37419	36
1.37365	34
1.37311	36
1.37257	44
1.37204	44
1.3715	42
1.37096	34
1.37043	28
1.36989	32
1.36936	36
1.36882	42
1.36829	36
1.36776	28
1.36722	38
1.36669	38
1.36616	34
1.36563	26
1.3651	20
1.36457	36
1.36404	34
1.36351	32
1.36298	30
1.36245	38
1.36192	32
1.36139	38
1.36087	36
1.36034	24
1.35981	36
1.35929	32
1.35876	32
1.35824	40
1.35771	38
1.35719	34
1.35667	36
1.35614	30
1.35562	40
1.3551	30
1.35458	28
1.35406	38
1.35353	32
1.35301	40
1.35249	32
1.35197	38
1.35146	38
1.35094	32
1.35042	34
1.3499	28
1.34938	28
1.34887	30
1.34835	28
1.34783	36
1.34732	34
1.3468	32
1.34629	30
1.34578	32
1.34526	38
1.34475	28
1.34424	32
1.34372	30
1.34321	38
1.3427	34
1.34219	26
1.34168	40
1.34117	28
1.34066	38
1.34015	28
1.33964	38
1.33913	28
1.33862	36
1.33812	38
1.33761	30
1.3371	26.1659
1.3366	33.6649
1.33609	28.4103
1.33558	28.501
1.33508	36.3551
1.33457	37.2278
1.33407	32.2718
1.33357	33.8501
1.33306	30.4012
1.33256	30.8027
1.33206	33.5902
1.33156	32.1086
1.33105	29.8263
1.33055	28.3574
1.33005	28.1841
1.32959	36
1.32909	34
1.32859	28
1.32809	28
1.32758	42
1.32708	36
1.32658	30
1.32608	34
1.32558	26
1.32508	34
1.32458	34
1.32408	36
1.32358	32
1.32309	36
1.32259	38
1.32209	24
1.3216	32
1.3211	36
1.3206	36
1.32011	36
1.31961	30
1.31912	30
1.31862	36
1.31813	32
1.31764	36
1.31714	30
1.31665	24
1.31616	36
1.31567	34
1.31518	36
1.31468	30
1.31419	32
1.3137	28
1.31321	32
1.31272	30
1.31224	30
1.31175	32
1.31126	32
1.31077	26
1.31028	30
1.3098	32
1.30931	30
1.30882	30
1.30834	32
1.30785	26
1.30737	32
1.30688	30
1.3064	30
1.30592	30
1.30543	28
1.30495	36
1.30447	38
1.30399	26
1.3035	32
1.30302	38
1.30254	30
1.30206	28
1.30158	32
1.3011	26
1.30062	32
1.30014	32
1.30001	32