File: ploting_and_data_tools/raman/CdSe2_01.txt
#Acq. time (s)=	1
#Accumulations=	1
#Range (eV)=	2...1
#Windows=	11
#Autofocus=	Off
#AutoExposure=	Off
#Spike filter=	Off
#Delay time (s)=	0
#Binning=	1
#Readout mode=	Signal
#DeNoise=	Off
#ICS correction=	Off
#Dark correction=	Off
#Inst. Process=	Off
#Instrument=	LabRAM HR Evol
#Detector=	Syncerity OE
#Objective=	x100_VIS_LWD
#Grating=	600 (500nm)
#ND Filter=	1%
#Laser=	442nm_Notch
#Hole=	150.001
#Range=	Visible
#Project=	Paty
#Sample=
#Site=	15-06-22
#Title=	CdSe2
#Remark=
#Date=	15.06.2022 21:03
#Acquired=	15.06.2022 21:03:29
2.74975	30
2.7475	32
2.74525	26
2.743	30
2.74076	28
2.73852	34
2.73629	30
2.73406	30
2.73183	32
2.72961	34
2.72739	28
2.72517	30
2.72296	32
2.72075	36
2.71854	24
2.71634	40
2.71414	34
2.71195	34
2.70976	26
2.70757	36
2.70539	32
2.70321	30
2.70103	36
2.69886	30
2.69669	32
2.69452	30
2.69236	38
2.6902	34
2.68805	32
2.6859	30
2.68375	42
2.68161	26
2.67947	32
2.67733	34
2.6752	30
2.67307	42
2.67094	48
2.66882	46
2.6667	44
2.66458	44
2.66247	36
2.66036	42
2.65826	46
2.65615	42
2.65405	42
2.65196	42
2.64987	44
2.64778	42
2.64569	42
2.64361	38
2.64153	50
2.63946	44
2.63739	40
2.63532	40
2.63325	36
2.63119	54
2.62913	44
2.62708	58
2.62503	46
2.62298	50
2.62094	56
2.61889	50
2.61686	48
2.61482	52
2.61279	60
2.61076	54
2.60873	66
2.60671	66
2.60469	72
2.60268	62
2.60067	60
2.59866	74
2.59665	72
2.59465	58
2.59265	82
2.59065	80
2.58866	80
2.58667	76
2.58468	88
2.5827	86
2.58072	92
2.57874	100
2.57677	94
2.5748	96
2.57283	94
2.57086	112
2.5689	124
2.56694	114
2.56499	128
2.56304	116
2.56109	130
2.55914	130
2.5572	142
2.55526	142
2.55332	156
2.55139	158
2.54946	152
2.54753	158
2.5456	164
2.54368	172
2.54176	180
2.53985	182
2.53794	214
2.53603	196
2.53412	212
2.53222	226
2.53031	240
2.52842	210
2.52652	260
2.52463	260
2.52274	276
2.52085	278
2.51897	282
2.51709	306
2.51521	326
2.51334	324
2.51147	344
2.5096	380
2.50773	372
2.50587	386
2.50401	396
2.50216	398
2.5003	408
2.49845	422
2.4966	430
2.49476	466
2.49291	460
2.49107	516
2.48924	548
2.4874	538
2.48557	518
2.48374	538
2.48192	616.204
2.48009	609.782
2.47827	630.377
2.47646	648.019
2.47464	675.036
2.47283	695.565
2.47102	728.773
2.46922	741.15
2.46741	764.715
2.46561	787.131
2.46381	824.115
2.46202	833.856
2.46023	872.473
2.45844	879.385
2.45665	932.231
2.45493	910
2.45314	968
2.45136	1012
2.44957	974
2.44779	1034
2.44601	1060
2.44424	1112
2.44247	1126
2.4407	1176
2.43893	1148
2.43716	1208
2.4354	1188
2.43364	1214
2.43188	1270
2.43013	1288
2.42838	1296
2.42663	1336
2.42488	1282
2.42314	1354
2.4214	1380
2.41966	1398
2.41792	1464
2.41619	1436
2.41446	1496
2.41273	1470
2.411	1518
2.40928	1488
2.40756	1544
2.40584	1556
2.40413	1596
2.40241	1542
2.4007	1584
2.39899	1610
2.39729	1586
2.39559	1600
2.39389	1642
2.39219	1638
2.39049	1702
2.3888	1664
2.38711	1678
2.38542	1674
2.38374	1690
2.38205	1706
2.38037	1678
2.37869	1730
2.37702	1746
2.37535	1686
2.37368	1670
2.37201	1760
2.37034	1696
2.36868	1758
2.36702	1686
2.36536	1700
2.3637	1688
2.36205	1622
2.3604	1658
2.35875	1648
2.3571	1654
2.35546	1700
2.35382	1600
2.35218	1644
2.35054	1602
2.34891	1604
2.34727	1548
2.34564	1566
2.34402	1554
2.34239	1502
2.34077	1532
2.33915	1468
2.33753	1442
2.33591	1476
2.3343	1412
2.33269	1422
2.33108	1426
2.32948	1364
2.32787	1384
2.32627	1380
2.32467	1370
2.32307	1298
2.32148	1256
2.31989	1300
2.3183	1260
2.31671	1210
2.31512	1260
2.31354	1234
2.31196	1252
2.31038	1192
2.3088	1148
2.30723	1152
2.30565	1138
2.30408	1106
2.30252	1064
2.30095	1078
2.29939	1108
2.29783	1088
2.29627	1066
2.29471	1060
2.29316	1022
2.29161	992
2.29006	1016
2.28851	1020
2.28696	1006
2.28542	968
2.28388	958
2.28234	920
2.2808	936
2.27927	918
2.27773	878
2.2762	880
2.27468	892
2.27315	890
2.27163	840
2.27011	850
2.26859	842
2.26707	834
2.26555	816
2.26404	800
2.26253	779.463
2.26102	763.47
2.25951	776.451
2.25801	755.273
2.25651	746.006
2.25501	723.638
2.25351	699.649
2.25201	698.532
2.25052	688.86
2.24902	671.498
2.24753	652.395
2.24605	652.235
2.24456	623.309
2.24308	607.757
2.2416	624.393
2.24011	592
2.23863	606
2.23715	580
2.23567	606
2.23419	566
2.23271	594
2.23124	542
2.22977	534
2.2283	562
2.22683	534
2.22536	516
2.2239	538
2.22244	516
2.22098	526
2.21952	500
2.21807	516
2.21661	510
2.21516	494
2.21371	510
2.21226	486
2.21082	472
2.20937	496
2.20793	484
2.20649	462
2.20505	478
2.20362	490
2.20218	490
2.20075	466
2.19932	464
2.19789	476
2.19647	460
2.19504	458
2.19362	464
2.1922	476
2.19078	446
2.18936	452
2.18795	460
2.18654	442
2.18513	454
2.18372	442
2.18231	452
2.18091	430
2.1795	454
2.1781	446
2.1767	464
2.1753	448
2.17391	436
2.17251	452
2.17112	440
2.16973	432
2.16834	400
2.16696	416
2.16557	404
2.16419	422
2.16281	412
2.16143	442
2.16005	400
2.15868	424
2.1573	432
2.15593	426
2.15456	428
2.1532	416
2.15183	412
2.15046	462
2.1491	434
2.14774	422
2.14638	424
2.14503	414
2.14367	430
2.14232	418
2.14097	400
2.13962	434
2.13827	444
2.13692	444
2.13558	418
2.13423	418
2.13289	436
2.13155	422
2.13022	400
2.12888	418
2.12755	432
2.12621	432
2.12488	424
2.12356	416
2.12223	442
2.1209	428
2.11958	428
2.11826	442
2.11694	414
2.11562	434
2.1143	426
2.11299	422
2.11168	430
2.11037	436
2.10906	422
2.10775	402
2.10644	440
2.10514	428
2.10384	398
2.10253	388
2.10123	414
2.09994	432
2.09864	446
2.09735	448
2.09605	414
2.09476	420
2.09347	430
2.09219	416
2.0909	416
2.08962	414
2.08834	396
2.08705	428
2.08578	438
2.0845	442
2.08322	436
2.08195	424
2.08068	402
2.0794	415.121
2.07814	414.761
2.07687	406.791
2.0756	397.833
2.07434	407.938
2.07307	416.024
2.07181	399.884
2.07055	402.847
2.0693	400.772
2.06804	405.188
2.06679	396.713
2.06553	391.742
2.06428	395.629
2.06303	396.904
2.06178	401.217
2.06069	370
2.05944	396
2.05819	408
2.05694	384
2.05569	392
2.05445	384
2.05321	408
2.05196	396
2.05072	386
2.04949	352
2.04825	382
2.04701	384
2.04578	378
2.04455	364
2.04332	374
2.04209	378
2.04086	384
2.03964	368
2.03841	390
2.03719	370
2.03597	370
2.03475	378
2.03353	372
2.03232	368
2.0311	396
2.02989	368
2.02868	358
2.02747	368
2.02626	354
2.02505	372
2.02384	380
2.02264	358
2.02144	374
2.02024	392
2.01904	380
2.01784	372
2.01664	384
2.01544	376
2.01425	398
2.01306	384
2.01187	386
2.01068	398
2.00949	388
2.0083	380
2.00712	382
2.00594	402
2.00475	406
2.00357	374
2.0024	398
2.00122	376
2.00004	368
1.99887	378
1.99769	412
1.99652	412
1.99535	394
1.99418	404
1.99302	416
1.99185	412
1.99069	392
1.98952	406
1.98836	390
1.9872	416
1.98604	418
1.98488	406
1.98373	402
1.98257	394
1.98142	414
1.98027	410
1.97912	408
1.97797	436
1.97682	382
1.97568	424
1.97453	412
1.97339	404
1.97225	394
1.97111	390
1.96997	408
1.96883	416
1.9677	402
1.96656	424
1.96543	388
1.9643	404
1.96316	390
1.96204	416
1.96091	384
1.95978	418
1.95866	426
1.95753	408
1.95641	396
1.95529	412
1.95417	446
1.95305	428
1.95193	414
1.95082	408
1.9497	428
1.94859	424
1.94748	442
1.94637	402
1.94526	412
1.94415	398
1.94305	400
1.94194	416
1.94084	420
1.93974	402
1.93864	420
1.93754	420
1.93644	426
1.93534	410
1.93425	424
1.93315	430
1.93206	412
1.93097	428
1.92988	422
1.92879	416
1.9277	418
1.92662	444
1.92553	418
1.92445	419.254
1.92337	409.855
1.92228	406.431
1.92121	399.249
1.92013	407.879
1.91905	383.211
1.91797	412.353
1.9169	409.616
1.91583	403.729
1.91475	401.25
1.91368	404.141
1.91261	399.685
1.91155	397.576
1.91048	417.406
1.90946	386
1.90839	378
1.90732	402
1.90626	370
1.90519	390
1.90413	392
1.90306	402
1.902	384
1.90094	376
1.89988	388
1.89882	384
1.89777	374
1.89671	374
1.89566	390
1.8946	396
1.89355	374
1.8925	386
1.89145	378
1.8904	388
1.88936	376
1.88831	384
1.88727	384
1.88622	382
1.88518	378
1.88414	368
1.8831	396
1.88206	388
1.88102	360
1.87999	392
1.87895	360
1.87792	376
1.87689	358
1.87586	350
1.87483	378
1.8738	388
1.87277	364
1.87174	372
1.87072	374
1.86969	374
1.86867	390
1.86765	366
1.86663	372
1.86561	374
1.86459	382
1.86357	384
1.86256	370
1.86154	348
1.86053	370
1.85952	356
1.85851	350
1.8575	408
1.85649	364
1.85548	370
1.85447	386
1.85347	372
1.85247	360
1.85146	386
1.85046	360
1.84946	388
1.84846	374
1.84746	346
1.84646	362
1.84547	366
1.84447	344
1.84348	368
1.84249	346
1.8415	348
1.84051	348
1.83952	340
1.83853	350
1.83754	334
1.83656	344
1.83557	342
1.83459	342
1.83361	360
1.83262	332
1.83164	350
1.83066	360
1.82969	344
1.82871	350
1.82773	338
1.82676	354
1.82579	342
1.82481	352
1.82384	350
1.82287	330
1.8219	330
1.82094	344
1.81997	348
1.819	332
1.81804	340
1.81708	342
1.81611	344
1.81515	356
1.81419	340
1.81323	358
1.81227	330
1.81132	334
1.81036	336
1.80941	336
1.80845	330
1.8075	324
1.80655	310
1.8056	326
1.80465	328
1.8037	314
1.80275	332
1.80181	298
1.80086	318
1.79992	310
1.79897	324
1.79803	342
1.79709	320
1.79615	336
1.79521	320
1.79428	342
1.79334	330
1.7924	304
1.79147	312.237
1.79053	305.956
1.7896	299.104
1.78867	291.001
1.78774	323.429
1.78681	312.156
1.78588	308.68
1.78496	305.519
1.78403	293.326
1.7831	291.682
1.78218	298.396
1.78126	289.405
1.78033	301.585
1.77941	287.624
1.77851	280
1.77759	288
1.77667	302
1.77575	298
1.77483	284
1.77391	302
1.77299	284
1.77207	282
1.77115	276
1.77024	274
1.76932	272
1.76841	278
1.7675	284
1.76659	294
1.76568	296
1.76477	274
1.76386	252
1.76295	250
1.76204	256
1.76114	274
1.76023	284
1.75933	292
1.75843	260
1.75753	254
1.75662	248
1.75572	268
1.75483	268
1.75393	268
1.75303	260
1.75214	262
1.75124	270
1.75035	258
1.74945	248
1.74856	258
1.74767	238
1.74678	254
1.74589	258
1.74501	252
1.74412	254
1.74323	240
1.74235	254
1.74146	238
1.74058	240
1.7397	220
1.73882	242
1.73794	230
1.73706	246
1.73618	232
1.7353	234
1.73443	230
1.73355	212
1.73268	240
1.7318	236
1.73093	216
1.73006	226
1.72919	248
1.72832	232
1.72745	224
1.72658	214
1.72571	222
1.72485	246
1.72398	240
1.72312	220
1.72225	214
1.72139	226
1.72053	214
1.71967	224
1.71881	204
1.71795	204
1.71709	210
1.71624	222
1.71538	210
1.71453	202
1.71367	196
1.71282	202
1.71197	220
1.71112	200
1.71027	212
1.70942	222
1.70857	196
1.70772	208
1.70687	212
1.70603	202
1.70518	204
1.70434	218
1.7035	212
1.70265	188
1.70181	182
1.70097	180
1.70013	204
1.69929	196
1.69846	170
1.69762	196
1.69678	182
1.69595	198
1.69511	188
1.69428	190
1.69345	198
1.69262	170
1.69179	168
1.69096	190
1.69013	190
1.6893	164
1.68847	184
1.68765	162
1.68682	166
1.686	164
1.68517	166
1.68435	158
1.68353	148
1.68271	156
1.68189	174
1.68107	154
1.68025	152
1.67943	154
1.67861	166
1.6778	160
1.67698	148.117
1.67617	147.314
1.67536	155.512
1.67454	172.213
1.67373	175.233
1.67292	157.597
1.67211	160.525
1.6713	153.056
1.6705	155.29
1.66969	153.962
1.66888	151.99
1.66808	153.57
1.66727	153.818
1.66647	158.32
1.66566	164.482
1.6649	162
1.66409	168
1.66329	156
1.66249	154
1.66168	150
1.66088	150
1.66008	142
1.65928	154
1.65848	154
1.65768	166
1.65688	134
1.65608	152
1.65529	142
1.65449	154
1.6537	154
1.6529	140
1.65211	150
1.65132	146
1.65053	132
1.64973	150
1.64894	140
1.64816	138
1.64737	140
1.64658	150
1.64579	152
1.64501	130
1.64422	158
1.64344	146
1.64265	138
1.64187	124
1.64109	142
1.64031	136
1.63953	130
1.63875	138
1.63797	138
1.63719	124
1.63642	122
1.63564	130
1.63486	126
1.63409	126
1.63331	124
1.63254	124
1.63177	122
1.631	120
1.63023	114
1.62946	120
1.62869	124
1.62792	112
1.62715	120
1.62639	134
1.62562	124
1.62485	104
1.62409	124
1.62333	134
1.62256	124
1.6218	112
1.62104	120
1.62028	116
1.61952	116
1.61876	120
1.618	114
1.61724	94
1.61649	128
1.61573	102
1.61498	102
1.61422	102
1.61347	120
1.61271	116
1.61196	110
1.61121	104
1.61046	108
1.60971	98
1.60896	104
1.60821	106
1.60747	106
1.60672	108
1.60597	110
1.60523	88
1.60448	94
1.60374	110
1.603	84
1.60225	102
1.60151	108
1.60077	96
1.60003	98
1.59929	88
1.59855	94
1.59782	94
1.59708	98
1.59634	88
1.59561	94
1.59487	90
1.59414	102
1.5934	102
1.59267	78
1.59194	86
1.59121	102
1.59048	90
1.58975	84
1.58902	88
1.58829	88
1.58756	94
1.58684	84
1.58611	86
1.58538	86
1.58466	88
1.58394	84
1.58321	76
1.58249	86
1.58177	86
1.58105	80
1.58033	86
1.57961	88
1.57889	76
1.57817	84
1.57745	86
1.57674	76
1.57602	79.976
1.5753	78.1846
1.57459	78.339
1.57388	68.9759
1.57316	74.5246
1.57245	70.8484
1.57174	76.9518
1.57103	73.1118
1.57032	71.3205
1.56961	64.1009
1.5689	72.0641
1.56819	69.52
1.56748	77.6174
1.56678	75.0668
1.56607	72
1.56544	84
1.56473	72
1.56402	70
1.56331	72
1.56261	76
1.5619	72
1.56119	74
1.56049	58
1.55979	58
1.55908	72
1.55838	54
1.55768	72
1.55698	64
1.55628	70
1.55558	68
1.55488	70
1.55418	66
1.55348	56
1.55278	62
1.55209	66
1.55139	62
1.5507	58
1.55	58
1.54931	62
1.54862	56
1.54792	56
1.54723	56
1.54654	52
1.54585	68
1.54516	60
1.54447	62
1.54378	58
1.5431	54
1.54241	76
1.54172	60
1.54104	58
1.54035	54
1.53967	56
1.53898	56
1.5383	62
1.53762	56
1.53694	46
1.53626	58
1.53558	62
1.5349	58
1.53422	54
1.53354	56
1.53286	46
1.53218	66
1.53151	60
1.53083	48
1.53016	54
1.52948	52
1.52881	52
1.52813	54
1.52746	50
1.52679	46
1.52612	60
1.52545	48
1.52478	56
1.52411	64
1.52344	46
1.52277	50
1.5221	52
1.52144	52
1.52077	52
1.52011	48
1.51944	54
1.51878	48
1.51811	52
1.51745	52
1.51679	48
1.51613	44
1.51547	62
1.51481	60
1.51415	46
1.51349	58
1.51283	60
1.51217	48
1.51151	50
1.51086	50
1.5102	48
1.50954	38
1.50889	54
1.50824	46
1.50758	44
1.50693	46
1.50628	38
1.50563	46
1.50497	44
1.50432	40
1.50367	38
1.50302	42
1.50238	48
1.50173	54
1.50108	44
1.50043	42
1.49979	52
1.49914	48
1.4985	42
1.49785	40
1.49721	48
1.49657	32
1.49592	44
1.49528	48
1.49464	38
1.494	48
1.49336	48
1.49272	42
1.49208	46
1.49144	44
1.49081	36
1.49017	44
1.48953	42
1.4889	44
1.48826	46
1.48763	38
1.48699	32.0099
1.48636	41.8966
1.48573	44.5644
1.4851	52.8334
1.48446	41.3965
1.48383	45.6527
1.4832	37.7098
1.48257	40.6129
1.48194	40.1826
1.48132	37.07
1.48069	40.4158
1.48006	42.213
1.47943	38.7494
1.47881	40.681
1.47818	43.1231
1.47756	34
1.47694	40
1.47631	36
1.47568	36
1.47505	34
1.47443	38
1.4738	30
1.47318	30
1.47256	40
1.47193	40
1.47131	40
1.47069	32
1.47006	38
1.46944	30
1.46882	36
1.4682	36
1.46758	36
1.46696	38
1.46635	40
1.46573	36
1.46511	42
1.46449	38
1.46388	34
1.46326	32
1.46265	32
1.46203	46
1.46142	38
1.46081	32
1.46019	30
1.45958	34
1.45897	32
1.45836	30
1.45775	40
1.45714	38
1.45653	34
1.45592	30
1.45531	34
1.4547	36
1.4541	24
1.45349	40
1.45288	30
1.45228	28
1.45167	34
1.45107	30
1.45047	26
1.44986	28
1.44926	30
1.44866	28
1.44806	32
1.44746	28
1.44686	32
1.44626	26
1.44566	26
1.44506	26
1.44446	30
1.44386	28
1.44326	26
1.44267	28
1.44207	30
1.44148	24
1.44088	26
1.44029	28
1.43969	30
1.4391	34
1.43851	38
1.43791	30
1.43732	30
1.43673	28
1.43614	24
1.43555	30
1.43496	28
1.43437	26
1.43378	28
1.4332	32
1.43261	32
1.43202	28
1.43143	32
1.43085	22
1.43026	20
1.42968	32
1.42909	36
1.42851	24
1.42793	20
1.42734	32
1.42676	34
1.42618	26
1.4256	30
1.42502	30
1.42444	28
1.42386	32
1.42328	34
1.4227	32
1.42212	36
1.42155	32
1.42097	18
1.42039	30
1.41982	34
1.41924	22
1.41867	30
1.41809	38
1.41752	26
1.41695	26
1.41637	28
1.4158	22
1.41523	24
1.41466	30
1.41409	24
1.41352	28
1.41295	32
1.41238	34
1.41181	20
1.41124	30
1.41067	26
1.41011	26
1.40954	26
1.40897	30
1.40841	22
1.40784	31.9884
1.40728	35.2438
1.40672	36.8515
1.40615	26.8208
1.40559	32.1705
1.40503	35.8327
1.40446	131.7
1.4039	35.4487
1.40334	33.4561
1.40278	30
1.40222	31.3692
1.40166	32.4265
1.4011	26.9268
1.40054	29.1982
1.39999	31.9836
1.39947	36
1.3989	32
1.39834	32
1.39779	26
1.39723	36
1.39667	34
1.39611	32
1.39555	22
1.395	34
1.39444	34
1.39388	32
1.39333	32
1.39277	36
1.39222	30
1.39166	36
1.39111	32
1.39056	34
1.39	32
1.38945	32
1.3889	40
1.38835	36
1.3878	38
1.38725	34
1.3867	36
1.38615	36
1.3856	28
1.38505	32
1.3845	36
1.38396	32
1.38341	36
1.38286	30
1.38232	32
1.38177	36
1.38123	36
1.38068	36
1.38014	38
1.3796	34
1.37905	30
1.37851	28
1.37797	36
1.37743	36
1.37688	30
1.37634	34
1.3758	30
1.37526	36
1.37472	36
1.37419	26
1.37365	22
1.37311	34
1.37257	34
1.37204	30
1.3715	34
1.37096	32
1.37043	34
1.36989	34
1.36936	32
1.36882	34
1.36829	26
1.36776	28
1.36722	32
1.36669	34
1.36616	28
1.36563	38
1.3651	30
1.36457	32
1.36404	32
1.36351	32
1.36298	24
1.36245	28
1.36192	36
1.36139	28
1.36087	32
1.36034	28
1.35981	34
1.35929	28
1.35876	26
1.35824	34
1.35771	34
1.35719	34
1.35667	32
1.35614	28
1.35562	30
1.3551	34
1.35458	34
1.35406	32
1.35353	28
1.35301	30
1.35249	30
1.35197	30
1.35146	42
1.35094	22
1.35042	26
1.3499	34
1.34938	30
1.34887	26
1.34835	32
1.34783	22
1.34732	28
1.3468	30
1.34629	24
1.34578	34
1.34526	28
1.34475	36
1.34424	32
1.34372	30
1.34321	26
1.3427	24
1.34219	36
1.34168	32
1.34117	34
1.34066	30
1.34015	32
1.33964	40
1.33913	32
1.33862	28
1.33812	32
1.33761	28
1.3371	20.2271
1.3366	23.902
1.33609	29.3143
1.33558	28.7785
1.33508	35.3089
1.33457	26.5613
1.33407	29.3205
1.33357	31
1.33306	33.736
1.33256	26.5221
1.33206	27.4078
1.33156	27.2254
1.33105	34.5953
1.33055	29.9885
1.33005	27.4377
1.32959	30
1.32909	32
1.32859	38
1.32809	30
1.32758	22
1.32708	20
1.32658	24
1.32608	36
1.32558	26
1.32508	26
1.32458	28
1.32408	36
1.32358	32
1.32309	30
1.32259	34
1.32209	32
1.3216	26
1.3211	24
1.3206	20
1.32011	28
1.31961	28
1.31912	36
1.31862	30
1.31813	28
1.31764	32
1.31714	26
1.31665	36
1.31616	28
1.31567	30
1.31518	26
1.31468	34
1.31419	30
1.3137	28
1.31321	26
1.31272	34
1.31224	30
1.31175	38
1.31126	28
1.31077	32
1.31028	26
1.3098	26
1.30931	34
1.30882	28
1.30834	26
1.30785	34
1.30737	34
1.30688	32
1.3064	30
1.30592	34
1.30543	24
1.30495	34
1.30447	32
1.30399	30
1.3035	36
1.30302	24
1.30254	32
1.30206	32
1.30158	30
1.3011	40
1.30062	32
1.30014	38
1.30001	26