File: ploting_and_data_tools/raman/CdSe1_17.txt
#Acq. time (s)=	1
#Accumulations=	1
#Range (eV)=	2...1
#Windows=	11
#Autofocus=	Off
#AutoExposure=	Off
#Spike filter=	Off
#Delay time (s)=	0
#Binning=	1
#Readout mode=	Signal
#DeNoise=	Off
#ICS correction=	Off
#Dark correction=	Off
#Inst. Process=	Off
#Instrument=	LabRAM HR Evol
#Detector=	Syncerity OE
#Objective=	x100_VIS_LWD
#Grating=	600 (500nm)
#ND Filter=	1%
#Laser=	442nm_Notch
#Hole=	150.001
#Range=	Visible
#Project=	Paty
#Sample=
#Site=	15-06-22
#Title=	CdSe1
#Remark=
#Date=	15.06.2022 20:53
#Acquired=	15.06.2022 20:53:42
2.74975	26
2.7475	24
2.74525	26
2.743	36
2.74076	30
2.73852	26
2.73629	28
2.73406	32
2.73183	34
2.72961	28
2.72739	30
2.72517	32
2.72296	28
2.72075	28
2.71854	30
2.71634	28
2.71414	32
2.71195	30
2.70976	30
2.70757	26
2.70539	28
2.70321	32
2.70103	30
2.69886	34
2.69669	42
2.69452	28
2.69236	34
2.6902	38
2.68805	24
2.6859	26
2.68375	30
2.68161	38
2.67947	32
2.67733	32
2.6752	38
2.67307	32
2.67094	36
2.66882	34
2.6667	32
2.66458	40
2.66247	30
2.66036	40
2.65826	38
2.65615	42
2.65405	38
2.65196	40
2.64987	34
2.64778	32
2.64569	40
2.64361	40
2.64153	44
2.63946	46
2.63739	42
2.63532	36
2.63325	38
2.63119	34
2.62913	42
2.62708	52
2.62503	34
2.62298	34
2.62094	42
2.61889	48
2.61686	40
2.61482	38
2.61279	54
2.61076	58
2.60873	50
2.60671	46
2.60469	62
2.60268	46
2.60067	64
2.59866	58
2.59665	62
2.59465	62
2.59265	60
2.59065	72
2.58866	66
2.58667	68
2.58468	64
2.5827	70
2.58072	88
2.57874	78
2.57677	76
2.5748	72
2.57283	80
2.57086	76
2.5689	94
2.56694	96
2.56499	86
2.56304	102
2.56109	94
2.55914	100
2.5572	108
2.55526	116
2.55332	118
2.55139	122
2.54946	116
2.54753	134
2.5456	136
2.54368	138
2.54176	158
2.53985	158
2.53794	146
2.53603	152
2.53412	176
2.53222	176
2.53031	192
2.52842	180
2.52652	194
2.52463	190
2.52274	218
2.52085	198
2.51897	238
2.51709	230
2.51521	246
2.51334	228
2.51147	254
2.5096	246
2.50773	280
2.50587	274
2.50401	290
2.50216	312
2.5003	316
2.49845	318
2.4966	332
2.49476	354
2.49291	370
2.49107	364
2.48924	370
2.4874	414
2.48557	420
2.48374	426
2.48192	451.115
2.48009	456.221
2.47827	480.609
2.47646	490.426
2.47464	500.211
2.47283	544.86
2.47102	544.17
2.46922	581.286
2.46741	596.559
2.46561	629.943
2.46381	640.439
2.46202	667.5
2.46023	689.164
2.45844	696.217
2.45665	718.744
2.45493	774
2.45314	748
2.45136	822
2.44957	846
2.44779	868
2.44601	858
2.44424	892
2.44247	906
2.4407	926
2.43893	916
2.43716	946
2.4354	990
2.43364	998
2.43188	1064
2.43013	1072
2.42838	1078
2.42663	1056
2.42488	1144
2.42314	1164
2.4214	1158
2.41966	1192
2.41792	1202
2.41619	1226
2.41446	1216
2.41273	1282
2.411	1222
2.40928	1344
2.40756	1302
2.40584	1340
2.40413	1344
2.40241	1358
2.4007	1356
2.39899	1344
2.39729	1430
2.39559	1402
2.39389	1438
2.39219	1470
2.39049	1420
2.3888	1464
2.38711	1488
2.38542	1516
2.38374	1548
2.38205	1482
2.38037	1500
2.37869	1542
2.37702	1564
2.37535	1552
2.37368	1574
2.37201	1590
2.37034	1562
2.36868	1546
2.36702	1580
2.36536	1580
2.3637	1564
2.36205	1552
2.3604	1574
2.35875	1554
2.3571	1530
2.35546	1544
2.35382	1554
2.35218	1532
2.35054	1498
2.34891	1486
2.34727	1520
2.34564	1480
2.34402	1478
2.34239	1458
2.34077	1404
2.33915	1440
2.33753	1436
2.33591	1424
2.3343	1376
2.33269	1360
2.33108	1312
2.32948	1372
2.32787	1392
2.32627	1358
2.32467	1280
2.32307	1330
2.32148	1314
2.31989	1248
2.3183	1226
2.31671	1246
2.31512	1208
2.31354	1210
2.31196	1176
2.31038	1174
2.3088	1142
2.30723	1156
2.30565	1138
2.30408	1138
2.30252	1134
2.30095	1132
2.29939	1046
2.29783	1086
2.29627	1064
2.29471	1078
2.29316	1034
2.29161	1026
2.29006	1000
2.28851	1034
2.28696	970
2.28542	976
2.28388	954
2.28234	928
2.2808	946
2.27927	950
2.27773	902
2.2762	890
2.27468	892
2.27315	872
2.27163	870
2.27011	834
2.26859	838
2.26707	872
2.26555	816
2.26404	822
2.26253	785.568
2.26102	761.748
2.25951	762.69
2.25801	742.573
2.25651	732.444
2.25501	729.121
2.25351	714.236
2.25201	694.027
2.25052	685.84
2.24902	660.713
2.24753	665.961
2.24605	654.231
2.24456	663.704
2.24308	611.309
2.2416	608.704
2.24011	592
2.23863	578
2.23715	562
2.23567	602
2.23419	580
2.23271	548
2.23124	550
2.22977	564
2.2283	516
2.22683	520
2.22536	532
2.2239	496
2.22244	520
2.22098	486
2.21952	496
2.21807	518
2.21661	470
2.21516	482
2.21371	464
2.21226	470
2.21082	448
2.20937	454
2.20793	448
2.20649	440
2.20505	450
2.20362	432
2.20218	442
2.20075	432
2.19932	428
2.19789	458
2.19647	430
2.19504	406
2.19362	422
2.1922	428
2.19078	436
2.18936	392
2.18795	388
2.18654	388
2.18513	374
2.18372	380
2.18231	378
2.18091	378
2.1795	388
2.1781	382
2.1767	386
2.1753	396
2.17391	374
2.17251	378
2.17112	370
2.16973	364
2.16834	362
2.16696	360
2.16557	342
2.16419	358
2.16281	360
2.16143	374
2.16005	350
2.15868	368
2.1573	368
2.15593	362
2.15456	358
2.1532	374
2.15183	376
2.15046	354
2.1491	344
2.14774	360
2.14638	352
2.14503	372
2.14367	348
2.14232	332
2.14097	342
2.13962	336
2.13827	346
2.13692	320
2.13558	330
2.13423	328
2.13289	344
2.13155	326
2.13022	332
2.12888	352
2.12755	332
2.12621	342
2.12488	340
2.12356	336
2.12223	360
2.1209	340
2.11958	346
2.11826	354
2.11694	348
2.11562	334
2.1143	340
2.11299	334
2.11168	340
2.11037	328
2.10906	324
2.10775	326
2.10644	326
2.10514	322
2.10384	348
2.10253	306
2.10123	336
2.09994	344
2.09864	312
2.09735	344
2.09605	334
2.09476	330
2.09347	328
2.09219	334
2.0909	356
2.08962	340
2.08834	326
2.08705	332
2.08578	300
2.0845	318
2.08322	334
2.08195	342
2.08068	314
2.0794	325.722
2.07814	319.849
2.07687	320.523
2.0756	318.339
2.07434	307.133
2.07307	311.333
2.07181	325.921
2.07055	309.782
2.0693	307.728
2.06804	309.771
2.06679	301.198
2.06553	315.311
2.06428	309.672
2.06303	305.442
2.06178	303.334
2.06069	296
2.05944	292
2.05819	284
2.05694	318
2.05569	308
2.05445	318
2.05321	292
2.05196	286
2.05072	294
2.04949	278
2.04825	318
2.04701	288
2.04578	282
2.04455	308
2.04332	298
2.04209	302
2.04086	296
2.03964	266
2.03841	296
2.03719	304
2.03597	284
2.03475	278
2.03353	286
2.03232	284
2.0311	294
2.02989	272
2.02868	284
2.02747	298
2.02626	286
2.02505	270
2.02384	284
2.02264	284
2.02144	306
2.02024	282
2.01904	300
2.01784	284
2.01664	292
2.01544	304
2.01425	286
2.01306	296
2.01187	294
2.01068	286
2.00949	292
2.0083	296
2.00712	338
2.00594	306
2.00475	294
2.00357	296
2.0024	296
2.00122	302
2.00004	298
1.99887	318
1.99769	290
1.99652	310
1.99535	282
1.99418	310
1.99302	306
1.99185	298
1.99069	290
1.98952	320
1.98836	320
1.9872	310
1.98604	308
1.98488	272
1.98373	314
1.98257	340
1.98142	318
1.98027	296
1.97912	298
1.97797	328
1.97682	322
1.97568	316
1.97453	310
1.97339	318
1.97225	296
1.97111	310
1.96997	312
1.96883	322
1.9677	312
1.96656	318
1.96543	318
1.9643	326
1.96316	328
1.96204	316
1.96091	312
1.95978	318
1.95866	298
1.95753	300
1.95641	320
1.95529	324
1.95417	322
1.95305	320
1.95193	304
1.95082	316
1.9497	314
1.94859	324
1.94748	308
1.94637	312
1.94526	338
1.94415	340
1.94305	318
1.94194	292
1.94084	338
1.93974	324
1.93864	308
1.93754	312
1.93644	306
1.93534	322
1.93425	326
1.93315	324
1.93206	324
1.93097	310
1.92988	332
1.92879	322
1.9277	312
1.92662	330
1.92553	336
1.92445	296.728
1.92337	293.92
1.92228	319.226
1.92121	316.249
1.92013	302.153
1.91905	310.029
1.91797	318.475
1.9169	313.88
1.91583	308.631
1.91475	312.11
1.91368	313.578
1.91261	308.795
1.91155	309.723
1.91048	295.679
1.90946	292
1.90839	316
1.90732	326
1.90626	300
1.90519	296
1.90413	290
1.90306	302
1.902	300
1.90094	300
1.89988	304
1.89882	300
1.89777	292
1.89671	296
1.89566	314
1.8946	304
1.89355	302
1.8925	294
1.89145	312
1.8904	290
1.88936	298
1.88831	288
1.88727	298
1.88622	294
1.88518	306
1.88414	296
1.8831	310
1.88206	288
1.88102	298
1.87999	294
1.87895	302
1.87792	312
1.87689	284
1.87586	300
1.87483	280
1.8738	280
1.87277	304
1.87174	264
1.87072	288
1.86969	286
1.86867	300
1.86765	270
1.86663	278
1.86561	272
1.86459	282
1.86357	316
1.86256	290
1.86154	284
1.86053	290
1.85952	306
1.85851	278
1.8575	276
1.85649	304
1.85548	302
1.85447	300
1.85347	272
1.85247	268
1.85146	274
1.85046	272
1.84946	282
1.84846	284
1.84746	280
1.84646	284
1.84547	276
1.84447	274
1.84348	280
1.84249	280
1.8415	272
1.84051	282
1.83952	270
1.83853	294
1.83754	276
1.83656	266
1.83557	280
1.83459	290
1.83361	268
1.83262	262
1.83164	284
1.83066	276
1.82969	280
1.82871	274
1.82773	268
1.82676	278
1.82579	270
1.82481	274
1.82384	272
1.82287	268
1.8219	250
1.82094	256
1.81997	256
1.819	260
1.81804	242
1.81708	260
1.81611	262
1.81515	268
1.81419	242
1.81323	234
1.81227	246
1.81132	256
1.81036	246
1.80941	254
1.80845	254
1.8075	246
1.80655	244
1.8056	236
1.80465	252
1.8037	252
1.80275	244
1.80181	258
1.80086	260
1.79992	240
1.79897	248
1.79803	250
1.79709	238
1.79615	264
1.79521	230
1.79428	254
1.79334	252
1.7924	216
1.79147	228.596
1.79053	234.128
1.7896	258.429
1.78867	247.202
1.78774	244.409
1.78681	237.206
1.78588	235.886
1.78496	232.715
1.78403	229.157
1.7831	235.343
1.78218	230.957
1.78126	224.349
1.78033	236.284
1.77941	228.903
1.77851	208
1.77759	232
1.77667	222
1.77575	240
1.77483	214
1.77391	222
1.77299	224
1.77207	204
1.77115	214
1.77024	204
1.76932	234
1.76841	228
1.7675	234
1.76659	234
1.76568	242
1.76477	224
1.76386	218
1.76295	222
1.76204	224
1.76114	218
1.76023	242
1.75933	224
1.75843	212
1.75753	206
1.75662	214
1.75572	206
1.75483	200
1.75393	204
1.75303	202
1.75214	214
1.75124	210
1.75035	190
1.74945	198
1.74856	194
1.74767	200
1.74678	204
1.74589	216
1.74501	202
1.74412	212
1.74323	202
1.74235	194
1.74146	196
1.74058	200
1.7397	174
1.73882	190
1.73794	204
1.73706	198
1.73618	188
1.7353	194
1.73443	190
1.73355	208
1.73268	194
1.7318	176
1.73093	172
1.73006	174
1.72919	174
1.72832	174
1.72745	184
1.72658	174
1.72571	190
1.72485	186
1.72398	178
1.72312	176
1.72225	160
1.72139	170
1.72053	172
1.71967	186
1.71881	166
1.71795	164
1.71709	172
1.71624	186
1.71538	180
1.71453	174
1.71367	162
1.71282	170
1.71197	164
1.71112	184
1.71027	170
1.70942	160
1.70857	160
1.70772	172
1.70687	168
1.70603	164
1.70518	164
1.70434	156
1.7035	174
1.70265	152
1.70181	160
1.70097	170
1.70013	160
1.69929	150
1.69846	164
1.69762	140
1.69678	154
1.69595	144
1.69511	150
1.69428	136
1.69345	132
1.69262	136
1.69179	158
1.69096	150
1.69013	140
1.6893	138
1.68847	158
1.68765	140
1.68682	136
1.686	142
1.68517	136
1.68435	140
1.68353	140
1.68271	142
1.68189	132
1.68107	128
1.68025	144
1.67943	126
1.67861	138
1.6778	142
1.67698	129.99
1.67617	133.513
1.67536	134.174
1.67454	135.262
1.67373	125.428
1.67292	135.257
1.67211	136.804
1.6713	129.594
1.6705	124.707
1.66969	130.213
1.66888	133.64
1.66808	129.755
1.66727	127.818
1.66647	127.773
1.66566	121.994
1.6649	118
1.66409	116
1.66329	122
1.66249	130
1.66168	120
1.66088	106
1.66008	126
1.65928	112
1.65848	120
1.65768	122
1.65688	112
1.65608	108
1.65529	124
1.65449	124
1.6537	126
1.6529	116
1.65211	114
1.65132	116
1.65053	114
1.64973	126
1.64894	116
1.64816	120
1.64737	118
1.64658	106
1.64579	114
1.64501	116
1.64422	120
1.64344	112
1.64265	96
1.64187	116
1.64109	122
1.64031	110
1.63953	118
1.63875	112
1.63797	110
1.63719	114
1.63642	98
1.63564	108
1.63486	102
1.63409	96
1.63331	104
1.63254	112
1.63177	100
1.631	100
1.63023	108
1.62946	96
1.62869	116
1.62792	112
1.62715	94
1.62639	104
1.62562	110
1.62485	108
1.62409	116
1.62333	94
1.62256	100
1.6218	88
1.62104	100
1.62028	92
1.61952	100
1.61876	100
1.618	94
1.61724	100
1.61649	94
1.61573	90
1.61498	88
1.61422	96
1.61347	86
1.61271	88
1.61196	84
1.61121	86
1.61046	96
1.60971	88
1.60896	90
1.60821	84
1.60747	92
1.60672	94
1.60597	94
1.60523	82
1.60448	86
1.60374	84
1.603	90
1.60225	84
1.60151	84
1.60077	82
1.60003	84
1.59929	88
1.59855	76
1.59782	72
1.59708	76
1.59634	84
1.59561	72
1.59487	80
1.59414	80
1.5934	86
1.59267	76
1.59194	92
1.59121	74
1.59048	78
1.58975	84
1.58902	78
1.58829	82
1.58756	74
1.58684	76
1.58611	74
1.58538	76
1.58466	72
1.58394	66
1.58321	70
1.58249	72
1.58177	74
1.58105	68
1.58033	64
1.57961	74
1.57889	72
1.57817	64
1.57745	62
1.57674	70
1.57602	56.0505
1.5753	63.1853
1.57459	74.7279
1.57388	66.7982
1.57316	71.8019
1.57245	67.297
1.57174	69.5592
1.57103	63.1806
1.57032	56.9198
1.56961	65.3604
1.5689	62.3613
1.56819	65.341
1.56748	66.2074
1.56678	59.3242
1.56607	58.9427
1.56544	56
1.56473	50
1.56402	64
1.56331	54
1.56261	60
1.5619	66
1.56119	68
1.56049	56
1.55979	62
1.55908	58
1.55838	62
1.55768	56
1.55698	60
1.55628	56
1.55558	62
1.55488	64
1.55418	64
1.55348	58
1.55278	50
1.55209	60
1.55139	52
1.5507	58
1.55	56
1.54931	62
1.54862	56
1.54792	54
1.54723	58
1.54654	50
1.54585	60
1.54516	56
1.54447	62
1.54378	56
1.5431	58
1.54241	50
1.54172	56
1.54104	58
1.54035	56
1.53967	50
1.53898	58
1.5383	52
1.53762	60
1.53694	52
1.53626	54
1.53558	52
1.5349	52
1.53422	60
1.53354	42
1.53286	54
1.53218	46
1.53151	46
1.53083	50
1.53016	60
1.52948	44
1.52881	46
1.52813	52
1.52746	52
1.52679	44
1.52612	52
1.52545	46
1.52478	44
1.52411	44
1.52344	46
1.52277	46
1.5221	40
1.52144	44
1.52077	54
1.52011	54
1.51944	48
1.51878	42
1.51811	48
1.51745	48
1.51679	42
1.51613	42
1.51547	48
1.51481	52
1.51415	44
1.51349	52
1.51283	42
1.51217	44
1.51151	48
1.51086	44
1.5102	44
1.50954	48
1.50889	46
1.50824	38
1.50758	50
1.50693	52
1.50628	50
1.50563	40
1.50497	44
1.50432	40
1.50367	48
1.50302	38
1.50238	48
1.50173	42
1.50108	40
1.50043	42
1.49979	44
1.49914	40
1.4985	46
1.49785	38
1.49721	46
1.49657	42
1.49592	48
1.49528	36
1.49464	36
1.494	40
1.49336	44
1.49272	40
1.49208	38
1.49144	40
1.49081	40
1.49017	44
1.48953	42
1.4889	40
1.48826	40
1.48763	34
1.48699	32.0495
1.48636	45.3157
1.48573	38.7034
1.4851	33.8226
1.48446	39.1287
1.48383	37.8789
1.4832	36.9349
1.48257	34.3726
1.48194	42.7393
1.48132	35.2171
1.48069	34.6909
1.48006	32.0743
1.47943	37.968
1.47881	38.8786
1.47818	45.4932
1.47756	34
1.47694	46
1.47631	40
1.47568	32
1.47505	40
1.47443	36
1.4738	30
1.47318	36
1.47256	34
1.47193	36
1.47131	36
1.47069	36
1.47006	36
1.46944	40
1.46882	44
1.4682	38
1.46758	38
1.46696	36
1.46635	44
1.46573	34
1.46511	32
1.46449	32
1.46388	30
1.46326	40
1.46265	32
1.46203	36
1.46142	28
1.46081	38
1.46019	36
1.45958	30
1.45897	36
1.45836	32
1.45775	40
1.45714	36
1.45653	30
1.45592	24
1.45531	36
1.4547	30
1.4541	30
1.45349	34
1.45288	34
1.45228	28
1.45167	26
1.45107	34
1.45047	30
1.44986	26
1.44926	22
1.44866	24
1.44806	32
1.44746	28
1.44686	32
1.44626	26
1.44566	24
1.44506	30
1.44446	30
1.44386	26
1.44326	28
1.44267	28
1.44207	28
1.44148	30
1.44088	34
1.44029	28
1.43969	24
1.4391	26
1.43851	34
1.43791	28
1.43732	30
1.43673	30
1.43614	34
1.43555	28
1.43496	28
1.43437	26
1.43378	26
1.4332	28
1.43261	24
1.43202	28
1.43143	26
1.43085	24
1.43026	30
1.42968	30
1.42909	24
1.42851	32
1.42793	30
1.42734	28
1.42676	22
1.42618	28
1.4256	26
1.42502	30
1.42444	32
1.42386	32
1.42328	28
1.4227	26
1.42212	34
1.42155	24
1.42097	28
1.42039	30
1.41982	30
1.41924	22
1.41867	28
1.41809	32
1.41752	22
1.41695	28
1.41637	30
1.4158	30
1.41523	24
1.41466	28
1.41409	26
1.41352	28
1.41295	32
1.41238	24
1.41181	24
1.41124	26
1.41067	28
1.41011	26
1.40954	24
1.40897	28
1.40841	30
1.40784	26.0082
1.40728	26.5805
1.40672	23.9995
1.40615	25.1485
1.40559	31.8295
1.40503	27.548
1.40446	132.615
1.4039	30.3544
1.40334	30.1689
1.40278	32.7239
1.40222	29.2079
1.40166	32.9695
1.4011	31.9134
1.40054	26.1881
1.39999	32.0331
1.39947	32
1.3989	30
1.39834	34
1.39779	32
1.39723	38
1.39667	26
1.39611	36
1.39555	28
1.395	26
1.39444	36
1.39388	30
1.39333	28
1.39277	30
1.39222	34
1.39166	40
1.39111	30
1.39056	26
1.39	32
1.38945	22
1.3889	30
1.38835	34
1.3878	36
1.38725	34
1.3867	34
1.38615	24
1.3856	26
1.38505	38
1.3845	32
1.38396	38
1.38341	36
1.38286	30
1.38232	36
1.38177	40
1.38123	30
1.38068	30
1.38014	32
1.3796	40
1.37905	36
1.37851	32
1.37797	30
1.37743	38
1.37688	42
1.37634	34
1.3758	36
1.37526	32
1.37472	26
1.37419	38
1.37365	30
1.37311	26
1.37257	28
1.37204	26
1.3715	38
1.37096	28
1.37043	32
1.36989	38
1.36936	32
1.36882	34
1.36829	34
1.36776	34
1.36722	38
1.36669	36
1.36616	30
1.36563	32
1.3651	26
1.36457	30
1.36404	30
1.36351	34
1.36298	28
1.36245	26
1.36192	36
1.36139	32
1.36087	36
1.36034	30
1.35981	34
1.35929	38
1.35876	30
1.35824	32
1.35771	36
1.35719	32
1.35667	22
1.35614	30
1.35562	28
1.3551	28
1.35458	36
1.35406	36
1.35353	36
1.35301	32
1.35249	32
1.35197	28
1.35146	28
1.35094	24
1.35042	30
1.3499	28
1.34938	22
1.34887	32
1.34835	32
1.34783	30
1.34732	34
1.3468	32
1.34629	30
1.34578	34
1.34526	36
1.34475	26
1.34424	24
1.34372	30
1.34321	32
1.3427	30
1.34219	28
1.34168	26
1.34117	34
1.34066	32
1.34015	16
1.33964	30
1.33913	34
1.33862	30
1.33812	32
1.33761	28
1.3371	24.1878
1.3366	31.4127
1.33609	33.3143
1.33558	25.1321
1.33508	28
1.33457	28.737
1.33407	26.8097
1.33357	30
1.33306	26.1346
1.33256	28.3905
1.33206	25.9208
1.33156	25.2971
1.33105	28.7639
1.33055	32.2201
1.33005	30.366
1.32959	24
1.32909	30
1.32859	30
1.32809	28
1.32758	28
1.32708	28
1.32658	28
1.32608	30
1.32558	32
1.32508	24
1.32458	36
1.32408	30
1.32358	36
1.32309	30
1.32259	30
1.32209	30
1.3216	20
1.3211	32
1.3206	28
1.32011	24
1.31961	30
1.31912	34
1.31862	28
1.31813	32
1.31764	28
1.31714	32
1.31665	34
1.31616	32
1.31567	26
1.31518	32
1.31468	36
1.31419	28
1.3137	30
1.31321	24
1.31272	36
1.31224	34
1.31175	32
1.31126	28
1.31077	26
1.31028	32
1.3098	34
1.30931	34
1.30882	36
1.30834	26
1.30785	24
1.30737	30
1.30688	26
1.3064	32
1.30592	32
1.30543	30
1.30495	32
1.30447	40
1.30399	38
1.3035	40
1.30302	28
1.30254	42
1.30206	30
1.30158	34
1.3011	32
1.30062	32
1.30014	32
1.30001	38