File: ploting_and_data_tools/raman/CdSe1_14.txt
#Acq. time (s)=	1
#Accumulations=	1
#Range (eV)=	2...1
#Windows=	11
#Autofocus=	Off
#AutoExposure=	Off
#Spike filter=	Off
#Delay time (s)=	0
#Binning=	1
#Readout mode=	Signal
#DeNoise=	Off
#ICS correction=	Off
#Dark correction=	Off
#Inst. Process=	Off
#Instrument=	LabRAM HR Evol
#Detector=	Syncerity OE
#Objective=	x100_VIS_LWD
#Grating=	600 (500nm)
#ND Filter=	1%
#Laser=	442nm_Notch
#Hole=	100.021
#Range=	Visible
#Project=	Paty
#Sample=
#Site=	15-06-22
#Title=	CdSe1
#Remark=
#Date=	15.06.2022 20:41
#Acquired=	15.06.2022 20:41:35
2.74975	24
2.7475	30
2.74525	28
2.743	28
2.74076	26
2.73852	24
2.73629	34
2.73406	32
2.73183	22
2.72961	32
2.72739	34
2.72517	28
2.72296	34
2.72075	28
2.71854	28
2.71634	28
2.71414	26
2.71195	28
2.70976	24
2.70757	22
2.70539	28
2.70321	24
2.70103	30
2.69886	34
2.69669	26
2.69452	20
2.69236	30
2.6902	32
2.68805	30
2.6859	28
2.68375	38
2.68161	26
2.67947	36
2.67733	30
2.6752	32
2.67307	30
2.67094	26
2.66882	38
2.6667	34
2.66458	32
2.66247	36
2.66036	32
2.65826	38
2.65615	36
2.65405	34
2.65196	22
2.64987	32
2.64778	36
2.64569	38
2.64361	26
2.64153	32
2.63946	38
2.63739	36
2.63532	40
2.63325	38
2.63119	34
2.62913	36
2.62708	34
2.62503	40
2.62298	38
2.62094	42
2.61889	48
2.61686	42
2.61482	36
2.61279	44
2.61076	36
2.60873	44
2.60671	50
2.60469	44
2.60268	38
2.60067	44
2.59866	46
2.59665	46
2.59465	50
2.59265	50
2.59065	54
2.58866	52
2.58667	54
2.58468	70
2.5827	56
2.58072	48
2.57874	64
2.57677	60
2.5748	70
2.57283	58
2.57086	70
2.5689	70
2.56694	80
2.56499	74
2.56304	86
2.56109	82
2.55914	96
2.5572	70
2.55526	86
2.55332	94
2.55139	98
2.54946	112
2.54753	108
2.5456	100
2.54368	104
2.54176	108
2.53985	112
2.53794	118
2.53603	112
2.53412	128
2.53222	144
2.53031	140
2.52842	132
2.52652	126
2.52463	140
2.52274	162
2.52085	162
2.51897	174
2.51709	178
2.51521	176
2.51334	192
2.51147	200
2.5096	216
2.50773	218
2.50587	202
2.50401	220
2.50216	216
2.5003	242
2.49845	264
2.4966	242
2.49476	264
2.49291	286
2.49107	276
2.48924	286
2.4874	272
2.48557	326
2.48374	304
2.48192	359.357
2.48009	345.293
2.47827	368.38
2.47646	387.782
2.47464	401.073
2.47283	416.487
2.47102	450.95
2.46922	467.134
2.46741	485.396
2.46561	519.298
2.46381	531.367
2.46202	569.567
2.46023	612.323
2.45844	610.636
2.45665	635.713
2.45493	670
2.45314	676
2.45136	694
2.44957	724
2.44779	720
2.44601	730
2.44424	772
2.44247	806
2.4407	810
2.43893	828
2.43716	844
2.4354	842
2.43364	854
2.43188	916
2.43013	912
2.42838	942
2.42663	918
2.42488	950
2.42314	972
2.4214	1044
2.41966	1046
2.41792	1082
2.41619	1082
2.41446	1108
2.41273	1088
2.411	1124
2.40928	1110
2.40756	1142
2.40584	1200
2.40413	1196
2.40241	1202
2.4007	1234
2.39899	1200
2.39729	1268
2.39559	1244
2.39389	1276
2.39219	1284
2.39049	1274
2.3888	1280
2.38711	1326
2.38542	1304
2.38374	1336
2.38205	1354
2.38037	1352
2.37869	1376
2.37702	1346
2.37535	1370
2.37368	1394
2.37201	1404
2.37034	1384
2.36868	1402
2.36702	1394
2.36536	1386
2.3637	1350
2.36205	1362
2.3604	1370
2.35875	1340
2.3571	1338
2.35546	1344
2.35382	1350
2.35218	1310
2.35054	1368
2.34891	1298
2.34727	1320
2.34564	1296
2.34402	1310
2.34239	1292
2.34077	1264
2.33915	1234
2.33753	1228
2.33591	1220
2.3343	1262
2.33269	1188
2.33108	1178
2.32948	1248
2.32787	1200
2.32627	1192
2.32467	1176
2.32307	1106
2.32148	1130
2.31989	1144
2.3183	1096
2.31671	1082
2.31512	1082
2.31354	1026
2.31196	1028
2.31038	1012
2.3088	1038
2.30723	1022
2.30565	1014
2.30408	982
2.30252	986
2.30095	944
2.29939	988
2.29783	946
2.29627	944
2.29471	930
2.29316	900
2.29161	912
2.29006	906
2.28851	856
2.28696	896
2.28542	878
2.28388	870
2.28234	836
2.2808	808
2.27927	858
2.27773	786
2.2762	820
2.27468	798
2.27315	792
2.27163	776
2.27011	760
2.26859	744
2.26707	716
2.26555	736
2.26404	718
2.26253	705.852
2.26102	687.031
2.25951	700.445
2.25801	696.102
2.25651	669.74
2.25501	663.63
2.25351	668.412
2.25201	655.577
2.25052	642.97
2.24902	622.813
2.24753	627.472
2.24605	638.804
2.24456	608.061
2.24308	607.868
2.2416	570.374
2.24011	568
2.23863	562
2.23715	566
2.23567	558
2.23419	520
2.23271	550
2.23124	536
2.22977	528
2.2283	536
2.22683	510
2.22536	498
2.2239	476
2.22244	494
2.22098	484
2.21952	492
2.21807	468
2.21661	470
2.21516	444
2.21371	452
2.21226	456
2.21082	436
2.20937	440
2.20793	450
2.20649	464
2.20505	414
2.20362	416
2.20218	432
2.20075	430
2.19932	452
2.19789	390
2.19647	396
2.19504	394
2.19362	402
2.1922	420
2.19078	414
2.18936	400
2.18795	406
2.18654	406
2.18513	386
2.18372	374
2.18231	404
2.18091	384
2.1795	408
2.1781	356
2.1767	372
2.1753	366
2.17391	344
2.17251	368
2.17112	376
2.16973	350
2.16834	354
2.16696	364
2.16557	372
2.16419	348
2.16281	358
2.16143	350
2.16005	362
2.15868	356
2.1573	340
2.15593	360
2.15456	364
2.1532	344
2.15183	356
2.15046	328
2.1491	334
2.14774	336
2.14638	362
2.14503	342
2.14367	346
2.14232	344
2.14097	358
2.13962	352
2.13827	364
2.13692	350
2.13558	344
2.13423	352
2.13289	338
2.13155	334
2.13022	342
2.12888	354
2.12755	340
2.12621	330
2.12488	344
2.12356	320
2.12223	346
2.1209	346
2.11958	360
2.11826	356
2.11694	348
2.11562	338
2.1143	360
2.11299	358
2.11168	346
2.11037	336
2.10906	336
2.10775	334
2.10644	324
2.10514	326
2.10384	326
2.10253	344
2.10123	316
2.09994	334
2.09864	330
2.09735	334
2.09605	324
2.09476	342
2.09347	330
2.09219	332
2.0909	330
2.08962	340
2.08834	338
2.08705	340
2.08578	322
2.0845	320
2.08322	344
2.08195	332
2.08068	312
2.0794	324.124
2.07814	332.874
2.07687	318.366
2.0756	329.023
2.07434	323.452
2.07307	332.275
2.07181	321.128
2.07055	321.211
2.0693	308.455
2.06804	331.654
2.06679	320.324
2.06553	311.363
2.06428	323.666
2.06303	315.516
2.06178	329.119
2.06069	320
2.05944	312
2.05819	324
2.05694	314
2.05569	314
2.05445	324
2.05321	316
2.05196	306
2.05072	318
2.04949	320
2.04825	334
2.04701	284
2.04578	318
2.04455	320
2.04332	316
2.04209	316
2.04086	314
2.03964	264
2.03841	312
2.03719	318
2.03597	306
2.03475	302
2.03353	290
2.03232	324
2.0311	290
2.02989	314
2.02868	322
2.02747	298
2.02626	312
2.02505	326
2.02384	320
2.02264	290
2.02144	302
2.02024	308
2.01904	308
2.01784	318
2.01664	332
2.01544	302
2.01425	308
2.01306	324
2.01187	318
2.01068	304
2.00949	310
2.0083	312
2.00712	352
2.00594	328
2.00475	320
2.00357	320
2.0024	312
2.00122	314
2.00004	324
1.99887	316
1.99769	318
1.99652	318
1.99535	322
1.99418	350
1.99302	336
1.99185	330
1.99069	338
1.98952	328
1.98836	348
1.9872	338
1.98604	324
1.98488	336
1.98373	326
1.98257	326
1.98142	356
1.98027	348
1.97912	338
1.97797	334
1.97682	342
1.97568	342
1.97453	354
1.97339	346
1.97225	348
1.97111	326
1.96997	336
1.96883	340
1.9677	354
1.96656	348
1.96543	330
1.9643	334
1.96316	350
1.96204	350
1.96091	340
1.95978	326
1.95866	342
1.95753	326
1.95641	344
1.95529	344
1.95417	340
1.95305	332
1.95193	350
1.95082	348
1.9497	352
1.94859	342
1.94748	332
1.94637	350
1.94526	344
1.94415	342
1.94305	350
1.94194	338
1.94084	350
1.93974	354
1.93864	352
1.93754	324
1.93644	316
1.93534	370
1.93425	334
1.93315	344
1.93206	338
1.93097	366
1.92988	348
1.92879	362
1.9277	342
1.92662	352
1.92553	342
1.92445	344.333
1.92337	361.08
1.92228	320.553
1.92121	370.518
1.92013	331.046
1.91905	335.767
1.91797	331.608
1.9169	350.556
1.91583	343.374
1.91475	342.573
1.91368	356.624
1.91261	347.874
1.91155	343.068
1.91048	353.174
1.90946	324
1.90839	340
1.90732	352
1.90626	332
1.90519	334
1.90413	346
1.90306	334
1.902	340
1.90094	326
1.89988	334
1.89882	362
1.89777	348
1.89671	314
1.89566	344
1.8946	348
1.89355	332
1.8925	318
1.89145	324
1.8904	316
1.88936	344
1.88831	340
1.88727	336
1.88622	340
1.88518	346
1.88414	342
1.8831	336
1.88206	338
1.88102	336
1.87999	340
1.87895	358
1.87792	314
1.87689	318
1.87586	338
1.87483	324
1.8738	330
1.87277	354
1.87174	312
1.87072	342
1.86969	330
1.86867	330
1.86765	316
1.86663	330
1.86561	336
1.86459	340
1.86357	318
1.86256	346
1.86154	318
1.86053	338
1.85952	336
1.85851	344
1.8575	312
1.85649	322
1.85548	320
1.85447	324
1.85347	328
1.85247	328
1.85146	324
1.85046	338
1.84946	328
1.84846	320
1.84746	332
1.84646	306
1.84547	306
1.84447	320
1.84348	318
1.84249	330
1.8415	322
1.84051	310
1.83952	298
1.83853	340
1.83754	318
1.83656	312
1.83557	310
1.83459	338
1.83361	314
1.83262	324
1.83164	308
1.83066	316
1.82969	312
1.82871	316
1.82773	292
1.82676	312
1.82579	304
1.82481	294
1.82384	278
1.82287	294
1.8219	292
1.82094	300
1.81997	306
1.819	316
1.81804	300
1.81708	298
1.81611	300
1.81515	296
1.81419	298
1.81323	286
1.81227	286
1.81132	310
1.81036	304
1.80941	268
1.80845	310
1.8075	296
1.80655	274
1.8056	302
1.80465	290
1.8037	284
1.80275	276
1.80181	288
1.80086	274
1.79992	278
1.79897	292
1.79803	282
1.79709	276
1.79615	274
1.79521	288
1.79428	262
1.79334	292
1.7924	290
1.79147	273.599
1.79053	267.702
1.7896	277.726
1.78867	272.326
1.78774	276.425
1.78681	273.822
1.78588	281.767
1.78496	272.069
1.78403	254.263
1.7831	274.27
1.78218	262.679
1.78126	257.733
1.78033	256.817
1.77941	257.704
1.77851	258
1.77759	252
1.77667	254
1.77575	254
1.77483	260
1.77391	224
1.77299	254
1.77207	250
1.77115	262
1.77024	258
1.76932	232
1.76841	246
1.7675	266
1.76659	248
1.76568	244
1.76477	238
1.76386	222
1.76295	240
1.76204	262
1.76114	236
1.76023	220
1.75933	240
1.75843	238
1.75753	250
1.75662	238
1.75572	240
1.75483	230
1.75393	238
1.75303	224
1.75214	232
1.75124	226
1.75035	230
1.74945	214
1.74856	236
1.74767	224
1.74678	228
1.74589	220
1.74501	232
1.74412	222
1.74323	220
1.74235	234
1.74146	204
1.74058	226
1.7397	230
1.73882	226
1.73794	202
1.73706	202
1.73618	198
1.7353	218
1.73443	216
1.73355	222
1.73268	196
1.7318	210
1.73093	218
1.73006	194
1.72919	204
1.72832	192
1.72745	202
1.72658	192
1.72571	220
1.72485	190
1.72398	184
1.72312	182
1.72225	202
1.72139	186
1.72053	196
1.71967	188
1.71881	194
1.71795	202
1.71709	200
1.71624	194
1.71538	190
1.71453	180
1.71367	178
1.71282	192
1.71197	200
1.71112	184
1.71027	174
1.70942	170
1.70857	172
1.70772	174
1.70687	154
1.70603	164
1.70518	164
1.70434	174
1.7035	182
1.70265	174
1.70181	176
1.70097	174
1.70013	176
1.69929	172
1.69846	170
1.69762	164
1.69678	156
1.69595	172
1.69511	168
1.69428	170
1.69345	154
1.69262	158
1.69179	166
1.69096	160
1.69013	148
1.6893	162
1.68847	146
1.68765	152
1.68682	164
1.686	140
1.68517	142
1.68435	136
1.68353	152
1.68271	150
1.68189	150
1.68107	134
1.68025	150
1.67943	138
1.67861	142
1.6778	130
1.67698	138.019
1.67617	138.095
1.67536	153.267
1.67454	131.03
1.67373	143.489
1.67292	136.621
1.67211	148.019
1.6713	134.65
1.6705	135.937
1.66969	132.808
1.66888	128.094
1.66808	137.126
1.66727	140.887
1.66647	139.547
1.66566	133.497
1.6649	128
1.66409	140
1.66329	134
1.66249	122
1.66168	132
1.66088	128
1.66008	126
1.65928	128
1.65848	130
1.65768	122
1.65688	134
1.65608	128
1.65529	126
1.65449	124
1.6537	120
1.6529	134
1.65211	130
1.65132	122
1.65053	130
1.64973	110
1.64894	114
1.64816	120
1.64737	124
1.64658	112
1.64579	116
1.64501	132
1.64422	120
1.64344	122
1.64265	118
1.64187	124
1.64109	120
1.64031	126
1.63953	112
1.63875	124
1.63797	116
1.63719	116
1.63642	112
1.63564	112
1.63486	122
1.63409	116
1.63331	102
1.63254	104
1.63177	108
1.631	104
1.63023	110
1.62946	102
1.62869	102
1.62792	106
1.62715	102
1.62639	102
1.62562	112
1.62485	104
1.62409	98
1.62333	112
1.62256	110
1.6218	98
1.62104	100
1.62028	102
1.61952	108
1.61876	92
1.618	100
1.61724	108
1.61649	108
1.61573	90
1.61498	98
1.61422	94
1.61347	100
1.61271	90
1.61196	102
1.61121	82
1.61046	94
1.60971	76
1.60896	98
1.60821	90
1.60747	84
1.60672	92
1.60597	84
1.60523	94
1.60448	80
1.60374	92
1.603	86
1.60225	92
1.60151	90
1.60077	78
1.60003	76
1.59929	84
1.59855	74
1.59782	78
1.59708	78
1.59634	84
1.59561	80
1.59487	78
1.59414	84
1.5934	80
1.59267	76
1.59194	80
1.59121	82
1.59048	84
1.58975	72
1.58902	74
1.58829	80
1.58756	78
1.58684	80
1.58611	78
1.58538	80
1.58466	76
1.58394	68
1.58321	66
1.58249	72
1.58177	70
1.58105	80
1.58033	72
1.57961	64
1.57889	70
1.57817	74
1.57745	84
1.57674	74
1.57602	71.9559
1.5753	67.4448
1.57459	77.296
1.57388	69.3211
1.57316	74.2674
1.57245	66.4851
1.57174	60.7314
1.57103	64.9522
1.57032	62.6795
1.56961	62.4118
1.5689	66.4281
1.56819	69.1473
1.56748	57.6098
1.56678	64.416
1.56607	59.6121
1.56544	56
1.56473	58
1.56402	54
1.56331	60
1.56261	64
1.5619	66
1.56119	60
1.56049	50
1.55979	62
1.55908	54
1.55838	50
1.55768	64
1.55698	56
1.55628	60
1.55558	54
1.55488	58
1.55418	58
1.55348	56
1.55278	60
1.55209	58
1.55139	62
1.5507	58
1.55	60
1.54931	52
1.54862	64
1.54792	50
1.54723	56
1.54654	58
1.54585	58
1.54516	56
1.54447	46
1.54378	60
1.5431	56
1.54241	50
1.54172	48
1.54104	46
1.54035	50
1.53967	46
1.53898	52
1.5383	44
1.53762	56
1.53694	52
1.53626	60
1.53558	46
1.5349	50
1.53422	48
1.53354	48
1.53286	54
1.53218	62
1.53151	56
1.53083	50
1.53016	48
1.52948	62
1.52881	42
1.52813	44
1.52746	52
1.52679	58
1.52612	54
1.52545	50
1.52478	40
1.52411	46
1.52344	52
1.52277	48
1.5221	46
1.52144	42
1.52077	46
1.52011	50
1.51944	44
1.51878	42
1.51811	46
1.51745	42
1.51679	48
1.51613	54
1.51547	38
1.51481	46
1.51415	44
1.51349	46
1.51283	54
1.51217	40
1.51151	42
1.51086	42
1.5102	36
1.50954	54
1.50889	52
1.50824	44
1.50758	46
1.50693	50
1.50628	40
1.50563	42
1.50497	46
1.50432	36
1.50367	42
1.50302	56
1.50238	46
1.50173	38
1.50108	50
1.50043	48
1.49979	38
1.49914	38
1.4985	32
1.49785	42
1.49721	42
1.49657	42
1.49592	44
1.49528	38
1.49464	46
1.494	50
1.49336	46
1.49272	38
1.49208	42
1.49144	44
1.49081	40
1.49017	44
1.48953	36
1.4889	32
1.48826	40
1.48763	46
1.48699	32.0198
1.48636	41.6447
1.48573	36.0646
1.4851	33.153
1.48446	36.6427
1.48383	37.3891
1.4832	38.7671
1.48257	33.1467
1.48194	38.6843
1.48132	34.7486
1.48069	33.8638
1.48006	33.8513
1.47943	31.1004
1.47881	38.7334
1.47818	32.5068
1.47756	32
1.47694	32
1.47631	34
1.47568	34
1.47505	36
1.47443	34
1.4738	38
1.47318	30
1.47256	36
1.47193	34
1.47131	30
1.47069	36
1.47006	40
1.46944	38
1.46882	38
1.4682	34
1.46758	34
1.46696	34
1.46635	28
1.46573	34
1.46511	30
1.46449	34
1.46388	34
1.46326	36
1.46265	32
1.46203	38
1.46142	38
1.46081	32
1.46019	32
1.45958	30
1.45897	32
1.45836	40
1.45775	32
1.45714	38
1.45653	32
1.45592	30
1.45531	28
1.4547	30
1.4541	28
1.45349	34
1.45288	30
1.45228	32
1.45167	30
1.45107	30
1.45047	28
1.44986	28
1.44926	34
1.44866	34
1.44806	34
1.44746	32
1.44686	30
1.44626	28
1.44566	30
1.44506	30
1.44446	24
1.44386	24
1.44326	30
1.44267	30
1.44207	42
1.44148	26
1.44088	30
1.44029	28
1.43969	34
1.4391	22
1.43851	26
1.43791	26
1.43732	28
1.43673	34
1.43614	22
1.43555	34
1.43496	30
1.43437	36
1.43378	32
1.4332	32
1.43261	32
1.43202	24
1.43143	26
1.43085	26
1.43026	32
1.42968	30
1.42909	22
1.42851	30
1.42793	26
1.42734	32
1.42676	24
1.42618	28
1.4256	30
1.42502	32
1.42444	24
1.42386	34
1.42328	32
1.4227	28
1.42212	26
1.42155	32
1.42097	28
1.42039	30
1.41982	32
1.41924	30
1.41867	34
1.41809	22
1.41752	30
1.41695	24
1.41637	30
1.4158	26
1.41523	30
1.41466	22
1.41409	24
1.41352	30
1.41295	26
1.41238	26
1.41181	32
1.41124	28
1.41067	28
1.41011	28
1.40954	24
1.40897	34
1.40841	32
1.40784	29.9811
1.40728	25.7301
1.40672	23.718
1.40615	30.7842
1.40559	29.0017
1.40503	30.0253
1.40446	51.1172
1.4039	28.5466
1.40334	30.0653
1.40278	25.8882
1.40222	27.8793
1.40166	30.3656
1.4011	28.0599
1.40054	31.5745
1.39999	32.9175
1.39947	30
1.3989	32
1.39834	36
1.39779	28
1.39723	30
1.39667	30
1.39611	32
1.39555	30
1.395	34
1.39444	42
1.39388	32
1.39333	28
1.39277	30
1.39222	28
1.39166	36
1.39111	26
1.39056	26
1.39	32
1.38945	28
1.3889	36
1.38835	36
1.3878	36
1.38725	30
1.3867	32
1.38615	32
1.3856	34
1.38505	36
1.3845	36
1.38396	28
1.38341	40
1.38286	30
1.38232	40
1.38177	32
1.38123	26
1.38068	36
1.38014	32
1.3796	36
1.37905	32
1.37851	30
1.37797	34
1.37743	36
1.37688	34
1.37634	30
1.3758	34
1.37526	30
1.37472	26
1.37419	22
1.37365	28
1.37311	34
1.37257	34
1.37204	26
1.3715	36
1.37096	32
1.37043	28
1.36989	40
1.36936	36
1.36882	30
1.36829	30
1.36776	32
1.36722	32
1.36669	32
1.36616	24
1.36563	34
1.3651	32
1.36457	30
1.36404	26
1.36351	36
1.36298	30
1.36245	32
1.36192	38
1.36139	30
1.36087	34
1.36034	28
1.35981	30
1.35929	26
1.35876	28
1.35824	24
1.35771	40
1.35719	26
1.35667	28
1.35614	24
1.35562	28
1.3551	24
1.35458	32
1.35406	32
1.35353	32
1.35301	32
1.35249	26
1.35197	26
1.35146	34
1.35094	30
1.35042	24
1.3499	34
1.34938	30
1.34887	22
1.34835	26
1.34783	26
1.34732	28
1.3468	34
1.34629	36
1.34578	28
1.34526	34
1.34475	30
1.34424	28
1.34372	26
1.34321	30
1.3427	26
1.34219	24
1.34168	34
1.34117	28
1.34066	22
1.34015	30
1.33964	30
1.33913	32
1.33862	28
1.33812	32
1.33761	32
1.3371	26.1988
1.3366	26.3012
1.33609	32.7365
1.33558	27.6331
1.33508	27.8755
1.33457	28.044
1.33407	29.1631
1.33357	26.8501
1.33306	29.5424
1.33256	29.6664
1.33206	27.6847
1.33156	33.5437
1.33105	31.1855
1.33055	25.7557
1.33005	28.2305
1.32959	28
1.32909	26
1.32859	20
1.32809	28
1.32758	22
1.32708	28
1.32658	34
1.32608	28
1.32558	32
1.32508	28
1.32458	34
1.32408	28
1.32358	30
1.32309	34
1.32259	32
1.32209	36
1.3216	32
1.3211	28
1.3206	26
1.32011	28
1.31961	32
1.31912	30
1.31862	26
1.31813	26
1.31764	38
1.31714	32
1.31665	28
1.31616	28
1.31567	36
1.31518	32
1.31468	36
1.31419	34
1.3137	28
1.31321	28
1.31272	32
1.31224	36
1.31175	28
1.31126	26
1.31077	34
1.31028	34
1.3098	42
1.30931	30
1.30882	26
1.30834	26
1.30785	42
1.30737	28
1.30688	24
1.3064	26
1.30592	30
1.30543	30
1.30495	34
1.30447	28
1.30399	30
1.3035	34
1.30302	32
1.30254	32
1.30206	30
1.30158	36
1.3011	30
1.30062	36
1.30014	28
1.30001	34