File: ploting_and_data_tools/raman/CdSe3_01.txt
#Acq. time (s)=	1
#Accumulations=	1
#Range (eV)=	2...1
#Windows=	11
#Autofocus=	Off
#AutoExposure=	Off
#Spike filter=	Off
#Delay time (s)=	0
#Binning=	1
#Readout mode=	Signal
#DeNoise=	Off
#ICS correction=	Off
#Dark correction=	Off
#Inst. Process=	Off
#Instrument=	LabRAM HR Evol
#Detector=	Syncerity OE
#Objective=	x100_VIS_LWD
#Grating=	600 (500nm)
#ND Filter=	1%
#Laser=	442nm_Notch
#Hole=	150.001
#Range=	Visible
#Project=	Paty
#Sample=
#Site=	15-06-22
#Title=	CdSe3
#Remark=
#Date=	15.06.2022 21:16
#Acquired=	15.06.2022 21:16:42
2.74975	36
2.7475	38
2.74525	42
2.743	34
2.74076	38
2.73852	32
2.73629	28
2.73406	36
2.73183	40
2.72961	40
2.72739	42
2.72517	44
2.72296	38
2.72075	38
2.71854	38
2.71634	38
2.71414	36
2.71195	28
2.70976	38
2.70757	36
2.70539	36
2.70321	46
2.70103	34
2.69886	36
2.69669	46
2.69452	36
2.69236	48
2.6902	44
2.68805	48
2.6859	46
2.68375	34
2.68161	46
2.67947	52
2.67733	42
2.6752	42
2.67307	48
2.67094	50
2.66882	48
2.6667	54
2.66458	54
2.66247	64
2.66036	60
2.65826	64
2.65615	66
2.65405	60
2.65196	56
2.64987	72
2.64778	70
2.64569	60
2.64361	72
2.64153	68
2.63946	66
2.63739	78
2.63532	68
2.63325	72
2.63119	80
2.62913	78
2.62708	78
2.62503	84
2.62298	86
2.62094	102
2.61889	106
2.61686	112
2.61482	98
2.61279	106
2.61076	106
2.60873	122
2.60671	120
2.60469	122
2.60268	118
2.60067	130
2.59866	136
2.59665	138
2.59465	146
2.59265	162
2.59065	156
2.58866	150
2.58667	160
2.58468	166
2.5827	166
2.58072	200
2.57874	198
2.57677	176
2.5748	212
2.57283	218
2.57086	226
2.5689	240
2.56694	246
2.56499	256
2.56304	298
2.56109	288
2.55914	284
2.5572	342
2.55526	302
2.55332	314
2.55139	358
2.54946	366
2.54753	396
2.5456	386
2.54368	402
2.54176	424
2.53985	432
2.53794	454
2.53603	504
2.53412	520
2.53222	498
2.53031	556
2.52842	562
2.52652	596
2.52463	630
2.52274	632
2.52085	642
2.51897	678
2.51709	748
2.51521	754
2.51334	758
2.51147	830
2.5096	810
2.50773	864
2.50587	894
2.50401	908
2.50216	962
2.5003	962
2.49845	1042
2.4966	1026
2.49476	1100
2.49291	1168
2.49107	1140
2.48924	1220
2.4874	1220
2.48557	1288
2.48374	1300
2.48192	1367.87
2.48009	1407.55
2.47827	1475.41
2.47646	1488.68
2.47464	1519.54
2.47283	1584.53
2.47102	1623.89
2.46922	1651.54
2.46741	1731.54
2.46561	1769.6
2.46381	1833.76
2.46202	1870.59
2.46023	1964.97
2.45844	1961.34
2.45665	2050.25
2.45493	2078
2.45314	2192
2.45136	2178
2.44957	2234
2.44779	2306
2.44601	2348
2.44424	2328
2.44247	2492
2.4407	2462
2.43893	2498
2.43716	2570
2.4354	2590
2.43364	2628
2.43188	2766
2.43013	2740
2.42838	2814
2.42663	2830
2.42488	2942
2.42314	2946
2.4214	3002
2.41966	2952
2.41792	3048
2.41619	3054
2.41446	3092
2.41273	3148
2.411	3236
2.40928	3202
2.40756	3294
2.40584	3208
2.40413	3252
2.40241	3298
2.4007	3314
2.39899	3414
2.39729	3398
2.39559	3466
2.39389	3476
2.39219	3410
2.39049	3488
2.3888	3496
2.38711	3512
2.38542	3512
2.38374	3532
2.38205	3586
2.38037	3472
2.37869	3524
2.37702	3504
2.37535	3570
2.37368	3586
2.37201	3572
2.37034	3542
2.36868	3626
2.36702	3556
2.36536	3544
2.3637	3514
2.36205	3492
2.3604	3454
2.35875	3448
2.3571	3444
2.35546	3452
2.35382	3304
2.35218	3380
2.35054	3406
2.34891	3258
2.34727	3224
2.34564	3214
2.34402	3254
2.34239	3214
2.34077	3146
2.33915	3160
2.33753	3136
2.33591	3046
2.3343	2976
2.33269	3016
2.33108	2930
2.32948	2912
2.32787	2882
2.32627	2948
2.32467	2854
2.32307	2816
2.32148	2700
2.31989	2796
2.3183	2666
2.31671	2664
2.31512	2678
2.31354	2616
2.31196	2624
2.31038	2610
2.3088	2566
2.30723	2626
2.30565	2510
2.30408	2492
2.30252	2524
2.30095	2426
2.29939	2464
2.29783	2386
2.29627	2378
2.29471	2324
2.29316	2354
2.29161	2264
2.29006	2274
2.28851	2288
2.28696	2286
2.28542	2274
2.28388	2246
2.28234	2234
2.2808	2218
2.27927	2226
2.27773	2222
2.2762	2186
2.27468	2168
2.27315	2164
2.27163	2158
2.27011	2126
2.26859	2112
2.26707	2140
2.26555	2094
2.26404	2118
2.26253	2161.38
2.26102	2081.71
2.25951	2044.87
2.25801	2025.77
2.25651	2010.36
2.25501	2012.02
2.25351	1970.23
2.25201	1928.44
2.25052	1883.07
2.24902	1875.08
2.24753	1866.5
2.24605	1847.51
2.24456	1845.5
2.24308	1803
2.2416	1771.2
2.24011	1726
2.23863	1758
2.23715	1750
2.23567	1746
2.23419	1758
2.23271	1730
2.23124	1716
2.22977	1700
2.2283	1652
2.22683	1752
2.22536	1684
2.2239	1652
2.22244	1692
2.22098	1664
2.21952	1662
2.21807	1688
2.21661	1688
2.21516	1686
2.21371	1654
2.21226	1688
2.21082	1630
2.20937	1642
2.20793	1726
2.20649	1668
2.20505	1682
2.20362	1680
2.20218	1696
2.20075	1626
2.19932	1682
2.19789	1640
2.19647	1684
2.19504	1660
2.19362	1648
2.1922	1664
2.19078	1718
2.18936	1682
2.18795	1676
2.18654	1696
2.18513	1670
2.18372	1642
2.18231	1660
2.18091	1710
2.1795	1692
2.1781	1684
2.1767	1698
2.1753	1668
2.17391	1700
2.17251	1676
2.17112	1744
2.16973	1678
2.16834	1690
2.16696	1706
2.16557	1692
2.16419	1732
2.16281	1708
2.16143	1774
2.16005	1762
2.15868	1784
2.1573	1778
2.15593	1772
2.15456	1768
2.1532	1812
2.15183	1764
2.15046	1794
2.1491	1744
2.14774	1806
2.14638	1808
2.14503	1826
2.14367	1858
2.14232	1808
2.14097	1824
2.13962	1808
2.13827	1784
2.13692	1850
2.13558	1872
2.13423	1826
2.13289	1806
2.13155	1856
2.13022	1844
2.12888	1846
2.12755	1838
2.12621	1878
2.12488	1904
2.12356	1864
2.12223	1892
2.1209	1918
2.11958	1944
2.11826	1854
2.11694	1922
2.11562	1852
2.1143	1922
2.11299	1868
2.11168	1872
2.11037	1928
2.10906	1924
2.10775	1916
2.10644	1882
2.10514	1968
2.10384	1952
2.10253	1940
2.10123	1928
2.09994	1904
2.09864	1914
2.09735	1948
2.09605	1960
2.09476	1944
2.09347	1984
2.09219	1998
2.0909	1884
2.08962	1930
2.08834	1992
2.08705	1960
2.08578	1966
2.0845	1958
2.08322	2052
2.08195	1970
2.08068	1992
2.0794	1960.8
2.07814	1985.67
2.07687	1951.89
2.0756	1956.47
2.07434	1917.52
2.07307	1902.69
2.07181	1865.05
2.07055	1886.26
2.0693	1868.83
2.06804	1824.18
2.06679	1878.08
2.06553	1799.88
2.06428	1835.05
2.06303	1822.55
2.06178	1811.77
2.06069	1774
2.05944	1746
2.05819	1816
2.05694	1764
2.05569	1794
2.05445	1788
2.05321	1794
2.05196	1768
2.05072	1824
2.04949	1832
2.04825	1768
2.04701	1742
2.04578	1718
2.04455	1750
2.04332	1782
2.04209	1718
2.04086	1730
2.03964	1746
2.03841	1766
2.03719	1722
2.03597	1710
2.03475	1698
2.03353	1750
2.03232	1730
2.0311	1746
2.02989	1728
2.02868	1678
2.02747	1764
2.02626	1754
2.02505	1740
2.02384	1814
2.02264	1772
2.02144	1752
2.02024	1736
2.01904	1758
2.01784	1772
2.01664	1782
2.01544	1782
2.01425	1824
2.01306	1814
2.01187	1794
2.01068	1802
2.00949	1810
2.0083	1798
2.00712	1844
2.00594	1806
2.00475	1776
2.00357	1826
2.0024	1854
2.00122	1860
2.00004	1894
1.99887	1908
1.99769	1922
1.99652	1904
1.99535	1944
1.99418	1894
1.99302	1894
1.99185	1948
1.99069	1940
1.98952	1976
1.98836	1948
1.9872	1930
1.98604	1968
1.98488	1982
1.98373	1946
1.98257	1974
1.98142	1982
1.98027	1964
1.97912	1996
1.97797	1994
1.97682	1992
1.97568	2020
1.97453	1998
1.97339	2054
1.97225	1982
1.97111	1994
1.96997	2016
1.96883	2020
1.9677	1958
1.96656	2026
1.96543	2016
1.9643	2036
1.96316	2060
1.96204	2076
1.96091	2064
1.95978	2068
1.95866	2034
1.95753	2028
1.95641	2008
1.95529	2064
1.95417	2054
1.95305	2014
1.95193	2038
1.95082	2076
1.9497	2076
1.94859	2048
1.94748	2016
1.94637	2108
1.94526	2046
1.94415	2050
1.94305	1978
1.94194	2076
1.94084	2124
1.93974	2038
1.93864	2038
1.93754	2032
1.93644	2032
1.93534	2034
1.93425	2098
1.93315	2082
1.93206	2042
1.93097	2048
1.92988	2056
1.92879	2064
1.9277	2056
1.92662	2096
1.92553	2028
1.92445	1973.89
1.92337	2030.49
1.92228	2024.78
1.92121	1986.95
1.92013	1985.73
1.91905	1964.6
1.91797	1980.37
1.9169	1937.27
1.91583	1967.48
1.91475	1962.37
1.91368	1944.68
1.91261	1920.65
1.91155	1921.24
1.91048	1892.07
1.90946	1918
1.90839	1898
1.90732	1880
1.90626	1854
1.90519	1854
1.90413	1874
1.90306	1888
1.902	1886
1.90094	1854
1.89988	1862
1.89882	1860
1.89777	1916
1.89671	1896
1.89566	1806
1.8946	1956
1.89355	1860
1.8925	1888
1.89145	1880
1.8904	1860
1.88936	1876
1.88831	1868
1.88727	1824
1.88622	1882
1.88518	1850
1.88414	1814
1.8831	1842
1.88206	1840
1.88102	1810
1.87999	1840
1.87895	1862
1.87792	1848
1.87689	1822
1.87586	1780
1.87483	1814
1.8738	1840
1.87277	1820
1.87174	1798
1.87072	1848
1.86969	1826
1.86867	1768
1.86765	1774
1.86663	1764
1.86561	1814
1.86459	1764
1.86357	1768
1.86256	1778
1.86154	1766
1.86053	1752
1.85952	1692
1.85851	1718
1.8575	1778
1.85649	1736
1.85548	1768
1.85447	1764
1.85347	1714
1.85247	1742
1.85146	1752
1.85046	1722
1.84946	1712
1.84846	1768
1.84746	1730
1.84646	1716
1.84547	1716
1.84447	1692
1.84348	1696
1.84249	1704
1.8415	1682
1.84051	1738
1.83952	1684
1.83853	1640
1.83754	1704
1.83656	1682
1.83557	1678
1.83459	1646
1.83361	1656
1.83262	1646
1.83164	1630
1.83066	1606
1.82969	1690
1.82871	1646
1.82773	1630
1.82676	1612
1.82579	1658
1.82481	1622
1.82384	1632
1.82287	1636
1.8219	1576
1.82094	1552
1.81997	1584
1.819	1642
1.81804	1586
1.81708	1572
1.81611	1636
1.81515	1646
1.81419	1642
1.81323	1584
1.81227	1580
1.81132	1528
1.81036	1558
1.80941	1562
1.80845	1548
1.8075	1566
1.80655	1526
1.8056	1554
1.80465	1554
1.8037	1558
1.80275	1560
1.80181	1520
1.80086	1536
1.79992	1560
1.79897	1536
1.79803	1476
1.79709	1500
1.79615	1500
1.79521	1504
1.79428	1498
1.79334	1484
1.7924	1482
1.79147	1485.64
1.79053	1449.59
1.7896	1446.64
1.78867	1433.77
1.78774	1408.31
1.78681	1409.24
1.78588	1418.54
1.78496	1397.41
1.78403	1369.45
1.7831	1391.94
1.78218	1362.55
1.78126	1347.65
1.78033	1338.26
1.77941	1351.24
1.77851	1370
1.77759	1324
1.77667	1334
1.77575	1332
1.77483	1298
1.77391	1358
1.77299	1298
1.77207	1250
1.77115	1304
1.77024	1262
1.76932	1272
1.76841	1272
1.7675	1286
1.76659	1260
1.76568	1282
1.76477	1292
1.76386	1234
1.76295	1262
1.76204	1220
1.76114	1196
1.76023	1188
1.75933	1222
1.75843	1234
1.75753	1182
1.75662	1178
1.75572	1236
1.75483	1172
1.75393	1198
1.75303	1194
1.75214	1160
1.75124	1186
1.75035	1182
1.74945	1128
1.74856	1182
1.74767	1158
1.74678	1154
1.74589	1120
1.74501	1074
1.74412	1118
1.74323	1066
1.74235	1114
1.74146	1126
1.74058	1078
1.7397	1084
1.73882	1080
1.73794	1088
1.73706	1074
1.73618	1102
1.7353	1028
1.73443	1064
1.73355	1042
1.73268	1060
1.7318	1068
1.73093	1028
1.73006	1044
1.72919	994
1.72832	994
1.72745	1004
1.72658	984
1.72571	1012
1.72485	970
1.72398	966
1.72312	982
1.72225	954
1.72139	948
1.72053	956
1.71967	932
1.71881	950
1.71795	952
1.71709	900
1.71624	918
1.71538	886
1.71453	918
1.71367	906
1.71282	888
1.71197	864
1.71112	838
1.71027	852
1.70942	918
1.70857	858
1.70772	886
1.70687	852
1.70603	830
1.70518	838
1.70434	844
1.7035	856
1.70265	832
1.70181	780
1.70097	798
1.70013	824
1.69929	798
1.69846	778
1.69762	798
1.69678	782
1.69595	804
1.69511	786
1.69428	766
1.69345	754
1.69262	740
1.69179	746
1.69096	718
1.69013	720
1.6893	704
1.68847	734
1.68765	730
1.68682	726
1.686	688
1.68517	706
1.68435	684
1.68353	720
1.68271	724
1.68189	690
1.68107	648
1.68025	700
1.67943	670
1.67861	686
1.6778	682
1.67698	677.874
1.67617	662.154
1.67536	667.218
1.67454	685.691
1.67373	656.4
1.67292	656.443
1.67211	646.538
1.6713	649.97
1.6705	630.904
1.66969	640.023
1.66888	643.203
1.66808	644.629
1.66727	617.171
1.66647	610.676
1.66566	605.172
1.6649	604
1.66409	616
1.66329	572
1.66249	610
1.66168	608
1.66088	620
1.66008	572
1.65928	568
1.65848	582
1.65768	604
1.65688	568
1.65608	590
1.65529	580
1.65449	562
1.6537	540
1.6529	574
1.65211	554
1.65132	554
1.65053	560
1.64973	550
1.64894	568
1.64816	516
1.64737	536
1.64658	518
1.64579	520
1.64501	494
1.64422	530
1.64344	526
1.64265	520
1.64187	528
1.64109	480
1.64031	478
1.63953	508
1.63875	492
1.63797	500
1.63719	480
1.63642	496
1.63564	468
1.63486	470
1.63409	492
1.63331	486
1.63254	472
1.63177	456
1.631	468
1.63023	446
1.62946	436
1.62869	426
1.62792	464
1.62715	440
1.62639	438
1.62562	444
1.62485	422
1.62409	410
1.62333	436
1.62256	408
1.6218	438
1.62104	404
1.62028	422
1.61952	380
1.61876	418
1.618	404
1.61724	398
1.61649	402
1.61573	384
1.61498	402
1.61422	370
1.61347	384
1.61271	388
1.61196	356
1.61121	364
1.61046	380
1.60971	370
1.60896	368
1.60821	338
1.60747	382
1.60672	360
1.60597	362
1.60523	348
1.60448	328
1.60374	366
1.603	342
1.60225	346
1.60151	334
1.60077	346
1.60003	326
1.59929	330
1.59855	320
1.59782	342
1.59708	306
1.59634	298
1.59561	334
1.59487	300
1.59414	314
1.5934	306
1.59267	306
1.59194	310
1.59121	294
1.59048	306
1.58975	308
1.58902	288
1.58829	290
1.58756	290
1.58684	280
1.58611	300
1.58538	286
1.58466	286
1.58394	280
1.58321	282
1.58249	264
1.58177	284
1.58105	272
1.58033	282
1.57961	266
1.57889	268
1.57817	278
1.57745	262
1.57674	264
1.57602	251.97
1.5753	248.887
1.57459	250.903
1.57388	243.867
1.57316	231.079
1.57245	245.589
1.57174	231.667
1.57103	231.177
1.57032	233.539
1.56961	224.972
1.5689	222.27
1.56819	219.15
1.56748	197.348
1.56678	210.116
1.56607	208.802
1.56544	204
1.56473	202
1.56402	216
1.56331	224
1.56261	196
1.5619	190
1.56119	194
1.56049	202
1.55979	192
1.55908	178
1.55838	190
1.55768	182
1.55698	184
1.55628	166
1.55558	212
1.55488	184
1.55418	196
1.55348	184
1.55278	176
1.55209	178
1.55139	188
1.5507	184
1.55	172
1.54931	186
1.54862	168
1.54792	164
1.54723	162
1.54654	158
1.54585	168
1.54516	170
1.54447	148
1.54378	160
1.5431	160
1.54241	156
1.54172	152
1.54104	158
1.54035	148
1.53967	148
1.53898	152
1.5383	152
1.53762	156
1.53694	136
1.53626	152
1.53558	156
1.5349	168
1.53422	140
1.53354	142
1.53286	152
1.53218	144
1.53151	148
1.53083	136
1.53016	138
1.52948	150
1.52881	144
1.52813	150
1.52746	138
1.52679	134
1.52612	138
1.52545	144
1.52478	138
1.52411	134
1.52344	126
1.52277	134
1.5221	126
1.52144	128
1.52077	134
1.52011	112
1.51944	138
1.51878	130
1.51811	112
1.51745	112
1.51679	130
1.51613	120
1.51547	118
1.51481	118
1.51415	128
1.51349	110
1.51283	126
1.51217	118
1.51151	110
1.51086	122
1.5102	108
1.50954	108
1.50889	114
1.50824	114
1.50758	124
1.50693	102
1.50628	102
1.50563	110
1.50497	84
1.50432	110
1.50367	100
1.50302	100
1.50238	114
1.50173	116
1.50108	108
1.50043	106
1.49979	100
1.49914	98
1.4985	98
1.49785	92
1.49721	100
1.49657	104
1.49592	96
1.49528	102
1.49464	100
1.494	92
1.49336	84
1.49272	100
1.49208	90
1.49144	90
1.49081	84
1.49017	90
1.48953	92
1.4889	86
1.48826	86
1.48763	74
1.48699	91.901
1.48636	80.3487
1.48573	85.3145
1.4851	84.3682
1.48446	85.0896
1.48383	84.3678
1.4832	77.4486
1.48257	80.5733
1.48194	77.3014
1.48132	74.1411
1.48069	78.6792
1.48006	83.609
1.47943	77.1004
1.47881	84.1786
1.47818	73.2352
1.47756	74
1.47694	70
1.47631	64
1.47568	70
1.47505	68
1.47443	76
1.4738	76
1.47318	66
1.47256	78
1.47193	80
1.47131	58
1.47069	76
1.47006	60
1.46944	64
1.46882	60
1.4682	64
1.46758	64
1.46696	70
1.46635	68
1.46573	58
1.46511	60
1.46449	58
1.46388	60
1.46326	60
1.46265	56
1.46203	70
1.46142	72
1.46081	54
1.46019	44
1.45958	38
1.45897	52
1.45836	48
1.45775	54
1.45714	56
1.45653	52
1.45592	54
1.45531	40
1.4547	46
1.4541	30
1.45349	48
1.45288	50
1.45228	44
1.45167	36
1.45107	24
1.45047	26
1.44986	30
1.44926	30
1.44866	22
1.44806	30
1.44746	34
1.44686	28
1.44626	34
1.44566	32
1.44506	36
1.44446	30
1.44386	26
1.44326	36
1.44267	28
1.44207	30
1.44148	26
1.44088	28
1.44029	32
1.43969	34
1.4391	30
1.43851	24
1.43791	26
1.43732	30
1.43673	30
1.43614	30
1.43555	30
1.43496	26
1.43437	32
1.43378	30
1.4332	28
1.43261	26
1.43202	30
1.43143	34
1.43085	22
1.43026	24
1.42968	26
1.42909	36
1.42851	26
1.42793	28
1.42734	26
1.42676	28
1.42618	30
1.4256	28
1.42502	20
1.42444	20
1.42386	28
1.42328	30
1.4227	38
1.42212	28
1.42155	34
1.42097	30
1.42039	28
1.41982	32
1.41924	26
1.41867	24
1.41809	26
1.41752	26
1.41695	30
1.41637	28
1.4158	34
1.41523	24
1.41466	34
1.41409	32
1.41352	28
1.41295	24
1.41238	28
1.41181	28
1.41124	32
1.41067	22
1.41011	28
1.40954	30
1.40897	40
1.40841	32
1.40784	28
1.40728	38.1281
1.40672	34.0052
1.40615	45.8406
1.40559	35.7766
1.40503	46.9624
1.40446	138.872
1.4039	44.4289
1.40334	43.4904
1.40278	38.6902
1.40222	40.7784
1.40166	47.2522
1.4011	46.0599
1.40054	46
1.39999	43.2641
1.39947	46
1.3989	44
1.39834	48
1.39779	52
1.39723	48
1.39667	44
1.39611	40
1.39555	38
1.395	44
1.39444	50
1.39388	52
1.39333	46
1.39277	40
1.39222	40
1.39166	48
1.39111	42
1.39056	42
1.39	48
1.38945	54
1.3889	54
1.38835	48
1.3878	46
1.38725	48
1.3867	44
1.38615	38
1.3856	52
1.38505	36
1.3845	48
1.38396	38
1.38341	40
1.38286	44
1.38232	40
1.38177	40
1.38123	44
1.38068	48
1.38014	42
1.3796	38
1.37905	42
1.37851	36
1.37797	42
1.37743	42
1.37688	34
1.37634	36
1.3758	42
1.37526	40
1.37472	44
1.37419	46
1.37365	48
1.37311	44
1.37257	44
1.37204	42
1.3715	42
1.37096	38
1.37043	38
1.36989	48
1.36936	48
1.36882	34
1.36829	36
1.36776	46
1.36722	44
1.36669	42
1.36616	40
1.36563	46
1.3651	38
1.36457	42
1.36404	46
1.36351	38
1.36298	42
1.36245	46
1.36192	38
1.36139	42
1.36087	34
1.36034	42
1.35981	44
1.35929	42
1.35876	44
1.35824	46
1.35771	38
1.35719	48
1.35667	46
1.35614	36
1.35562	42
1.3551	34
1.35458	48
1.35406	44
1.35353	40
1.35301	36
1.35249	42
1.35197	36
1.35146	38
1.35094	42
1.35042	40
1.3499	32
1.34938	36
1.34887	42
1.34835	44
1.34783	42
1.34732	34
1.3468	38
1.34629	40
1.34578	34
1.34526	32
1.34475	32
1.34424	40
1.34372	42
1.34321	32
1.3427	44
1.34219	38
1.34168	42
1.34117	46
1.34066	34
1.34015	38
1.33964	36
1.33913	28
1.33862	36
1.33812	32
1.33761	40
1.3371	32.1127
1.3366	41.9323
1.33609	27.4222
1.33558	25.1495
1.33508	32.9144
1.33457	32.7105
1.33407	33.7339
1.33357	31.075
1.33306	30.8667
1.33256	39.2718
1.33206	31.9463
1.33156	33.9338
1.33105	35.8533
1.33055	34.8575
1.33005	33.1224
1.32959	36
1.32909	42
1.32859	30
1.32809	40
1.32758	44
1.32708	32
1.32658	28
1.32608	40
1.32558	30
1.32508	32
1.32458	36
1.32408	40
1.32358	42
1.32309	34
1.32259	44
1.32209	34
1.3216	24
1.3211	38
1.3206	36
1.32011	40
1.31961	22
1.31912	40
1.31862	38
1.31813	36
1.31764	34
1.31714	30
1.31665	38
1.31616	34
1.31567	40
1.31518	36
1.31468	32
1.31419	38
1.3137	34
1.31321	40
1.31272	28
1.31224	34
1.31175	42
1.31126	30
1.31077	34
1.31028	32
1.3098	30
1.30931	40
1.30882	44
1.30834	46
1.30785	40
1.30737	38
1.30688	32
1.3064	38
1.30592	44
1.30543	32
1.30495	34
1.30447	34
1.30399	36
1.3035	40
1.30302	34
1.30254	44
1.30206	36
1.30158	36
1.3011	38
1.30062	30
1.30014	36
1.30001	40