File: ploting_and_data_tools/raman/CdSe3_03.txt
#Acq. time (s)=	1
#Accumulations=	1
#Range (eV)=	2...1
#Windows=	11
#Autofocus=	Off
#AutoExposure=	Off
#Spike filter=	Off
#Delay time (s)=	0
#Binning=	1
#Readout mode=	Signal
#DeNoise=	Off
#ICS correction=	Off
#Dark correction=	Off
#Inst. Process=	Off
#Instrument=	LabRAM HR Evol
#Detector=	Syncerity OE
#Objective=	x100_VIS_LWD
#Grating=	600 (500nm)
#ND Filter=	1%
#Laser=	442nm_Notch
#Hole=	150.001
#Range=	Visible
#Project=	Paty
#Sample=
#Site=	15-06-22
#Title=	CdSe3
#Remark=
#Date=	15.06.2022 21:21
#Acquired=	15.06.2022 21:21:47
2.74975	30
2.7475	32
2.74525	34
2.743	32
2.74076	34
2.73852	30
2.73629	28
2.73406	32
2.73183	30
2.72961	30
2.72739	26
2.72517	32
2.72296	32
2.72075	28
2.71854	36
2.71634	26
2.71414	32
2.71195	42
2.70976	32
2.70757	32
2.70539	34
2.70321	36
2.70103	32
2.69886	36
2.69669	38
2.69452	34
2.69236	36
2.6902	32
2.68805	40
2.6859	32
2.68375	34
2.68161	28
2.67947	38
2.67733	30
2.6752	38
2.67307	44
2.67094	38
2.66882	40
2.6667	34
2.66458	44
2.66247	42
2.66036	38
2.65826	36
2.65615	40
2.65405	40
2.65196	44
2.64987	38
2.64778	48
2.64569	40
2.64361	50
2.64153	50
2.63946	52
2.63739	50
2.63532	46
2.63325	48
2.63119	50
2.62913	54
2.62708	52
2.62503	48
2.62298	52
2.62094	64
2.61889	66
2.61686	58
2.61482	58
2.61279	56
2.61076	66
2.60873	54
2.60671	66
2.60469	64
2.60268	66
2.60067	82
2.59866	74
2.59665	74
2.59465	82
2.59265	82
2.59065	76
2.58866	92
2.58667	74
2.58468	88
2.5827	90
2.58072	96
2.57874	88
2.57677	92
2.5748	114
2.57283	106
2.57086	108
2.5689	112
2.56694	114
2.56499	118
2.56304	142
2.56109	138
2.55914	124
2.5572	140
2.55526	148
2.55332	152
2.55139	152
2.54946	134
2.54753	160
2.5456	180
2.54368	186
2.54176	196
2.53985	178
2.53794	196
2.53603	208
2.53412	222
2.53222	224
2.53031	222
2.52842	236
2.52652	256
2.52463	248
2.52274	266
2.52085	254
2.51897	262
2.51709	272
2.51521	296
2.51334	298
2.51147	314
2.5096	336
2.50773	312
2.50587	366
2.50401	364
2.50216	368
2.5003	364
2.49845	386
2.4966	406
2.49476	412
2.49291	418
2.49107	440
2.48924	446
2.4874	482
2.48557	498
2.48374	478
2.48192	503.6
2.48009	479.431
2.47827	527.035
2.47646	533.128
2.47464	526.727
2.47283	544.285
2.47102	580.447
2.46922	604.559
2.46741	597.91
2.46561	617.439
2.46381	619.171
2.46202	654.145
2.46023	669.031
2.45844	648.898
2.45665	669.418
2.45493	698
2.45314	708
2.45136	740
2.44957	742
2.44779	748
2.44601	752
2.44424	746
2.44247	746
2.4407	774
2.43893	800
2.43716	800
2.4354	780
2.43364	866
2.43188	862
2.43013	870
2.42838	868
2.42663	860
2.42488	924
2.42314	904
2.4214	928
2.41966	894
2.41792	886
2.41619	936
2.41446	914
2.41273	922
2.411	940
2.40928	944
2.40756	956
2.40584	940
2.40413	938
2.40241	932
2.4007	928
2.39899	944
2.39729	934
2.39559	944
2.39389	998
2.39219	960
2.39049	936
2.3888	940
2.38711	942
2.38542	968
2.38374	954
2.38205	952
2.38037	940
2.37869	910
2.37702	946
2.37535	926
2.37368	930
2.37201	918
2.37034	914
2.36868	900
2.36702	888
2.36536	862
2.3637	934
2.36205	838
2.3604	894
2.35875	864
2.3571	854
2.35546	842
2.35382	814
2.35218	822
2.35054	794
2.34891	796
2.34727	818
2.34564	792
2.34402	752
2.34239	760
2.34077	718
2.33915	758
2.33753	734
2.33591	728
2.3343	680
2.33269	670
2.33108	670
2.32948	688
2.32787	672
2.32627	644
2.32467	618
2.32307	622
2.32148	640
2.31989	626
2.3183	582
2.31671	578
2.31512	594
2.31354	602
2.31196	566
2.31038	550
2.3088	558
2.30723	538
2.30565	564
2.30408	532
2.30252	502
2.30095	510
2.29939	510
2.29783	510
2.29627	516
2.29471	500
2.29316	500
2.29161	504
2.29006	522
2.28851	490
2.28696	460
2.28542	492
2.28388	472
2.28234	470
2.2808	490
2.27927	462
2.27773	444
2.2762	456
2.27468	440
2.27315	438
2.27163	436
2.27011	446
2.26859	444
2.26707	440
2.26555	406
2.26404	422
2.26253	419.476
2.26102	423.444
2.25951	430.033
2.25801	412.011
2.25651	422.28
2.25501	410.592
2.25351	399.439
2.25201	400.843
2.25052	402.38
2.24902	388.419
2.24753	388.463
2.24605	381.391
2.24456	357.384
2.24308	370.755
2.2416	365.853
2.24011	350
2.23863	368
2.23715	376
2.23567	338
2.23419	366
2.23271	324
2.23124	342
2.22977	354
2.2283	350
2.22683	350
2.22536	334
2.2239	350
2.22244	336
2.22098	330
2.21952	342
2.21807	342
2.21661	340
2.21516	336
2.21371	332
2.21226	326
2.21082	332
2.20937	330
2.20793	324
2.20649	332
2.20505	330
2.20362	326
2.20218	340
2.20075	320
2.19932	324
2.19789	334
2.19647	344
2.19504	326
2.19362	326
2.1922	330
2.19078	324
2.18936	334
2.18795	328
2.18654	338
2.18513	316
2.18372	320
2.18231	332
2.18091	302
2.1795	304
2.1781	320
2.1767	334
2.1753	312
2.17391	326
2.17251	306
2.17112	312
2.16973	312
2.16834	332
2.16696	326
2.16557	314
2.16419	328
2.16281	328
2.16143	322
2.16005	326
2.15868	328
2.1573	306
2.15593	328
2.15456	342
2.1532	360
2.15183	316
2.15046	336
2.1491	324
2.14774	336
2.14638	328
2.14503	318
2.14367	326
2.14232	350
2.14097	336
2.13962	332
2.13827	332
2.13692	318
2.13558	308
2.13423	310
2.13289	356
2.13155	354
2.13022	340
2.12888	352
2.12755	316
2.12621	342
2.12488	328
2.12356	324
2.12223	338
2.1209	342
2.11958	370
2.11826	342
2.11694	344
2.11562	330
2.1143	332
2.11299	356
2.11168	344
2.11037	340
2.10906	342
2.10775	338
2.10644	330
2.10514	348
2.10384	326
2.10253	360
2.10123	376
2.09994	328
2.09864	354
2.09735	342
2.09605	340
2.09476	326
2.09347	344
2.09219	338
2.0909	350
2.08962	346
2.08834	356
2.08705	322
2.08578	356
2.0845	344
2.08322	356
2.08195	356
2.08068	332
2.0794	328.915
2.07814	331.653
2.07687	329.339
2.0756	315.52
2.07434	324.773
2.07307	326.268
2.07181	314.963
2.07055	334.27
2.0693	318.325
2.06804	320.673
2.06679	302.357
2.06553	310.28
2.06428	323.745
2.06303	307.817
2.06178	319.364
2.06069	304
2.05944	304
2.05819	312
2.05694	314
2.05569	322
2.05445	288
2.05321	318
2.05196	320
2.05072	330
2.04949	298
2.04825	316
2.04701	330
2.04578	312
2.04455	308
2.04332	324
2.04209	302
2.04086	298
2.03964	320
2.03841	284
2.03719	320
2.03597	302
2.03475	292
2.03353	296
2.03232	276
2.0311	300
2.02989	326
2.02868	292
2.02747	294
2.02626	290
2.02505	284
2.02384	312
2.02264	304
2.02144	304
2.02024	296
2.01904	322
2.01784	288
2.01664	304
2.01544	294
2.01425	308
2.01306	304
2.01187	324
2.01068	282
2.00949	302
2.0083	320
2.00712	334
2.00594	300
2.00475	312
2.00357	302
2.0024	300
2.00122	284
2.00004	326
1.99887	314
1.99769	334
1.99652	332
1.99535	306
1.99418	324
1.99302	324
1.99185	332
1.99069	320
1.98952	314
1.98836	328
1.9872	328
1.98604	326
1.98488	330
1.98373	330
1.98257	326
1.98142	322
1.98027	332
1.97912	310
1.97797	348
1.97682	332
1.97568	328
1.97453	348
1.97339	324
1.97225	348
1.97111	322
1.96997	322
1.96883	322
1.9677	354
1.96656	334
1.96543	340
1.9643	358
1.96316	332
1.96204	316
1.96091	328
1.95978	356
1.95866	352
1.95753	356
1.95641	336
1.95529	326
1.95417	322
1.95305	330
1.95193	334
1.95082	348
1.9497	340
1.94859	324
1.94748	338
1.94637	332
1.94526	334
1.94415	332
1.94305	338
1.94194	360
1.94084	320
1.93974	336
1.93864	324
1.93754	312
1.93644	318
1.93534	328
1.93425	328
1.93315	332
1.93206	320
1.93097	322
1.92988	332
1.92879	328
1.9277	324
1.92662	322
1.92553	318
1.92445	307.976
1.92337	324.491
1.92228	317.872
1.92121	323
1.92013	318.814
1.91905	332.826
1.91797	301.224
1.9169	312.721
1.91583	315.213
1.91475	313.527
1.91368	325.075
1.91261	333.76
1.91155	308.928
1.91048	315.464
1.90946	302
1.90839	298
1.90732	308
1.90626	298
1.90519	320
1.90413	304
1.90306	300
1.902	310
1.90094	314
1.89988	312
1.89882	316
1.89777	314
1.89671	292
1.89566	296
1.8946	310
1.89355	294
1.8925	292
1.89145	310
1.8904	308
1.88936	312
1.88831	320
1.88727	302
1.88622	292
1.88518	302
1.88414	318
1.8831	324
1.88206	290
1.88102	260
1.87999	312
1.87895	286
1.87792	302
1.87689	292
1.87586	300
1.87483	298
1.8738	284
1.87277	300
1.87174	296
1.87072	304
1.86969	300
1.86867	296
1.86765	318
1.86663	286
1.86561	288
1.86459	286
1.86357	304
1.86256	306
1.86154	302
1.86053	302
1.85952	296
1.85851	308
1.8575	290
1.85649	290
1.85548	282
1.85447	288
1.85347	290
1.85247	280
1.85146	292
1.85046	282
1.84946	288
1.84846	290
1.84746	278
1.84646	286
1.84547	252
1.84447	280
1.84348	296
1.84249	288
1.8415	292
1.84051	280
1.83952	282
1.83853	284
1.83754	278
1.83656	252
1.83557	274
1.83459	278
1.83361	264
1.83262	278
1.83164	282
1.83066	254
1.82969	276
1.82871	262
1.82773	272
1.82676	276
1.82579	274
1.82481	252
1.82384	262
1.82287	256
1.8219	272
1.82094	264
1.81997	260
1.819	266
1.81804	238
1.81708	268
1.81611	260
1.81515	286
1.81419	236
1.81323	264
1.81227	252
1.81132	262
1.81036	270
1.80941	246
1.80845	252
1.8075	260
1.80655	228
1.8056	254
1.80465	254
1.8037	238
1.80275	242
1.80181	264
1.80086	256
1.79992	224
1.79897	246
1.79803	226
1.79709	260
1.79615	234
1.79521	242
1.79428	268
1.79334	228
1.7924	236
1.79147	232.853
1.79053	239.613
1.7896	236.546
1.78867	228.441
1.78774	219.65
1.78681	216.982
1.78588	218.861
1.78496	227.964
1.78403	221.703
1.7831	228.48
1.78218	210.718
1.78126	225.696
1.78033	223.443
1.77941	210.823
1.77851	212
1.77759	220
1.77667	212
1.77575	214
1.77483	216
1.77391	218
1.77299	194
1.77207	190
1.77115	226
1.77024	206
1.76932	220
1.76841	200
1.7675	212
1.76659	204
1.76568	204
1.76477	214
1.76386	202
1.76295	208
1.76204	202
1.76114	192
1.76023	200
1.75933	186
1.75843	202
1.75753	190
1.75662	186
1.75572	200
1.75483	188
1.75393	204
1.75303	180
1.75214	188
1.75124	186
1.75035	198
1.74945	200
1.74856	192
1.74767	184
1.74678	200
1.74589	178
1.74501	190
1.74412	180
1.74323	176
1.74235	174
1.74146	176
1.74058	188
1.7397	170
1.73882	176
1.73794	162
1.73706	164
1.73618	174
1.7353	156
1.73443	174
1.73355	166
1.73268	174
1.7318	170
1.73093	174
1.73006	158
1.72919	172
1.72832	166
1.72745	150
1.72658	146
1.72571	150
1.72485	174
1.72398	158
1.72312	150
1.72225	148
1.72139	140
1.72053	156
1.71967	164
1.71881	146
1.71795	152
1.71709	162
1.71624	172
1.71538	156
1.71453	152
1.71367	144
1.71282	152
1.71197	148
1.71112	148
1.71027	136
1.70942	142
1.70857	152
1.70772	148
1.70687	144
1.70603	146
1.70518	140
1.70434	144
1.7035	144
1.70265	158
1.70181	132
1.70097	148
1.70013	134
1.69929	140
1.69846	126
1.69762	132
1.69678	130
1.69595	120
1.69511	132
1.69428	146
1.69345	118
1.69262	118
1.69179	126
1.69096	128
1.69013	126
1.6893	126
1.68847	118
1.68765	116
1.68682	118
1.686	122
1.68517	128
1.68435	112
1.68353	124
1.68271	122
1.68189	110
1.68107	130
1.68025	114
1.67943	120
1.67861	116
1.6778	116
1.67698	114.039
1.67617	110.244
1.67536	117.836
1.67454	109.244
1.67373	122.637
1.67292	116.673
1.67211	107.264
1.6713	114.474
1.6705	110.131
1.66969	112.767
1.66888	115.327
1.66808	109.324
1.66727	110.725
1.66647	97.8828
1.66566	118.771
1.6649	118
1.66409	106
1.66329	98
1.66249	102
1.66168	104
1.66088	118
1.66008	96
1.65928	100
1.65848	88
1.65768	108
1.65688	104
1.65608	98
1.65529	102
1.65449	90
1.6537	100
1.6529	110
1.65211	102
1.65132	94
1.65053	106
1.64973	98
1.64894	106
1.64816	92
1.64737	94
1.64658	98
1.64579	88
1.64501	108
1.64422	90
1.64344	96
1.64265	88
1.64187	90
1.64109	104
1.64031	98
1.63953	98
1.63875	90
1.63797	98
1.63719	92
1.63642	88
1.63564	92
1.63486	100
1.63409	88
1.63331	88
1.63254	86
1.63177	80
1.631	84
1.63023	92
1.62946	84
1.62869	96
1.62792	82
1.62715	80
1.62639	96
1.62562	82
1.62485	88
1.62409	86
1.62333	76
1.62256	84
1.6218	88
1.62104	80
1.62028	94
1.61952	86
1.61876	88
1.618	82
1.61724	82
1.61649	88
1.61573	70
1.61498	80
1.61422	72
1.61347	78
1.61271	76
1.61196	74
1.61121	80
1.61046	80
1.60971	80
1.60896	76
1.60821	88
1.60747	74
1.60672	74
1.60597	74
1.60523	70
1.60448	66
1.60374	82
1.603	70
1.60225	72
1.60151	74
1.60077	76
1.60003	72
1.59929	74
1.59855	66
1.59782	74
1.59708	74
1.59634	64
1.59561	74
1.59487	66
1.59414	68
1.5934	60
1.59267	68
1.59194	66
1.59121	62
1.59048	70
1.58975	74
1.58902	68
1.58829	64
1.58756	64
1.58684	60
1.58611	66
1.58538	72
1.58466	58
1.58394	68
1.58321	54
1.58249	58
1.58177	66
1.58105	68
1.58033	58
1.57961	58
1.57889	64
1.57817	54
1.57745	58
1.57674	68
1.57602	54.0364
1.5753	57.739
1.57459	53.9382
1.57388	57.7251
1.57316	54.6435
1.57245	56.7037
1.57174	52.6475
1.57103	48.8078
1.57032	52.394
1.56961	49.1525
1.5689	51.3838
1.56819	48
1.56748	60.5976
1.56678	52.557
1.56607	48.3724
1.56544	52
1.56473	50
1.56402	52
1.56331	46
1.56261	52
1.5619	58
1.56119	50
1.56049	58
1.55979	42
1.55908	48
1.55838	46
1.55768	54
1.55698	44
1.55628	42
1.55558	54
1.55488	52
1.55418	56
1.55348	44
1.55278	50
1.55209	44
1.55139	46
1.5507	46
1.55	44
1.54931	42
1.54862	44
1.54792	54
1.54723	58
1.54654	50
1.54585	40
1.54516	48
1.54447	54
1.54378	48
1.5431	42
1.54241	52
1.54172	48
1.54104	54
1.54035	50
1.53967	46
1.53898	48
1.5383	42
1.53762	46
1.53694	44
1.53626	46
1.53558	48
1.5349	46
1.53422	52
1.53354	40
1.53286	48
1.53218	42
1.53151	46
1.53083	52
1.53016	46
1.52948	40
1.52881	36
1.52813	44
1.52746	46
1.52679	42
1.52612	50
1.52545	46
1.52478	52
1.52411	46
1.52344	48
1.52277	48
1.5221	40
1.52144	36
1.52077	46
1.52011	44
1.51944	44
1.51878	44
1.51811	44
1.51745	38
1.51679	44
1.51613	36
1.51547	38
1.51481	40
1.51415	46
1.51349	44
1.51283	40
1.51217	40
1.51151	46
1.51086	46
1.5102	42
1.50954	38
1.50889	32
1.50824	38
1.50758	42
1.50693	38
1.50628	36
1.50563	32
1.50497	38
1.50432	38
1.50367	40
1.50302	38
1.50238	34
1.50173	38
1.50108	38
1.50043	40
1.49979	34
1.49914	38
1.4985	46
1.49785	40
1.49721	40
1.49657	28
1.49592	36
1.49528	34
1.49464	34
1.494	38
1.49336	34
1.49272	36
1.49208	30
1.49144	32
1.49081	36
1.49017	40
1.48953	34
1.4889	40
1.48826	38
1.48763	38
1.48699	35.9703
1.48636	34.1419
1.48573	33.1018
1.4851	34.9
1.48446	32.3801
1.48383	35.8911
1.4832	37.6087
1.48257	36.4995
1.48194	32.8812
1.48132	33.1818
1.48069	29.4265
1.48006	31.2474
1.47943	34.6611
1.47881	38.062
1.47818	29.1362
1.47756	34
1.47694	36
1.47631	40
1.47568	30
1.47505	28
1.47443	30
1.4738	32
1.47318	30
1.47256	34
1.47193	30
1.47131	32
1.47069	30
1.47006	40
1.46944	36
1.46882	34
1.4682	32
1.46758	40
1.46696	32
1.46635	38
1.46573	32
1.46511	32
1.46449	34
1.46388	34
1.46326	28
1.46265	32
1.46203	32
1.46142	32
1.46081	30
1.46019	34
1.45958	24
1.45897	34
1.45836	28
1.45775	28
1.45714	28
1.45653	32
1.45592	26
1.45531	34
1.4547	30
1.4541	26
1.45349	28
1.45288	30
1.45228	26
1.45167	34
1.45107	36
1.45047	24
1.44986	26
1.44926	32
1.44866	34
1.44806	28
1.44746	34
1.44686	28
1.44626	28
1.44566	30
1.44506	28
1.44446	32
1.44386	24
1.44326	34
1.44267	40
1.44207	26
1.44148	30
1.44088	32
1.44029	30
1.43969	26
1.4391	28
1.43851	22
1.43791	30
1.43732	40
1.43673	30
1.43614	28
1.43555	36
1.43496	30
1.43437	34
1.43378	26
1.4332	26
1.43261	20
1.43202	34
1.43143	32
1.43085	32
1.43026	28
1.42968	28
1.42909	28
1.42851	32
1.42793	28
1.42734	36
1.42676	26
1.42618	24
1.4256	30
1.42502	30
1.42444	26
1.42386	34
1.42328	22
1.4227	36
1.42212	34
1.42155	32
1.42097	30
1.42039	32
1.41982	32
1.41924	24
1.41867	30
1.41809	20
1.41752	28
1.41695	30
1.41637	28
1.4158	30
1.41523	26
1.41466	26
1.41409	18
1.41352	26
1.41295	24
1.41238	28
1.41181	32
1.41124	28
1.41067	30
1.41011	26
1.40954	28
1.40897	28
1.40841	32
1.40784	26.0073
1.40728	31.6962
1.40672	29.1352
1.40615	23.3079
1.40559	34.5704
1.40503	31.297
1.40446	127.202
1.4039	34.4289
1.40334	30.134
1.40278	31.3547
1.40222	31.3692
1.40166	23.5567
1.4011	27.3668
1.40054	34.9697
1.39999	26.0495
1.39947	40
1.3989	26
1.39834	40
1.39779	28
1.39723	36
1.39667	32
1.39611	30
1.39555	24
1.395	36
1.39444	30
1.39388	28
1.39333	42
1.39277	32
1.39222	28
1.39166	32
1.39111	30
1.39056	34
1.39	28
1.38945	32
1.3889	28
1.38835	26
1.3878	30
1.38725	32
1.3867	30
1.38615	36
1.3856	24
1.38505	32
1.3845	34
1.38396	32
1.38341	28
1.38286	24
1.38232	38
1.38177	34
1.38123	30
1.38068	32
1.38014	32
1.3796	24
1.37905	30
1.37851	26
1.37797	28
1.37743	36
1.37688	34
1.37634	24
1.3758	28
1.37526	30
1.37472	32
1.37419	34
1.37365	36
1.37311	30
1.37257	36
1.37204	34
1.3715	28
1.37096	34
1.37043	28
1.36989	28
1.36936	28
1.36882	32
1.36829	30
1.36776	30
1.36722	32
1.36669	28
1.36616	34
1.36563	32
1.3651	28
1.36457	32
1.36404	24
1.36351	34
1.36298	32
1.36245	30
1.36192	36
1.36139	34
1.36087	28
1.36034	38
1.35981	28
1.35929	26
1.35876	32
1.35824	28
1.35771	32
1.35719	26
1.35667	30
1.35614	34
1.35562	30
1.3551	32
1.35458	24
1.35406	28
1.35353	30
1.35301	32
1.35249	32
1.35197	32
1.35146	26
1.35094	34
1.35042	34
1.3499	28
1.34938	30
1.34887	28
1.34835	30
1.34783	28
1.34732	32
1.3468	30
1.34629	30
1.34578	32
1.34526	40
1.34475	26
1.34424	30
1.34372	30
1.34321	32
1.3427	30
1.34219	26
1.34168	24
1.34117	28
1.34066	34
1.34015	30
1.33964	32
1.33913	22
1.33862	28
1.33812	34
1.33761	30
1.3371	28.0376
1.3366	33.0135
1.33609	22.3204
1.33558	30.0447
1.33508	27.7438
1.33457	27.2806
1.33407	27.7068
1.33357	26.075
1.33306	30.2745
1.33256	27.4779
1.33206	28.7619
1.33156	24.4507
1.33105	29.629
1.33055	25.1666
1.33005	28.9768
1.32959	28
1.32909	32
1.32859	28
1.32809	28
1.32758	30
1.32708	26
1.32658	30
1.32608	24
1.32558	26
1.32508	28
1.32458	30
1.32408	34
1.32358	30
1.32309	30
1.32259	28
1.32209	30
1.3216	28
1.3211	24
1.3206	32
1.32011	28
1.31961	28
1.31912	26
1.31862	40
1.31813	34
1.31764	30
1.31714	30
1.31665	34
1.31616	34
1.31567	30
1.31518	28
1.31468	24
1.31419	30
1.3137	36
1.31321	34
1.31272	32
1.31224	34
1.31175	34
1.31126	28
1.31077	32
1.31028	28
1.3098	36
1.30931	28
1.30882	32
1.30834	26
1.30785	30
1.30737	32
1.30688	22
1.3064	34
1.30592	30
1.30543	32
1.30495	30
1.30447	30
1.30399	28
1.3035	32
1.30302	30
1.30254	36
1.30206	24
1.30158	30
1.3011	36
1.30062	26
1.30014	26
1.30001	44