File: ploting_and_data_tools/raman/CdSe4_04.txt
#Acq. time (s)=	1
#Accumulations=	1
#Range (eV)=	2...1
#Windows=	11
#Autofocus=	Off
#AutoExposure=	Off
#Spike filter=	Off
#Delay time (s)=	0
#Binning=	1
#Readout mode=	Signal
#DeNoise=	Off
#ICS correction=	Off
#Dark correction=	Off
#Inst. Process=	Off
#Instrument=	LabRAM HR Evol
#Detector=	Syncerity OE
#Objective=	x100_VIS_LWD
#Grating=	600 (500nm)
#ND Filter=	1%
#Laser=	442nm_Notch
#Hole=	150.001
#Range=	Visible
#Project=	Paty
#Sample=
#Site=	15-06-22
#Title=	CdSe4
#Remark=
#Date=	15.06.2022 21:36
#Acquired=	15.06.2022 21:36:44
2.74975	26
2.7475	24
2.74525	32
2.743	24
2.74076	28
2.73852	28
2.73629	34
2.73406	28
2.73183	30
2.72961	26
2.72739	34
2.72517	32
2.72296	26
2.72075	26
2.71854	30
2.71634	36
2.71414	34
2.71195	34
2.70976	38
2.70757	30
2.70539	34
2.70321	38
2.70103	32
2.69886	22
2.69669	26
2.69452	40
2.69236	32
2.6902	36
2.68805	30
2.6859	28
2.68375	30
2.68161	34
2.67947	28
2.67733	24
2.6752	30
2.67307	44
2.67094	34
2.66882	40
2.6667	36
2.66458	40
2.66247	42
2.66036	40
2.65826	36
2.65615	38
2.65405	40
2.65196	36
2.64987	40
2.64778	42
2.64569	42
2.64361	42
2.64153	44
2.63946	36
2.63739	44
2.63532	42
2.63325	50
2.63119	44
2.62913	56
2.62708	58
2.62503	32
2.62298	42
2.62094	54
2.61889	54
2.61686	48
2.61482	52
2.61279	60
2.61076	50
2.60873	60
2.60671	62
2.60469	60
2.60268	68
2.60067	76
2.59866	60
2.59665	62
2.59465	66
2.59265	68
2.59065	86
2.58866	78
2.58667	86
2.58468	76
2.5827	86
2.58072	84
2.57874	84
2.57677	88
2.5748	94
2.57283	100
2.57086	122
2.5689	108
2.56694	110
2.56499	112
2.56304	114
2.56109	120
2.55914	130
2.5572	132
2.55526	146
2.55332	146
2.55139	148
2.54946	164
2.54753	154
2.5456	160
2.54368	172
2.54176	176
2.53985	186
2.53794	182
2.53603	194
2.53412	204
2.53222	228
2.53031	228
2.52842	232
2.52652	240
2.52463	264
2.52274	262
2.52085	264
2.51897	272
2.51709	280
2.51521	312
2.51334	316
2.51147	308
2.5096	338
2.50773	350
2.50587	354
2.50401	378
2.50216	398
2.5003	392
2.49845	408
2.4966	454
2.49476	458
2.49291	474
2.49107	474
2.48924	494
2.4874	498
2.48557	554
2.48374	536
2.48192	571.958
2.48009	575.685
2.47827	599.501
2.47646	638.839
2.47464	634.287
2.47283	677.415
2.47102	684.344
2.46922	699.161
2.46741	735.652
2.46561	744.639
2.46381	768.755
2.46202	792.384
2.46023	841.785
2.45844	834.104
2.45665	845.371
2.45493	858
2.45314	952
2.45136	954
2.44957	970
2.44779	958
2.44601	1026
2.44424	1002
2.44247	1086
2.4407	1074
2.43893	1112
2.43716	1126
2.4354	1148
2.43364	1178
2.43188	1222
2.43013	1208
2.42838	1198
2.42663	1256
2.42488	1276
2.42314	1300
2.4214	1306
2.41966	1372
2.41792	1390
2.41619	1356
2.41446	1372
2.41273	1414
2.411	1388
2.40928	1438
2.40756	1496
2.40584	1438
2.40413	1510
2.40241	1534
2.4007	1522
2.39899	1532
2.39729	1560
2.39559	1562
2.39389	1550
2.39219	1608
2.39049	1598
2.3888	1592
2.38711	1606
2.38542	1648
2.38374	1622
2.38205	1624
2.38037	1632
2.37869	1648
2.37702	1672
2.37535	1700
2.37368	1660
2.37201	1652
2.37034	1702
2.36868	1676
2.36702	1714
2.36536	1612
2.3637	1668
2.36205	1640
2.3604	1686
2.35875	1664
2.3571	1616
2.35546	1608
2.35382	1594
2.35218	1562
2.35054	1556
2.34891	1540
2.34727	1536
2.34564	1578
2.34402	1500
2.34239	1506
2.34077	1534
2.33915	1498
2.33753	1492
2.33591	1410
2.3343	1422
2.33269	1416
2.33108	1386
2.32948	1392
2.32787	1400
2.32627	1366
2.32467	1362
2.32307	1346
2.32148	1334
2.31989	1308
2.3183	1340
2.31671	1308
2.31512	1266
2.31354	1296
2.31196	1260
2.31038	1230
2.3088	1264
2.30723	1240
2.30565	1224
2.30408	1202
2.30252	1190
2.30095	1218
2.29939	1162
2.29783	1126
2.29627	1140
2.29471	1168
2.29316	1136
2.29161	1088
2.29006	1102
2.28851	1100
2.28696	1082
2.28542	1100
2.28388	1014
2.28234	1082
2.2808	1078
2.27927	1042
2.27773	1014
2.2762	1018
2.27468	1024
2.27315	1012
2.27163	970
2.27011	962
2.26859	938
2.26707	966
2.26555	924
2.26404	926
2.26253	940.898
2.26102	899.148
2.25951	913.132
2.25801	906.484
2.25651	863.731
2.25501	891.024
2.25351	881.473
2.25201	830.02
2.25052	856.307
2.24902	829.304
2.24753	806.811
2.24605	793.054
2.24456	784.591
2.24308	765.686
2.2416	733.241
2.24011	716
2.23863	730
2.23715	742
2.23567	742
2.23419	704
2.23271	702
2.23124	728
2.22977	664
2.2283	722
2.22683	684
2.22536	712
2.2239	684
2.22244	662
2.22098	664
2.21952	642
2.21807	686
2.21661	656
2.21516	640
2.21371	652
2.21226	606
2.21082	646
2.20937	624
2.20793	652
2.20649	624
2.20505	610
2.20362	622
2.20218	610
2.20075	624
2.19932	606
2.19789	588
2.19647	592
2.19504	596
2.19362	596
2.1922	610
2.19078	596
2.18936	576
2.18795	574
2.18654	574
2.18513	592
2.18372	570
2.18231	540
2.18091	572
2.1795	540
2.1781	576
2.1767	562
2.1753	568
2.17391	576
2.17251	532
2.17112	534
2.16973	534
2.16834	586
2.16696	566
2.16557	544
2.16419	580
2.16281	572
2.16143	546
2.16005	560
2.15868	552
2.1573	530
2.15593	528
2.15456	576
2.1532	560
2.15183	532
2.15046	552
2.1491	566
2.14774	528
2.14638	550
2.14503	548
2.14367	522
2.14232	560
2.14097	558
2.13962	528
2.13827	570
2.13692	566
2.13558	510
2.13423	530
2.13289	556
2.13155	518
2.13022	536
2.12888	556
2.12755	560
2.12621	548
2.12488	552
2.12356	534
2.12223	534
2.1209	562
2.11958	522
2.11826	554
2.11694	550
2.11562	526
2.1143	544
2.11299	554
2.11168	538
2.11037	572
2.10906	536
2.10775	530
2.10644	544
2.10514	556
2.10384	554
2.10253	534
2.10123	556
2.09994	548
2.09864	534
2.09735	564
2.09605	530
2.09476	534
2.09347	548
2.09219	550
2.0909	530
2.08962	534
2.08834	536
2.08705	566
2.08578	534
2.0845	534
2.08322	550
2.08195	520
2.08068	572
2.0794	561.631
2.07814	562.496
2.07687	535.707
2.0756	501.78
2.07434	535.84
2.07307	521.667
2.07181	514.357
2.07055	507.52
2.0693	510.859
2.06804	513.744
2.06679	508.011
2.06553	478.143
2.06428	519.129
2.06303	470.893
2.06178	485.253
2.06069	488
2.05944	484
2.05819	490
2.05694	500
2.05569	510
2.05445	494
2.05321	474
2.05196	468
2.05072	510
2.04949	518
2.04825	498
2.04701	498
2.04578	478
2.04455	466
2.04332	482
2.04209	460
2.04086	492
2.03964	488
2.03841	490
2.03719	462
2.03597	468
2.03475	478
2.03353	488
2.03232	474
2.0311	464
2.02989	472
2.02868	464
2.02747	482
2.02626	456
2.02505	486
2.02384	476
2.02264	482
2.02144	476
2.02024	480
2.01904	500
2.01784	490
2.01664	500
2.01544	480
2.01425	488
2.01306	488
2.01187	506
2.01068	526
2.00949	488
2.0083	492
2.00712	522
2.00594	496
2.00475	502
2.00357	470
2.0024	510
2.00122	520
2.00004	516
1.99887	506
1.99769	514
1.99652	526
1.99535	540
1.99418	544
1.99302	532
1.99185	532
1.99069	532
1.98952	552
1.98836	516
1.9872	518
1.98604	556
1.98488	518
1.98373	534
1.98257	540
1.98142	552
1.98027	552
1.97912	558
1.97797	554
1.97682	538
1.97568	568
1.97453	552
1.97339	564
1.97225	508
1.97111	554
1.96997	548
1.96883	550
1.9677	550
1.96656	536
1.96543	532
1.9643	540
1.96316	564
1.96204	572
1.96091	536
1.95978	550
1.95866	554
1.95753	546
1.95641	562
1.95529	572
1.95417	542
1.95305	552
1.95193	566
1.95082	552
1.9497	542
1.94859	582
1.94748	536
1.94637	528
1.94526	542
1.94415	556
1.94305	554
1.94194	592
1.94084	592
1.93974	588
1.93864	548
1.93754	568
1.93644	592
1.93534	558
1.93425	604
1.93315	566
1.93206	526
1.93097	546
1.92988	594
1.92879	568
1.9277	572
1.92662	576
1.92553	532
1.92445	564.322
1.92337	567.681
1.92228	578.01
1.92121	570.018
1.92013	554.573
1.91905	547.989
1.91797	570.014
1.9169	568.361
1.91583	562.12
1.91475	558.159
1.91368	558.417
1.91261	560.241
1.91155	551.84
1.91048	560.083
1.90946	542
1.90839	530
1.90732	584
1.90626	532
1.90519	566
1.90413	582
1.90306	524
1.902	526
1.90094	578
1.89988	558
1.89882	550
1.89777	570
1.89671	552
1.89566	564
1.8946	582
1.89355	554
1.8925	564
1.89145	544
1.8904	542
1.88936	564
1.88831	568
1.88727	538
1.88622	546
1.88518	544
1.88414	536
1.8831	568
1.88206	544
1.88102	554
1.87999	546
1.87895	554
1.87792	550
1.87689	558
1.87586	540
1.87483	516
1.8738	554
1.87277	562
1.87174	540
1.87072	544
1.86969	540
1.86867	544
1.86765	554
1.86663	560
1.86561	528
1.86459	540
1.86357	494
1.86256	542
1.86154	558
1.86053	526
1.85952	520
1.85851	528
1.8575	552
1.85649	504
1.85548	532
1.85447	514
1.85347	538
1.85247	542
1.85146	492
1.85046	534
1.84946	532
1.84846	508
1.84746	504
1.84646	522
1.84547	530
1.84447	530
1.84348	512
1.84249	526
1.8415	500
1.84051	506
1.83952	500
1.83853	510
1.83754	518
1.83656	526
1.83557	492
1.83459	510
1.83361	524
1.83262	534
1.83164	526
1.83066	520
1.82969	522
1.82871	498
1.82773	508
1.82676	492
1.82579	492
1.82481	492
1.82384	512
1.82287	532
1.8219	520
1.82094	516
1.81997	502
1.819	512
1.81804	516
1.81708	504
1.81611	502
1.81515	494
1.81419	478
1.81323	454
1.81227	480
1.81132	492
1.81036	482
1.80941	472
1.80845	452
1.8075	472
1.80655	478
1.8056	494
1.80465	478
1.8037	460
1.80275	488
1.80181	482
1.80086	468
1.79992	486
1.79897	454
1.79803	456
1.79709	460
1.79615	450
1.79521	446
1.79428	452
1.79334	460
1.7924	434
1.79147	445.664
1.79053	441.226
1.7896	460.724
1.78867	450.483
1.78774	433.047
1.78681	447.019
1.78588	454.914
1.78496	439.76
1.78403	438.71
1.7831	429.898
1.78218	424.875
1.78126	418.275
1.78033	429.845
1.77941	419.84
1.77851	422
1.77759	424
1.77667	404
1.77575	424
1.77483	424
1.77391	400
1.77299	430
1.77207	434
1.77115	426
1.77024	402
1.76932	392
1.76841	396
1.7675	414
1.76659	400
1.76568	406
1.76477	392
1.76386	400
1.76295	398
1.76204	408
1.76114	398
1.76023	376
1.75933	390
1.75843	378
1.75753	386
1.75662	388
1.75572	404
1.75483	386
1.75393	388
1.75303	374
1.75214	396
1.75124	372
1.75035	370
1.74945	362
1.74856	372
1.74767	402
1.74678	360
1.74589	336
1.74501	352
1.74412	364
1.74323	352
1.74235	360
1.74146	368
1.74058	372
1.7397	346
1.73882	340
1.73794	344
1.73706	360
1.73618	344
1.7353	334
1.73443	320
1.73355	368
1.73268	318
1.7318	338
1.73093	336
1.73006	320
1.72919	318
1.72832	302
1.72745	336
1.72658	340
1.72571	314
1.72485	316
1.72398	314
1.72312	324
1.72225	324
1.72139	330
1.72053	306
1.71967	314
1.71881	290
1.71795	302
1.71709	292
1.71624	300
1.71538	286
1.71453	274
1.71367	308
1.71282	300
1.71197	296
1.71112	288
1.71027	278
1.70942	278
1.70857	298
1.70772	284
1.70687	282
1.70603	262
1.70518	254
1.70434	276
1.7035	302
1.70265	272
1.70181	292
1.70097	272
1.70013	274
1.69929	254
1.69846	270
1.69762	256
1.69678	252
1.69595	264
1.69511	250
1.69428	278
1.69345	258
1.69262	260
1.69179	244
1.69096	238
1.69013	250
1.6893	220
1.68847	254
1.68765	226
1.68682	236
1.686	252
1.68517	236
1.68435	230
1.68353	214
1.68271	216
1.68189	218
1.68107	234
1.68025	224
1.67943	202
1.67861	220
1.6778	234
1.67698	225.981
1.67617	215.085
1.67536	209.385
1.67454	216.729
1.67373	207.107
1.67292	202.144
1.67211	212.027
1.6713	220.643
1.6705	215.614
1.66969	218.967
1.66888	216.845
1.66808	212.868
1.66727	215.275
1.66647	205.049
1.66566	202.458
1.6649	202
1.66409	206
1.66329	196
1.66249	204
1.66168	190
1.66088	218
1.66008	188
1.65928	198
1.65848	216
1.65768	198
1.65688	200
1.65608	194
1.65529	210
1.65449	196
1.6537	196
1.6529	166
1.65211	190
1.65132	202
1.65053	202
1.64973	190
1.64894	200
1.64816	182
1.64737	188
1.64658	186
1.64579	188
1.64501	178
1.64422	176
1.64344	186
1.64265	190
1.64187	188
1.64109	192
1.64031	164
1.63953	162
1.63875	170
1.63797	164
1.63719	160
1.63642	186
1.63564	166
1.63486	170
1.63409	176
1.63331	170
1.63254	156
1.63177	150
1.631	162
1.63023	154
1.62946	156
1.62869	162
1.62792	162
1.62715	160
1.62639	168
1.62562	158
1.62485	144
1.62409	146
1.62333	152
1.62256	156
1.6218	154
1.62104	140
1.62028	144
1.61952	162
1.61876	152
1.618	154
1.61724	156
1.61649	146
1.61573	148
1.61498	138
1.61422	140
1.61347	132
1.61271	132
1.61196	150
1.61121	138
1.61046	130
1.60971	134
1.60896	136
1.60821	126
1.60747	136
1.60672	146
1.60597	138
1.60523	118
1.60448	136
1.60374	132
1.603	154
1.60225	136
1.60151	126
1.60077	130
1.60003	126
1.59929	120
1.59855	130
1.59782	128
1.59708	126
1.59634	126
1.59561	120
1.59487	112
1.59414	110
1.5934	122
1.59267	122
1.59194	112
1.59121	118
1.59048	124
1.58975	112
1.58902	104
1.58829	106
1.58756	114
1.58684	116
1.58611	110
1.58538	116
1.58466	108
1.58394	110
1.58321	112
1.58249	112
1.58177	112
1.58105	100
1.58033	98
1.57961	92
1.57889	104
1.57817	98
1.57745	100
1.57674	96
1.57602	105.958
1.5753	104.665
1.57459	110.267
1.57388	99.5478
1.57316	96.693
1.57245	100.037
1.57174	100.291
1.57103	90.2004
1.57032	97.9281
1.56961	97.0139
1.5689	100.547
1.56819	93.3814
1.56748	93.9598
1.56678	91.6238
1.56607	94.7004
1.56544	100
1.56473	92
1.56402	74
1.56331	74
1.56261	80
1.5619	82
1.56119	96
1.56049	86
1.55979	86
1.55908	82
1.55838	84
1.55768	72
1.55698	94
1.55628	82
1.55558	94
1.55488	76
1.55418	90
1.55348	72
1.55278	76
1.55209	70
1.55139	74
1.5507	58
1.55	72
1.54931	86
1.54862	78
1.54792	72
1.54723	76
1.54654	62
1.54585	76
1.54516	76
1.54447	86
1.54378	74
1.5431	74
1.54241	76
1.54172	72
1.54104	68
1.54035	76
1.53967	72
1.53898	64
1.5383	76
1.53762	76
1.53694	64
1.53626	66
1.53558	72
1.5349	72
1.53422	68
1.53354	78
1.53286	74
1.53218	68
1.53151	66
1.53083	80
1.53016	78
1.52948	62
1.52881	70
1.52813	68
1.52746	68
1.52679	76
1.52612	60
1.52545	62
1.52478	62
1.52411	62
1.52344	66
1.52277	48
1.5221	64
1.52144	60
1.52077	66
1.52011	70
1.51944	78
1.51878	68
1.51811	62
1.51745	62
1.51679	54
1.51613	58
1.51547	60
1.51481	54
1.51415	64
1.51349	68
1.51283	64
1.51217	48
1.51151	56
1.51086	56
1.5102	60
1.50954	50
1.50889	60
1.50824	72
1.50758	56
1.50693	62
1.50628	58
1.50563	50
1.50497	54
1.50432	56
1.50367	64
1.50302	54
1.50238	54
1.50173	66
1.50108	56
1.50043	48
1.49979	58
1.49914	52
1.4985	54
1.49785	56
1.49721	46
1.49657	50
1.49592	54
1.49528	58
1.49464	54
1.494	58
1.49336	46
1.49272	58
1.49208	50
1.49144	52
1.49081	44
1.49017	56
1.48953	56
1.4889	48
1.48826	44
1.48763	42
1.48699	50.0099
1.48636	45.561
1.48573	45.0839
1.4851	50.3546
1.48446	45.7322
1.48383	46.9413
1.4832	46.2235
1.48257	49.9127
1.48194	49.2553
1.48132	46.93
1.48069	43.3655
1.48006	44.1037
1.47943	47.3146
1.47881	45.319
1.47818	49.8515
1.47756	42
1.47694	38
1.47631	40
1.47568	36
1.47505	52
1.47443	40
1.4738	48
1.47318	42
1.47256	46
1.47193	46
1.47131	48
1.47069	44
1.47006	42
1.46944	34
1.46882	44
1.4682	40
1.46758	48
1.46696	44
1.46635	46
1.46573	34
1.46511	40
1.46449	34
1.46388	34
1.46326	40
1.46265	40
1.46203	46
1.46142	38
1.46081	30
1.46019	44
1.45958	50
1.45897	44
1.45836	34
1.45775	30
1.45714	32
1.45653	42
1.45592	28
1.45531	28
1.4547	28
1.4541	36
1.45349	36
1.45288	36
1.45228	38
1.45167	26
1.45107	30
1.45047	36
1.44986	30
1.44926	28
1.44866	26
1.44806	26
1.44746	34
1.44686	28
1.44626	26
1.44566	28
1.44506	28
1.44446	34
1.44386	30
1.44326	28
1.44267	28
1.44207	24
1.44148	32
1.44088	32
1.44029	30
1.43969	30
1.4391	28
1.43851	24
1.43791	24
1.43732	30
1.43673	32
1.43614	28
1.43555	32
1.43496	32
1.43437	30
1.43378	22
1.4332	28
1.43261	32
1.43202	32
1.43143	32
1.43085	38
1.43026	22
1.42968	28
1.42909	26
1.42851	26
1.42793	30
1.42734	30
1.42676	28
1.42618	28
1.4256	28
1.42502	22
1.42444	28
1.42386	26
1.42328	24
1.4227	30
1.42212	28
1.42155	28
1.42097	22
1.42039	26
1.41982	26
1.41924	26
1.41867	26
1.41809	32
1.41752	32
1.41695	30
1.41637	24
1.4158	28
1.41523	30
1.41466	26
1.41409	26
1.41352	28
1.41295	36
1.41238	30
1.41181	36
1.41124	20
1.41067	28
1.41011	30
1.40954	34
1.40897	26
1.40841	24
1.40784	35.9776
1.40728	31.966
1.40672	29.7129
1.40615	24.0921
1.40559	28.8218
1.40503	30.8119
1.40446	130.26
1.4039	31.7634
1.40334	32.0343
1.40278	33.0297
1.40222	34.6978
1.40166	32.144
1.4011	35.3401
1.40054	32.5644
1.39999	30.8845
1.39947	36
1.3989	34
1.39834	26
1.39779	34
1.39723	34
1.39667	40
1.39611	30
1.39555	24
1.395	32
1.39444	32
1.39388	46
1.39333	36
1.39277	28
1.39222	28
1.39166	36
1.39111	32
1.39056	34
1.39	32
1.38945	38
1.3889	42
1.38835	30
1.3878	34
1.38725	32
1.3867	36
1.38615	38
1.3856	30
1.38505	38
1.3845	40
1.38396	32
1.38341	30
1.38286	40
1.38232	32
1.38177	40
1.38123	26
1.38068	36
1.38014	34
1.3796	30
1.37905	32
1.37851	38
1.37797	28
1.37743	42
1.37688	34
1.37634	32
1.3758	28
1.37526	28
1.37472	32
1.37419	32
1.37365	38
1.37311	34
1.37257	34
1.37204	36
1.3715	26
1.37096	30
1.37043	34
1.36989	36
1.36936	30
1.36882	30
1.36829	32
1.36776	32
1.36722	40
1.36669	34
1.36616	38
1.36563	30
1.3651	28
1.36457	34
1.36404	42
1.36351	34
1.36298	30
1.36245	30
1.36192	34
1.36139	44
1.36087	42
1.36034	32
1.35981	26
1.35929	40
1.35876	50
1.35824	26
1.35771	34
1.35719	28
1.35667	32
1.35614	38
1.35562	32
1.3551	36
1.35458	28
1.35406	26
1.35353	22
1.35301	30
1.35249	30
1.35197	42
1.35146	34
1.35094	34
1.35042	26
1.3499	26
1.34938	32
1.34887	34
1.34835	34
1.34783	30
1.34732	36
1.3468	32
1.34629	38
1.34578	30
1.34526	30
1.34475	32
1.34424	28
1.34372	34
1.34321	32
1.3427	28
1.34219	36
1.34168	32
1.34117	36
1.34066	38
1.34015	26
1.33964	30
1.33913	26
1.33862	36
1.33812	26
1.33761	30
1.3371	39.7463
1.3366	33.6311
1.33609	31.1525
1.33558	22.1788
1.33508	28.0329
1.33457	30.5701
1.33407	28.3262
1.33357	34
1.33306	34.5896
1.33256	31.9255
1.33206	29.3541
1.33156	29.0874
1.33105	27.6796
1.33055	26.0598
1.33005	30.3297
1.32959	26
1.32909	26
1.32859	28
1.32809	32
1.32758	30
1.32708	32
1.32658	40
1.32608	30
1.32558	34
1.32508	30
1.32458	36
1.32408	30
1.32358	30
1.32309	38
1.32259	34
1.32209	26
1.3216	26
1.3211	32
1.3206	30
1.32011	34
1.31961	30
1.31912	26
1.31862	28
1.31813	28
1.31764	36
1.31714	32
1.31665	28
1.31616	26
1.31567	26
1.31518	28
1.31468	32
1.31419	34
1.3137	30
1.31321	34
1.31272	32
1.31224	28
1.31175	34
1.31126	36
1.31077	36
1.31028	32
1.3098	28
1.30931	40
1.30882	38
1.30834	38
1.30785	30
1.30737	32
1.30688	30
1.3064	26
1.30592	32
1.30543	32
1.30495	28
1.30447	40
1.30399	34
1.3035	32
1.30302	34
1.30254	32
1.30206	32
1.30158	32
1.3011	38
1.30062	38
1.30014	34
1.30001	28