File: ploting_and_data_tools/raman/CdSe1_08.txt
#Acq. time (s)=	2
#Accumulations=	1
#Range (eV)=	2...1
#Windows=	11
#Autofocus=	Off
#AutoExposure=	Off
#Spike filter=	Off
#Delay time (s)=	0
#Binning=	1
#Readout mode=	Signal
#DeNoise=	Off
#ICS correction=	Off
#Dark correction=	Off
#Inst. Process=	Off
#Instrument=	LabRAM HR Evol
#Detector=	Syncerity OE
#Objective=	x10_VIS
#Grating=	600 (500nm)
#ND Filter=	50%
#Laser=	442nm_Notch
#Hole=	100.021
#Range=	Visible
#Project=	Paty
#Sample=
#Site=	15-06-22
#Title=	CdSe1
#Remark=
#Date=	15.06.2022 20:12
#Acquired=	15.06.2022 20:12:49
2.74975	32
2.7475	30
2.74525	26
2.743	22
2.74076	26
2.73852	30
2.73629	30
2.73406	28
2.73183	32
2.72961	28
2.72739	36
2.72517	32
2.72296	30
2.72075	36
2.71854	30
2.71634	32
2.71414	34
2.71195	28
2.70976	30
2.70757	36
2.70539	36
2.70321	26
2.70103	34
2.69886	32
2.69669	22
2.69452	28
2.69236	26
2.6902	32
2.68805	28
2.6859	30
2.68375	34
2.68161	26
2.67947	26
2.67733	30
2.6752	26
2.67307	34
2.67094	30
2.66882	34
2.6667	36
2.66458	30
2.66247	28
2.66036	32
2.65826	32
2.65615	32
2.65405	36
2.65196	34
2.64987	30
2.64778	32
2.64569	36
2.64361	30
2.64153	38
2.63946	38
2.63739	28
2.63532	26
2.63325	42
2.63119	40
2.62913	36
2.62708	32
2.62503	32
2.62298	36
2.62094	38
2.61889	28
2.61686	44
2.61482	28
2.61279	34
2.61076	40
2.60873	46
2.60671	44
2.60469	40
2.60268	38
2.60067	34
2.59866	46
2.59665	34
2.59465	44
2.59265	46
2.59065	44
2.58866	38
2.58667	40
2.58468	52
2.5827	42
2.58072	44
2.57874	40
2.57677	44
2.5748	52
2.57283	44
2.57086	42
2.5689	52
2.56694	48
2.56499	54
2.56304	64
2.56109	48
2.55914	52
2.5572	64
2.55526	56
2.55332	54
2.55139	52
2.54946	56
2.54753	62
2.5456	48
2.54368	64
2.54176	54
2.53985	64
2.53794	64
2.53603	68
2.53412	68
2.53222	78
2.53031	76
2.52842	66
2.52652	72
2.52463	76
2.52274	82
2.52085	74
2.51897	84
2.51709	90
2.51521	84
2.51334	94
2.51147	84
2.5096	92
2.50773	104
2.50587	116
2.50401	106
2.50216	118
2.5003	126
2.49845	128
2.4966	120
2.49476	112
2.49291	118
2.49107	122
2.48924	134
2.4874	144
2.48557	152
2.48374	150
2.48192	146.827
2.48009	136.891
2.47827	154.781
2.47646	161.603
2.47464	159.037
2.47283	161.627
2.47102	189.121
2.46922	191.272
2.46741	195.701
2.46561	215.76
2.46381	221.874
2.46202	225.303
2.46023	254.331
2.45844	236.274
2.45665	265.068
2.45493	268
2.45314	270
2.45136	260
2.44957	266
2.44779	290
2.44601	302
2.44424	300
2.44247	294
2.4407	302
2.43893	310
2.43716	324
2.4354	328
2.43364	338
2.43188	336
2.43013	342
2.42838	384
2.42663	358
2.42488	384
2.42314	372
2.4214	372
2.41966	392
2.41792	366
2.41619	426
2.41446	386
2.41273	416
2.411	402
2.40928	412
2.40756	392
2.40584	410
2.40413	432
2.40241	406
2.4007	460
2.39899	438
2.39729	434
2.39559	468
2.39389	456
2.39219	468
2.39049	464
2.3888	476
2.38711	446
2.38542	486
2.38374	478
2.38205	454
2.38037	488
2.37869	464
2.37702	472
2.37535	478
2.37368	502
2.37201	482
2.37034	518
2.36868	456
2.36702	464
2.36536	476
2.3637	490
2.36205	466
2.3604	478
2.35875	476
2.3571	474
2.35546	464
2.35382	468
2.35218	462
2.35054	470
2.34891	448
2.34727	454
2.34564	450
2.34402	420
2.34239	422
2.34077	412
2.33915	434
2.33753	410
2.33591	400
2.3343	418
2.33269	392
2.33108	380
2.32948	392
2.32787	400
2.32627	394
2.32467	390
2.32307	374
2.32148	370
2.31989	368
2.3183	352
2.31671	384
2.31512	334
2.31354	380
2.31196	360
2.31038	340
2.3088	328
2.30723	324
2.30565	318
2.30408	350
2.30252	316
2.30095	332
2.29939	306
2.29783	314
2.29627	284
2.29471	300
2.29316	294
2.29161	296
2.29006	288
2.28851	290
2.28696	280
2.28542	280
2.28388	288
2.28234	278
2.2808	286
2.27927	288
2.27773	260
2.2762	278
2.27468	280
2.27315	268
2.27163	244
2.27011	270
2.26859	264
2.26707	250
2.26555	244
2.26404	244
2.26253	268.042
2.26102	238.207
2.25951	233.752
2.25801	230.223
2.25651	246.267
2.25501	237.825
2.25351	243.669
2.25201	229.249
2.25052	252.82
2.24902	238.734
2.24753	226.58
2.24605	241.213
2.24456	239.034
2.24308	223.202
2.2416	222.055
2.24011	212
2.23863	224
2.23715	212
2.23567	228
2.23419	230
2.23271	216
2.23124	182
2.22977	214
2.2283	220
2.22683	212
2.22536	196
2.2239	204
2.22244	206
2.22098	194
2.21952	206
2.21807	190
2.21661	190
2.21516	178
2.21371	184
2.21226	198
2.21082	198
2.20937	186
2.20793	192
2.20649	188
2.20505	188
2.20362	198
2.20218	184
2.20075	184
2.19932	184
2.19789	172
2.19647	178
2.19504	184
2.19362	180
2.1922	194
2.19078	184
2.18936	182
2.18795	184
2.18654	188
2.18513	188
2.18372	168
2.18231	176
2.18091	174
2.1795	170
2.1781	176
2.1767	176
2.1753	164
2.17391	172
2.17251	174
2.17112	162
2.16973	184
2.16834	180
2.16696	176
2.16557	166
2.16419	166
2.16281	174
2.16143	152
2.16005	182
2.15868	186
2.1573	156
2.15593	160
2.15456	172
2.1532	176
2.15183	174
2.15046	166
2.1491	152
2.14774	178
2.14638	170
2.14503	180
2.14367	168
2.14232	172
2.14097	162
2.13962	186
2.13827	176
2.13692	182
2.13558	172
2.13423	180
2.13289	192
2.13155	154
2.13022	172
2.12888	172
2.12755	174
2.12621	168
2.12488	172
2.12356	156
2.12223	174
2.1209	164
2.11958	180
2.11826	172
2.11694	178
2.11562	168
2.1143	174
2.11299	160
2.11168	168
2.11037	166
2.10906	172
2.10775	162
2.10644	146
2.10514	178
2.10384	174
2.10253	172
2.10123	170
2.09994	168
2.09864	184
2.09735	168
2.09605	172
2.09476	180
2.09347	170
2.09219	168
2.0909	168
2.08962	168
2.08834	156
2.08705	164
2.08578	174
2.0845	154
2.08322	180
2.08195	178
2.08068	170
2.0794	160.419
2.07814	168.055
2.07687	167.819
2.0756	171.912
2.07434	172.981
2.07307	179.816
2.07181	168.193
2.07055	162.109
2.0693	167.211
2.06804	183.303
2.06679	170.054
2.06553	182.077
2.06428	179.315
2.06303	173.905
2.06178	177.537
2.06069	178
2.05944	176
2.05819	180
2.05694	176
2.05569	182
2.05445	170
2.05321	180
2.05196	172
2.05072	156
2.04949	184
2.04825	180
2.04701	174
2.04578	166
2.04455	154
2.04332	176
2.04209	174
2.04086	166
2.03964	160
2.03841	172
2.03719	174
2.03597	166
2.03475	172
2.03353	186
2.03232	164
2.0311	172
2.02989	168
2.02868	162
2.02747	172
2.02626	172
2.02505	172
2.02384	162
2.02264	154
2.02144	172
2.02024	158
2.01904	182
2.01784	172
2.01664	172
2.01544	178
2.01425	170
2.01306	182
2.01187	188
2.01068	168
2.00949	174
2.0083	170
2.00712	204
2.00594	180
2.00475	176
2.00357	176
2.0024	184
2.00122	186
2.00004	174
1.99887	180
1.99769	178
1.99652	184
1.99535	180
1.99418	182
1.99302	204
1.99185	188
1.99069	184
1.98952	184
1.98836	194
1.9872	174
1.98604	178
1.98488	190
1.98373	186
1.98257	196
1.98142	186
1.98027	188
1.97912	208
1.97797	180
1.97682	194
1.97568	194
1.97453	186
1.97339	202
1.97225	212
1.97111	180
1.96997	194
1.96883	190
1.9677	184
1.96656	208
1.96543	204
1.9643	228
1.96316	182
1.96204	198
1.96091	226
1.95978	206
1.95866	196
1.95753	204
1.95641	200
1.95529	206
1.95417	196
1.95305	210
1.95193	206
1.95082	198
1.9497	276
1.94859	200
1.94748	182
1.94637	206
1.94526	220
1.94415	206
1.94305	202
1.94194	204
1.94084	204
1.93974	190
1.93864	200
1.93754	202
1.93644	202
1.93534	212
1.93425	218
1.93315	204
1.93206	194
1.93097	192
1.92988	196
1.92879	214
1.9277	210
1.92662	218
1.92553	212
1.92445	204.675
1.92337	214.74
1.92228	208.232
1.92121	214.661
1.92013	192.497
1.91905	214.109
1.91797	221.13
1.9169	214.829
1.91583	207.627
1.91475	202.051
1.91368	212.565
1.91261	209.884
1.91155	217.336
1.91048	221.873
1.90946	212
1.90839	222
1.90732	218
1.90626	212
1.90519	248
1.90413	220
1.90306	212
1.902	210
1.90094	214
1.89988	210
1.89882	208
1.89777	214
1.89671	204
1.89566	210
1.8946	218
1.89355	226
1.8925	222
1.89145	210
1.8904	212
1.88936	236
1.88831	220
1.88727	204
1.88622	218
1.88518	230
1.88414	242
1.8831	224
1.88206	204
1.88102	226
1.87999	222
1.87895	226
1.87792	208
1.87689	228
1.87586	206
1.87483	222
1.8738	208
1.87277	222
1.87174	226
1.87072	222
1.86969	224
1.86867	218
1.86765	232
1.86663	228
1.86561	232
1.86459	232
1.86357	208
1.86256	200
1.86154	216
1.86053	216
1.85952	228
1.85851	254
1.8575	458
1.85649	328
1.85548	236
1.85447	220
1.85347	240
1.85247	220
1.85146	228
1.85046	222
1.84946	248
1.84846	226
1.84746	216
1.84646	222
1.84547	232
1.84447	210
1.84348	220
1.84249	214
1.8415	212
1.84051	216
1.83952	222
1.83853	238
1.83754	222
1.83656	220
1.83557	224
1.83459	244
1.83361	226
1.83262	236
1.83164	214
1.83066	218
1.82969	236
1.82871	218
1.82773	224
1.82676	206
1.82579	228
1.82481	216
1.82384	224
1.82287	234
1.8219	224
1.82094	214
1.81997	208
1.819	210
1.81804	212
1.81708	206
1.81611	218
1.81515	212
1.81419	218
1.81323	226
1.81227	242
1.81132	202
1.81036	210
1.80941	206
1.80845	208
1.8075	202
1.80655	226
1.8056	218
1.80465	228
1.8037	202
1.80275	208
1.80181	216
1.80086	210
1.79992	214
1.79897	208
1.79803	192
1.79709	218
1.79615	210
1.79521	204
1.79428	204
1.79334	202
1.7924	210
1.79147	210.949
1.79053	199.296
1.7896	207.298
1.78867	213.637
1.78774	217.058
1.78681	208.363
1.78588	210.979
1.78496	200.137
1.78403	209.731
1.7831	210.265
1.78218	217.559
1.78126	204.213
1.78033	204.13
1.77941	217.569
1.77851	220
1.77759	214
1.77667	210
1.77575	202
1.77483	210
1.77391	218
1.77299	212
1.77207	204
1.77115	190
1.77024	196
1.76932	230
1.76841	210
1.7675	210
1.76659	208
1.76568	192
1.76477	188
1.76386	192
1.76295	204
1.76204	210
1.76114	186
1.76023	206
1.75933	214
1.75843	204
1.75753	202
1.75662	202
1.75572	288
1.75483	230
1.75393	214
1.75303	204
1.75214	208
1.75124	224
1.75035	194
1.74945	204
1.74856	196
1.74767	200
1.74678	210
1.74589	186
1.74501	202
1.74412	194
1.74323	204
1.74235	198
1.74146	202
1.74058	198
1.7397	192
1.73882	194
1.73794	190
1.73706	206
1.73618	182
1.7353	196
1.73443	194
1.73355	194
1.73268	172
1.7318	186
1.73093	194
1.73006	204
1.72919	178
1.72832	184
1.72745	180
1.72658	190
1.72571	188
1.72485	172
1.72398	182
1.72312	198
1.72225	180
1.72139	194
1.72053	190
1.71967	196
1.71881	172
1.71795	182
1.71709	164
1.71624	172
1.71538	180
1.71453	172
1.71367	440
1.71282	164
1.71197	176
1.71112	166
1.71027	164
1.70942	160
1.70857	188
1.70772	164
1.70687	150
1.70603	168
1.70518	174
1.70434	172
1.7035	308
1.70265	350
1.70181	156
1.70097	174
1.70013	184
1.69929	164
1.69846	164
1.69762	152
1.69678	170
1.69595	174
1.69511	176
1.69428	160
1.69345	152
1.69262	160
1.69179	160
1.69096	144
1.69013	150
1.6893	162
1.68847	212
1.68765	174
1.68682	146
1.686	156
1.68517	150
1.68435	158
1.68353	142
1.68271	160
1.68189	150
1.68107	142
1.68025	166
1.67943	150
1.67861	146
1.6778	142
1.67698	154
1.67617	158.559
1.67536	145.667
1.67454	148.203
1.67373	141.129
1.67292	139.912
1.67211	147.372
1.6713	153.246
1.6705	142.581
1.66969	156.302
1.66888	144.75
1.66808	147.646
1.66727	144.712
1.66647	151.234
1.66566	155.777
1.6649	156
1.66409	130
1.66329	142
1.66249	154
1.66168	160
1.66088	158
1.66008	160
1.65928	160
1.65848	152
1.65768	152
1.65688	136
1.65608	156
1.65529	152
1.65449	154
1.6537	158
1.6529	142
1.65211	142
1.65132	148
1.65053	144
1.64973	156
1.64894	144
1.64816	144
1.64737	144
1.64658	152
1.64579	146
1.64501	152
1.64422	144
1.64344	130
1.64265	140
1.64187	140
1.64109	144
1.64031	146
1.63953	130
1.63875	142
1.63797	142
1.63719	138
1.63642	144
1.63564	138
1.63486	142
1.63409	126
1.63331	126
1.63254	142
1.63177	130
1.631	138
1.63023	136
1.62946	122
1.62869	132
1.62792	134
1.62715	136
1.62639	128
1.62562	126
1.62485	136
1.62409	128
1.62333	116
1.62256	128
1.6218	122
1.62104	126
1.62028	126
1.61952	116
1.61876	126
1.618	112
1.61724	128
1.61649	132
1.61573	130
1.61498	124
1.61422	130
1.61347	120
1.61271	118
1.61196	122
1.61121	112
1.61046	114
1.60971	100
1.60896	108
1.60821	112
1.60747	118
1.60672	106
1.60597	114
1.60523	122
1.60448	130
1.60374	104
1.603	122
1.60225	106
1.60151	116
1.60077	114
1.60003	108
1.59929	104
1.59855	112
1.59782	114
1.59708	108
1.59634	112
1.59561	102
1.59487	100
1.59414	104
1.5934	102
1.59267	114
1.59194	106
1.59121	102
1.59048	112
1.58975	104
1.58902	108
1.58829	102
1.58756	112
1.58684	100
1.58611	94
1.58538	104
1.58466	112
1.58394	100
1.58321	84
1.58249	108
1.58177	96
1.58105	108
1.58033	104
1.57961	108
1.57889	98
1.57817	92
1.57745	82
1.57674	88
1.57602	101.967
1.5753	105.145
1.57459	96.7897
1.57388	88.5545
1.57316	91.6931
1.57245	97.0423
1.57174	91.5179
1.57103	93.1922
1.57032	88.5836
1.56961	98.6021
1.5689	89.636
1.56819	81.419
1.56748	97.06
1.56678	98.698
1.56607	84.6044
1.56544	86
1.56473	100
1.56402	90
1.56331	92
1.56261	84
1.5619	106
1.56119	90
1.56049	88
1.55979	90
1.55908	84
1.55838	82
1.55768	90
1.55698	84
1.55628	84
1.55558	80
1.55488	84
1.55418	76
1.55348	88
1.55278	72
1.55209	64
1.55139	72
1.5507	82
1.55	88
1.54931	80
1.54862	82
1.54792	96
1.54723	98
1.54654	84
1.54585	90
1.54516	72
1.54447	80
1.54378	82
1.5431	80
1.54241	78
1.54172	76
1.54104	80
1.54035	86
1.53967	92
1.53898	80
1.5383	74
1.53762	108
1.53694	78
1.53626	78
1.53558	68
1.5349	72
1.53422	70
1.53354	82
1.53286	66
1.53218	74
1.53151	76
1.53083	70
1.53016	80
1.52948	68
1.52881	84
1.52813	86
1.52746	76
1.52679	82
1.52612	60
1.52545	66
1.52478	74
1.52411	78
1.52344	62
1.52277	74
1.5221	68
1.52144	78
1.52077	66
1.52011	72
1.51944	76
1.51878	70
1.51811	62
1.51745	76
1.51679	78
1.51613	60
1.51547	58
1.51481	68
1.51415	78
1.51349	72
1.51283	68
1.51217	74
1.51151	74
1.51086	64
1.5102	70
1.50954	62
1.50889	74
1.50824	54
1.50758	68
1.50693	70
1.50628	62
1.50563	66
1.50497	62
1.50432	62
1.50367	64
1.50302	60
1.50238	68
1.50173	56
1.50108	70
1.50043	74
1.49979	64
1.49914	64
1.4985	64
1.49785	68
1.49721	58
1.49657	64
1.49592	54
1.49528	66
1.49464	64
1.494	72
1.49336	58
1.49272	48
1.49208	58
1.49144	54
1.49081	62
1.49017	48
1.48953	60
1.4889	58
1.48826	62
1.48763	54
1.48699	59.9604
1.48636	55.703
1.48573	51.3422
1.4851	54.6697
1.48446	54.5252
1.48383	58.5941
1.4832	65.2918
1.48257	60.1718
1.48194	56.9166
1.48132	57.4851
1.48069	53.8469
1.48006	52.8169
1.47943	57.617
1.47881	51.6428
1.47818	52.3088
1.47756	56
1.47694	56
1.47631	54
1.47568	56
1.47505	50
1.47443	46
1.4738	46
1.47318	60
1.47256	54
1.47193	48
1.47131	56
1.47069	44
1.47006	54
1.46944	50
1.46882	56
1.4682	44
1.46758	52
1.46696	54
1.46635	58
1.46573	44
1.46511	40
1.46449	54
1.46388	50
1.46326	44
1.46265	42
1.46203	42
1.46142	54
1.46081	48
1.46019	48
1.45958	32
1.45897	40
1.45836	48
1.45775	46
1.45714	40
1.45653	46
1.45592	40
1.45531	38
1.4547	34
1.4541	44
1.45349	36
1.45288	38
1.45228	34
1.45167	38
1.45107	32
1.45047	24
1.44986	20
1.44926	30
1.44866	30
1.44806	30
1.44746	30
1.44686	28
1.44626	36
1.44566	30
1.44506	22
1.44446	28
1.44386	34
1.44326	34
1.44267	38
1.44207	26
1.44148	28
1.44088	26
1.44029	34
1.43969	34
1.4391	30
1.43851	20
1.43791	28
1.43732	32
1.43673	34
1.43614	32
1.43555	30
1.43496	38
1.43437	38
1.43378	28
1.4332	28
1.43261	24
1.43202	26
1.43143	26
1.43085	30
1.43026	22
1.42968	36
1.42909	26
1.42851	22
1.42793	30
1.42734	32
1.42676	28
1.42618	28
1.4256	28
1.42502	24
1.42444	20
1.42386	26
1.42328	26
1.4227	36
1.42212	28
1.42155	28
1.42097	32
1.42039	28
1.41982	28
1.41924	30
1.41867	26
1.41809	32
1.41752	30
1.41695	34
1.41637	32
1.4158	18
1.41523	32
1.41466	34
1.41409	34
1.41352	28
1.41295	26
1.41238	34
1.41181	34
1.41124	24
1.41067	28
1.41011	30
1.40954	22
1.40897	40
1.40841	34
1.40784	39.9613
1.40728	36.7086
1.40672	39.4257
1.40615	40.4411
1.40559	46.4306
1.40503	54.6699
1.40446	4981.87
1.4039	133.902
1.40334	65.0152
1.40278	49.1456
1.40222	44.4296
1.40166	45.7175
1.4011	45.2268
1.40054	41.4963
1.39999	46.0659
1.39947	38
1.3989	52
1.39834	46
1.39779	48
1.39723	44
1.39667	46
1.39611	44
1.39555	42
1.395	38
1.39444	44
1.39388	38
1.39333	50
1.39277	44
1.39222	44
1.39166	42
1.39111	48
1.39056	40
1.39	46
1.38945	48
1.3889	44
1.38835	34
1.3878	48
1.38725	46
1.3867	44
1.38615	44
1.3856	46
1.38505	40
1.3845	44
1.38396	46
1.38341	48
1.38286	32
1.38232	40
1.38177	46
1.38123	42
1.38068	36
1.38014	56
1.3796	42
1.37905	52
1.37851	46
1.37797	44
1.37743	44
1.37688	44
1.37634	42
1.3758	40
1.37526	30
1.37472	46
1.37419	50
1.37365	48
1.37311	42
1.37257	38
1.37204	50
1.3715	46
1.37096	50
1.37043	32
1.36989	38
1.36936	36
1.36882	44
1.36829	46
1.36776	44
1.36722	40
1.36669	42
1.36616	44
1.36563	48
1.3651	48
1.36457	46
1.36404	30
1.36351	46
1.36298	48
1.36245	38
1.36192	48
1.36139	52
1.36087	42
1.36034	38
1.35981	40
1.35929	46
1.35876	44
1.35824	46
1.35771	42
1.35719	38
1.35667	36
1.35614	50
1.35562	46
1.3551	48
1.35458	34
1.35406	32
1.35353	42
1.35301	42
1.35249	44
1.35197	50
1.35146	38
1.35094	40
1.35042	52
1.3499	40
1.34938	32
1.34887	32
1.34835	40
1.34783	40
1.34732	34
1.3468	44
1.34629	40
1.34578	38
1.34526	42
1.34475	52
1.34424	40
1.34372	40
1.34321	50
1.3427	38
1.34219	38
1.34168	38
1.34117	38
1.34066	34
1.34015	50
1.33964	42
1.33913	28
1.33862	42
1.33812	38
1.33761	32
1.3371	38.022
1.3366	38.2335
1.33609	34.1798
1.33558	37.1768
1.33508	35.2833
1.33457	37.0266
1.33407	35.6467
1.33357	37.6252
1.33306	37.7282
1.33256	35.9038
1.33206	37.7103
1.33156	34.1436
1.33105	40.1737
1.33055	39.042
1.33005	35.4884
1.32959	38
1.32909	38
1.32859	38
1.32809	36
1.32758	46
1.32708	28
1.32658	32
1.32608	32
1.32558	32
1.32508	36
1.32458	32
1.32408	38
1.32358	36
1.32309	34
1.32259	34
1.32209	34
1.3216	42
1.3211	46
1.3206	42
1.32011	28
1.31961	34
1.31912	42
1.31862	42
1.31813	36
1.31764	38
1.31714	38
1.31665	34
1.31616	38
1.31567	40
1.31518	40
1.31468	44
1.31419	34
1.3137	40
1.31321	40
1.31272	42
1.31224	34
1.31175	38
1.31126	36
1.31077	46
1.31028	36
1.3098	38
1.30931	30
1.30882	42
1.30834	32
1.30785	46
1.30737	34
1.30688	44
1.3064	36
1.30592	46
1.30543	46
1.30495	30
1.30447	36
1.30399	36
1.3035	40
1.30302	34
1.30254	32
1.30206	34
1.30158	40
1.3011	38
1.30062	32
1.30014	34
1.30001	38