File: ploting_and_data_tools/raman/CdSe2_02.txt
#Acq. time (s)=	1
#Accumulations=	1
#Range (eV)=	2...1
#Windows=	11
#Autofocus=	Off
#AutoExposure=	Off
#Spike filter=	Off
#Delay time (s)=	0
#Binning=	1
#Readout mode=	Signal
#DeNoise=	Off
#ICS correction=	Off
#Dark correction=	Off
#Inst. Process=	Off
#Instrument=	LabRAM HR Evol
#Detector=	Syncerity OE
#Objective=	x100_VIS_LWD
#Grating=	600 (500nm)
#ND Filter=	1%
#Laser=	442nm_Notch
#Hole=	150.001
#Range=	Visible
#Project=	Paty
#Sample=
#Site=	15-06-22
#Title=	CdSe2
#Remark=
#Date=	15.06.2022 21:05
#Acquired=	15.06.2022 21:05:32
2.74975	30
2.7475	24
2.74525	46
2.743	34
2.74076	36
2.73852	30
2.73629	34
2.73406	32
2.73183	36
2.72961	26
2.72739	32
2.72517	32
2.72296	36
2.72075	34
2.71854	34
2.71634	34
2.71414	34
2.71195	40
2.70976	30
2.70757	24
2.70539	32
2.70321	32
2.70103	34
2.69886	34
2.69669	38
2.69452	30
2.69236	42
2.6902	36
2.68805	36
2.6859	44
2.68375	42
2.68161	46
2.67947	42
2.67733	40
2.6752	46
2.67307	46
2.67094	50
2.66882	36
2.6667	42
2.66458	40
2.66247	48
2.66036	46
2.65826	52
2.65615	56
2.65405	48
2.65196	50
2.64987	54
2.64778	50
2.64569	52
2.64361	56
2.64153	52
2.63946	58
2.63739	54
2.63532	54
2.63325	62
2.63119	66
2.62913	68
2.62708	70
2.62503	76
2.62298	78
2.62094	82
2.61889	82
2.61686	76
2.61482	100
2.61279	86
2.61076	94
2.60873	82
2.60671	92
2.60469	98
2.60268	106
2.60067	106
2.59866	106
2.59665	102
2.59465	114
2.59265	130
2.59065	120
2.58866	116
2.58667	130
2.58468	140
2.5827	156
2.58072	152
2.57874	154
2.57677	150
2.5748	148
2.57283	180
2.57086	174
2.5689	196
2.56694	196
2.56499	210
2.56304	222
2.56109	226
2.55914	230
2.5572	250
2.55526	264
2.55332	264
2.55139	282
2.54946	276
2.54753	320
2.5456	302
2.54368	348
2.54176	348
2.53985	358
2.53794	370
2.53603	418
2.53412	396
2.53222	432
2.53031	478
2.52842	514
2.52652	500
2.52463	526
2.52274	550
2.52085	558
2.51897	582
2.51709	580
2.51521	632
2.51334	676
2.51147	726
2.5096	730
2.50773	748
2.50587	806
2.50401	800
2.50216	872
2.5003	898
2.49845	896
2.4966	956
2.49476	1012
2.49291	998
2.49107	1076
2.48924	1094
2.4874	1118
2.48557	1174
2.48374	1208
2.48192	1250.68
2.48009	1306.99
2.47827	1418.71
2.47646	1431.62
2.47464	1493.09
2.47283	1559.5
2.47102	1595.09
2.46922	1696.67
2.46741	1753.95
2.46561	1814.35
2.46381	1888.11
2.46202	1962.88
2.46023	2049.64
2.45844	2153.44
2.45665	2204.45
2.45493	2230
2.45314	2382
2.45136	2394
2.44957	2438
2.44779	2566
2.44601	2610
2.44424	2642
2.44247	2756
2.4407	2872
2.43893	2870
2.43716	3010
2.4354	3014
2.43364	3112
2.43188	3132
2.43013	3220
2.42838	3326
2.42663	3404
2.42488	3498
2.42314	3548
2.4214	3606
2.41966	3720
2.41792	3698
2.41619	3790
2.41446	3836
2.41273	3998
2.411	4148
2.40928	4110
2.40756	4200
2.40584	4224
2.40413	4272
2.40241	4336
2.4007	4424
2.39899	4482
2.39729	4502
2.39559	4470
2.39389	4544
2.39219	4730
2.39049	4738
2.3888	4850
2.38711	4914
2.38542	4944
2.38374	4952
2.38205	5008
2.38037	5024
2.37869	5180
2.37702	5150
2.37535	5360
2.37368	5284
2.37201	5242
2.37034	5254
2.36868	5276
2.36702	5326
2.36536	5374
2.3637	5290
2.36205	5354
2.3604	5238
2.35875	5190
2.3571	5298
2.35546	5282
2.35382	5272
2.35218	5216
2.35054	5198
2.34891	5242
2.34727	5192
2.34564	5128
2.34402	5110
2.34239	5068
2.34077	4946
2.33915	5084
2.33753	5004
2.33591	4844
2.3343	4934
2.33269	4916
2.33108	4764
2.32948	4826
2.32787	4766
2.32627	4672
2.32467	4784
2.32307	4654
2.32148	4550
2.31989	4550
2.3183	4470
2.31671	4410
2.31512	4414
2.31354	4336
2.31196	4326
2.31038	4248
2.3088	4224
2.30723	4148
2.30565	4142
2.30408	4190
2.30252	4078
2.30095	3944
2.29939	4042
2.29783	3962
2.29627	3868
2.29471	3698
2.29316	3782
2.29161	3716
2.29006	3762
2.28851	3668
2.28696	3620
2.28542	3604
2.28388	3590
2.28234	3534
2.2808	3438
2.27927	3458
2.27773	3424
2.2762	3386
2.27468	3398
2.27315	3278
2.27163	3258
2.27011	3144
2.26859	3112
2.26707	3116
2.26555	3016
2.26404	3068
2.26253	3011.45
2.26102	2917.73
2.25951	2904.32
2.25801	2865.07
2.25651	2811.13
2.25501	2754.39
2.25351	2746.15
2.25201	2657.17
2.25052	2622.9
2.24902	2563.28
2.24753	2550.78
2.24605	2476.45
2.24456	2449.84
2.24308	2381.16
2.2416	2324.81
2.24011	2324
2.23863	2292
2.23715	2222
2.23567	2208
2.23419	2162
2.23271	2094
2.23124	2130
2.22977	2104
2.2283	2060
2.22683	2084
2.22536	1958
2.2239	1940
2.22244	1966
2.22098	1924
2.21952	1912
2.21807	1864
2.21661	1882
2.21516	1836
2.21371	1856
2.21226	1774
2.21082	1764
2.20937	1784
2.20793	1754
2.20649	1714
2.20505	1688
2.20362	1710
2.20218	1634
2.20075	1664
2.19932	1664
2.19789	1666
2.19647	1618
2.19504	1540
2.19362	1536
2.1922	1556
2.19078	1548
2.18936	1498
2.18795	1522
2.18654	1512
2.18513	1460
2.18372	1506
2.18231	1488
2.18091	1460
2.1795	1460
2.1781	1506
2.1767	1442
2.1753	1422
2.17391	1414
2.17251	1402
2.17112	1400
2.16973	1434
2.16834	1416
2.16696	1430
2.16557	1398
2.16419	1410
2.16281	1416
2.16143	1356
2.16005	1350
2.15868	1368
2.1573	1346
2.15593	1334
2.15456	1386
2.1532	1346
2.15183	1392
2.15046	1340
2.1491	1362
2.14774	1358
2.14638	1348
2.14503	1308
2.14367	1310
2.14232	1336
2.14097	1314
2.13962	1288
2.13827	1340
2.13692	1334
2.13558	1308
2.13423	1302
2.13289	1342
2.13155	1318
2.13022	1298
2.12888	1300
2.12755	1322
2.12621	1312
2.12488	1334
2.12356	1310
2.12223	1362
2.1209	1330
2.11958	1254
2.11826	1280
2.11694	1308
2.11562	1298
2.1143	1292
2.11299	1312
2.11168	1262
2.11037	1344
2.10906	1318
2.10775	1304
2.10644	1286
2.10514	1278
2.10384	1252
2.10253	1306
2.10123	1254
2.09994	1262
2.09864	1252
2.09735	1266
2.09605	1312
2.09476	1232
2.09347	1270
2.09219	1312
2.0909	1300
2.08962	1310
2.08834	1294
2.08705	1318
2.08578	1240
2.0845	1324
2.08322	1294
2.08195	1298
2.08068	1254
2.0794	1275.44
2.07814	1271.95
2.07687	1254.84
2.0756	1223.03
2.07434	1273.99
2.07307	1255.39
2.07181	1194.57
2.07055	1213.5
2.0693	1206.63
2.06804	1211.03
2.06679	1173.06
2.06553	1183.28
2.06428	1175.99
2.06303	1173.38
2.06178	1137.43
2.06069	1150
2.05944	1148
2.05819	1156
2.05694	1212
2.05569	1166
2.05445	1130
2.05321	1180
2.05196	1182
2.05072	1152
2.04949	1162
2.04825	1220
2.04701	1142
2.04578	1162
2.04455	1138
2.04332	1114
2.04209	1102
2.04086	1132
2.03964	1092
2.03841	1100
2.03719	1120
2.03597	1140
2.03475	1142
2.03353	1098
2.03232	1072
2.0311	1130
2.02989	1118
2.02868	1104
2.02747	1108
2.02626	1116
2.02505	1120
2.02384	1098
2.02264	1072
2.02144	1058
2.02024	1138
2.01904	1124
2.01784	1194
2.01664	1092
2.01544	1144
2.01425	1118
2.01306	1110
2.01187	1140
2.01068	1102
2.00949	1138
2.0083	1124
2.00712	1142
2.00594	1158
2.00475	1178
2.00357	1128
2.0024	1134
2.00122	1188
2.00004	1190
1.99887	1172
1.99769	1208
1.99652	1208
1.99535	1160
1.99418	1174
1.99302	1212
1.99185	1210
1.99069	1198
1.98952	1234
1.98836	1214
1.9872	1202
1.98604	1238
1.98488	1216
1.98373	1212
1.98257	1230
1.98142	1226
1.98027	1230
1.97912	1250
1.97797	1212
1.97682	1248
1.97568	1214
1.97453	1298
1.97339	1302
1.97225	1246
1.97111	1246
1.96997	1244
1.96883	1252
1.9677	1254
1.96656	1260
1.96543	1270
1.9643	1268
1.96316	1250
1.96204	1232
1.96091	1252
1.95978	1276
1.95866	1274
1.95753	1280
1.95641	1256
1.95529	1276
1.95417	1290
1.95305	1266
1.95193	1272
1.95082	1304
1.9497	1274
1.94859	1274
1.94748	1272
1.94637	1304
1.94526	1284
1.94415	1288
1.94305	1276
1.94194	1280
1.94084	1282
1.93974	1314
1.93864	1334
1.93754	1264
1.93644	1284
1.93534	1250
1.93425	1290
1.93315	1288
1.93206	1292
1.93097	1306
1.92988	1316
1.92879	1304
1.9277	1342
1.92662	1322
1.92553	1316
1.92445	1289.37
1.92337	1316.73
1.92228	1260.47
1.92121	1298.46
1.92013	1289.4
1.91905	1290.84
1.91797	1301.89
1.9169	1287.24
1.91583	1254.58
1.91475	1252.7
1.91368	1254.98
1.91261	1256.85
1.91155	1263.44
1.91048	1239.05
1.90946	1196
1.90839	1280
1.90732	1216
1.90626	1260
1.90519	1256
1.90413	1256
1.90306	1292
1.902	1286
1.90094	1262
1.89988	1280
1.89882	1210
1.89777	1220
1.89671	1232
1.89566	1232
1.8946	1222
1.89355	1232
1.8925	1262
1.89145	1238
1.8904	1230
1.88936	1224
1.88831	1210
1.88727	1246
1.88622	1264
1.88518	1222
1.88414	1252
1.8831	1212
1.88206	1220
1.88102	1236
1.87999	1222
1.87895	1212
1.87792	1208
1.87689	1200
1.87586	1288
1.87483	1184
1.8738	1204
1.87277	1236
1.87174	1206
1.87072	1188
1.86969	1218
1.86867	1226
1.86765	1218
1.86663	1200
1.86561	1212
1.86459	1222
1.86357	1218
1.86256	1164
1.86154	1190
1.86053	1216
1.85952	1176
1.85851	1196
1.8575	1230
1.85649	1238
1.85548	1196
1.85447	1184
1.85347	1232
1.85247	1192
1.85146	1186
1.85046	1164
1.84946	1222
1.84846	1200
1.84746	1170
1.84646	1160
1.84547	1236
1.84447	1170
1.84348	1188
1.84249	1188
1.8415	1198
1.84051	1190
1.83952	1200
1.83853	1182
1.83754	1188
1.83656	1162
1.83557	1148
1.83459	1160
1.83361	1160
1.83262	1152
1.83164	1124
1.83066	1204
1.82969	1144
1.82871	1142
1.82773	1162
1.82676	1150
1.82579	1160
1.82481	1140
1.82384	1154
1.82287	1166
1.8219	1170
1.82094	1124
1.81997	1138
1.819	1140
1.81804	1134
1.81708	1134
1.81611	1152
1.81515	1118
1.81419	1090
1.81323	1102
1.81227	1156
1.81132	1112
1.81036	1116
1.80941	1130
1.80845	1080
1.8075	1096
1.80655	1132
1.8056	1090
1.80465	1062
1.8037	1066
1.80275	1086
1.80181	1060
1.80086	1092
1.79992	1078
1.79897	1070
1.79803	1066
1.79709	1084
1.79615	1064
1.79521	1034
1.79428	1074
1.79334	1030
1.7924	1072
1.79147	1042.38
1.79053	1054.29
1.7896	1062.47
1.78867	1019.89
1.78774	1045.37
1.78681	1023.07
1.78588	1024.85
1.78496	1038
1.78403	1013.03
1.7831	1019.05
1.78218	1007.39
1.78126	980.191
1.78033	975.991
1.77941	956.207
1.77851	970
1.77759	978
1.77667	952
1.77575	968
1.77483	968
1.77391	986
1.77299	920
1.77207	954
1.77115	970
1.77024	870
1.76932	936
1.76841	954
1.7675	926
1.76659	954
1.76568	904
1.76477	864
1.76386	914
1.76295	940
1.76204	904
1.76114	906
1.76023	882
1.75933	928
1.75843	842
1.75753	894
1.75662	878
1.75572	844
1.75483	896
1.75393	898
1.75303	866
1.75214	892
1.75124	880
1.75035	822
1.74945	864
1.74856	854
1.74767	862
1.74678	844
1.74589	842
1.74501	844
1.74412	880
1.74323	866
1.74235	804
1.74146	818
1.74058	816
1.7397	800
1.73882	826
1.73794	812
1.73706	776
1.73618	808
1.7353	764
1.73443	804
1.73355	764
1.73268	766
1.7318	748
1.73093	764
1.73006	744
1.72919	788
1.72832	764
1.72745	778
1.72658	738
1.72571	760
1.72485	758
1.72398	718
1.72312	776
1.72225	714
1.72139	718
1.72053	732
1.71967	720
1.71881	742
1.71795	708
1.71709	706
1.71624	696
1.71538	706
1.71453	688
1.71367	710
1.71282	668
1.71197	684
1.71112	658
1.71027	656
1.70942	702
1.70857	660
1.70772	662
1.70687	666
1.70603	658
1.70518	654
1.70434	626
1.7035	646
1.70265	654
1.70181	636
1.70097	610
1.70013	626
1.69929	576
1.69846	644
1.69762	620
1.69678	594
1.69595	640
1.69511	584
1.69428	588
1.69345	592
1.69262	592
1.69179	606
1.69096	588
1.69013	560
1.6893	582
1.68847	572
1.68765	546
1.68682	558
1.686	538
1.68517	584
1.68435	566
1.68353	564
1.68271	536
1.68189	550
1.68107	530
1.68025	528
1.67943	534
1.67861	552
1.6778	520
1.67698	534.078
1.67617	492.963
1.67536	526.38
1.67454	525.344
1.67373	523.362
1.67292	528.212
1.67211	530.68
1.6713	514.472
1.6705	512.769
1.66969	524.717
1.66888	513.086
1.66808	522.932
1.66727	500.511
1.66647	502.4
1.66566	517.924
1.6649	526
1.66409	508
1.66329	478
1.66249	528
1.66168	504
1.66088	502
1.66008	500
1.65928	476
1.65848	494
1.65768	460
1.65688	486
1.65608	454
1.65529	476
1.65449	484
1.6537	454
1.6529	462
1.65211	476
1.65132	462
1.65053	450
1.64973	446
1.64894	456
1.64816	446
1.64737	426
1.64658	444
1.64579	466
1.64501	434
1.64422	420
1.64344	426
1.64265	440
1.64187	426
1.64109	424
1.64031	426
1.63953	412
1.63875	408
1.63797	414
1.63719	408
1.63642	418
1.63564	414
1.63486	406
1.63409	408
1.63331	390
1.63254	380
1.63177	370
1.631	372
1.63023	386
1.62946	384
1.62869	368
1.62792	380
1.62715	374
1.62639	358
1.62562	358
1.62485	350
1.62409	358
1.62333	360
1.62256	348
1.6218	350
1.62104	348
1.62028	352
1.61952	356
1.61876	346
1.618	332
1.61724	356
1.61649	334
1.61573	334
1.61498	320
1.61422	338
1.61347	328
1.61271	320
1.61196	328
1.61121	346
1.61046	300
1.60971	332
1.60896	312
1.60821	328
1.60747	316
1.60672	286
1.60597	306
1.60523	288
1.60448	298
1.60374	312
1.603	286
1.60225	320
1.60151	294
1.60077	292
1.60003	284
1.59929	290
1.59855	278
1.59782	300
1.59708	282
1.59634	274
1.59561	282
1.59487	276
1.59414	274
1.5934	254
1.59267	262
1.59194	258
1.59121	262
1.59048	254
1.58975	268
1.58902	258
1.58829	260
1.58756	264
1.58684	238
1.58611	234
1.58538	236
1.58466	246
1.58394	254
1.58321	242
1.58249	228
1.58177	238
1.58105	234
1.58033	220
1.57961	230
1.57889	218
1.57817	224
1.57745	228
1.57674	234
1.57602	229.903
1.5753	227.846
1.57459	212.997
1.57388	219.339
1.57316	210.208
1.57245	204.788
1.57174	205.449
1.57103	196.664
1.57032	197.335
1.56961	203.283
1.5689	185.25
1.56819	193.954
1.56748	189.598
1.56678	189.317
1.56607	176.57
1.56544	180
1.56473	196
1.56402	200
1.56331	178
1.56261	178
1.5619	182
1.56119	192
1.56049	180
1.55979	164
1.55908	172
1.55838	180
1.55768	182
1.55698	170
1.55628	182
1.55558	172
1.55488	162
1.55418	166
1.55348	168
1.55278	168
1.55209	156
1.55139	156
1.5507	162
1.55	166
1.54931	158
1.54862	152
1.54792	150
1.54723	158
1.54654	146
1.54585	150
1.54516	148
1.54447	156
1.54378	150
1.5431	144
1.54241	154
1.54172	146
1.54104	154
1.54035	124
1.53967	152
1.53898	142
1.5383	138
1.53762	154
1.53694	130
1.53626	130
1.53558	138
1.5349	128
1.53422	124
1.53354	138
1.53286	140
1.53218	132
1.53151	122
1.53083	128
1.53016	138
1.52948	134
1.52881	128
1.52813	120
1.52746	120
1.52679	132
1.52612	138
1.52545	126
1.52478	130
1.52411	130
1.52344	128
1.52277	132
1.5221	122
1.52144	116
1.52077	114
1.52011	142
1.51944	118
1.51878	120
1.51811	118
1.51745	106
1.51679	110
1.51613	124
1.51547	112
1.51481	112
1.51415	102
1.51349	110
1.51283	114
1.51217	108
1.51151	106
1.51086	116
1.5102	102
1.50954	112
1.50889	104
1.50824	120
1.50758	116
1.50693	116
1.50628	116
1.50563	100
1.50497	106
1.50432	100
1.50367	96
1.50302	90
1.50238	98
1.50173	100
1.50108	82
1.50043	98
1.49979	94
1.49914	104
1.4985	92
1.49785	88
1.49721	90
1.49657	100
1.49592	96
1.49528	90
1.49464	100
1.494	94
1.49336	92
1.49272	84
1.49208	98
1.49144	82
1.49081	92
1.49017	84
1.48953	78
1.4889	86
1.48826	82
1.48763	76
1.48699	83.9901
1.48636	94.7602
1.48573	87.1386
1.4851	79.2151
1.48446	83.7817
1.48383	82.2925
1.4832	85.8666
1.48257	75.6328
1.48194	67.484
1.48132	75.7008
1.48069	67.5628
1.48006	66.8564
1.47943	69.9604
1.47881	79.2453
1.47818	69.0631
1.47756	82
1.47694	56
1.47631	78
1.47568	66
1.47505	58
1.47443	66
1.4738	70
1.47318	80
1.47256	66
1.47193	76
1.47131	72
1.47069	64
1.47006	60
1.46944	50
1.46882	66
1.4682	60
1.46758	68
1.46696	62
1.46635	56
1.46573	64
1.46511	58
1.46449	60
1.46388	58
1.46326	56
1.46265	54
1.46203	62
1.46142	64
1.46081	48
1.46019	40
1.45958	36
1.45897	42
1.45836	46
1.45775	42
1.45714	54
1.45653	54
1.45592	42
1.45531	42
1.4547	38
1.4541	30
1.45349	48
1.45288	40
1.45228	42
1.45167	34
1.45107	34
1.45047	30
1.44986	30
1.44926	26
1.44866	34
1.44806	20
1.44746	34
1.44686	24
1.44626	30
1.44566	32
1.44506	30
1.44446	30
1.44386	30
1.44326	22
1.44267	28
1.44207	32
1.44148	28
1.44088	28
1.44029	30
1.43969	24
1.4391	32
1.43851	28
1.43791	30
1.43732	22
1.43673	28
1.43614	32
1.43555	22
1.43496	20
1.43437	30
1.43378	28
1.4332	36
1.43261	38
1.43202	28
1.43143	36
1.43085	28
1.43026	18
1.42968	34
1.42909	28
1.42851	30
1.42793	26
1.42734	30
1.42676	36
1.42618	20
1.4256	30
1.42502	28
1.42444	20
1.42386	28
1.42328	28
1.4227	32
1.42212	22
1.42155	30
1.42097	32
1.42039	24
1.41982	32
1.41924	28
1.41867	28
1.41809	20
1.41752	30
1.41695	30
1.41637	26
1.4158	30
1.41523	28
1.41466	24
1.41409	26
1.41352	24
1.41295	26
1.41238	26
1.41181	28
1.41124	30
1.41067	32
1.41011	26
1.40954	24
1.40897	36
1.40841	42
1.40784	35.9496
1.40728	32.2631
1.40672	34.8567
1.40615	39.9327
1.40559	37.1722
1.40503	39.297
1.40446	132.886
1.4039	40.0792
1.40334	41.866
1.40278	43.668
1.40222	39.2753
1.40166	40.7921
1.4011	39.6733
1.40054	49.2475
1.39999	44.0495
1.39947	50
1.3989	38
1.39834	44
1.39779	48
1.39723	48
1.39667	42
1.39611	44
1.39555	42
1.395	54
1.39444	46
1.39388	44
1.39333	46
1.39277	46
1.39222	42
1.39166	42
1.39111	42
1.39056	36
1.39	48
1.38945	40
1.3889	44
1.38835	44
1.3878	46
1.38725	46
1.3867	50
1.38615	44
1.3856	40
1.38505	30
1.3845	44
1.38396	44
1.38341	40
1.38286	44
1.38232	44
1.38177	44
1.38123	40
1.38068	48
1.38014	48
1.3796	42
1.37905	42
1.37851	42
1.37797	44
1.37743	48
1.37688	34
1.37634	46
1.3758	42
1.37526	42
1.37472	42
1.37419	42
1.37365	36
1.37311	46
1.37257	36
1.37204	44
1.3715	42
1.37096	40
1.37043	54
1.36989	42
1.36936	42
1.36882	42
1.36829	46
1.36776	36
1.36722	46
1.36669	34
1.36616	44
1.36563	48
1.3651	42
1.36457	38
1.36404	46
1.36351	46
1.36298	44
1.36245	38
1.36192	36
1.36139	44
1.36087	34
1.36034	50
1.35981	40
1.35929	42
1.35876	40
1.35824	42
1.35771	48
1.35719	44
1.35667	34
1.35614	36
1.35562	38
1.3551	42
1.35458	38
1.35406	32
1.35353	42
1.35301	34
1.35249	38
1.35197	26
1.35146	44
1.35094	40
1.35042	42
1.3499	52
1.34938	36
1.34887	36
1.34835	46
1.34783	38
1.34732	34
1.3468	32
1.34629	42
1.34578	32
1.34526	40
1.34475	40
1.34424	32
1.34372	36
1.34321	36
1.3427	46
1.34219	36
1.34168	38
1.34117	32
1.34066	44
1.34015	34
1.33964	44
1.33913	34
1.33862	34
1.33812	38
1.33761	36
1.3371	37.9295
1.3366	33.4466
1.33609	37.6347
1.33558	29.2795
1.33508	43.7299
1.33457	29.6839
1.33407	32.9184
1.33357	34.075
1.33306	34.8614
1.33256	39.8509
1.33206	34.882
1.33156	32.276
1.33105	33.6055
1.33055	35.3384
1.33005	34.9261
1.32959	28
1.32909	34
1.32859	32
1.32809	30
1.32758	42
1.32708	34
1.32658	36
1.32608	36
1.32558	28
1.32508	24
1.32458	42
1.32408	42
1.32358	42
1.32309	40
1.32259	26
1.32209	30
1.3216	44
1.3211	42
1.3206	34
1.32011	28
1.31961	34
1.31912	46
1.31862	38
1.31813	36
1.31764	34
1.31714	30
1.31665	42
1.31616	30
1.31567	38
1.31518	34
1.31468	42
1.31419	38
1.3137	38
1.31321	34
1.31272	34
1.31224	28
1.31175	42
1.31126	24
1.31077	38
1.31028	26
1.3098	30
1.30931	30
1.30882	44
1.30834	34
1.30785	28
1.30737	34
1.30688	44
1.3064	44
1.30592	40
1.30543	34
1.30495	34
1.30447	32
1.30399	36
1.3035	30
1.30302	38
1.30254	34
1.30206	40
1.30158	36
1.3011	38
1.30062	36
1.30014	44
1.30001	40