File: ploting_and_data_tools.ipynb/___archivosraman/CdSe1_13.txt
#Acq. time (s)=	1
#Accumulations=	1
#Range (eV)=	2...1
#Windows=	11
#Autofocus=	Off
#AutoExposure=	Off
#Spike filter=	Off
#Delay time (s)=	0
#Binning=	1
#Readout mode=	Signal
#DeNoise=	Off
#ICS correction=	Off
#Dark correction=	Off
#Inst. Process=	Off
#Instrument=	LabRAM HR Evol
#Detector=	Syncerity OE
#Objective=	x100_VIS_LWD
#Grating=	600 (500nm)
#ND Filter=	1%
#Laser=	442nm_Notch
#Hole=	100.021
#Range=	Visible
#Project=	Paty
#Sample=
#Site=	15-06-22
#Title=	CdSe1
#Remark=
#Date=	15.06.2022 20:38
#Acquired=	15.06.2022 20:38:50
2.74975	22
2.7475	26
2.74525	30
2.743	30
2.74076	24
2.73852	26
2.73629	28
2.73406	30
2.73183	22
2.72961	24
2.72739	26
2.72517	30
2.72296	32
2.72075	26
2.71854	20
2.71634	28
2.71414	26
2.71195	28
2.70976	30
2.70757	28
2.70539	34
2.70321	30
2.70103	30
2.69886	24
2.69669	36
2.69452	34
2.69236	30
2.6902	32
2.68805	26
2.6859	36
2.68375	28
2.68161	38
2.67947	26
2.67733	24
2.6752	28
2.67307	32
2.67094	34
2.66882	34
2.6667	32
2.66458	24
2.66247	34
2.66036	36
2.65826	32
2.65615	42
2.65405	32
2.65196	40
2.64987	42
2.64778	32
2.64569	34
2.64361	36
2.64153	30
2.63946	32
2.63739	30
2.63532	26
2.63325	40
2.63119	36
2.62913	38
2.62708	34
2.62503	32
2.62298	32
2.62094	42
2.61889	38
2.61686	40
2.61482	32
2.61279	36
2.61076	36
2.60873	42
2.60671	40
2.60469	40
2.60268	36
2.60067	50
2.59866	38
2.59665	50
2.59465	44
2.59265	52
2.59065	38
2.58866	40
2.58667	46
2.58468	44
2.5827	54
2.58072	48
2.57874	48
2.57677	50
2.5748	42
2.57283	56
2.57086	56
2.5689	62
2.56694	48
2.56499	58
2.56304	58
2.56109	58
2.55914	60
2.5572	50
2.55526	58
2.55332	56
2.55139	64
2.54946	66
2.54753	58
2.5456	66
2.54368	66
2.54176	68
2.53985	82
2.53794	72
2.53603	70
2.53412	74
2.53222	88
2.53031	88
2.52842	82
2.52652	84
2.52463	84
2.52274	84
2.52085	86
2.51897	84
2.51709	90
2.51521	94
2.51334	98
2.51147	108
2.5096	102
2.50773	104
2.50587	106
2.50401	118
2.50216	110
2.5003	110
2.49845	108
2.4966	118
2.49476	130
2.49291	116
2.49107	126
2.48924	134
2.4874	134
2.48557	138
2.48374	136
2.48192	146.119
2.48009	138.96
2.47827	141.064
2.47646	151.744
2.47464	147.236
2.47283	155.82
2.47102	158.397
2.46922	164.446
2.46741	178
2.46561	176.414
2.46381	173.676
2.46202	187.08
2.46023	187.477
2.45844	186.967
2.45665	191.514
2.45493	186
2.45314	202
2.45136	206
2.44957	210
2.44779	220
2.44601	212
2.44424	212
2.44247	206
2.4407	208
2.43893	200
2.43716	224
2.4354	226
2.43364	236
2.43188	234
2.43013	234
2.42838	234
2.42663	246
2.42488	230
2.42314	256
2.4214	250
2.41966	244
2.41792	270
2.41619	256
2.41446	258
2.41273	254
2.411	256
2.40928	280
2.40756	262
2.40584	274
2.40413	266
2.40241	260
2.4007	278
2.39899	262
2.39729	270
2.39559	258
2.39389	244
2.39219	252
2.39049	272
2.3888	276
2.38711	278
2.38542	254
2.38374	268
2.38205	254
2.38037	284
2.37869	250
2.37702	246
2.37535	278
2.37368	254
2.37201	266
2.37034	282
2.36868	278
2.36702	274
2.36536	272
2.3637	264
2.36205	252
2.3604	252
2.35875	264
2.3571	242
2.35546	240
2.35382	248
2.35218	240
2.35054	250
2.34891	240
2.34727	230
2.34564	230
2.34402	236
2.34239	244
2.34077	212
2.33915	238
2.33753	222
2.33591	220
2.3343	208
2.33269	222
2.33108	212
2.32948	218
2.32787	200
2.32627	204
2.32467	206
2.32307	170
2.32148	210
2.31989	188
2.3183	202
2.31671	200
2.31512	200
2.31354	184
2.31196	184
2.31038	184
2.3088	202
2.30723	194
2.30565	188
2.30408	178
2.30252	178
2.30095	168
2.29939	172
2.29783	162
2.29627	190
2.29471	176
2.29316	180
2.29161	182
2.29006	162
2.28851	164
2.28696	156
2.28542	162
2.28388	158
2.28234	176
2.2808	170
2.27927	176
2.27773	176
2.2762	154
2.27468	164
2.27315	174
2.27163	166
2.27011	166
2.26859	164
2.26707	170
2.26555	146
2.26404	160
2.26253	161.962
2.26102	165.733
2.25951	161.97
2.25801	159.509
2.25651	159.076
2.25501	152.302
2.25351	153.718
2.25201	152.891
2.25052	164.883
2.24902	164.368
2.24753	149.421
2.24605	158.694
2.24456	172.515
2.24308	155.964
2.2416	159.514
2.24011	160
2.23863	154
2.23715	142
2.23567	150
2.23419	146
2.23271	154
2.23124	148
2.22977	146
2.2283	160
2.22683	150
2.22536	160
2.2239	142
2.22244	146
2.22098	154
2.21952	150
2.21807	154
2.21661	150
2.21516	170
2.21371	152
2.21226	154
2.21082	150
2.20937	144
2.20793	146
2.20649	164
2.20505	160
2.20362	156
2.20218	172
2.20075	154
2.19932	158
2.19789	158
2.19647	146
2.19504	152
2.19362	158
2.1922	170
2.19078	156
2.18936	164
2.18795	168
2.18654	144
2.18513	148
2.18372	162
2.18231	170
2.18091	172
2.1795	164
2.1781	148
2.1767	176
2.1753	156
2.17391	158
2.17251	168
2.17112	172
2.16973	162
2.16834	168
2.16696	158
2.16557	176
2.16419	180
2.16281	172
2.16143	190
2.16005	170
2.15868	162
2.1573	182
2.15593	168
2.15456	178
2.1532	162
2.15183	190
2.15046	186
2.1491	172
2.14774	170
2.14638	182
2.14503	176
2.14367	182
2.14232	198
2.14097	178
2.13962	198
2.13827	174
2.13692	194
2.13558	180
2.13423	176
2.13289	192
2.13155	190
2.13022	186
2.12888	202
2.12755	202
2.12621	182
2.12488	184
2.12356	178
2.12223	192
2.1209	204
2.11958	186
2.11826	196
2.11694	184
2.11562	186
2.1143	208
2.11299	198
2.11168	184
2.11037	208
2.10906	202
2.10775	184
2.10644	194
2.10514	190
2.10384	196
2.10253	180
2.10123	190
2.09994	198
2.09864	218
2.09735	196
2.09605	210
2.09476	194
2.09347	192
2.09219	206
2.0909	208
2.08962	214
2.08834	218
2.08705	212
2.08578	210
2.0845	216
2.08322	184
2.08195	198
2.08068	206
2.0794	195.995
2.07814	206.174
2.07687	198.401
2.0756	195.728
2.07434	193.745
2.07307	196.254
2.07181	208.976
2.07055	190.967
2.0693	192.351
2.06804	199.65
2.06679	195.192
2.06553	206.809
2.06428	198.073
2.06303	199.722
2.06178	202.181
2.06069	194
2.05944	204
2.05819	196
2.05694	192
2.05569	210
2.05445	210
2.05321	212
2.05196	204
2.05072	204
2.04949	204
2.04825	212
2.04701	216
2.04578	194
2.04455	196
2.04332	188
2.04209	206
2.04086	206
2.03964	190
2.03841	184
2.03719	190
2.03597	200
2.03475	186
2.03353	188
2.03232	200
2.0311	214
2.02989	212
2.02868	202
2.02747	198
2.02626	194
2.02505	210
2.02384	202
2.02264	200
2.02144	220
2.02024	210
2.01904	198
2.01784	192
2.01664	202
2.01544	200
2.01425	208
2.01306	198
2.01187	214
2.01068	200
2.00949	214
2.0083	210
2.00712	200
2.00594	224
2.00475	204
2.00357	184
2.0024	194
2.00122	200
2.00004	220
1.99887	208
1.99769	204
1.99652	202
1.99535	224
1.99418	200
1.99302	222
1.99185	200
1.99069	206
1.98952	216
1.98836	194
1.9872	210
1.98604	220
1.98488	212
1.98373	214
1.98257	208
1.98142	212
1.98027	218
1.97912	206
1.97797	208
1.97682	224
1.97568	204
1.97453	208
1.97339	190
1.97225	212
1.97111	200
1.96997	210
1.96883	192
1.9677	216
1.96656	216
1.96543	210
1.9643	202
1.96316	202
1.96204	210
1.96091	200
1.95978	198
1.95866	210
1.95753	220
1.95641	206
1.95529	204
1.95417	206
1.95305	204
1.95193	216
1.95082	212
1.9497	200
1.94859	204
1.94748	206
1.94637	198
1.94526	204
1.94415	212
1.94305	206
1.94194	212
1.94084	186
1.93974	204
1.93864	190
1.93754	200
1.93644	194
1.93534	210
1.93425	194
1.93315	180
1.93206	184
1.93097	178
1.92988	182
1.92879	214
1.9277	182
1.92662	190
1.92553	186
1.92445	190.652
1.92337	175.093
1.92228	196.412
1.92121	185
1.92013	177.126
1.91905	185.676
1.91797	187.933
1.9169	182.927
1.91583	181.675
1.91475	183.23
1.91368	176.843
1.91261	181.063
1.91155	196.55
1.91048	190.664
1.90946	176
1.90839	188
1.90732	194
1.90626	190
1.90519	176
1.90413	182
1.90306	168
1.902	170
1.90094	194
1.89988	178
1.89882	186
1.89777	162
1.89671	166
1.89566	180
1.8946	150
1.89355	168
1.8925	166
1.89145	172
1.8904	158
1.88936	174
1.88831	174
1.88727	150
1.88622	164
1.88518	166
1.88414	184
1.8831	150
1.88206	174
1.88102	170
1.87999	160
1.87895	160
1.87792	174
1.87689	158
1.87586	160
1.87483	156
1.8738	170
1.87277	164
1.87174	168
1.87072	148
1.86969	146
1.86867	166
1.86765	148
1.86663	142
1.86561	150
1.86459	154
1.86357	148
1.86256	150
1.86154	156
1.86053	148
1.85952	148
1.85851	152
1.8575	138
1.85649	130
1.85548	148
1.85447	142
1.85347	140
1.85247	138
1.85146	138
1.85046	136
1.84946	138
1.84846	140
1.84746	124
1.84646	126
1.84547	132
1.84447	130
1.84348	114
1.84249	126
1.8415	136
1.84051	114
1.83952	124
1.83853	120
1.83754	124
1.83656	130
1.83557	122
1.83459	128
1.83361	134
1.83262	124
1.83164	128
1.83066	122
1.82969	120
1.82871	116
1.82773	108
1.82676	122
1.82579	116
1.82481	114
1.82384	122
1.82287	122
1.8219	106
1.82094	112
1.81997	114
1.819	116
1.81804	108
1.81708	100
1.81611	114
1.81515	114
1.81419	106
1.81323	108
1.81227	108
1.81132	112
1.81036	112
1.80941	96
1.80845	112
1.8075	92
1.80655	102
1.8056	104
1.80465	96
1.8037	100
1.80275	90
1.80181	100
1.80086	90
1.79992	92
1.79897	88
1.79803	100
1.79709	86
1.79615	96
1.79521	100
1.79428	106
1.79334	100
1.7924	96
1.79147	99.931
1.79053	89.1738
1.7896	92.8737
1.78867	84.9983
1.78774	97.8986
1.78681	95.7175
1.78588	93.4745
1.78496	92.703
1.78403	96.2924
1.7831	92.2401
1.78218	95.2036
1.78126	90.3461
1.78033	94.0422
1.77941	89.7099
1.77851	80
1.77759	82
1.77667	102
1.77575	84
1.77483	86
1.77391	92
1.77299	86
1.77207	110
1.77115	90
1.77024	96
1.76932	98
1.76841	90
1.7675	84
1.76659	76
1.76568	82
1.76477	78
1.76386	90
1.76295	86
1.76204	76
1.76114	86
1.76023	82
1.75933	92
1.75843	82
1.75753	86
1.75662	82
1.75572	84
1.75483	72
1.75393	74
1.75303	74
1.75214	78
1.75124	86
1.75035	68
1.74945	80
1.74856	72
1.74767	82
1.74678	82
1.74589	72
1.74501	68
1.74412	72
1.74323	72
1.74235	70
1.74146	66
1.74058	70
1.7397	76
1.73882	78
1.73794	78
1.73706	68
1.73618	70
1.7353	76
1.73443	74
1.73355	74
1.73268	72
1.7318	64
1.73093	66
1.73006	72
1.72919	58
1.72832	68
1.72745	70
1.72658	64
1.72571	70
1.72485	62
1.72398	68
1.72312	64
1.72225	68
1.72139	66
1.72053	70
1.71967	68
1.71881	60
1.71795	64
1.71709	68
1.71624	56
1.71538	64
1.71453	66
1.71367	54
1.71282	58
1.71197	54
1.71112	54
1.71027	58
1.70942	54
1.70857	60
1.70772	58
1.70687	62
1.70603	56
1.70518	54
1.70434	68
1.7035	60
1.70265	58
1.70181	50
1.70097	56
1.70013	66
1.69929	66
1.69846	52
1.69762	64
1.69678	52
1.69595	66
1.69511	50
1.69428	58
1.69345	58
1.69262	54
1.69179	52
1.69096	52
1.69013	52
1.6893	58
1.68847	56
1.68765	60
1.68682	46
1.686	52
1.68517	50
1.68435	50
1.68353	54
1.68271	62
1.68189	52
1.68107	58
1.68025	48
1.67943	50
1.67861	48
1.6778	44
1.67698	44.0485
1.67617	48.0743
1.67536	53.7184
1.67454	53.6799
1.67373	46.9569
1.67292	51.1604
1.67211	48.3495
1.6713	48.8398
1.6705	52.838
1.66969	52.5917
1.66888	44.7253
1.66808	47.2797
1.66727	1258.09
1.66647	50.4003
1.66566	51.4095
1.6649	46
1.66409	48
1.66329	56
1.66249	58
1.66168	46
1.66088	50
1.66008	54
1.65928	56
1.65848	52
1.65768	52
1.65688	48
1.65608	46
1.65529	46
1.65449	52
1.6537	48
1.6529	56
1.65211	50
1.65132	60
1.65053	54
1.64973	50
1.64894	46
1.64816	36
1.64737	40
1.64658	52
1.64579	48
1.64501	44
1.64422	46
1.64344	52
1.64265	46
1.64187	42
1.64109	44
1.64031	50
1.63953	40
1.63875	56
1.63797	42
1.63719	38
1.63642	50
1.63564	46
1.63486	42
1.63409	54
1.63331	48
1.63254	56
1.63177	52
1.631	38
1.63023	36
1.62946	46
1.62869	50
1.62792	38
1.62715	44
1.62639	42
1.62562	46
1.62485	42
1.62409	48
1.62333	48
1.62256	38
1.6218	42
1.62104	40
1.62028	46
1.61952	48
1.61876	44
1.618	34
1.61724	52
1.61649	42
1.61573	38
1.61498	46
1.61422	50
1.61347	44
1.61271	34
1.61196	40
1.61121	40
1.61046	38
1.60971	40
1.60896	42
1.60821	44
1.60747	42
1.60672	40
1.60597	44
1.60523	44
1.60448	36
1.60374	36
1.603	42
1.60225	36
1.60151	40
1.60077	38
1.60003	42
1.59929	34
1.59855	36
1.59782	52
1.59708	40
1.59634	38
1.59561	32
1.59487	38
1.59414	46
1.5934	40
1.59267	40
1.59194	30
1.59121	42
1.59048	46
1.58975	36
1.58902	40
1.58829	42
1.58756	40
1.58684	46
1.58611	38
1.58538	34
1.58466	38
1.58394	38
1.58321	36
1.58249	30
1.58177	32
1.58105	36
1.58033	36
1.57961	40
1.57889	34
1.57817	32
1.57745	38
1.57674	38
1.57602	35.9732
1.5753	36.3706
1.57459	39.8146
1.57388	36
1.57316	33.2079
1.57245	38.3759
1.57174	35.8898
1.57103	36.9534
1.57032	36
1.56961	37.8773
1.5689	36.4185
1.56819	37.8063
1.56748	32.6016
1.56678	29.2771
1.56607	30.0835
1.56544	32
1.56473	34
1.56402	28
1.56331	38
1.56261	30
1.5619	32
1.56119	36
1.56049	34
1.55979	30
1.55908	36
1.55838	28
1.55768	34
1.55698	32
1.55628	30
1.55558	30
1.55488	40
1.55418	44
1.55348	30
1.55278	28
1.55209	32
1.55139	36
1.5507	30
1.55	34
1.54931	44
1.54862	30
1.54792	38
1.54723	42
1.54654	32
1.54585	40
1.54516	34
1.54447	24
1.54378	36
1.5431	36
1.54241	34
1.54172	36
1.54104	30
1.54035	30
1.53967	30
1.53898	38
1.5383	34
1.53762	34
1.53694	40
1.53626	38
1.53558	30
1.5349	32
1.53422	34
1.53354	38
1.53286	30
1.53218	32
1.53151	38
1.53083	42
1.53016	34
1.52948	28
1.52881	32
1.52813	34
1.52746	34
1.52679	36
1.52612	36
1.52545	26
1.52478	36
1.52411	38
1.52344	36
1.52277	34
1.5221	30
1.52144	30
1.52077	28
1.52011	32
1.51944	32
1.51878	36
1.51811	28
1.51745	30
1.51679	32
1.51613	32
1.51547	38
1.51481	30
1.51415	28
1.51349	36
1.51283	30
1.51217	24
1.51151	30
1.51086	30
1.5102	34
1.50954	26
1.50889	28
1.50824	34
1.50758	26
1.50693	34
1.50628	32
1.50563	32
1.50497	36
1.50432	36
1.50367	26
1.50302	34
1.50238	30
1.50173	34
1.50108	26
1.50043	34
1.49979	28
1.49914	28
1.4985	36
1.49785	32
1.49721	20
1.49657	32
1.49592	32
1.49528	34
1.49464	32
1.494	30
1.49336	32
1.49272	34
1.49208	30
1.49144	36
1.49081	32
1.49017	32
1.48953	32
1.4889	34
1.48826	36
1.48763	32
1.48699	28.0198
1.48636	26.3036
1.48573	33.4257
1.4851	27.6364
1.48446	29.6591
1.48383	30.9413
1.4832	28.7671
1.48257	30.5733
1.48194	29.6348
1.48132	28.0877
1.48069	32.604
1.48006	32.1092
1.47943	25.3709
1.47881	27.5596
1.47818	41.4802
1.47756	30
1.47694	28
1.47631	26
1.47568	34
1.47505	34
1.47443	28
1.4738	28
1.47318	28
1.47256	30
1.47193	26
1.47131	30
1.47069	26
1.47006	24
1.46944	36
1.46882	36
1.4682	26
1.46758	34
1.46696	28
1.46635	30
1.46573	24
1.46511	24
1.46449	24
1.46388	26
1.46326	32
1.46265	24
1.46203	32
1.46142	24
1.46081	30
1.46019	32
1.45958	32
1.45897	34
1.45836	28
1.45775	30
1.45714	34
1.45653	28
1.45592	30
1.45531	30
1.4547	32
1.4541	24
1.45349	34
1.45288	32
1.45228	28
1.45167	28
1.45107	30
1.45047	28
1.44986	40
1.44926	24
1.44866	28
1.44806	34
1.44746	30
1.44686	26
1.44626	20
1.44566	28
1.44506	28
1.44446	34
1.44386	26
1.44326	24
1.44267	36
1.44207	32
1.44148	38
1.44088	24
1.44029	28
1.43969	28
1.4391	40
1.43851	32
1.43791	28
1.43732	26
1.43673	32
1.43614	36
1.43555	28
1.43496	24
1.43437	20
1.43378	28
1.4332	30
1.43261	32
1.43202	28
1.43143	26
1.43085	28
1.43026	30
1.42968	32
1.42909	36
1.42851	38
1.42793	20
1.42734	24
1.42676	18
1.42618	32
1.4256	24
1.42502	34
1.42444	28
1.42386	34
1.42328	26
1.4227	28
1.42212	28
1.42155	30
1.42097	26
1.42039	28
1.41982	30
1.41924	20
1.41867	28
1.41809	34
1.41752	28
1.41695	30
1.41637	24
1.4158	36
1.41523	18
1.41466	30
1.41409	22
1.41352	26
1.41295	28
1.41238	30
1.41181	34
1.41124	22
1.41067	36
1.41011	28
1.40954	34
1.40897	30
1.40841	22
1.40784	29.9703
1.40728	22.5465
1.40672	31.1421
1.40615	27.5743
1.40559	25.9966
1.40503	33.3554
1.40446	52.639
1.4039	28.7832
1.40334	28.6126
1.40278	27.4141
1.40222	30.9128
1.40166	32.0221
1.4011	29.2867
1.40054	28.466
1.39999	27.0001
1.39947	24
1.3989	30
1.39834	30
1.39779	30
1.39723	36
1.39667	32
1.39611	32
1.39555	32
1.395	28
1.39444	28
1.39388	24
1.39333	28
1.39277	24
1.39222	26
1.39166	32
1.39111	28
1.39056	28
1.39	32
1.38945	38
1.3889	34
1.38835	26
1.3878	28
1.38725	28
1.3867	30
1.38615	28
1.3856	26
1.38505	34
1.3845	28
1.38396	26
1.38341	22
1.38286	36
1.38232	28
1.38177	28
1.38123	34
1.38068	24
1.38014	20
1.3796	28
1.37905	24
1.37851	24
1.37797	34
1.37743	32
1.37688	26
1.37634	36
1.3758	26
1.37526	22
1.37472	40
1.37419	34
1.37365	28
1.37311	22
1.37257	30
1.37204	30
1.3715	28
1.37096	30
1.37043	24
1.36989	30
1.36936	30
1.36882	26
1.36829	26
1.36776	40
1.36722	34
1.36669	34
1.36616	34
1.36563	34
1.3651	30
1.36457	26
1.36404	28
1.36351	34
1.36298	28
1.36245	34
1.36192	24
1.36139	28
1.36087	34
1.36034	36
1.35981	34
1.35929	30
1.35876	28
1.35824	40
1.35771	34
1.35719	32
1.35667	30
1.35614	30
1.35562	28
1.3551	30
1.35458	28
1.35406	34
1.35353	24
1.35301	26
1.35249	34
1.35197	30
1.35146	28
1.35094	28
1.35042	26
1.3499	38
1.34938	28
1.34887	28
1.34835	28
1.34783	26
1.34732	32
1.3468	32
1.34629	30
1.34578	30
1.34526	32
1.34475	22
1.34424	26
1.34372	22
1.34321	28
1.3427	26
1.34219	24
1.34168	26
1.34117	22
1.34066	28
1.34015	30
1.33964	24
1.33913	26
1.33862	32
1.33812	38
1.33761	32
1.3371	20.2583
1.3366	28.1845
1.33609	24.9612
1.33558	32.1341
1.33508	30.7826
1.33457	24.8862
1.33407	24.9999
1.33357	25
1.33306	30.8667
1.33256	28.4475
1.33206	20.8692
1.33156	23.6761
1.33105	28.4941
1.33055	30.3448
1.33005	25.6826
1.32959	26
1.32909	28
1.32859	34
1.32809	16
1.32758	28
1.32708	20
1.32658	30
1.32608	32
1.32558	30
1.32508	32
1.32458	28
1.32408	26
1.32358	36
1.32309	28
1.32259	30
1.32209	18
1.3216	32
1.3211	36
1.3206	32
1.32011	30
1.31961	28
1.31912	28
1.31862	32
1.31813	32
1.31764	22
1.31714	26
1.31665	34
1.31616	30
1.31567	34
1.31518	32
1.31468	30
1.31419	28
1.3137	26
1.31321	20
1.31272	28
1.31224	34
1.31175	36
1.31126	32
1.31077	36
1.31028	28
1.3098	32
1.30931	38
1.30882	38
1.30834	30
1.30785	24
1.30737	28
1.30688	30
1.3064	30
1.30592	26
1.30543	24
1.30495	32
1.30447	36
1.30399	32
1.3035	34
1.30302	24
1.30254	28
1.30206	28
1.30158	28
1.3011	28
1.30062	28
1.30014	30
1.30001	36