File: ploting_and_data_tools.ipynb/___archivosraman/CdSe3_04.txt
#Acq. time (s)=	1
#Accumulations=	1
#Range (eV)=	2...1
#Windows=	11
#Autofocus=	Off
#AutoExposure=	Off
#Spike filter=	Off
#Delay time (s)=	0
#Binning=	1
#Readout mode=	Signal
#DeNoise=	Off
#ICS correction=	Off
#Dark correction=	Off
#Inst. Process=	Off
#Instrument=	LabRAM HR Evol
#Detector=	Syncerity OE
#Objective=	x100_VIS_LWD
#Grating=	600 (500nm)
#ND Filter=	1%
#Laser=	442nm_Notch
#Hole=	150.001
#Range=	Visible
#Project=	Paty
#Sample=
#Site=	15-06-22
#Title=	CdSe3
#Remark=
#Date=	15.06.2022 21:23
#Acquired=	15.06.2022 21:23:58
2.74975	20
2.7475	28
2.74525	30
2.743	34
2.74076	32
2.73852	28
2.73629	26
2.73406	28
2.73183	30
2.72961	28
2.72739	30
2.72517	36
2.72296	30
2.72075	28
2.71854	38
2.71634	22
2.71414	28
2.71195	28
2.70976	32
2.70757	26
2.70539	26
2.70321	34
2.70103	26
2.69886	36
2.69669	34
2.69452	34
2.69236	30
2.6902	36
2.68805	40
2.6859	40
2.68375	34
2.68161	32
2.67947	44
2.67733	36
2.6752	34
2.67307	38
2.67094	40
2.66882	32
2.6667	38
2.66458	34
2.66247	34
2.66036	38
2.65826	34
2.65615	38
2.65405	34
2.65196	40
2.64987	44
2.64778	42
2.64569	30
2.64361	42
2.64153	48
2.63946	44
2.63739	44
2.63532	40
2.63325	46
2.63119	42
2.62913	46
2.62708	40
2.62503	40
2.62298	54
2.62094	44
2.61889	54
2.61686	44
2.61482	54
2.61279	46
2.61076	42
2.60873	56
2.60671	54
2.60469	62
2.60268	62
2.60067	60
2.59866	46
2.59665	60
2.59465	54
2.59265	56
2.59065	70
2.58866	72
2.58667	66
2.58468	68
2.5827	80
2.58072	68
2.57874	76
2.57677	82
2.5748	80
2.57283	78
2.57086	80
2.5689	86
2.56694	92
2.56499	84
2.56304	102
2.56109	110
2.55914	104
2.5572	126
2.55526	118
2.55332	118
2.55139	124
2.54946	118
2.54753	140
2.5456	126
2.54368	136
2.54176	146
2.53985	158
2.53794	150
2.53603	146
2.53412	164
2.53222	180
2.53031	182
2.52842	180
2.52652	188
2.52463	192
2.52274	218
2.52085	218
2.51897	210
2.51709	230
2.51521	230
2.51334	242
2.51147	252
2.5096	256
2.50773	290
2.50587	278
2.50401	296
2.50216	292
2.5003	344
2.49845	338
2.4966	308
2.49476	336
2.49291	350
2.49107	372
2.48924	388
2.4874	378
2.48557	412
2.48374	424
2.48192	437.422
2.48009	457.578
2.47827	479.689
2.47646	485.542
2.47464	522.114
2.47283	541.268
2.47102	556.943
2.46922	577.614
2.46741	600.955
2.46561	642.859
2.46381	679.682
2.46202	720.28
2.46023	716.224
2.45844	742.554
2.45665	768.239
2.45493	782
2.45314	804
2.45136	810
2.44957	854
2.44779	890
2.44601	946
2.44424	930
2.44247	966
2.4407	994
2.43893	976
2.43716	1024
2.4354	1034
2.43364	1084
2.43188	1092
2.43013	1110
2.42838	1136
2.42663	1152
2.42488	1216
2.42314	1196
2.4214	1218
2.41966	1274
2.41792	1254
2.41619	1270
2.41446	1272
2.41273	1332
2.411	1352
2.40928	1350
2.40756	1364
2.40584	1374
2.40413	1416
2.40241	1448
2.4007	1408
2.39899	1454
2.39729	1452
2.39559	1444
2.39389	1482
2.39219	1498
2.39049	1512
2.3888	1566
2.38711	1588
2.38542	1554
2.38374	1576
2.38205	1624
2.38037	1650
2.37869	1626
2.37702	1606
2.37535	1642
2.37368	1632
2.37201	1634
2.37034	1666
2.36868	1662
2.36702	1660
2.36536	1664
2.3637	1652
2.36205	1686
2.3604	1640
2.35875	1630
2.3571	1652
2.35546	1666
2.35382	1664
2.35218	1580
2.35054	1622
2.34891	1598
2.34727	1616
2.34564	1642
2.34402	1580
2.34239	1580
2.34077	1570
2.33915	1510
2.33753	1504
2.33591	1518
2.3343	1498
2.33269	1466
2.33108	1486
2.32948	1502
2.32787	1426
2.32627	1502
2.32467	1382
2.32307	1418
2.32148	1350
2.31989	1380
2.3183	1348
2.31671	1314
2.31512	1332
2.31354	1330
2.31196	1262
2.31038	1286
2.3088	1244
2.30723	1236
2.30565	1202
2.30408	1214
2.30252	1188
2.30095	1174
2.29939	1192
2.29783	1236
2.29627	1152
2.29471	1156
2.29316	1160
2.29161	1116
2.29006	1092
2.28851	1114
2.28696	1112
2.28542	1106
2.28388	1066
2.28234	1064
2.2808	1050
2.27927	1050
2.27773	1058
2.2762	1012
2.27468	1000
2.27315	1012
2.27163	992
2.27011	950
2.26859	958
2.26707	976
2.26555	934
2.26404	920
2.26253	907.751
2.26102	894.326
2.25951	910.587
2.25801	885.748
2.25651	860.554
2.25501	841.974
2.25351	832.955
2.25201	825.136
2.25052	819.413
2.24902	815.257
2.24753	776.836
2.24605	799.473
2.24456	795.77
2.24308	756.032
2.2416	762.39
2.24011	716
2.23863	748
2.23715	748
2.23567	714
2.23419	704
2.23271	700
2.23124	712
2.22977	688
2.2283	642
2.22683	670
2.22536	666
2.2239	676
2.22244	672
2.22098	620
2.21952	632
2.21807	616
2.21661	662
2.21516	628
2.21371	582
2.21226	608
2.21082	582
2.20937	586
2.20793	604
2.20649	598
2.20505	586
2.20362	566
2.20218	564
2.20075	548
2.19932	570
2.19789	556
2.19647	534
2.19504	526
2.19362	546
2.1922	550
2.19078	518
2.18936	534
2.18795	540
2.18654	516
2.18513	544
2.18372	526
2.18231	506
2.18091	518
2.1795	510
2.1781	498
2.1767	492
2.1753	508
2.17391	512
2.17251	494
2.17112	478
2.16973	496
2.16834	510
2.16696	486
2.16557	462
2.16419	488
2.16281	496
2.16143	508
2.16005	490
2.15868	500
2.1573	496
2.15593	494
2.15456	510
2.1532	478
2.15183	456
2.15046	476
2.1491	480
2.14774	462
2.14638	462
2.14503	470
2.14367	468
2.14232	454
2.14097	486
2.13962	464
2.13827	478
2.13692	462
2.13558	514
2.13423	498
2.13289	462
2.13155	488
2.13022	456
2.12888	484
2.12755	448
2.12621	480
2.12488	494
2.12356	464
2.12223	496
2.1209	486
2.11958	482
2.11826	478
2.11694	486
2.11562	484
2.1143	466
2.11299	456
2.11168	456
2.11037	456
2.10906	458
2.10775	478
2.10644	432
2.10514	482
2.10384	468
2.10253	468
2.10123	456
2.09994	484
2.09864	460
2.09735	498
2.09605	460
2.09476	478
2.09347	486
2.09219	484
2.0909	452
2.08962	438
2.08834	462
2.08705	474
2.08578	450
2.0845	458
2.08322	464
2.08195	468
2.08068	478
2.0794	468.368
2.07814	472.953
2.07687	439.356
2.0756	467.845
2.07434	456.989
2.07307	457.16
2.07181	439.335
2.07055	457.871
2.0693	450.167
2.06804	439.65
2.06679	426.02
2.06553	445.271
2.06428	434.563
2.06303	442.324
2.06178	431.446
2.06069	450
2.05944	426
2.05819	454
2.05694	414
2.05569	422
2.05445	430
2.05321	458
2.05196	454
2.05072	410
2.04949	434
2.04825	418
2.04701	424
2.04578	410
2.04455	424
2.04332	404
2.04209	438
2.04086	418
2.03964	430
2.03841	400
2.03719	452
2.03597	418
2.03475	418
2.03353	432
2.03232	420
2.0311	446
2.02989	414
2.02868	432
2.02747	436
2.02626	408
2.02505	442
2.02384	420
2.02264	402
2.02144	402
2.02024	414
2.01904	424
2.01784	446
2.01664	446
2.01544	432
2.01425	412
2.01306	452
2.01187	432
2.01068	466
2.00949	462
2.0083	440
2.00712	440
2.00594	452
2.00475	454
2.00357	454
2.0024	454
2.00122	458
2.00004	456
1.99887	458
1.99769	452
1.99652	476
1.99535	456
1.99418	464
1.99302	488
1.99185	476
1.99069	450
1.98952	454
1.98836	474
1.9872	466
1.98604	456
1.98488	492
1.98373	480
1.98257	498
1.98142	488
1.98027	494
1.97912	476
1.97797	488
1.97682	508
1.97568	486
1.97453	488
1.97339	502
1.97225	490
1.97111	468
1.96997	500
1.96883	494
1.9677	486
1.96656	502
1.96543	520
1.9643	516
1.96316	508
1.96204	516
1.96091	532
1.95978	498
1.95866	536
1.95753	488
1.95641	516
1.95529	520
1.95417	502
1.95305	496
1.95193	526
1.95082	552
1.9497	516
1.94859	498
1.94748	520
1.94637	524
1.94526	500
1.94415	496
1.94305	518
1.94194	524
1.94084	510
1.93974	512
1.93864	512
1.93754	526
1.93644	540
1.93534	532
1.93425	500
1.93315	516
1.93206	506
1.93097	524
1.92988	536
1.92879	534
1.9277	520
1.92662	500
1.92553	536
1.92445	532.719
1.92337	516.785
1.92228	507.837
1.92121	532.518
1.92013	507.972
1.91905	522.135
1.91797	515.943
1.9169	536.258
1.91583	526.122
1.91475	511.454
1.91368	513.252
1.91261	537.687
1.91155	512.773
1.91048	519.806
1.90946	516
1.90839	540
1.90732	498
1.90626	490
1.90519	540
1.90413	532
1.90306	532
1.902	524
1.90094	518
1.89988	508
1.89882	530
1.89777	490
1.89671	520
1.89566	516
1.8946	534
1.89355	498
1.8925	496
1.89145	500
1.8904	482
1.88936	512
1.88831	518
1.88727	506
1.88622	518
1.88518	546
1.88414	532
1.8831	526
1.88206	514
1.88102	514
1.87999	530
1.87895	528
1.87792	510
1.87689	488
1.87586	516
1.87483	536
1.8738	524
1.87277	528
1.87174	520
1.87072	502
1.86969	510
1.86867	534
1.86765	510
1.86663	512
1.86561	520
1.86459	522
1.86357	514
1.86256	500
1.86154	508
1.86053	506
1.85952	516
1.85851	514
1.8575	502
1.85649	516
1.85548	540
1.85447	522
1.85347	510
1.85247	526
1.85146	556
1.85046	512
1.84946	544
1.84846	514
1.84746	492
1.84646	514
1.84547	512
1.84447	510
1.84348	506
1.84249	500
1.8415	488
1.84051	512
1.83952	512
1.83853	522
1.83754	490
1.83656	516
1.83557	494
1.83459	498
1.83361	504
1.83262	502
1.83164	506
1.83066	478
1.82969	500
1.82871	506
1.82773	502
1.82676	510
1.82579	486
1.82481	500
1.82384	482
1.82287	488
1.8219	488
1.82094	522
1.81997	492
1.819	498
1.81804	492
1.81708	488
1.81611	480
1.81515	494
1.81419	502
1.81323	496
1.81227	494
1.81132	510
1.81036	478
1.80941	484
1.80845	472
1.8075	482
1.80655	468
1.8056	482
1.80465	500
1.8037	506
1.80275	500
1.80181	482
1.80086	446
1.79992	478
1.79897	456
1.79803	470
1.79709	490
1.79615	456
1.79521	462
1.79428	476
1.79334	480
1.7924	456
1.79147	463.975
1.79053	484.665
1.7896	465.399
1.78867	464.517
1.78774	468.115
1.78681	487.46
1.78588	462.925
1.78496	472.824
1.78403	447.85
1.7831	457.245
1.78218	455.399
1.78126	437.395
1.78033	463.216
1.77941	451.233
1.77851	422
1.77759	456
1.77667	442
1.77575	452
1.77483	438
1.77391	442
1.77299	422
1.77207	428
1.77115	464
1.77024	426
1.76932	446
1.76841	436
1.7675	428
1.76659	410
1.76568	432
1.76477	418
1.76386	418
1.76295	420
1.76204	442
1.76114	410
1.76023	420
1.75933	416
1.75843	402
1.75753	400
1.75662	390
1.75572	414
1.75483	422
1.75393	388
1.75303	398
1.75214	392
1.75124	400
1.75035	390
1.74945	424
1.74856	394
1.74767	396
1.74678	394
1.74589	384
1.74501	382
1.74412	418
1.74323	390
1.74235	380
1.74146	376
1.74058	376
1.7397	370
1.73882	382
1.73794	374
1.73706	368
1.73618	380
1.7353	380
1.73443	362
1.73355	384
1.73268	382
1.7318	370
1.73093	364
1.73006	352
1.72919	328
1.72832	354
1.72745	378
1.72658	362
1.72571	358
1.72485	348
1.72398	358
1.72312	358
1.72225	356
1.72139	352
1.72053	350
1.71967	348
1.71881	336
1.71795	338
1.71709	322
1.71624	346
1.71538	340
1.71453	336
1.71367	336
1.71282	342
1.71197	332
1.71112	350
1.71027	352
1.70942	320
1.70857	320
1.70772	316
1.70687	318
1.70603	324
1.70518	320
1.70434	308
1.7035	326
1.70265	304
1.70181	302
1.70097	322
1.70013	280
1.69929	320
1.69846	304
1.69762	292
1.69678	296
1.69595	290
1.69511	282
1.69428	282
1.69345	294
1.69262	266
1.69179	284
1.69096	282
1.69013	262
1.6893	300
1.68847	244
1.68765	276
1.68682	282
1.686	266
1.68517	250
1.68435	272
1.68353	260
1.68271	262
1.68189	266
1.68107	274
1.68025	278
1.67943	276
1.67861	266
1.6778	260
1.67698	264.019
1.67617	261.492
1.67536	242.505
1.67454	257.124
1.67373	268.001
1.67292	259.362
1.67211	250.339
1.6713	253.178
1.6705	243.029
1.66969	258.025
1.66888	249.282
1.66808	247.139
1.66727	249.282
1.66647	241.02
1.66566	248.657
1.6649	262
1.66409	242
1.66329	238
1.66249	250
1.66168	234
1.66088	238
1.66008	240
1.65928	242
1.65848	230
1.65768	234
1.65688	234
1.65608	220
1.65529	226
1.65449	236
1.6537	228
1.6529	240
1.65211	238
1.65132	220
1.65053	216
1.64973	214
1.64894	224
1.64816	218
1.64737	196
1.64658	218
1.64579	214
1.64501	206
1.64422	220
1.64344	212
1.64265	240
1.64187	210
1.64109	210
1.64031	210
1.63953	224
1.63875	204
1.63797	206
1.63719	204
1.63642	202
1.63564	208
1.63486	212
1.63409	194
1.63331	224
1.63254	188
1.63177	186
1.631	200
1.63023	184
1.62946	184
1.62869	206
1.62792	188
1.62715	212
1.62639	196
1.62562	192
1.62485	188
1.62409	190
1.62333	178
1.62256	184
1.6218	190
1.62104	200
1.62028	186
1.61952	186
1.61876	172
1.618	194
1.61724	176
1.61649	174
1.61573	176
1.61498	160
1.61422	178
1.61347	176
1.61271	170
1.61196	174
1.61121	164
1.61046	168
1.60971	174
1.60896	154
1.60821	152
1.60747	150
1.60672	166
1.60597	170
1.60523	150
1.60448	152
1.60374	156
1.603	152
1.60225	164
1.60151	152
1.60077	158
1.60003	144
1.59929	156
1.59855	144
1.59782	156
1.59708	134
1.59634	136
1.59561	140
1.59487	130
1.59414	130
1.5934	138
1.59267	134
1.59194	154
1.59121	144
1.59048	140
1.58975	134
1.58902	140
1.58829	124
1.58756	156
1.58684	122
1.58611	130
1.58538	124
1.58466	130
1.58394	136
1.58321	114
1.58249	130
1.58177	134
1.58105	120
1.58033	128
1.57961	128
1.57889	120
1.57817	112
1.57745	128
1.57674	122
1.57602	121.967
1.5753	121.481
1.57459	116.851
1.57388	117.796
1.57316	114.792
1.57245	116.073
1.57174	118.883
1.57103	114.266
1.57032	102.015
1.56961	106.166
1.5689	101.676
1.56819	106.815
1.56748	112.259
1.56678	112.163
1.56607	109.742
1.56544	98
1.56473	100
1.56402	92
1.56331	102
1.56261	104
1.5619	102
1.56119	102
1.56049	86
1.55979	106
1.55908	88
1.55838	100
1.55768	88
1.55698	96
1.55628	100
1.55558	104
1.55488	106
1.55418	88
1.55348	86
1.55278	100
1.55209	102
1.55139	74
1.5507	98
1.55	92
1.54931	88
1.54862	98
1.54792	86
1.54723	88
1.54654	78
1.54585	98
1.54516	94
1.54447	90
1.54378	88
1.5431	88
1.54241	80
1.54172	82
1.54104	72
1.54035	86
1.53967	76
1.53898	96
1.5383	80
1.53762	92
1.53694	68
1.53626	72
1.53558	78
1.5349	82
1.53422	76
1.53354	82
1.53286	92
1.53218	82
1.53151	78
1.53083	84
1.53016	74
1.52948	84
1.52881	78
1.52813	70
1.52746	68
1.52679	70
1.52612	78
1.52545	80
1.52478	70
1.52411	78
1.52344	78
1.52277	66
1.5221	74
1.52144	72
1.52077	68
1.52011	58
1.51944	78
1.51878	68
1.51811	66
1.51745	64
1.51679	70
1.51613	74
1.51547	80
1.51481	64
1.51415	64
1.51349	66
1.51283	70
1.51217	70
1.51151	72
1.51086	70
1.5102	64
1.50954	74
1.50889	64
1.50824	62
1.50758	72
1.50693	66
1.50628	70
1.50563	66
1.50497	66
1.50432	58
1.50367	80
1.50302	64
1.50238	66
1.50173	62
1.50108	52
1.50043	62
1.49979	56
1.49914	58
1.4985	72
1.49785	66
1.49721	62
1.49657	64
1.49592	56
1.49528	58
1.49464	58
1.494	58
1.49336	60
1.49272	58
1.49208	46
1.49144	56
1.49081	48
1.49017	58
1.48953	56
1.4889	56
1.48826	58
1.48763	56
1.48699	53.9505
1.48636	55.7932
1.48573	57.4436
1.4851	55.2106
1.48446	54.6035
1.48383	58.2384
1.4832	54.3168
1.48257	49.2998
1.48194	46.6986
1.48132	51.7663
1.48069	54.9543
1.48006	55.5347
1.47943	50.8996
1.47881	48.1786
1.47818	52.0495
1.47756	54
1.47694	52
1.47631	40
1.47568	48
1.47505	52
1.47443	46
1.4738	52
1.47318	48
1.47256	48
1.47193	50
1.47131	42
1.47069	52
1.47006	48
1.46944	46
1.46882	46
1.4682	44
1.46758	48
1.46696	56
1.46635	38
1.46573	38
1.46511	42
1.46449	38
1.46388	36
1.46326	32
1.46265	44
1.46203	50
1.46142	48
1.46081	42
1.46019	36
1.45958	34
1.45897	36
1.45836	40
1.45775	30
1.45714	38
1.45653	34
1.45592	44
1.45531	42
1.4547	28
1.4541	32
1.45349	34
1.45288	40
1.45228	36
1.45167	34
1.45107	32
1.45047	30
1.44986	36
1.44926	28
1.44866	30
1.44806	32
1.44746	30
1.44686	34
1.44626	30
1.44566	26
1.44506	28
1.44446	28
1.44386	24
1.44326	26
1.44267	28
1.44207	26
1.44148	28
1.44088	34
1.44029	30
1.43969	28
1.4391	34
1.43851	38
1.43791	24
1.43732	30
1.43673	28
1.43614	32
1.43555	30
1.43496	32
1.43437	36
1.43378	34
1.4332	30
1.43261	38
1.43202	30
1.43143	30
1.43085	28
1.43026	24
1.42968	30
1.42909	36
1.42851	24
1.42793	20
1.42734	28
1.42676	30
1.42618	28
1.4256	26
1.42502	20
1.42444	36
1.42386	30
1.42328	26
1.4227	20
1.42212	30
1.42155	24
1.42097	26
1.42039	26
1.41982	22
1.41924	20
1.41867	26
1.41809	36
1.41752	32
1.41695	34
1.41637	22
1.4158	24
1.41523	20
1.41466	28
1.41409	24
1.41352	24
1.41295	26
1.41238	32
1.41181	28
1.41124	26
1.41067	28
1.41011	30
1.40954	20
1.40897	26
1.40841	34
1.40784	28.0306
1.40728	27.7573
1.40672	37.9931
1.40615	34.3277
1.40559	31.3955
1.40503	36.5941
1.40446	127.262
1.4039	34.5513
1.40334	37.0878
1.40278	34.8992
1.40222	36.0942
1.40166	34.5263
1.4011	29.3935
1.40054	46.0695
1.39999	42.8183
1.39947	30
1.3989	36
1.39834	40
1.39779	40
1.39723	32
1.39667	32
1.39611	38
1.39555	34
1.395	38
1.39444	34
1.39388	40
1.39333	32
1.39277	32
1.39222	40
1.39166	44
1.39111	34
1.39056	32
1.39	34
1.38945	38
1.3889	30
1.38835	36
1.3878	38
1.38725	38
1.3867	36
1.38615	26
1.3856	30
1.38505	42
1.3845	32
1.38396	40
1.38341	36
1.38286	40
1.38232	38
1.38177	30
1.38123	34
1.38068	36
1.38014	28
1.3796	42
1.37905	30
1.37851	36
1.37797	38
1.37743	32
1.37688	34
1.37634	36
1.3758	38
1.37526	38
1.37472	36
1.37419	36
1.37365	40
1.37311	38
1.37257	38
1.37204	42
1.3715	40
1.37096	40
1.37043	34
1.36989	34
1.36936	30
1.36882	32
1.36829	36
1.36776	44
1.36722	40
1.36669	30
1.36616	32
1.36563	30
1.3651	38
1.36457	38
1.36404	38
1.36351	30
1.36298	44
1.36245	36
1.36192	40
1.36139	38
1.36087	34
1.36034	42
1.35981	34
1.35929	30
1.35876	28
1.35824	28
1.35771	26
1.35719	42
1.35667	34
1.35614	36
1.35562	36
1.3551	36
1.35458	30
1.35406	38
1.35353	34
1.35301	36
1.35249	34
1.35197	38
1.35146	40
1.35094	32
1.35042	38
1.3499	32
1.34938	40
1.34887	40
1.34835	26
1.34783	34
1.34732	30
1.3468	32
1.34629	34
1.34578	38
1.34526	36
1.34475	38
1.34424	38
1.34372	36
1.34321	26
1.3427	36
1.34219	44
1.34168	26
1.34117	38
1.34066	28
1.34015	40
1.33964	42
1.33913	30
1.33862	38
1.33812	26
1.33761	30
1.3371	35.9358
1.3366	31.7327
1.33609	26.8263
1.33558	28.8232
1.33508	28.8814
1.33457	33.0786
1.33407	28.9727
1.33357	31
1.33306	27.1333
1.33256	31.9471
1.33206	35.4333
1.33156	27.6817
1.33105	35.5059
1.33055	31.9758
1.33005	27.3043
1.32959	34
1.32909	40
1.32859	30
1.32809	34
1.32758	40
1.32708	28
1.32658	38
1.32608	24
1.32558	28
1.32508	32
1.32458	28
1.32408	32
1.32358	36
1.32309	26
1.32259	34
1.32209	30
1.3216	26
1.3211	28
1.3206	28
1.32011	26
1.31961	32
1.31912	34
1.31862	40
1.31813	34
1.31764	32
1.31714	28
1.31665	30
1.31616	36
1.31567	26
1.31518	32
1.31468	30
1.31419	38
1.3137	36
1.31321	34
1.31272	30
1.31224	36
1.31175	32
1.31126	34
1.31077	36
1.31028	34
1.3098	36
1.30931	44
1.30882	32
1.30834	32
1.30785	28
1.30737	34
1.30688	30
1.3064	32
1.30592	30
1.30543	36
1.30495	28
1.30447	30
1.30399	28
1.3035	32
1.30302	30
1.30254	40
1.30206	32
1.30158	34
1.3011	36
1.30062	26
1.30014	36
1.30001	26