File: ploting_and_data_tools.ipynb/___archivosraman/CdSe2_04.txt
#Acq. time (s)=	1
#Accumulations=	1
#Range (eV)=	2...1
#Windows=	11
#Autofocus=	Off
#AutoExposure=	Off
#Spike filter=	Off
#Delay time (s)=	0
#Binning=	1
#Readout mode=	Signal
#DeNoise=	Off
#ICS correction=	Off
#Dark correction=	Off
#Inst. Process=	Off
#Instrument=	LabRAM HR Evol
#Detector=	Syncerity OE
#Objective=	x100_VIS_LWD
#Grating=	600 (500nm)
#ND Filter=	1%
#Laser=	442nm_Notch
#Hole=	150.001
#Range=	Visible
#Project=	Paty
#Sample=
#Site=	15-06-22
#Title=	CdSe2
#Remark=
#Date=	15.06.2022 21:11
#Acquired=	15.06.2022 21:11:34
2.74975	36
2.7475	36
2.74525	42
2.743	40
2.74076	48
2.73852	32
2.73629	32
2.73406	34
2.73183	42
2.72961	38
2.72739	30
2.72517	34
2.72296	36
2.72075	34
2.71854	34
2.71634	36
2.71414	38
2.71195	36
2.70976	36
2.70757	38
2.70539	40
2.70321	30
2.70103	42
2.69886	38
2.69669	38
2.69452	38
2.69236	38
2.6902	32
2.68805	36
2.6859	50
2.68375	46
2.68161	40
2.67947	48
2.67733	54
2.6752	54
2.67307	52
2.67094	56
2.66882	52
2.6667	52
2.66458	58
2.66247	52
2.66036	48
2.65826	60
2.65615	62
2.65405	60
2.65196	56
2.64987	54
2.64778	62
2.64569	64
2.64361	66
2.64153	74
2.63946	56
2.63739	72
2.63532	74
2.63325	80
2.63119	74
2.62913	72
2.62708	82
2.62503	84
2.62298	92
2.62094	90
2.61889	92
2.61686	94
2.61482	94
2.61279	92
2.61076	102
2.60873	102
2.60671	108
2.60469	112
2.60268	110
2.60067	124
2.59866	116
2.59665	114
2.59465	144
2.59265	146
2.59065	154
2.58866	152
2.58667	152
2.58468	164
2.5827	178
2.58072	164
2.57874	172
2.57677	182
2.5748	194
2.57283	208
2.57086	234
2.5689	242
2.56694	222
2.56499	256
2.56304	270
2.56109	268
2.55914	276
2.5572	304
2.55526	312
2.55332	332
2.55139	320
2.54946	354
2.54753	362
2.5456	398
2.54368	396
2.54176	440
2.53985	452
2.53794	462
2.53603	472
2.53412	502
2.53222	532
2.53031	536
2.52842	560
2.52652	588
2.52463	606
2.52274	666
2.52085	666
2.51897	700
2.51709	742
2.51521	752
2.51334	774
2.51147	820
2.5096	842
2.50773	912
2.50587	930
2.50401	942
2.50216	986
2.5003	1044
2.49845	1046
2.4966	1086
2.49476	1180
2.49291	1172
2.49107	1300
2.48924	1264
2.4874	1340
2.48557	1422
2.48374	1472
2.48192	1563.99
2.48009	1591.06
2.47827	1670.32
2.47646	1756.5
2.47464	1830.54
2.47283	1901.94
2.47102	2003.98
2.46922	2080.98
2.46741	2150.84
2.46561	2290.29
2.46381	2377.5
2.46202	2476.08
2.46023	2624.02
2.45844	2722.16
2.45665	2770.53
2.45493	2888
2.45314	2982
2.45136	3096
2.44957	3088
2.44779	3156
2.44601	3294
2.44424	3446
2.44247	3448
2.4407	3602
2.43893	3656
2.43716	3846
2.4354	3942
2.43364	3864
2.43188	4086
2.43013	4102
2.42838	4258
2.42663	4270
2.42488	4388
2.42314	4492
2.4214	4612
2.41966	4670
2.41792	4700
2.41619	4922
2.41446	4906
2.41273	5038
2.411	5104
2.40928	5174
2.40756	5250
2.40584	5322
2.40413	5410
2.40241	5464
2.4007	5490
2.39899	5620
2.39729	5710
2.39559	5786
2.39389	5886
2.39219	5966
2.39049	6010
2.3888	5982
2.38711	6046
2.38542	6116
2.38374	6260
2.38205	6312
2.38037	6438
2.37869	6448
2.37702	6516
2.37535	6650
2.37368	6594
2.37201	6642
2.37034	6696
2.36868	6666
2.36702	6594
2.36536	6686
2.3637	6638
2.36205	6692
2.3604	6646
2.35875	6670
2.3571	6516
2.35546	6640
2.35382	6670
2.35218	6466
2.35054	6650
2.34891	6638
2.34727	6506
2.34564	6476
2.34402	6536
2.34239	6464
2.34077	6520
2.33915	6346
2.33753	6410
2.33591	6266
2.3343	6188
2.33269	6296
2.33108	6164
2.32948	6186
2.32787	6050
2.32627	5990
2.32467	5980
2.32307	5952
2.32148	5880
2.31989	5828
2.3183	5800
2.31671	5792
2.31512	5724
2.31354	5610
2.31196	5648
2.31038	5588
2.3088	5590
2.30723	5378
2.30565	5488
2.30408	5360
2.30252	5350
2.30095	5220
2.29939	5138
2.29783	5166
2.29627	5094
2.29471	5140
2.29316	5028
2.29161	4922
2.29006	4924
2.28851	4906
2.28696	4912
2.28542	4826
2.28388	4778
2.28234	4640
2.2808	4714
2.27927	4602
2.27773	4600
2.2762	4532
2.27468	4472
2.27315	4510
2.27163	4464
2.27011	4288
2.26859	4348
2.26707	4326
2.26555	4190
2.26404	4176
2.26253	4125.75
2.26102	4010.22
2.25951	3950.06
2.25801	3967.5
2.25651	3851.74
2.25501	3782.66
2.25351	3740.61
2.25201	3712.31
2.25052	3573.66
2.24902	3545.31
2.24753	3503.31
2.24605	3428.33
2.24456	3297.38
2.24308	3238.28
2.2416	3193.81
2.24011	3156
2.23863	3168
2.23715	3098
2.23567	3048
2.23419	2978
2.23271	3066
2.23124	2916
2.22977	2936
2.2283	2812
2.22683	2756
2.22536	2794
2.2239	2786
2.22244	2724
2.22098	2716
2.21952	2654
2.21807	2672
2.21661	2610
2.21516	2584
2.21371	2518
2.21226	2490
2.21082	2470
2.20937	2486
2.20793	2446
2.20649	2360
2.20505	2400
2.20362	2418
2.20218	2298
2.20075	2342
2.19932	2314
2.19789	2346
2.19647	2298
2.19504	2216
2.19362	2192
2.1922	2246
2.19078	2220
2.18936	2214
2.18795	2222
2.18654	2186
2.18513	2142
2.18372	2162
2.18231	2136
2.18091	2132
2.1795	2102
2.1781	2106
2.1767	2124
2.1753	2088
2.17391	2092
2.17251	2056
2.17112	2062
2.16973	2098
2.16834	2046
2.16696	2072
2.16557	1996
2.16419	2058
2.16281	1990
2.16143	2086
2.16005	1992
2.15868	2022
2.1573	1960
2.15593	2030
2.15456	2000
2.1532	1974
2.15183	2002
2.15046	2030
2.1491	2006
2.14774	1942
2.14638	1992
2.14503	1934
2.14367	1938
2.14232	1986
2.14097	1996
2.13962	1906
2.13827	1964
2.13692	1938
2.13558	1962
2.13423	1936
2.13289	1966
2.13155	1964
2.13022	1970
2.12888	1944
2.12755	1956
2.12621	1932
2.12488	1976
2.12356	1958
2.12223	1930
2.1209	1942
2.11958	1958
2.11826	1958
2.11694	1972
2.11562	1944
2.1143	1944
2.11299	1924
2.11168	1958
2.11037	1892
2.10906	1958
2.10775	1944
2.10644	1934
2.10514	1926
2.10384	1922
2.10253	1938
2.10123	1948
2.09994	1928
2.09864	1964
2.09735	1954
2.09605	1986
2.09476	1956
2.09347	1934
2.09219	1936
2.0909	1956
2.08962	1998
2.08834	1934
2.08705	1932
2.08578	1976
2.0845	1952
2.08322	1924
2.08195	1904
2.08068	1952
2.0794	1894.8
2.07814	1932.45
2.07687	1919.75
2.0756	1902.36
2.07434	1851.03
2.07307	1859.86
2.07181	1853.94
2.07055	1876.55
2.0693	1798.21
2.06804	1834.39
2.06679	1822.26
2.06553	1841.63
2.06428	1833.22
2.06303	1798.44
2.06178	1804.58
2.06069	1844
2.05944	1766
2.05819	1836
2.05694	1840
2.05569	1832
2.05445	1782
2.05321	1834
2.05196	1812
2.05072	1732
2.04949	1816
2.04825	1788
2.04701	1812
2.04578	1758
2.04455	1766
2.04332	1754
2.04209	1768
2.04086	1738
2.03964	1764
2.03841	1788
2.03719	1738
2.03597	1740
2.03475	1700
2.03353	1754
2.03232	1720
2.0311	1692
2.02989	1734
2.02868	1722
2.02747	1714
2.02626	1806
2.02505	1702
2.02384	1774
2.02264	1762
2.02144	1720
2.02024	1750
2.01904	1716
2.01784	1764
2.01664	1752
2.01544	1752
2.01425	1774
2.01306	1824
2.01187	1812
2.01068	1834
2.00949	1772
2.0083	1854
2.00712	1848
2.00594	1846
2.00475	1856
2.00357	1866
2.0024	1876
2.00122	1870
2.00004	1896
1.99887	1880
1.99769	1892
1.99652	1894
1.99535	1942
1.99418	1926
1.99302	1948
1.99185	1986
1.99069	1968
1.98952	1930
1.98836	1948
1.9872	1924
1.98604	1938
1.98488	2012
1.98373	2000
1.98257	1986
1.98142	1940
1.98027	2000
1.97912	2014
1.97797	1984
1.97682	2030
1.97568	2042
1.97453	2014
1.97339	2000
1.97225	2038
1.97111	2018
1.96997	2058
1.96883	2062
1.9677	2038
1.96656	2058
1.96543	2048
1.9643	2070
1.96316	2106
1.96204	2060
1.96091	2112
1.95978	2106
1.95866	2050
1.95753	2078
1.95641	2072
1.95529	2090
1.95417	2092
1.95305	2104
1.95193	2066
1.95082	2110
1.9497	2088
1.94859	2086
1.94748	2106
1.94637	2158
1.94526	2098
1.94415	2112
1.94305	2096
1.94194	2136
1.94084	2140
1.93974	2136
1.93864	2144
1.93754	2078
1.93644	2034
1.93534	2126
1.93425	2128
1.93315	2100
1.93206	2170
1.93097	2092
1.92988	2154
1.92879	2156
1.9277	2146
1.92662	2114
1.92553	2142
1.92445	2125.76
1.92337	2121.11
1.92228	2119.63
1.92121	2138.02
1.92013	2111.42
1.91905	2135.45
1.91797	2108.37
1.9169	2111.16
1.91583	2088.07
1.91475	2106.17
1.91368	2105.23
1.91261	2096.32
1.91155	2094.62
1.91048	2041.56
1.90946	2108
1.90839	2026
1.90732	2114
1.90626	2110
1.90519	2090
1.90413	2120
1.90306	2104
1.902	2104
1.90094	2082
1.89988	2066
1.89882	2152
1.89777	2042
1.89671	2094
1.89566	2092
1.8946	2068
1.89355	2118
1.8925	2052
1.89145	2094
1.8904	2070
1.88936	2112
1.88831	2074
1.88727	2082
1.88622	2116
1.88518	2126
1.88414	2138
1.8831	2070
1.88206	2082
1.88102	2106
1.87999	2112
1.87895	2094
1.87792	2054
1.87689	2106
1.87586	2074
1.87483	2108
1.8738	2052
1.87277	2042
1.87174	2052
1.87072	2054
1.86969	2052
1.86867	2038
1.86765	2092
1.86663	1996
1.86561	2104
1.86459	2082
1.86357	1990
1.86256	2046
1.86154	2052
1.86053	2006
1.85952	2074
1.85851	2018
1.8575	2030
1.85649	2046
1.85548	2032
1.85447	1978
1.85347	2056
1.85247	2024
1.85146	2024
1.85046	2018
1.84946	1920
1.84846	1996
1.84746	1978
1.84646	2018
1.84547	1986
1.84447	2040
1.84348	1966
1.84249	2024
1.8415	1964
1.84051	2016
1.83952	1990
1.83853	1994
1.83754	1968
1.83656	1948
1.83557	1984
1.83459	1992
1.83361	1964
1.83262	1914
1.83164	1998
1.83066	1994
1.82969	1956
1.82871	1946
1.82773	1970
1.82676	1958
1.82579	1966
1.82481	1954
1.82384	1922
1.82287	1938
1.8219	1960
1.82094	1968
1.81997	1928
1.819	1918
1.81804	1976
1.81708	1930
1.81611	1926
1.81515	1962
1.81419	1934
1.81323	1918
1.81227	1870
1.81132	1968
1.81036	1926
1.80941	1934
1.80845	1848
1.8075	1876
1.80655	1828
1.8056	1860
1.80465	1924
1.8037	1856
1.80275	1950
1.80181	1914
1.80086	1894
1.79992	1836
1.79897	1818
1.79803	1840
1.79709	1852
1.79615	1844
1.79521	1862
1.79428	1774
1.79334	1802
1.7924	1802
1.79147	1820.64
1.79053	1786.21
1.7896	1813.25
1.78867	1757.29
1.78774	1751.83
1.78681	1769.59
1.78588	1762.66
1.78496	1718.76
1.78403	1717.05
1.7831	1736.44
1.78218	1741.29
1.78126	1674.01
1.78033	1722.52
1.77941	1707.45
1.77851	1740
1.77759	1656
1.77667	1658
1.77575	1676
1.77483	1664
1.77391	1636
1.77299	1608
1.77207	1668
1.77115	1666
1.77024	1640
1.76932	1590
1.76841	1572
1.7675	1632
1.76659	1642
1.76568	1574
1.76477	1588
1.76386	1562
1.76295	1560
1.76204	1572
1.76114	1544
1.76023	1578
1.75933	1568
1.75843	1532
1.75753	1558
1.75662	1518
1.75572	1504
1.75483	1526
1.75393	1528
1.75303	1504
1.75214	1500
1.75124	1480
1.75035	1508
1.74945	1522
1.74856	1516
1.74767	1466
1.74678	1488
1.74589	1470
1.74501	1466
1.74412	1434
1.74323	1412
1.74235	1468
1.74146	1440
1.74058	1386
1.7397	1402
1.73882	1382
1.73794	1444
1.73706	1440
1.73618	1352
1.7353	1392
1.73443	1370
1.73355	1404
1.73268	1350
1.7318	1354
1.73093	1256
1.73006	1344
1.72919	1308
1.72832	1276
1.72745	1276
1.72658	1342
1.72571	1318
1.72485	1276
1.72398	1292
1.72312	1282
1.72225	1262
1.72139	1236
1.72053	1300
1.71967	1260
1.71881	1210
1.71795	1202
1.71709	1252
1.71624	1244
1.71538	1196
1.71453	1202
1.71367	1150
1.71282	1196
1.71197	1156
1.71112	1194
1.71027	1190
1.70942	1184
1.70857	1138
1.70772	1192
1.70687	1154
1.70603	1142
1.70518	1118
1.70434	1112
1.7035	1172
1.70265	1108
1.70181	1126
1.70097	1092
1.70013	1112
1.69929	1074
1.69846	1064
1.69762	1086
1.69678	1064
1.69595	1084
1.69511	1068
1.69428	1040
1.69345	1026
1.69262	1032
1.69179	1020
1.69096	1002
1.69013	974
1.6893	1012
1.68847	980
1.68765	926
1.68682	962
1.686	950
1.68517	930
1.68435	932
1.68353	954
1.68271	948
1.68189	944
1.68107	944
1.68025	892
1.67943	934
1.67861	914
1.6778	930
1.67698	918.078
1.67617	904.398
1.67536	941.106
1.67454	918.376
1.67373	895.866
1.67292	896.669
1.67211	911.576
1.6713	887.737
1.6705	902.132
1.66969	880.133
1.66888	866.981
1.66808	879.029
1.66727	879.644
1.66647	879.215
1.66566	850.371
1.6649	866
1.66409	882
1.66329	850
1.66249	830
1.66168	848
1.66088	814
1.66008	836
1.65928	852
1.65848	826
1.65768	798
1.65688	796
1.65608	814
1.65529	828
1.65449	830
1.6537	800
1.6529	794
1.65211	812
1.65132	810
1.65053	784
1.64973	782
1.64894	742
1.64816	772
1.64737	762
1.64658	760
1.64579	734
1.64501	738
1.64422	764
1.64344	2912
1.64265	740
1.64187	734
1.64109	736
1.64031	752
1.63953	732
1.63875	714
1.63797	684
1.63719	704
1.63642	666
1.63564	670
1.63486	660
1.63409	678
1.63331	680
1.63254	684
1.63177	656
1.631	656
1.63023	664
1.62946	654
1.62869	648
1.62792	668
1.62715	670
1.62639	652
1.62562	630
1.62485	632
1.62409	618
1.62333	608
1.62256	616
1.6218	610
1.62104	590
1.62028	620
1.61952	630
1.61876	608
1.618	568
1.61724	568
1.61649	608
1.61573	624
1.61498	564
1.61422	588
1.61347	598
1.61271	550
1.61196	554
1.61121	552
1.61046	536
1.60971	570
1.60896	540
1.60821	546
1.60747	506
1.60672	520
1.60597	518
1.60523	502
1.60448	528
1.60374	514
1.603	520
1.60225	510
1.60151	504
1.60077	500
1.60003	520
1.59929	498
1.59855	512
1.59782	490
1.59708	462
1.59634	508
1.59561	478
1.59487	468
1.59414	452
1.5934	466
1.59267	448
1.59194	434
1.59121	460
1.59048	436
1.58975	424
1.58902	430
1.58829	426
1.58756	440
1.58684	444
1.58611	406
1.58538	428
1.58466	408
1.58394	432
1.58321	420
1.58249	418
1.58177	404
1.58105	412
1.58033	408
1.57961	396
1.57889	392
1.57817	404
1.57745	396
1.57674	384
1.57602	391.824
1.5753	387.879
1.57459	364.672
1.57388	375.001
1.57316	368.247
1.57245	361.94
1.57174	347.65
1.57103	346.558
1.57032	336.327
1.56961	342.481
1.5689	334.346
1.56819	341.237
1.56748	330.797
1.56678	320.832
1.56607	315.214
1.56544	312
1.56473	304
1.56402	324
1.56331	306
1.56261	304
1.5619	302
1.56119	322
1.56049	284
1.55979	304
1.55908	286
1.55838	274
1.55768	272
1.55698	292
1.55628	276
1.55558	304
1.55488	284
1.55418	284
1.55348	274
1.55278	282
1.55209	284
1.55139	292
1.5507	266
1.55	274
1.54931	256
1.54862	260
1.54792	246
1.54723	248
1.54654	248
1.54585	254
1.54516	250
1.54447	252
1.54378	236
1.5431	222
1.54241	232
1.54172	242
1.54104	252
1.54035	238
1.53967	224
1.53898	236
1.5383	218
1.53762	230
1.53694	236
1.53626	240
1.53558	236
1.5349	242
1.53422	220
1.53354	208
1.53286	214
1.53218	204
1.53151	220
1.53083	216
1.53016	218
1.52948	200
1.52881	216
1.52813	198
1.52746	198
1.52679	220
1.52612	224
1.52545	218
1.52478	206
1.52411	206
1.52344	204
1.52277	206
1.5221	202
1.52144	178
1.52077	174
1.52011	200
1.51944	206
1.51878	198
1.51811	188
1.51745	182
1.51679	178
1.51613	180
1.51547	172
1.51481	174
1.51415	180
1.51349	184
1.51283	194
1.51217	176
1.51151	194
1.51086	176
1.5102	166
1.50954	178
1.50889	152
1.50824	178
1.50758	170
1.50693	158
1.50628	176
1.50563	170
1.50497	164
1.50432	152
1.50367	152
1.50302	156
1.50238	172
1.50173	152
1.50108	168
1.50043	146
1.49979	152
1.49914	140
1.4985	150
1.49785	140
1.49721	150
1.49657	142
1.49592	148
1.49528	152
1.49464	140
1.494	146
1.49336	142
1.49272	134
1.49208	122
1.49144	142
1.49081	140
1.49017	134
1.48953	138
1.4889	142
1.48826	116
1.48763	122
1.48699	124.02
1.48636	130.663
1.48573	125.537
1.4851	125.206
1.48446	127.279
1.48383	140.243
1.4832	116.372
1.48257	115.398
1.48194	112.794
1.48132	114.357
1.48069	106.507
1.48006	106.54
1.47943	120.423
1.47881	118.867
1.47818	112.1
1.47756	110
1.47694	94
1.47631	104
1.47568	90
1.47505	100
1.47443	90
1.4738	112
1.47318	108
1.47256	88
1.47193	104
1.47131	90
1.47069	84
1.47006	90
1.46944	78
1.46882	88
1.4682	96
1.46758	94
1.46696	108
1.46635	100
1.46573	86
1.46511	80
1.46449	76
1.46388	70
1.46326	74
1.46265	84
1.46203	100
1.46142	84
1.46081	76
1.46019	60
1.45958	56
1.45897	54
1.45836	76
1.45775	68
1.45714	78
1.45653	60
1.45592	68
1.45531	62
1.4547	50
1.4541	46
1.45349	46
1.45288	54
1.45228	46
1.45167	40
1.45107	34
1.45047	36
1.44986	36
1.44926	36
1.44866	36
1.44806	32
1.44746	34
1.44686	22
1.44626	28
1.44566	32
1.44506	32
1.44446	26
1.44386	28
1.44326	28
1.44267	32
1.44207	30
1.44148	38
1.44088	30
1.44029	26
1.43969	30
1.4391	28
1.43851	24
1.43791	34
1.43732	22
1.43673	36
1.43614	22
1.43555	24
1.43496	28
1.43437	30
1.43378	28
1.4332	28
1.43261	28
1.43202	22
1.43143	28
1.43085	26
1.43026	26
1.42968	26
1.42909	28
1.42851	28
1.42793	28
1.42734	28
1.42676	24
1.42618	30
1.4256	36
1.42502	26
1.42444	36
1.42386	28
1.42328	24
1.4227	32
1.42212	28
1.42155	34
1.42097	28
1.42039	24
1.41982	24
1.41924	26
1.41867	24
1.41809	32
1.41752	28
1.41695	24
1.41637	28
1.4158	24
1.41523	36
1.41466	18
1.41409	32
1.41352	32
1.41295	34
1.41238	24
1.41181	24
1.41124	26
1.41067	40
1.41011	28
1.40954	34
1.40897	42
1.40841	44
1.40784	43.975
1.40728	45.6554
1.40672	41.4339
1.40615	40.8149
1.40559	52.9181
1.40503	57.7491
1.40446	160.515
1.4039	50.1178
1.40334	55.1531
1.40278	52.6977
1.40222	50.9393
1.40166	56.0609
1.4011	58.9332
1.40054	63.1403
1.39999	49.1155
1.39947	52
1.3989	52
1.39834	64
1.39779	60
1.39723	72
1.39667	58
1.39611	58
1.39555	62
1.395	54
1.39444	56
1.39388	54
1.39333	66
1.39277	56
1.39222	56
1.39166	66
1.39111	64
1.39056	62
1.39	62
1.38945	56
1.3889	52
1.38835	60
1.3878	56
1.38725	56
1.3867	50
1.38615	52
1.3856	60
1.38505	58
1.3845	56
1.38396	62
1.38341	56
1.38286	58
1.38232	56
1.38177	56
1.38123	66
1.38068	62
1.38014	60
1.3796	50
1.37905	58
1.37851	50
1.37797	62
1.37743	66
1.37688	52
1.37634	50
1.3758	52
1.37526	50
1.37472	54
1.37419	52
1.37365	48
1.37311	48
1.37257	52
1.37204	60
1.3715	60
1.37096	52
1.37043	46
1.36989	58
1.36936	52
1.36882	40
1.36829	46
1.36776	60
1.36722	46
1.36669	56
1.36616	60
1.36563	40
1.3651	54
1.36457	58
1.36404	48
1.36351	44
1.36298	52
1.36245	56
1.36192	52
1.36139	52
1.36087	50
1.36034	40
1.35981	54
1.35929	48
1.35876	42
1.35824	44
1.35771	44
1.35719	50
1.35667	52
1.35614	42
1.35562	54
1.3551	52
1.35458	58
1.35406	54
1.35353	40
1.35301	38
1.35249	46
1.35197	52
1.35146	48
1.35094	40
1.35042	44
1.3499	46
1.34938	50
1.34887	48
1.34835	32
1.34783	38
1.34732	40
1.3468	48
1.34629	54
1.34578	42
1.34526	38
1.34475	42
1.34424	46
1.34372	54
1.34321	48
1.3427	46
1.34219	48
1.34168	40
1.34117	54
1.34066	42
1.34015	36
1.33964	46
1.33913	50
1.33862	48
1.33812	44
1.33761	36
1.3371	36.1942
1.3366	44.0829
1.33609	41.0838
1.33558	42.0134
1.33508	43.1845
1.33457	39.4475
1.33407	38.1087
1.33357	41.1499
1.33306	40.7242
1.33256	41.0225
1.33206	40.9356
1.33156	38.9438
1.33105	37.258
1.33055	39.72
1.33005	39.9515
1.32959	44
1.32909	42
1.32859	40
1.32809	42
1.32758	40
1.32708	32
1.32658	40
1.32608	42
1.32558	42
1.32508	38
1.32458	44
1.32408	36
1.32358	42
1.32309	36
1.32259	40
1.32209	36
1.3216	38
1.3211	46
1.3206	34
1.32011	40
1.31961	40
1.31912	44
1.31862	42
1.31813	44
1.31764	44
1.31714	46
1.31665	46
1.31616	48
1.31567	42
1.31518	36
1.31468	36
1.31419	38
1.3137	34
1.31321	38
1.31272	40
1.31224	42
1.31175	48
1.31126	40
1.31077	40
1.31028	46
1.3098	40
1.30931	44
1.30882	44
1.30834	34
1.30785	36
1.30737	44
1.30688	38
1.3064	48
1.30592	52
1.30543	40
1.30495	44
1.30447	34
1.30399	44
1.3035	36
1.30302	38
1.30254	48
1.30206	34
1.30158	44
1.3011	40
1.30062	42
1.30014	42
1.30001	44