File: ploting_and_data_tools.ipynb/___archivosraman/CdSe1_11.txt
#Acq. time (s)=	1
#Accumulations=	1
#Range (eV)=	2...1
#Windows=	11
#Autofocus=	Off
#AutoExposure=	Off
#Spike filter=	Off
#Delay time (s)=	0
#Binning=	1
#Readout mode=	Signal
#DeNoise=	Off
#ICS correction=	Off
#Dark correction=	Off
#Inst. Process=	Off
#Instrument=	LabRAM HR Evol
#Detector=	Syncerity OE
#Objective=	x100_VIS_LWD
#Grating=	600 (500nm)
#ND Filter=	3.2%
#Laser=	442nm_Notch
#Hole=	100.021
#Range=	Visible
#Project=	Paty
#Sample=
#Site=	15-06-22
#Title=	CdSe1
#Remark=
#Date=	15.06.2022 20:33
#Acquired=	15.06.2022 20:33:12
2.74975	26
2.7475	28
2.74525	28
2.743	36
2.74076	34
2.73852	34
2.73629	30
2.73406	24
2.73183	28
2.72961	28
2.72739	36
2.72517	30
2.72296	30
2.72075	34
2.71854	28
2.71634	38
2.71414	30
2.71195	28
2.70976	34
2.70757	30
2.70539	36
2.70321	36
2.70103	34
2.69886	34
2.69669	44
2.69452	36
2.69236	40
2.6902	38
2.68805	34
2.6859	38
2.68375	40
2.68161	36
2.67947	34
2.67733	38
2.6752	36
2.67307	40
2.67094	44
2.66882	44
2.6667	40
2.66458	42
2.66247	40
2.66036	40
2.65826	50
2.65615	44
2.65405	40
2.65196	48
2.64987	42
2.64778	50
2.64569	52
2.64361	54
2.64153	50
2.63946	54
2.63739	58
2.63532	46
2.63325	52
2.63119	54
2.62913	56
2.62708	54
2.62503	60
2.62298	74
2.62094	64
2.61889	54
2.61686	68
2.61482	70
2.61279	70
2.61076	66
2.60873	72
2.60671	76
2.60469	74
2.60268	88
2.60067	78
2.59866	84
2.59665	86
2.59465	94
2.59265	88
2.59065	106
2.58866	102
2.58667	102
2.58468	98
2.5827	120
2.58072	106
2.57874	106
2.57677	114
2.5748	140
2.57283	142
2.57086	144
2.5689	132
2.56694	142
2.56499	152
2.56304	146
2.56109	150
2.55914	156
2.5572	158
2.55526	164
2.55332	194
2.55139	194
2.54946	196
2.54753	204
2.5456	212
2.54368	226
2.54176	222
2.53985	250
2.53794	244
2.53603	246
2.53412	252
2.53222	262
2.53031	268
2.52842	310
2.52652	286
2.52463	302
2.52274	306
2.52085	316
2.51897	344
2.51709	342
2.51521	380
2.51334	366
2.51147	380
2.5096	402
2.50773	438
2.50587	420
2.50401	442
2.50216	446
2.5003	460
2.49845	500
2.4966	512
2.49476	520
2.49291	522
2.49107	534
2.48924	566
2.4874	604
2.48557	614
2.48374	584
2.48192	638.252
2.48009	645.391
2.47827	657.957
2.47646	665.753
2.47464	707.851
2.47283	720.663
2.47102	727.415
2.46922	757.037
2.46741	777.604
2.46561	800.414
2.46381	823.278
2.46202	830.204
2.46023	843.249
2.45844	874.17
2.45665	898.615
2.45493	942
2.45314	936
2.45136	994
2.44957	994
2.44779	964
2.44601	988
2.44424	1008
2.44247	1062
2.4407	1074
2.43893	1086
2.43716	1078
2.4354	1150
2.43364	1128
2.43188	1182
2.43013	1218
2.42838	1228
2.42663	1230
2.42488	1230
2.42314	1236
2.4214	1282
2.41966	1306
2.41792	1280
2.41619	1276
2.41446	1308
2.41273	1328
2.411	1344
2.40928	1340
2.40756	1396
2.40584	1392
2.40413	1412
2.40241	1388
2.4007	1360
2.39899	1386
2.39729	1380
2.39559	1442
2.39389	1404
2.39219	1420
2.39049	1424
2.3888	1430
2.38711	1482
2.38542	1454
2.38374	1466
2.38205	1432
2.38037	1420
2.37869	1468
2.37702	1436
2.37535	1392
2.37368	1444
2.37201	1432
2.37034	1408
2.36868	1448
2.36702	1414
2.36536	1454
2.3637	1392
2.36205	1414
2.3604	1410
2.35875	1372
2.3571	1350
2.35546	1284
2.35382	1304
2.35218	1302
2.35054	1264
2.34891	1256
2.34727	1264
2.34564	1296
2.34402	1232
2.34239	1202
2.34077	1186
2.33915	1168
2.33753	1162
2.33591	1166
2.3343	1126
2.33269	1150
2.33108	1116
2.32948	1082
2.32787	1090
2.32627	1054
2.32467	1018
2.32307	1038
2.32148	1050
2.31989	1022
2.3183	978
2.31671	966
2.31512	930
2.31354	958
2.31196	934
2.31038	922
2.3088	910
2.30723	890
2.30565	894
2.30408	874
2.30252	900
2.30095	826
2.29939	856
2.29783	830
2.29627	802
2.29471	810
2.29316	798
2.29161	784
2.29006	754
2.28851	758
2.28696	790
2.28542	752
2.28388	710
2.28234	738
2.2808	718
2.27927	730
2.27773	692
2.2762	708
2.27468	718
2.27315	672
2.27163	676
2.27011	648
2.26859	654
2.26707	656
2.26555	638
2.26404	668
2.26253	657.27
2.26102	626.995
2.25951	623.054
2.25801	644.093
2.25651	608.446
2.25501	624.041
2.25351	600.928
2.25201	603.433
2.25052	589.863
2.24902	581.988
2.24753	558.241
2.24605	543.424
2.24456	548.145
2.24308	538.825
2.2416	543.726
2.24011	502
2.23863	544
2.23715	510
2.23567	532
2.23419	532
2.23271	506
2.23124	532
2.22977	498
2.2283	484
2.22683	516
2.22536	496
2.2239	508
2.22244	506
2.22098	492
2.21952	484
2.21807	492
2.21661	492
2.21516	466
2.21371	466
2.21226	452
2.21082	480
2.20937	486
2.20793	442
2.20649	466
2.20505	452
2.20362	470
2.20218	476
2.20075	472
2.19932	460
2.19789	476
2.19647	452
2.19504	454
2.19362	462
2.1922	464
2.19078	464
2.18936	442
2.18795	460
2.18654	458
2.18513	450
2.18372	458
2.18231	452
2.18091	446
2.1795	426
2.1781	444
2.1767	464
2.1753	452
2.17391	472
2.17251	420
2.17112	438
2.16973	450
2.16834	432
2.16696	434
2.16557	444
2.16419	446
2.16281	442
2.16143	468
2.16005	488
2.15868	452
2.1573	496
2.15593	434
2.15456	456
2.1532	472
2.15183	474
2.15046	446
2.1491	452
2.14774	452
2.14638	454
2.14503	440
2.14367	466
2.14232	458
2.14097	464
2.13962	452
2.13827	466
2.13692	464
2.13558	454
2.13423	492
2.13289	472
2.13155	460
2.13022	458
2.12888	456
2.12755	456
2.12621	464
2.12488	468
2.12356	478
2.12223	472
2.1209	468
2.11958	472
2.11826	502
2.11694	470
2.11562	480
2.1143	492
2.11299	476
2.11168	448
2.11037	468
2.10906	508
2.10775	476
2.10644	488
2.10514	462
2.10384	492
2.10253	472
2.10123	514
2.09994	476
2.09864	474
2.09735	476
2.09605	504
2.09476	492
2.09347	514
2.09219	510
2.0909	496
2.08962	512
2.08834	506
2.08705	510
2.08578	506
2.0845	492
2.08322	486
2.08195	514
2.08068	516
2.0794	487.484
2.07814	491.489
2.07687	484.449
2.0756	475.785
2.07434	498.258
2.07307	482.162
2.07181	481.008
2.07055	488.698
2.0693	460.832
2.06804	476.438
2.06679	499.584
2.06553	463.705
2.06428	470.484
2.06303	467.813
2.06178	479.168
2.06069	486
2.05944	456
2.05819	480
2.05694	482
2.05569	480
2.05445	466
2.05321	492
2.05196	456
2.05072	498
2.04949	448
2.04825	472
2.04701	482
2.04578	458
2.04455	446
2.04332	442
2.04209	444
2.04086	442
2.03964	436
2.03841	456
2.03719	464
2.03597	490
2.03475	434
2.03353	420
2.03232	474
2.0311	472
2.02989	452
2.02868	456
2.02747	466
2.02626	410
2.02505	414
2.02384	444
2.02264	452
2.02144	448
2.02024	466
2.01904	476
2.01784	426
2.01664	454
2.01544	464
2.01425	426
2.01306	444
2.01187	452
2.01068	448
2.00949	444
2.0083	470
2.00712	466
2.00594	484
2.00475	454
2.00357	468
2.0024	432
2.00122	474
2.00004	462
1.99887	460
1.99769	428
1.99652	470
1.99535	468
1.99418	488
1.99302	432
1.99185	464
1.99069	462
1.98952	470
1.98836	460
1.9872	462
1.98604	482
1.98488	478
1.98373	486
1.98257	488
1.98142	486
1.98027	486
1.97912	470
1.97797	456
1.97682	478
1.97568	492
1.97453	480
1.97339	502
1.97225	478
1.97111	476
1.96997	472
1.96883	474
1.9677	468
1.96656	488
1.96543	478
1.9643	508
1.96316	452
1.96204	458
1.96091	480
1.95978	482
1.95866	470
1.95753	494
1.95641	460
1.95529	506
1.95417	480
1.95305	466
1.95193	494
1.95082	456
1.9497	494
1.94859	484
1.94748	452
1.94637	470
1.94526	482
1.94415	494
1.94305	466
1.94194	466
1.94084	462
1.93974	474
1.93864	454
1.93754	484
1.93644	472
1.93534	470
1.93425	460
1.93315	460
1.93206	452
1.93097	444
1.92988	468
1.92879	442
1.9277	470
1.92662	458
1.92553	458
1.92445	442.042
1.92337	467.457
1.92228	442.513
1.92121	446.179
1.92013	458.34
1.91905	452.367
1.91797	445.89
1.9169	438.456
1.91583	450.14
1.91475	432.765
1.91368	465.693
1.91261	464.625
1.91155	439.21
1.91048	456.576
1.90946	434
1.90839	438
1.90732	452
1.90626	444
1.90519	454
1.90413	416
1.90306	416
1.902	424
1.90094	416
1.89988	430
1.89882	454
1.89777	416
1.89671	440
1.89566	422
1.8946	438
1.89355	440
1.8925	422
1.89145	402
1.8904	422
1.88936	442
1.88831	418
1.88727	430
1.88622	418
1.88518	426
1.88414	412
1.8831	414
1.88206	400
1.88102	414
1.87999	416
1.87895	432
1.87792	396
1.87689	414
1.87586	390
1.87483	386
1.8738	396
1.87277	404
1.87174	384
1.87072	390
1.86969	410
1.86867	388
1.86765	392
1.86663	388
1.86561	378
1.86459	408
1.86357	388
1.86256	352
1.86154	344
1.86053	360
1.85952	368
1.85851	378
1.8575	364
1.85649	350
1.85548	364
1.85447	376
1.85347	354
1.85247	360
1.85146	374
1.85046	400
1.84946	364
1.84846	378
1.84746	342
1.84646	328
1.84547	368
1.84447	332
1.84348	340
1.84249	346
1.8415	338
1.84051	346
1.83952	338
1.83853	342
1.83754	350
1.83656	338
1.83557	340
1.83459	326
1.83361	342
1.83262	350
1.83164	328
1.83066	308
1.82969	332
1.82871	324
1.82773	328
1.82676	340
1.82579	324
1.82481	322
1.82384	322
1.82287	284
1.8219	304
1.82094	338
1.81997	312
1.819	304
1.81804	326
1.81708	314
1.81611	306
1.81515	296
1.81419	312
1.81323	308
1.81227	288
1.81132	304
1.81036	326
1.80941	282
1.80845	304
1.8075	298
1.80655	286
1.8056	278
1.80465	290
1.8037	292
1.80275	292
1.80181	298
1.80086	260
1.79992	276
1.79897	272
1.79803	280
1.79709	294
1.79615	276
1.79521	268
1.79428	276
1.79334	252
1.7924	260
1.79147	268.443
1.79053	272.084
1.7896	259.14
1.78867	254.201
1.78774	264.775
1.78681	248.716
1.78588	254.835
1.78496	259.783
1.78403	254.443
1.7831	235.49
1.78218	238.916
1.78126	239.444
1.78033	253.604
1.77941	246.295
1.77851	228
1.77759	238
1.77667	238
1.77575	242
1.77483	216
1.77391	214
1.77299	230
1.77207	222
1.77115	230
1.77024	224
1.76932	220
1.76841	220
1.7675	206
1.76659	206
1.76568	218
1.76477	206
1.76386	214
1.76295	212
1.76204	216
1.76114	220
1.76023	202
1.75933	200
1.75843	196
1.75753	196
1.75662	200
1.75572	188
1.75483	190
1.75393	194
1.75303	198
1.75214	190
1.75124	170
1.75035	202
1.74945	174
1.74856	176
1.74767	182
1.74678	180
1.74589	188
1.74501	184
1.74412	182
1.74323	182
1.74235	182
1.74146	166
1.74058	176
1.7397	186
1.73882	172
1.73794	168
1.73706	184
1.73618	168
1.7353	168
1.73443	188
1.73355	172
1.73268	172
1.7318	164
1.73093	182
1.73006	160
1.72919	164
1.72832	166
1.72745	152
1.72658	170
1.72571	160
1.72485	158
1.72398	160
1.72312	154
1.72225	144
1.72139	166
1.72053	168
1.71967	164
1.71881	150
1.71795	146
1.71709	142
1.71624	152
1.71538	156
1.71453	168
1.71367	152
1.71282	144
1.71197	150
1.71112	128
1.71027	150
1.70942	144
1.70857	136
1.70772	138
1.70687	144
1.70603	144
1.70518	142
1.70434	142
1.7035	144
1.70265	136
1.70181	140
1.70097	156
1.70013	138
1.69929	136
1.69846	144
1.69762	128
1.69678	110
1.69595	134
1.69511	130
1.69428	110
1.69345	130
1.69262	126
1.69179	126
1.69096	122
1.69013	132
1.6893	116
1.68847	128
1.68765	112
1.68682	122
1.686	112
1.68517	128
1.68435	116
1.68353	130
1.68271	110
1.68189	124
1.68107	122
1.68025	110
1.67943	110
1.67861	128
1.6778	110
1.67698	108.107
1.67617	117.733
1.67536	119.781
1.67454	114.125
1.67373	118.511
1.67292	119.018
1.67211	114.788
1.6713	103.452
1.6705	113.229
1.66969	105.572
1.66888	111.401
1.66808	116.264
1.66727	111.816
1.66647	110.252
1.66566	104.262
1.6649	124
1.66409	104
1.66329	122
1.66249	110
1.66168	110
1.66088	108
1.66008	96
1.65928	106
1.65848	112
1.65768	106
1.65688	104
1.65608	88
1.65529	96
1.65449	100
1.6537	92
1.6529	96
1.65211	110
1.65132	110
1.65053	106
1.64973	102
1.64894	106
1.64816	98
1.64737	100
1.64658	102
1.64579	110
1.64501	100
1.64422	100
1.64344	98
1.64265	86
1.64187	90
1.64109	82
1.64031	96
1.63953	90
1.63875	94
1.63797	98
1.63719	102
1.63642	92
1.63564	94
1.63486	88
1.63409	94
1.63331	84
1.63254	98
1.63177	94
1.631	80
1.63023	90
1.62946	94
1.62869	80
1.62792	94
1.62715	80
1.62639	84
1.62562	86
1.62485	106
1.62409	86
1.62333	84
1.62256	80
1.6218	76
1.62104	82
1.62028	92
1.61952	76
1.61876	76
1.618	84
1.61724	84
1.61649	72
1.61573	70
1.61498	84
1.61422	80
1.61347	80
1.61271	88
1.61196	82
1.61121	84
1.61046	82
1.60971	72
1.60896	60
1.60821	76
1.60747	74
1.60672	76
1.60597	82
1.60523	78
1.60448	70
1.60374	74
1.603	76
1.60225	74
1.60151	58
1.60077	58
1.60003	72
1.59929	70
1.59855	82
1.59782	72
1.59708	78
1.59634	76
1.59561	70
1.59487	74
1.59414	64
1.5934	68
1.59267	62
1.59194	72
1.59121	72
1.59048	60
1.58975	60
1.58902	74
1.58829	76
1.58756	68
1.58684	66
1.58611	56
1.58538	66
1.58466	46
1.58394	64
1.58321	68
1.58249	64
1.58177	58
1.58105	68
1.58033	60
1.57961	62
1.57889	54
1.57817	70
1.57745	64
1.57674	56
1.57602	51.9875
1.5753	60.0736
1.57459	52.1236
1.57388	59.645
1.57316	58.0792
1.57245	52.8846
1.57174	52.799
1.57103	54.0932
1.57032	54.8932
1.56961	58.6376
1.5689	58.7349
1.56819	56.3727
1.56748	54.3267
1.56678	62.4701
1.56607	54.3413
1.56544	46
1.56473	46
1.56402	60
1.56331	46
1.56261	52
1.5619	52
1.56119	46
1.56049	54
1.55979	56
1.55908	54
1.55838	54
1.55768	50
1.55698	36
1.55628	52
1.55558	50
1.55488	48
1.55418	48
1.55348	48
1.55278	64
1.55209	64
1.55139	42
1.5507	48
1.55	58
1.54931	54
1.54862	48
1.54792	48
1.54723	48
1.54654	48
1.54585	56
1.54516	60
1.54447	52
1.54378	56
1.5431	50
1.54241	56
1.54172	54
1.54104	46
1.54035	46
1.53967	44
1.53898	44
1.5383	54
1.53762	48
1.53694	50
1.53626	42
1.53558	40
1.5349	48
1.53422	36
1.53354	48
1.53286	48
1.53218	50
1.53151	50
1.53083	46
1.53016	48
1.52948	38
1.52881	44
1.52813	52
1.52746	36
1.52679	38
1.52612	44
1.52545	52
1.52478	46
1.52411	48
1.52344	40
1.52277	38
1.5221	38
1.52144	42
1.52077	34
1.52011	48
1.51944	40
1.51878	44
1.51811	38
1.51745	46
1.51679	44
1.51613	42
1.51547	46
1.51481	44
1.51415	38
1.51349	44
1.51283	48
1.51217	40
1.51151	40
1.51086	40
1.5102	40
1.50954	34
1.50889	34
1.50824	42
1.50758	42
1.50693	36
1.50628	40
1.50563	44
1.50497	36
1.50432	32
1.50367	36
1.50302	30
1.50238	42
1.50173	44
1.50108	40
1.50043	40
1.49979	38
1.49914	44
1.4985	38
1.49785	28
1.49721	46
1.49657	32
1.49592	34
1.49528	42
1.49464	38
1.494	32
1.49336	40
1.49272	44
1.49208	38
1.49144	34
1.49081	40
1.49017	36
1.48953	32
1.4889	44
1.48826	40
1.48763	28
1.48699	32.0198
1.48636	37.6578
1.48573	38.9806
1.4851	33.5833
1.48446	35.347
1.48383	32.3641
1.4832	37.393
1.48257	36
1.48194	38.1683
1.48132	35.4912
1.48069	34.2537
1.48006	37.5347
1.47943	36.0563
1.47881	34.743
1.47818	34
1.47756	36
1.47694	30
1.47631	30
1.47568	36
1.47505	42
1.47443	34
1.4738	30
1.47318	36
1.47256	40
1.47193	38
1.47131	34
1.47069	32
1.47006	32
1.46944	32
1.46882	36
1.4682	34
1.46758	36
1.46696	32
1.46635	28
1.46573	34
1.46511	36
1.46449	36
1.46388	38
1.46326	30
1.46265	32
1.46203	38
1.46142	28
1.46081	42
1.46019	38
1.45958	34
1.45897	32
1.45836	28
1.45775	22
1.45714	34
1.45653	36
1.45592	34
1.45531	36
1.4547	32
1.4541	28
1.45349	40
1.45288	34
1.45228	30
1.45167	28
1.45107	20
1.45047	32
1.44986	20
1.44926	32
1.44866	32
1.44806	40
1.44746	32
1.44686	28
1.44626	28
1.44566	32
1.44506	30
1.44446	36
1.44386	34
1.44326	24
1.44267	32
1.44207	26
1.44148	28
1.44088	26
1.44029	30
1.43969	22
1.4391	30
1.43851	30
1.43791	30
1.43732	30
1.43673	36
1.43614	26
1.43555	34
1.43496	32
1.43437	28
1.43378	32
1.4332	24
1.43261	32
1.43202	34
1.43143	24
1.43085	40
1.43026	28
1.42968	30
1.42909	26
1.42851	30
1.42793	26
1.42734	30
1.42676	30
1.42618	32
1.4256	28
1.42502	26
1.42444	28
1.42386	30
1.42328	30
1.4227	22
1.42212	22
1.42155	34
1.42097	30
1.42039	28
1.41982	20
1.41924	30
1.41867	32
1.41809	36
1.41752	20
1.41695	26
1.41637	24
1.4158	28
1.41523	30
1.41466	20
1.41409	24
1.41352	28
1.41295	26
1.41238	32
1.41181	26
1.41124	30
1.41067	28
1.41011	34
1.40954	30
1.40897	26
1.40841	24
1.40784	33.9686
1.40728	31.5816
1.40672	31.4257
1.40615	29.1485
1.40559	22
1.40503	28.3015
1.40446	106.779
1.4039	29.0198
1.40334	33.4594
1.40278	30.7612
1.40222	31.6375
1.40166	30.0389
1.4011	29.9668
1.40054	30.4458
1.39999	32.1652
1.39947	36
1.3989	36
1.39834	32
1.39779	32
1.39723	32
1.39667	26
1.39611	32
1.39555	32
1.395	28
1.39444	20
1.39388	32
1.39333	30
1.39277	26
1.39222	30
1.39166	34
1.39111	28
1.39056	30
1.39	34
1.38945	32
1.3889	36
1.38835	32
1.3878	22
1.38725	34
1.3867	28
1.38615	36
1.3856	30
1.38505	36
1.3845	32
1.38396	28
1.38341	32
1.38286	34
1.38232	22
1.38177	28
1.38123	26
1.38068	34
1.38014	26
1.3796	26
1.37905	28
1.37851	34
1.37797	38
1.37743	36
1.37688	36
1.37634	36
1.3758	24
1.37526	28
1.37472	30
1.37419	32
1.37365	30
1.37311	34
1.37257	36
1.37204	32
1.3715	32
1.37096	26
1.37043	24
1.36989	32
1.36936	34
1.36882	26
1.36829	36
1.36776	36
1.36722	30
1.36669	28
1.36616	36
1.36563	28
1.3651	30
1.36457	30
1.36404	22
1.36351	28
1.36298	36
1.36245	30
1.36192	38
1.36139	26
1.36087	34
1.36034	36
1.35981	28
1.35929	30
1.35876	34
1.35824	26
1.35771	30
1.35719	42
1.35667	34
1.35614	32
1.35562	28
1.3551	26
1.35458	34
1.35406	32
1.35353	28
1.35301	22
1.35249	34
1.35197	26
1.35146	42
1.35094	30
1.35042	24
1.3499	42
1.34938	24
1.34887	30
1.34835	32
1.34783	32
1.34732	30
1.3468	32
1.34629	30
1.34578	26
1.34526	34
1.34475	32
1.34424	36
1.34372	30
1.34321	28
1.3427	32
1.34219	24
1.34168	32
1.34117	32
1.34066	30
1.34015	28
1.33964	26
1.33913	32
1.33862	30
1.33812	24
1.33761	26
1.3371	28.0485
1.3366	24.1167
1.33609	26.6857
1.33558	33.0427
1.33508	29.4407
1.33457	31.263
1.33407	29.8097
1.33357	32.8501
1.33306	28.4603
1.33256	20.8027
1.33206	32.4466
1.33156	27.9338
1.33105	25.4318
1.33055	27.2265
1.33005	25.0717
1.32959	32
1.32909	30
1.32859	28
1.32809	26
1.32758	24
1.32708	36
1.32658	32
1.32608	22
1.32558	26
1.32508	26
1.32458	36
1.32408	34
1.32358	28
1.32309	28
1.32259	30
1.32209	26
1.3216	32
1.3211	22
1.3206	26
1.32011	34
1.31961	32
1.31912	32
1.31862	32
1.31813	34
1.31764	30
1.31714	32
1.31665	32
1.31616	28
1.31567	30
1.31518	32
1.31468	28
1.31419	26
1.3137	26
1.31321	32
1.31272	34
1.31224	36
1.31175	34
1.31126	28
1.31077	30
1.31028	28
1.3098	26
1.30931	30
1.30882	32
1.30834	36
1.30785	30
1.30737	32
1.30688	26
1.3064	28
1.30592	30
1.30543	32
1.30495	36
1.30447	26
1.30399	32
1.3035	34
1.30302	34
1.30254	38
1.30206	36
1.30158	28
1.3011	30
1.30062	32
1.30014	40
1.30001	30