File: ploting_and_data_tools.ipynb/___archivosraman/CdSe4_01.txt
#Acq. time (s)=	1
#Accumulations=	1
#Range (eV)=	2...1
#Windows=	11
#Autofocus=	Off
#AutoExposure=	Off
#Spike filter=	Off
#Delay time (s)=	0
#Binning=	1
#Readout mode=	Signal
#DeNoise=	Off
#ICS correction=	Off
#Dark correction=	Off
#Inst. Process=	Off
#Instrument=	LabRAM HR Evol
#Detector=	Syncerity OE
#Objective=	x100_VIS_LWD
#Grating=	600 (500nm)
#ND Filter=	1%
#Laser=	442nm_Notch
#Hole=	150.001
#Range=	Visible
#Project=	Paty
#Sample=
#Site=	15-06-22
#Title=	CdSe4
#Remark=
#Date=	15.06.2022 21:29
#Acquired=	15.06.2022 21:29:14
2.74975	28
2.7475	30
2.74525	26
2.743	40
2.74076	26
2.73852	30
2.73629	30
2.73406	30
2.73183	32
2.72961	32
2.72739	32
2.72517	32
2.72296	34
2.72075	34
2.71854	30
2.71634	40
2.71414	34
2.71195	30
2.70976	36
2.70757	48
2.70539	40
2.70321	34
2.70103	34
2.69886	38
2.69669	30
2.69452	32
2.69236	36
2.6902	38
2.68805	36
2.6859	38
2.68375	38
2.68161	32
2.67947	34
2.67733	44
2.6752	38
2.67307	40
2.67094	34
2.66882	44
2.6667	42
2.66458	44
2.66247	34
2.66036	42
2.65826	40
2.65615	40
2.65405	52
2.65196	46
2.64987	48
2.64778	40
2.64569	50
2.64361	46
2.64153	48
2.63946	52
2.63739	50
2.63532	56
2.63325	50
2.63119	50
2.62913	58
2.62708	56
2.62503	58
2.62298	72
2.62094	62
2.61889	58
2.61686	56
2.61482	56
2.61279	70
2.61076	74
2.60873	78
2.60671	58
2.60469	74
2.60268	78
2.60067	80
2.59866	76
2.59665	86
2.59465	94
2.59265	94
2.59065	92
2.58866	94
2.58667	92
2.58468	104
2.5827	106
2.58072	104
2.57874	102
2.57677	126
2.5748	116
2.57283	120
2.57086	128
2.5689	114
2.56694	148
2.56499	142
2.56304	156
2.56109	160
2.55914	156
2.5572	164
2.55526	190
2.55332	184
2.55139	180
2.54946	218
2.54753	214
2.5456	238
2.54368	220
2.54176	236
2.53985	240
2.53794	250
2.53603	272
2.53412	278
2.53222	284
2.53031	308
2.52842	316
2.52652	310
2.52463	348
2.52274	382
2.52085	350
2.51897	380
2.51709	378
2.51521	424
2.51334	418
2.51147	432
2.5096	448
2.50773	492
2.50587	508
2.50401	556
2.50216	542
2.5003	532
2.49845	586
2.4966	610
2.49476	596
2.49291	646
2.49107	634
2.48924	696
2.4874	692
2.48557	734
2.48374	742
2.48192	786.501
2.48009	818.82
2.47827	847.55
2.47646	897.624
2.47464	892.875
2.47283	938.281
2.47102	966.309
2.46922	977.588
2.46741	1007.26
2.46561	1063.97
2.46381	1081.23
2.46202	1123.24
2.46023	1181.59
2.45844	1202.96
2.45665	1206.37
2.45493	1276
2.45314	1322
2.45136	1354
2.44957	1370
2.44779	1400
2.44601	1416
2.44424	1482
2.44247	1470
2.4407	1534
2.43893	1612
2.43716	1576
2.4354	1664
2.43364	1692
2.43188	1698
2.43013	1732
2.42838	1782
2.42663	1822
2.42488	1834
2.42314	1898
2.4214	1894
2.41966	1930
2.41792	1964
2.41619	1900
2.41446	2006
2.41273	2038
2.411	2004
2.40928	2078
2.40756	2144
2.40584	2122
2.40413	2188
2.40241	2236
2.4007	2230
2.39899	2292
2.39729	2276
2.39559	2234
2.39389	2302
2.39219	2342
2.39049	2342
2.3888	2378
2.38711	2348
2.38542	2388
2.38374	2428
2.38205	2502
2.38037	2474
2.37869	2460
2.37702	2460
2.37535	2508
2.37368	2530
2.37201	2518
2.37034	2546
2.36868	2452
2.36702	2592
2.36536	2448
2.3637	2526
2.36205	2462
2.3604	2486
2.35875	2466
2.3571	2470
2.35546	2502
2.35382	2398
2.35218	2392
2.35054	2362
2.34891	2320
2.34727	2370
2.34564	2334
2.34402	2248
2.34239	2362
2.34077	2330
2.33915	2288
2.33753	2218
2.33591	2204
2.3343	2238
2.33269	2204
2.33108	2184
2.32948	2122
2.32787	2108
2.32627	2024
2.32467	2128
2.32307	2008
2.32148	2082
2.31989	2064
2.3183	1988
2.31671	2022
2.31512	1982
2.31354	1926
2.31196	1906
2.31038	1898
2.3088	1910
2.30723	1900
2.30565	1846
2.30408	1852
2.30252	1870
2.30095	1804
2.29939	1806
2.29783	1772
2.29627	1698
2.29471	1734
2.29316	1728
2.29161	1772
2.29006	1688
2.28851	1660
2.28696	1624
2.28542	1622
2.28388	1652
2.28234	1660
2.2808	1562
2.27927	1588
2.27773	1556
2.2762	1500
2.27468	1530
2.27315	1464
2.27163	1538
2.27011	1520
2.26859	1464
2.26707	1472
2.26555	1412
2.26404	1426
2.26253	1432.55
2.26102	1372.49
2.25951	1389.27
2.25801	1375.83
2.25651	1324.5
2.25501	1316.21
2.25351	1295.04
2.25201	1246.71
2.25052	1257.23
2.24902	1232.4
2.24753	1188.29
2.24605	1224.82
2.24456	1183.56
2.24308	1136.25
2.2416	1167.79
2.24011	1124
2.23863	1148
2.23715	1090
2.23567	1096
2.23419	1070
2.23271	1072
2.23124	1072
2.22977	1082
2.2283	1044
2.22683	1062
2.22536	996
2.2239	1046
2.22244	1018
2.22098	966
2.21952	986
2.21807	980
2.21661	952
2.21516	966
2.21371	942
2.21226	968
2.21082	940
2.20937	942
2.20793	928
2.20649	896
2.20505	932
2.20362	924
2.20218	870
2.20075	880
2.19932	922
2.19789	882
2.19647	870
2.19504	872
2.19362	854
2.1922	902
2.19078	854
2.18936	840
2.18795	868
2.18654	876
2.18513	850
2.18372	818
2.18231	802
2.18091	808
2.1795	848
2.1781	816
2.1767	840
2.1753	862
2.17391	832
2.17251	840
2.17112	790
2.16973	802
2.16834	816
2.16696	802
2.16557	834
2.16419	818
2.16281	820
2.16143	792
2.16005	808
2.15868	812
2.1573	800
2.15593	776
2.15456	802
2.1532	816
2.15183	768
2.15046	770
2.1491	822
2.14774	778
2.14638	782
2.14503	784
2.14367	788
2.14232	808
2.14097	776
2.13962	756
2.13827	764
2.13692	770
2.13558	772
2.13423	764
2.13289	802
2.13155	776
2.13022	784
2.12888	810
2.12755	782
2.12621	774
2.12488	786
2.12356	774
2.12223	780
2.1209	782
2.11958	788
2.11826	808
2.11694	768
2.11562	770
2.1143	760
2.11299	786
2.11168	792
2.11037	768
2.10906	732
2.10775	786
2.10644	736
2.10514	784
2.10384	770
2.10253	762
2.10123	770
2.09994	758
2.09864	786
2.09735	768
2.09605	766
2.09476	792
2.09347	768
2.09219	772
2.0909	792
2.08962	774
2.08834	774
2.08705	788
2.08578	762
2.0845	796
2.08322	804
2.08195	782
2.08068	794
2.0794	772.198
2.07814	759.339
2.07687	759.37
2.0756	726.009
2.07434	750.345
2.07307	754.948
2.07181	732.014
2.07055	714.662
2.0693	716.447
2.06804	718.303
2.06679	726.55
2.06553	710.754
2.06428	702.808
2.06303	708.276
2.06178	717.324
2.06069	702
2.05944	686
2.05819	688
2.05694	752
2.05569	720
2.05445	666
2.05321	736
2.05196	676
2.05072	696
2.04949	662
2.04825	670
2.04701	690
2.04578	672
2.04455	690
2.04332	676
2.04209	702
2.04086	672
2.03964	704
2.03841	680
2.03719	640
2.03597	670
2.03475	680
2.03353	660
2.03232	628
2.0311	634
2.02989	674
2.02868	674
2.02747	696
2.02626	686
2.02505	680
2.02384	670
2.02264	630
2.02144	688
2.02024	672
2.01904	694
2.01784	680
2.01664	668
2.01544	674
2.01425	686
2.01306	706
2.01187	690
2.01068	710
2.00949	716
2.0083	730
2.00712	720
2.00594	706
2.00475	706
2.00357	724
2.0024	704
2.00122	730
2.00004	732
1.99887	718
1.99769	752
1.99652	722
1.99535	770
1.99418	726
1.99302	726
1.99185	732
1.99069	752
1.98952	726
1.98836	756
1.9872	750
1.98604	726
1.98488	754
1.98373	788
1.98257	726
1.98142	796
1.98027	766
1.97912	730
1.97797	764
1.97682	762
1.97568	750
1.97453	754
1.97339	770
1.97225	798
1.97111	762
1.96997	788
1.96883	748
1.9677	766
1.96656	790
1.96543	790
1.9643	796
1.96316	788
1.96204	772
1.96091	760
1.95978	782
1.95866	796
1.95753	778
1.95641	766
1.95529	760
1.95417	784
1.95305	760
1.95193	768
1.95082	816
1.9497	794
1.94859	780
1.94748	782
1.94637	768
1.94526	780
1.94415	798
1.94305	744
1.94194	778
1.94084	816
1.93974	780
1.93864	772
1.93754	802
1.93644	786
1.93534	778
1.93425	756
1.93315	782
1.93206	784
1.93097	800
1.92988	816
1.92879	784
1.9277	762
1.92662	790
1.92553	756
1.92445	783.452
1.92337	810.346
1.92228	775.738
1.92121	774.661
1.92013	786.411
1.91905	758.673
1.91797	777.093
1.9169	781.696
1.91583	767.597
1.91475	773.071
1.91368	768.507
1.91261	786.006
1.91155	764.887
1.91048	766.356
1.90946	780
1.90839	782
1.90732	790
1.90626	764
1.90519	768
1.90413	778
1.90306	752
1.902	790
1.90094	784
1.89988	778
1.89882	788
1.89777	816
1.89671	744
1.89566	730
1.8946	766
1.89355	782
1.8925	760
1.89145	770
1.8904	782
1.88936	776
1.88831	768
1.88727	786
1.88622	754
1.88518	760
1.88414	758
1.8831	748
1.88206	746
1.88102	758
1.87999	708
1.87895	754
1.87792	770
1.87689	738
1.87586	736
1.87483	772
1.8738	752
1.87277	760
1.87174	762
1.87072	746
1.86969	724
1.86867	760
1.86765	718
1.86663	770
1.86561	720
1.86459	780
1.86357	732
1.86256	768
1.86154	740
1.86053	764
1.85952	730
1.85851	720
1.8575	790
1.85649	724
1.85548	726
1.85447	750
1.85347	740
1.85247	732
1.85146	726
1.85046	698
1.84946	718
1.84846	764
1.84746	712
1.84646	728
1.84547	722
1.84447	732
1.84348	742
1.84249	740
1.8415	736
1.84051	706
1.83952	706
1.83853	700
1.83754	760
1.83656	704
1.83557	750
1.83459	718
1.83361	730
1.83262	708
1.83164	718
1.83066	726
1.82969	746
1.82871	716
1.82773	738
1.82676	700
1.82579	718
1.82481	732
1.82384	744
1.82287	732
1.8219	694
1.82094	706
1.81997	716
1.819	694
1.81804	666
1.81708	692
1.81611	714
1.81515	730
1.81419	710
1.81323	704
1.81227	690
1.81132	672
1.81036	632
1.80941	698
1.80845	660
1.8075	672
1.80655	676
1.8056	692
1.80465	652
1.8037	666
1.80275	670
1.80181	686
1.80086	678
1.79992	670
1.79897	650
1.79803	694
1.79709	670
1.79615	660
1.79521	692
1.79428	646
1.79334	640
1.7924	658
1.79147	646.05
1.79053	644.291
1.7896	657.302
1.78867	632.201
1.78774	650.491
1.78681	622.648
1.78588	635.29
1.78496	616.541
1.78403	596.711
1.7831	620.947
1.78218	613.109
1.78126	636.091
1.78033	599.44
1.77941	596.129
1.77851	618
1.77759	580
1.77667	612
1.77575	616
1.77483	610
1.77391	586
1.77299	590
1.77207	580
1.77115	592
1.77024	586
1.76932	602
1.76841	580
1.7675	590
1.76659	588
1.76568	572
1.76477	558
1.76386	576
1.76295	558
1.76204	548
1.76114	562
1.76023	562
1.75933	546
1.75843	560
1.75753	564
1.75662	532
1.75572	540
1.75483	526
1.75393	546
1.75303	552
1.75214	532
1.75124	538
1.75035	516
1.74945	538
1.74856	512
1.74767	534
1.74678	526
1.74589	524
1.74501	518
1.74412	504
1.74323	510
1.74235	522
1.74146	520
1.74058	512
1.7397	514
1.73882	518
1.73794	476
1.73706	518
1.73618	514
1.7353	488
1.73443	480
1.73355	482
1.73268	502
1.7318	480
1.73093	492
1.73006	464
1.72919	462
1.72832	468
1.72745	470
1.72658	438
1.72571	456
1.72485	470
1.72398	466
1.72312	464
1.72225	434
1.72139	454
1.72053	454
1.71967	424
1.71881	444
1.71795	450
1.71709	444
1.71624	430
1.71538	452
1.71453	446
1.71367	420
1.71282	432
1.71197	440
1.71112	434
1.71027	420
1.70942	422
1.70857	412
1.70772	438
1.70687	422
1.70603	372
1.70518	398
1.70434	406
1.7035	398
1.70265	396
1.70181	414
1.70097	398
1.70013	382
1.69929	386
1.69846	378
1.69762	380
1.69678	394
1.69595	358
1.69511	380
1.69428	378
1.69345	382
1.69262	360
1.69179	398
1.69096	346
1.69013	336
1.6893	356
1.68847	360
1.68765	330
1.68682	364
1.686	354
1.68517	326
1.68435	356
1.68353	352
1.68271	326
1.68189	322
1.68107	332
1.68025	368
1.67943	324
1.67861	326
1.6778	322
1.67698	330.126
1.67617	315.239
1.67536	337.518
1.67454	321.982
1.67373	313.784
1.67292	325.461
1.67211	334.594
1.6713	327.069
1.6705	316.262
1.66969	322.327
1.66888	319.071
1.66808	320.58
1.66727	313.701
1.66647	303.742
1.66566	308.961
1.6649	314
1.66409	300
1.66329	318
1.66249	308
1.66168	308
1.66088	304
1.66008	314
1.65928	300
1.65848	296
1.65768	294
1.65688	304
1.65608	296
1.65529	306
1.65449	292
1.6537	298
1.6529	284
1.65211	282
1.65132	290
1.65053	292
1.64973	288
1.64894	258
1.64816	280
1.64737	270
1.64658	276
1.64579	274
1.64501	290
1.64422	260
1.64344	256
1.64265	256
1.64187	272
1.64109	276
1.64031	278
1.63953	282
1.63875	274
1.63797	256
1.63719	264
1.63642	248
1.63564	248
1.63486	268
1.63409	254
1.63331	262
1.63254	262
1.63177	250
1.631	254
1.63023	256
1.62946	242
1.62869	242
1.62792	234
1.62715	246
1.62639	240
1.62562	214
1.62485	236
1.62409	230
1.62333	250
1.62256	224
1.6218	224
1.62104	222
1.62028	228
1.61952	218
1.61876	216
1.618	220
1.61724	236
1.61649	232
1.61573	224
1.61498	206
1.61422	234
1.61347	214
1.61271	212
1.61196	212
1.61121	222
1.61046	212
1.60971	212
1.60896	216
1.60821	204
1.60747	184
1.60672	202
1.60597	222
1.60523	200
1.60448	196
1.60374	194
1.603	200
1.60225	188
1.60151	178
1.60077	174
1.60003	190
1.59929	172
1.59855	198
1.59782	186
1.59708	178
1.59634	174
1.59561	186
1.59487	186
1.59414	178
1.5934	170
1.59267	152
1.59194	166
1.59121	180
1.59048	166
1.58975	176
1.58902	150
1.58829	168
1.58756	172
1.58684	162
1.58611	156
1.58538	164
1.58466	162
1.58394	154
1.58321	160
1.58249	164
1.58177	166
1.58105	160
1.58033	156
1.57961	146
1.57889	142
1.57817	146
1.57745	144
1.57674	156
1.57602	139.932
1.5753	146.774
1.57459	138.879
1.57388	140.749
1.57316	143.465
1.57245	140.933
1.57174	131.116
1.57103	146.252
1.57032	131.921
1.56961	140.907
1.5689	127.881
1.56819	129.156
1.56748	123.032
1.56678	120.423
1.56607	126.133
1.56544	124
1.56473	132
1.56402	120
1.56331	120
1.56261	118
1.5619	124
1.56119	110
1.56049	106
1.55979	114
1.55908	114
1.55838	114
1.55768	110
1.55698	102
1.55628	118
1.55558	138
1.55488	110
1.55418	116
1.55348	102
1.55278	110
1.55209	108
1.55139	110
1.5507	110
1.55	104
1.54931	106
1.54862	98
1.54792	116
1.54723	104
1.54654	108
1.54585	104
1.54516	106
1.54447	102
1.54378	100
1.5431	110
1.54241	108
1.54172	96
1.54104	106
1.54035	88
1.53967	88
1.53898	94
1.5383	102
1.53762	100
1.53694	90
1.53626	106
1.53558	88
1.5349	88
1.53422	94
1.53354	98
1.53286	96
1.53218	106
1.53151	88
1.53083	84
1.53016	98
1.52948	88
1.52881	78
1.52813	94
1.52746	86
1.52679	82
1.52612	82
1.52545	84
1.52478	76
1.52411	82
1.52344	78
1.52277	84
1.5221	84
1.52144	78
1.52077	80
1.52011	84
1.51944	74
1.51878	80
1.51811	76
1.51745	90
1.51679	76
1.51613	82
1.51547	72
1.51481	90
1.51415	70
1.51349	84
1.51283	80
1.51217	78
1.51151	76
1.51086	82
1.5102	70
1.50954	82
1.50889	70
1.50824	68
1.50758	66
1.50693	78
1.50628	68
1.50563	86
1.50497	78
1.50432	74
1.50367	64
1.50302	72
1.50238	72
1.50173	66
1.50108	62
1.50043	76
1.49979	62
1.49914	60
1.4985	68
1.49785	72
1.49721	64
1.49657	60
1.49592	74
1.49528	72
1.49464	64
1.494	64
1.49336	60
1.49272	64
1.49208	58
1.49144	60
1.49081	66
1.49017	74
1.48953	66
1.4889	64
1.48826	54
1.48763	56
1.48699	55.9901
1.48636	55.7481
1.48573	65.703
1.4851	58.9046
1.48446	68.0443
1.48383	56.4851
1.4832	48.9828
1.48257	60.0053
1.48194	59.3014
1.48132	52.6025
1.48069	50.4113
1.48006	52.2074
1.47943	62.2065
1.47881	56.5002
1.47818	60.1485
1.47756	58
1.47694	56
1.47631	54
1.47568	44
1.47505	62
1.47443	48
1.4738	54
1.47318	56
1.47256	56
1.47193	64
1.47131	56
1.47069	48
1.47006	48
1.46944	40
1.46882	46
1.4682	50
1.46758	56
1.46696	52
1.46635	50
1.46573	50
1.46511	46
1.46449	36
1.46388	48
1.46326	50
1.46265	36
1.46203	54
1.46142	40
1.46081	40
1.46019	44
1.45958	40
1.45897	36
1.45836	44
1.45775	36
1.45714	42
1.45653	52
1.45592	36
1.45531	40
1.4547	36
1.4541	34
1.45349	32
1.45288	42
1.45228	36
1.45167	30
1.45107	32
1.45047	36
1.44986	34
1.44926	32
1.44866	26
1.44806	28
1.44746	28
1.44686	32
1.44626	34
1.44566	24
1.44506	32
1.44446	28
1.44386	28
1.44326	34
1.44267	36
1.44207	24
1.44148	30
1.44088	32
1.44029	20
1.43969	20
1.4391	24
1.43851	30
1.43791	28
1.43732	28
1.43673	26
1.43614	28
1.43555	34
1.43496	24
1.43437	32
1.43378	24
1.4332	24
1.43261	36
1.43202	28
1.43143	30
1.43085	32
1.43026	28
1.42968	26
1.42909	28
1.42851	30
1.42793	30
1.42734	28
1.42676	30
1.42618	32
1.4256	26
1.42502	28
1.42444	20
1.42386	28
1.42328	22
1.4227	30
1.42212	30
1.42155	32
1.42097	30
1.42039	28
1.41982	26
1.41924	22
1.41867	28
1.41809	26
1.41752	34
1.41695	30
1.41637	28
1.4158	28
1.41523	28
1.41466	30
1.41409	22
1.41352	22
1.41295	30
1.41238	24
1.41181	28
1.41124	24
1.41067	32
1.41011	32
1.40954	36
1.40897	34
1.40841	28
1.40784	22.0207
1.40728	26.3174
1.40672	34.2871
1.40615	30.1134
1.40559	37.9565
1.40503	39.6907
1.40446	123.861
1.4039	32.6306
1.40334	38.8812
1.40278	35.5894
1.40222	36.1476
1.40166	31.396
1.4011	39.8803
1.40054	33.4963
1.39999	35.066
1.39947	42
1.3989	50
1.39834	38
1.39779	38
1.39723	40
1.39667	46
1.39611	40
1.39555	34
1.395	34
1.39444	34
1.39388	34
1.39333	36
1.39277	36
1.39222	40
1.39166	38
1.39111	34
1.39056	34
1.39	42
1.38945	42
1.3889	38
1.38835	40
1.3878	36
1.38725	40
1.3867	34
1.38615	34
1.3856	32
1.38505	36
1.3845	32
1.38396	40
1.38341	34
1.38286	36
1.38232	44
1.38177	40
1.38123	42
1.38068	32
1.38014	36
1.3796	30
1.37905	40
1.37851	38
1.37797	32
1.37743	30
1.37688	32
1.37634	38
1.3758	44
1.37526	42
1.37472	36
1.37419	26
1.37365	46
1.37311	40
1.37257	38
1.37204	36
1.3715	38
1.37096	40
1.37043	30
1.36989	38
1.36936	36
1.36882	32
1.36829	40
1.36776	30
1.36722	34
1.36669	40
1.36616	32
1.36563	38
1.3651	38
1.36457	36
1.36404	36
1.36351	36
1.36298	36
1.36245	28
1.36192	40
1.36139	30
1.36087	36
1.36034	32
1.35981	36
1.35929	34
1.35876	34
1.35824	32
1.35771	32
1.35719	42
1.35667	32
1.35614	26
1.35562	42
1.3551	28
1.35458	38
1.35406	34
1.35353	26
1.35301	32
1.35249	36
1.35197	30
1.35146	30
1.35094	30
1.35042	36
1.3499	40
1.34938	32
1.34887	32
1.34835	28
1.34783	30
1.34732	38
1.3468	40
1.34629	40
1.34578	28
1.34526	32
1.34475	38
1.34424	36
1.34372	36
1.34321	36
1.3427	34
1.34219	38
1.34168	28
1.34117	38
1.34066	34
1.34015	32
1.33964	34
1.33913	26
1.33862	32
1.33812	28
1.33761	40
1.3371	34.0907
1.3366	35.5295
1.33609	35.2455
1.33558	27.2662
1.33508	33.9671
1.33457	30.8862
1.33407	32.7282
1.33357	32.8501
1.33306	27.0013
1.33256	30.2061
1.33206	28.9484
1.33156	30.7746
1.33105	36.1467
1.33055	31.042
1.33005	34.1456
1.32959	30
1.32909	28
1.32859	32
1.32809	26
1.32758	34
1.32708	30
1.32658	26
1.32608	32
1.32558	32
1.32508	38
1.32458	26
1.32408	28
1.32358	28
1.32309	30
1.32259	34
1.32209	34
1.3216	32
1.3211	32
1.3206	32
1.32011	30
1.31961	30
1.31912	28
1.31862	28
1.31813	36
1.31764	36
1.31714	30
1.31665	30
1.31616	36
1.31567	32
1.31518	34
1.31468	38
1.31419	34
1.3137	34
1.31321	34
1.31272	36
1.31224	38
1.31175	28
1.31126	30
1.31077	30
1.31028	34
1.3098	38
1.30931	46
1.30882	28
1.30834	36
1.30785	28
1.30737	30
1.30688	30
1.3064	32
1.30592	44
1.30543	40
1.30495	34
1.30447	34
1.30399	28
1.3035	28
1.30302	36
1.30254	36
1.30206	30
1.30158	28
1.3011	36
1.30062	38
1.30014	36
1.30001	20