File: ploting_and_data_tools.ipynb/___archivosraman/CdSe2_03.txt
#Acq. time (s)=	1
#Accumulations=	1
#Range (eV)=	2...1
#Windows=	11
#Autofocus=	Off
#AutoExposure=	Off
#Spike filter=	Off
#Delay time (s)=	0
#Binning=	1
#Readout mode=	Signal
#DeNoise=	Off
#ICS correction=	Off
#Dark correction=	Off
#Inst. Process=	Off
#Instrument=	LabRAM HR Evol
#Detector=	Syncerity OE
#Objective=	x100_VIS_LWD
#Grating=	600 (500nm)
#ND Filter=	1%
#Laser=	442nm_Notch
#Hole=	150.001
#Range=	Visible
#Project=	Paty
#Sample=
#Site=	15-06-22
#Title=	CdSe2
#Remark=
#Date=	15.06.2022 21:09
#Acquired=	15.06.2022 21:09:12
2.74975	32
2.7475	28
2.74525	32
2.743	38
2.74076	30
2.73852	30
2.73629	40
2.73406	38
2.73183	30
2.72961	38
2.72739	36
2.72517	34
2.72296	42
2.72075	32
2.71854	32
2.71634	36
2.71414	36
2.71195	38
2.70976	34
2.70757	36
2.70539	32
2.70321	38
2.70103	42
2.69886	36
2.69669	40
2.69452	46
2.69236	44
2.6902	48
2.68805	44
2.6859	34
2.68375	46
2.68161	44
2.67947	42
2.67733	46
2.6752	44
2.67307	48
2.67094	52
2.66882	48
2.6667	42
2.66458	46
2.66247	46
2.66036	46
2.65826	48
2.65615	42
2.65405	44
2.65196	44
2.64987	52
2.64778	58
2.64569	56
2.64361	52
2.64153	60
2.63946	66
2.63739	60
2.63532	64
2.63325	66
2.63119	68
2.62913	62
2.62708	62
2.62503	66
2.62298	74
2.62094	88
2.61889	88
2.61686	86
2.61482	72
2.61279	86
2.61076	84
2.60873	100
2.60671	96
2.60469	106
2.60268	104
2.60067	122
2.59866	124
2.59665	126
2.59465	110
2.59265	132
2.59065	142
2.58866	134
2.58667	146
2.58468	144
2.5827	154
2.58072	180
2.57874	164
2.57677	170
2.5748	196
2.57283	188
2.57086	178
2.5689	220
2.56694	200
2.56499	194
2.56304	230
2.56109	222
2.55914	264
2.5572	236
2.55526	286
2.55332	254
2.55139	290
2.54946	300
2.54753	308
2.5456	342
2.54368	338
2.54176	366
2.53985	358
2.53794	402
2.53603	400
2.53412	430
2.53222	428
2.53031	436
2.52842	456
2.52652	506
2.52463	500
2.52274	520
2.52085	538
2.51897	564
2.51709	622
2.51521	588
2.51334	622
2.51147	676
2.5096	686
2.50773	678
2.50587	732
2.50401	776
2.50216	798
2.5003	780
2.49845	876
2.4966	870
2.49476	912
2.49291	916
2.49107	978
2.48924	988
2.4874	1020
2.48557	1048
2.48374	1076
2.48192	1124.91
2.48009	1153.82
2.47827	1225.93
2.47646	1232.37
2.47464	1248.21
2.47283	1313.19
2.47102	1323.62
2.46922	1346.91
2.46741	1432.09
2.46561	1447.19
2.46381	1468.23
2.46202	1509.97
2.46023	1519.59
2.45844	1581.21
2.45665	1641.8
2.45493	1636
2.45314	1674
2.45136	1722
2.44957	1802
2.44779	1802
2.44601	1898
2.44424	1864
2.44247	1904
2.4407	1936
2.43893	2006
2.43716	2032
2.4354	2094
2.43364	2130
2.43188	2160
2.43013	2204
2.42838	2286
2.42663	2214
2.42488	2324
2.42314	2294
2.4214	2352
2.41966	2372
2.41792	2394
2.41619	2430
2.41446	2436
2.41273	2468
2.411	2510
2.40928	2578
2.40756	2546
2.40584	2570
2.40413	2570
2.40241	2658
2.4007	2624
2.39899	2592
2.39729	2660
2.39559	2710
2.39389	2716
2.39219	2682
2.39049	2694
2.3888	2706
2.38711	2774
2.38542	2768
2.38374	2730
2.38205	2716
2.38037	2760
2.37869	2784
2.37702	2768
2.37535	2782
2.37368	2732
2.37201	2716
2.37034	2734
2.36868	2714
2.36702	2786
2.36536	2706
2.3637	2678
2.36205	2674
2.3604	2636
2.35875	2648
2.3571	2592
2.35546	2588
2.35382	2528
2.35218	2492
2.35054	2420
2.34891	2446
2.34727	2450
2.34564	2392
2.34402	2358
2.34239	2340
2.34077	2308
2.33915	2230
2.33753	2212
2.33591	2174
2.3343	2160
2.33269	2148
2.33108	2068
2.32948	2116
2.32787	2068
2.32627	2034
2.32467	2018
2.32307	1916
2.32148	1942
2.31989	1840
2.3183	1810
2.31671	1852
2.31512	1826
2.31354	1814
2.31196	1724
2.31038	1732
2.3088	1688
2.30723	1670
2.30565	1680
2.30408	1646
2.30252	1598
2.30095	1600
2.29939	1572
2.29783	1562
2.29627	1490
2.29471	1476
2.29316	1462
2.29161	1484
2.29006	1406
2.28851	1460
2.28696	1396
2.28542	1398
2.28388	1378
2.28234	1338
2.2808	1374
2.27927	1318
2.27773	1346
2.2762	1302
2.27468	1324
2.27315	1272
2.27163	1236
2.27011	1228
2.26859	1246
2.26707	1182
2.26555	1236
2.26404	1190
2.26253	1146.18
2.26102	1168.27
2.25951	1101.76
2.25801	1099.71
2.25651	1064.96
2.25501	1053.2
2.25351	1017.97
2.25201	1031.28
2.25052	981.587
2.24902	949.852
2.24753	955.136
2.24605	931.483
2.24456	927.039
2.24308	865.289
2.2416	853.374
2.24011	858
2.23863	870
2.23715	822
2.23567	878
2.23419	876
2.23271	762
2.23124	816
2.22977	828
2.2283	800
2.22683	774
2.22536	794
2.2239	778
2.22244	774
2.22098	792
2.21952	780
2.21807	762
2.21661	730
2.21516	726
2.21371	758
2.21226	734
2.21082	710
2.20937	712
2.20793	712
2.20649	724
2.20505	726
2.20362	714
2.20218	676
2.20075	700
2.19932	698
2.19789	710
2.19647	680
2.19504	676
2.19362	674
2.1922	674
2.19078	702
2.18936	670
2.18795	690
2.18654	678
2.18513	668
2.18372	682
2.18231	672
2.18091	720
2.1795	720
2.1781	658
2.1767	682
2.1753	676
2.17391	676
2.17251	648
2.17112	652
2.16973	660
2.16834	658
2.16696	680
2.16557	664
2.16419	666
2.16281	666
2.16143	666
2.16005	680
2.15868	650
2.1573	660
2.15593	666
2.15456	698
2.1532	670
2.15183	690
2.15046	652
2.1491	668
2.14774	668
2.14638	650
2.14503	658
2.14367	670
2.14232	690
2.14097	672
2.13962	704
2.13827	648
2.13692	706
2.13558	640
2.13423	666
2.13289	678
2.13155	646
2.13022	686
2.12888	710
2.12755	688
2.12621	696
2.12488	694
2.12356	670
2.12223	672
2.1209	656
2.11958	702
2.11826	736
2.11694	696
2.11562	694
2.1143	690
2.11299	714
2.11168	714
2.11037	690
2.10906	706
2.10775	694
2.10644	698
2.10514	688
2.10384	666
2.10253	744
2.10123	684
2.09994	688
2.09864	702
2.09735	700
2.09605	700
2.09476	692
2.09347	702
2.09219	722
2.0909	696
2.08962	716
2.08834	690
2.08705	710
2.08578	682
2.0845	694
2.08322	670
2.08195	672
2.08068	702
2.0794	700.056
2.07814	696.775
2.07687	646.264
2.0756	657.99
2.07434	664.092
2.07307	682.433
2.07181	663.921
2.07055	669.239
2.0693	656.017
2.06804	675.596
2.06679	625.56
2.06553	652.24
2.06428	627.755
2.06303	622.173
2.06178	663.887
2.06069	612
2.05944	640
2.05819	618
2.05694	628
2.05569	634
2.05445	650
2.05321	646
2.05196	634
2.05072	628
2.04949	626
2.04825	626
2.04701	634
2.04578	588
2.04455	620
2.04332	624
2.04209	590
2.04086	604
2.03964	634
2.03841	590
2.03719	600
2.03597	602
2.03475	612
2.03353	588
2.03232	610
2.0311	620
2.02989	602
2.02868	620
2.02747	578
2.02626	602
2.02505	578
2.02384	598
2.02264	584
2.02144	606
2.02024	612
2.01904	604
2.01784	620
2.01664	636
2.01544	598
2.01425	644
2.01306	578
2.01187	624
2.01068	590
2.00949	616
2.0083	610
2.00712	622
2.00594	620
2.00475	618
2.00357	654
2.0024	622
2.00122	638
2.00004	642
1.99887	624
1.99769	660
1.99652	638
1.99535	646
1.99418	664
1.99302	660
1.99185	626
1.99069	626
1.98952	658
1.98836	630
1.9872	642
1.98604	630
1.98488	656
1.98373	652
1.98257	660
1.98142	666
1.98027	636
1.97912	654
1.97797	652
1.97682	684
1.97568	668
1.97453	650
1.97339	678
1.97225	650
1.97111	668
1.96997	668
1.96883	660
1.9677	660
1.96656	660
1.96543	672
1.9643	678
1.96316	700
1.96204	640
1.96091	688
1.95978	678
1.95866	674
1.95753	670
1.95641	666
1.95529	656
1.95417	682
1.95305	698
1.95193	668
1.95082	678
1.9497	656
1.94859	694
1.94748	670
1.94637	682
1.94526	636
1.94415	668
1.94305	676
1.94194	658
1.94084	650
1.93974	666
1.93864	642
1.93754	644
1.93644	662
1.93534	672
1.93425	698
1.93315	670
1.93206	652
1.93097	656
1.92988	664
1.92879	664
1.9277	670
1.92662	648
1.92553	678
1.92445	650.944
1.92337	659.29
1.92228	668.324
1.92121	647.803
1.92013	633.787
1.91905	646.121
1.91797	631.087
1.9169	642.031
1.91583	646.948
1.91475	621.838
1.91368	630.428
1.91261	625.046
1.91155	618.525
1.91048	623.441
1.90946	616
1.90839	584
1.90732	644
1.90626	630
1.90519	640
1.90413	600
1.90306	612
1.902	636
1.90094	626
1.89988	624
1.89882	624
1.89777	630
1.89671	618
1.89566	618
1.8946	640
1.89355	620
1.8925	590
1.89145	604
1.8904	602
1.88936	614
1.88831	616
1.88727	618
1.88622	608
1.88518	606
1.88414	578
1.8831	574
1.88206	594
1.88102	590
1.87999	602
1.87895	596
1.87792	568
1.87689	590
1.87586	614
1.87483	578
1.8738	596
1.87277	592
1.87174	592
1.87072	530
1.86969	592
1.86867	572
1.86765	582
1.86663	590
1.86561	568
1.86459	576
1.86357	550
1.86256	564
1.86154	576
1.86053	574
1.85952	598
1.85851	576
1.8575	584
1.85649	564
1.85548	552
1.85447	550
1.85347	536
1.85247	580
1.85146	590
1.85046	546
1.84946	556
1.84846	542
1.84746	552
1.84646	564
1.84547	554
1.84447	548
1.84348	562
1.84249	532
1.8415	530
1.84051	526
1.83952	534
1.83853	560
1.83754	552
1.83656	556
1.83557	522
1.83459	534
1.83361	524
1.83262	522
1.83164	538
1.83066	546
1.82969	540
1.82871	518
1.82773	528
1.82676	514
1.82579	520
1.82481	492
1.82384	490
1.82287	528
1.8219	488
1.82094	492
1.81997	518
1.819	514
1.81804	506
1.81708	502
1.81611	522
1.81515	508
1.81419	540
1.81323	492
1.81227	472
1.81132	472
1.81036	504
1.80941	520
1.80845	480
1.8075	464
1.80655	490
1.8056	478
1.80465	484
1.8037	462
1.80275	498
1.80181	480
1.80086	470
1.79992	456
1.79897	494
1.79803	452
1.79709	466
1.79615	490
1.79521	448
1.79428	454
1.79334	472
1.7924	454
1.79147	482.214
1.79053	438.794
1.7896	452.725
1.78867	463.808
1.78774	462.149
1.78681	443.511
1.78588	447.351
1.78496	437.264
1.78403	427.195
1.7831	442.888
1.78218	425.753
1.78126	455.633
1.78033	434.986
1.77941	435.078
1.77851	408
1.77759	414
1.77667	420
1.77575	416
1.77483	392
1.77391	418
1.77299	392
1.77207	386
1.77115	408
1.77024	420
1.76932	386
1.76841	400
1.7675	400
1.76659	402
1.76568	396
1.76477	374
1.76386	390
1.76295	378
1.76204	382
1.76114	404
1.76023	386
1.75933	368
1.75843	378
1.75753	370
1.75662	394
1.75572	376
1.75483	390
1.75393	362
1.75303	380
1.75214	372
1.75124	356
1.75035	348
1.74945	354
1.74856	368
1.74767	366
1.74678	366
1.74589	352
1.74501	338
1.74412	348
1.74323	350
1.74235	360
1.74146	328
1.74058	338
1.7397	350
1.73882	350
1.73794	344
1.73706	314
1.73618	344
1.7353	330
1.73443	346
1.73355	316
1.73268	310
1.7318	284
1.73093	328
1.73006	338
1.72919	316
1.72832	318
1.72745	320
1.72658	316
1.72571	312
1.72485	332
1.72398	316
1.72312	312
1.72225	290
1.72139	328
1.72053	300
1.71967	294
1.71881	304
1.71795	288
1.71709	300
1.71624	304
1.71538	298
1.71453	270
1.71367	288
1.71282	278
1.71197	286
1.71112	268
1.71027	284
1.70942	296
1.70857	272
1.70772	282
1.70687	308
1.70603	262
1.70518	280
1.70434	262
1.7035	266
1.70265	264
1.70181	264
1.70097	256
1.70013	264
1.69929	264
1.69846	252
1.69762	254
1.69678	258
1.69595	250
1.69511	244
1.69428	270
1.69345	250
1.69262	246
1.69179	258
1.69096	262
1.69013	272
1.6893	216
1.68847	236
1.68765	218
1.68682	220
1.686	222
1.68517	212
1.68435	230
1.68353	232
1.68271	228
1.68189	222
1.68107	224
1.68025	208
1.67943	200
1.67861	212
1.6778	204
1.67698	225.981
1.67617	223.444
1.67536	213.096
1.67454	212.538
1.67373	221.167
1.67292	204.467
1.67211	209.348
1.6713	210.523
1.6705	200.969
1.66969	218.077
1.66888	208.76
1.66808	199.627
1.66727	199.84
1.66647	210.206
1.66566	214.214
1.6649	212
1.66409	188
1.66329	194
1.66249	188
1.66168	200
1.66088	190
1.66008	202
1.65928	184
1.65848	194
1.65768	198
1.65688	190
1.65608	190
1.65529	194
1.65449	190
1.6537	178
1.6529	188
1.65211	178
1.65132	186
1.65053	200
1.64973	186
1.64894	180
1.64816	174
1.64737	160
1.64658	186
1.64579	188
1.64501	192
1.64422	186
1.64344	172
1.64265	178
1.64187	158
1.64109	172
1.64031	172
1.63953	164
1.63875	166
1.63797	166
1.63719	156
1.63642	162
1.63564	162
1.63486	154
1.63409	164
1.63331	158
1.63254	160
1.63177	160
1.631	160
1.63023	156
1.62946	144
1.62869	154
1.62792	156
1.62715	150
1.62639	162
1.62562	148
1.62485	152
1.62409	160
1.62333	148
1.62256	148
1.6218	138
1.62104	144
1.62028	146
1.61952	136
1.61876	128
1.618	138
1.61724	140
1.61649	146
1.61573	130
1.61498	134
1.61422	132
1.61347	130
1.61271	138
1.61196	148
1.61121	146
1.61046	146
1.60971	126
1.60896	148
1.60821	132
1.60747	120
1.60672	122
1.60597	122
1.60523	130
1.60448	122
1.60374	110
1.603	132
1.60225	138
1.60151	124
1.60077	118
1.60003	112
1.59929	116
1.59855	126
1.59782	124
1.59708	106
1.59634	114
1.59561	114
1.59487	122
1.59414	120
1.5934	126
1.59267	106
1.59194	114
1.59121	96
1.59048	104
1.58975	108
1.58902	104
1.58829	108
1.58756	114
1.58684	108
1.58611	100
1.58538	104
1.58466	100
1.58394	92
1.58321	96
1.58249	92
1.58177	86
1.58105	94
1.58033	106
1.57961	100
1.57889	92
1.57817	92
1.57745	82
1.57674	98
1.57602	94.024
1.5753	100.922
1.57459	87.1605
1.57388	88.173
1.57316	100.98
1.57245	90.7518
1.57174	85.1584
1.57103	90.226
1.57032	79.7504
1.56961	82.2277
1.5689	93.5147
1.56819	85.4336
1.56748	82
1.56678	87.4828
1.56607	81.3388
1.56544	82
1.56473	82
1.56402	66
1.56331	82
1.56261	76
1.5619	90
1.56119	84
1.56049	82
1.55979	76
1.55908	74
1.55838	84
1.55768	74
1.55698	76
1.55628	76
1.55558	70
1.55488	78
1.55418	72
1.55348	70
1.55278	70
1.55209	78
1.55139	72
1.5507	70
1.55	68
1.54931	68
1.54862	74
1.54792	76
1.54723	72
1.54654	62
1.54585	70
1.54516	58
1.54447	76
1.54378	74
1.5431	70
1.54241	66
1.54172	64
1.54104	64
1.54035	64
1.53967	68
1.53898	60
1.5383	74
1.53762	66
1.53694	62
1.53626	64
1.53558	68
1.5349	54
1.53422	64
1.53354	64
1.53286	64
1.53218	60
1.53151	66
1.53083	72
1.53016	52
1.52948	56
1.52881	64
1.52813	66
1.52746	54
1.52679	62
1.52612	60
1.52545	58
1.52478	58
1.52411	54
1.52344	68
1.52277	64
1.5221	66
1.52144	62
1.52077	64
1.52011	56
1.51944	66
1.51878	58
1.51811	58
1.51745	44
1.51679	52
1.51613	42
1.51547	70
1.51481	62
1.51415	48
1.51349	58
1.51283	62
1.51217	58
1.51151	54
1.51086	58
1.5102	44
1.50954	42
1.50889	56
1.50824	50
1.50758	56
1.50693	50
1.50628	52
1.50563	62
1.50497	58
1.50432	44
1.50367	50
1.50302	50
1.50238	50
1.50173	48
1.50108	50
1.50043	48
1.49979	52
1.49914	54
1.4985	48
1.49785	48
1.49721	50
1.49657	50
1.49592	58
1.49528	50
1.49464	46
1.494	46
1.49336	50
1.49272	40
1.49208	44
1.49144	54
1.49081	44
1.49017	48
1.48953	42
1.4889	42
1.48826	46
1.48763	40
1.48699	51.9703
1.48636	45.9934
1.48573	44.0646
1.4851	44.4167
1.48446	39.8382
1.48383	48.2468
1.4832	42
1.48257	42.8587
1.48194	42.2694
1.48132	42.0817
1.48069	45.5582
1.48006	40.5397
1.47943	42.7494
1.47881	41.9475
1.47818	36.8286
1.47756	38
1.47694	36
1.47631	38
1.47568	46
1.47505	38
1.47443	46
1.4738	52
1.47318	38
1.47256	42
1.47193	46
1.47131	40
1.47069	46
1.47006	40
1.46944	38
1.46882	40
1.4682	52
1.46758	42
1.46696	36
1.46635	42
1.46573	46
1.46511	34
1.46449	34
1.46388	34
1.46326	32
1.46265	50
1.46203	36
1.46142	38
1.46081	40
1.46019	36
1.45958	34
1.45897	36
1.45836	28
1.45775	28
1.45714	34
1.45653	36
1.45592	36
1.45531	38
1.4547	32
1.4541	28
1.45349	30
1.45288	38
1.45228	30
1.45167	28
1.45107	26
1.45047	38
1.44986	34
1.44926	28
1.44866	38
1.44806	28
1.44746	38
1.44686	24
1.44626	24
1.44566	36
1.44506	24
1.44446	26
1.44386	30
1.44326	28
1.44267	18
1.44207	24
1.44148	32
1.44088	28
1.44029	28
1.43969	26
1.4391	28
1.43851	30
1.43791	36
1.43732	34
1.43673	22
1.43614	34
1.43555	28
1.43496	28
1.43437	28
1.43378	26
1.4332	34
1.43261	30
1.43202	22
1.43143	24
1.43085	26
1.43026	28
1.42968	34
1.42909	28
1.42851	24
1.42793	34
1.42734	32
1.42676	30
1.42618	30
1.4256	26
1.42502	30
1.42444	32
1.42386	36
1.42328	28
1.4227	34
1.42212	28
1.42155	34
1.42097	24
1.42039	34
1.41982	28
1.41924	26
1.41867	26
1.41809	32
1.41752	30
1.41695	26
1.41637	28
1.4158	28
1.41523	28
1.41466	36
1.41409	28
1.41352	28
1.41295	32
1.41238	24
1.41181	28
1.41124	20
1.41067	18
1.41011	32
1.40954	26
1.40897	30
1.40841	28
1.40784	24.0181
1.40728	31.5612
1.40672	23.4287
1.40615	31.5589
1.40559	29.0017
1.40503	28.5357
1.40446	132.542
1.4039	35.4534
1.40334	29.7624
1.40278	31.4589
1.40222	32.1881
1.40166	34.9307
1.4011	32.0267
1.40054	31.4761
1.39999	26.9342
1.39947	32
1.3989	30
1.39834	38
1.39779	28
1.39723	30
1.39667	26
1.39611	36
1.39555	34
1.395	34
1.39444	30
1.39388	28
1.39333	28
1.39277	36
1.39222	38
1.39166	34
1.39111	30
1.39056	36
1.39	36
1.38945	32
1.3889	28
1.38835	34
1.3878	38
1.38725	38
1.3867	34
1.38615	32
1.3856	34
1.38505	34
1.3845	42
1.38396	34
1.38341	36
1.38286	26
1.38232	34
1.38177	42
1.38123	34
1.38068	28
1.38014	34
1.3796	34
1.37905	34
1.37851	36
1.37797	30
1.37743	34
1.37688	34
1.37634	32
1.3758	34
1.37526	28
1.37472	34
1.37419	34
1.37365	32
1.37311	32
1.37257	36
1.37204	36
1.3715	34
1.37096	34
1.37043	30
1.36989	42
1.36936	26
1.36882	38
1.36829	34
1.36776	28
1.36722	30
1.36669	22
1.36616	26
1.36563	32
1.3651	40
1.36457	34
1.36404	28
1.36351	32
1.36298	36
1.36245	32
1.36192	36
1.36139	28
1.36087	32
1.36034	40
1.35981	28
1.35929	26
1.35876	28
1.35824	28
1.35771	40
1.35719	46
1.35667	30
1.35614	30
1.35562	30
1.3551	32
1.35458	38
1.35406	34
1.35353	40
1.35301	24
1.35249	30
1.35197	36
1.35146	28
1.35094	32
1.35042	32
1.3499	24
1.34938	24
1.34887	32
1.34835	32
1.34783	28
1.34732	26
1.3468	30
1.34629	28
1.34578	36
1.34526	28
1.34475	26
1.34424	36
1.34372	34
1.34321	34
1.3427	30
1.34219	34
1.34168	34
1.34117	26
1.34066	22
1.34015	28
1.33964	38
1.33913	38
1.33862	22
1.33812	34
1.33761	28
1.3371	28.2161
1.3366	31.8984
1.33609	27.4222
1.33558	28.9573
1.33508	33.4737
1.33457	32.7017
1.33407	31.3806
1.33357	32.925
1.33306	26.8667
1.33256	33.9255
1.33206	25.9745
1.33156	33.3395
1.33105	31.533
1.33055	30.9822
1.33005	30.3275
1.32959	28
1.32909	34
1.32859	32
1.32809	32
1.32758	30
1.32708	34
1.32658	30
1.32608	32
1.32558	32
1.32508	32
1.32458	34
1.32408	26
1.32358	36
1.32309	30
1.32259	24
1.32209	36
1.3216	34
1.3211	28
1.3206	36
1.32011	38
1.31961	24
1.31912	34
1.31862	30
1.31813	30
1.31764	30
1.31714	32
1.31665	26
1.31616	34
1.31567	36
1.31518	32
1.31468	28
1.31419	28
1.3137	32
1.31321	34
1.31272	26
1.31224	30
1.31175	36
1.31126	32
1.31077	24
1.31028	32
1.3098	26
1.30931	32
1.30882	34
1.30834	24
1.30785	38
1.30737	34
1.30688	38
1.3064	32
1.30592	30
1.30543	34
1.30495	34
1.30447	40
1.30399	28
1.3035	36
1.30302	34
1.30254	40
1.30206	46
1.30158	30
1.3011	36
1.30062	36
1.30014	34
1.30001	34