File: ploting_and_data_tools.ipynb/___archivosraman/CdSe1_12.txt
#Acq. time (s)=	2
#Accumulations=	1
#Range (eV)=	2...1
#Windows=	11
#Autofocus=	Off
#AutoExposure=	Off
#Spike filter=	Off
#Delay time (s)=	0
#Binning=	1
#Readout mode=	Signal
#DeNoise=	Off
#ICS correction=	Off
#Dark correction=	Off
#Inst. Process=	Off
#Instrument=	LabRAM HR Evol
#Detector=	Syncerity OE
#Objective=	x100_VIS_LWD
#Grating=	600 (500nm)
#ND Filter=	1%
#Laser=	442nm_Notch
#Hole=	100.021
#Range=	Visible
#Project=	Paty
#Sample=
#Site=	15-06-22
#Title=	CdSe1
#Remark=
#Date=	15.06.2022 20:35
#Acquired=	15.06.2022 20:35:38
2.74975	26
2.7475	28
2.74525	28
2.743	26
2.74076	32
2.73852	36
2.73629	38
2.73406	24
2.73183	28
2.72961	32
2.72739	34
2.72517	24
2.72296	44
2.72075	32
2.71854	26
2.71634	34
2.71414	30
2.71195	32
2.70976	28
2.70757	28
2.70539	32
2.70321	28
2.70103	34
2.69886	32
2.69669	36
2.69452	36
2.69236	36
2.6902	26
2.68805	32
2.6859	30
2.68375	32
2.68161	40
2.67947	32
2.67733	28
2.6752	34
2.67307	34
2.67094	42
2.66882	34
2.6667	32
2.66458	46
2.66247	36
2.66036	32
2.65826	38
2.65615	38
2.65405	40
2.65196	42
2.64987	36
2.64778	44
2.64569	34
2.64361	32
2.64153	36
2.63946	50
2.63739	42
2.63532	42
2.63325	48
2.63119	36
2.62913	44
2.62708	44
2.62503	50
2.62298	50
2.62094	40
2.61889	54
2.61686	42
2.61482	38
2.61279	50
2.61076	50
2.60873	50
2.60671	54
2.60469	54
2.60268	68
2.60067	54
2.59866	46
2.59665	48
2.59465	64
2.59265	60
2.59065	66
2.58866	66
2.58667	50
2.58468	70
2.5827	70
2.58072	80
2.57874	72
2.57677	70
2.5748	72
2.57283	74
2.57086	76
2.5689	76
2.56694	78
2.56499	82
2.56304	76
2.56109	92
2.55914	102
2.5572	92
2.55526	94
2.55332	92
2.55139	96
2.54946	104
2.54753	94
2.5456	112
2.54368	114
2.54176	112
2.53985	108
2.53794	124
2.53603	116
2.53412	128
2.53222	142
2.53031	138
2.52842	138
2.52652	154
2.52463	140
2.52274	158
2.52085	156
2.51897	164
2.51709	158
2.51521	168
2.51334	182
2.51147	166
2.5096	188
2.50773	180
2.50587	188
2.50401	202
2.50216	196
2.5003	202
2.49845	210
2.4966	216
2.49476	228
2.49291	240
2.49107	230
2.48924	242
2.4874	248
2.48557	248
2.48374	268
2.48192	272.479
2.48009	247.623
2.47827	289.874
2.47646	289.011
2.47464	301.374
2.47283	309.539
2.47102	315.424
2.46922	325.32
2.46741	319.161
2.46561	334.186
2.46381	349.634
2.46202	361.949
2.46023	376.332
2.45844	370.444
2.45665	377.545
2.45493	406
2.45314	390
2.45136	404
2.44957	436
2.44779	426
2.44601	438
2.44424	434
2.44247	442
2.4407	414
2.43893	456
2.43716	490
2.4354	466
2.43364	464
2.43188	478
2.43013	486
2.42838	514
2.42663	504
2.42488	524
2.42314	494
2.4214	536
2.41966	494
2.41792	550
2.41619	544
2.41446	550
2.41273	544
2.411	554
2.40928	544
2.40756	538
2.40584	528
2.40413	538
2.40241	528
2.4007	570
2.39899	548
2.39729	534
2.39559	538
2.39389	574
2.39219	536
2.39049	546
2.3888	534
2.38711	556
2.38542	576
2.38374	558
2.38205	536
2.38037	564
2.37869	550
2.37702	568
2.37535	572
2.37368	568
2.37201	540
2.37034	544
2.36868	544
2.36702	532
2.36536	552
2.3637	550
2.36205	542
2.3604	538
2.35875	536
2.3571	542
2.35546	500
2.35382	540
2.35218	496
2.35054	496
2.34891	464
2.34727	478
2.34564	488
2.34402	482
2.34239	472
2.34077	460
2.33915	452
2.33753	470
2.33591	460
2.3343	450
2.33269	436
2.33108	462
2.32948	418
2.32787	452
2.32627	432
2.32467	416
2.32307	424
2.32148	434
2.31989	418
2.3183	396
2.31671	412
2.31512	398
2.31354	398
2.31196	394
2.31038	360
2.3088	392
2.30723	356
2.30565	368
2.30408	390
2.30252	360
2.30095	358
2.29939	352
2.29783	368
2.29627	346
2.29471	344
2.29316	316
2.29161	334
2.29006	356
2.28851	324
2.28696	330
2.28542	334
2.28388	344
2.28234	338
2.2808	298
2.27927	314
2.27773	306
2.2762	322
2.27468	326
2.27315	318
2.27163	314
2.27011	334
2.26859	316
2.26707	300
2.26555	290
2.26404	282
2.26253	308.066
2.26102	317.247
2.25951	292.89
2.25801	303.191
2.25651	291.926
2.25501	297.888
2.25351	306.408
2.25201	303.911
2.25052	312.52
2.24902	298.034
2.24753	282.695
2.24605	294.057
2.24456	297.515
2.24308	301.966
2.2416	296.087
2.24011	270
2.23863	294
2.23715	290
2.23567	272
2.23419	258
2.23271	278
2.23124	292
2.22977	292
2.2283	284
2.22683	292
2.22536	298
2.2239	272
2.22244	290
2.22098	286
2.21952	284
2.21807	296
2.21661	286
2.21516	294
2.21371	298
2.21226	284
2.21082	286
2.20937	282
2.20793	270
2.20649	300
2.20505	290
2.20362	282
2.20218	272
2.20075	280
2.19932	300
2.19789	290
2.19647	292
2.19504	304
2.19362	294
2.1922	322
2.19078	294
2.18936	288
2.18795	314
2.18654	296
2.18513	308
2.18372	272
2.18231	292
2.18091	298
2.1795	290
2.1781	292
2.1767	322
2.1753	304
2.17391	290
2.17251	310
2.17112	290
2.16973	322
2.16834	310
2.16696	310
2.16557	304
2.16419	326
2.16281	330
2.16143	336
2.16005	334
2.15868	324
2.1573	328
2.15593	318
2.15456	308
2.1532	326
2.15183	324
2.15046	342
2.1491	334
2.14774	324
2.14638	340
2.14503	346
2.14367	318
2.14232	316
2.14097	334
2.13962	316
2.13827	338
2.13692	346
2.13558	354
2.13423	352
2.13289	324
2.13155	354
2.13022	338
2.12888	342
2.12755	336
2.12621	334
2.12488	344
2.12356	356
2.12223	350
2.1209	332
2.11958	358
2.11826	346
2.11694	362
2.11562	334
2.1143	354
2.11299	336
2.11168	376
2.11037	350
2.10906	330
2.10775	350
2.10644	350
2.10514	360
2.10384	358
2.10253	354
2.10123	360
2.09994	386
2.09864	388
2.09735	370
2.09605	352
2.09476	366
2.09347	356
2.09219	364
2.0909	362
2.08962	364
2.08834	366
2.08705	360
2.08578	366
2.0845	376
2.08322	390
2.08195	350
2.08068	376
2.0794	381.558
2.07814	367.524
2.07687	378.873
2.0756	375.979
2.07434	393.098
2.07307	371.366
2.07181	385.521
2.07055	370.46
2.0693	376.763
2.06804	377.099
2.06679	361.119
2.06553	376.649
2.06428	385.236
2.06303	374.285
2.06178	361.791
2.06069	390
2.05944	376
2.05819	368
2.05694	356
2.05569	360
2.05445	366
2.05321	370
2.05196	352
2.05072	386
2.04949	374
2.04825	366
2.04701	370
2.04578	396
2.04455	368
2.04332	374
2.04209	370
2.04086	368
2.03964	366
2.03841	382
2.03719	370
2.03597	380
2.03475	376
2.03353	362
2.03232	376
2.0311	374
2.02989	358
2.02868	342
2.02747	354
2.02626	384
2.02505	382
2.02384	364
2.02264	360
2.02144	356
2.02024	356
2.01904	374
2.01784	362
2.01664	366
2.01544	376
2.01425	362
2.01306	358
2.01187	368
2.01068	356
2.00949	360
2.0083	364
2.00712	368
2.00594	362
2.00475	356
2.00357	366
2.0024	382
2.00122	380
2.00004	378
1.99887	364
1.99769	372
1.99652	370
1.99535	368
1.99418	394
1.99302	398
1.99185	372
1.99069	388
1.98952	370
1.98836	398
1.9872	378
1.98604	390
1.98488	386
1.98373	378
1.98257	400
1.98142	364
1.98027	366
1.97912	384
1.97797	390
1.97682	368
1.97568	404
1.97453	368
1.97339	378
1.97225	378
1.97111	390
1.96997	380
1.96883	364
1.9677	382
1.96656	382
1.96543	384
1.9643	398
1.96316	370
1.96204	382
1.96091	372
1.95978	378
1.95866	366
1.95753	382
1.95641	382
1.95529	380
1.95417	354
1.95305	372
1.95193	376
1.95082	350
1.9497	380
1.94859	390
1.94748	362
1.94637	394
1.94526	376
1.94415	380
1.94305	376
1.94194	384
1.94084	360
1.93974	348
1.93864	368
1.93754	382
1.93644	354
1.93534	360
1.93425	376
1.93315	386
1.93206	382
1.93097	362
1.92988	336
1.92879	338
1.9277	328
1.92662	336
1.92553	348
1.92445	346.922
1.92337	343.024
1.92228	342.036
1.92121	351.5
1.92013	356.542
1.91905	340.654
1.91797	356.329
1.9169	353.735
1.91583	352.763
1.91475	348.434
1.91368	343.699
1.91261	353.435
1.91155	354.551
1.91048	362.11
1.90946	328
1.90839	334
1.90732	348
1.90626	354
1.90519	324
1.90413	324
1.90306	340
1.902	326
1.90094	320
1.89988	316
1.89882	340
1.89777	338
1.89671	310
1.89566	304
1.8946	316
1.89355	326
1.8925	340
1.89145	308
1.8904	304
1.88936	300
1.88831	318
1.88727	304
1.88622	300
1.88518	310
1.88414	294
1.8831	294
1.88206	278
1.88102	312
1.87999	302
1.87895	286
1.87792	292
1.87689	286
1.87586	280
1.87483	306
1.8738	264
1.87277	272
1.87174	302
1.87072	286
1.86969	260
1.86867	254
1.86765	262
1.86663	292
1.86561	276
1.86459	254
1.86357	250
1.86256	260
1.86154	274
1.86053	252
1.85952	250
1.85851	268
1.8575	252
1.85649	246
1.85548	244
1.85447	240
1.85347	250
1.85247	248
1.85146	264
1.85046	234
1.84946	242
1.84846	238
1.84746	232
1.84646	240
1.84547	230
1.84447	252
1.84348	252
1.84249	220
1.8415	230
1.84051	256
1.83952	218
1.83853	224
1.83754	228
1.83656	224
1.83557	218
1.83459	218
1.83361	224
1.83262	222
1.83164	206
1.83066	220
1.82969	216
1.82871	212
1.82773	210
1.82676	214
1.82579	200
1.82481	214
1.82384	222
1.82287	210
1.8219	214
1.82094	202
1.81997	206
1.819	190
1.81804	204
1.81708	204
1.81611	204
1.81515	198
1.81419	186
1.81323	184
1.81227	206
1.81132	192
1.81036	198
1.80941	168
1.80845	200
1.8075	188
1.80655	188
1.8056	188
1.80465	184
1.8037	190
1.80275	182
1.80181	176
1.80086	180
1.79992	162
1.79897	174
1.79803	176
1.79709	170
1.79615	188
1.79521	180
1.79428	172
1.79334	168
1.7924	156
1.79147	178.129
1.79053	173.09
1.7896	167.42
1.78867	164.036
1.78774	164.627
1.78681	162.453
1.78588	168.216
1.78496	162.52
1.78403	166.997
1.7831	160.289
1.78218	166.847
1.78126	166.553
1.78033	159.667
1.77941	165.575
1.77851	164
1.77759	160
1.77667	156
1.77575	160
1.77483	164
1.77391	144
1.77299	146
1.77207	154
1.77115	152
1.77024	150
1.76932	144
1.76841	154
1.7675	138
1.76659	148
1.76568	142
1.76477	150
1.76386	132
1.76295	136
1.76204	156
1.76114	140
1.76023	144
1.75933	146
1.75843	136
1.75753	136
1.75662	136
1.75572	130
1.75483	146
1.75393	132
1.75303	132
1.75214	150
1.75124	134
1.75035	130
1.74945	116
1.74856	128
1.74767	126
1.74678	126
1.74589	138
1.74501	128
1.74412	118
1.74323	128
1.74235	114
1.74146	134
1.74058	116
1.7397	130
1.73882	130
1.73794	124
1.73706	114
1.73618	116
1.7353	104
1.73443	118
1.73355	120
1.73268	108
1.7318	130
1.73093	108
1.73006	112
1.72919	104
1.72832	114
1.72745	114
1.72658	112
1.72571	104
1.72485	114
1.72398	122
1.72312	116
1.72225	98
1.72139	112
1.72053	112
1.71967	104
1.71881	106
1.71795	108
1.71709	94
1.71624	114
1.71538	116
1.71453	102
1.71367	94
1.71282	84
1.71197	112
1.71112	96
1.71027	94
1.70942	106
1.70857	96
1.70772	94
1.70687	108
1.70603	108
1.70518	94
1.70434	92
1.7035	102
1.70265	98
1.70181	94
1.70097	108
1.70013	82
1.69929	92
1.69846	86
1.69762	78
1.69678	94
1.69595	90
1.69511	84
1.69428	86
1.69345	102
1.69262	84
1.69179	78
1.69096	92
1.69013	80
1.6893	84
1.68847	84
1.68765	74
1.68682	78
1.686	74
1.68517	86
1.68435	72
1.68353	84
1.68271	76
1.68189	74
1.68107	88
1.68025	74
1.67943	74
1.67861	80
1.6778	80
1.67698	75.9806
1.67617	78.1694
1.67536	68.7042
1.67454	80.1073
1.67373	81.5953
1.67292	75.0185
1.67211	75.9503
1.6713	79.3873
1.6705	73.7416
1.66969	82.3784
1.66888	76.6311
1.66808	84.0194
1.66727	76.3726
1.66647	73.6169
1.66566	79.3222
1.6649	84
1.66409	74
1.66329	74
1.66249	70
1.66168	64
1.66088	76
1.66008	80
1.65928	72
1.65848	80
1.65768	76
1.65688	74
1.65608	74
1.65529	62
1.65449	74
1.6537	72
1.6529	70
1.65211	78
1.65132	70
1.65053	76
1.64973	70
1.64894	68
1.64816	70
1.64737	74
1.64658	72
1.64579	70
1.64501	70
1.64422	70
1.64344	70
1.64265	64
1.64187	66
1.64109	74
1.64031	64
1.63953	60
1.63875	60
1.63797	54
1.63719	76
1.63642	70
1.63564	66
1.63486	70
1.63409	66
1.63331	56
1.63254	66
1.63177	64
1.631	72
1.63023	58
1.62946	66
1.62869	62
1.62792	70
1.62715	62
1.62639	64
1.62562	66
1.62485	68
1.62409	58
1.62333	62
1.62256	68
1.6218	66
1.62104	58
1.62028	56
1.61952	52
1.61876	58
1.618	70
1.61724	62
1.61649	54
1.61573	64
1.61498	60
1.61422	60
1.61347	56
1.61271	64
1.61196	60
1.61121	62
1.61046	52
1.60971	54
1.60896	64
1.60821	52
1.60747	60
1.60672	54
1.60597	62
1.60523	50
1.60448	62
1.60374	58
1.603	56
1.60225	54
1.60151	66
1.60077	56
1.60003	54
1.59929	52
1.59855	50
1.59782	50
1.59708	62
1.59634	58
1.59561	54
1.59487	48
1.59414	44
1.5934	48
1.59267	46
1.59194	50
1.59121	48
1.59048	32
1.58975	50
1.58902	48
1.58829	52
1.58756	46
1.58684	52
1.58611	40
1.58538	52
1.58466	54
1.58394	58
1.58321	54
1.58249	50
1.58177	54
1.58105	56
1.58033	46
1.57961	54
1.57889	46
1.57817	50
1.57745	54
1.57674	46
1.57602	45.9872
1.5753	51.739
1.57459	53.2404
1.57388	56.2173
1.57316	43.3366
1.57245	46.2301
1.57174	45.4752
1.57103	48.979
1.57032	46.6436
1.56961	42.596
1.5689	41.3319
1.56819	44.604
1.56748	47.2272
1.56678	46.7922
1.56607	47.2316
1.56544	50
1.56473	50
1.56402	42
1.56331	40
1.56261	44
1.5619	50
1.56119	46
1.56049	38
1.55979	44
1.55908	36
1.55838	42
1.55768	50
1.55698	46
1.55628	30
1.55558	48
1.55488	52
1.55418	44
1.55348	36
1.55278	38
1.55209	32
1.55139	44
1.5507	40
1.55	44
1.54931	44
1.54862	42
1.54792	38
1.54723	50
1.54654	40
1.54585	36
1.54516	46
1.54447	36
1.54378	42
1.5431	38
1.54241	42
1.54172	40
1.54104	38
1.54035	36
1.53967	38
1.53898	48
1.5383	36
1.53762	38
1.53694	42
1.53626	34
1.53558	46
1.5349	44
1.53422	44
1.53354	34
1.53286	42
1.53218	34
1.53151	44
1.53083	38
1.53016	38
1.52948	34
1.52881	30
1.52813	44
1.52746	36
1.52679	44
1.52612	36
1.52545	34
1.52478	48
1.52411	34
1.52344	34
1.52277	48
1.5221	38
1.52144	40
1.52077	42
1.52011	34
1.51944	28
1.51878	38
1.51811	36
1.51745	34
1.51679	36
1.51613	36
1.51547	36
1.51481	30
1.51415	42
1.51349	40
1.51283	44
1.51217	40
1.51151	44
1.51086	30
1.5102	42
1.50954	34
1.50889	32
1.50824	34
1.50758	42
1.50693	44
1.50628	42
1.50563	40
1.50497	34
1.50432	46
1.50367	42
1.50302	36
1.50238	32
1.50173	32
1.50108	36
1.50043	32
1.49979	36
1.49914	34
1.4985	38
1.49785	30
1.49721	28
1.49657	36
1.49592	30
1.49528	40
1.49464	44
1.494	34
1.49336	32
1.49272	34
1.49208	38
1.49144	42
1.49081	30
1.49017	38
1.48953	30
1.4889	38
1.48826	38
1.48763	32
1.48699	24.0396
1.48636	37.5545
1.48573	30.5097
1.4851	36.8424
1.48446	36.3852
1.48383	32.0084
1.4832	31.2996
1.48257	33.0594
1.48194	30.8262
1.48132	32.924
1.48069	34.7356
1.48006	30.5691
1.47943	34
1.47881	36.8071
1.47818	29.0254
1.47756	30
1.47694	32
1.47631	32
1.47568	18
1.47505	40
1.47443	36
1.4738	26
1.47318	36
1.47256	32
1.47193	36
1.47131	30
1.47069	40
1.47006	30
1.46944	34
1.46882	34
1.4682	34
1.46758	36
1.46696	34
1.46635	34
1.46573	32
1.46511	28
1.46449	30
1.46388	22
1.46326	38
1.46265	32
1.46203	36
1.46142	32
1.46081	30
1.46019	22
1.45958	36
1.45897	30
1.45836	32
1.45775	34
1.45714	38
1.45653	32
1.45592	36
1.45531	28
1.4547	36
1.4541	20
1.45349	30
1.45288	22
1.45228	32
1.45167	30
1.45107	32
1.45047	32
1.44986	24
1.44926	24
1.44866	24
1.44806	26
1.44746	22
1.44686	28
1.44626	28
1.44566	36
1.44506	30
1.44446	32
1.44386	30
1.44326	18
1.44267	28
1.44207	24
1.44148	30
1.44088	32
1.44029	38
1.43969	24
1.4391	26
1.43851	30
1.43791	28
1.43732	22
1.43673	30
1.43614	26
1.43555	30
1.43496	22
1.43437	28
1.43378	36
1.4332	32
1.43261	36
1.43202	30
1.43143	30
1.43085	34
1.43026	32
1.42968	26
1.42909	36
1.42851	30
1.42793	28
1.42734	28
1.42676	38
1.42618	36
1.4256	22
1.42502	26
1.42444	28
1.42386	24
1.42328	30
1.4227	24
1.42212	28
1.42155	26
1.42097	32
1.42039	34
1.41982	30
1.41924	30
1.41867	28
1.41809	30
1.41752	26
1.41695	26
1.41637	30
1.4158	26
1.41523	28
1.41466	26
1.41409	24
1.41352	28
1.41295	22
1.41238	24
1.41181	32
1.41124	24
1.41067	22
1.41011	24
1.40954	30
1.40897	26
1.40841	30
1.40784	26.028
1.40728	27.5884
1.40672	27.7146
1.40615	29.0871
1.40559	30.9148
1.40503	32.6777
1.40446	62.3421
1.4039	26.3544
1.40334	29.1154
1.40278	27.4851
1.40222	28.6978
1.40166	29.9611
1.4011	26.647
1.40054	26.1881
1.39999	28
1.39947	26
1.3989	34
1.39834	28
1.39779	34
1.39723	28
1.39667	26
1.39611	38
1.39555	28
1.395	28
1.39444	28
1.39388	20
1.39333	24
1.39277	26
1.39222	30
1.39166	38
1.39111	32
1.39056	20
1.39	24
1.38945	30
1.3889	34
1.38835	30
1.3878	28
1.38725	30
1.3867	30
1.38615	36
1.3856	32
1.38505	30
1.3845	32
1.38396	32
1.38341	32
1.38286	24
1.38232	36
1.38177	32
1.38123	32
1.38068	32
1.38014	30
1.3796	34
1.37905	34
1.37851	30
1.37797	28
1.37743	36
1.37688	32
1.37634	26
1.3758	28
1.37526	28
1.37472	32
1.37419	40
1.37365	28
1.37311	26
1.37257	32
1.37204	36
1.3715	32
1.37096	28
1.37043	32
1.36989	38
1.36936	42
1.36882	32
1.36829	28
1.36776	30
1.36722	26
1.36669	28
1.36616	30
1.36563	22
1.3651	34
1.36457	28
1.36404	26
1.36351	30
1.36298	28
1.36245	26
1.36192	30
1.36139	30
1.36087	30
1.36034	38
1.35981	30
1.35929	36
1.35876	28
1.35824	32
1.35771	36
1.35719	38
1.35667	40
1.35614	28
1.35562	28
1.3551	30
1.35458	34
1.35406	32
1.35353	32
1.35301	26
1.35249	24
1.35197	30
1.35146	38
1.35094	28
1.35042	26
1.3499	32
1.34938	34
1.34887	32
1.34835	34
1.34783	30
1.34732	26
1.3468	30
1.34629	28
1.34578	32
1.34526	34
1.34475	24
1.34424	30
1.34372	36
1.34321	32
1.3427	32
1.34219	32
1.34168	38
1.34117	30
1.34066	26
1.34015	32
1.33964	30
1.33913	28
1.33862	30
1.33812	32
1.33761	26
1.3371	29.9341
1.3366	31.7478
1.33609	28.1348
1.33558	25.9687
1.33508	31.8682
1.33457	24.1933
1.33407	29.5923
1.33357	26.1499
1.33306	28.1346
1.33256	27.1619
1.33206	33.6438
1.33156	28.5999
1.33105	26.1467
1.33055	25.9643
1.33005	31.5369
1.32959	32
1.32909	24
1.32859	24
1.32809	38
1.32758	26
1.32708	30
1.32658	30
1.32608	26
1.32558	20
1.32508	30
1.32458	30
1.32408	36
1.32358	42
1.32309	30
1.32259	26
1.32209	28
1.3216	32
1.3211	32
1.3206	24
1.32011	32
1.31961	28
1.31912	32
1.31862	26
1.31813	26
1.31764	42
1.31714	28
1.31665	24
1.31616	24
1.31567	36
1.31518	32
1.31468	24
1.31419	28
1.3137	28
1.31321	32
1.31272	36
1.31224	28
1.31175	34
1.31126	28
1.31077	34
1.31028	32
1.3098	24
1.30931	32
1.30882	36
1.30834	34
1.30785	32
1.30737	28
1.30688	28
1.3064	30
1.30592	30
1.30543	28
1.30495	30
1.30447	24
1.30399	28
1.3035	28
1.30302	34
1.30254	32
1.30206	30
1.30158	28
1.3011	34
1.30062	38
1.30014	30
1.30001	32