File: ploting_and_data_tools.ipynb/___archivosraman/CdSe1_06.txt
#Acq. time (s)=	2
#Accumulations=	1
#Range (eV)=	2...1
#Windows=	11
#Autofocus=	Off
#AutoExposure=	Off
#Spike filter=	Off
#Delay time (s)=	0
#Binning=	1
#Readout mode=	Signal
#DeNoise=	Off
#ICS correction=	Off
#Dark correction=	Off
#Inst. Process=	Off
#Instrument=	LabRAM HR Evol
#Detector=	Syncerity OE
#Objective=	x10_VIS
#Grating=	600 (500nm)
#ND Filter=	5%
#Laser=	442nm_Notch
#Hole=	100.021
#Range=	Visible
#Project=	Paty
#Sample=
#Site=	15-06-22
#Title=	CdSe1
#Remark=
#Date=	15.06.2022 20:04
#Acquired=	15.06.2022 20:04:26
2.74975	22
2.7475	24
2.74525	22
2.743	30
2.74076	30
2.73852	24
2.73629	28
2.73406	36
2.73183	32
2.72961	24
2.72739	30
2.72517	26
2.72296	36
2.72075	26
2.71854	30
2.71634	32
2.71414	28
2.71195	36
2.70976	32
2.70757	26
2.70539	24
2.70321	22
2.70103	26
2.69886	28
2.69669	24
2.69452	30
2.69236	28
2.6902	24
2.68805	34
2.6859	22
2.68375	34
2.68161	30
2.67947	34
2.67733	22
2.6752	26
2.67307	30
2.67094	32
2.66882	28
2.6667	22
2.66458	30
2.66247	32
2.66036	18
2.65826	30
2.65615	30
2.65405	28
2.65196	34
2.64987	32
2.64778	40
2.64569	30
2.64361	30
2.64153	24
2.63946	22
2.63739	34
2.63532	24
2.63325	40
2.63119	30
2.62913	26
2.62708	32
2.62503	36
2.62298	36
2.62094	36
2.61889	30
2.61686	26
2.61482	40
2.61279	36
2.61076	26
2.60873	28
2.60671	32
2.60469	28
2.60268	30
2.60067	24
2.59866	34
2.59665	30
2.59465	36
2.59265	32
2.59065	36
2.58866	28
2.58667	36
2.58468	24
2.5827	28
2.58072	30
2.57874	36
2.57677	28
2.5748	18
2.57283	30
2.57086	32
2.5689	34
2.56694	32
2.56499	32
2.56304	30
2.56109	32
2.55914	34
2.5572	32
2.55526	32
2.55332	42
2.55139	38
2.54946	26
2.54753	30
2.5456	42
2.54368	40
2.54176	34
2.53985	38
2.53794	42
2.53603	46
2.53412	32
2.53222	42
2.53031	42
2.52842	42
2.52652	38
2.52463	44
2.52274	34
2.52085	36
2.51897	34
2.51709	32
2.51521	30
2.51334	36
2.51147	34
2.5096	38
2.50773	36
2.50587	40
2.50401	42
2.50216	42
2.5003	34
2.49845	38
2.4966	34
2.49476	46
2.49291	44
2.49107	42
2.48924	34
2.4874	44
2.48557	46
2.48374	40
2.48192	50.016
2.48009	47.68
2.47827	41.4302
2.47646	49.3162
2.47464	49.1355
2.47283	59.3272
2.47102	44.5463
2.46922	46.4576
2.46741	51.5608
2.46561	55.607
2.46381	56.9708
2.46202	53.9479
2.46023	60.31
2.45844	55.7738
2.45665	61.6134
2.45493	68
2.45314	64
2.45136	64
2.44957	68
2.44779	64
2.44601	70
2.44424	70
2.44247	72
2.4407	76
2.43893	64
2.43716	78
2.4354	78
2.43364	70
2.43188	80
2.43013	82
2.42838	82
2.42663	82
2.42488	76
2.42314	80
2.4214	88
2.41966	84
2.41792	76
2.41619	90
2.41446	84
2.41273	90
2.411	80
2.40928	80
2.40756	98
2.40584	84
2.40413	98
2.40241	84
2.4007	92
2.39899	92
2.39729	86
2.39559	104
2.39389	92
2.39219	94
2.39049	98
2.3888	84
2.38711	104
2.38542	84
2.38374	100
2.38205	88
2.38037	106
2.37869	100
2.37702	92
2.37535	96
2.37368	102
2.37201	106
2.37034	102
2.36868	102
2.36702	98
2.36536	88
2.3637	98
2.36205	88
2.3604	98
2.35875	102
2.3571	106
2.35546	94
2.35382	100
2.35218	84
2.35054	102
2.34891	112
2.34727	104
2.34564	100
2.34402	100
2.34239	96
2.34077	94
2.33915	104
2.33753	102
2.33591	86
2.3343	96
2.33269	96
2.33108	96
2.32948	88
2.32787	82
2.32627	84
2.32467	86
2.32307	78
2.32148	84
2.31989	78
2.3183	82
2.31671	72
2.31512	88
2.31354	88
2.31196	84
2.31038	86
2.3088	80
2.30723	76
2.30565	82
2.30408	72
2.30252	80
2.30095	84
2.29939	90
2.29783	64
2.29627	88
2.29471	70
2.29316	78
2.29161	78
2.29006	76
2.28851	58
2.28696	74
2.28542	74
2.28388	72
2.28234	76
2.2808	74
2.27927	76
2.27773	66
2.2762	74
2.27468	58
2.27315	72
2.27163	64
2.27011	76
2.26859	70
2.26707	70
2.26555	64
2.26404	64
2.26253	69.9873
2.26102	68.507
2.25951	68.62
2.25801	71.8341
2.25651	63.7302
2.25501	62.834
2.25351	67.8478
2.25201	67.2958
2.25052	64.5933
2.24902	68.626
2.24753	60.6849
2.24605	60.6937
2.24456	68.483
2.24308	68.8295
2.2416	81.5232
2.24011	66
2.23863	62
2.23715	64
2.23567	78
2.23419	70
2.23271	66
2.23124	64
2.22977	62
2.2283	62
2.22683	64
2.22536	58
2.2239	60
2.22244	62
2.22098	66
2.21952	62
2.21807	66
2.21661	52
2.21516	68
2.21371	70
2.21226	68
2.21082	48
2.20937	56
2.20793	62
2.20649	72
2.20505	64
2.20362	58
2.20218	66
2.20075	64
2.19932	62
2.19789	62
2.19647	52
2.19504	60
2.19362	60
2.1922	62
2.19078	62
2.18936	56
2.18795	68
2.18654	56
2.18513	48
2.18372	62
2.18231	64
2.18091	52
2.1795	70
2.1781	62
2.1767	64
2.1753	64
2.17391	52
2.17251	62
2.17112	58
2.16973	58
2.16834	58
2.16696	62
2.16557	58
2.16419	54
2.16281	48
2.16143	60
2.16005	54
2.15868	56
2.1573	62
2.15593	60
2.15456	72
2.1532	56
2.15183	64
2.15046	62
2.1491	58
2.14774	58
2.14638	64
2.14503	62
2.14367	56
2.14232	66
2.14097	54
2.13962	66
2.13827	52
2.13692	62
2.13558	52
2.13423	56
2.13289	70
2.13155	68
2.13022	56
2.12888	62
2.12755	54
2.12621	58
2.12488	58
2.12356	56
2.12223	60
2.1209	54
2.11958	66
2.11826	64
2.11694	56
2.11562	58
2.1143	58
2.11299	68
2.11168	60
2.11037	70
2.10906	66
2.10775	52
2.10644	60
2.10514	58
2.10384	60
2.10253	56
2.10123	62
2.09994	56
2.09864	66
2.09735	62
2.09605	54
2.09476	60
2.09347	66
2.09219	64
2.0909	64
2.08962	60
2.08834	66
2.08705	66
2.08578	66
2.0845	62
2.08322	58
2.08195	50
2.08068	66
2.0794	60.1244
2.07814	63.6027
2.07687	57.5345
2.0756	59.2379
2.07434	55.8918
2.07307	59.9193
2.07181	65.5914
2.07055	64.1388
2.0693	58.3947
2.06804	61.2736
2.06679	62.8689
2.06553	67.1355
2.06428	64.3336
2.06303	69.1272
2.06178	58.1611
2.06069	68
2.05944	64
2.05819	58
2.05694	62
2.05569	64
2.05445	74
2.05321	68
2.05196	66
2.05072	60
2.04949	64
2.04825	66
2.04701	64
2.04578	58
2.04455	56
2.04332	64
2.04209	60
2.04086	56
2.03964	66
2.03841	58
2.03719	64
2.03597	68
2.03475	58
2.03353	56
2.03232	48
2.0311	62
2.02989	60
2.02868	66
2.02747	62
2.02626	66
2.02505	58
2.02384	72
2.02264	54
2.02144	60
2.02024	52
2.01904	66
2.01784	68
2.01664	60
2.01544	64
2.01425	68
2.01306	64
2.01187	70
2.01068	70
2.00949	64
2.0083	70
2.00712	74
2.00594	66
2.00475	68
2.00357	66
2.0024	62
2.00122	72
2.00004	66
1.99887	66
1.99769	66
1.99652	74
1.99535	70
1.99418	76
1.99302	70
1.99185	70
1.99069	68
1.98952	78
1.98836	76
1.9872	68
1.98604	62
1.98488	64
1.98373	68
1.98257	80
1.98142	68
1.98027	74
1.97912	74
1.97797	76
1.97682	68
1.97568	64
1.97453	68
1.97339	68
1.97225	76
1.97111	82
1.96997	72
1.96883	76
1.9677	72
1.96656	76
1.96543	86
1.9643	68
1.96316	74
1.96204	70
1.96091	70
1.95978	84
1.95866	70
1.95753	70
1.95641	70
1.95529	72
1.95417	78
1.95305	76
1.95193	76
1.95082	68
1.9497	78
1.94859	76
1.94748	72
1.94637	78
1.94526	78
1.94415	84
1.94305	72
1.94194	72
1.94084	78
1.93974	82
1.93864	82
1.93754	70
1.93644	70
1.93534	62
1.93425	84
1.93315	66
1.93206	78
1.93097	64
1.92988	76
1.92879	80
1.9277	74
1.92662	70
1.92553	76
1.92445	77.9515
1.92337	81.2077
1.92228	85.0164
1.92121	71.2667
1.92013	72.8901
1.91905	73.429
1.91797	74.2031
1.9169	77.049
1.91583	76.8613
1.91475	80.6286
1.91368	78.5392
1.91261	83.4735
1.91155	76.1218
1.91048	88.642
1.90946	80
1.90839	78
1.90732	80
1.90626	82
1.90519	84
1.90413	74
1.90306	78
1.902	78
1.90094	80
1.89988	82
1.89882	80
1.89777	82
1.89671	78
1.89566	84
1.8946	76
1.89355	88
1.8925	72
1.89145	82
1.8904	90
1.88936	86
1.88831	76
1.88727	88
1.88622	76
1.88518	86
1.88414	78
1.8831	76
1.88206	86
1.88102	80
1.87999	70
1.87895	80
1.87792	90
1.87689	82
1.87586	80
1.87483	78
1.8738	80
1.87277	72
1.87174	84
1.87072	82
1.86969	72
1.86867	76
1.86765	76
1.86663	80
1.86561	84
1.86459	90
1.86357	78
1.86256	84
1.86154	94
1.86053	84
1.85952	84
1.85851	80
1.8575	94
1.85649	98
1.85548	86
1.85447	90
1.85347	74
1.85247	74
1.85146	80
1.85046	76
1.84946	86
1.84846	80
1.84746	94
1.84646	86
1.84547	96
1.84447	86
1.84348	88
1.84249	84
1.8415	78
1.84051	84
1.83952	90
1.83853	98
1.83754	80
1.83656	84
1.83557	80
1.83459	92
1.83361	80
1.83262	84
1.83164	72
1.83066	70
1.82969	94
1.82871	84
1.82773	90
1.82676	74
1.82579	90
1.82481	82
1.82384	84
1.82287	78
1.8219	88
1.82094	82
1.81997	76
1.819	92
1.81804	86
1.81708	78
1.81611	90
1.81515	94
1.81419	82
1.81323	88
1.81227	80
1.81132	80
1.81036	84
1.80941	86
1.80845	88
1.8075	78
1.80655	78
1.8056	80
1.80465	76
1.8037	80
1.80275	72
1.80181	92
1.80086	76
1.79992	72
1.79897	80
1.79803	68
1.79709	76
1.79615	76
1.79521	92
1.79428	74
1.79334	86
1.7924	86
1.79147	83.6464
1.79053	81.7032
1.7896	95.542
1.78867	77.1176
1.78774	82.3257
1.78681	77.7541
1.78588	79.5469
1.78496	77.2109
1.78403	83.8807
1.7831	91.3574
1.78218	77.6788
1.78126	79.8692
1.78033	76.4659
1.77941	81.5285
1.77851	70
1.77759	84
1.77667	88
1.77575	86
1.77483	70
1.77391	84
1.77299	92
1.77207	84
1.77115	82
1.77024	80
1.76932	84
1.76841	84
1.7675	76
1.76659	78
1.76568	84
1.76477	84
1.76386	88
1.76295	76
1.76204	74
1.76114	90
1.76023	84
1.75933	84
1.75843	82
1.75753	92
1.75662	82
1.75572	88
1.75483	80
1.75393	92
1.75303	80
1.75214	84
1.75124	86
1.75035	78
1.74945	68
1.74856	76
1.74767	72
1.74678	72
1.74589	80
1.74501	74
1.74412	74
1.74323	84
1.74235	80
1.74146	72
1.74058	88
1.7397	72
1.73882	76
1.73794	72
1.73706	84
1.73618	76
1.7353	80
1.73443	86
1.73355	80
1.73268	82
1.7318	80
1.73093	76
1.73006	74
1.72919	78
1.72832	72
1.72745	68
1.72658	64
1.72571	76
1.72485	72
1.72398	74
1.72312	78
1.72225	68
1.72139	78
1.72053	76
1.71967	68
1.71881	70
1.71795	76
1.71709	76
1.71624	70
1.71538	74
1.71453	74
1.71367	84
1.71282	78
1.71197	82
1.71112	60
1.71027	70
1.70942	68
1.70857	68
1.70772	76
1.70687	76
1.70603	70
1.70518	76
1.70434	68
1.7035	88
1.70265	86
1.70181	76
1.70097	72
1.70013	64
1.69929	70
1.69846	62
1.69762	76
1.69678	76
1.69595	70
1.69511	74
1.69428	66
1.69345	58
1.69262	86
1.69179	64
1.69096	70
1.69013	56
1.6893	64
1.68847	70
1.68765	72
1.68682	68
1.686	66
1.68517	66
1.68435	60
1.68353	68
1.68271	58
1.68189	62
1.68107	72
1.68025	60
1.67943	70
1.67861	70
1.6778	60
1.67698	67.9806
1.67617	56.7311
1.67536	64.2259
1.67454	66.9323
1.67373	70.3161
1.67292	67.7818
1.67211	58.4757
1.6713	68.366
1.6705	72.4525
1.66969	66.1636
1.66888	63.9255
1.66808	63.9358
1.66727	71.5157
1.66647	61.6131
1.66566	63.4969
1.6649	64
1.66409	70
1.66329	70
1.66249	68
1.66168	68
1.66088	62
1.66008	68
1.65928	58
1.65848	66
1.65768	68
1.65688	72
1.65608	66
1.65529	52
1.65449	62
1.6537	58
1.6529	60
1.65211	60
1.65132	72
1.65053	56
1.64973	66
1.64894	70
1.64816	62
1.64737	64
1.64658	60
1.64579	60
1.64501	52
1.64422	64
1.64344	58
1.64265	62
1.64187	62
1.64109	54
1.64031	62
1.63953	72
1.63875	64
1.63797	60
1.63719	58
1.63642	62
1.63564	60
1.63486	54
1.63409	60
1.63331	62
1.63254	58
1.63177	64
1.631	60
1.63023	60
1.62946	60
1.62869	64
1.62792	58
1.62715	52
1.62639	56
1.62562	64
1.62485	68
1.62409	66
1.62333	60
1.62256	58
1.6218	62
1.62104	48
1.62028	52
1.61952	64
1.61876	54
1.618	60
1.61724	50
1.61649	60
1.61573	58
1.61498	46
1.61422	50
1.61347	44
1.61271	64
1.61196	68
1.61121	56
1.61046	60
1.60971	48
1.60896	50
1.60821	68
1.60747	52
1.60672	62
1.60597	64
1.60523	64
1.60448	62
1.60374	56
1.603	48
1.60225	52
1.60151	58
1.60077	52
1.60003	50
1.59929	62
1.59855	58
1.59782	52
1.59708	60
1.59634	52
1.59561	52
1.59487	58
1.59414	62
1.5934	46
1.59267	46
1.59194	52
1.59121	52
1.59048	50
1.58975	50
1.58902	42
1.58829	52
1.58756	60
1.58684	54
1.58611	46
1.58538	50
1.58466	48
1.58394	58
1.58321	52
1.58249	48
1.58177	50
1.58105	52
1.58033	42
1.57961	48
1.57889	52
1.57817	44
1.57745	48
1.57674	56
1.57602	46.0268
1.5753	49.7405
1.57459	44.2653
1.57388	45.0999
1.57316	47.3565
1.57245	48.776
1.57174	48.2066
1.57103	41.3799
1.57032	51.5607
1.56961	45.7545
1.5689	44.5372
1.56819	42.5434
1.56748	50.1037
1.56678	47.584
1.56607	48.5364
1.56544	44
1.56473	42
1.56402	46
1.56331	48
1.56261	42
1.5619	48
1.56119	46
1.56049	44
1.55979	46
1.55908	48
1.55838	44
1.55768	32
1.55698	40
1.55628	46
1.55558	54
1.55488	40
1.55418	50
1.55348	38
1.55278	46
1.55209	44
1.55139	52
1.5507	52
1.55	38
1.54931	50
1.54862	44
1.54792	42
1.54723	38
1.54654	44
1.54585	38
1.54516	42
1.54447	38
1.54378	44
1.5431	48
1.54241	56
1.54172	46
1.54104	46
1.54035	46
1.53967	50
1.53898	48
1.5383	48
1.53762	44
1.53694	38
1.53626	52
1.53558	54
1.5349	42
1.53422	36
1.53354	48
1.53286	44
1.53218	44
1.53151	36
1.53083	44
1.53016	48
1.52948	46
1.52881	38
1.52813	48
1.52746	42
1.52679	38
1.52612	42
1.52545	48
1.52478	44
1.52411	38
1.52344	42
1.52277	42
1.5221	46
1.52144	46
1.52077	48
1.52011	40
1.51944	48
1.51878	46
1.51811	44
1.51745	50
1.51679	44
1.51613	44
1.51547	40
1.51481	36
1.51415	42
1.51349	40
1.51283	42
1.51217	40
1.51151	38
1.51086	36
1.5102	40
1.50954	36
1.50889	32
1.50824	42
1.50758	48
1.50693	40
1.50628	48
1.50563	46
1.50497	40
1.50432	40
1.50367	50
1.50302	36
1.50238	38
1.50173	36
1.50108	36
1.50043	32
1.49979	40
1.49914	42
1.4985	32
1.49785	40
1.49721	40
1.49657	44
1.49592	38
1.49528	34
1.49464	32
1.494	34
1.49336	40
1.49272	36
1.49208	44
1.49144	44
1.49081	38
1.49017	36
1.48953	34
1.4889	32
1.48826	44
1.48763	34
1.48699	35.9802
1.48636	37.4445
1.48573	34.9905
1.4851	37.5743
1.48446	35.4696
1.48383	37.297
1.4832	36.0823
1.48257	38.6129
1.48194	39.3014
1.48132	37.7723
1.48069	40.1576
1.48006	32.5397
1.47943	33.9361
1.47881	41.0689
1.47818	32.8274
1.47756	26
1.47694	30
1.47631	42
1.47568	34
1.47505	38
1.47443	38
1.4738	30
1.47318	34
1.47256	40
1.47193	32
1.47131	44
1.47069	32
1.47006	40
1.46944	38
1.46882	34
1.4682	34
1.46758	38
1.46696	32
1.46635	36
1.46573	32
1.46511	32
1.46449	32
1.46388	30
1.46326	36
1.46265	40
1.46203	30
1.46142	36
1.46081	34
1.46019	32
1.45958	32
1.45897	38
1.45836	34
1.45775	28
1.45714	36
1.45653	36
1.45592	32
1.45531	36
1.4547	34
1.4541	36
1.45349	26
1.45288	34
1.45228	28
1.45167	36
1.45107	26
1.45047	34
1.44986	24
1.44926	24
1.44866	28
1.44806	28
1.44746	34
1.44686	24
1.44626	30
1.44566	38
1.44506	36
1.44446	34
1.44386	28
1.44326	30
1.44267	34
1.44207	38
1.44148	26
1.44088	30
1.44029	28
1.43969	30
1.4391	36
1.43851	30
1.43791	32
1.43732	30
1.43673	34
1.43614	34
1.43555	30
1.43496	30
1.43437	24
1.43378	34
1.4332	30
1.43261	24
1.43202	30
1.43143	24
1.43085	32
1.43026	28
1.42968	30
1.42909	28
1.42851	26
1.42793	32
1.42734	26
1.42676	30
1.42618	28
1.4256	30
1.42502	32
1.42444	38
1.42386	32
1.42328	36
1.4227	30
1.42212	30
1.42155	34
1.42097	30
1.42039	32
1.41982	28
1.41924	32
1.41867	30
1.41809	28
1.41752	28
1.41695	26
1.41637	30
1.4158	28
1.41523	24
1.41466	28
1.41409	32
1.41352	32
1.41295	26
1.41238	26
1.41181	36
1.41124	30
1.41067	30
1.41011	18
1.40954	28
1.40897	24
1.40841	36
1.40784	27.9901
1.40728	33.4127
1.40672	24.8579
1.40615	34.7074
1.40559	34.3504
1.40503	39.4981
1.40446	499.96
1.4039	37.6108
1.40334	34.3097
1.40278	35.9289
1.40222	35.1546
1.40166	30.5651
1.4011	34.6396
1.40054	31.8119
1.39999	32.8349
1.39947	34
1.3989	30
1.39834	36
1.39779	30
1.39723	38
1.39667	34
1.39611	30
1.39555	34
1.395	26
1.39444	34
1.39388	34
1.39333	34
1.39277	36
1.39222	32
1.39166	40
1.39111	26
1.39056	34
1.39	34
1.38945	34
1.3889	32
1.38835	36
1.3878	30
1.38725	32
1.3867	32
1.38615	38
1.3856	26
1.38505	30
1.3845	30
1.38396	40
1.38341	32
1.38286	34
1.38232	30
1.38177	32
1.38123	32
1.38068	32
1.38014	34
1.3796	36
1.37905	26
1.37851	36
1.37797	40
1.37743	40
1.37688	24
1.37634	38
1.3758	30
1.37526	32
1.37472	36
1.37419	30
1.37365	34
1.37311	38
1.37257	32
1.37204	34
1.3715	34
1.37096	32
1.37043	34
1.36989	32
1.36936	30
1.36882	32
1.36829	34
1.36776	28
1.36722	34
1.36669	34
1.36616	32
1.36563	24
1.3651	36
1.36457	36
1.36404	32
1.36351	32
1.36298	30
1.36245	28
1.36192	28
1.36139	30
1.36087	40
1.36034	28
1.35981	30
1.35929	38
1.35876	34
1.35824	34
1.35771	40
1.35719	30
1.35667	40
1.35614	22
1.35562	34
1.3551	32
1.35458	42
1.35406	34
1.35353	34
1.35301	32
1.35249	38
1.35197	38
1.35146	32
1.35094	26
1.35042	32
1.3499	36
1.34938	34
1.34887	32
1.34835	30
1.34783	32
1.34732	38
1.3468	28
1.34629	22
1.34578	34
1.34526	38
1.34475	36
1.34424	28
1.34372	28
1.34321	32
1.3427	40
1.34219	22
1.34168	38
1.34117	28
1.34066	30
1.34015	32
1.33964	34
1.33913	28
1.33862	28
1.33812	28
1.33761	28
1.3371	32.0376
1.3366	27.7327
1.33609	25.8144
1.33558	28.4116
1.33508	31.9341
1.33457	28.737
1.33407	30.0272
1.33357	32.7751
1.33306	30.455
1.33256	31.0225
1.33206	35.1308
1.33156	30.5999
1.33105	29.1855
1.33055	32.7977
1.33005	28.3297
1.32959	32
1.32909	30
1.32859	26
1.32809	32
1.32758	30
1.32708	28
1.32658	26
1.32608	40
1.32558	36
1.32508	28
1.32458	24
1.32408	32
1.32358	34
1.32309	32
1.32259	30
1.32209	22
1.3216	30
1.3211	24
1.3206	36
1.32011	26
1.31961	32
1.31912	34
1.31862	36
1.31813	34
1.31764	30
1.31714	30
1.31665	28
1.31616	44
1.31567	42
1.31518	30
1.31468	32
1.31419	30
1.3137	32
1.31321	30
1.31272	36
1.31224	24
1.31175	32
1.31126	30
1.31077	34
1.31028	34
1.3098	34
1.30931	24
1.30882	26
1.30834	28
1.30785	26
1.30737	28
1.30688	34
1.3064	32
1.30592	30
1.30543	32
1.30495	22
1.30447	30
1.30399	28
1.3035	32
1.30302	30
1.30254	24
1.30206	32
1.30158	38
1.3011	36
1.30062	28
1.30014	28
1.30001	34