File: ploting_and_data_tools.ipynb/___archivosraman/CdSe1_04.txt
#Acq. time (s)=	2
#Accumulations=	1
#Range (eV)=	2...1
#Windows=	11
#Autofocus=	Off
#AutoExposure=	Off
#Spike filter=	Off
#Delay time (s)=	0
#Binning=	1
#Readout mode=	Signal
#DeNoise=	Off
#ICS correction=	Off
#Dark correction=	Off
#Inst. Process=	Off
#Instrument=	LabRAM HR Evol
#Detector=	Syncerity OE
#Objective=	x10_VIS
#Grating=	600 (500nm)
#ND Filter=	0.1%
#Laser=	442nm_Notch
#Hole=	70.0087
#Range=	Visible
#Project=	Paty
#Sample=
#Site=	15-06-22
#Title=	CdSe1
#Remark=
#Date=	15.06.2022 19:57
#Acquired=	15.06.2022 19:57:38
2.69985	32
2.69767	38
2.69551	40
2.69334	36
2.69118	38
2.68902	28
2.68687	34
2.68472	26
2.68257	32
2.68043	34
2.67829	38
2.67615	42
2.67402	28
2.67189	38
2.66977	34
2.66764	32
2.66553	40
2.66341	38
2.6613	36
2.65919	46
2.65709	42
2.65499	36
2.65289	38
2.65079	38
2.6487	40
2.64661	48
2.64453	46
2.64245	40
2.64037	36
2.6383	54
2.63623	46
2.63416	46
2.63209	50
2.63003	54
2.62798	50
2.62592	56
2.62387	46
2.62182	40
2.61978	52
2.61774	52
2.6157	54
2.61367	54
2.61164	58
2.60961	50
2.60758	56
2.60556	66
2.60354	62
2.60153	62
2.59952	56
2.59751	58
2.5955	84
2.5935	76
2.5915	78
2.58951	72
2.58751	78
2.58553	88
2.58354	82
2.58156	84
2.57958	98
2.5776	92
2.57563	86
2.57366	108
2.57169	110
2.56972	106
2.56776	102
2.56581	120
2.56385	110
2.5619	112
2.55995	124
2.558	124
2.55606	124
2.55412	134
2.55219	140
2.55025	140
2.54832	156
2.5464	162
2.54447	154
2.54255	156
2.54063	174
2.53872	174
2.5368	190
2.53489	204
2.53299	204
2.53108	202
2.52918	226
2.52729	230
2.52539	218
2.5235	240
2.52161	252
2.51973	276
2.51784	250
2.51596	278
2.51409	272
2.51221	300
2.51034	298
2.50847	310
2.50661	330
2.50475	320
2.50289	346
2.50103	380
2.49918	396
2.49733	396
2.49548	372
2.49363	436
2.49179	436
2.48995	440
2.48811	458
2.48628	460
2.48445	504
2.48262	540
2.4808	536
2.47897	534
2.47715	568
2.47534	552
2.47352	568
2.47171	584
2.4699	606
2.4681	628
2.46629	638
2.46449	658
2.46269	676
2.4609	692
2.45911	694
2.45732	706
2.45553	770
2.45375	756
2.45197	838
2.45019	788
2.44841	814
2.44664	832
2.44487	826
2.4431	844
2.44133	862.981
2.43957	900.779
2.43781	937.286
2.43605	918.77
2.4343	977.487
2.43255	973.832
2.4308	988.635
2.42905	986.441
2.42731	1022.64
2.42557	1036.41
2.42383	1085.83
2.42209	1097.89
2.42036	1121.69
2.41863	1106.11
2.41713	1120
2.4154	1142
2.41367	1210
2.41194	1196
2.41022	1204
2.40849	1202
2.40677	1204
2.40505	1224
2.40334	1240
2.40163	1258
2.39992	1258
2.39821	1250
2.3965	1288
2.3948	1320
2.3931	1288
2.3914	1274
2.38971	1300
2.38801	1292
2.38632	1324
2.38464	1330
2.38295	1324
2.38127	1362
2.37959	1304
2.37791	1334
2.37623	1370
2.37456	1336
2.37289	1336
2.37122	1314
2.36956	1326
2.36789	1308
2.36623	1338
2.36457	1282
2.36292	1274
2.36126	1290
2.35961	1262
2.35796	1268
2.35632	1290
2.35467	1212
2.35303	1228
2.35139	1234
2.34976	1222
2.34812	1216
2.34649	1200
2.34486	1160
2.34323	1200
2.34161	1202
2.33999	1100
2.33837	1146
2.33675	1134
2.33513	1110
2.33352	1080
2.33191	1106
2.3303	1076
2.32869	1076
2.32709	1052
2.32549	1030
2.32389	1036
2.32229	1028
2.32069	1000
2.3191	1012
2.31751	974
2.31592	960
2.31434	990
2.31275	948
2.31117	970
2.30959	944
2.30802	906
2.30644	882
2.30487	886
2.3033	900
2.30173	868
2.30017	892
2.2986	828
2.29704	854
2.29548	816
2.29393	830
2.29237	822
2.29082	816
2.28927	828
2.28772	828
2.28618	840
2.28463	800
2.28309	786
2.28155	770
2.28002	774
2.27848	748
2.27695	760
2.27542	736
2.27389	778
2.27236	764
2.27084	754
2.26932	698
2.2678	710
2.26628	694
2.26477	698
2.26325	716
2.26174	720
2.26023	702
2.25873	674
2.25722	690
2.25572	696
2.25422	640
2.25272	650
2.25122	664
2.24973	642
2.24824	642
2.24675	688
2.24526	648
2.24377	646
2.24229	644
2.24081	646
2.23933	636
2.23785	660
2.23637	638
2.2349	666
2.23343	620
2.23196	618
2.23049	622
2.22902	616.878
2.22756	610.848
2.2261	603.236
2.22464	627.608
2.22318	593.834
2.22173	594.655
2.22027	607.627
2.21882	570.069
2.21737	589.252
2.21593	559.991
2.21448	552.066
2.21304	550.063
2.21159	538.362
2.21016	525.198
2.20882	530
2.20738	552
2.20594	560
2.2045	534
2.20307	538
2.20163	546
2.2002	514
2.19877	544
2.19734	532
2.19591	526
2.19449	540
2.19307	548
2.19165	528
2.19023	506
2.18881	518
2.1874	524
2.18598	520
2.18457	510
2.18316	516
2.18176	540
2.18035	530
2.17895	550
2.17755	502
2.17615	540
2.17475	512
2.17335	528
2.17196	548
2.17057	520
2.16918	542
2.16779	544
2.1664	548
2.16502	544
2.16363	502
2.16225	532
2.16087	546
2.1595	534
2.15812	554
2.15675	512
2.15538	564
2.15401	506
2.15264	544
2.15127	556
2.14991	570
2.14854	542
2.14718	574
2.14582	564
2.14447	562
2.14311	578
2.14176	588
2.14041	600
2.13906	516
2.13771	558
2.13636	542
2.13502	544
2.13367	578
2.13233	534
2.13099	560
2.12966	548
2.12832	584
2.12699	594
2.12565	612
2.12432	582
2.12299	578
2.12167	582
2.12034	562
2.11902	592
2.1177	580
2.11638	612
2.11506	610
2.11374	624
2.11242	590
2.11111	612
2.1098	592
2.10849	574
2.10718	620
2.10588	602
2.10457	596
2.10327	582
2.10197	604
2.10067	624
2.09937	612
2.09807	622
2.09678	590
2.09549	622
2.09419	632
2.09291	600
2.09162	596
2.09033	618
2.08905	636
2.08776	616
2.08648	636
2.0852	628
2.08393	640
2.08265	670
2.08138	634
2.0801	648
2.07883	636
2.07756	610
2.07629	646
2.07503	608
2.07376	626
2.0725	644
2.07124	608
2.06998	628
2.06872	622
2.06746	606
2.06621	644
2.06496	622
2.0637	650
2.06245	626
2.06121	630
2.05996	616
2.05871	626
2.05747	626
2.05623	602
2.05499	636
2.05375	624
2.05251	628
2.05127	660.524
2.05004	623.173
2.04881	615.905
2.04758	621.65
2.04635	604.242
2.04512	632.158
2.04389	624.04
2.04267	635.763
2.04145	625.515
2.04022	624.248
2.039	627.155
2.03779	604.497
2.03657	638.07
2.03535	588.575
2.0343	604
2.03308	616
2.03186	636
2.03065	620
2.02943	602
2.02822	618
2.02701	618
2.0258	580
2.0246	610
2.02339	622
2.02218	610
2.02098	634
2.01978	612
2.01858	652
2.01738	618
2.01618	648
2.01499	634
2.0138	638
2.0126	642
2.01141	620
2.01022	618
2.00903	656
2.00785	680
2.00666	636
2.00548	656
2.0043	628
2.00312	662
2.00194	660
2.00076	650
1.99958	630
1.99841	674
1.99723	674
1.99606	690
1.99489	642
1.99372	668
1.99255	688
1.99139	658
1.99022	680
1.98906	672
1.9879	698
1.98674	682
1.98558	712
1.98442	678
1.98327	708
1.98211	692
1.98096	684
1.97981	706
1.97866	710
1.97751	724
1.97636	696
1.97521	710
1.97407	698
1.97292	734
1.97178	690
1.97064	724
1.9695	750
1.96836	758
1.96723	708
1.96609	756
1.96496	730
1.96383	722
1.9627	666
1.96157	748
1.96044	738
1.95931	738
1.95819	730
1.95706	736
1.95594	730
1.95482	724
1.9537	760
1.95258	758
1.95146	756
1.95035	758
1.94923	744
1.94812	742
1.94701	750
1.9459	728
1.94479	730
1.94368	736
1.94257	746
1.94147	730
1.94036	766
1.93926	768
1.93816	786
1.93706	740
1.93596	746
1.93486	728
1.93377	732
1.93267	762
1.93158	718
1.93049	728
1.9294	736
1.92831	784
1.92722	744
1.92614	770
1.92505	716
1.92397	760
1.92288	734
1.9218	760
1.92072	766
1.91964	754
1.91857	720
1.91749	766
1.91641	732
1.91534	770
1.91427	758
1.9132	734
1.91213	694
1.91106	724
1.90999	732
1.90893	728
1.90786	740
1.9068	714
1.90574	718
1.90467	736
1.90361	738
1.90256	724
1.9015	738
1.90044	741.014
1.89939	746.62
1.89833	732.316
1.89728	739.081
1.89623	720.132
1.89518	728.488
1.89413	727.2
1.89309	761.337
1.89204	742.003
1.891	711.969
1.88995	713.149
1.88891	745.055
1.88787	741.881
1.88683	732.685
1.88579	722
1.88475	720
1.88371	714
1.88267	722
1.88163	708
1.8806	744
1.87956	736
1.87852	732
1.87749	744
1.87646	724
1.87543	716
1.8744	760
1.87337	694
1.87234	702
1.87131	728
1.87029	684
1.86926	736
1.86824	718
1.86722	682
1.8662	722
1.86518	734
1.86416	756
1.86314	684
1.86213	686
1.86111	700
1.8601	668
1.85908	696
1.85807	694
1.85706	722
1.85605	692
1.85505	690
1.85404	714
1.85303	680
1.85203	706
1.85103	704
1.85002	690
1.84902	672
1.84802	662
1.84703	696
1.84603	668
1.84503	666
1.84404	706
1.84304	692
1.84205	718
1.84106	664
1.84007	660
1.83908	718
1.83809	682
1.8371	692
1.83612	654
1.83513	686
1.83415	736
1.83316	662
1.83218	720
1.8312	676
1.83022	684
1.82924	696
1.82827	696
1.82729	690
1.82632	706
1.82534	656
1.82437	700
1.8234	668
1.82243	712
1.82146	680
1.82049	650
1.81952	634
1.81856	664
1.81759	650
1.81663	666
1.81567	676
1.8147	668
1.81374	650
1.81278	630
1.81183	656
1.81087	656
1.80991	650
1.80896	622
1.808	628
1.80705	664
1.8061	652
1.80515	646
1.8042	646
1.80325	634
1.8023	638
1.80135	620
1.80041	604
1.79946	652
1.79852	614
1.79758	614
1.79664	624
1.7957	632
1.79476	616
1.79382	610
1.79288	628
1.79195	596
1.79101	606
1.79008	626
1.78914	618
1.78821	616
1.78728	602
1.78635	576
1.78542	578
1.7845	604
1.78357	602
1.78264	588
1.78172	630
1.7808	588
1.77987	586
1.77895	586
1.77803	566
1.77711	582
1.77619	610
1.77528	558
1.77436	578
1.77344	574
1.77253	590
1.77162	592
1.7707	562.179
1.76979	564.776
1.76888	567.533
1.76797	551.338
1.76707	560.792
1.76616	560.861
1.76525	554.81
1.76435	553.002
1.76344	544.289
1.76254	541.857
1.76164	541.408
1.76074	547.608
1.75984	543.272
1.75894	544.074
1.75806	540
1.75716	536
1.75626	558
1.75536	544
1.75446	516
1.75356	548
1.75266	502
1.75177	526
1.75087	508
1.74998	514
1.74909	508
1.74819	514
1.7473	516
1.74641	534
1.74552	522
1.74464	502
1.74375	502
1.74286	486
1.74198	474
1.74109	530
1.74021	478
1.73933	498
1.73845	494
1.73756	498
1.73669	518
1.73581	462
1.73493	456
1.73405	476
1.73318	490
1.7323	478
1.73143	486
1.73055	468
1.72968	438
1.72881	460
1.72794	464
1.72707	450
1.7262	452
1.72534	460
1.72447	434
1.7236	414
1.72274	454
1.72188	446
1.72101	430
1.72015	458
1.71929	448
1.71843	436
1.71757	450
1.71671	418
1.71586	412
1.715	428
1.71415	458
1.71329	432
1.71244	404
1.71159	406
1.71073	406
1.70988	410
1.70903	434
1.70818	418
1.70734	394
1.70649	414
1.70564	400
1.7048	424
1.70395	400
1.70311	400
1.70227	400
1.70143	376
1.70059	396
1.69975	388
1.69891	374
1.69807	370
1.69723	360
1.69639	390
1.69556	370
1.69472	360
1.69389	354
1.69306	356
1.69223	360
1.6914	348
1.69057	338
1.68974	334
1.68891	324
1.68808	350
1.68725	330
1.68643	330
1.6856	354
1.68478	342
1.68396	340
1.68313	338
1.68231	366
1.68149	332
1.68067	344
1.67985	332
1.67904	364
1.67822	342
1.6774	330
1.67659	336
1.67577	348
1.67496	340
1.67415	338
1.67333	326
1.67252	342
1.67171	326
1.6709	326
1.67009	326
1.66929	340
1.66848	304
1.66767	332
1.66687	310
1.66607	294
1.66526	316
1.66446	330
1.66366	294
1.66286	320
1.66206	294
1.66126	306
1.66046	312
1.65966	324
1.65886	313.971
1.65807	308.658
1.65727	302.974
1.65648	312.393
1.65569	311.296
1.65489	299.912
1.6541	298.333
1.65331	299.478
1.65252	291.892
1.65173	305.168
1.65094	295.635
1.65015	290.804
1.64937	283.494
1.64858	287.216
1.6478	264.915
1.64705	280
1.64626	268
1.64547	276
1.64469	274
1.6439	292
1.64312	276
1.64233	266
1.64155	278
1.64077	248
1.63999	254
1.63921	242
1.63843	274
1.63765	254
1.63687	270
1.63609	264
1.63532	248
1.63454	244
1.63376	226
1.63299	240
1.63222	236
1.63144	240
1.63067	268
1.6299	252
1.62913	224
1.62836	244
1.62759	238
1.62682	238
1.62606	234
1.62529	246
1.62453	246
1.62376	236
1.623	228
1.62223	234
1.62147	238
1.62071	246
1.61995	216
1.61919	222
1.61843	232
1.61767	228
1.61691	216
1.61616	216
1.6154	230
1.61464	220
1.61389	218
1.61313	238
1.61238	202
1.61163	210
1.61088	206
1.61013	200
1.60938	216
1.60863	200
1.60788	204
1.60713	216
1.60638	202
1.60564	210
1.60489	200
1.60415	194
1.6034	204
1.60266	188
1.60192	192
1.60117	188
1.60043	200
1.59969	188
1.59895	172
1.59821	176
1.59747	206
1.59674	186
1.596	190
1.59526	176
1.59453	186
1.59379	196
1.59306	180
1.59233	174
1.5916	186
1.59086	180
1.59013	172
1.5894	172
1.58867	182
1.58794	168
1.58722	158
1.58649	162
1.58576	164
1.58504	188
1.58431	168
1.58359	158
1.58286	170
1.58214	150
1.58142	152
1.5807	160
1.57998	170
1.57926	154
1.57854	160
1.57782	164
1.5771	152
1.57638	158
1.57567	148
1.57495	146
1.57424	146
1.57352	146
1.57281	138
1.5721	144
1.57138	146
1.57067	144
1.56996	142
1.56925	142
1.56854	146
1.56783	140
1.56713	158
1.56642	146
1.56571	144
1.56501	136
1.5643	132
1.5636	148
1.56289	122
1.56219	126
1.56149	140
1.56079	142
1.56008	137.905
1.55938	133.125
1.55868	123.936
1.55799	123.149
1.55729	117.566
1.55659	131.888
1.55589	117.816
1.5552	122.87
1.5545	112.393
1.55381	120.607
1.55311	115.041
1.55242	123.861
1.55173	108.716
1.55103	111.627
1.55034	105.566
1.54971	110
1.54902	106
1.54833	108
1.54763	102
1.54694	114
1.54625	118
1.54556	128
1.54487	116
1.54418	106
1.54349	110
1.5428	98
1.54212	118
1.54143	112
1.54074	102
1.54006	98
1.53937	104
1.53869	116
1.53801	108
1.53732	92
1.53664	100
1.53596	88
1.53528	102
1.5346	100
1.53392	96
1.53324	92
1.53256	106
1.53189	102
1.53121	96
1.53053	94
1.52986	100
1.52918	90
1.52851	100
1.52783	90
1.52716	96
1.52649	80
1.52582	96
1.52515	90
1.52448	98
1.52381	80
1.52314	94
1.52247	96
1.5218	84
1.52113	86
1.52047	90
1.5198	84
1.51914	86
1.51847	82
1.51781	86
1.51715	80
1.51648	74
1.51582	78
1.51516	90
1.5145	86
1.51384	82
1.51318	76
1.51252	88
1.51186	82
1.5112	76
1.51055	78
1.50989	80
1.50923	76
1.50858	80
1.50793	84
1.50727	76
1.50662	76
1.50597	84
1.50531	76
1.50466	72
1.50401	74
1.50336	86
1.50271	82
1.50206	70
1.50141	70
1.50077	88
1.50012	76
1.49947	76
1.49883	78
1.49818	64
1.49754	74
1.49689	78
1.49625	76
1.49561	68
1.49496	76
1.49432	72
1.49368	68
1.49304	70
1.4924	70
1.49176	68
1.49112	66
1.49049	72
1.48985	74
1.48921	70
1.48858	68
1.48794	66
1.48731	70
1.48667	66
1.48604	56
1.4854	72
1.48477	58
1.48414	72
1.48351	64
1.48288	64
1.48225	70
1.48162	70
1.48099	54
1.48036	54
1.47973	58
1.47911	60
1.47848	68
1.47785	64
1.47723	64
1.4766	54
1.47598	58
1.47535	52
1.47473	56
1.47411	52
1.47349	64
1.47287	62
1.47224	54.2333
1.47162	52.3349
1.471	54.5245
1.47039	51.45
1.46977	50.3016
1.46915	46.016
1.46853	51.513
1.46791	52.5377
1.4673	55.3496
1.46668	49.6637
1.46607	52.7797
1.46545	46.948
1.46484	38.57
1.46423	46.6711
1.46363	40
1.46302	48
1.4624	52
1.46179	52
1.46117	62
1.46056	32
1.45995	40
1.45934	40
1.45872	48
1.45811	48
1.4575	46
1.45689	40
1.45628	38
1.45567	38
1.45506	40
1.45446	26
1.45385	32
1.45324	36
1.45264	36
1.45203	36
1.45142	26
1.45082	18
1.45022	30
1.44961	30
1.44901	28
1.44841	30
1.44781	30
1.4472	24
1.4466	24
1.446	28
1.4454	34
1.4448	26
1.44421	26
1.44361	32
1.44301	28
1.44241	32
1.44182	36
1.44122	32
1.44063	32
1.44003	26
1.43944	32
1.43884	24
1.43825	32
1.43766	22
1.43706	34
1.43647	30
1.43588	32
1.43529	32
1.4347	24
1.43411	36
1.43352	26
1.43293	32
1.43235	34
1.43176	26
1.43117	34
1.43059	30
1.43	26
1.42942	30
1.42883	36
1.42825	30
1.42766	26
1.42708	32
1.4265	32
1.42592	32
1.42533	30
1.42475	26
1.42417	28
1.42359	34
1.42301	24
1.42244	24
1.42186	28
1.42128	24
1.4207	24
1.42012	32
1.41955	26
1.41897	32
1.4184	26
1.41782	32
1.41725	24
1.41668	28
1.4161	28
1.41553	20
1.41496	24
1.41439	22
1.41381	32
1.41324	30
1.41267	28
1.4121	26
1.41154	28
1.41097	28
1.4104	30
1.40983	28
1.40926	28
1.4087	38
1.40813	38
1.40757	34
1.407	36
1.40644	40
1.40587	32
1.40531	40
1.40475	36
1.40418	58
1.40362	46
1.40306	36
1.4025	46
1.40194	42
1.40138	44
1.40082	40
1.40026	42
1.3997	40
1.39914	40
1.39859	44
1.39803	36
1.39747	42
1.39692	38
1.39636	40
1.39581	36
1.39525	46
1.3947	45.3334
1.39415	41.5696
1.39359	39.6561
1.39304	42.789
1.39249	39.9525
1.39194	44.6446
1.39139	36.2093
1.39084	42.1065
1.39029	39.7584
1.38974	38.992
1.38919	39.2525
1.38864	39.0396
1.38809	39.3745
1.38754	44.0631
1.38705	28
1.3865	44
1.38595	40
1.3854	44
1.38485	46
1.3843	40
1.38375	42
1.38321	32
1.38266	38
1.38211	40
1.38157	38
1.38102	38
1.38048	38
1.37993	40
1.37939	34
1.37885	44
1.3783	32
1.37776	42
1.37722	36
1.37668	32
1.37614	34
1.37559	34
1.37505	32
1.37452	34
1.37398	40
1.37344	30
1.3729	36
1.37236	44
1.37182	46
1.37129	40
1.37075	40
1.37022	46
1.36968	40
1.36914	34
1.36861	40
1.36808	34
1.36754	38
1.36701	36
1.36648	34
1.36594	36
1.36541	38
1.36488	36
1.36435	42
1.36382	38
1.36329	40
1.36276	36
1.36223	42
1.3617	46
1.36118	34
1.36065	34
1.36012	32
1.35959	30
1.35907	40
1.35854	40
1.35802	44
1.35749	32
1.35697	34
1.35644	40
1.35592	36
1.3554	30
1.35488	32
1.35435	40
1.35383	36
1.35331	32
1.35279	46
1.35227	34
1.35175	40
1.35123	44
1.35071	50
1.35019	32
1.34967	34
1.34916	32
1.34864	38
1.34812	38
1.34761	36
1.34709	32
1.34657	40
1.34606	34
1.34555	40
1.34503	32
1.34452	38
1.344	44
1.34349	30
1.34298	32
1.34247	26
1.34196	32
1.34144	42
1.34093	36
1.34042	36
1.33991	36
1.3394	30
1.3389	34
1.33839	32
1.33788	30
1.33737	34
1.33686	42
1.33636	30
1.33585	28
1.33535	30
1.33484	34
1.33434	36
1.33383	38
1.33333	40
1.33282	36
1.33232	34
1.33182	30
1.33132	26
1.33081	38
1.33031	36
1.32981	32
1.32931	32
1.32881	24
1.32831	36
1.32781	32
1.32731	30
1.32681	28
1.32631	38
1.32582	28
1.32532	35.78
1.32482	31.3027
1.32433	31.0075
1.32383	34.3266
1.32333	29.5993
1.32284	24.8438
1.32234	33.0051
1.32185	32.1813
1.32136	32.6224
1.32086	30.0528
1.32037	31.126
1.31988	26.1451
1.31939	29.0096
1.31889	32.8364
1.31843	34
1.31793	32
1.31744	32
1.31695	38
1.31645	32
1.31596	34
1.31547	28
1.31498	32
1.31449	38
1.31399	28
1.3135	32
1.31301	30
1.31252	28
1.31204	34
1.31155	26
1.31106	32
1.31057	24
1.31008	30
1.30959	32
1.30911	32
1.30862	26
1.30814	28
1.30765	34
1.30717	34
1.30668	28
1.3062	30
1.30571	28
1.30523	34
1.30475	34
1.30426	26
1.30378	36
1.3033	40
1.30282	30
1.30234	34
1.30185	28
1.30137	36
1.30089	30
1.30041	28
1.3	30