File: ploting_and_data_tools.ipynb/___archivosraman/CdSe1_10.txt
#Acq. time (s)=	1
#Accumulations=	1
#Range (eV)=	2...1
#Windows=	11
#Autofocus=	Off
#AutoExposure=	Off
#Spike filter=	Off
#Delay time (s)=	0
#Binning=	1
#Readout mode=	Signal
#DeNoise=	Off
#ICS correction=	Off
#Dark correction=	Off
#Inst. Process=	Off
#Instrument=	LabRAM HR Evol
#Detector=	Syncerity OE
#Objective=	x100_VIS_LWD
#Grating=	600 (500nm)
#ND Filter=	1%
#Laser=	442nm_Notch
#Hole=	100.021
#Range=	Visible
#Project=	Paty
#Sample=
#Site=	15-06-22
#Title=	CdSe1
#Remark=
#Date=	15.06.2022 20:30
#Acquired=	15.06.2022 20:30:37
2.74975	28
2.7475	28
2.74525	32
2.743	30
2.74076	26
2.73852	32
2.73629	24
2.73406	28
2.73183	24
2.72961	38
2.72739	32
2.72517	24
2.72296	32
2.72075	26
2.71854	30
2.71634	30
2.71414	26
2.71195	26
2.70976	32
2.70757	32
2.70539	32
2.70321	24
2.70103	26
2.69886	26
2.69669	32
2.69452	32
2.69236	30
2.6902	24
2.68805	34
2.6859	38
2.68375	42
2.68161	34
2.67947	38
2.67733	30
2.6752	38
2.67307	38
2.67094	34
2.66882	34
2.6667	36
2.66458	34
2.66247	36
2.66036	42
2.65826	32
2.65615	32
2.65405	36
2.65196	38
2.64987	40
2.64778	42
2.64569	42
2.64361	42
2.64153	46
2.63946	50
2.63739	36
2.63532	44
2.63325	50
2.63119	42
2.62913	46
2.62708	48
2.62503	54
2.62298	46
2.62094	48
2.61889	54
2.61686	52
2.61482	54
2.61279	58
2.61076	58
2.60873	50
2.60671	56
2.60469	54
2.60268	60
2.60067	60
2.59866	66
2.59665	60
2.59465	72
2.59265	64
2.59065	78
2.58866	64
2.58667	84
2.58468	80
2.5827	80
2.58072	84
2.57874	72
2.57677	84
2.5748	76
2.57283	88
2.57086	84
2.5689	88
2.56694	96
2.56499	98
2.56304	112
2.56109	112
2.55914	120
2.5572	122
2.55526	118
2.55332	124
2.55139	138
2.54946	142
2.54753	152
2.5456	150
2.54368	160
2.54176	156
2.53985	160
2.53794	174
2.53603	162
2.53412	190
2.53222	188
2.53031	202
2.52842	222
2.52652	200
2.52463	230
2.52274	218
2.52085	218
2.51897	226
2.51709	238
2.51521	250
2.51334	264
2.51147	274
2.5096	266
2.50773	290
2.50587	320
2.50401	306
2.50216	330
2.5003	314
2.49845	372
2.4966	362
2.49476	382
2.49291	376
2.49107	402
2.48924	376
2.4874	434
2.48557	422
2.48374	440
2.48192	437.49
2.48009	457.123
2.47827	482.772
2.47646	501.486
2.47464	540.546
2.47283	556.472
2.47102	557.479
2.46922	589.431
2.46741	605.364
2.46561	625.379
2.46381	662.812
2.46202	682.704
2.46023	719.497
2.45844	721.782
2.45665	769.988
2.45493	804
2.45314	806
2.45136	800
2.44957	826
2.44779	894
2.44601	892
2.44424	868
2.44247	866
2.4407	928
2.43893	930
2.43716	966
2.4354	954
2.43364	996
2.43188	1010
2.43013	1040
2.42838	1020
2.42663	1060
2.42488	1076
2.42314	1108
2.4214	1122
2.41966	1188
2.41792	1112
2.41619	1128
2.41446	1182
2.41273	1192
2.411	1166
2.40928	1208
2.40756	1236
2.40584	1198
2.40413	1248
2.40241	1244
2.4007	1230
2.39899	1250
2.39729	1280
2.39559	1276
2.39389	1280
2.39219	1280
2.39049	1290
2.3888	1306
2.38711	1312
2.38542	1276
2.38374	1258
2.38205	1344
2.38037	1324
2.37869	1386
2.37702	1346
2.37535	1316
2.37368	1338
2.37201	1340
2.37034	1344
2.36868	1346
2.36702	1344
2.36536	1256
2.3637	1290
2.36205	1300
2.3604	1288
2.35875	1324
2.3571	1258
2.35546	1218
2.35382	1230
2.35218	1260
2.35054	1228
2.34891	1200
2.34727	1220
2.34564	1214
2.34402	1146
2.34239	1128
2.34077	1144
2.33915	1092
2.33753	1120
2.33591	1050
2.3343	1074
2.33269	1098
2.33108	1056
2.32948	1012
2.32787	1012
2.32627	1028
2.32467	986
2.32307	986
2.32148	990
2.31989	950
2.3183	920
2.31671	928
2.31512	916
2.31354	864
2.31196	872
2.31038	832
2.3088	850
2.30723	806
2.30565	844
2.30408	800
2.30252	822
2.30095	796
2.29939	798
2.29783	772
2.29627	782
2.29471	754
2.29316	714
2.29161	732
2.29006	702
2.28851	730
2.28696	716
2.28542	704
2.28388	670
2.28234	654
2.2808	658
2.27927	676
2.27773	636
2.2762	602
2.27468	600
2.27315	612
2.27163	606
2.27011	590
2.26859	576
2.26707	584
2.26555	576
2.26404	574
2.26253	583.316
2.26102	578.797
2.25951	530.289
2.25801	535.255
2.25651	549.887
2.25501	532.212
2.25351	505.224
2.25201	510.073
2.25052	503.333
2.24902	483.373
2.24753	482.512
2.24605	478.551
2.24456	466.217
2.24308	451.884
2.2416	465.619
2.24011	428
2.23863	424
2.23715	444
2.23567	412
2.23419	438
2.23271	424
2.23124	420
2.22977	406
2.2283	376
2.22683	408
2.22536	398
2.2239	392
2.22244	376
2.22098	372
2.21952	374
2.21807	360
2.21661	370
2.21516	378
2.21371	372
2.21226	370
2.21082	350
2.20937	348
2.20793	368
2.20649	346
2.20505	324
2.20362	344
2.20218	338
2.20075	356
2.19932	334
2.19789	350
2.19647	354
2.19504	348
2.19362	352
2.1922	332
2.19078	340
2.18936	330
2.18795	338
2.18654	316
2.18513	324
2.18372	328
2.18231	338
2.18091	312
2.1795	322
2.1781	322
2.1767	332
2.1753	326
2.17391	326
2.17251	308
2.17112	316
2.16973	322
2.16834	314
2.16696	318
2.16557	296
2.16419	322
2.16281	318
2.16143	346
2.16005	314
2.15868	310
2.1573	312
2.15593	304
2.15456	316
2.1532	286
2.15183	296
2.15046	312
2.1491	296
2.14774	300
2.14638	316
2.14503	308
2.14367	298
2.14232	300
2.14097	304
2.13962	326
2.13827	292
2.13692	316
2.13558	296
2.13423	320
2.13289	322
2.13155	298
2.13022	318
2.12888	324
2.12755	294
2.12621	292
2.12488	312
2.12356	296
2.12223	298
2.1209	336
2.11958	310
2.11826	306
2.11694	304
2.11562	310
2.1143	310
2.11299	304
2.11168	292
2.11037	328
2.10906	300
2.10775	316
2.10644	326
2.10514	306
2.10384	316
2.10253	320
2.10123	312
2.09994	316
2.09864	328
2.09735	322
2.09605	308
2.09476	304
2.09347	302
2.09219	304
2.0909	342
2.08962	328
2.08834	318
2.08705	308
2.08578	300
2.0845	302
2.08322	312
2.08195	334
2.08068	316
2.0794	305.883
2.07814	297.277
2.07687	307.05
2.0756	300.099
2.07434	303.855
2.07307	299.683
2.07181	312.536
2.07055	296.165
2.0693	292.903
2.06804	306.285
2.06679	282.64
2.06553	296.994
2.06428	307.605
2.06303	284.75
2.06178	289.033
2.06069	300
2.05944	292
2.05819	302
2.05694	276
2.05569	306
2.05445	286
2.05321	292
2.05196	284
2.05072	298
2.04949	298
2.04825	300
2.04701	292
2.04578	292
2.04455	314
2.04332	286
2.04209	296
2.04086	296
2.03964	286
2.03841	264
2.03719	284
2.03597	280
2.03475	278
2.03353	282
2.03232	302
2.0311	300
2.02989	282
2.02868	270
2.02747	280
2.02626	274
2.02505	276
2.02384	294
2.02264	270
2.02144	278
2.02024	294
2.01904	300
2.01784	292
2.01664	286
2.01544	278
2.01425	294
2.01306	288
2.01187	298
2.01068	276
2.00949	284
2.0083	308
2.00712	296
2.00594	278
2.00475	298
2.00357	284
2.0024	264
2.00122	294
2.00004	288
1.99887	288
1.99769	302
1.99652	312
1.99535	292
1.99418	302
1.99302	302
1.99185	298
1.99069	298
1.98952	288
1.98836	284
1.9872	292
1.98604	322
1.98488	280
1.98373	294
1.98257	320
1.98142	310
1.98027	294
1.97912	300
1.97797	290
1.97682	332
1.97568	302
1.97453	308
1.97339	314
1.97225	318
1.97111	320
1.96997	304
1.96883	318
1.9677	316
1.96656	302
1.96543	300
1.9643	302
1.96316	306
1.96204	288
1.96091	298
1.95978	304
1.95866	304
1.95753	280
1.95641	306
1.95529	294
1.95417	288
1.95305	290
1.95193	290
1.95082	298
1.9497	314
1.94859	314
1.94748	296
1.94637	278
1.94526	306
1.94415	292
1.94305	294
1.94194	290
1.94084	312
1.93974	302
1.93864	292
1.93754	316
1.93644	274
1.93534	296
1.93425	276
1.93315	288
1.93206	294
1.93097	274
1.92988	294
1.92879	288
1.9277	294
1.92662	280
1.92553	298
1.92445	281.974
1.92337	282.341
1.92228	290.67
1.92121	291.321
1.92013	303.592
1.91905	284.047
1.91797	293.934
1.9169	291.936
1.91583	280.599
1.91475	292.744
1.91368	275.915
1.91261	287.761
1.91155	277.063
1.91048	280.532
1.90946	282
1.90839	282
1.90732	284
1.90626	292
1.90519	278
1.90413	264
1.90306	282
1.902	272
1.90094	282
1.89988	282
1.89882	304
1.89777	266
1.89671	274
1.89566	276
1.8946	246
1.89355	292
1.8925	274
1.89145	276
1.8904	266
1.88936	272
1.88831	252
1.88727	258
1.88622	258
1.88518	258
1.88414	282
1.8831	248
1.88206	248
1.88102	260
1.87999	274
1.87895	248
1.87792	252
1.87689	256
1.87586	262
1.87483	260
1.8738	250
1.87277	256
1.87174	260
1.87072	270
1.86969	248
1.86867	262
1.86765	248
1.86663	262
1.86561	274
1.86459	258
1.86357	250
1.86256	236
1.86154	254
1.86053	258
1.85952	250
1.85851	246
1.8575	254
1.85649	238
1.85548	256
1.85447	226
1.85347	244
1.85247	242
1.85146	240
1.85046	230
1.84946	246
1.84846	244
1.84746	248
1.84646	228
1.84547	262
1.84447	238
1.84348	206
1.84249	250
1.8415	236
1.84051	230
1.83952	234
1.83853	228
1.83754	236
1.83656	234
1.83557	220
1.83459	224
1.83361	244
1.83262	250
1.83164	218
1.83066	222
1.82969	220
1.82871	234
1.82773	210
1.82676	224
1.82579	234
1.82481	234
1.82384	208
1.82287	230
1.8219	206
1.82094	224
1.81997	220
1.819	212
1.81804	212
1.81708	226
1.81611	218
1.81515	218
1.81419	216
1.81323	218
1.81227	222
1.81132	224
1.81036	218
1.80941	220
1.80845	216
1.8075	202
1.80655	194
1.8056	222
1.80465	202
1.8037	188
1.80275	218
1.80181	202
1.80086	202
1.79992	204
1.79897	214
1.79803	230
1.79709	204
1.79615	214
1.79521	212
1.79428	186
1.79334	198
1.7924	192
1.79147	201.737
1.79053	202.084
1.7896	203.98
1.78867	193.681
1.78774	195.359
1.78681	191.579
1.78588	195.361
1.78496	186.439
1.78403	182.293
1.7831	178.657
1.78218	187.761
1.78126	180.634
1.78033	183.383
1.77941	170.851
1.77851	178
1.77759	196
1.77667	170
1.77575	194
1.77483	190
1.77391	170
1.77299	172
1.77207	174
1.77115	180
1.77024	192
1.76932	176
1.76841	170
1.7675	170
1.76659	174
1.76568	158
1.76477	160
1.76386	168
1.76295	182
1.76204	176
1.76114	176
1.76023	166
1.75933	162
1.75843	160
1.75753	164
1.75662	172
1.75572	190
1.75483	158
1.75393	160
1.75303	166
1.75214	172
1.75124	162
1.75035	154
1.74945	150
1.74856	174
1.74767	162
1.74678	152
1.74589	174
1.74501	148
1.74412	140
1.74323	158
1.74235	154
1.74146	158
1.74058	146
1.7397	138
1.73882	156
1.73794	146
1.73706	152
1.73618	142
1.7353	158
1.73443	132
1.73355	150
1.73268	148
1.7318	142
1.73093	144
1.73006	136
1.72919	140
1.72832	140
1.72745	146
1.72658	152
1.72571	134
1.72485	136
1.72398	150
1.72312	144
1.72225	130
1.72139	144
1.72053	120
1.71967	128
1.71881	136
1.71795	126
1.71709	126
1.71624	130
1.71538	124
1.71453	150
1.71367	130
1.71282	128
1.71197	128
1.71112	124
1.71027	122
1.70942	128
1.70857	130
1.70772	118
1.70687	124
1.70603	124
1.70518	118
1.70434	114
1.7035	126
1.70265	142
1.70181	132
1.70097	118
1.70013	108
1.69929	106
1.69846	112
1.69762	112
1.69678	110
1.69595	108
1.69511	114
1.69428	112
1.69345	114
1.69262	112
1.69179	118
1.69096	122
1.69013	102
1.6893	104
1.68847	90
1.68765	102
1.68682	102
1.686	104
1.68517	88
1.68435	100
1.68353	104
1.68271	114
1.68189	100
1.68107	94
1.68025	106
1.67943	96
1.67861	94
1.6778	108
1.67698	109.951
1.67617	90.9451
1.67536	95.9377
1.67454	107.982
1.67373	107.059
1.67292	91.994
1.67211	100.35
1.6713	98.1893
1.6705	96.9664
1.66969	95.1453
1.66888	101.657
1.66808	91.839
1.66727	96.3525
1.66647	100.117
1.66566	97.9338
1.6649	96
1.66409	92
1.66329	100
1.66249	100
1.66168	102
1.66088	90
1.66008	92
1.65928	92
1.65848	84
1.65768	86
1.65688	86
1.65608	96
1.65529	94
1.65449	106
1.6537	88
1.6529	82
1.65211	88
1.65132	86
1.65053	96
1.64973	82
1.64894	96
1.64816	92
1.64737	82
1.64658	76
1.64579	82
1.64501	88
1.64422	88
1.64344	86
1.64265	86
1.64187	90
1.64109	102
1.64031	78
1.63953	74
1.63875	80
1.63797	84
1.63719	82
1.63642	78
1.63564	86
1.63486	90
1.63409	82
1.63331	80
1.63254	86
1.63177	80
1.631	98
1.63023	76
1.62946	74
1.62869	76
1.62792	84
1.62715	94
1.62639	94
1.62562	78
1.62485	88
1.62409	66
1.62333	80
1.62256	90
1.6218	62
1.62104	76
1.62028	72
1.61952	62
1.61876	80
1.618	68
1.61724	80
1.61649	80
1.61573	68
1.61498	68
1.61422	66
1.61347	72
1.61271	64
1.61196	66
1.61121	66
1.61046	62
1.60971	54
1.60896	60
1.60821	70
1.60747	72
1.60672	68
1.60597	70
1.60523	68
1.60448	66
1.60374	70
1.603	62
1.60225	52
1.60151	62
1.60077	74
1.60003	54
1.59929	56
1.59855	68
1.59782	62
1.59708	70
1.59634	60
1.59561	56
1.59487	54
1.59414	58
1.5934	60
1.59267	56
1.59194	60
1.59121	62
1.59048	66
1.58975	68
1.58902	52
1.58829	60
1.58756	56
1.58684	56
1.58611	64
1.58538	50
1.58466	66
1.58394	64
1.58321	56
1.58249	56
1.58177	48
1.58105	54
1.58033	50
1.57961	56
1.57889	56
1.57817	56
1.57745	48
1.57674	54
1.57602	59.9435
1.5753	53.628
1.57459	46.028
1.57388	50.1995
1.57316	61.099
1.57245	48.0727
1.57174	51.8222
1.57103	47.9872
1.57032	46.0719
1.56961	51.7723
1.5689	55.8787
1.56819	49.977
1.56748	52.8247
1.56678	49.0418
1.56607	48.6199
1.56544	48
1.56473	46
1.56402	44
1.56331	44
1.56261	42
1.5619	52
1.56119	44
1.56049	48
1.55979	52
1.55908	42
1.55838	40
1.55768	36
1.55698	36
1.55628	46
1.55558	40
1.55488	50
1.55418	46
1.55348	48
1.55278	44
1.55209	44
1.55139	48
1.5507	40
1.55	36
1.54931	48
1.54862	50
1.54792	46
1.54723	46
1.54654	54
1.54585	44
1.54516	40
1.54447	46
1.54378	46
1.5431	44
1.54241	54
1.54172	42
1.54104	44
1.54035	38
1.53967	50
1.53898	54
1.5383	40
1.53762	48
1.53694	48
1.53626	48
1.53558	50
1.5349	42
1.53422	36
1.53354	38
1.53286	44
1.53218	40
1.53151	46
1.53083	30
1.53016	46
1.52948	48
1.52881	44
1.52813	38
1.52746	40
1.52679	34
1.52612	44
1.52545	48
1.52478	34
1.52411	42
1.52344	42
1.52277	44
1.5221	38
1.52144	38
1.52077	40
1.52011	38
1.51944	30
1.51878	36
1.51811	42
1.51745	34
1.51679	44
1.51613	32
1.51547	44
1.51481	34
1.51415	44
1.51349	38
1.51283	36
1.51217	38
1.51151	36
1.51086	34
1.5102	42
1.50954	28
1.50889	38
1.50824	30
1.50758	46
1.50693	44
1.50628	36
1.50563	34
1.50497	32
1.50432	34
1.50367	48
1.50302	40
1.50238	40
1.50173	30
1.50108	36
1.50043	40
1.49979	36
1.49914	36
1.4985	36
1.49785	28
1.49721	38
1.49657	34
1.49592	32
1.49528	36
1.49464	30
1.494	44
1.49336	32
1.49272	28
1.49208	34
1.49144	36
1.49081	34
1.49017	28
1.48953	38
1.4889	36
1.48826	26
1.48763	34
1.48699	32.0198
1.48636	28.4841
1.48573	32.2404
1.4851	36.7228
1.48446	33.4356
1.48383	35.1881
1.4832	37.6242
1.48257	36.4861
1.48194	32.6028
1.48132	29.1637
1.48069	29.0457
1.48006	32.7077
1.47943	39.2583
1.47881	35.1309
1.47818	31.3211
1.47756	28
1.47694	30
1.47631	30
1.47568	34
1.47505	30
1.47443	36
1.4738	34
1.47318	36
1.47256	28
1.47193	30
1.47131	28
1.47069	30
1.47006	34
1.46944	36
1.46882	26
1.4682	36
1.46758	32
1.46696	28
1.46635	30
1.46573	34
1.46511	22
1.46449	34
1.46388	32
1.46326	30
1.46265	34
1.46203	36
1.46142	30
1.46081	36
1.46019	32
1.45958	26
1.45897	22
1.45836	32
1.45775	32
1.45714	28
1.45653	30
1.45592	26
1.45531	28
1.4547	34
1.4541	28
1.45349	26
1.45288	26
1.45228	32
1.45167	26
1.45107	26
1.45047	30
1.44986	34
1.44926	32
1.44866	34
1.44806	32
1.44746	28
1.44686	28
1.44626	22
1.44566	28
1.44506	36
1.44446	30
1.44386	30
1.44326	32
1.44267	26
1.44207	28
1.44148	26
1.44088	32
1.44029	32
1.43969	34
1.4391	32
1.43851	26
1.43791	32
1.43732	34
1.43673	22
1.43614	28
1.43555	30
1.43496	34
1.43437	30
1.43378	26
1.4332	28
1.43261	28
1.43202	32
1.43143	30
1.43085	34
1.43026	30
1.42968	28
1.42909	22
1.42851	30
1.42793	32
1.42734	32
1.42676	24
1.42618	30
1.4256	28
1.42502	28
1.42444	24
1.42386	32
1.42328	26
1.4227	30
1.42212	28
1.42155	26
1.42097	28
1.42039	24
1.41982	28
1.41924	30
1.41867	22
1.41809	26
1.41752	28
1.41695	32
1.41637	36
1.4158	28
1.41523	30
1.41466	32
1.41409	34
1.41352	28
1.41295	24
1.41238	36
1.41181	26
1.41124	36
1.41067	32
1.41011	28
1.40954	24
1.40897	28
1.40841	34
1.40784	26.0155
1.40728	26.4388
1.40672	28.282
1.40615	27.605
1.40559	32.7844
1.40503	29.8074
1.40446	50.7736
1.4039	29.3694
1.40334	31.7314
1.40278	28.5859
1.40222	31.007
1.40166	27.374
1.4011	28.093
1.40054	27.6845
1.39999	29.1155
1.39947	30
1.3989	30
1.39834	28
1.39779	28
1.39723	32
1.39667	34
1.39611	30
1.39555	34
1.395	32
1.39444	30
1.39388	30
1.39333	30
1.39277	34
1.39222	32
1.39166	36
1.39111	36
1.39056	24
1.39	32
1.38945	28
1.3889	30
1.38835	38
1.3878	26
1.38725	30
1.3867	32
1.38615	34
1.3856	34
1.38505	28
1.3845	30
1.38396	34
1.38341	34
1.38286	24
1.38232	26
1.38177	34
1.38123	34
1.38068	32
1.38014	40
1.3796	28
1.37905	32
1.37851	32
1.37797	30
1.37743	34
1.37688	32
1.37634	34
1.3758	32
1.37526	36
1.37472	34
1.37419	24
1.37365	24
1.37311	32
1.37257	32
1.37204	26
1.3715	36
1.37096	36
1.37043	40
1.36989	30
1.36936	22
1.36882	28
1.36829	36
1.36776	36
1.36722	36
1.36669	30
1.36616	28
1.36563	28
1.3651	24
1.36457	28
1.36404	38
1.36351	24
1.36298	30
1.36245	36
1.36192	28
1.36139	32
1.36087	36
1.36034	34
1.35981	28
1.35929	34
1.35876	24
1.35824	34
1.35771	32
1.35719	30
1.35667	30
1.35614	28
1.35562	34
1.3551	30
1.35458	34
1.35406	34
1.35353	32
1.35301	26
1.35249	38
1.35197	28
1.35146	28
1.35094	28
1.35042	30
1.3499	20
1.34938	22
1.34887	28
1.34835	26
1.34783	30
1.34732	22
1.3468	28
1.34629	28
1.34578	30
1.34526	32
1.34475	28
1.34424	36
1.34372	36
1.34321	28
1.3427	26
1.34219	20
1.34168	36
1.34117	26
1.34066	28
1.34015	28
1.33964	30
1.33913	24
1.33862	34
1.33812	22
1.33761	28
1.3371	28.1081
1.3366	31.5633
1.33609	29.4671
1.33558	31.3962
1.33508	30.2233
1.33457	25.4475
1.33407	32.598
1.33357	31.8501
1.33306	24.2692
1.33256	25.4563
1.33206	28.8283
1.33156	38.1804
1.33105	25.6796
1.33055	27.8155
1.33005	26.5116
1.32959	32
1.32909	34
1.32859	22
1.32809	34
1.32758	24
1.32708	28
1.32658	30
1.32608	26
1.32558	28
1.32508	26
1.32458	28
1.32408	32
1.32358	32
1.32309	28
1.32259	36
1.32209	32
1.3216	22
1.3211	34
1.3206	28
1.32011	24
1.31961	28
1.31912	30
1.31862	28
1.31813	28
1.31764	34
1.31714	34
1.31665	34
1.31616	34
1.31567	22
1.31518	28
1.31468	32
1.31419	40
1.3137	34
1.31321	18
1.31272	34
1.31224	26
1.31175	34
1.31126	36
1.31077	30
1.31028	24
1.3098	36
1.30931	32
1.30882	26
1.30834	32
1.30785	28
1.30737	34
1.30688	24
1.3064	26
1.30592	30
1.30543	28
1.30495	28
1.30447	28
1.30399	26
1.3035	34
1.30302	30
1.30254	34
1.30206	32
1.30158	30
1.3011	30
1.30062	38
1.30014	26
1.30001	34