File: ploting_and_data_tools.ipynb/___archivosraman/CdSe1_16.txt
#Acq. time (s)=	1
#Accumulations=	1
#Range (eV)=	2...1
#Windows=	11
#Autofocus=	Off
#AutoExposure=	Off
#Spike filter=	Off
#Delay time (s)=	0
#Binning=	1
#Readout mode=	Signal
#DeNoise=	Off
#ICS correction=	Off
#Dark correction=	Off
#Inst. Process=	Off
#Instrument=	LabRAM HR Evol
#Detector=	Syncerity OE
#Objective=	x100_VIS_LWD
#Grating=	600 (500nm)
#ND Filter=	1%
#Laser=	442nm_Notch
#Hole=	150.001
#Range=	Visible
#Project=	Paty
#Sample=
#Site=	15-06-22
#Title=	CdSe1
#Remark=
#Date=	15.06.2022 20:51
#Acquired=	15.06.2022 20:51:26
2.74975	34
2.7475	38
2.74525	34
2.743	40
2.74076	42
2.73852	46
2.73629	40
2.73406	48
2.73183	48
2.72961	36
2.72739	42
2.72517	50
2.72296	56
2.72075	44
2.71854	40
2.71634	44
2.71414	50
2.71195	52
2.70976	50
2.70757	50
2.70539	50
2.70321	54
2.70103	54
2.69886	54
2.69669	54
2.69452	58
2.69236	66
2.6902	54
2.68805	62
2.6859	62
2.68375	68
2.68161	68
2.67947	68
2.67733	70
2.6752	70
2.67307	68
2.67094	74
2.66882	80
2.6667	70
2.66458	64
2.66247	72
2.66036	86
2.65826	82
2.65615	74
2.65405	84
2.65196	94
2.64987	90
2.64778	86
2.64569	92
2.64361	102
2.64153	94
2.63946	122
2.63739	116
2.63532	110
2.63325	112
2.63119	108
2.62913	128
2.62708	126
2.62503	136
2.62298	146
2.62094	130
2.61889	150
2.61686	152
2.61482	160
2.61279	162
2.61076	168
2.60873	188
2.60671	186
2.60469	182
2.60268	202
2.60067	222
2.59866	192
2.59665	236
2.59465	238
2.59265	268
2.59065	250
2.58866	256
2.58667	278
2.58468	322
2.5827	288
2.58072	328
2.57874	330
2.57677	368
2.5748	360
2.57283	372
2.57086	380
2.5689	382
2.56694	448
2.56499	436
2.56304	460
2.56109	488
2.55914	520
2.5572	518
2.55526	546
2.55332	600
2.55139	592
2.54946	606
2.54753	660
2.5456	658
2.54368	722
2.54176	716
2.53985	786
2.53794	824
2.53603	864
2.53412	840
2.53222	890
2.53031	982
2.52842	972
2.52652	1022
2.52463	1094
2.52274	1114
2.52085	1174
2.51897	1190
2.51709	1240
2.51521	1282
2.51334	1370
2.51147	1392
2.5096	1510
2.50773	1570
2.50587	1554
2.50401	1640
2.50216	1654
2.5003	1726
2.49845	1808
2.4966	1830
2.49476	1950
2.49291	2032
2.49107	2092
2.48924	2124
2.4874	2256
2.48557	2316
2.48374	2454
2.48192	2420.67
2.48009	2608.31
2.47827	2742.33
2.47646	2830.73
2.47464	3034.52
2.47283	3153.22
2.47102	3250.47
2.46922	3477.11
2.46741	3587.19
2.46561	3756.11
2.46381	3927.28
2.46202	4117.68
2.46023	4316.41
2.45844	4441.33
2.45665	4612.42
2.45493	4890
2.45314	4942
2.45136	5034
2.44957	5230
2.44779	5376
2.44601	5506
2.44424	5670
2.44247	5648
2.4407	5882
2.43893	6062
2.43716	6114
2.4354	6348
2.43364	6494
2.43188	6650
2.43013	6784
2.42838	6860
2.42663	6974
2.42488	7108
2.42314	7290
2.4214	7390
2.41966	7452
2.41792	7770
2.41619	7812
2.41446	7920
2.41273	8024
2.411	8174
2.40928	8310
2.40756	8302
2.40584	8502
2.40413	8682
2.40241	8786
2.4007	8960
2.39899	8984
2.39729	9018
2.39559	9204
2.39389	9324
2.39219	9384
2.39049	9452
2.3888	9412
2.38711	9528
2.38542	9626
2.38374	9724
2.38205	9712
2.38037	9806
2.37869	10070
2.37702	9940
2.37535	10134
2.37368	10112
2.37201	10148
2.37034	10278
2.36868	10224
2.36702	10098
2.36536	10212
2.3637	10130
2.36205	10108
2.3604	10150
2.35875	10072
2.3571	10022
2.35546	10024
2.35382	10004
2.35218	9828
2.35054	9760
2.34891	9738
2.34727	9734
2.34564	9606
2.34402	9600
2.34239	9480
2.34077	9422
2.33915	9352
2.33753	9220
2.33591	9220
2.3343	9088
2.33269	9032
2.33108	8960
2.32948	8894
2.32787	8710
2.32627	8628
2.32467	8542
2.32307	8438
2.32148	8472
2.31989	8226
2.3183	8106
2.31671	8132
2.31512	7946
2.31354	7838
2.31196	7892
2.31038	7716
2.3088	7686
2.30723	7528
2.30565	7502
2.30408	7490
2.30252	7394
2.30095	7124
2.29939	7158
2.29783	7080
2.29627	6972
2.29471	6940
2.29316	6794
2.29161	6794
2.29006	6856
2.28851	6750
2.28696	6624
2.28542	6532
2.28388	6416
2.28234	6470
2.2808	6366
2.27927	6310
2.27773	6220
2.2762	6160
2.27468	6076
2.27315	6042
2.27163	5820
2.27011	5904
2.26859	5862
2.26707	5902
2.26555	5682
2.26404	5648
2.26253	5622.08
2.26102	5573.79
2.25951	5445.04
2.25801	5425.6
2.25651	5335.73
2.25501	5269.8
2.25351	5199.35
2.25201	5143.48
2.25052	5089.87
2.24902	4990.75
2.24753	4930.93
2.24605	4821.32
2.24456	4813.92
2.24308	4705.65
2.2416	4623.65
2.24011	4578
2.23863	4488
2.23715	4452
2.23567	4460
2.23419	4428
2.23271	4392
2.23124	4280
2.22977	4268
2.2283	4226
2.22683	4074
2.22536	4118
2.2239	4112
2.22244	4046
2.22098	3936
2.21952	3948
2.21807	3968
2.21661	4000
2.21516	3890
2.21371	3828
2.21226	3830
2.21082	3742
2.20937	3776
2.20793	3696
2.20649	3726
2.20505	3604
2.20362	3686
2.20218	3620
2.20075	3536
2.19932	3584
2.19789	3512
2.19647	3476
2.19504	3482
2.19362	3474
2.1922	3420
2.19078	3426
2.18936	3408
2.18795	3416
2.18654	3356
2.18513	3384
2.18372	3286
2.18231	3294
2.18091	3282
2.1795	3370
2.1781	3342
2.1767	3268
2.1753	3314
2.17391	3264
2.17251	3218
2.17112	3260
2.16973	3292
2.16834	3168
2.16696	3178
2.16557	3194
2.16419	3208
2.16281	3202
2.16143	3208
2.16005	3180
2.15868	3200
2.1573	3166
2.15593	3240
2.15456	3132
2.1532	3122
2.15183	3160
2.15046	3226
2.1491	3128
2.14774	3184
2.14638	3192
2.14503	3170
2.14367	3164
2.14232	3136
2.14097	3208
2.13962	3138
2.13827	3160
2.13692	3144
2.13558	3146
2.13423	3132
2.13289	3104
2.13155	3076
2.13022	3170
2.12888	3220
2.12755	3152
2.12621	3188
2.12488	3218
2.12356	3228
2.12223	3228
2.1209	3282
2.11958	3200
2.11826	3150
2.11694	3158
2.11562	3220
2.1143	3184
2.11299	3182
2.11168	3204
2.11037	3212
2.10906	3218
2.10775	3224
2.10644	3238
2.10514	3194
2.10384	3262
2.10253	3224
2.10123	3198
2.09994	3244
2.09864	3218
2.09735	3266
2.09605	3290
2.09476	3308
2.09347	3160
2.09219	3246
2.0909	3180
2.08962	3186
2.08834	3286
2.08705	3236
2.08578	3186
2.0845	3230
2.08322	3284
2.08195	3170
2.08068	3248
2.0794	3307.11
2.07814	3240.38
2.07687	3182.11
2.0756	3065.31
2.07434	3109.67
2.07307	3048.06
2.07181	3127.18
2.07055	3044.06
2.0693	3032.95
2.06804	2999.92
2.06679	2993.6
2.06553	2955.23
2.06428	2946.88
2.06303	2910.21
2.06178	2960.07
2.06069	2926
2.05944	2936
2.05819	2880
2.05694	2918
2.05569	2986
2.05445	3048
2.05321	2948
2.05196	2924
2.05072	2874
2.04949	2932
2.04825	2984
2.04701	2882
2.04578	2886
2.04455	2930
2.04332	2802
2.04209	2822
2.04086	2798
2.03964	2858
2.03841	2938
2.03719	2862
2.03597	2804
2.03475	2810
2.03353	2850
2.03232	2828
2.0311	2908
2.02989	2858
2.02868	2812
2.02747	2878
2.02626	2848
2.02505	2842
2.02384	2940
2.02264	2876
2.02144	2916
2.02024	2860
2.01904	2906
2.01784	2866
2.01664	2890
2.01544	2998
2.01425	2884
2.01306	2968
2.01187	2970
2.01068	2912
2.00949	2972
2.0083	2980
2.00712	3050
2.00594	2980
2.00475	3040
2.00357	2990
2.0024	3060
2.00122	3012
2.00004	3032
1.99887	3084
1.99769	3138
1.99652	3076
1.99535	3130
1.99418	3082
1.99302	3116
1.99185	3118
1.99069	3238
1.98952	3102
1.98836	3184
1.9872	3236
1.98604	3238
1.98488	3214
1.98373	3236
1.98257	3268
1.98142	3228
1.98027	3136
1.97912	3250
1.97797	3290
1.97682	3248
1.97568	3260
1.97453	3292
1.97339	3348
1.97225	3294
1.97111	3264
1.96997	3288
1.96883	3334
1.9677	3384
1.96656	3348
1.96543	3324
1.9643	3368
1.96316	3328
1.96204	3316
1.96091	3278
1.95978	3362
1.95866	3376
1.95753	3392
1.95641	3382
1.95529	3388
1.95417	3392
1.95305	3392
1.95193	3394
1.95082	3400
1.9497	3412
1.94859	3366
1.94748	3338
1.94637	3468
1.94526	3444
1.94415	3384
1.94305	3436
1.94194	3384
1.94084	3354
1.93974	3472
1.93864	3428
1.93754	3422
1.93644	3478
1.93534	3414
1.93425	3466
1.93315	3426
1.93206	3420
1.93097	3438
1.92988	3458
1.92879	3412
1.9277	3382
1.92662	3410
1.92553	3480
1.92445	3437.22
1.92337	3397.22
1.92228	3420.23
1.92121	3399.98
1.92013	3398.32
1.91905	3411.81
1.91797	3387.02
1.9169	3384.33
1.91583	3358
1.91475	3299.54
1.91368	3405.79
1.91261	3338.71
1.91155	3360.2
1.91048	3356.9
1.90946	3308
1.90839	3342
1.90732	3352
1.90626	3320
1.90519	3352
1.90413	3384
1.90306	3286
1.902	3344
1.90094	3318
1.89988	3400
1.89882	3302
1.89777	3428
1.89671	3314
1.89566	3320
1.8946	3348
1.89355	3312
1.8925	3304
1.89145	3288
1.8904	3328
1.88936	3310
1.88831	3304
1.88727	3284
1.88622	3286
1.88518	3298
1.88414	3328
1.8831	3336
1.88206	3278
1.88102	3270
1.87999	3256
1.87895	3244
1.87792	3292
1.87689	3302
1.87586	3296
1.87483	3300
1.8738	3270
1.87277	3230
1.87174	3244
1.87072	3270
1.86969	3292
1.86867	3162
1.86765	3162
1.86663	3186
1.86561	3198
1.86459	3244
1.86357	3196
1.86256	3250
1.86154	3186
1.86053	3234
1.85952	3170
1.85851	3176
1.8575	3146
1.85649	3132
1.85548	3102
1.85447	3142
1.85347	3204
1.85247	3142
1.85146	3130
1.85046	3154
1.84946	3110
1.84846	3258
1.84746	3042
1.84646	3100
1.84547	3140
1.84447	3186
1.84348	3130
1.84249	3120
1.8415	3078
1.84051	3088
1.83952	3062
1.83853	3120
1.83754	3122
1.83656	3096
1.83557	3032
1.83459	3066
1.83361	3030
1.83262	3094
1.83164	3012
1.83066	3028
1.82969	3050
1.82871	3032
1.82773	3036
1.82676	2966
1.82579	2992
1.82481	2964
1.82384	3048
1.82287	2990
1.8219	3018
1.82094	3014
1.81997	3010
1.819	2906
1.81804	3016
1.81708	2910
1.81611	2938
1.81515	2992
1.81419	2924
1.81323	2884
1.81227	3032
1.81132	2906
1.81036	2860
1.80941	2892
1.80845	2976
1.8075	2884
1.80655	2828
1.8056	2870
1.80465	2856
1.8037	2908
1.80275	2888
1.80181	2850
1.80086	2858
1.79992	2840
1.79897	2812
1.79803	2858
1.79709	2876
1.79615	2828
1.79521	2882
1.79428	2820
1.79334	2766
1.7924	2806
1.79147	2763.41
1.79053	2746.35
1.7896	2764.29
1.78867	2737.52
1.78774	2719.29
1.78681	2691.15
1.78588	2644.55
1.78496	2662.66
1.78403	2646.14
1.7831	2656.8
1.78218	2596.9
1.78126	2613.68
1.78033	2597.41
1.77941	2580.49
1.77851	2488
1.77759	2500
1.77667	2510
1.77575	2548
1.77483	2576
1.77391	2480
1.77299	2532
1.77207	2506
1.77115	2460
1.77024	2478
1.76932	2474
1.76841	2428
1.7675	2448
1.76659	2422
1.76568	2398
1.76477	2414
1.76386	2404
1.76295	2446
1.76204	2368
1.76114	2398
1.76023	2372
1.75933	2356
1.75843	2344
1.75753	2342
1.75662	2328
1.75572	2292
1.75483	2326
1.75393	2312
1.75303	2308
1.75214	2310
1.75124	2294
1.75035	2316
1.74945	2278
1.74856	2258
1.74767	2206
1.74678	2254
1.74589	2186
1.74501	2178
1.74412	2146
1.74323	2194
1.74235	2162
1.74146	2186
1.74058	2102
1.7397	2136
1.73882	2080
1.73794	2160
1.73706	2122
1.73618	2122
1.7353	2102
1.73443	2106
1.73355	2070
1.73268	2104
1.7318	2052
1.73093	2084
1.73006	2018
1.72919	1982
1.72832	2004
1.72745	1966
1.72658	1942
1.72571	1902
1.72485	1954
1.72398	1894
1.72312	1884
1.72225	1902
1.72139	1908
1.72053	1890
1.71967	1864
1.71881	1856
1.71795	1834
1.71709	1812
1.71624	1894
1.71538	1836
1.71453	1828
1.71367	1836
1.71282	1862
1.71197	1802
1.71112	1808
1.71027	1760
1.70942	1756
1.70857	1742
1.70772	1752
1.70687	1758
1.70603	1694
1.70518	1680
1.70434	1730
1.7035	1706
1.70265	1718
1.70181	1678
1.70097	1648
1.70013	1674
1.69929	1640
1.69846	1566
1.69762	1614
1.69678	1554
1.69595	1594
1.69511	1596
1.69428	1586
1.69345	1590
1.69262	1482
1.69179	1556
1.69096	1480
1.69013	1506
1.6893	1464
1.68847	1414
1.68765	1416
1.68682	1438
1.686	1418
1.68517	1442
1.68435	1424
1.68353	1336
1.68271	1430
1.68189	1392
1.68107	1350
1.68025	1396
1.67943	1434
1.67861	1348
1.6778	1380
1.67698	1388.17
1.67617	1374.69
1.67536	1414.75
1.67454	1347.04
1.67373	1351.14
1.67292	1327.17
1.67211	1380.67
1.6713	1358.01
1.6705	1323.62
1.66969	1349.14
1.66888	1327.31
1.66808	1328.58
1.66727	1304.51
1.66647	1313.73
1.66566	1266.42
1.6649	1304
1.66409	1308
1.66329	1314
1.66249	1324
1.66168	1256
1.66088	1262
1.66008	1250
1.65928	1246
1.65848	1248
1.65768	1230
1.65688	1248
1.65608	1200
1.65529	1200
1.65449	1224
1.6537	1186
1.6529	1194
1.65211	1166
1.65132	1182
1.65053	1150
1.64973	1150
1.64894	1146
1.64816	1134
1.64737	1094
1.64658	1136
1.64579	1168
1.64501	1134
1.64422	1094
1.64344	1128
1.64265	1074
1.64187	1124
1.64109	1130
1.64031	1066
1.63953	1070
1.63875	1064
1.63797	1066
1.63719	1044
1.63642	1058
1.63564	1078
1.63486	1044
1.63409	1016
1.63331	996
1.63254	976
1.63177	962
1.631	994
1.63023	956
1.62946	974
1.62869	972
1.62792	1004
1.62715	966
1.62639	964
1.62562	942
1.62485	950
1.62409	954
1.62333	930
1.62256	938
1.6218	936
1.62104	894
1.62028	926
1.61952	904
1.61876	894
1.618	896
1.61724	866
1.61649	886
1.61573	882
1.61498	846
1.61422	806
1.61347	844
1.61271	852
1.61196	810
1.61121	800
1.61046	804
1.60971	844
1.60896	800
1.60821	776
1.60747	796
1.60672	804
1.60597	768
1.60523	782
1.60448	742
1.60374	794
1.603	792
1.60225	760
1.60151	740
1.60077	740
1.60003	740
1.59929	728
1.59855	740
1.59782	728
1.59708	718
1.59634	724
1.59561	702
1.59487	706
1.59414	686
1.5934	666
1.59267	668
1.59194	666
1.59121	648
1.59048	646
1.58975	688
1.58902	660
1.58829	616
1.58756	638
1.58684	628
1.58611	642
1.58538	628
1.58466	646
1.58394	624
1.58321	586
1.58249	596
1.58177	588
1.58105	592
1.58033	608
1.57961	618
1.57889	588
1.57817	582
1.57745	582
1.57674	570
1.57602	555.784
1.5753	539.291
1.57459	577.213
1.57388	536.15
1.57316	532.812
1.57245	519.226
1.57174	502.09
1.57103	491.954
1.57032	482.853
1.56961	504.705
1.5689	501.683
1.56819	474.885
1.56748	487.953
1.56678	466.225
1.56607	463.328
1.56544	442
1.56473	452
1.56402	424
1.56331	438
1.56261	454
1.5619	434
1.56119	416
1.56049	414
1.55979	432
1.55908	436
1.55838	404
1.55768	406
1.55698	422
1.55628	402
1.55558	410
1.55488	414
1.55418	398
1.55348	416
1.55278	380
1.55209	388
1.55139	386
1.5507	372
1.55	378
1.54931	382
1.54862	372
1.54792	368
1.54723	376
1.54654	352
1.54585	380
1.54516	352
1.54447	342
1.54378	366
1.5431	366
1.54241	340
1.54172	336
1.54104	336
1.54035	340
1.53967	336
1.53898	346
1.5383	318
1.53762	318
1.53694	344
1.53626	332
1.53558	336
1.5349	308
1.53422	304
1.53354	326
1.53286	320
1.53218	292
1.53151	318
1.53083	296
1.53016	302
1.52948	298
1.52881	308
1.52813	312
1.52746	288
1.52679	302
1.52612	294
1.52545	276
1.52478	276
1.52411	284
1.52344	278
1.52277	280
1.5221	292
1.52144	286
1.52077	276
1.52011	272
1.51944	304
1.51878	292
1.51811	246
1.51745	258
1.51679	264
1.51613	232
1.51547	272
1.51481	252
1.51415	270
1.51349	274
1.51283	254
1.51217	252
1.51151	254
1.51086	252
1.5102	250
1.50954	230
1.50889	224
1.50824	246
1.50758	262
1.50693	242
1.50628	230
1.50563	224
1.50497	224
1.50432	210
1.50367	232
1.50302	226
1.50238	252
1.50173	216
1.50108	236
1.50043	224
1.49979	226
1.49914	196
1.4985	206
1.49785	184
1.49721	210
1.49657	218
1.49592	212
1.49528	218
1.49464	198
1.494	216
1.49336	212
1.49272	192
1.49208	186
1.49144	196
1.49081	180
1.49017	188
1.48953	200
1.4889	188
1.48826	186
1.48763	184
1.48699	181.941
1.48636	194.024
1.48573	170.629
1.4851	180.479
1.48446	175.212
1.48383	178.753
1.4832	178.25
1.48257	168.933
1.48194	157.743
1.48132	156.842
1.48069	157.537
1.48006	160.62
1.47943	155.896
1.47881	161.019
1.47818	154.409
1.47756	160
1.47694	148
1.47631	130
1.47568	124
1.47505	128
1.47443	148
1.4738	144
1.47318	152
1.47256	148
1.47193	146
1.47131	142
1.47069	118
1.47006	112
1.46944	110
1.46882	122
1.4682	138
1.46758	144
1.46696	142
1.46635	122
1.46573	112
1.46511	102
1.46449	98
1.46388	82
1.46326	106
1.46265	110
1.46203	130
1.46142	112
1.46081	106
1.46019	90
1.45958	72
1.45897	70
1.45836	82
1.45775	88
1.45714	108
1.45653	106
1.45592	78
1.45531	68
1.4547	54
1.4541	56
1.45349	64
1.45288	66
1.45228	62
1.45167	50
1.45107	40
1.45047	24
1.44986	36
1.44926	30
1.44866	32
1.44806	32
1.44746	34
1.44686	32
1.44626	30
1.44566	30
1.44506	30
1.44446	26
1.44386	20
1.44326	34
1.44267	30
1.44207	20
1.44148	34
1.44088	22
1.44029	30
1.43969	26
1.4391	20
1.43851	26
1.43791	38
1.43732	30
1.43673	32
1.43614	26
1.43555	28
1.43496	28
1.43437	26
1.43378	26
1.4332	34
1.43261	30
1.43202	32
1.43143	22
1.43085	26
1.43026	24
1.42968	24
1.42909	30
1.42851	28
1.42793	26
1.42734	30
1.42676	32
1.42618	30
1.4256	30
1.42502	26
1.42444	28
1.42386	30
1.42328	32
1.4227	28
1.42212	34
1.42155	30
1.42097	26
1.42039	24
1.41982	28
1.41924	28
1.41867	22
1.41809	30
1.41752	28
1.41695	24
1.41637	30
1.4158	26
1.41523	32
1.41466	26
1.41409	24
1.41352	16
1.41295	30
1.41238	24
1.41181	34
1.41124	30
1.41067	28
1.41011	34
1.40954	40
1.40897	48
1.40841	48
1.40784	51.9488
1.40728	42.297
1.40672	56.5609
1.40615	58.3797
1.40559	64.3009
1.40503	83.4223
1.40446	167.194
1.4039	72.5128
1.40334	75.687
1.40278	62.5411
1.40222	65.611
1.40166	77.5125
1.4011	77.5867
1.40054	78.6743
1.39999	69.2146
1.39947	76
1.3989	76
1.39834	78
1.39779	80
1.39723	76
1.39667	72
1.39611	70
1.39555	72
1.395	70
1.39444	86
1.39388	82
1.39333	80
1.39277	80
1.39222	78
1.39166	82
1.39111	72
1.39056	84
1.39	66
1.38945	70
1.3889	78
1.38835	72
1.3878	76
1.38725	76
1.3867	64
1.38615	78
1.3856	80
1.38505	66
1.3845	68
1.38396	70
1.38341	82
1.38286	70
1.38232	62
1.38177	70
1.38123	70
1.38068	76
1.38014	70
1.3796	74
1.37905	70
1.37851	68
1.37797	68
1.37743	70
1.37688	62
1.37634	62
1.3758	58
1.37526	68
1.37472	82
1.37419	72
1.37365	68
1.37311	74
1.37257	74
1.37204	60
1.3715	64
1.37096	62
1.37043	62
1.36989	60
1.36936	58
1.36882	68
1.36829	64
1.36776	68
1.36722	64
1.36669	66
1.36616	66
1.36563	54
1.3651	54
1.36457	66
1.36404	64
1.36351	66
1.36298	68
1.36245	62
1.36192	64
1.36139	62
1.36087	68
1.36034	56
1.35981	76
1.35929	58
1.35876	58
1.35824	60
1.35771	56
1.35719	62
1.35667	56
1.35614	64
1.35562	58
1.3551	60
1.35458	52
1.35406	48
1.35353	58
1.35301	68
1.35249	64
1.35197	62
1.35146	64
1.35094	52
1.35042	58
1.3499	56
1.34938	46
1.34887	56
1.34835	66
1.34783	56
1.34732	40
1.3468	56
1.34629	56
1.34578	46
1.34526	52
1.34475	56
1.34424	52
1.34372	56
1.34321	54
1.3427	44
1.34219	54
1.34168	52
1.34117	60
1.34066	48
1.34015	54
1.33964	48
1.33913	66
1.33862	50
1.33812	46
1.33761	50
1.3371	42.1237
1.3366	57.6801
1.33609	51.982
1.33558	51.2621
1.33508	49.1047
1.33457	63.0698
1.33407	53.701
1.33357	49.7751
1.33306	42.3986
1.33256	50.6712
1.33206	49.4205
1.33156	47.9632
1.33105	39.9223
1.33055	51.3626
1.33005	48.366
1.32959	60
1.32909	40
1.32859	50
1.32809	46
1.32758	48
1.32708	48
1.32658	40
1.32608	52
1.32558	44
1.32508	42
1.32458	46
1.32408	38
1.32358	48
1.32309	46
1.32259	50
1.32209	50
1.3216	44
1.3211	48
1.3206	58
1.32011	50
1.31961	52
1.31912	52
1.31862	42
1.31813	46
1.31764	52
1.31714	46
1.31665	46
1.31616	44
1.31567	52
1.31518	48
1.31468	40
1.31419	48
1.3137	40
1.31321	40
1.31272	50
1.31224	46
1.31175	50
1.31126	46
1.31077	58
1.31028	48
1.3098	42
1.30931	44
1.30882	44
1.30834	50
1.30785	46
1.30737	46
1.30688	44
1.3064	40
1.30592	46
1.30543	46
1.30495	48
1.30447	48
1.30399	42
1.3035	52
1.30302	58
1.30254	52
1.30206	58
1.30158	46
1.3011	48
1.30062	48
1.30014	52
1.30001	48