File: DataDrivenSE/datosramanb/CN-Sastre_15.txt
#Acq. time (s)=	20
#Accumulations=	2
#Range (cm-¹)=	50...4000
#Windows=	3
#Autofocus=	Off
#AutoExposure=	Off
#Spike filter=	Multiple accum.
#Delay time (s)=	0
#Binning=	1
#Readout mode=	Signal
#DeNoise=	Off
#ICS correction=	Off
#Dark correction=	Off
#Inst. Process=	Off
#Instrument=	LabRAM HR Evol
#Detector=	Syncerity OE
#Objective=	x100_VIS
#Grating=	600 (500nm)
#ND Filter=	100%
#Laser=	532nm_Edge
#Hole=	100.021
#Range=	Visible
#Project=	Omar
#Sample=
#Site=	21-09-22
#Title=	 CN-Sastre
#Remark=
#Date=	21.09.2022 13:55
#Acquired=	21.09.2022 13:55:11
51.0918	38
54.7807	48
58.4681	80
62.154	180
65.8385	308
69.5216	462
73.2032	780
76.8834	1048
80.5621	1304
84.2393	1528
87.9152	1686
91.5874	1770
95.2603	1736
98.9318	1732
102.602	1752
106.27	1792
109.936	1760
113.601	1798
117.266	1814
120.926	1802
124.588	1814
128.246	1744
131.904	1706
135.561	1700
139.215	1748
142.869	1728
146.52	1698
150.171	1736
153.819	1664
157.465	1714
161.112	1686
164.756	1692
168.398	1632
172.041	1688
175.68	1698
179.318	1612
182.955	1616
186.592	1648
190.225	1606
193.857	1594
197.488	1604
201.118	1606
204.746	1606
208.372	1580
211.997	1560
215.621	1564
219.243	1568
222.864	1572
226.483	1578
230.101	1526
233.718	1570
237.331	1522
240.945	1516
244.557	1554
248.168	1570
251.776	1538
255.384	1580
258.991	1568
262.594	1554
266.198	1532
269.799	1544
273.4	1558
277	1560
280.596	1560
284.193	1524
287.786	1550
291.378	1570
294.971	1536
298.561	1538
302.148	1564
305.737	1550
309.322	1574
312.906	1570
316.49	1624
320.071	1594
323.651	1624
327.229	1616
330.806	1588
334.381	1612
337.955	1606
341.528	1584
345.099	1594
348.669	1616
352.238	1558
355.805	1610
359.371	1630
362.935	1620
366.498	1640
370.06	1590
373.62	1638
377.177	1642
380.734	1648
384.29	1662
387.845	1672
391.396	1680
394.948	1648
398.499	1642
402.046	1660
405.594	1650
409.138	1630
412.683	1602
416.225	1656
419.768	1652
423.307	1604
426.844	1630
430.382	1622
433.917	1634
437.451	1642
440.985	1662
444.516	1664
448.045	1692
451.574	1682
455.102	1698
458.628	1658
462.152	1656
465.674	1682
469.196	1620
472.716	1656
476.234	1636
479.752	1656
483.268	1664
486.782	1632
490.295	1604
493.807	1562
497.316	1590
500.825	1562
504.333	1602
507.839	1592
511.344	1546
514.846	1584
518.349	1608
521.85	1650
525.347	1686
528.846	1708
532.341	1804
535.837	1860
539.329	1954
542.822	2068
546.312	2118
549.802	2126
553.289	2218
556.775	2176
560.261	2212
563.744	2202
567.226	2154
570.709	2194
574.188	2112
577.665	2064
581.142	2020
584.617	1940
588.091	1938
591.565	1906
595.036	1850
598.506	1806
601.974	1752
605.442	1726
608.905	1682
612.37	1684
615.833	1678
619.295	1596
622.755	1578
626.215	1558
629.67	1536
633.127	1544
636.582	1486
640.036	1464
643.487	1420
646.938	1436
650.386	1366
653.835	1332
657.282	1294
660.726	1288
664.171	1232
667.613	1222
671.053	1180
674.494	1182
677.931	1128
681.369	1086
684.804	1094
688.238	1072
691.67	1050
695.103	990
698.533	1020
701.961	996
705.389	954
708.814	946
712.239	880
715.662	956
719.084	898
722.505	884
725.924	908
729.342	896
732.759	860
736.174	868
739.589	888
742.999	852
746.411	868
749.821	878
753.23	884
756.636	888
760.043	904
763.448	898
766.85	912
770.252	926
773.652	954
777.052	916
780.448	916
783.846	946
787.24	934
790.635	896
794.027	900
797.417	910
800.808	884
804.196	908
807.582	870
810.968	850
814.354	828
817.736	834
821.118	806
824.498	766
827.877	754
831.254	740
834.631	720
838.006	732
841.38	698
844.752	706
848.123	710
851.493	698
854.86	678
858.228	670
861.594	680
864.959	688
868.321	700
871.683	692
875.044	692
878.402	688
881.761	666
885.116	682
888.472	710
891.825	688
895.179	706
898.529	752
901.88	730
905.228	744
908.575	774
911.922	788
915.266	808
918.609	828
921.951	838
925.293	890
928.633	904
931.97	908
935.307	936
938.642	948
941.977	898
945.31	1006
948.641	1022
951.972	980
955.301	1004
958.629	1018
961.955	982
965.279	972
968.603	1020
971.926	994
975.248	982
978.566	1036
981.886	1056
985.204	1062
988.519	1062
991.834	1074
995.147	1110
998.46	1090
1001.77	1142
1005.08	1144
1008.39	1178
1011.7	1156
1015	1198
1018.3	1228
1021.61	1264
1024.91	1294
1028.21	1310
1031.51	1322
1034.81	1396
1038.1	1404
1041.4	1444
1044.69	1482
1047.99	1556
1051.28	1546
1054.57	1608
1057.86	1636
1061.14	1694
1064.43	1740
1067.72	1806
1071	1814
1074.28	1954
1077.57	1980
1080.84	2026
1084.12	2056
1087.4	2122
1090.68	2138
1093.95	2134
1097.22	2114
1100.5	2116
1103.77	2036
1107.04	2004
1110.31	1898
1113.58	1850
1116.84	1814
1120.1	1734
1123.37	1672
1126.63	1564
1129.89	1544
1133.15	1488
1136.41	1372
1139.67	1346
1142.92	1278
1146.18	1286
1149.43	1254
1152.68	1202
1155.93	1174
1159.18	1112
1162.43	1122
1165.68	1050
1168.93	1032
1172.17	1010
1175.41	966
1178.66	968
1181.9	906
1185.14	926
1188.37	878
1191.61	858
1194.85	840
1198.08	828
1201.31	792
1204.55	750
1207.78	760
1211.01	716
1214.24	702
1217.46	716
1220.69	684
1223.91	692
1227.14	670
1230.36	636
1233.58	662
1236.8	640
1240.02	646
1243.23	620
1246.45	652
1249.67	622
1252.88	652
1256.09	624
1259.3	676
1262.51	630
1265.72	616
1268.93	648
1272.13	644
1275.34	642
1278.54	640
1281.74	612
1284.94	606
1288.15	642
1291.34	632
1294.54	626
1297.74	648
1300.93	644
1304.12	646
1307.32	654
1310.51	616
1313.7	656
1316.89	618
1320.07	660
1323.26	630
1326.45	646
1329.63	668
1332.81	670
1335.99	668
1339.17	652
1342.35	668
1345.53	650
1348.71	660
1351.88	660
1355.06	680
1358.23	666
1361.4	664
1364.57	646
1367.74	664
1370.91	646
1374.08	632
1377.24	642
1380.41	628
1383.57	622
1386.73	658
1389.89	632
1393.05	670
1396.21	648
1399.37	664
1402.52	658
1405.68	652
1408.83	644
1411.98	678
1415.13	664
1418.29	654
1421.43	648
1424.58	640
1427.73	656
1430.87	672
1434.02	650
1437.16	664
1440.3	628
1443.44	650
1446.58	644
1449.72	676
1452.85	672
1455.99	626
1459.12	642
1462.26	682
1465.39	676
1468.52	628
1471.65	660
1474.78	632
1477.9	662
1481.03	650
1484.16	662
1487.28	662
1490.4	636
1493.52	694
1496.64	676
1499.76	662
1502.88	622
1506	682
1509.11	696
1512.22	682
1515.34	690
1518.45	682
1521.56	640
1524.67	662
1527.78	702
1530.88	660
1533.99	688
1537.09	688
1540.2	680
1543.3	664
1546.4	698
1549.5	652
1552.6	688
1555.7	712
1558.79	668
1561.89	702
1564.98	676
1568.08	684
1571.17	684
1574.26	680
1577.35	698
1580.43	664
1583.52	672
1586.61	700
1589.69	694
1592.77	652
1595.86	712
1598.94	688
1602.02	680
1605.1	650
1608.18	652.72
1611.25	668.597
1614.33	706.26
1617.4	627.211
1620.47	674.931
1623.55	667.671
1626.62	645.491
1629.69	623.572
1632.75	677.855
1635.82	675.406
1638.89	629.222
1641.95	664.923
1645.02	647.133
1648.08	647.801
1651.14	648.739
1654.2	650.019
1657.26	654.802
1660.32	653.475
1663.37	652.534
1666.43	661.225
1669.48	658.802
1672.54	672.75
1675.59	658.859
1678.64	629.141
1681.69	629.594
1684.74	648.087
1687.79	645.405
1690.83	651.919
1693.88	637.659
1696.92	623.818
1699.96	619.268
1703.01	627.649
1706.05	642.992
1709.09	592.662
1712.12	640.669
1715.16	626.46
1718.2	635.69
1721.23	627.588
1724.27	630.907
1727.3	608.622
1730.33	622.73
1733.36	606.369
1736.39	605.02
1739.42	596.945
1742.44	617.591
1745.47	610.556
1748.49	588.098
1751.52	605.871
1754.54	586.998
1757.56	620.288
1759.14	574
1762.18	568
1765.21	576
1768.24	574
1771.27	586
1774.3	590
1777.32	586
1780.35	594
1783.38	618
1786.4	592
1789.42	616
1792.44	588
1795.47	572
1798.48	596
1801.5	606
1804.52	558
1807.54	598
1810.55	588
1813.57	604
1816.58	596
1819.59	598
1822.6	592
1825.61	602
1828.62	600
1831.63	602
1834.63	572
1837.64	590
1840.64	598
1843.64	622
1846.64	602
1849.64	578
1852.64	600
1855.64	590
1858.64	612
1861.64	592
1864.63	578
1867.63	598
1870.62	598
1873.61	596
1876.6	582
1879.59	608
1882.58	622
1885.56	620
1888.55	598
1891.54	618
1894.52	614
1897.5	588
1900.48	610
1903.46	606
1906.44	606
1909.42	598
1912.4	610
1915.38	608
1918.35	608
1921.32	620
1924.3	622
1927.27	612
1930.24	592
1933.21	604
1936.18	590
1939.15	616
1942.11	600
1945.08	608
1948.04	582
1951	624
1953.97	594
1956.93	604
1959.89	576
1962.85	602
1965.8	622
1968.76	598
1971.71	622
1974.67	592
1977.62	616
1980.57	612
1983.53	608
1986.48	608
1989.42	614
1992.37	584
1995.32	618
1998.26	592
2001.21	584
2004.15	610
2007.09	584
2010.03	610
2012.98	588
2015.92	620
2018.85	598
2021.79	604
2024.73	604
2027.66	630
2030.59	642
2033.53	604
2036.46	608
2039.39	608
2042.32	616
2045.25	616
2048.17	598
2051.1	588
2054.02	604
2056.95	590
2059.87	628
2062.79	616
2065.71	600
2068.63	614
2071.55	614
2074.47	632
2077.39	616
2080.3	638
2083.22	618
2086.13	612
2089.04	600
2091.95	588
2094.86	638
2097.77	620
2100.68	606
2103.59	610
2106.49	634
2109.4	602
2112.3	606
2115.21	608
2118.11	604
2121.01	620
2123.91	600
2126.8	596
2129.7	636
2132.6	606
2135.49	632
2138.39	610
2141.28	608
2144.17	666
2147.06	602
2149.95	622
2152.84	604
2155.73	626
2158.62	634
2161.5	624
2164.39	632
2167.27	628
2170.15	610
2173.04	640
2175.92	640
2178.79	616
2181.67	634
2184.55	618
2187.43	638
2190.3	640
2193.18	600
2196.05	616
2198.92	598
2201.79	590
2204.66	604
2207.53	630
2210.4	620
2213.27	624
2216.13	570
2219	576
2221.86	620
2224.72	622
2227.59	614
2230.45	556
2233.31	590
2236.16	610
2239.02	620
2241.88	584
2244.73	630
2247.59	612
2250.44	618
2253.29	616
2256.15	606
2259	592
2261.84	572
2264.69	592
2267.54	608
2270.39	630
2273.23	610
2276.07	604
2278.92	616
2281.76	604
2284.6	608
2287.44	614
2290.28	600
2293.12	612
2295.95	642
2298.79	674
2301.62	634
2304.46	610
2307.29	606
2310.12	620
2312.95	644
2315.78	674
2318.61	658
2321.44	640
2324.27	666
2327.09	712
2329.92	712
2332.74	642
2335.56	710
2338.38	652
2341.2	688
2344.02	664
2346.84	680
2349.66	688
2352.48	702
2355.29	678
2358.11	694
2360.92	712
2363.73	720
2366.54	722
2369.35	712
2372.16	714
2374.97	750
2377.78	708
2380.58	732
2383.39	736
2386.19	718
2389	728
2391.8	722
2394.6	746
2397.4	738
2400.2	732
2403	742
2405.79	758
2408.59	780
2411.38	774
2414.18	788
2416.97	754
2419.76	770
2422.55	756
2425.34	760
2428.13	762
2430.92	776
2433.71	792
2436.49	762
2439.28	810
2442.06	802
2444.85	776
2447.63	770
2450.41	774
2453.19	784
2455.97	816
2458.75	772
2461.52	776
2464.3	790
2467.07	798
2469.85	748
2472.62	754
2475.39	774
2478.16	772
2480.94	738
2483.7	782
2486.47	788
2489.24	768
2492	776
2494.77	776
2497.53	770
2500.3	804
2503.06	796
2505.82	756
2508.58	794
2511.34	766
2514.1	794
2516.85	758
2519.61	792
2522.37	748
2525.12	756
2527.87	776
2530.63	766
2533.38	766
2536.13	778
2538.88	784
2541.62	782
2544.37	778
2547.12	766
2549.86	776
2552.61	774
2555.35	752
2558.09	760
2560.84	784
2563.57	774
2566.32	776
2569.05	792
2571.79	784
2574.53	762
2577.26	764
2580	792
2582.73	728
2585.46	790
2588.19	788
2590.93	776
2593.66	740
2596.39	802
2599.11	786
2601.84	792
2604.56	784
2607.29	788
2610.01	798
2612.74	776
2615.46	794
2618.18	802
2620.9	818
2623.62	814
2626.34	820
2629.05	788
2631.77	790
2634.48	800
2637.2	836
2639.91	810
2642.62	816
2645.33	802
2648.05	794
2650.75	822
2653.46	808
2656.17	832
2658.88	832
2661.58	820
2664.29	834
2666.99	828
2669.69	844
2672.39	788
2675.09	822
2677.79	836
2680.49	828
2683.19	838
2685.89	804
2688.58	800
2691.28	782
2693.97	808
2696.67	828
2699.36	830
2702.05	836
2704.74	828
2707.43	788
2710.12	816
2712.8	838
2715.49	826
2718.17	782
2720.86	830
2723.54	822
2726.22	838
2728.91	858
2731.59	816
2734.27	842
2736.95	848
2739.62	850
2742.3	856
2744.98	836
2747.65	858
2750.33	860
2753	830
2755.67	844
2758.34	846
2761.01	882
2763.68	848
2766.35	864
2769.02	820
2771.68	854
2774.35	872
2777.01	866
2779.68	878
2782.34	894
2785	878
2787.66	882
2790.32	898
2792.98	866
2795.64	846
2798.3	876
2800.95	884
2803.61	908
2806.26	886
2808.91	912
2811.57	886
2814.22	938
2816.87	900
2819.52	882
2822.17	880
2824.81	918
2827.46	882
2830.11	898
2832.75	936
2835.39	890
2838.04	962
2840.68	902
2843.32	922
2845.96	934
2848.6	948
2851.24	920
2853.88	892
2856.51	928
2859.15	970
2861.78	962
2864.42	952
2867.05	948
2869.68	932
2872.31	922
2874.94	952
2877.57	924
2880.2	944
2882.82	968
2885.45	978
2888.08	968
2890.7	980
2893.33	966
2895.95	950
2898.57	984
2901.19	932
2903.81	982
2906.43	972
2909.05	978
2911.66	1002
2914.28	998
2916.89	996
2919.51	964.384
2922.12	1004.46
2924.73	968.033
2927.35	1002.02
2929.96	1002.93
2932.57	974.384
2935.17	1004.56
2937.78	984.813
2940.39	986.434
2943	995.748
2945.6	998.683
2948.2	1023.39
2950.81	974.151
2953.41	997.773
2956.01	1024.43
2958.61	992.81
2961.21	1027.05
2963.81	1024.63
2966.41	1043.12
2969.01	1048.18
2971.6	1041.06
2974.2	1045.41
2976.79	1034.29
2979.39	1024.58
2981.98	1048.84
2984.57	1059.17
2987.16	1054.67
2989.75	1051.3
2992.34	1063
2994.93	1080.98
2997.51	1052.58
3000.1	1075.4
3002.68	1075.47
3005.27	1073.27
3007.85	1058.15
3010.43	1062.54
3013.01	1091.41
3015.59	1105.43
3018.18	1094.41
3020.75	1115.97
3023.33	1099.89
3025.91	1085.08
3028.48	1099.9
3031.06	1099.57
3033.64	1121.9
3036.21	1089.98
3038.78	1089.94
3041.35	1119.57
3043.92	1104.24
3046.49	1128.37
3048.11	1114
3050.69	1140
3053.27	1174
3055.85	1116
3058.43	1116
3061.01	1140
3063.58	1146
3066.16	1144
3068.73	1138
3071.31	1136
3073.88	1166
3076.45	1134
3079.02	1178
3081.59	1176
3084.16	1164
3086.73	1172
3089.29	1186
3091.86	1126
3094.43	1174
3096.99	1162
3099.55	1190
3102.12	1188
3104.68	1186
3107.24	1234
3109.8	1214
3112.36	1220
3114.92	1228
3117.48	1204
3120.03	1148
3122.59	1238
3125.14	1242
3127.7	1278
3130.25	1232
3132.8	1234
3135.35	1268
3137.9	1254
3140.45	1252
3143	1282
3145.55	1274
3148.1	1288
3150.64	1254
3153.19	1290
3155.73	1264
3158.28	1274
3160.82	1304
3163.36	1276
3165.9	1290
3168.44	1290
3170.98	1298
3173.52	1344
3176.06	1300
3178.59	1302
3181.13	1252
3183.66	1284
3186.2	1322
3188.73	1346
3191.26	1346
3193.79	1318
3196.32	1332
3198.85	1302
3201.38	1332
3203.91	1344
3206.44	1306
3208.96	1354
3211.49	1348
3214.01	1362
3216.54	1378
3219.06	1342
3221.58	1342
3224.1	1392
3226.62	1392
3229.14	1348
3231.66	1388
3234.18	1376
3236.69	1376
3239.21	1386
3241.72	1416
3244.24	1378
3246.75	1382
3249.26	1396
3251.78	1398
3254.29	1414
3256.8	1428
3259.3	1396
3261.81	1446
3264.32	1420
3266.83	1450
3269.33	1448
3271.84	1422
3274.34	1464
3276.84	1458
3279.35	1436
3281.85	1442
3284.35	1468
3286.85	1476
3289.35	1464
3291.84	1488
3294.34	1428
3296.84	1484
3299.33	1448
3301.83	1494
3304.32	1468
3306.81	1486
3309.3	1558
3311.79	1542
3314.29	1526
3316.77	1526
3319.26	1494
3321.75	1528
3324.24	1562
3326.72	1514
3329.21	1534
3331.69	1562
3334.18	1534
3336.66	1594
3339.14	1564
3341.62	1602
3344.1	1552
3346.58	1564
3349.06	1574
3351.54	1584
3354.01	1562
3356.49	1566
3358.96	1584
3361.44	1584
3363.91	1622
3366.38	1560
3368.85	1598
3371.33	1604
3373.8	1622
3376.26	1594
3378.73	1632
3381.2	1616
3383.67	1626
3386.13	1640
3388.6	1606
3391.06	1632
3393.52	1620
3395.99	1606
3398.45	1624
3400.91	1662
3403.37	1674
3405.83	1662
3408.29	1696
3410.74	1660
3413.2	1624
3415.66	1694
3418.11	1692
3420.56	1684
3423.02	1666
3425.47	1678
3427.92	1688
3430.37	1740
3432.82	1676
3435.27	1736
3437.72	1718
3440.17	1744
3442.61	1758
3445.06	1788
3447.51	1740
3449.95	1726
3452.39	1776
3454.83	1792
3457.28	1752
3459.72	1838
3462.16	1816
3464.6	1766
3467.04	1800
3469.47	1814
3471.91	1848
3474.34	1766
3476.78	1814
3479.21	1826
3481.65	1830
3484.08	1830
3486.51	1854
3488.94	1858
3491.37	1844
3493.8	1850
3496.23	1790
3498.66	1828
3501.09	1838
3503.51	1806
3505.94	1816
3508.36	1810
3510.79	1854
3513.21	1792
3515.63	1804
3518.05	1858
3520.47	1814
3522.89	1856
3525.31	1834
3527.73	1836
3530.14	1864
3532.56	1898
3534.98	1816
3537.39	1834
3539.81	1870
3542.22	1864
3544.63	1874
3547.04	1940
3549.45	1878
3551.86	1874
3554.27	1846
3556.68	1844
3559.09	1900
3561.49	1934
3563.9	1894
3566.3	1914
3568.71	1890
3571.11	1944
3573.51	1954
3575.92	1922
3578.32	1954
3580.72	1922
3583.12	1942
3585.51	2002
3587.91	1956
3590.31	1996
3592.71	1990
3595.1	1996
3597.49	1990
3599.89	2058
3602.28	2038
3604.67	1990
3607.06	2006
3609.45	2040
3611.84	2034
3614.23	2024
3616.62	2070
3619.01	2058
3621.39	2032
3623.78	2080
3626.17	2100
3628.55	2036
3630.93	2086
3633.31	2062
3635.7	2090
3638.08	2080
3640.46	2076
3642.84	2072
3645.22	2106
3647.59	2096
3649.97	2078
3652.35	2068
3654.72	2098
3657.1	2102
3659.47	2110
3661.84	2108
3664.21	2104
3666.59	2106
3668.96	2094
3671.33	2108
3673.69	2092
3676.06	2108
3678.43	2092
3680.8	2102
3683.16	2128
3685.53	2118
3687.89	2118
3690.25	2120
3692.62	2134
3694.98	2144
3697.34	2136
3699.7	2180
3702.06	2098
3704.42	2162
3706.78	2124
3709.13	2102
3711.49	2190
3713.85	2116
3716.2	2160
3718.56	2190
3720.91	2208
3723.26	2200
3725.61	2176
3727.96	2198
3730.31	2166
3732.66	2220
3735.01	2186
3737.36	2258
3739.7	2236
3742.05	2244
3744.4	2286
3746.74	2260
3749.09	2290
3751.43	2276
3753.77	2272
3756.11	2300
3758.45	2318
3760.79	2246
3763.13	2322
3765.47	2310
3767.81	2318
3770.14	2302
3772.48	2308
3774.82	2298
3777.15	2326
3779.48	2286
3781.82	2334
3784.15	2266
3786.48	2362
3788.81	2356
3791.14	2294
3793.47	2382
3795.8	2310
3798.13	2346
3800.45	2328
3802.78	2338
3805.1	2332
3807.43	2306
3809.75	2342
3812.07	2356
3814.4	2338
3816.72	2334
3819.04	2370
3821.36	2326
3823.68	2292
3826	2334
3828.31	2378
3830.63	2346
3832.95	2364
3835.26	2326
3837.58	2374
3839.89	2338
3842.2	2348
3844.51	2368
3846.83	2360
3849.14	2320
3851.45	2352
3853.76	2372
3856.06	2376
3858.37	2392
3860.68	2426
3862.98	2380
3865.29	2382
3867.59	2394
3869.9	2378
3872.2	2396
3874.5	2426
3876.8	2424
3879.1	2436
3881.4	2490
3883.7	2474
3886	2482
3888.3	2502
3890.6	2482
3892.89	2444
3895.19	2544
3897.48	2474
3899.78	2500
3902.07	2548
3904.36	2540
3906.65	2492
3908.94	2478
3911.23	2556
3913.52	2526
3915.81	2574
3918.1	2564
3920.39	2502
3922.67	2562
3924.96	2572
3927.24	2524
3929.53	2554
3931.81	2552
3934.09	2556
3936.38	2552
3938.66	2566
3940.94	2580
3943.22	2556
3945.5	2580
3947.77	2520
3950.05	2622
3952.33	2624
3954.6	2606
3956.88	2594
3959.15	2592
3961.43	2578
3963.7	2594
3965.97	2556
3968.24	2564
3970.51	2532
3972.78	2560
3975.05	2584
3977.32	2544
3979.59	2528
3981.85	2536
3984.12	2550
3986.39	2574
3988.65	2584
3990.91	2644
3993.18	2608
3995.44	2552
3997.7	2666
3999.96	2660