File: DataDrivenSE/datosramanb/CN-Sastre_16.txt
#Acq. time (s)=	20
#Accumulations=	2
#Range (cm-¹)=	50...4000
#Windows=	3
#Autofocus=	Off
#AutoExposure=	Off
#Spike filter=	Multiple accum.
#Delay time (s)=	0
#Binning=	1
#Readout mode=	Signal
#DeNoise=	Off
#ICS correction=	Off
#Dark correction=	Off
#Inst. Process=	Off
#Instrument=	LabRAM HR Evol
#Detector=	Syncerity OE
#Objective=	x100_VIS
#Grating=	600 (500nm)
#ND Filter=	100%
#Laser=	532nm_Edge
#Hole=	100.021
#Range=	Visible
#Project=	Omar
#Sample=
#Site=	21-09-22
#Title=	 CN-Sastre
#Remark=
#Date=	21.09.2022 14:00
#Acquired=	21.09.2022 14:00:18
51.0918	44
54.7807	54
58.4681	94
62.154	184
65.8385	308
69.5216	464
73.2032	806
76.8834	1110
80.5621	1412
84.2393	1676
87.9152	1818
91.5874	1884
95.2603	1800
98.9318	1804
102.602	1810
106.27	1914
109.936	1890
113.601	1894
117.266	1882
120.926	1880
124.588	1814
128.246	1844
131.904	1806
135.561	1784
139.215	1820
142.869	1844
146.52	1806
150.171	1784
153.819	1814
157.465	1808
161.112	1786
164.756	1790
168.398	1746
172.041	1766
175.68	1724
179.318	1726
182.955	1690
186.592	1720
190.225	1684
193.857	1730
197.488	1726
201.118	1700
204.746	1678
208.372	1680
211.997	1696
215.621	1698
219.243	1624
222.864	1628
226.483	1652
230.101	1620
233.718	1604
237.331	1634
240.945	1608
244.557	1644
248.168	1620
251.776	1674
255.384	1610
258.991	1634
262.594	1580
266.198	1630
269.799	1664
273.4	1596
277	1606
280.596	1572
284.193	1640
287.786	1634
291.378	1654
294.971	1634
298.561	1642
302.148	1640
305.737	1648
309.322	1684
312.906	1618
316.49	1634
320.071	1658
323.651	1698
327.229	1690
330.806	1646
334.381	1700
337.955	1656
341.528	1660
345.099	1668
348.669	1690
352.238	1674
355.805	1754
359.371	1690
362.935	1674
366.498	1760
370.06	1700
373.62	1700
377.177	1732
380.734	1748
384.29	1736
387.845	1730
391.396	1740
394.948	1724
398.499	1736
402.046	1754
405.594	1720
409.138	1722
412.683	1710
416.225	1714
419.768	1722
423.307	1720
426.844	1704
430.382	1712
433.917	1742
437.451	1730
440.985	1730
444.516	1732
448.045	1750
451.574	1786
455.102	1766
458.628	1808
462.152	1776
465.674	1764
469.196	1718
472.716	1758
476.234	1734
479.752	1702
483.268	1702
486.782	1706
490.295	1678
493.807	1674
497.316	1630
500.825	1624
504.333	1666
507.839	1638
511.344	1672
514.846	1630
518.349	1694
521.85	1748
525.347	1754
528.846	1818
532.341	1844
535.837	1984
539.329	2090
542.822	2140
546.312	2218
549.802	2268
553.289	2308
556.775	2322
560.261	2326
563.744	2308
567.226	2280
570.709	2236
574.188	2192
577.665	2154
581.142	2096
584.617	2058
588.091	2040
591.565	1980
595.036	1956
598.506	1876
601.974	1878
605.442	1822
608.905	1760
612.37	1726
615.833	1714
619.295	1704
622.755	1682
626.215	1618
629.67	1574
633.127	1556
636.582	1560
640.036	1540
643.487	1508
646.938	1474
650.386	1424
653.835	1384
657.282	1364
660.726	1320
664.171	1324
667.613	1314
671.053	1226
674.494	1232
677.931	1196
681.369	1184
684.804	1110
688.238	1112
691.67	1060
695.103	1070
698.533	1028
701.961	1010
705.389	962
708.814	992
712.239	962
715.662	922
719.084	936
722.505	946
725.924	870
729.342	920
732.759	880
736.174	910
739.589	900
742.999	884
746.411	924
749.821	894
753.23	946
756.636	920
760.043	902
763.448	920
766.85	954
770.252	916
773.652	920
777.052	962
780.448	956
783.846	964
787.24	936
790.635	976
794.027	964
797.417	932
800.808	916
804.196	912
807.582	898
810.968	852
814.354	860
817.736	856
821.118	836
824.498	800
827.877	776
831.254	746
834.631	780
838.006	744
841.38	696
844.752	736
848.123	722
851.493	678
854.86	690
858.228	684
861.594	662
864.959	706
868.321	692
871.683	700
875.044	732
878.402	702
881.761	674
885.116	748
888.472	670
891.825	706
895.179	718
898.529	718
901.88	732
905.228	756
908.575	800
911.922	808
915.266	814
918.609	830
921.951	842
925.293	912
928.633	892
931.97	914
935.307	962
938.642	966
941.977	982
945.31	1004
948.641	1010
951.972	1030
955.301	1010
958.629	1016
961.955	1038
965.279	970
968.603	1042
971.926	1006
975.248	1042
978.566	1024
981.886	1064
985.204	1098
988.519	1076
991.834	1112
995.147	1132
998.46	1184
1001.77	1156
1005.08	1176
1008.39	1164
1011.7	1214
1015	1212
1018.3	1260
1021.61	1298
1024.91	1292
1028.21	1320
1031.51	1348
1034.81	1394
1038.1	1430
1041.4	1466
1044.69	1544
1047.99	1612
1051.28	1658
1054.57	1682
1057.86	1704
1061.14	1756
1064.43	1786
1067.72	1912
1071	1968
1074.28	1988
1077.57	2078
1080.84	2144
1084.12	2170
1087.4	2138
1090.68	2182
1093.95	2166
1097.22	2206
1100.5	2148
1103.77	2168
1107.04	2084
1110.31	2062
1113.58	1954
1116.84	1812
1120.1	1786
1123.37	1720
1126.63	1650
1129.89	1616
1133.15	1558
1136.41	1462
1139.67	1382
1142.92	1350
1146.18	1288
1149.43	1292
1152.68	1270
1155.93	1180
1159.18	1118
1162.43	1144
1165.68	1088
1168.93	1060
1172.17	1032
1175.41	1010
1178.66	958
1181.9	950
1185.14	884
1188.37	866
1191.61	882
1194.85	852
1198.08	800
1201.31	806
1204.55	764
1207.78	790
1211.01	720
1214.24	736
1217.46	674
1220.69	698
1223.91	686
1227.14	680
1230.36	674
1233.58	664
1236.8	656
1240.02	640
1243.23	654
1246.45	638
1249.67	626
1252.88	634
1256.09	626
1259.3	622
1262.51	646
1265.72	620
1268.93	638
1272.13	646
1275.34	658
1278.54	608
1281.74	624
1284.94	642
1288.15	668
1291.34	656
1294.54	654
1297.74	632
1300.93	646
1304.12	650
1307.32	624
1310.51	628
1313.7	646
1316.89	648
1320.07	634
1323.26	644
1326.45	654
1329.63	650
1332.81	658
1335.99	654
1339.17	668
1342.35	666
1345.53	650
1348.71	640
1351.88	652
1355.06	696
1358.23	642
1361.4	644
1364.57	630
1367.74	658
1370.91	632
1374.08	662
1377.24	638
1380.41	674
1383.57	644
1386.73	654
1389.89	636
1393.05	638
1396.21	612
1399.37	624
1402.52	644
1405.68	654
1408.83	624
1411.98	662
1415.13	626
1418.29	662
1421.43	660
1424.58	638
1427.73	638
1430.87	630
1434.02	622
1437.16	648
1440.3	662
1443.44	638
1446.58	674
1449.72	634
1452.85	660
1455.99	674
1459.12	626
1462.26	638
1465.39	642
1468.52	654
1471.65	666
1474.78	632
1477.9	656
1481.03	676
1484.16	646
1487.28	658
1490.4	680
1493.52	676
1496.64	690
1499.76	662
1502.88	652
1506	652
1509.11	668
1512.22	672
1515.34	682
1518.45	656
1521.56	668
1524.67	676
1527.78	676
1530.88	658
1533.99	688
1537.09	654
1540.2	678
1543.3	656
1546.4	684
1549.5	688
1552.6	686
1555.7	714
1558.79	686
1561.89	678
1564.98	698
1568.08	690
1571.17	688
1574.26	662
1577.35	692
1580.43	686
1583.52	696
1586.61	690
1589.69	724
1592.77	668
1595.86	700
1598.94	658
1602.02	690
1605.1	684
1608.18	666.064
1611.25	658.456
1614.33	671.089
1617.4	687.329
1620.47	656.41
1623.55	651.042
1626.62	659.437
1629.69	632.621
1632.75	631.301
1635.82	640.96
1638.89	654.959
1641.95	629.176
1645.02	642.69
1648.08	662.247
1651.14	642.349
1654.2	654.227
1657.26	640.584
1660.32	629.662
1663.37	631.819
1666.43	619.813
1669.48	637.264
1672.54	619.893
1675.59	641.53
1678.64	633.574
1681.69	619.282
1684.74	616.035
1687.79	620.997
1690.83	619.417
1693.88	619.717
1696.92	620.568
1699.96	609.118
1703.01	610.659
1706.05	631.341
1709.09	616.747
1712.12	597.832
1715.16	613.581
1718.2	603.255
1721.23	599.515
1724.27	605.54
1727.3	608.724
1730.33	596.555
1733.36	607.622
1736.39	576.643
1739.42	609.456
1742.44	570.208
1745.47	601.626
1748.49	570.809
1751.52	573.379
1754.54	567.564
1757.56	556.428
1759.14	576
1762.18	586
1765.21	582
1768.24	570
1771.27	592
1774.3	590
1777.32	576
1780.35	580
1783.38	542
1786.4	572
1789.42	568
1792.44	576
1795.47	602
1798.48	616
1801.5	582
1804.52	564
1807.54	598
1810.55	574
1813.57	572
1816.58	588
1819.59	584
1822.6	606
1825.61	578
1828.62	572
1831.63	588
1834.63	558
1837.64	580
1840.64	592
1843.64	572
1846.64	594
1849.64	600
1852.64	584
1855.64	580
1858.64	584
1861.64	582
1864.63	598
1867.63	606
1870.62	574
1873.61	588
1876.6	582
1879.59	590
1882.58	604
1885.56	592
1888.55	600
1891.54	534
1894.52	564
1897.5	600
1900.48	594
1903.46	574
1906.44	608
1909.42	582
1912.4	602
1915.38	580
1918.35	606
1921.32	570
1924.3	584
1927.27	594
1930.24	590
1933.21	582
1936.18	588
1939.15	572
1942.11	578
1945.08	594
1948.04	590
1951	604
1953.97	588
1956.93	574
1959.89	604
1962.85	590
1965.8	604
1968.76	562
1971.71	590
1974.67	586
1977.62	602
1980.57	588
1983.53	608
1986.48	586
1989.42	606
1992.37	594
1995.32	590
1998.26	618
2001.21	594
2004.15	606
2007.09	594
2010.03	610
2012.98	580
2015.92	602
2018.85	612
2021.79	592
2024.73	590
2027.66	614
2030.59	572
2033.53	606
2036.46	592
2039.39	606
2042.32	590
2045.25	592
2048.17	616
2051.1	604
2054.02	592
2056.95	594
2059.87	560
2062.79	582
2065.71	624
2068.63	616
2071.55	600
2074.47	644
2077.39	618
2080.3	610
2083.22	612
2086.13	618
2089.04	604
2091.95	616
2094.86	594
2097.77	612
2100.68	608
2103.59	602
2106.49	578
2109.4	624
2112.3	620
2115.21	622
2118.11	614
2121.01	566
2123.91	598
2126.8	610
2129.7	614
2132.6	602
2135.49	586
2138.39	586
2141.28	638
2144.17	598
2147.06	620
2149.95	598
2152.84	620
2155.73	622
2158.62	592
2161.5	582
2164.39	598
2167.27	610
2170.15	592
2173.04	598
2175.92	592
2178.79	630
2181.67	608
2184.55	624
2187.43	612
2190.3	616
2193.18	610
2196.05	592
2198.92	606
2201.79	614
2204.66	612
2207.53	582
2210.4	634
2213.27	604
2216.13	622
2219	592
2221.86	614
2224.72	598
2227.59	594
2230.45	574
2233.31	600
2236.16	578
2239.02	588
2241.88	566
2244.73	616
2247.59	572
2250.44	590
2253.29	626
2256.15	594
2259	608
2261.84	578
2264.69	566
2267.54	578
2270.39	592
2273.23	602
2276.07	618
2278.92	648
2281.76	606
2284.6	598
2287.44	620
2290.28	592
2293.12	598
2295.95	606
2298.79	646
2301.62	616
2304.46	654
2307.29	624
2310.12	624
2312.95	632
2315.78	640
2318.61	648
2321.44	658
2324.27	650
2327.09	696
2329.92	688
2332.74	668
2335.56	674
2338.38	650
2341.2	686
2344.02	690
2346.84	688
2349.66	666
2352.48	696
2355.29	660
2358.11	700
2360.92	696
2363.73	724
2366.54	704
2369.35	732
2372.16	736
2374.97	708
2377.78	724
2380.58	740
2383.39	726
2386.19	732
2389	722
2391.8	752
2394.6	776
2397.4	730
2400.2	792
2403	740
2405.79	752
2408.59	778
2411.38	754
2414.18	754
2416.97	754
2419.76	762
2422.55	778
2425.34	740
2428.13	798
2430.92	768
2433.71	772
2436.49	776
2439.28	766
2442.06	798
2444.85	754
2447.63	806
2450.41	790
2453.19	786
2455.97	774
2458.75	770
2461.52	772
2464.3	780
2467.07	772
2469.85	774
2472.62	742
2475.39	806
2478.16	766
2480.94	796
2483.7	760
2486.47	800
2489.24	788
2492	754
2494.77	764
2497.53	782
2500.3	798
2503.06	776
2505.82	768
2508.58	774
2511.34	774
2514.1	772
2516.85	762
2519.61	790
2522.37	774
2525.12	780
2527.87	776
2530.63	756
2533.38	768
2536.13	786
2538.88	798
2541.62	788
2544.37	778
2547.12	774
2549.86	800
2552.61	784
2555.35	786
2558.09	776
2560.84	782
2563.57	776
2566.32	760
2569.05	746
2571.79	782
2574.53	786
2577.26	796
2580	770
2582.73	788
2585.46	774
2588.19	788
2590.93	790
2593.66	772
2596.39	806
2599.11	778
2601.84	802
2604.56	786
2607.29	812
2610.01	812
2612.74	804
2615.46	804
2618.18	800
2620.9	816
2623.62	806
2626.34	776
2629.05	812
2631.77	822
2634.48	820
2637.2	790
2639.91	806
2642.62	844
2645.33	858
2648.05	804
2650.75	814
2653.46	836
2656.17	814
2658.88	830
2661.58	816
2664.29	844
2666.99	824
2669.69	804
2672.39	812
2675.09	828
2677.79	832
2680.49	810
2683.19	844
2685.89	796
2688.58	794
2691.28	798
2693.97	826
2696.67	804
2699.36	818
2702.05	820
2704.74	798
2707.43	830
2710.12	830
2712.8	820
2715.49	828
2718.17	856
2720.86	814
2723.54	856
2726.22	828
2728.91	800
2731.59	832
2734.27	840
2736.95	818
2739.62	828
2742.3	832
2744.98	832
2747.65	838
2750.33	832
2753	850
2755.67	856
2758.34	864
2761.01	856
2763.68	872
2766.35	844
2769.02	850
2771.68	874
2774.35	844
2777.01	874
2779.68	868
2782.34	892
2785	896
2787.66	864
2790.32	900
2792.98	902
2795.64	902
2798.3	924
2800.95	892
2803.61	894
2806.26	920
2808.91	922
2811.57	894
2814.22	894
2816.87	922
2819.52	910
2822.17	896
2824.81	902
2827.46	876
2830.11	930
2832.75	922
2835.39	894
2838.04	940
2840.68	968
2843.32	928
2845.96	972
2848.6	906
2851.24	922
2853.88	954
2856.51	932
2859.15	966
2861.78	966
2864.42	958
2867.05	956
2869.68	964
2872.31	964
2874.94	938
2877.57	924
2880.2	1010
2882.82	966
2885.45	956
2888.08	952
2890.7	994
2893.33	1008
2895.95	966
2898.57	1004
2901.19	992
2903.81	980
2906.43	1004
2909.05	1012
2911.66	988
2914.28	1006
2916.89	984
2919.51	1029.44
2922.12	982.653
2924.73	994.789
2927.35	999.134
2929.96	1005.7
2932.57	1008.54
2935.17	1000.3
2937.78	1012.6
2940.39	977.582
2943	1033.95
2945.6	1011.39
2948.2	1013.72
2950.81	1016.02
2953.41	1023.91
2956.01	1028.18
2958.61	1060.47
2961.21	1035.54
2963.81	1012.82
2966.41	1030.64
2969.01	1023.17
2971.6	1050.86
2974.2	1040.29
2976.79	1072.54
2979.39	1077.52
2981.98	1055.2
2984.57	1065.72
2987.16	1062.56
2989.75	1050.43
2992.34	1070.64
2994.93	1073.44
2997.51	1071.54
3000.1	1071.48
3002.68	1103.75
3005.27	1090.73
3007.85	1094.04
3010.43	1108.21
3013.01	1083.23
3015.59	1097.78
3018.18	1082.1
3020.75	1117.5
3023.33	1086.63
3025.91	1102.42
3028.48	1117.87
3031.06	1105.93
3033.64	1099.71
3036.21	1131.28
3038.78	1092.59
3041.35	1130.95
3043.92	1136.9
3046.49	1115.74
3048.11	1110
3050.69	1132
3053.27	1160
3055.85	1176
3058.43	1156
3061.01	1160
3063.58	1138
3066.16	1168
3068.73	1190
3071.31	1136
3073.88	1174
3076.45	1190
3079.02	1102
3081.59	1212
3084.16	1150
3086.73	1222
3089.29	1176
3091.86	1200
3094.43	1218
3096.99	1220
3099.55	1194
3102.12	1184
3104.68	1244
3107.24	1196
3109.8	1220
3112.36	1242
3114.92	1236
3117.48	1248
3120.03	1186
3122.59	1234
3125.14	1258
3127.7	1290
3130.25	1242
3132.8	1228
3135.35	1304
3137.9	1276
3140.45	1266
3143	1288
3145.55	1274
3148.1	1292
3150.64	1304
3153.19	1266
3155.73	1276
3158.28	1312
3160.82	1318
3163.36	1322
3165.9	1340
3168.44	1314
3170.98	1316
3173.52	1356
3176.06	1368
3178.59	1324
3181.13	1348
3183.66	1334
3186.2	1316
3188.73	1344
3191.26	1386
3193.79	1340
3196.32	1362
3198.85	1340
3201.38	1356
3203.91	1370
3206.44	1348
3208.96	1366
3211.49	1368
3214.01	1370
3216.54	1368
3219.06	1422
3221.58	1402
3224.1	1354
3226.62	1410
3229.14	1370
3231.66	1428
3234.18	1412
3236.69	1362
3239.21	1464
3241.72	1396
3244.24	1406
3246.75	1426
3249.26	1396
3251.78	1408
3254.29	1428
3256.8	1422
3259.3	1468
3261.81	1430
3264.32	1436
3266.83	1460
3269.33	1456
3271.84	1468
3274.34	1468
3276.84	1478
3279.35	1508
3281.85	1492
3284.35	1504
3286.85	1486
3289.35	1528
3291.84	1506
3294.34	1504
3296.84	1538
3299.33	1526
3301.83	1542
3304.32	1554
3306.81	1540
3309.3	1538
3311.79	1508
3314.29	1568
3316.77	1594
3319.26	1536
3321.75	1548
3324.24	1568
3326.72	1606
3329.21	1622
3331.69	1554
3334.18	1576
3336.66	1574
3339.14	1568
3341.62	1612
3344.1	1616
3346.58	1632
3349.06	1622
3351.54	1640
3354.01	1616
3356.49	1604
3358.96	1602
3361.44	1652
3363.91	1646
3366.38	1634
3368.85	1654
3371.33	1618
3373.8	1644
3376.26	1612
3378.73	1678
3381.2	1628
3383.67	1664
3386.13	1642
3388.6	1696
3391.06	1666
3393.52	1652
3395.99	1668
3398.45	1662
3400.91	1626
3403.37	1670
3405.83	1716
3408.29	1700
3410.74	1738
3413.2	1750
3415.66	1716
3418.11	1718
3420.56	1734
3423.02	1710
3425.47	1726
3427.92	1754
3430.37	1808
3432.82	1744
3435.27	1736
3437.72	1794
3440.17	1790
3442.61	1810
3445.06	1786
3447.51	1760
3449.95	1744
3452.39	1808
3454.83	1814
3457.28	1798
3459.72	1822
3462.16	1822
3464.6	1814
3467.04	1822
3469.47	1846
3471.91	1872
3474.34	1856
3476.78	1842
3479.21	1868
3481.65	1862
3484.08	1842
3486.51	1842
3488.94	1878
3491.37	1930
3493.8	1848
3496.23	1844
3498.66	1902
3501.09	1906
3503.51	1892
3505.94	1870
3508.36	1856
3510.79	1894
3513.21	1898
3515.63	1894
3518.05	1898
3520.47	1888
3522.89	1866
3525.31	1888
3527.73	1876
3530.14	1902
3532.56	1916
3534.98	1866
3537.39	1906
3539.81	1876
3542.22	1912
3544.63	1896
3547.04	1904
3549.45	1906
3551.86	1964
3554.27	1930
3556.68	1944
3559.09	1898
3561.49	1964
3563.9	1898
3566.3	1966
3568.71	1912
3571.11	1974
3573.51	1928
3575.92	1978
3578.32	1992
3580.72	2002
3583.12	2040
3585.51	2014
3587.91	2026
3590.31	2044
3592.71	2068
3595.1	2018
3597.49	2022
3599.89	2048
3602.28	2130
3604.67	2104
3607.06	2106
3609.45	2108
3611.84	2090
3614.23	2090
3616.62	2092
3619.01	2090
3621.39	2176
3623.78	2128
3626.17	2110
3628.55	2086
3630.93	2118
3633.31	2166
3635.7	2152
3638.08	2144
3640.46	2108
3642.84	2146
3645.22	2112
3647.59	2126
3649.97	2146
3652.35	2108
3654.72	2140
3657.1	2182
3659.47	2158
3661.84	2126
3664.21	2148
3666.59	2158
3668.96	2148
3671.33	2148
3673.69	2120
3676.06	2164
3678.43	2160
3680.8	2148
3683.16	2122
3685.53	2142
3687.89	2146
3690.25	2186
3692.62	2180
3694.98	2174
3697.34	2164
3699.7	2176
3702.06	2224
3704.42	2128
3706.78	2182
3709.13	2228
3711.49	2202
3713.85	2204
3716.2	2226
3718.56	2232
3720.91	2240
3723.26	2204
3725.61	2272
3727.96	2290
3730.31	2294
3732.66	2312
3735.01	2272
3737.36	2264
3739.7	2286
3742.05	2294
3744.4	2312
3746.74	2328
3749.09	2358
3751.43	2384
3753.77	2358
3756.11	2348
3758.45	2348
3760.79	2350
3763.13	2376
3765.47	2352
3767.81	2388
3770.14	2362
3772.48	2416
3774.82	2372
3777.15	2398
3779.48	2362
3781.82	2374
3784.15	2440
3786.48	2420
3788.81	2364
3791.14	2384
3793.47	2378
3795.8	2398
3798.13	2358
3800.45	2368
3802.78	2392
3805.1	2394
3807.43	2404
3809.75	2394
3812.07	2412
3814.4	2426
3816.72	2404
3819.04	2356
3821.36	2402
3823.68	2412
3826	2338
3828.31	2392
3830.63	2404
3832.95	2394
3835.26	2386
3837.58	2434
3839.89	2392
3842.2	2434
3844.51	2426
3846.83	2392
3849.14	2420
3851.45	2428
3853.76	2420
3856.06	2408
3858.37	2384
3860.68	2404
3862.98	2446
3865.29	2458
3867.59	2502
3869.9	2468
3872.2	2446
3874.5	2540
3876.8	2514
3879.1	2522
3881.4	2472
3883.7	2504
3886	2526
3888.3	2550
3890.6	2550
3892.89	2632
3895.19	2578
3897.48	2582
3899.78	2586
3902.07	2554
3904.36	2604
3906.65	2530
3908.94	2630
3911.23	2598
3913.52	2572
3915.81	2616
3918.1	2642
3920.39	2618
3922.67	2612
3924.96	2620
3927.24	2594
3929.53	2612
3931.81	2602
3934.09	2668
3936.38	2550
3938.66	2678
3940.94	2618
3943.22	2644
3945.5	2646
3947.77	2612
3950.05	2602
3952.33	2638
3954.6	2660
3956.88	2622
3959.15	2664
3961.43	2652
3963.7	2612
3965.97	2638
3968.24	2656
3970.51	2660
3972.78	2674
3975.05	2674
3977.32	2672
3979.59	2632
3981.85	2662
3984.12	2674
3986.39	2676
3988.65	2666
3990.91	2608
3993.18	2704
3995.44	2646
3997.7	2696
3999.96	2694