File: DataDrivenSE/datosramanb/CN-Sastre_12.txt
#Acq. time (s)=	20
#Accumulations=	2
#Range (cm-¹)=	50...4000
#Windows=	3
#Autofocus=	Off
#AutoExposure=	Off
#Spike filter=	Multiple accum.
#Delay time (s)=	0
#Binning=	1
#Readout mode=	Signal
#DeNoise=	Off
#ICS correction=	Off
#Dark correction=	Off
#Inst. Process=	Off
#Instrument=	LabRAM HR Evol
#Detector=	Syncerity OE
#Objective=	x100_VIS
#Grating=	600 (500nm)
#ND Filter=	100%
#Laser=	532nm_Edge
#Hole=	100.021
#Range=	Visible
#Project=	Omar
#Sample=
#Site=	21-09-22
#Title=	 CN-Sastre
#Remark=
#Date=	21.09.2022 13:38
#Acquired=	21.09.2022 13:38:08
51.0918	42
54.7807	46
58.4681	84
62.154	178
65.8385	304
69.5216	452
73.2032	790
76.8834	1106
80.5621	1358
84.2393	1656
87.9152	1818
91.5874	1888
95.2603	1806
98.9318	1802
102.602	1844
106.27	1960
109.936	1862
113.601	1970
117.266	1886
120.926	1886
124.588	1824
128.246	1822
131.904	1832
135.561	1796
139.215	1874
142.869	1864
146.52	1882
150.171	1812
153.819	1838
157.465	1762
161.112	1854
164.756	1802
168.398	1788
172.041	1756
175.68	1720
179.318	1732
182.955	1740
186.592	1780
190.225	1716
193.857	1728
197.488	1664
201.118	1684
204.746	1702
208.372	1714
211.997	1696
215.621	1666
219.243	1688
222.864	1658
226.483	1602
230.101	1608
233.718	1618
237.331	1630
240.945	1620
244.557	1670
248.168	1612
251.776	1624
255.384	1640
258.991	1630
262.594	1636
266.198	1634
269.799	1658
273.4	1622
277	1660
280.596	1662
284.193	1656
287.786	1590
291.378	1614
294.971	1640
298.561	1630
302.148	1652
305.737	1678
309.322	1686
312.906	1652
316.49	1690
320.071	1690
323.651	1674
327.229	1670
330.806	1688
334.381	1700
337.955	1642
341.528	1712
345.099	1668
348.669	1666
352.238	1720
355.805	1718
359.371	1738
362.935	1716
366.498	1682
370.06	1734
373.62	1732
377.177	1756
380.734	1736
384.29	1772
387.845	1742
391.396	1766
394.948	1768
398.499	1784
402.046	1774
405.594	1750
409.138	1802
412.683	1800
416.225	1738
419.768	1746
423.307	1740
426.844	1756
430.382	1744
433.917	1758
437.451	1738
440.985	1802
444.516	1806
448.045	1720
451.574	1740
455.102	1798
458.628	1782
462.152	1768
465.674	1786
469.196	1746
472.716	1752
476.234	1764
479.752	1756
483.268	1784
486.782	1760
490.295	1688
493.807	1708
497.316	1674
500.825	1694
504.333	1694
507.839	1700
511.344	1684
514.846	1716
518.349	1710
521.85	1740
525.347	1818
528.846	1850
532.341	1900
535.837	2028
539.329	2130
542.822	2184
546.312	2270
549.802	2330
553.289	2380
556.775	2372
560.261	2428
563.744	2318
567.226	2330
570.709	2286
574.188	2228
577.665	2194
581.142	2214
584.617	2086
588.091	2062
591.565	2020
595.036	2018
598.506	1964
601.974	1906
605.442	1874
608.905	1830
612.37	1778
615.833	1728
619.295	1776
622.755	1654
626.215	1660
629.67	1626
633.127	1654
636.582	1540
640.036	1546
643.487	1534
646.938	1522
650.386	1472
653.835	1450
657.282	1404
660.726	1364
664.171	1304
667.613	1290
671.053	1298
674.494	1262
677.931	1204
681.369	1214
684.804	1132
688.238	1120
691.67	1110
695.103	1088
698.533	1058
701.961	988
705.389	1002
708.814	980
712.239	970
715.662	964
719.084	906
722.505	962
725.924	928
729.342	954
732.759	920
736.174	906
739.589	920
742.999	872
746.411	914
749.821	908
753.23	948
756.636	914
760.043	954
763.448	906
766.85	992
770.252	992
773.652	962
777.052	970
780.448	960
783.846	970
787.24	936
790.635	966
794.027	966
797.417	948
800.808	940
804.196	916
807.582	896
810.968	868
814.354	872
817.736	854
821.118	832
824.498	818
827.877	796
831.254	830
834.631	762
838.006	732
841.38	724
844.752	750
848.123	710
851.493	734
854.86	714
858.228	706
861.594	698
864.959	722
868.321	690
871.683	712
875.044	740
878.402	720
881.761	700
885.116	748
888.472	718
891.825	692
895.179	718
898.529	722
901.88	772
905.228	772
908.575	786
911.922	814
915.266	828
918.609	812
921.951	856
925.293	886
928.633	894
931.97	922
935.307	988
938.642	992
941.977	1028
945.31	1062
948.641	1024
951.972	1058
955.301	1060
958.629	1062
961.955	1066
965.279	1082
968.603	1038
971.926	1044
975.248	1076
978.566	1076
981.886	1066
985.204	1134
988.519	1152
991.834	1124
995.147	1178
998.46	1184
1001.77	1174
1005.08	1194
1008.39	1190
1011.7	1260
1015	1200
1018.3	1270
1021.61	1322
1024.91	1338
1028.21	1362
1031.51	1402
1034.81	1436
1038.1	1502
1041.4	1524
1044.69	1584
1047.99	1614
1051.28	1640
1054.57	1710
1057.86	1702
1061.14	1792
1064.43	1868
1067.72	1948
1071	1996
1074.28	2018
1077.57	2124
1080.84	2152
1084.12	2196
1087.4	2164
1090.68	2286
1093.95	2272
1097.22	2276
1100.5	2282
1103.77	2228
1107.04	2168
1110.31	2092
1113.58	1954
1116.84	1948
1120.1	1870
1123.37	1830
1126.63	1712
1129.89	1630
1133.15	1642
1136.41	1478
1139.67	1422
1142.92	1392
1146.18	1360
1149.43	1328
1152.68	1280
1155.93	1242
1159.18	1168
1162.43	1132
1165.68	1124
1168.93	1070
1172.17	1066
1175.41	1044
1178.66	998
1181.9	994
1185.14	960
1188.37	898
1191.61	906
1194.85	892
1198.08	836
1201.31	850
1204.55	800
1207.78	810
1211.01	770
1214.24	768
1217.46	724
1220.69	724
1223.91	704
1227.14	698
1230.36	714
1233.58	656
1236.8	680
1240.02	662
1243.23	674
1246.45	660
1249.67	656
1252.88	690
1256.09	668
1259.3	660
1262.51	630
1265.72	688
1268.93	698
1272.13	664
1275.34	678
1278.54	720
1281.74	672
1284.94	660
1288.15	685
1291.34	664
1294.54	688
1297.74	682
1300.93	648
1304.12	670
1307.32	664
1310.51	682
1313.7	652
1316.89	646
1320.07	646
1323.26	696
1326.45	672
1329.63	678
1332.81	658
1335.99	702
1339.17	656
1342.35	664
1345.53	688
1348.71	680
1351.88	636
1355.06	658
1358.23	664
1361.4	678
1364.57	684
1367.74	658
1370.91	698
1374.08	662
1377.24	650
1380.41	688
1383.57	660
1386.73	680
1389.89	648
1393.05	686
1396.21	642
1399.37	684
1402.52	660
1405.68	670
1408.83	656
1411.98	680
1415.13	688
1418.29	672
1421.43	672
1424.58	692
1427.73	666
1430.87	684
1434.02	710
1437.16	690
1440.3	680
1443.44	712
1446.58	660
1449.72	656
1452.85	732
1455.99	694
1459.12	666
1462.26	650
1465.39	676
1468.52	674
1471.65	684
1474.78	720
1477.9	682
1481.03	684
1484.16	676
1487.28	704
1490.4	712
1493.52	678
1496.64	728
1499.76	716
1502.88	676
1506	708
1509.11	704
1512.22	728
1515.34	744
1518.45	686
1521.56	706
1524.67	722
1527.78	676
1530.88	738
1533.99	694
1537.09	706
1540.2	710
1543.3	682
1546.4	702
1549.5	716
1552.6	706
1555.7	746
1558.79	692
1561.89	694
1564.98	694
1568.08	694
1571.17	726
1574.26	716
1577.35	690
1580.43	762
1583.52	708
1586.61	728
1589.69	722
1592.77	712
1595.86	718
1598.94	686
1602.02	704
1605.1	708
1608.18	710.012
1611.25	718.68
1614.33	691.999
1617.4	715.618
1620.47	707.416
1623.55	693.891
1626.62	703.026
1629.69	689.689
1632.75	700.149
1635.82	685.959
1638.89	671.679
1641.95	672.048
1645.02	659.705
1648.08	698.101
1651.14	695.431
1654.2	684.698
1657.26	670.128
1660.32	668.188
1663.37	676.526
1666.43	652.485
1669.48	649.749
1672.54	663.91
1675.59	644.648
1678.64	645.706
1681.69	656.432
1684.74	662.391
1687.79	640.916
1690.83	638.156
1693.88	662.746
1696.92	671.368
1699.96	644.046
1703.01	658.901
1706.05	629.475
1709.09	632.495
1712.12	637.39
1715.16	646.342
1718.2	613.419
1721.23	624.221
1724.27	627.081
1727.3	611.885
1730.33	617.291
1733.36	630.913
1736.39	622.906
1739.42	605.11
1742.44	626.003
1745.47	619.158
1748.49	596.599
1751.52	626.104
1754.54	602.47
1757.56	595.491
1759.14	614
1762.18	608
1765.21	604
1768.24	594
1771.27	590
1774.3	610
1777.32	586
1780.35	594
1783.38	600
1786.4	606
1789.42	588
1792.44	586
1795.47	604
1798.48	602
1801.5	606
1804.52	616
1807.54	614
1810.55	618
1813.57	604
1816.58	598
1819.59	620
1822.6	578
1825.61	604
1828.62	594
1831.63	600
1834.63	608
1837.64	610
1840.64	610
1843.64	606
1846.64	634
1849.64	620
1852.64	612
1855.64	618
1858.64	582
1861.64	612
1864.63	636
1867.63	602
1870.62	614
1873.61	628
1876.6	624
1879.59	634
1882.58	600
1885.56	618
1888.55	628
1891.54	614
1894.52	634
1897.5	596
1900.48	624
1903.46	602
1906.44	622
1909.42	586
1912.4	624
1915.38	648
1918.35	624
1921.32	632
1924.3	590
1927.27	596
1930.24	628
1933.21	610
1936.18	666
1939.15	632
1942.11	630
1945.08	638
1948.04	620
1951	618
1953.97	620
1956.93	638
1959.89	602
1962.85	638
1965.8	606
1968.76	612
1971.71	604
1974.67	602
1977.62	608
1980.57	614
1983.53	628
1986.48	642
1989.42	620
1992.37	646
1995.32	608
1998.26	604
2001.21	634
2004.15	632
2007.09	628
2010.03	626
2012.98	632
2015.92	632
2018.85	636
2021.79	628
2024.73	648
2027.66	628
2030.59	626
2033.53	652
2036.46	652
2039.39	646
2042.32	666
2045.25	636
2048.17	634
2051.1	658
2054.02	642
2056.95	662
2059.87	628
2062.79	648
2065.71	662
2068.63	624
2071.55	626
2074.47	638
2077.39	672
2080.3	650
2083.22	638
2086.13	672
2089.04	650
2091.95	654
2094.86	628
2097.77	658
2100.68	630
2103.59	616
2106.49	622
2109.4	624
2112.3	652
2115.21	624
2118.11	662
2121.01	644
2123.91	650
2126.8	656
2129.7	650
2132.6	654
2135.49	646
2138.39	640
2141.28	632
2144.17	634
2147.06	640
2149.95	634
2152.84	664
2155.73	636
2158.62	616
2161.5	630
2164.39	650
2167.27	626
2170.15	664
2173.04	638
2175.92	670
2178.79	656
2181.67	662
2184.55	664
2187.43	660
2190.3	664
2193.18	646
2196.05	644
2198.92	634
2201.79	636
2204.66	630
2207.53	656
2210.4	630
2213.27	632
2216.13	626
2219	650
2221.86	626
2224.72	600
2227.59	620
2230.45	664
2233.31	642
2236.16	646
2239.02	604
2241.88	632
2244.73	614
2247.59	620
2250.44	616
2253.29	628
2256.15	600
2259	658
2261.84	662
2264.69	628
2267.54	628
2270.39	642
2273.23	646
2276.07	638
2278.92	654
2281.76	616
2284.6	638
2287.44	618
2290.28	650
2293.12	672
2295.95	674
2298.79	650
2301.62	680
2304.46	630
2307.29	652
2310.12	660
2312.95	694
2315.78	652
2318.61	688
2321.44	696
2324.27	704
2327.09	708
2329.92	736
2332.74	708
2335.56	702
2338.38	700
2341.2	694
2344.02	716
2346.84	710
2349.66	730
2352.48	728
2355.29	738
2358.11	756
2360.92	764
2363.73	758
2366.54	768
2369.35	780
2372.16	766
2374.97	770
2377.78	750
2380.58	774
2383.39	780
2386.19	756
2389	786
2391.8	780
2394.6	810
2397.4	802
2400.2	834
2403	804
2405.79	782
2408.59	826
2411.38	818
2414.18	816
2416.97	828
2419.76	810
2422.55	840
2425.34	828
2428.13	818
2430.92	852
2433.71	826
2436.49	834
2439.28	826
2442.06	842
2444.85	848
2447.63	816
2450.41	860
2453.19	864
2455.97	846
2458.75	838
2461.52	816
2464.3	828
2467.07	816
2469.85	834
2472.62	856
2475.39	814
2478.16	830
2480.94	834
2483.7	816
2486.47	848
2489.24	806
2492	832
2494.77	812
2497.53	828
2500.3	834
2503.06	840
2505.82	794
2508.58	844
2511.34	816
2514.1	844
2516.85	834
2519.61	798
2522.37	842
2525.12	824
2527.87	808
2530.63	864
2533.38	862
2536.13	854
2538.88	830
2541.62	838
2544.37	816
2547.12	836
2549.86	828
2552.61	818
2555.35	862
2558.09	854
2560.84	844
2563.57	814
2566.32	844
2569.05	850
2571.79	822
2574.53	828
2577.26	834
2580	808
2582.73	852
2585.46	808
2588.19	840
2590.93	864
2593.66	848
2596.39	852
2599.11	834
2601.84	828
2604.56	870
2607.29	832
2610.01	880
2612.74	848
2615.46	862
2618.18	870
2620.9	852
2623.62	874
2626.34	862
2629.05	858
2631.77	874
2634.48	860
2637.2	896
2639.91	864
2642.62	840
2645.33	878
2648.05	882
2650.75	884
2653.46	862
2656.17	876
2658.88	878
2661.58	868
2664.29	910
2666.99	902
2669.69	882
2672.39	908
2675.09	876
2677.79	898
2680.49	892
2683.19	872
2685.89	894
2688.58	918
2691.28	904
2693.97	900
2696.67	906
2699.36	866
2702.05	884
2704.74	922
2707.43	912
2710.12	902
2712.8	890
2715.49	876
2718.17	882
2720.86	926
2723.54	920
2726.22	900
2728.91	880
2731.59	910
2734.27	908
2736.95	912
2739.62	932
2742.3	916
2744.98	908
2747.65	892
2750.33	884
2753	928
2755.67	950
2758.34	912
2761.01	918
2763.68	930
2766.35	936
2769.02	916
2771.68	926
2774.35	960
2777.01	928
2779.68	950
2782.34	986
2785	960
2787.66	916
2790.32	956
2792.98	926
2795.64	980
2798.3	1000
2800.95	942
2803.61	930
2806.26	1012
2808.91	968
2811.57	970
2814.22	980
2816.87	986
2819.52	958
2822.17	990
2824.81	998
2827.46	1030
2830.11	1022
2832.75	1028
2835.39	998
2838.04	1018
2840.68	996
2843.32	1026
2845.96	1024
2848.6	1038
2851.24	1020
2853.88	1078
2856.51	1064
2859.15	1038
2861.78	1066
2864.42	1022
2867.05	1044
2869.68	1002
2872.31	1078
2874.94	1046
2877.57	1088
2880.2	1108
2882.82	1088
2885.45	1030
2888.08	1068
2890.7	1054
2893.33	1076
2895.95	1110
2898.57	1086
2901.19	1090
2903.81	1134
2906.43	1058
2909.05	1094
2911.66	1110
2914.28	1102
2916.89	1110
2919.51	1097.49
2922.12	1111.26
2924.73	1107.1
2927.35	1111.5
2929.96	1113.5
2932.57	1108.37
2935.17	1124.88
2937.78	1103.26
2940.39	1101.91
2943	1099.57
2945.6	1123.66
2948.2	1119.32
2950.81	1129.33
2953.41	1093.1
2956.01	1107.15
2958.61	1145.51
2961.21	1120.19
2963.81	1156.11
2966.41	1119.42
2969.01	1128.67
2971.6	1161.02
2974.2	1143.07
2976.79	1152.32
2979.39	1171.54
2981.98	1123.62
2984.57	1142.08
2987.16	1168.94
2989.75	1146.72
2992.34	1144.43
2994.93	1164.54
2997.51	1179.6
3000.1	1170.96
3002.68	1167.23
3005.27	1178.9
3007.85	1174.33
3010.43	1163.43
3013.01	1165.89
3015.59	1200.77
3018.18	1187.39
3020.75	1209.82
3023.33	1203.69
3025.91	1209.36
3028.48	1209.96
3031.06	1203.31
3033.64	1208.43
3036.21	1228.82
3038.78	1207.92
3041.35	1221.78
3043.92	1219.36
3046.49	1221.32
3048.11	1276
3050.69	1194
3053.27	1266
3055.85	1234
3058.43	1242
3061.01	1218
3063.58	1266
3066.16	1278
3068.73	1236
3071.31	1250
3073.88	1266
3076.45	1266
3079.02	1268
3081.59	1278
3084.16	1272
3086.73	1302
3089.29	1306
3091.86	1286
3094.43	1310
3096.99	1316
3099.55	1298
3102.12	1272
3104.68	1324
3107.24	1282
3109.8	1312
3112.36	1300
3114.92	1300
3117.48	1326
3120.03	1364
3122.59	1376
3125.14	1310
3127.7	1382
3130.25	1388
3132.8	1338
3135.35	1378
3137.9	1390
3140.45	1382
3143	1352
3145.55	1394
3148.1	1398
3150.64	1392
3153.19	1406
3155.73	1430
3158.28	1410
3160.82	1396
3163.36	1432
3165.9	1420
3168.44	1448
3170.98	1464
3173.52	1450
3176.06	1470
3178.59	1478
3181.13	1464
3183.66	1478
3186.2	1508
3188.73	1464
3191.26	1458
3193.79	1454
3196.32	1492
3198.85	1464
3201.38	1476
3203.91	1502
3206.44	1512
3208.96	1510
3211.49	1490
3214.01	1524
3216.54	1486
3219.06	1504
3221.58	1518
3224.1	1482
3226.62	1538
3229.14	1502
3231.66	1524
3234.18	1516
3236.69	1530
3239.21	1558
3241.72	1534
3244.24	1512
3246.75	1498
3249.26	1562
3251.78	1552
3254.29	1566
3256.8	1556
3259.3	1600
3261.81	1586
3264.32	1600
3266.83	1578
3269.33	1594
3271.84	1586
3274.34	1646
3276.84	1596
3279.35	1620
3281.85	1620
3284.35	1604
3286.85	1650
3289.35	1650
3291.84	1638
3294.34	1628
3296.84	1630
3299.33	1630
3301.83	1640
3304.32	1640
3306.81	1694
3309.3	1676
3311.79	1708
3314.29	1670
3316.77	1686
3319.26	1700
3321.75	1710
3324.24	1748
3326.72	1722
3329.21	1728
3331.69	1712
3334.18	1728
3336.66	1734
3339.14	1744
3341.62	1694
3344.1	1736
3346.58	1748
3349.06	1756
3351.54	1724
3354.01	1798
3356.49	1750
3358.96	1728
3361.44	1740
3363.91	1750
3366.38	1754
3368.85	1762
3371.33	1782
3373.8	1756
3376.26	1814
3378.73	1768
3381.2	1810
3383.67	1774
3386.13	1792
3388.6	1802
3391.06	1818
3393.52	1776
3395.99	1810
3398.45	1840
3400.91	1814
3403.37	1812
3405.83	1882
3408.29	1838
3410.74	1850
3413.2	1794
3415.66	1860
3418.11	1892
3420.56	1878
3423.02	1898
3425.47	1902
3427.92	1844
3430.37	1944
3432.82	1942
3435.27	1946
3437.72	1920
3440.17	1994
3442.61	1946
3445.06	1990
3447.51	1922
3449.95	1950
3452.39	1984
3454.83	1980
3457.28	1972
3459.72	1972
3462.16	2042
3464.6	2026
3467.04	2016
3469.47	2024
3471.91	2012
3474.34	2010
3476.78	2028
3479.21	2044
3481.65	2004
3484.08	2068
3486.51	2028
3488.94	2016
3491.37	2030
3493.8	1980
3496.23	2034
3498.66	2092
3501.09	2046
3503.51	2032
3505.94	2062
3508.36	2026
3510.79	2036
3513.21	2116
3515.63	2076
3518.05	2068
3520.47	2038
3522.89	2058
3525.31	2042
3527.73	2054
3530.14	2078
3532.56	2088
3534.98	2046
3537.39	2084
3539.81	2090
3542.22	2118
3544.63	2080
3547.04	2104
3549.45	2108
3551.86	2062
3554.27	2120
3556.68	2100
3559.09	2144
3561.49	2160
3563.9	2128
3566.3	2154
3568.71	2148
3571.11	2152
3573.51	2158
3575.92	2176
3578.32	2186
3580.72	2200
3583.12	2188
3585.51	2202
3587.91	2148
3590.31	2222
3592.71	2224
3595.1	2242
3597.49	2258
3599.89	2240
3602.28	2252
3604.67	2260
3607.06	2254
3609.45	2288
3611.84	2340
3614.23	2358
3616.62	2288
3619.01	2282
3621.39	2292
3623.78	2350
3626.17	2334
3628.55	2334
3630.93	2364
3633.31	2340
3635.7	2320
3638.08	2314
3640.46	2324
3642.84	2384
3645.22	2328
3647.59	2290
3649.97	2336
3652.35	2362
3654.72	2366
3657.1	2316
3659.47	2356
3661.84	2332
3664.21	2348
3666.59	2336
3668.96	2376
3671.33	2352
3673.69	2362
3676.06	2320
3678.43	2352
3680.8	2332
3683.16	2324
3685.53	2398
3687.89	2414
3690.25	2370
3692.62	2362
3694.98	2404
3697.34	2412
3699.7	2370
3702.06	2406
3704.42	2424
3706.78	2448
3709.13	2402
3711.49	2402
3713.85	2420
3716.2	2488
3718.56	2486
3720.91	2382
3723.26	2418
3725.61	2438
3727.96	2512
3730.31	2470
3732.66	2470
3735.01	2482
3737.36	2526
3739.7	2480
3742.05	2462
3744.4	2526
3746.74	2532
3749.09	2550
3751.43	2496
3753.77	2592
3756.11	2546
3758.45	2560
3760.79	2632
3763.13	2584
3765.47	2570
3767.81	2566
3770.14	2610
3772.48	2610
3774.82	2644
3777.15	2558
3779.48	2604
3781.82	2608
3784.15	2626
3786.48	2580
3788.81	2628
3791.14	2622
3793.47	2646
3795.8	2574
3798.13	2600
3800.45	2640
3802.78	2624
3805.1	2606
3807.43	2618
3809.75	2654
3812.07	2682
3814.4	2626
3816.72	2586
3819.04	2596
3821.36	2652
3823.68	2586
3826	2626
3828.31	2642
3830.63	2616
3832.95	2632
3835.26	2628
3837.58	2644
3839.89	2678
3842.2	2670
3844.51	2590
3846.83	2648
3849.14	2650
3851.45	2658
3853.76	2616
3856.06	2682
3858.37	2696
3860.68	2608
3862.98	2682
3865.29	2662
3867.59	2708
3869.9	2748
3872.2	2716
3874.5	2766
3876.8	2760
3879.1	2788
3881.4	2776
3883.7	2806
3886	2760
3888.3	2764
3890.6	2768
3892.89	2774
3895.19	2818
3897.48	2828
3899.78	2838
3902.07	2814
3904.36	2828
3906.65	2784
3908.94	2850
3911.23	2858
3913.52	2898
3915.81	2860
3918.1	2816
3920.39	2856
3922.67	2866
3924.96	2870
3927.24	2940
3929.53	2844
3931.81	2842
3934.09	2888
3936.38	2894
3938.66	2890
3940.94	2848
3943.22	2892
3945.5	2862
3947.77	2868
3950.05	2864
3952.33	2884
3954.6	2944
3956.88	2940
3959.15	2922
3961.43	2852
3963.7	2956
3965.97	2866
3968.24	2922
3970.51	2856
3972.78	2876
3975.05	2900
3977.32	2904
3979.59	2900
3981.85	2876
3984.12	2882
3986.39	2894
3988.65	2884
3990.91	2928
3993.18	2936
3995.44	2898
3997.7	2916
3999.96	2950