File: DataDrivenSE/datosramanb/CN-Sastre_19.txt
#Acq. time (s)=	20
#Accumulations=	2
#Range (cm-¹)=	50...4000
#Windows=	3
#Autofocus=	Off
#AutoExposure=	Off
#Spike filter=	Multiple accum.
#Delay time (s)=	0
#Binning=	1
#Readout mode=	Signal
#DeNoise=	Off
#ICS correction=	Off
#Dark correction=	Off
#Inst. Process=	Off
#Instrument=	LabRAM HR Evol
#Detector=	Syncerity OE
#Objective=	x100_VIS
#Grating=	600 (500nm)
#ND Filter=	100%
#Laser=	532nm_Edge
#Hole=	100.021
#Range=	Visible
#Project=	Omar
#Sample=
#Site=	21-09-22
#Title=	 CN-Sastre
#Remark=
#Date=	21.09.2022 14:19
#Acquired=	21.09.2022 14:19:06
51.0918	40
54.7807	50
58.4681	90
62.154	204
65.8385	334
69.5216	540
73.2032	872
76.8834	1214
80.5621	1472
84.2393	1744
87.9152	1936
91.5874	2016
95.2603	1988
98.9318	1978
102.602	1962
106.27	2050
109.936	1986
113.601	2018
117.266	2030
120.926	1968
124.588	1934
128.246	1912
131.904	1880
135.561	1866
139.215	1910
142.869	1844
146.52	1898
150.171	1834
153.819	1894
157.465	1812
161.112	1850
164.756	1792
168.398	1784
172.041	1802
175.68	1784
179.318	1790
182.955	1780
186.592	1818
190.225	1754
193.857	1752
197.488	1764
201.118	1678
204.746	1674
208.372	1664
211.997	1676
215.621	1662
219.243	1616
222.864	1670
226.483	1628
230.101	1578
233.718	1594
237.331	1618
240.945	1594
244.557	1624
248.168	1612
251.776	1606
255.384	1614
258.991	1620
262.594	1598
266.198	1566
269.799	1568
273.4	1630
277	1598
280.596	1578
284.193	1626
287.786	1554
291.378	1566
294.971	1572
298.561	1562
302.148	1602
305.737	1636
309.322	1666
312.906	1654
316.49	1634
320.071	1608
323.651	1668
327.229	1618
330.806	1612
334.381	1624
337.955	1610
341.528	1624
345.099	1628
348.669	1566
352.238	1656
355.805	1640
359.371	1630
362.935	1594
366.498	1634
370.06	1640
373.62	1636
377.177	1700
380.734	1656
384.29	1676
387.845	1670
391.396	1672
394.948	1648
398.499	1662
402.046	1690
405.594	1658
409.138	1676
412.683	1672
416.225	1652
419.768	1688
423.307	1706
426.844	1622
430.382	1704
433.917	1708
437.451	1734
440.985	1714
444.516	1752
448.045	1686
451.574	1732
455.102	1722
458.628	1704
462.152	1716
465.674	1718
469.196	1678
472.716	1666
476.234	1720
479.752	1710
483.268	1700
486.782	1694
490.295	1626
493.807	1654
497.316	1674
500.825	1688
504.333	1630
507.839	1652
511.344	1660
514.846	1670
518.349	1694
521.85	1670
525.347	1756
528.846	1766
532.341	1844
535.837	1898
539.329	1948
542.822	2090
546.312	2126
549.802	2180
553.289	2198
556.775	2256
560.261	2246
563.744	2198
567.226	2196
570.709	2164
574.188	2136
577.665	2028
581.142	2024
584.617	1956
588.091	1928
591.565	1860
595.036	1782
598.506	1800
601.974	1722
605.442	1694
608.905	1622
612.37	1632
615.833	1612
619.295	1578
622.755	1532
626.215	1490
629.67	1462
633.127	1466
636.582	1488
640.036	1462
643.487	1458
646.938	1388
650.386	1394
653.835	1372
657.282	1322
660.726	1282
664.171	1278
667.613	1294
671.053	1276
674.494	1270
677.931	1234
681.369	1160
684.804	1150
688.238	1162
691.67	1126
695.103	1088
698.533	1064
701.961	1010
705.389	994
708.814	992
712.239	984
715.662	966
719.084	940
722.505	990
725.924	940
729.342	956
732.759	946
736.174	916
739.589	960
742.999	946
746.411	924
749.821	926
753.23	926
756.636	958
760.043	990
763.448	982
766.85	1008
770.252	986
773.652	960
777.052	992
780.448	990
783.846	982
787.24	962
790.635	926
794.027	960
797.417	978
800.808	950
804.196	948
807.582	924
810.968	910
814.354	930
817.736	890
821.118	868
824.498	892
827.877	846
831.254	826
834.631	808
838.006	812
841.38	828
844.752	778
848.123	788
851.493	796
854.86	778
858.228	750
861.594	808
864.959	784
868.321	758
871.683	790
875.044	786
878.402	750
881.761	802
885.116	816
888.472	774
891.825	816
895.179	794
898.529	830
901.88	826
905.228	836
908.575	866
911.922	898
915.266	864
918.609	892
921.951	898
925.293	912
928.633	956
931.97	970
935.307	958
938.642	984
941.977	1008
945.31	1040
948.641	1016
951.972	994
955.301	1038
958.629	1032
961.955	1014
965.279	1020
968.603	1034
971.926	1034
975.248	1046
978.566	1086
981.886	1052
985.204	1120
988.519	1110
991.834	1120
995.147	1122
998.46	1112
1001.77	1132
1005.08	1164
1008.39	1144
1011.7	1166
1015	1184
1018.3	1226
1021.61	1274
1024.91	1270
1028.21	1320
1031.51	1374
1034.81	1364
1038.1	1356
1041.4	1428
1044.69	1466
1047.99	1520
1051.28	1540
1054.57	1538
1057.86	1606
1061.14	1682
1064.43	1678
1067.72	1736
1071	1814
1074.28	1850
1077.57	1918
1080.84	1950
1084.12	1938
1087.4	1966
1090.68	1996
1093.95	2064
1097.22	1982
1100.5	1978
1103.77	1938
1107.04	1886
1110.31	1834
1113.58	1782
1116.84	1722
1120.1	1664
1123.37	1616
1126.63	1554
1129.89	1494
1133.15	1426
1136.41	1376
1139.67	1372
1142.92	1316
1146.18	1260
1149.43	1258
1152.68	1200
1155.93	1198
1159.18	1136
1162.43	1138
1165.68	1118
1168.93	1104
1172.17	1082
1175.41	1052
1178.66	1004
1181.9	990
1185.14	982
1188.37	926
1191.61	954
1194.85	946
1198.08	912
1201.31	912
1204.55	922
1207.78	900
1211.01	884
1214.24	840
1217.46	830
1220.69	834
1223.91	844
1227.14	836
1230.36	820
1233.58	848
1236.8	846
1240.02	828
1243.23	826
1246.45	844
1249.67	820
1252.88	840
1256.09	830
1259.3	852
1262.51	840
1265.72	852
1268.93	888
1272.13	836
1275.34	872
1278.54	870
1281.74	880
1284.94	884
1288.15	937
1291.34	940
1294.54	970
1297.74	996
1300.93	994
1304.12	1042
1307.32	1044
1310.51	1102
1313.7	1108
1316.89	1146
1320.07	1190
1323.26	1240
1326.45	1312
1329.63	1324
1332.81	1362
1335.99	1414
1339.17	1444
1342.35	1478
1345.53	1442
1348.71	1436
1351.88	1448
1355.06	1402
1358.23	1374
1361.4	1358
1364.57	1296
1367.74	1226
1370.91	1188
1374.08	1120
1377.24	1098
1380.41	1056
1383.57	1054
1386.73	1040
1389.89	980
1393.05	1010
1396.21	948
1399.37	976
1402.52	912
1405.68	908
1408.83	936
1411.98	874
1415.13	888
1418.29	928
1421.43	884
1424.58	876
1427.73	914
1430.87	874
1434.02	888
1437.16	844
1440.3	868
1443.44	830
1446.58	854
1449.72	846
1452.85	868
1455.99	868
1459.12	824
1462.26	886
1465.39	864
1468.52	856
1471.65	880
1474.78	838
1477.9	852
1481.03	862
1484.16	864
1487.28	886
1490.4	874
1493.52	884
1496.64	886
1499.76	884
1502.88	880
1506	878
1509.11	914
1512.22	904
1515.34	874
1518.45	920
1521.56	900
1524.67	946
1527.78	942
1530.88	926
1533.99	954
1537.09	948
1540.2	1002
1543.3	1046
1546.4	1070
1549.5	1098
1552.6	1112
1555.7	1188
1558.79	1246
1561.89	1320
1564.98	1396
1568.08	1502
1571.17	1620
1574.26	1694
1577.35	1778
1580.43	1748
1583.52	1666
1586.61	1576
1589.69	1456
1592.77	1340
1595.86	1316
1598.94	1280
1602.02	1212
1605.1	1176
1608.18	1185.4
1611.25	1191.99
1614.33	1185.54
1617.4	1126.61
1620.47	1084.27
1623.55	994.576
1626.62	983.998
1629.69	944.941
1632.75	922.25
1635.82	921.849
1638.89	873.263
1641.95	860.26
1645.02	849.407
1648.08	831.302
1651.14	835.187
1654.2	837.326
1657.26	825.644
1660.32	823.054
1663.37	832.138
1666.43	824.702
1669.48	817.508
1672.54	815.037
1675.59	814.44
1678.64	785.441
1681.69	785.054
1684.74	808.932
1687.79	797.399
1690.83	813.341
1693.88	786.478
1696.92	804.587
1699.96	798.146
1703.01	796.86
1706.05	803.415
1709.09	798.825
1712.12	786.261
1715.16	789.606
1718.2	803.988
1721.23	828.147
1724.27	794.92
1727.3	771.969
1730.33	790.164
1733.36	798.695
1736.39	801.488
1739.42	828.382
1742.44	763.285
1745.47	784.627
1748.49	774.745
1751.52	815.833
1754.54	794.984
1757.56	757.431
1759.14	776
1762.18	788
1765.21	782
1768.24	758
1771.27	804
1774.3	770
1777.32	780
1780.35	774
1783.38	780
1786.4	792
1789.42	764
1792.44	792
1795.47	768
1798.48	782
1801.5	784
1804.52	790
1807.54	778
1810.55	820
1813.57	782
1816.58	750
1819.59	780
1822.6	786
1825.61	764
1828.62	784
1831.63	826
1834.63	770
1837.64	762
1840.64	808
1843.64	812
1846.64	788
1849.64	764
1852.64	820
1855.64	776
1858.64	802
1861.64	776
1864.63	786
1867.63	774
1870.62	776
1873.61	762
1876.6	834
1879.59	790
1882.58	796
1885.56	792
1888.55	804
1891.54	794
1894.52	780
1897.5	810
1900.48	788
1903.46	790
1906.44	764
1909.42	788
1912.4	816
1915.38	792
1918.35	814
1921.32	770
1924.3	758
1927.27	798
1930.24	778
1933.21	800
1936.18	754
1939.15	810
1942.11	774
1945.08	788
1948.04	782
1951	812
1953.97	754
1956.93	790
1959.89	758
1962.85	778
1965.8	792
1968.76	780
1971.71	806
1974.67	794
1977.62	788
1980.57	754
1983.53	770
1986.48	782
1989.42	762
1992.37	786
1995.32	774
1998.26	762
2001.21	794
2004.15	764
2007.09	776
2010.03	788
2012.98	780
2015.92	802
2018.85	766
2021.79	772
2024.73	780
2027.66	768
2030.59	758
2033.53	798
2036.46	782
2039.39	798
2042.32	780
2045.25	762
2048.17	820
2051.1	780
2054.02	788
2056.95	770
2059.87	806
2062.79	810
2065.71	782
2068.63	806
2071.55	782
2074.47	800
2077.39	770
2080.3	766
2083.22	780
2086.13	766
2089.04	788
2091.95	754
2094.86	776
2097.77	784
2100.68	784
2103.59	748
2106.49	796
2109.4	768
2112.3	774
2115.21	758
2118.11	772
2121.01	788
2123.91	742
2126.8	760
2129.7	750
2132.6	760
2135.49	754
2138.39	738
2141.28	758
2144.17	780
2147.06	746
2149.95	764
2152.84	776
2155.73	772
2158.62	798
2161.5	756
2164.39	786
2167.27	780
2170.15	748
2173.04	772
2175.92	774
2178.79	750
2181.67	788
2184.55	772
2187.43	782
2190.3	762
2193.18	808
2196.05	774
2198.92	772
2201.79	762
2204.66	780
2207.53	740
2210.4	782
2213.27	788
2216.13	750
2219	738
2221.86	762
2224.72	774
2227.59	762
2230.45	742
2233.31	730
2236.16	746
2239.02	730
2241.88	744
2244.73	754
2247.59	742
2250.44	726
2253.29	752
2256.15	766
2259	710
2261.84	714
2264.69	738
2267.54	772
2270.39	730
2273.23	728
2276.07	740
2278.92	768
2281.76	760
2284.6	788
2287.44	724
2290.28	758
2293.12	742
2295.95	748
2298.79	758
2301.62	758
2304.46	776
2307.29	770
2310.12	778
2312.95	748
2315.78	792
2318.61	772
2321.44	772
2324.27	772
2327.09	832
2329.92	826
2332.74	786
2335.56	782
2338.38	802
2341.2	800
2344.02	810
2346.84	814
2349.66	808
2352.48	816
2355.29	844
2358.11	816
2360.92	854
2363.73	806
2366.54	838
2369.35	790
2372.16	820
2374.97	836
2377.78	832
2380.58	854
2383.39	858
2386.19	862
2389	830
2391.8	818
2394.6	894
2397.4	894
2400.2	868
2403	844
2405.79	872
2408.59	858
2411.38	856
2414.18	878
2416.97	858
2419.76	872
2422.55	856
2425.34	882
2428.13	896
2430.92	864
2433.71	880
2436.49	872
2439.28	906
2442.06	898
2444.85	898
2447.63	892
2450.41	918
2453.19	900
2455.97	870
2458.75	920
2461.52	864
2464.3	874
2467.07	902
2469.85	900
2472.62	866
2475.39	876
2478.16	894
2480.94	872
2483.7	872
2486.47	884
2489.24	856
2492	884
2494.77	936
2497.53	910
2500.3	878
2503.06	864
2505.82	870
2508.58	916
2511.34	874
2514.1	886
2516.85	846
2519.61	918
2522.37	884
2525.12	892
2527.87	856
2530.63	896
2533.38	904
2536.13	868
2538.88	858
2541.62	904
2544.37	872
2547.12	876
2549.86	862
2552.61	906
2555.35	876
2558.09	870
2560.84	874
2563.57	902
2566.32	898
2569.05	916
2571.79	872
2574.53	904
2577.26	902
2580	896
2582.73	888
2585.46	906
2588.19	902
2590.93	916
2593.66	906
2596.39	964
2599.11	940
2601.84	952
2604.56	936
2607.29	902
2610.01	944
2612.74	900
2615.46	928
2618.18	966
2620.9	976
2623.62	928
2626.34	980
2629.05	962
2631.77	982
2634.48	938
2637.2	982
2639.91	1004
2642.62	976
2645.33	1004
2648.05	980
2650.75	1092
2653.46	1026
2656.17	1076
2658.88	1112
2661.58	1100
2664.29	1062
2666.99	1064
2669.69	1108
2672.39	1072
2675.09	1118
2677.79	1126
2680.49	1160
2683.19	1130
2685.89	1116
2688.58	1166
2691.28	1168
2693.97	1110
2696.67	1142
2699.36	1110
2702.05	1118
2704.74	1102
2707.43	1144
2710.12	1146
2712.8	1094
2715.49	1096
2718.17	1126
2720.86	1154
2723.54	1136
2726.22	1124
2728.91	1072
2731.59	1088
2734.27	1084
2736.95	1040
2739.62	1048
2742.3	1038
2744.98	1042
2747.65	1030
2750.33	1028
2753	1080
2755.67	1006
2758.34	1012
2761.01	996
2763.68	1010
2766.35	1030
2769.02	1030
2771.68	1014
2774.35	1016
2777.01	996
2779.68	1006
2782.34	980
2785	990
2787.66	986
2790.32	1036
2792.98	1016
2795.64	1014
2798.3	1020
2800.95	962
2803.61	996
2806.26	1020
2808.91	1004
2811.57	1002
2814.22	1030
2816.87	974
2819.52	1006
2822.17	984
2824.81	988
2827.46	1030
2830.11	1034
2832.75	1002
2835.39	990
2838.04	1026
2840.68	1034
2843.32	988
2845.96	1010
2848.6	998
2851.24	1054
2853.88	1046
2856.51	990
2859.15	1020
2861.78	1022
2864.42	1018
2867.05	1030
2869.68	1010
2872.31	1086
2874.94	1044
2877.57	1008
2880.2	1020
2882.82	1014
2885.45	1026
2888.08	1050
2890.7	1074
2893.33	1052
2895.95	1060
2898.57	1064
2901.19	1082
2903.81	1078
2906.43	1072
2909.05	1070
2911.66	1076
2914.28	1086
2916.89	1104
2919.51	1054.17
2922.12	1093.93
2924.73	1077.56
2927.35	1073.21
2929.96	1090.59
2932.57	1092.29
2935.17	1081.28
2937.78	1108.87
2940.39	1106.3
2943	1080.27
2945.6	1076.22
2948.2	1084.7
2950.81	1068.1
2953.41	1091.56
2956.01	1119.92
2958.61	1101.55
2961.21	1108.95
2963.81	1114.63
2966.41	1108.81
2969.01	1075.59
2971.6	1097.37
2974.2	1099.39
2976.79	1083.89
2979.39	1093.18
2981.98	1079.93
2984.57	1113.48
2987.16	1101.69
2989.75	1105.57
2992.34	1117.31
2994.93	1087.62
2997.51	1088.11
3000.1	1087.56
3002.68	1120.42
3005.27	1143.34
3007.85	1107.65
3010.43	1117.62
3013.01	1117.02
3015.59	1082.33
3018.18	1136.88
3020.75	1144.77
3023.33	1108.3
3025.91	1128.89
3028.48	1138.03
3031.06	1127.75
3033.64	1126.39
3036.21	1141.88
3038.78	1111.62
3041.35	1151.98
3043.92	1151.47
3046.49	1157.34
3048.11	1154
3050.69	1140
3053.27	1152
3055.85	1146
3058.43	1156
3061.01	1176
3063.58	1178
3066.16	1136
3068.73	1152
3071.31	1182
3073.88	1172
3076.45	1170
3079.02	1150
3081.59	1154
3084.16	1170
3086.73	1170
3089.29	1212
3091.86	1180
3094.43	1176
3096.99	1210
3099.55	1164
3102.12	1188
3104.68	1188
3107.24	1212
3109.8	1210
3112.36	1240
3114.92	1202
3117.48	1198
3120.03	1208
3122.59	1176
3125.14	1216
3127.7	1214
3130.25	1246
3132.8	1218
3135.35	1200
3137.9	1226
3140.45	1282
3143	1216
3145.55	1222
3148.1	1244
3150.64	1228
3153.19	1252
3155.73	1276
3158.28	1264
3160.82	1262
3163.36	1284
3165.9	1284
3168.44	1262
3170.98	1306
3173.52	1252
3176.06	1250
3178.59	1308
3181.13	1284
3183.66	1298
3186.2	1276
3188.73	1272
3191.26	1282
3193.79	1324
3196.32	1296
3198.85	1282
3201.38	1302
3203.91	1302
3206.44	1302
3208.96	1306
3211.49	1300
3214.01	1318
3216.54	1336
3219.06	1328
3221.58	1310
3224.1	1272
3226.62	1346
3229.14	1330
3231.66	1322
3234.18	1306
3236.69	1390
3239.21	1344
3241.72	1334
3244.24	1310
3246.75	1378
3249.26	1332
3251.78	1336
3254.29	1342
3256.8	1324
3259.3	1362
3261.81	1364
3264.32	1346
3266.83	1378
3269.33	1330
3271.84	1390
3274.34	1382
3276.84	1374
3279.35	1386
3281.85	1370
3284.35	1374
3286.85	1404
3289.35	1340
3291.84	1378
3294.34	1400
3296.84	1426
3299.33	1358
3301.83	1408
3304.32	1426
3306.81	1440
3309.3	1410
3311.79	1436
3314.29	1470
3316.77	1456
3319.26	1450
3321.75	1430
3324.24	1470
3326.72	1482
3329.21	1452
3331.69	1434
3334.18	1440
3336.66	1474
3339.14	1444
3341.62	1438
3344.1	1490
3346.58	1468
3349.06	1494
3351.54	1474
3354.01	1462
3356.49	1496
3358.96	1456
3361.44	1460
3363.91	1454
3366.38	1472
3368.85	1464
3371.33	1492
3373.8	1444
3376.26	1510
3378.73	1522
3381.2	1510
3383.67	1456
3386.13	1492
3388.6	1514
3391.06	1482
3393.52	1492
3395.99	1504
3398.45	1476
3400.91	1488
3403.37	1542
3405.83	1536
3408.29	1522
3410.74	1574
3413.2	1556
3415.66	1550
3418.11	1582
3420.56	1552
3423.02	1568
3425.47	1556
3427.92	1632
3430.37	1558
3432.82	1572
3435.27	1630
3437.72	1602
3440.17	1626
3442.61	1518
3445.06	1626
3447.51	1630
3449.95	1634
3452.39	1638
3454.83	1622
3457.28	1616
3459.72	1676
3462.16	1676
3464.6	1632
3467.04	1702
3469.47	1646
3471.91	1652
3474.34	1674
3476.78	1684
3479.21	1688
3481.65	1664
3484.08	1654
3486.51	1692
3488.94	1638
3491.37	1672
3493.8	1654
3496.23	1628
3498.66	1706
3501.09	1640
3503.51	1626
3505.94	1698
3508.36	1696
3510.79	1690
3513.21	1696
3515.63	1658
3518.05	1712
3520.47	1696
3522.89	1714
3525.31	1656
3527.73	1718
3530.14	1684
3532.56	1684
3534.98	1680
3537.39	1658
3539.81	1664
3542.22	1674
3544.63	1694
3547.04	1682
3549.45	1676
3551.86	1730
3554.27	1710
3556.68	1706
3559.09	1712
3561.49	1718
3563.9	1736
3566.3	1752
3568.71	1782
3571.11	1796
3573.51	1752
3575.92	1774
3578.32	1712
3580.72	1764
3583.12	1798
3585.51	1782
3587.91	1772
3590.31	1794
3592.71	1800
3595.1	1792
3597.49	1820
3599.89	1834
3602.28	1824
3604.67	1780
3607.06	1808
3609.45	1858
3611.84	1846
3614.23	1808
3616.62	1798
3619.01	1824
3621.39	1808
3623.78	1852
3626.17	1836
3628.55	1870
3630.93	1876
3633.31	1878
3635.7	1834
3638.08	1792
3640.46	1854
3642.84	1850
3645.22	1866
3647.59	1872
3649.97	1852
3652.35	1898
3654.72	1824
3657.1	1830
3659.47	1824
3661.84	1866
3664.21	1842
3666.59	1818
3668.96	1876
3671.33	1892
3673.69	1848
3676.06	1810
3678.43	1852
3680.8	1846
3683.16	1876
3685.53	1858
3687.89	1842
3690.25	1914
3692.62	1846
3694.98	1858
3697.34	1886
3699.7	1850
3702.06	1900
3704.42	1916
3706.78	1884
3709.13	1944
3711.49	1892
3713.85	1890
3716.2	1886
3718.56	1924
3720.91	1872
3723.26	1896
3725.61	1936
3727.96	1922
3730.31	1982
3732.66	1986
3735.01	1954
3737.36	2020
3739.7	1914
3742.05	1964
3744.4	1994
3746.74	2002
3749.09	2026
3751.43	1988
3753.77	2066
3756.11	1986
3758.45	2026
3760.79	2026
3763.13	2042
3765.47	2012
3767.81	2006
3770.14	2076
3772.48	2038
3774.82	2030
3777.15	2050
3779.48	2052
3781.82	1996
3784.15	2054
3786.48	2012
3788.81	2102
3791.14	2070
3793.47	2016
3795.8	2004
3798.13	2022
3800.45	2072
3802.78	2046
3805.1	2048
3807.43	2032
3809.75	2024
3812.07	2062
3814.4	2074
3816.72	2062
3819.04	2002
3821.36	2014
3823.68	2038
3826	2008
3828.31	2084
3830.63	2026
3832.95	2058
3835.26	2050
3837.58	1994
3839.89	2060
3842.2	2050
3844.51	2098
3846.83	2014
3849.14	2036
3851.45	2054
3853.76	1998
3856.06	2048
3858.37	2030
3860.68	2102
3862.98	2068
3865.29	2132
3867.59	2072
3869.9	2104
3872.2	2136
3874.5	2084
3876.8	2088
3879.1	2100
3881.4	2080
3883.7	2076
3886	2130
3888.3	2172
3890.6	2120
3892.89	2176
3895.19	2184
3897.48	2108
3899.78	2188
3902.07	2190
3904.36	2224
3906.65	2194
3908.94	2186
3911.23	2228
3913.52	2196
3915.81	2160
3918.1	2202
3920.39	2208
3922.67	2202
3924.96	2242
3927.24	2222
3929.53	2214
3931.81	2210
3934.09	2164
3936.38	2228
3938.66	2234
3940.94	2224
3943.22	2246
3945.5	2198
3947.77	2188
3950.05	2206
3952.33	2222
3954.6	2182
3956.88	2208
3959.15	2250
3961.43	2240
3963.7	2236
3965.97	2242
3968.24	2198
3970.51	2274
3972.78	2256
3975.05	2238
3977.32	2256
3979.59	2202
3981.85	2204
3984.12	2258
3986.39	2204
3988.65	2222
3990.91	2244
3993.18	2250
3995.44	2218
3997.7	2248
3999.96	2256