File: DataDrivenSE/datosramanb/CN-Sastre_14.txt
#Acq. time (s)=	20
#Accumulations=	2
#Range (cm-¹)=	50...4000
#Windows=	3
#Autofocus=	Off
#AutoExposure=	Off
#Spike filter=	Multiple accum.
#Delay time (s)=	0
#Binning=	1
#Readout mode=	Signal
#DeNoise=	Off
#ICS correction=	Off
#Dark correction=	Off
#Inst. Process=	Off
#Instrument=	LabRAM HR Evol
#Detector=	Syncerity OE
#Objective=	x100_VIS
#Grating=	600 (500nm)
#ND Filter=	100%
#Laser=	532nm_Edge
#Hole=	100.021
#Range=	Visible
#Project=	Omar
#Sample=
#Site=	21-09-22
#Title=	 CN-Sastre
#Remark=
#Date=	21.09.2022 13:48
#Acquired=	21.09.2022 13:48:49
51.0918	42
54.7807	46
58.4681	86
62.154	202
65.8385	312
69.5216	480
73.2032	858
76.8834	1100
80.5621	1436
84.2393	1694
87.9152	1824
91.5874	1936
95.2603	1884
98.9318	1860
102.602	1864
106.27	1994
109.936	1940
113.601	1950
117.266	1972
120.926	1934
124.588	1864
128.246	1872
131.904	1860
135.561	1910
139.215	1914
142.869	1906
146.52	1832
150.171	1878
153.819	1842
157.465	1840
161.112	1840
164.756	1794
168.398	1832
172.041	1812
175.68	1838
179.318	1780
182.955	1744
186.592	1784
190.225	1768
193.857	1778
197.488	1700
201.118	1756
204.746	1752
208.372	1734
211.997	1736
215.621	1728
219.243	1614
222.864	1696
226.483	1654
230.101	1702
233.718	1698
237.331	1664
240.945	1622
244.557	1706
248.168	1682
251.776	1636
255.384	1674
258.991	1672
262.594	1654
266.198	1640
269.799	1656
273.4	1662
277	1650
280.596	1698
284.193	1670
287.786	1652
291.378	1732
294.971	1696
298.561	1634
302.148	1714
305.737	1728
309.322	1742
312.906	1732
316.49	1756
320.071	1736
323.651	1724
327.229	1696
330.806	1744
334.381	1758
337.955	1740
341.528	1740
345.099	1768
348.669	1722
352.238	1770
355.805	1740
359.371	1750
362.935	1722
366.498	1772
370.06	1790
373.62	1760
377.177	1820
380.734	1858
384.29	1812
387.845	1846
391.396	1840
394.948	1832
398.499	1818
402.046	1812
405.594	1758
409.138	1776
412.683	1802
416.225	1794
419.768	1808
423.307	1808
426.844	1750
430.382	1774
433.917	1798
437.451	1824
440.985	1798
444.516	1814
448.045	1840
451.574	1828
455.102	1840
458.628	1884
462.152	1840
465.674	1882
469.196	1806
472.716	1808
476.234	1758
479.752	1842
483.268	1748
486.782	1712
490.295	1792
493.807	1716
497.316	1756
500.825	1758
504.333	1754
507.839	1740
511.344	1750
514.846	1758
518.349	1744
521.85	1800
525.347	1906
528.846	1830
532.341	1988
535.837	2100
539.329	2186
542.822	2158
546.312	2274
549.802	2348
553.289	2356
556.775	2382
560.261	2412
563.744	2380
567.226	2324
570.709	2336
574.188	2322
577.665	2234
581.142	2206
584.617	2160
588.091	2146
591.565	2058
595.036	2052
598.506	2024
601.974	1980
605.442	1902
608.905	1854
612.37	1810
615.833	1800
619.295	1776
622.755	1712
626.215	1722
629.67	1650
633.127	1604
636.582	1656
640.036	1576
643.487	1550
646.938	1562
650.386	1498
653.835	1500
657.282	1430
660.726	1426
664.171	1404
667.613	1378
671.053	1318
674.494	1260
677.931	1312
681.369	1248
684.804	1222
688.238	1170
691.67	1162
695.103	1142
698.533	1134
701.961	1094
705.389	1106
708.814	1076
712.239	1038
715.662	1026
719.084	1002
722.505	966
725.924	986
729.342	1026
732.759	986
736.174	972
739.589	1004
742.999	1000
746.411	1000
749.821	1012
753.23	970
756.636	982
760.043	1018
763.448	1026
766.85	1044
770.252	1098
773.652	1058
777.052	1070
780.448	1058
783.846	1040
787.24	1086
790.635	1060
794.027	1044
797.417	988
800.808	1036
804.196	1020
807.582	972
810.968	960
814.354	968
817.736	910
821.118	892
824.498	902
827.877	866
831.254	872
834.631	870
838.006	852
841.38	838
844.752	826
848.123	816
851.493	812
854.86	778
858.228	810
861.594	802
864.959	796
868.321	780
871.683	856
875.044	810
878.402	834
881.761	784
885.116	806
888.472	818
891.825	830
895.179	852
898.529	846
901.88	854
905.228	856
908.575	874
911.922	860
915.266	902
918.609	910
921.951	908
925.293	1016
928.633	1000
931.97	1042
935.307	1032
938.642	1098
941.977	1080
945.31	1086
948.641	1112
951.972	1130
955.301	1136
958.629	1128
961.955	1114
965.279	1132
968.603	1136
971.926	1126
975.248	1158
978.566	1164
981.886	1180
985.204	1170
988.519	1208
991.834	1254
995.147	1228
998.46	1264
1001.77	1256
1005.08	1264
1008.39	1236
1011.7	1328
1015	1338
1018.3	1366
1021.61	1382
1024.91	1406
1028.21	1468
1031.51	1466
1034.81	1500
1038.1	1578
1041.4	1588
1044.69	1662
1047.99	1680
1051.28	1728
1054.57	1762
1057.86	1842
1061.14	1854
1064.43	1886
1067.72	1980
1071	2024
1074.28	2074
1077.57	2138
1080.84	2216
1084.12	2218
1087.4	2252
1090.68	2260
1093.95	2324
1097.22	2314
1100.5	2306
1103.77	2240
1107.04	2262
1110.31	2136
1113.58	2058
1116.84	1962
1120.1	1918
1123.37	1852
1126.63	1796
1129.89	1706
1133.15	1664
1136.41	1614
1139.67	1520
1142.92	1508
1146.18	1426
1149.43	1360
1152.68	1352
1155.93	1264
1159.18	1228
1162.43	1256
1165.68	1220
1168.93	1206
1172.17	1152
1175.41	1096
1178.66	1070
1181.9	1026
1185.14	1020
1188.37	1004
1191.61	994
1194.85	978
1198.08	948
1201.31	908
1204.55	898
1207.78	906
1211.01	886
1214.24	860
1217.46	840
1220.69	814
1223.91	794
1227.14	782
1230.36	756
1233.58	810
1236.8	800
1240.02	736
1243.23	802
1246.45	778
1249.67	738
1252.88	764
1256.09	762
1259.3	782
1262.51	750
1265.72	802
1268.93	790
1272.13	766
1275.34	798
1278.54	758
1281.74	740
1284.94	748
1288.15	787
1291.34	788
1294.54	758
1297.74	788
1300.93	766
1304.12	758
1307.32	780
1310.51	774
1313.7	830
1316.89	792
1320.07	772
1323.26	800
1326.45	776
1329.63	788
1332.81	814
1335.99	828
1339.17	796
1342.35	752
1345.53	804
1348.71	820
1351.88	772
1355.06	790
1358.23	774
1361.4	810
1364.57	780
1367.74	790
1370.91	778
1374.08	768
1377.24	774
1380.41	782
1383.57	776
1386.73	786
1389.89	798
1393.05	758
1396.21	816
1399.37	782
1402.52	786
1405.68	792
1408.83	812
1411.98	768
1415.13	794
1418.29	812
1421.43	786
1424.58	792
1427.73	772
1430.87	786
1434.02	810
1437.16	802
1440.3	794
1443.44	818
1446.58	824
1449.72	786
1452.85	828
1455.99	790
1459.12	794
1462.26	786
1465.39	776
1468.52	794
1471.65	796
1474.78	834
1477.9	828
1481.03	808
1484.16	772
1487.28	796
1490.4	788
1493.52	792
1496.64	848
1499.76	854
1502.88	806
1506	834
1509.11	842
1512.22	814
1515.34	826
1518.45	854
1521.56	820
1524.67	832
1527.78	818
1530.88	806
1533.99	798
1537.09	846
1540.2	816
1543.3	822
1546.4	822
1549.5	842
1552.6	842
1555.7	870
1558.79	896
1561.89	814
1564.98	810
1568.08	868
1571.17	850
1574.26	854
1577.35	876
1580.43	858
1583.52	810
1586.61	852
1589.69	810
1592.77	866
1595.86	846
1598.94	826
1602.02	818
1605.1	838
1608.18	817.249
1611.25	789.25
1614.33	821.438
1617.4	824.722
1620.47	826.224
1623.55	788.701
1626.62	801.505
1629.69	771.661
1632.75	770.577
1635.82	785.047
1638.89	780.034
1641.95	760.654
1645.02	760.529
1648.08	785.449
1651.14	778.068
1654.2	800.551
1657.26	778.819
1660.32	753.24
1663.37	791.25
1666.43	774.708
1669.48	760.03
1672.54	762.073
1675.59	772.495
1678.64	746.429
1681.69	748.544
1684.74	748.15
1687.79	751.078
1690.83	750.999
1693.88	743.486
1696.92	744.155
1699.96	720.072
1703.01	737.22
1706.05	755.101
1709.09	741.195
1712.12	733.686
1715.16	720.15
1718.2	729.149
1721.23	702.761
1724.27	727.35
1727.3	712.566
1730.33	705.493
1733.36	713.751
1736.39	685.234
1739.42	711.114
1742.44	693.501
1745.47	664.843
1748.49	671.34
1751.52	674.386
1754.54	672.044
1757.56	653.789
1759.14	650
1762.18	682
1765.21	654
1768.24	676
1771.27	646
1774.3	658
1777.32	668
1780.35	680
1783.38	664
1786.4	688
1789.42	670
1792.44	708
1795.47	682
1798.48	662
1801.5	664
1804.52	690
1807.54	686
1810.55	678
1813.57	680
1816.58	648
1819.59	668
1822.6	668
1825.61	716
1828.62	684
1831.63	700
1834.63	682
1837.64	690
1840.64	656
1843.64	658
1846.64	672
1849.64	682
1852.64	652
1855.64	696
1858.64	686
1861.64	676
1864.63	708
1867.63	698
1870.62	686
1873.61	684
1876.6	654
1879.59	662
1882.58	682
1885.56	640
1888.55	686
1891.54	692
1894.52	696
1897.5	696
1900.48	704
1903.46	712
1906.44	670
1909.42	724
1912.4	712
1915.38	694
1918.35	704
1921.32	700
1924.3	688
1927.27	718
1930.24	676
1933.21	708
1936.18	694
1939.15	686
1942.11	668
1945.08	690
1948.04	686
1951	626
1953.97	696
1956.93	700
1959.89	706
1962.85	686
1965.8	680
1968.76	688
1971.71	674
1974.67	684
1977.62	686
1980.57	676
1983.53	676
1986.48	676
1989.42	702
1992.37	688
1995.32	680
1998.26	658
2001.21	662
2004.15	722
2007.09	722
2010.03	698
2012.98	676
2015.92	706
2018.85	706
2021.79	664
2024.73	660
2027.66	696
2030.59	692
2033.53	706
2036.46	688
2039.39	710
2042.32	680
2045.25	696
2048.17	708
2051.1	694
2054.02	712
2056.95	700
2059.87	684
2062.79	702
2065.71	700
2068.63	706
2071.55	696
2074.47	704
2077.39	704
2080.3	724
2083.22	706
2086.13	696
2089.04	680
2091.95	720
2094.86	718
2097.77	688
2100.68	708
2103.59	694
2106.49	676
2109.4	712
2112.3	692
2115.21	708
2118.11	722
2121.01	698
2123.91	700
2126.8	696
2129.7	710
2132.6	714
2135.49	716
2138.39	690
2141.28	726
2144.17	688
2147.06	730
2149.95	682
2152.84	728
2155.73	708
2158.62	728
2161.5	718
2164.39	728
2167.27	720
2170.15	698
2173.04	740
2175.92	730
2178.79	728
2181.67	682
2184.55	718
2187.43	746
2190.3	732
2193.18	714
2196.05	726
2198.92	730
2201.79	712
2204.66	702
2207.53	730
2210.4	724
2213.27	684
2216.13	694
2219	684
2221.86	692
2224.72	696
2227.59	684
2230.45	710
2233.31	668
2236.16	684
2239.02	686
2241.88	664
2244.73	702
2247.59	688
2250.44	690
2253.29	696
2256.15	692
2259	684
2261.84	692
2264.69	696
2267.54	652
2270.39	726
2273.23	710
2276.07	718
2278.92	716
2281.76	676
2284.6	690
2287.44	686
2290.28	708
2293.12	722
2295.95	692
2298.79	678
2301.62	698
2304.46	680
2307.29	686
2310.12	756
2312.95	748
2315.78	716
2318.61	732
2321.44	756
2324.27	736
2327.09	742
2329.92	800
2332.74	786
2335.56	752
2338.38	734
2341.2	748
2344.02	754
2346.84	794
2349.66	796
2352.48	772
2355.29	792
2358.11	804
2360.92	804
2363.73	814
2366.54	800
2369.35	824
2372.16	818
2374.97	834
2377.78	808
2380.58	860
2383.39	844
2386.19	856
2389	804
2391.8	866
2394.6	870
2397.4	830
2400.2	826
2403	852
2405.79	860
2408.59	852
2411.38	872
2414.18	834
2416.97	832
2419.76	852
2422.55	880
2425.34	870
2428.13	850
2430.92	860
2433.71	854
2436.49	898
2439.28	894
2442.06	850
2444.85	882
2447.63	868
2450.41	886
2453.19	878
2455.97	862
2458.75	872
2461.52	900
2464.3	868
2467.07	894
2469.85	886
2472.62	888
2475.39	894
2478.16	890
2480.94	882
2483.7	878
2486.47	894
2489.24	850
2492	892
2494.77	870
2497.53	822
2500.3	878
2503.06	840
2505.82	836
2508.58	862
2511.34	876
2514.1	884
2516.85	882
2519.61	866
2522.37	900
2525.12	906
2527.87	872
2530.63	872
2533.38	822
2536.13	902
2538.88	872
2541.62	894
2544.37	866
2547.12	902
2549.86	878
2552.61	858
2555.35	868
2558.09	920
2560.84	894
2563.57	860
2566.32	880
2569.05	874
2571.79	864
2574.53	864
2577.26	892
2580	900
2582.73	902
2585.46	884
2588.19	878
2590.93	868
2593.66	878
2596.39	876
2599.11	878
2601.84	886
2604.56	904
2607.29	900
2610.01	902
2612.74	928
2615.46	912
2618.18	876
2620.9	906
2623.62	918
2626.34	922
2629.05	906
2631.77	910
2634.48	932
2637.2	884
2639.91	898
2642.62	924
2645.33	896
2648.05	916
2650.75	920
2653.46	908
2656.17	942
2658.88	932
2661.58	926
2664.29	920
2666.99	942
2669.69	930
2672.39	920
2675.09	970
2677.79	934
2680.49	922
2683.19	900
2685.89	958
2688.58	896
2691.28	936
2693.97	954
2696.67	904
2699.36	964
2702.05	940
2704.74	968
2707.43	924
2710.12	924
2712.8	948
2715.49	930
2718.17	880
2720.86	938
2723.54	942
2726.22	950
2728.91	946
2731.59	956
2734.27	912
2736.95	920
2739.62	956
2742.3	942
2744.98	972
2747.65	934
2750.33	926
2753	954
2755.67	988
2758.34	940
2761.01	978
2763.68	992
2766.35	986
2769.02	1002
2771.68	982
2774.35	978
2777.01	982
2779.68	992
2782.34	944
2785	1014
2787.66	986
2790.32	1012
2792.98	1032
2795.64	1000
2798.3	974
2800.95	1026
2803.61	1018
2806.26	1026
2808.91	1016
2811.57	994
2814.22	1000
2816.87	1010
2819.52	1026
2822.17	1020
2824.81	1004
2827.46	1022
2830.11	1004
2832.75	1002
2835.39	1046
2838.04	1086
2840.68	1076
2843.32	1052
2845.96	1070
2848.6	1066
2851.24	1020
2853.88	1022
2856.51	1044
2859.15	1080
2861.78	1062
2864.42	1054
2867.05	1086
2869.68	1040
2872.31	1070
2874.94	1100
2877.57	1074
2880.2	1084
2882.82	1088
2885.45	1080
2888.08	1102
2890.7	1122
2893.33	1106
2895.95	1094
2898.57	1098
2901.19	1124
2903.81	1108
2906.43	1104
2909.05	1118
2911.66	1096
2914.28	1120
2916.89	1106
2919.51	1133.21
2922.12	1129.23
2924.73	1138.1
2927.35	1129.54
2929.96	1133.7
2932.57	1153.14
2935.17	1178.76
2937.78	1128.49
2940.39	1156.9
2943	1127.66
2945.6	1131.88
2948.2	1146.21
2950.81	1162.53
2953.41	1137.53
2956.01	1116.54
2958.61	1138.6
2961.21	1152.82
2963.81	1130.11
2966.41	1113.77
2969.01	1142.03
2971.6	1166.02
2974.2	1142.51
2976.79	1149.83
2979.39	1147.67
2981.98	1170.06
2984.57	1148.1
2987.16	1159.89
2989.75	1164.68
2992.34	1164.13
2994.93	1199.66
2997.51	1178.56
3000.1	1167.08
3002.68	1184.74
3005.27	1191.86
3007.85	1193.74
3010.43	1200.79
3013.01	1198.63
3015.59	1200.15
3018.18	1182.65
3020.75	1181.34
3023.33	1198.81
3025.91	1185.28
3028.48	1209.09
3031.06	1197.67
3033.64	1226.64
3036.21	1198.31
3038.78	1249.62
3041.35	1208.95
3043.92	1220.49
3046.49	1232.44
3048.11	1244
3050.69	1210
3053.27	1236
3055.85	1232
3058.43	1240
3061.01	1204
3063.58	1228
3066.16	1290
3068.73	1274
3071.31	1278
3073.88	1238
3076.45	1242
3079.02	1294
3081.59	1272
3084.16	1318
3086.73	1282
3089.29	1282
3091.86	1252
3094.43	1282
3096.99	1300
3099.55	1324
3102.12	1296
3104.68	1270
3107.24	1328
3109.8	1300
3112.36	1308
3114.92	1360
3117.48	1330
3120.03	1320
3122.59	1290
3125.14	1330
3127.7	1348
3130.25	1364
3132.8	1320
3135.35	1370
3137.9	1362
3140.45	1412
3143	1358
3145.55	1356
3148.1	1366
3150.64	1376
3153.19	1414
3155.73	1394
3158.28	1404
3160.82	1404
3163.36	1406
3165.9	1372
3168.44	1436
3170.98	1424
3173.52	1416
3176.06	1408
3178.59	1440
3181.13	1472
3183.66	1436
3186.2	1400
3188.73	1464
3191.26	1444
3193.79	1482
3196.32	1456
3198.85	1430
3201.38	1436
3203.91	1466
3206.44	1466
3208.96	1472
3211.49	1468
3214.01	1476
3216.54	1476
3219.06	1480
3221.58	1502
3224.1	1484
3226.62	1468
3229.14	1494
3231.66	1498
3234.18	1486
3236.69	1508
3239.21	1516
3241.72	1508
3244.24	1498
3246.75	1514
3249.26	1528
3251.78	1536
3254.29	1548
3256.8	1534
3259.3	1508
3261.81	1530
3264.32	1536
3266.83	1578
3269.33	1546
3271.84	1528
3274.34	1558
3276.84	1568
3279.35	1580
3281.85	1568
3284.35	1534
3286.85	1600
3289.35	1578
3291.84	1610
3294.34	1636
3296.84	1570
3299.33	1632
3301.83	1660
3304.32	1608
3306.81	1646
3309.3	1654
3311.79	1676
3314.29	1642
3316.77	1684
3319.26	1630
3321.75	1634
3324.24	1636
3326.72	1642
3329.21	1644
3331.69	1662
3334.18	1712
3336.66	1706
3339.14	1732
3341.62	1690
3344.1	1672
3346.58	1664
3349.06	1668
3351.54	1700
3354.01	1642
3356.49	1650
3358.96	1694
3361.44	1726
3363.91	1696
3366.38	1712
3368.85	1712
3371.33	1732
3373.8	1708
3376.26	1708
3378.73	1758
3381.2	1728
3383.67	1710
3386.13	1746
3388.6	1724
3391.06	1764
3393.52	1728
3395.99	1794
3398.45	1740
3400.91	1792
3403.37	1750
3405.83	1800
3408.29	1798
3410.74	1798
3413.2	1780
3415.66	1790
3418.11	1850
3420.56	1828
3423.02	1838
3425.47	1824
3427.92	1816
3430.37	1844
3432.82	1870
3435.27	1876
3437.72	1872
3440.17	1906
3442.61	1882
3445.06	1900
3447.51	1906
3449.95	1912
3452.39	1940
3454.83	1892
3457.28	1920
3459.72	1972
3462.16	1978
3464.6	1898
3467.04	1944
3469.47	1968
3471.91	1940
3474.34	1968
3476.78	1958
3479.21	1990
3481.65	1910
3484.08	1990
3486.51	1976
3488.94	1952
3491.37	1966
3493.8	1984
3496.23	1948
3498.66	2020
3501.09	1996
3503.51	2036
3505.94	2020
3508.36	1976
3510.79	1948
3513.21	1974
3515.63	1950
3518.05	1964
3520.47	1980
3522.89	2012
3525.31	1980
3527.73	2032
3530.14	1982
3532.56	1986
3534.98	2024
3537.39	1924
3539.81	1998
3542.22	2042
3544.63	2030
3547.04	2004
3549.45	2032
3551.86	2012
3554.27	2042
3556.68	2004
3559.09	2018
3561.49	2048
3563.9	2020
3566.3	2082
3568.71	2046
3571.11	2044
3573.51	2064
3575.92	2112
3578.32	2134
3580.72	2120
3583.12	2136
3585.51	2106
3587.91	2126
3590.31	2138
3592.71	2112
3595.1	2096
3597.49	2126
3599.89	2158
3602.28	2122
3604.67	2186
3607.06	2182
3609.45	2200
3611.84	2128
3614.23	2214
3616.62	2178
3619.01	2174
3621.39	2206
3623.78	2260
3626.17	2242
3628.55	2232
3630.93	2222
3633.31	2188
3635.7	2218
3638.08	2244
3640.46	2220
3642.84	2252
3645.22	2238
3647.59	2238
3649.97	2246
3652.35	2216
3654.72	2216
3657.1	2216
3659.47	2246
3661.84	2244
3664.21	2270
3666.59	2240
3668.96	2270
3671.33	2202
3673.69	2236
3676.06	2240
3678.43	2238
3680.8	2228
3683.16	2276
3685.53	2214
3687.89	2276
3690.25	2246
3692.62	2252
3694.98	2328
3697.34	2282
3699.7	2330
3702.06	2312
3704.42	2252
3706.78	2360
3709.13	2316
3711.49	2342
3713.85	2304
3716.2	2328
3718.56	2360
3720.91	2332
3723.26	2360
3725.61	2268
3727.96	2418
3730.31	2388
3732.66	2368
3735.01	2378
3737.36	2366
3739.7	2388
3742.05	2430
3744.4	2402
3746.74	2368
3749.09	2458
3751.43	2412
3753.77	2410
3756.11	2436
3758.45	2438
3760.79	2478
3763.13	2496
3765.47	2458
3767.81	2482
3770.14	2474
3772.48	2526
3774.82	2482
3777.15	2490
3779.48	2496
3781.82	2458
3784.15	2482
3786.48	2506
3788.81	2484
3791.14	2500
3793.47	2516
3795.8	2524
3798.13	2492
3800.45	2468
3802.78	2520
3805.1	2484
3807.43	2530
3809.75	2446
3812.07	2510
3814.4	2510
3816.72	2520
3819.04	2446
3821.36	2456
3823.68	2546
3826	2536
3828.31	2518
3830.63	2536
3832.95	2496
3835.26	2478
3837.58	2506
3839.89	2542
3842.2	2530
3844.51	2540
3846.83	2538
3849.14	2540
3851.45	2500
3853.76	2566
3856.06	2558
3858.37	2580
3860.68	2588
3862.98	2552
3865.29	2600
3867.59	2582
3869.9	2566
3872.2	2590
3874.5	2630
3876.8	2642
3879.1	2596
3881.4	2690
3883.7	2630
3886	2628
3888.3	2624
3890.6	2720
3892.89	2652
3895.19	2664
3897.48	2682
3899.78	2694
3902.07	2704
3904.36	2696
3906.65	2714
3908.94	2724
3911.23	2678
3913.52	2706
3915.81	2696
3918.1	2732
3920.39	2706
3922.67	2738
3924.96	2726
3927.24	2698
3929.53	2740
3931.81	2734
3934.09	2794
3936.38	2750
3938.66	2720
3940.94	2716
3943.22	2678
3945.5	2734
3947.77	2742
3950.05	2764
3952.33	2770
3954.6	2760
3956.88	2784
3959.15	2762
3961.43	2770
3963.7	2724
3965.97	2772
3968.24	2750
3970.51	2760
3972.78	2722
3975.05	2746
3977.32	2758
3979.59	2740
3981.85	2726
3984.12	2758
3986.39	2786
3988.65	2726
3990.91	2776
3993.18	2794
3995.44	2788
3997.7	2808
3999.96	2832