File: DataDrivenSE/datosramanb/CN-Sastre_17.txt
#Acq. time (s)=	20
#Accumulations=	2
#Range (cm-¹)=	50...4000
#Windows=	3
#Autofocus=	Off
#AutoExposure=	Off
#Spike filter=	Multiple accum.
#Delay time (s)=	0
#Binning=	1
#Readout mode=	Signal
#DeNoise=	Off
#ICS correction=	Off
#Dark correction=	Off
#Inst. Process=	Off
#Instrument=	LabRAM HR Evol
#Detector=	Syncerity OE
#Objective=	x100_VIS
#Grating=	600 (500nm)
#ND Filter=	100%
#Laser=	532nm_Edge
#Hole=	100.021
#Range=	Visible
#Project=	Omar
#Sample=
#Site=	21-09-22
#Title=	 CN-Sastre
#Remark=
#Date=	21.09.2022 14:08
#Acquired=	21.09.2022 14:08:07
51.0918	34
54.7807	48
58.4681	84
62.154	184
65.8385	308
69.5216	476
73.2032	818
76.8834	1048
80.5621	1366
84.2393	1598
87.9152	1788
91.5874	1860
95.2603	1772
98.9318	1748
102.602	1804
106.27	1892
109.936	1848
113.601	1882
117.266	1858
120.926	1852
124.588	1782
128.246	1808
131.904	1796
135.561	1812
139.215	1856
142.869	1772
146.52	1814
150.171	1784
153.819	1784
157.465	1756
161.112	1738
164.756	1730
168.398	1732
172.041	1726
175.68	1678
179.318	1718
182.955	1634
186.592	1706
190.225	1656
193.857	1610
197.488	1684
201.118	1650
204.746	1630
208.372	1638
211.997	1640
215.621	1562
219.243	1580
222.864	1606
226.483	1598
230.101	1574
233.718	1594
237.331	1568
240.945	1596
244.557	1568
248.168	1634
251.776	1620
255.384	1614
258.991	1594
262.594	1596
266.198	1578
269.799	1582
273.4	1570
277	1600
280.596	1562
284.193	1588
287.786	1586
291.378	1618
294.971	1640
298.561	1572
302.148	1646
305.737	1572
309.322	1638
312.906	1632
316.49	1626
320.071	1654
323.651	1624
327.229	1658
330.806	1666
334.381	1648
337.955	1616
341.528	1680
345.099	1674
348.669	1652
352.238	1624
355.805	1642
359.371	1696
362.935	1646
366.498	1684
370.06	1670
373.62	1712
377.177	1712
380.734	1692
384.29	1730
387.845	1732
391.396	1734
394.948	1730
398.499	1688
402.046	1684
405.594	1692
409.138	1710
412.683	1718
416.225	1694
419.768	1674
423.307	1688
426.844	1710
430.382	1732
433.917	1666
437.451	1674
440.985	1706
444.516	1736
448.045	1722
451.574	1736
455.102	1728
458.628	1738
462.152	1694
465.674	1718
469.196	1708
472.716	1750
476.234	1702
479.752	1748
483.268	1744
486.782	1684
490.295	1676
493.807	1620
497.316	1628
500.825	1600
504.333	1624
507.839	1600
511.344	1660
514.846	1674
518.349	1700
521.85	1660
525.347	1756
528.846	1792
532.341	1912
535.837	1952
539.329	2080
542.822	2110
546.312	2198
549.802	2206
553.289	2282
556.775	2312
560.261	2262
563.744	2286
567.226	2284
570.709	2222
574.188	2128
577.665	2138
581.142	2066
584.617	2060
588.091	1990
591.565	1944
595.036	1982
598.506	1938
601.974	1850
605.442	1812
608.905	1786
612.37	1768
615.833	1662
619.295	1652
622.755	1606
626.215	1624
629.67	1548
633.127	1572
636.582	1574
640.036	1476
643.487	1462
646.938	1466
650.386	1404
653.835	1390
657.282	1352
660.726	1328
664.171	1266
667.613	1244
671.053	1190
674.494	1172
677.931	1164
681.369	1114
684.804	1122
688.238	1112
691.67	1104
695.103	1044
698.533	1000
701.961	1010
705.389	970
708.814	956
712.239	952
715.662	932
719.084	872
722.505	892
725.924	874
729.342	898
732.759	878
736.174	874
739.589	850
742.999	884
746.411	900
749.821	874
753.23	902
756.636	914
760.043	880
763.448	924
766.85	920
770.252	940
773.652	920
777.052	894
780.448	950
783.846	918
787.24	902
790.635	944
794.027	926
797.417	912
800.808	878
804.196	834
807.582	862
810.968	860
814.354	832
817.736	800
821.118	810
824.498	794
827.877	784
831.254	744
834.631	726
838.006	688
841.38	694
844.752	686
848.123	728
851.493	674
854.86	660
858.228	714
861.594	682
864.959	690
868.321	660
871.683	672
875.044	674
878.402	706
881.761	694
885.116	666
888.472	700
891.825	696
895.179	722
898.529	730
901.88	754
905.228	754
908.575	750
911.922	760
915.266	808
918.609	778
921.951	814
925.293	862
928.633	872
931.97	912
935.307	944
938.642	984
941.977	976
945.31	998
948.641	1006
951.972	988
955.301	1022
958.629	1016
961.955	968
965.279	992
968.603	1004
971.926	1034
975.248	1032
978.566	1040
981.886	1022
985.204	1062
988.519	1058
991.834	1086
995.147	1112
998.46	1134
1001.77	1128
1005.08	1104
1008.39	1138
1011.7	1172
1015	1222
1018.3	1212
1021.61	1284
1024.91	1306
1028.21	1304
1031.51	1366
1034.81	1420
1038.1	1430
1041.4	1486
1044.69	1504
1047.99	1590
1051.28	1600
1054.57	1660
1057.86	1744
1061.14	1788
1064.43	1818
1067.72	1880
1071	1884
1074.28	1990
1077.57	2012
1080.84	2058
1084.12	2086
1087.4	2170
1090.68	2182
1093.95	2176
1097.22	2162
1100.5	2114
1103.77	2090
1107.04	2080
1110.31	1998
1113.58	1924
1116.84	1858
1120.1	1818
1123.37	1752
1126.63	1634
1129.89	1600
1133.15	1490
1136.41	1450
1139.67	1414
1142.92	1316
1146.18	1278
1149.43	1240
1152.68	1256
1155.93	1122
1159.18	1120
1162.43	1094
1165.68	1086
1168.93	998
1172.17	1006
1175.41	988
1178.66	900
1181.9	902
1185.14	916
1188.37	874
1191.61	816
1194.85	820
1198.08	804
1201.31	764
1204.55	738
1207.78	728
1211.01	718
1214.24	718
1217.46	672
1220.69	702
1223.91	676
1227.14	662
1230.36	632
1233.58	648
1236.8	640
1240.02	618
1243.23	584
1246.45	600
1249.67	614
1252.88	642
1256.09	602
1259.3	622
1262.51	596
1265.72	614
1268.93	616
1272.13	590
1275.34	602
1278.54	610
1281.74	600
1284.94	610
1288.15	620
1291.34	640
1294.54	620
1297.74	620
1300.93	586
1304.12	590
1307.32	612
1310.51	634
1313.7	608
1316.89	628
1320.07	588
1323.26	608
1326.45	606
1329.63	618
1332.81	634
1335.99	614
1339.17	610
1342.35	646
1345.53	628
1348.71	622
1351.88	628
1355.06	618
1358.23	644
1361.4	652
1364.57	578
1367.74	568
1370.91	596
1374.08	618
1377.24	630
1380.41	588
1383.57	618
1386.73	616
1389.89	630
1393.05	592
1396.21	608
1399.37	652
1402.52	606
1405.68	596
1408.83	602
1411.98	598
1415.13	606
1418.29	614
1421.43	600
1424.58	608
1427.73	618
1430.87	634
1434.02	646
1437.16	646
1440.3	634
1443.44	620
1446.58	624
1449.72	630
1452.85	618
1455.99	630
1459.12	640
1462.26	634
1465.39	624
1468.52	604
1471.65	632
1474.78	610
1477.9	634
1481.03	638
1484.16	650
1487.28	640
1490.4	634
1493.52	622
1496.64	646
1499.76	634
1502.88	628
1506	600
1509.11	640
1512.22	656
1515.34	662
1518.45	674
1521.56	658
1524.67	630
1527.78	670
1530.88	676
1533.99	634
1537.09	634
1540.2	652
1543.3	628
1546.4	650
1549.5	658
1552.6	660
1555.7	676
1558.79	696
1561.89	636
1564.98	634
1568.08	638
1571.17	660
1574.26	654
1577.35	700
1580.43	640
1583.52	660
1586.61	650
1589.69	630
1592.77	668
1595.86	640
1598.94	632
1602.02	638
1605.1	616
1608.18	648.299
1611.25	612.91
1614.33	655.561
1617.4	607.968
1620.47	644.138
1623.55	635.659
1626.62	642.417
1629.69	645.179
1632.75	640.128
1635.82	626.048
1638.89	620.372
1641.95	611.305
1645.02	598.174
1648.08	624.099
1651.14	604.496
1654.2	636.596
1657.26	611.247
1660.32	616.165
1663.37	618.992
1666.43	640.02
1669.48	617.989
1672.54	587.293
1675.59	598.939
1678.64	601.756
1681.69	616.377
1684.74	603.258
1687.79	596.827
1690.83	605.094
1693.88	607.737
1696.92	596.921
1699.96	612.354
1703.01	603.692
1706.05	600.077
1709.09	606.073
1712.12	597.966
1715.16	604.187
1718.2	620.574
1721.23	599.013
1724.27	600.689
1727.3	599.635
1730.33	576.13
1733.36	588.081
1736.39	560.628
1739.42	587.64
1742.44	569.872
1745.47	578.396
1748.49	595.384
1751.52	577.838
1754.54	569.422
1757.56	560.13
1759.14	568
1762.18	550
1765.21	548
1768.24	550
1771.27	580
1774.3	584
1777.32	554
1780.35	536
1783.38	564
1786.4	586
1789.42	540
1792.44	558
1795.47	578
1798.48	560
1801.5	562
1804.52	564
1807.54	568
1810.55	572
1813.57	550
1816.58	588
1819.59	558
1822.6	566
1825.61	572
1828.62	560
1831.63	566
1834.63	566
1837.64	574
1840.64	568
1843.64	566
1846.64	562
1849.64	568
1852.64	580
1855.64	586
1858.64	554
1861.64	566
1864.63	548
1867.63	594
1870.62	592
1873.61	570
1876.6	558
1879.59	578
1882.58	590
1885.56	594
1888.55	574
1891.54	572
1894.52	596
1897.5	578
1900.48	562
1903.46	574
1906.44	572
1909.42	572
1912.4	576
1915.38	596
1918.35	570
1921.32	596
1924.3	582
1927.27	568
1930.24	586
1933.21	596
1936.18	578
1939.15	598
1942.11	590
1945.08	578
1948.04	582
1951	564
1953.97	568
1956.93	578
1959.89	584
1962.85	550
1965.8	596
1968.76	588
1971.71	584
1974.67	574
1977.62	586
1980.57	578
1983.53	590
1986.48	570
1989.42	598
1992.37	586
1995.32	572
1998.26	578
2001.21	584
2004.15	600
2007.09	570
2010.03	576
2012.98	584
2015.92	592
2018.85	598
2021.79	602
2024.73	590
2027.66	612
2030.59	590
2033.53	578
2036.46	592
2039.39	594
2042.32	582
2045.25	588
2048.17	590
2051.1	600
2054.02	604
2056.95	600
2059.87	612
2062.79	618
2065.71	576
2068.63	608
2071.55	602
2074.47	586
2077.39	588
2080.3	586
2083.22	610
2086.13	588
2089.04	596
2091.95	592
2094.86	592
2097.77	588
2100.68	608
2103.59	594
2106.49	576
2109.4	594
2112.3	586
2115.21	594
2118.11	574
2121.01	620
2123.91	592
2126.8	582
2129.7	578
2132.6	604
2135.49	576
2138.39	592
2141.28	616
2144.17	572
2147.06	602
2149.95	608
2152.84	600
2155.73	614
2158.62	608
2161.5	608
2164.39	624
2167.27	606
2170.15	592
2173.04	616
2175.92	590
2178.79	592
2181.67	578
2184.55	598
2187.43	596
2190.3	598
2193.18	608
2196.05	596
2198.92	606
2201.79	576
2204.66	596
2207.53	584
2210.4	578
2213.27	586
2216.13	592
2219	594
2221.86	594
2224.72	590
2227.59	568
2230.45	582
2233.31	608
2236.16	570
2239.02	560
2241.88	588
2244.73	556
2247.59	558
2250.44	612
2253.29	572
2256.15	610
2259	586
2261.84	532
2264.69	580
2267.54	560
2270.39	564
2273.23	582
2276.07	600
2278.92	564
2281.76	588
2284.6	586
2287.44	612
2290.28	600
2293.12	624
2295.95	602
2298.79	606
2301.62	650
2304.46	586
2307.29	616
2310.12	608
2312.95	620
2315.78	626
2318.61	602
2321.44	618
2324.27	646
2327.09	704
2329.92	672
2332.74	630
2335.56	650
2338.38	618
2341.2	614
2344.02	662
2346.84	626
2349.66	660
2352.48	656
2355.29	652
2358.11	706
2360.92	660
2363.73	706
2366.54	728
2369.35	686
2372.16	702
2374.97	726
2377.78	726
2380.58	728
2383.39	722
2386.19	738
2389	734
2391.8	726
2394.6	746
2397.4	716
2400.2	744
2403	756
2405.79	760
2408.59	738
2411.38	702
2414.18	746
2416.97	740
2419.76	748
2422.55	786
2425.34	770
2428.13	754
2430.92	764
2433.71	762
2436.49	726
2439.28	764
2442.06	754
2444.85	750
2447.63	772
2450.41	760
2453.19	764
2455.97	788
2458.75	778
2461.52	782
2464.3	762
2467.07	748
2469.85	774
2472.62	760
2475.39	772
2478.16	764
2480.94	752
2483.7	736
2486.47	748
2489.24	756
2492	774
2494.77	752
2497.53	752
2500.3	768
2503.06	740
2505.82	742
2508.58	750
2511.34	746
2514.1	778
2516.85	764
2519.61	744
2522.37	752
2525.12	750
2527.87	784
2530.63	770
2533.38	794
2536.13	758
2538.88	764
2541.62	790
2544.37	750
2547.12	782
2549.86	760
2552.61	786
2555.35	768
2558.09	740
2560.84	762
2563.57	760
2566.32	756
2569.05	776
2571.79	752
2574.53	754
2577.26	770
2580	766
2582.73	770
2585.46	770
2588.19	796
2590.93	766
2593.66	790
2596.39	772
2599.11	792
2601.84	764
2604.56	782
2607.29	788
2610.01	782
2612.74	808
2615.46	796
2618.18	790
2620.9	736
2623.62	784
2626.34	798
2629.05	798
2631.77	816
2634.48	804
2637.2	762
2639.91	818
2642.62	812
2645.33	798
2648.05	804
2650.75	828
2653.46	822
2656.17	804
2658.88	770
2661.58	826
2664.29	826
2666.99	834
2669.69	800
2672.39	832
2675.09	796
2677.79	778
2680.49	802
2683.19	816
2685.89	806
2688.58	802
2691.28	806
2693.97	834
2696.67	772
2699.36	816
2702.05	802
2704.74	792
2707.43	810
2710.12	842
2712.8	806
2715.49	806
2718.17	826
2720.86	838
2723.54	828
2726.22	814
2728.91	850
2731.59	824
2734.27	832
2736.95	816
2739.62	796
2742.3	822
2744.98	816
2747.65	832
2750.33	852
2753	800
2755.67	834
2758.34	832
2761.01	860
2763.68	864
2766.35	862
2769.02	846
2771.68	870
2774.35	890
2777.01	862
2779.68	878
2782.34	872
2785	856
2787.66	850
2790.32	870
2792.98	886
2795.64	852
2798.3	910
2800.95	892
2803.61	846
2806.26	868
2808.91	880
2811.57	888
2814.22	932
2816.87	922
2819.52	870
2822.17	914
2824.81	906
2827.46	906
2830.11	872
2832.75	894
2835.39	888
2838.04	882
2840.68	946
2843.32	868
2845.96	932
2848.6	924
2851.24	926
2853.88	956
2856.51	930
2859.15	926
2861.78	946
2864.42	944
2867.05	932
2869.68	948
2872.31	960
2874.94	920
2877.57	984
2880.2	908
2882.82	966
2885.45	1008
2888.08	962
2890.7	946
2893.33	986
2895.95	934
2898.57	938
2901.19	986
2903.81	948
2906.43	954
2909.05	978
2911.66	996
2914.28	972
2916.89	1016
2919.51	968.488
2922.12	989.37
2924.73	972.024
2927.35	987.137
2929.96	1009.42
2932.57	973.169
2935.17	1004.36
2937.78	992.324
2940.39	1006.87
2943	1000.74
2945.6	1003.89
2948.2	992.038
2950.81	976.472
2953.41	1017.16
2956.01	1020.06
2958.61	1020.93
2961.21	1007.85
2963.81	1020.95
2966.41	1022
2969.01	1017.93
2971.6	991.749
2974.2	1036.43
2976.79	1041.8
2979.39	1031.01
2981.98	1035.14
2984.57	1040.02
2987.16	1057.78
2989.75	1058.72
2992.34	1055.53
2994.93	1051.39
2997.51	1057.24
3000.1	1072.71
3002.68	1053.16
3005.27	1075.2
3007.85	1095.42
3010.43	1051.04
3013.01	1092.01
3015.59	1075.51
3018.18	1086.79
3020.75	1102.16
3023.33	1083.36
3025.91	1101.07
3028.48	1077.35
3031.06	1107.55
3033.64	1126.25
3036.21	1097.01
3038.78	1109.45
3041.35	1102.62
3043.92	1148.95
3046.49	1120.26
3048.11	1116
3050.69	1140
3053.27	1142
3055.85	1126
3058.43	1130
3061.01	1154
3063.58	1140
3066.16	1114
3068.73	1156
3071.31	1142
3073.88	1144
3076.45	1148
3079.02	1176
3081.59	1180
3084.16	1180
3086.73	1200
3089.29	1174
3091.86	1184
3094.43	1186
3096.99	1190
3099.55	1200
3102.12	1190
3104.68	1170
3107.24	1212
3109.8	1208
3112.36	1232
3114.92	1222
3117.48	1218
3120.03	1244
3122.59	1224
3125.14	1196
3127.7	1256
3130.25	1212
3132.8	1242
3135.35	1284
3137.9	1256
3140.45	1262
3143	1252
3145.55	1260
3148.1	1256
3150.64	1292
3153.19	1278
3155.73	1302
3158.28	1290
3160.82	1296
3163.36	1290
3165.9	1338
3168.44	1284
3170.98	1334
3173.52	1290
3176.06	1322
3178.59	1342
3181.13	1330
3183.66	1316
3186.2	1342
3188.73	1338
3191.26	1336
3193.79	1346
3196.32	1274
3198.85	1360
3201.38	1336
3203.91	1356
3206.44	1360
3208.96	1380
3211.49	1368
3214.01	1372
3216.54	1364
3219.06	1358
3221.58	1368
3224.1	1388
3226.62	1398
3229.14	1362
3231.66	1372
3234.18	1392
3236.69	1386
3239.21	1366
3241.72	1366
3244.24	1342
3246.75	1426
3249.26	1388
3251.78	1430
3254.29	1424
3256.8	1414
3259.3	1430
3261.81	1410
3264.32	1410
3266.83	1476
3269.33	1440
3271.84	1462
3274.34	1434
3276.84	1472
3279.35	1454
3281.85	1488
3284.35	1472
3286.85	1504
3289.35	1488
3291.84	1478
3294.34	1488
3296.84	1494
3299.33	1490
3301.83	1508
3304.32	1508
3306.81	1570
3309.3	1508
3311.79	1558
3314.29	1544
3316.77	1588
3319.26	1554
3321.75	1558
3324.24	1566
3326.72	1532
3329.21	1562
3331.69	1552
3334.18	1592
3336.66	1578
3339.14	1608
3341.62	1564
3344.1	1592
3346.58	1568
3349.06	1570
3351.54	1580
3354.01	1584
3356.49	1608
3358.96	1636
3361.44	1596
3363.91	1576
3366.38	1630
3368.85	1622
3371.33	1636
3373.8	1650
3376.26	1628
3378.73	1626
3381.2	1618
3383.67	1602
3386.13	1636
3388.6	1672
3391.06	1656
3393.52	1670
3395.99	1642
3398.45	1660
3400.91	1668
3403.37	1676
3405.83	1660
3408.29	1658
3410.74	1652
3413.2	1674
3415.66	1710
3418.11	1698
3420.56	1708
3423.02	1742
3425.47	1722
3427.92	1698
3430.37	1730
3432.82	1746
3435.27	1746
3437.72	1774
3440.17	1782
3442.61	1728
3445.06	1796
3447.51	1810
3449.95	1806
3452.39	1754
3454.83	1760
3457.28	1804
3459.72	1792
3462.16	1838
3464.6	1820
3467.04	1830
3469.47	1866
3471.91	1784
3474.34	1838
3476.78	1860
3479.21	1858
3481.65	1862
3484.08	1804
3486.51	1852
3488.94	1820
3491.37	1886
3493.8	1836
3496.23	1836
3498.66	1880
3501.09	1862
3503.51	1854
3505.94	1848
3508.36	1844
3510.79	1882
3513.21	1836
3515.63	1894
3518.05	1850
3520.47	1884
3522.89	1884
3525.31	1910
3527.73	1860
3530.14	1842
3532.56	1888
3534.98	1888
3537.39	1880
3539.81	1872
3542.22	1910
3544.63	1858
3547.04	1938
3549.45	1886
3551.86	1886
3554.27	1890
3556.68	1916
3559.09	1896
3561.49	1936
3563.9	1974
3566.3	1918
3568.71	1946
3571.11	1968
3573.51	1968
3575.92	1990
3578.32	1976
3580.72	1996
3583.12	2044
3585.51	2014
3587.91	2014
3590.31	2004
3592.71	2028
3595.1	2004
3597.49	2048
3599.89	1996
3602.28	2052
3604.67	2054
3607.06	2000
3609.45	2070
3611.84	2128
3614.23	2082
3616.62	2066
3619.01	2064
3621.39	2092
3623.78	2100
3626.17	2116
3628.55	2072
3630.93	2088
3633.31	2142
3635.7	2170
3638.08	2136
3640.46	2138
3642.84	2118
3645.22	2124
3647.59	2032
3649.97	2076
3652.35	2194
3654.72	2164
3657.1	2124
3659.47	2152
3661.84	2154
3664.21	2126
3666.59	2144
3668.96	2204
3671.33	2144
3673.69	2128
3676.06	2134
3678.43	2160
3680.8	2148
3683.16	2164
3685.53	2142
3687.89	2134
3690.25	2188
3692.62	2178
3694.98	2136
3697.34	2144
3699.7	2160
3702.06	2182
3704.42	2176
3706.78	2170
3709.13	2150
3711.49	2168
3713.85	2238
3716.2	2250
3718.56	2184
3720.91	2250
3723.26	2190
3725.61	2296
3727.96	2288
3730.31	2268
3732.66	2268
3735.01	2258
3737.36	2272
3739.7	2258
3742.05	2318
3744.4	2270
3746.74	2364
3749.09	2312
3751.43	2312
3753.77	2352
3756.11	2336
3758.45	2314
3760.79	2308
3763.13	2346
3765.47	2346
3767.81	2360
3770.14	2346
3772.48	2364
3774.82	2404
3777.15	2404
3779.48	2372
3781.82	2344
3784.15	2348
3786.48	2386
3788.81	2392
3791.14	2400
3793.47	2378
3795.8	2394
3798.13	2402
3800.45	2348
3802.78	2328
3805.1	2398
3807.43	2360
3809.75	2364
3812.07	2318
3814.4	2364
3816.72	2404
3819.04	2380
3821.36	2374
3823.68	2420
3826	2408
3828.31	2336
3830.63	2404
3832.95	2394
3835.26	2396
3837.58	2358
3839.89	2384
3842.2	2388
3844.51	2422
3846.83	2430
3849.14	2418
3851.45	2428
3853.76	2422
3856.06	2450
3858.37	2424
3860.68	2418
3862.98	2460
3865.29	2446
3867.59	2490
3869.9	2446
3872.2	2474
3874.5	2502
3876.8	2518
3879.1	2456
3881.4	2474
3883.7	2552
3886	2472
3888.3	2524
3890.6	2504
3892.89	2530
3895.19	2542
3897.48	2532
3899.78	2512
3902.07	2614
3904.36	2568
3906.65	2546
3908.94	2584
3911.23	2598
3913.52	2650
3915.81	2560
3918.1	2540
3920.39	2582
3922.67	2610
3924.96	2600
3927.24	2646
3929.53	2612
3931.81	2540
3934.09	2656
3936.38	2608
3938.66	2624
3940.94	2594
3943.22	2638
3945.5	2642
3947.77	2624
3950.05	2648
3952.33	2632
3954.6	2638
3956.88	2586
3959.15	2584
3961.43	2608
3963.7	2594
3965.97	2618
3968.24	2606
3970.51	2680
3972.78	2612
3975.05	2598
3977.32	2636
3979.59	2652
3981.85	2634
3984.12	2610
3986.39	2654
3988.65	2662
3990.91	2640
3993.18	2668
3995.44	2656
3997.7	2634
3999.96	2678