File: DataDrivenSE/datosramanb/CN-Sastre_20.txt
#Acq. time (s)=	20
#Accumulations=	2
#Range (cm-¹)=	50...4000
#Windows=	3
#Autofocus=	Off
#AutoExposure=	Off
#Spike filter=	Multiple accum.
#Delay time (s)=	0
#Binning=	1
#Readout mode=	Signal
#DeNoise=	Off
#ICS correction=	Off
#Dark correction=	Off
#Inst. Process=	Off
#Instrument=	LabRAM HR Evol
#Detector=	Syncerity OE
#Objective=	x100_VIS
#Grating=	600 (500nm)
#ND Filter=	100%
#Laser=	532nm_Edge
#Hole=	100.021
#Range=	Visible
#Project=	Omar
#Sample=
#Site=	21-09-22
#Title=	 CN-Sastre
#Remark=
#Date=	21.09.2022 14:37
#Acquired=	21.09.2022 14:37:50
51.0918	44
54.7807	54
58.4681	94
62.154	188
65.8385	314
69.5216	494
73.2032	846
76.8834	1138
80.5621	1386
84.2393	1666
87.9152	1856
91.5874	1808
95.2603	1770
98.9318	1788
102.602	1858
106.27	1932
109.936	1862
113.601	1910
117.266	1840
120.926	1868
124.588	1826
128.246	1878
131.904	1810
135.561	1818
139.215	1818
142.869	1790
146.52	1804
150.171	1834
153.819	1838
157.465	1804
161.112	1784
164.756	1720
168.398	1768
172.041	1770
175.68	1714
179.318	1696
182.955	1720
186.592	1698
190.225	1674
193.857	1718
197.488	1644
201.118	1668
204.746	1680
208.372	1656
211.997	1676
215.621	1628
219.243	1628
222.864	1674
226.483	1582
230.101	1596
233.718	1606
237.331	1592
240.945	1604
244.557	1654
248.168	1644
251.776	1614
255.384	1606
258.991	1622
262.594	1590
266.198	1616
269.799	1578
273.4	1628
277	1592
280.596	1614
284.193	1596
287.786	1636
291.378	1616
294.971	1642
298.561	1636
302.148	1632
305.737	1654
309.322	1656
312.906	1698
316.49	1652
320.071	1692
323.651	1676
327.229	1672
330.806	1662
334.381	1650
337.955	1636
341.528	1640
345.099	1656
348.669	1670
352.238	1684
355.805	1678
359.371	1684
362.935	1686
366.498	1684
370.06	1704
373.62	1682
377.177	1734
380.734	1738
384.29	1760
387.845	1738
391.396	1758
394.948	1722
398.499	1742
402.046	1724
405.594	1756
409.138	1734
412.683	1742
416.225	1690
419.768	1744
423.307	1750
426.844	1724
430.382	1748
433.917	1686
437.451	1724
440.985	1768
444.516	1738
448.045	1714
451.574	1760
455.102	1808
458.628	1728
462.152	1738
465.674	1770
469.196	1758
472.716	1762
476.234	1726
479.752	1788
483.268	1716
486.782	1728
490.295	1696
493.807	1724
497.316	1662
500.825	1660
504.333	1676
507.839	1660
511.344	1668
514.846	1686
518.349	1686
521.85	1722
525.347	1782
528.846	1868
532.341	1850
535.837	1952
539.329	2076
542.822	2170
546.312	2230
549.802	2298
553.289	2314
556.775	2300
560.261	2258
563.744	2286
567.226	2302
570.709	2260
574.188	2174
577.665	2132
581.142	2088
584.617	2064
588.091	2034
591.565	1984
595.036	1936
598.506	1930
601.974	1852
605.442	1774
608.905	1748
612.37	1736
615.833	1706
619.295	1700
622.755	1640
626.215	1618
629.67	1622
633.127	1550
636.582	1568
640.036	1504
643.487	1488
646.938	1460
650.386	1442
653.835	1404
657.282	1364
660.726	1346
664.171	1322
667.613	1274
671.053	1254
674.494	1220
677.931	1152
681.369	1150
684.804	1142
688.238	1114
691.67	1100
695.103	1072
698.533	1056
701.961	1018
705.389	1000
708.814	976
712.239	938
715.662	962
719.084	966
722.505	952
725.924	946
729.342	932
732.759	910
736.174	872
739.589	900
742.999	922
746.411	924
749.821	926
753.23	926
756.636	916
760.043	934
763.448	962
766.85	950
770.252	946
773.652	994
777.052	974
780.448	960
783.846	980
787.24	960
790.635	950
794.027	978
797.417	954
800.808	942
804.196	950
807.582	948
810.968	902
814.354	916
817.736	840
821.118	852
824.498	830
827.877	814
831.254	772
834.631	788
838.006	738
841.38	730
844.752	730
848.123	738
851.493	716
854.86	730
858.228	718
861.594	714
864.959	740
868.321	756
871.683	740
875.044	778
878.402	726
881.761	728
885.116	738
888.472	732
891.825	750
895.179	768
898.529	766
901.88	806
905.228	798
908.575	780
911.922	806
915.266	844
918.609	850
921.951	862
925.293	904
928.633	948
931.97	934
935.307	944
938.642	1018
941.977	1026
945.31	1024
948.641	1056
951.972	1044
955.301	1066
958.629	1024
961.955	1064
965.279	1036
968.603	1022
971.926	1066
975.248	1062
978.566	1020
981.886	1134
985.204	1144
988.519	1118
991.834	1140
995.147	1140
998.46	1148
1001.77	1148
1005.08	1208
1008.39	1184
1011.7	1224
1015	1254
1018.3	1266
1021.61	1308
1024.91	1344
1028.21	1332
1031.51	1426
1034.81	1482
1038.1	1450
1041.4	1534
1044.69	1568
1047.99	1536
1051.28	1652
1054.57	1692
1057.86	1742
1061.14	1796
1064.43	1842
1067.72	1872
1071	1960
1074.28	2020
1077.57	2008
1080.84	2106
1084.12	2144
1087.4	2128
1090.68	2186
1093.95	2170
1097.22	2108
1100.5	2182
1103.77	2152
1107.04	2102
1110.31	2036
1113.58	1944
1116.84	1894
1120.1	1808
1123.37	1746
1126.63	1638
1129.89	1584
1133.15	1542
1136.41	1468
1139.67	1446
1142.92	1376
1146.18	1328
1149.43	1262
1152.68	1278
1155.93	1230
1159.18	1192
1162.43	1146
1165.68	1124
1168.93	1086
1172.17	1004
1175.41	966
1178.66	972
1181.9	948
1185.14	946
1188.37	878
1191.61	882
1194.85	870
1198.08	838
1201.31	780
1204.55	826
1207.78	736
1211.01	778
1214.24	738
1217.46	732
1220.69	712
1223.91	720
1227.14	716
1230.36	678
1233.58	694
1236.8	664
1240.02	650
1243.23	670
1246.45	662
1249.67	670
1252.88	658
1256.09	648
1259.3	678
1262.51	640
1265.72	674
1268.93	622
1272.13	656
1275.34	644
1278.54	650
1281.74	642
1284.94	692
1288.15	668
1291.34	654
1294.54	704
1297.74	664
1300.93	658
1304.12	664
1307.32	658
1310.51	694
1313.7	654
1316.89	652
1320.07	666
1323.26	676
1326.45	678
1329.63	704
1332.81	660
1335.99	684
1339.17	682
1342.35	688
1345.53	674
1348.71	696
1351.88	692
1355.06	672
1358.23	688
1361.4	690
1364.57	682
1367.74	678
1370.91	656
1374.08	698
1377.24	650
1380.41	668
1383.57	682
1386.73	710
1389.89	666
1393.05	686
1396.21	648
1399.37	658
1402.52	664
1405.68	636
1408.83	674
1411.98	710
1415.13	678
1418.29	684
1421.43	680
1424.58	662
1427.73	692
1430.87	680
1434.02	702
1437.16	700
1440.3	704
1443.44	664
1446.58	686
1449.72	662
1452.85	704
1455.99	666
1459.12	686
1462.26	658
1465.39	698
1468.52	656
1471.65	704
1474.78	704
1477.9	678
1481.03	688
1484.16	710
1487.28	674
1490.4	676
1493.52	704
1496.64	670
1499.76	706
1502.88	706
1506	724
1509.11	690
1512.22	702
1515.34	724
1518.45	688
1521.56	700
1524.67	716
1527.78	722
1530.88	714
1533.99	692
1537.09	736
1540.2	708
1543.3	696
1546.4	688
1549.5	698
1552.6	696
1555.7	734
1558.79	732
1561.89	746
1564.98	702
1568.08	690
1571.17	712
1574.26	704
1577.35	748
1580.43	674
1583.52	688
1586.61	696
1589.69	690
1592.77	720
1595.86	716
1598.94	686
1602.02	678
1605.1	702
1608.18	725.803
1611.25	719.074
1614.33	698.971
1617.4	669.646
1620.47	683.744
1623.55	704.27
1626.62	683.778
1629.69	696.897
1632.75	688.492
1635.82	670.77
1638.89	662.896
1641.95	688.468
1645.02	681.298
1648.08	689.297
1651.14	677.705
1654.2	646.181
1657.26	687.659
1660.32	669.959
1663.37	676.466
1666.43	671.51
1669.48	673.021
1672.54	649.046
1675.59	652.234
1678.64	658.741
1681.69	680.105
1684.74	657.742
1687.79	645.56
1690.83	663.634
1693.88	666.622
1696.92	651.475
1699.96	654.514
1703.01	618.638
1706.05	656.781
1709.09	648.515
1712.12	650.393
1715.16	649.311
1718.2	633.148
1721.23	633.503
1724.27	652.095
1727.3	633.008
1730.33	622.313
1733.36	614.679
1736.39	618.398
1739.42	649.695
1742.44	612.96
1745.47	625.271
1748.49	635.709
1751.52	606.999
1754.54	601.782
1757.56	602.432
1759.14	600
1762.18	624
1765.21	618
1768.24	596
1771.27	626
1774.3	604
1777.32	598
1780.35	626
1783.38	608
1786.4	628
1789.42	606
1792.44	622
1795.47	636
1798.48	614
1801.5	608
1804.52	618
1807.54	628
1810.55	616
1813.57	636
1816.58	596
1819.59	626
1822.6	602
1825.61	616
1828.62	638
1831.63	632
1834.63	608
1837.64	642
1840.64	610
1843.64	640
1846.64	618
1849.64	598
1852.64	616
1855.64	602
1858.64	590
1861.64	620
1864.63	628
1867.63	608
1870.62	622
1873.61	622
1876.6	622
1879.59	612
1882.58	626
1885.56	630
1888.55	626
1891.54	636
1894.52	628
1897.5	592
1900.48	602
1903.46	636
1906.44	632
1909.42	610
1912.4	598
1915.38	628
1918.35	624
1921.32	592
1924.3	604
1927.27	632
1930.24	642
1933.21	628
1936.18	640
1939.15	626
1942.11	594
1945.08	606
1948.04	612
1951	660
1953.97	650
1956.93	636
1959.89	608
1962.85	636
1965.8	598
1968.76	622
1971.71	614
1974.67	626
1977.62	636
1980.57	620
1983.53	634
1986.48	636
1989.42	628
1992.37	628
1995.32	638
1998.26	634
2001.21	614
2004.15	626
2007.09	610
2010.03	600
2012.98	606
2015.92	630
2018.85	616
2021.79	632
2024.73	642
2027.66	624
2030.59	638
2033.53	628
2036.46	628
2039.39	628
2042.32	638
2045.25	636
2048.17	632
2051.1	630
2054.02	624
2056.95	642
2059.87	640
2062.79	616
2065.71	642
2068.63	644
2071.55	646
2074.47	618
2077.39	628
2080.3	648
2083.22	622
2086.13	624
2089.04	646
2091.95	638
2094.86	636
2097.77	640
2100.68	624
2103.59	616
2106.49	616
2109.4	624
2112.3	634
2115.21	640
2118.11	650
2121.01	624
2123.91	636
2126.8	632
2129.7	652
2132.6	646
2135.49	646
2138.39	630
2141.28	634
2144.17	640
2147.06	656
2149.95	658
2152.84	642
2155.73	630
2158.62	648
2161.5	650
2164.39	634
2167.27	648
2170.15	642
2173.04	658
2175.92	660
2178.79	624
2181.67	656
2184.55	642
2187.43	646
2190.3	648
2193.18	638
2196.05	636
2198.92	606
2201.79	634
2204.66	644
2207.53	626
2210.4	654
2213.27	636
2216.13	656
2219	628
2221.86	624
2224.72	610
2227.59	586
2230.45	628
2233.31	604
2236.16	638
2239.02	612
2241.88	626
2244.73	590
2247.59	626
2250.44	634
2253.29	616
2256.15	608
2259	620
2261.84	612
2264.69	634
2267.54	624
2270.39	652
2273.23	610
2276.07	626
2278.92	622
2281.76	638
2284.6	670
2287.44	624
2290.28	636
2293.12	648
2295.95	632
2298.79	628
2301.62	626
2304.46	638
2307.29	656
2310.12	662
2312.95	652
2315.78	656
2318.61	662
2321.44	658
2324.27	680
2327.09	710
2329.92	696
2332.74	698
2335.56	694
2338.38	670
2341.2	674
2344.02	690
2346.84	678
2349.66	724
2352.48	706
2355.29	690
2358.11	710
2360.92	712
2363.73	738
2366.54	720
2369.35	732
2372.16	746
2374.97	740
2377.78	734
2380.58	764
2383.39	758
2386.19	762
2389	790
2391.8	764
2394.6	750
2397.4	768
2400.2	752
2403	778
2405.79	778
2408.59	776
2411.38	794
2414.18	782
2416.97	782
2419.76	772
2422.55	792
2425.34	784
2428.13	758
2430.92	786
2433.71	762
2436.49	820
2439.28	794
2442.06	772
2444.85	792
2447.63	804
2450.41	786
2453.19	812
2455.97	776
2458.75	798
2461.52	812
2464.3	814
2467.07	780
2469.85	772
2472.62	790
2475.39	778
2478.16	782
2480.94	778
2483.7	802
2486.47	794
2489.24	794
2492	792
2494.77	796
2497.53	800
2500.3	784
2503.06	770
2505.82	760
2508.58	796
2511.34	788
2514.1	802
2516.85	764
2519.61	774
2522.37	792
2525.12	808
2527.87	796
2530.63	792
2533.38	822
2536.13	792
2538.88	810
2541.62	810
2544.37	796
2547.12	788
2549.86	770
2552.61	780
2555.35	798
2558.09	800
2560.84	792
2563.57	798
2566.32	780
2569.05	796
2571.79	796
2574.53	810
2577.26	790
2580	794
2582.73	772
2585.46	760
2588.19	806
2590.93	800
2593.66	806
2596.39	782
2599.11	800
2601.84	788
2604.56	812
2607.29	794
2610.01	830
2612.74	828
2615.46	840
2618.18	792
2620.9	804
2623.62	794
2626.34	816
2629.05	810
2631.77	792
2634.48	832
2637.2	838
2639.91	836
2642.62	816
2645.33	816
2648.05	822
2650.75	822
2653.46	838
2656.17	820
2658.88	832
2661.58	832
2664.29	798
2666.99	850
2669.69	850
2672.39	834
2675.09	822
2677.79	832
2680.49	838
2683.19	808
2685.89	842
2688.58	828
2691.28	832
2693.97	836
2696.67	844
2699.36	814
2702.05	820
2704.74	818
2707.43	836
2710.12	828
2712.8	848
2715.49	822
2718.17	848
2720.86	868
2723.54	838
2726.22	854
2728.91	850
2731.59	868
2734.27	818
2736.95	858
2739.62	884
2742.3	868
2744.98	836
2747.65	844
2750.33	862
2753	836
2755.67	858
2758.34	850
2761.01	862
2763.68	878
2766.35	872
2769.02	892
2771.68	858
2774.35	874
2777.01	862
2779.68	898
2782.34	850
2785	856
2787.66	890
2790.32	890
2792.98	918
2795.64	900
2798.3	930
2800.95	892
2803.61	914
2806.26	948
2808.91	928
2811.57	896
2814.22	916
2816.87	928
2819.52	904
2822.17	932
2824.81	906
2827.46	920
2830.11	944
2832.75	922
2835.39	916
2838.04	944
2840.68	930
2843.32	942
2845.96	928
2848.6	958
2851.24	962
2853.88	968
2856.51	950
2859.15	966
2861.78	976
2864.42	946
2867.05	958
2869.68	980
2872.31	986
2874.94	962
2877.57	976
2880.2	1008
2882.82	988
2885.45	966
2888.08	948
2890.7	992
2893.33	934
2895.95	954
2898.57	992
2901.19	964
2903.81	1004
2906.43	998
2909.05	1024
2911.66	984
2914.28	994
2916.89	982
2919.51	997.898
2922.12	994.016
2924.73	1005.76
2927.35	991.412
2929.96	1007.8
2932.57	989.316
2935.17	975.672
2937.78	1012.53
2940.39	1049.43
2943	1007.33
2945.6	1027.82
2948.2	999.423
2950.81	1030.16
2953.41	1027.32
2956.01	1023.78
2958.61	1022.01
2961.21	1047.85
2963.81	1035.97
2966.41	1039.7
2969.01	1022.43
2971.6	1056.33
2974.2	1061.42
2976.79	1048.2
2979.39	1049.66
2981.98	1066.3
2984.57	1060.14
2987.16	1069.24
2989.75	1090.74
2992.34	1020.94
2994.93	1097.44
2997.51	1100.83
3000.1	1063.39
3002.68	1083.19
3005.27	1075.72
3007.85	1081.17
3010.43	1103.08
3013.01	1081.73
3015.59	1106.91
3018.18	1097.57
3020.75	1096.06
3023.33	1114.91
3025.91	1100.27
3028.48	1105.36
3031.06	1126.08
3033.64	1115.4
3036.21	1126.82
3038.78	1132.82
3041.35	1151.27
3043.92	1133.12
3046.49	1142.47
3048.11	1110
3050.69	1168
3053.27	1112
3055.85	1156
3058.43	1148
3061.01	1134
3063.58	1152
3066.16	1158
3068.73	1178
3071.31	1168
3073.88	1172
3076.45	1164
3079.02	1192
3081.59	1170
3084.16	1212
3086.73	1204
3089.29	1172
3091.86	1194
3094.43	1176
3096.99	1188
3099.55	1178
3102.12	1192
3104.68	1182
3107.24	1218
3109.8	1176
3112.36	1256
3114.92	1234
3117.48	1230
3120.03	1234
3122.59	1232
3125.14	1244
3127.7	1266
3130.25	1244
3132.8	1282
3135.35	1228
3137.9	1270
3140.45	1286
3143	1268
3145.55	1248
3148.1	1254
3150.64	1288
3153.19	1318
3155.73	1304
3158.28	1310
3160.82	1334
3163.36	1320
3165.9	1324
3168.44	1290
3170.98	1316
3173.52	1334
3176.06	1326
3178.59	1310
3181.13	1318
3183.66	1344
3186.2	1332
3188.73	1358
3191.26	1284
3193.79	1330
3196.32	1356
3198.85	1370
3201.38	1342
3203.91	1338
3206.44	1392
3208.96	1390
3211.49	1374
3214.01	1390
3216.54	1386
3219.06	1354
3221.58	1350
3224.1	1344
3226.62	1340
3229.14	1418
3231.66	1372
3234.18	1372
3236.69	1392
3239.21	1410
3241.72	1390
3244.24	1326
3246.75	1386
3249.26	1400
3251.78	1400
3254.29	1408
3256.8	1414
3259.3	1418
3261.81	1454
3264.32	1442
3266.83	1420
3269.33	1470
3271.84	1460
3274.34	1488
3276.84	1464
3279.35	1454
3281.85	1470
3284.35	1484
3286.85	1498
3289.35	1488
3291.84	1432
3294.34	1508
3296.84	1544
3299.33	1502
3301.83	1534
3304.32	1542
3306.81	1530
3309.3	1542
3311.79	1520
3314.29	1540
3316.77	1536
3319.26	1544
3321.75	1566
3324.24	1552
3326.72	1572
3329.21	1538
3331.69	1556
3334.18	1556
3336.66	1560
3339.14	1556
3341.62	1568
3344.1	1576
3346.58	1568
3349.06	1618
3351.54	1560
3354.01	1560
3356.49	1592
3358.96	1580
3361.44	1568
3363.91	1632
3366.38	1620
3368.85	1644
3371.33	1598
3373.8	1606
3376.26	1588
3378.73	1626
3381.2	1614
3383.67	1650
3386.13	1680
3388.6	1658
3391.06	1632
3393.52	1622
3395.99	1672
3398.45	1624
3400.91	1698
3403.37	1684
3405.83	1650
3408.29	1648
3410.74	1650
3413.2	1682
3415.66	1706
3418.11	1694
3420.56	1722
3423.02	1698
3425.47	1710
3427.92	1722
3430.37	1732
3432.82	1728
3435.27	1768
3437.72	1766
3440.17	1712
3442.61	1754
3445.06	1764
3447.51	1778
3449.95	1784
3452.39	1784
3454.83	1820
3457.28	1784
3459.72	1808
3462.16	1836
3464.6	1808
3467.04	1804
3469.47	1836
3471.91	1822
3474.34	1838
3476.78	1822
3479.21	1842
3481.65	1844
3484.08	1830
3486.51	1842
3488.94	1842
3491.37	1872
3493.8	1870
3496.23	1812
3498.66	1816
3501.09	1852
3503.51	1854
3505.94	1896
3508.36	1820
3510.79	1830
3513.21	1906
3515.63	1846
3518.05	1824
3520.47	1862
3522.89	1846
3525.31	1836
3527.73	1876
3530.14	1848
3532.56	1852
3534.98	1842
3537.39	1852
3539.81	1904
3542.22	1878
3544.63	1872
3547.04	1864
3549.45	1846
3551.86	1900
3554.27	1884
3556.68	1920
3559.09	1946
3561.49	1926
3563.9	1902
3566.3	1912
3568.71	1914
3571.11	1964
3573.51	1906
3575.92	1948
3578.32	1950
3580.72	1990
3583.12	1998
3585.51	1964
3587.91	1972
3590.31	1966
3592.71	2002
3595.1	2030
3597.49	1996
3599.89	2014
3602.28	2028
3604.67	2018
3607.06	2048
3609.45	2018
3611.84	2076
3614.23	2032
3616.62	2068
3619.01	2074
3621.39	2042
3623.78	2078
3626.17	2034
3628.55	2110
3630.93	2074
3633.31	2052
3635.7	2084
3638.08	2088
3640.46	2144
3642.84	2112
3645.22	2052
3647.59	2106
3649.97	2096
3652.35	2018
3654.72	2070
3657.1	2082
3659.47	2124
3661.84	2080
3664.21	2084
3666.59	2096
3668.96	2104
3671.33	2124
3673.69	2098
3676.06	2074
3678.43	2108
3680.8	2152
3683.16	2054
3685.53	2092
3687.89	2130
3690.25	2148
3692.62	2114
3694.98	2134
3697.34	2102
3699.7	2158
3702.06	2178
3704.42	2158
3706.78	2148
3709.13	2166
3711.49	2144
3713.85	2176
3716.2	2156
3718.56	2132
3720.91	2204
3723.26	2186
3725.61	2184
3727.96	2248
3730.31	2202
3732.66	2260
3735.01	2254
3737.36	2254
3739.7	2268
3742.05	2210
3744.4	2276
3746.74	2296
3749.09	2280
3751.43	2258
3753.77	2318
3756.11	2262
3758.45	2232
3760.79	2304
3763.13	2318
3765.47	2286
3767.81	2324
3770.14	2328
3772.48	2338
3774.82	2384
3777.15	2334
3779.48	2328
3781.82	2344
3784.15	2390
3786.48	2362
3788.81	2360
3791.14	2272
3793.47	2346
3795.8	2388
3798.13	2308
3800.45	2342
3802.78	2356
3805.1	2372
3807.43	2358
3809.75	2370
3812.07	2394
3814.4	2338
3816.72	2356
3819.04	2370
3821.36	2388
3823.68	2374
3826	2306
3828.31	2396
3830.63	2350
3832.95	2360
3835.26	2304
3837.58	2346
3839.89	2366
3842.2	2386
3844.51	2328
3846.83	2378
3849.14	2384
3851.45	2414
3853.76	2378
3856.06	2388
3858.37	2400
3860.68	2404
3862.98	2376
3865.29	2410
3867.59	2382
3869.9	2414
3872.2	2416
3874.5	2408
3876.8	2438
3879.1	2444
3881.4	2434
3883.7	2454
3886	2508
3888.3	2464
3890.6	2504
3892.89	2452
3895.19	2518
3897.48	2486
3899.78	2456
3902.07	2534
3904.36	2560
3906.65	2552
3908.94	2536
3911.23	2540
3913.52	2556
3915.81	2528
3918.1	2554
3920.39	2570
3922.67	2556
3924.96	2558
3927.24	2564
3929.53	2576
3931.81	2584
3934.09	2488
3936.38	2540
3938.66	2644
3940.94	2554
3943.22	2582
3945.5	2592
3947.77	2544
3950.05	2542
3952.33	2572
3954.6	2544
3956.88	2564
3959.15	2610
3961.43	2570
3963.7	2570
3965.97	2594
3968.24	2586
3970.51	2630
3972.78	2586
3975.05	2518
3977.32	2602
3979.59	2598
3981.85	2584
3984.12	2586
3986.39	2532
3988.65	2608
3990.91	2650
3993.18	2590
3995.44	2608
3997.7	2584
3999.96	2658