File: Graficas/datosramanc/CN-Sastre_24.txt
#Acq. time (s)=	20
#Accumulations=	2
#Range (cm-¹)=	50...4000
#Windows=	3
#Autofocus=	Off
#AutoExposure=	Off
#Spike filter=	Multiple accum.
#Delay time (s)=	0
#Binning=	1
#Readout mode=	Signal
#DeNoise=	Off
#ICS correction=	Off
#Dark correction=	Off
#Inst. Process=	Off
#Instrument=	LabRAM HR Evol
#Detector=	Syncerity OE
#Objective=	x100_VIS
#Grating=	600 (500nm)
#ND Filter=	100%
#Laser=	532nm_Edge
#Hole=	100.021
#Range=	Visible
#Project=	Omar
#Sample=
#Site=	21-09-22
#Title=	 CN-Sastre
#Remark=
#Date=	21.09.2022 15:04
#Acquired=	21.09.2022 15:04:10
51.0918	46
54.7807	56
58.4681	122
62.154	274
65.8385	464
69.5216	756
73.2032	1208
76.8834	1608
80.5621	2022
84.2393	2380
87.9152	2614
91.5874	2704
95.2603	2690
98.9318	2822
102.602	2788
106.27	2842
109.936	2836
113.601	2844
117.266	2822
120.926	2816
124.588	2754
128.246	2736
131.904	2676
135.561	2680
139.215	2738
142.869	2710
146.52	2796
150.171	2724
153.819	2786
157.465	2734
161.112	2706
164.756	2762
168.398	2700
172.041	2646
175.68	2656
179.318	2664
182.955	2688
186.592	2662
190.225	2552
193.857	2562
197.488	2494
201.118	2440
204.746	2434
208.372	2418
211.997	2356
215.621	2336
219.243	2330
222.864	2276
226.483	2272
230.101	2284
233.718	2252
237.331	2256
240.945	2230
244.557	2246
248.168	2316
251.776	2246
255.384	2258
258.991	2248
262.594	2258
266.198	2258
269.799	2226
273.4	2186
277	2162
280.596	2202
284.193	2134
287.786	2228
291.378	2272
294.971	2212
298.561	2222
302.148	2242
305.737	2232
309.322	2284
312.906	2278
316.49	2344
320.071	2310
323.651	2324
327.229	2308
330.806	2286
334.381	2370
337.955	2278
341.528	2314
345.099	2284
348.669	2244
352.238	2328
355.805	2350
359.371	2324
362.935	2292
366.498	2342
370.06	2404
373.62	2342
377.177	2358
380.734	2372
384.29	2396
387.845	2420
391.396	2436
394.948	2464
398.499	2450
402.046	2484
405.594	2486
409.138	2404
412.683	2466
416.225	2444
419.768	2466
423.307	2490
426.844	2494
430.382	2440
433.917	2556
437.451	2418
440.985	2438
444.516	2498
448.045	2510
451.574	2482
455.102	2548
458.628	2560
462.152	2564
465.674	2532
469.196	2536
472.716	2446
476.234	2494
479.752	2466
483.268	2534
486.782	2506
490.295	2478
493.807	2498
497.316	2460
500.825	2536
504.333	2516
507.839	2500
511.344	2520
514.846	2496
518.349	2568
521.85	2620
525.347	2698
528.846	2788
532.341	2864
535.837	2994
539.329	3050
542.822	3128
546.312	3300
549.802	3328
553.289	3454
556.775	3456
560.261	3424
563.744	3460
567.226	3428
570.709	3352
574.188	3256
577.665	3198
581.142	3050
584.617	2928
588.091	2872
591.565	2756
595.036	2662
598.506	2624
601.974	2580
605.442	2442
608.905	2504
612.37	2392
615.833	2446
619.295	2316
622.755	2302
626.215	2310
629.67	2256
633.127	2252
636.582	2198
640.036	2214
643.487	2174
646.938	2168
650.386	2166
653.835	2098
657.282	2122
660.726	2104
664.171	2068
667.613	1992
671.053	2014
674.494	1964
677.931	1952
681.369	1942
684.804	1922
688.238	1888
691.67	1904
695.103	1814
698.533	1834
701.961	1858
705.389	1794
708.814	1762
712.239	1748
715.662	1742
719.084	1672
722.505	1706
725.924	1794
729.342	1728
732.759	1682
736.174	1664
739.589	1666
742.999	1684
746.411	1692
749.821	1728
753.23	1686
756.636	1754
760.043	1758
763.448	1674
766.85	1696
770.252	1736
773.652	1728
777.052	1770
780.448	1646
783.846	1732
787.24	1752
790.635	1734
794.027	1718
797.417	1648
800.808	1672
804.196	1670
807.582	1670
810.968	1616
814.354	1636
817.736	1652
821.118	1612
824.498	1608
827.877	1568
831.254	1578
834.631	1540
838.006	1590
841.38	1532
844.752	1570
848.123	1526
851.493	1542
854.86	1518
858.228	1564
861.594	1576
864.959	1528
868.321	1540
871.683	1522
875.044	1558
878.402	1536
881.761	1496
885.116	1534
888.472	1554
891.825	1534
895.179	1566
898.529	1528
901.88	1590
905.228	1558
908.575	1522
911.922	1598
915.266	1634
918.609	1624
921.951	1662
925.293	1718
928.633	1694
931.97	1736
935.307	1780
938.642	1794
941.977	1792
945.31	1824
948.641	1754
951.972	1762
955.301	1844
958.629	1858
961.955	1846
965.279	1778
968.603	1788
971.926	1840
975.248	1792
978.566	1844
981.886	1842
985.204	1894
988.519	1910
991.834	1906
995.147	1888
998.46	1912
1001.77	1936
1005.08	1990
1008.39	1944
1011.7	2002
1015	1998
1018.3	2040
1021.61	2076
1024.91	2100
1028.21	2140
1031.51	2198
1034.81	2152
1038.1	2250
1041.4	2274
1044.69	2320
1047.99	2276
1051.28	2400
1054.57	2458
1057.86	2418
1061.14	2524
1064.43	2576
1067.72	2584
1071	2698
1074.28	2696
1077.57	2732
1080.84	2840
1084.12	2832
1087.4	2866
1090.68	2874
1093.95	2884
1097.22	2816
1100.5	2862
1103.77	2798
1107.04	2746
1110.31	2700
1113.58	2634
1116.84	2614
1120.1	2512
1123.37	2466
1126.63	2414
1129.89	2342
1133.15	2308
1136.41	2302
1139.67	2196
1142.92	2232
1146.18	2110
1149.43	2042
1152.68	2074
1155.93	2040
1159.18	1986
1162.43	1958
1165.68	1896
1168.93	1922
1172.17	1928
1175.41	1892
1178.66	1872
1181.9	1846
1185.14	1830
1188.37	1808
1191.61	1724
1194.85	1770
1198.08	1720
1201.31	1768
1204.55	1696
1207.78	1676
1211.01	1694
1214.24	1692
1217.46	1656
1220.69	1688
1223.91	1686
1227.14	1634
1230.36	1624
1233.58	1654
1236.8	1652
1240.02	1626
1243.23	1598
1246.45	1592
1249.67	1624
1252.88	1616
1256.09	1652
1259.3	1626
1262.51	1670
1265.72	1646
1268.93	1634
1272.13	1702
1275.34	1654
1278.54	1654
1281.74	1682
1284.94	1712
1288.15	1698
1291.34	1720
1294.54	1752
1297.74	1720
1300.93	1776
1304.12	1774
1307.32	1808
1310.51	1808
1313.7	1844
1316.89	1922
1320.07	1852
1323.26	1872
1326.45	1962
1329.63	1988
1332.81	1952
1335.99	1996
1339.17	1978
1342.35	2086
1345.53	2048
1348.71	2020
1351.88	2110
1355.06	2046
1358.23	2030
1361.4	2020
1364.57	1956
1367.74	1930
1370.91	1898
1374.08	1930
1377.24	1806
1380.41	1846
1383.57	1786
1386.73	1798
1389.89	1742
1393.05	1758
1396.21	1780
1399.37	1720
1402.52	1720
1405.68	1712
1408.83	1712
1411.98	1758
1415.13	1740
1418.29	1746
1421.43	1750
1424.58	1726
1427.73	1716
1430.87	1710
1434.02	1756
1437.16	1670
1440.3	1740
1443.44	1724
1446.58	1684
1449.72	1720
1452.85	1672
1455.99	1750
1459.12	1684
1462.26	1700
1465.39	1750
1468.52	1712
1471.65	1714
1474.78	1678
1477.9	1746
1481.03	1698
1484.16	1686
1487.28	1692
1490.4	1692
1493.52	1682
1496.64	1722
1499.76	1694
1502.88	1764
1506	1778
1509.11	1714
1512.22	1738
1515.34	1730
1518.45	1782
1521.56	1780
1524.67	1708
1527.78	1768
1530.88	1804
1533.99	1750
1537.09	1798
1540.2	1760
1543.3	1758
1546.4	1856
1549.5	1852
1552.6	1876
1555.7	1856
1558.79	1858
1561.89	1950
1564.98	1966
1568.08	1958
1571.17	2026
1574.26	2036
1577.35	2034
1580.43	2048
1583.52	2014
1586.61	2056
1589.69	2066
1592.77	2070
1595.86	1952
1598.94	2034
1602.02	1912
1605.1	1978
1608.18	1956.26
1611.25	1943.26
1614.33	1859.33
1617.4	1852.23
1620.47	1849.88
1623.55	1784.63
1626.62	1726.42
1629.69	1680.14
1632.75	1695.39
1635.82	1643.63
1638.89	1595.02
1641.95	1590.23
1645.02	1616.15
1648.08	1531.16
1651.14	1567.63
1654.2	1540.3
1657.26	1517.22
1660.32	1482.96
1663.37	1487.59
1666.43	1475.41
1669.48	1429.48
1672.54	1399.07
1675.59	1383.04
1678.64	1439.18
1681.69	1387.94
1684.74	1370.33
1687.79	1357.07
1690.83	1314.32
1693.88	1327.04
1696.92	1304.06
1699.96	1269.51
1703.01	1243.47
1706.05	1237.21
1709.09	1227.58
1712.12	1243.88
1715.16	1181.08
1718.2	1174.68
1721.23	1181.67
1724.27	1147.94
1727.3	1151.24
1730.33	1116.38
1733.36	1103.55
1736.39	1087.95
1739.42	1041.97
1742.44	1040.19
1745.47	1015.22
1748.49	1012.28
1751.52	993.57
1754.54	989.444
1757.56	1015.16
1759.14	968
1762.18	942
1765.21	970
1768.24	956
1771.27	980
1774.3	964
1777.32	1014
1780.35	948
1783.38	948
1786.4	984
1789.42	954
1792.44	934
1795.47	964
1798.48	994
1801.5	970
1804.52	958
1807.54	984
1810.55	952
1813.57	950
1816.58	986
1819.59	1008
1822.6	958
1825.61	988
1828.62	992
1831.63	982
1834.63	976
1837.64	976
1840.64	976
1843.64	966
1846.64	962
1849.64	944
1852.64	1008
1855.64	974
1858.64	956
1861.64	938
1864.63	974
1867.63	990
1870.62	972
1873.61	954
1876.6	972
1879.59	980
1882.58	940
1885.56	972
1888.55	954
1891.54	966
1894.52	1002
1897.5	972
1900.48	992
1903.46	1006
1906.44	926
1909.42	990
1912.4	1024
1915.38	996
1918.35	990
1921.32	1030
1924.3	960
1927.27	986
1930.24	1048
1933.21	1012
1936.18	986
1939.15	964
1942.11	980
1945.08	1000
1948.04	964
1951	984
1953.97	980
1956.93	978
1959.89	994
1962.85	968
1965.8	978
1968.76	996
1971.71	968
1974.67	930
1977.62	930
1980.57	956
1983.53	954
1986.48	946
1989.42	954
1992.37	978
1995.32	948
1998.26	990
2001.21	976
2004.15	972
2007.09	978
2010.03	962
2012.98	978
2015.92	984
2018.85	996
2021.79	962
2024.73	1008
2027.66	970
2030.59	976
2033.53	978
2036.46	1022
2039.39	980
2042.32	950
2045.25	950
2048.17	990
2051.1	972
2054.02	972
2056.95	954
2059.87	1000
2062.79	978
2065.71	960
2068.63	1000
2071.55	988
2074.47	966
2077.39	980
2080.3	1024
2083.22	980
2086.13	982
2089.04	984
2091.95	966
2094.86	1008
2097.77	954
2100.68	978
2103.59	974
2106.49	986
2109.4	970
2112.3	954
2115.21	952
2118.11	952
2121.01	982
2123.91	960
2126.8	974
2129.7	970
2132.6	956
2135.49	954
2138.39	966
2141.28	980
2144.17	980
2147.06	990
2149.95	948
2152.84	954
2155.73	982
2158.62	986
2161.5	972
2164.39	992
2167.27	1004
2170.15	942
2173.04	940
2175.92	998
2178.79	1010
2181.67	990
2184.55	978
2187.43	982
2190.3	976
2193.18	950
2196.05	962
2198.92	984
2201.79	986
2204.66	964
2207.53	1004
2210.4	962
2213.27	982
2216.13	968
2219	934
2221.86	944
2224.72	966
2227.59	936
2230.45	978
2233.31	954
2236.16	910
2239.02	960
2241.88	994
2244.73	968
2247.59	960
2250.44	978
2253.29	956
2256.15	930
2259	958
2261.84	970
2264.69	918
2267.54	960
2270.39	940
2273.23	926
2276.07	976
2278.92	942
2281.76	970
2284.6	964
2287.44	970
2290.28	972
2293.12	980
2295.95	974
2298.79	936
2301.62	996
2304.46	976
2307.29	978
2310.12	970
2312.95	992
2315.78	1010
2318.61	988
2321.44	1036
2324.27	932
2327.09	1058
2329.92	1026
2332.74	994
2335.56	1000
2338.38	1024
2341.2	1012
2344.02	1030
2346.84	966
2349.66	1024
2352.48	1052
2355.29	1044
2358.11	1046
2360.92	1020
2363.73	1060
2366.54	1026
2369.35	1074
2372.16	1064
2374.97	1056
2377.78	1048
2380.58	1058
2383.39	1108
2386.19	1076
2389	1074
2391.8	1080
2394.6	1090
2397.4	1062
2400.2	1058
2403	1116
2405.79	1088
2408.59	1078
2411.38	1088
2414.18	1118
2416.97	1072
2419.76	1092
2422.55	1140
2425.34	1110
2428.13	1104
2430.92	1100
2433.71	1092
2436.49	1094
2439.28	1126
2442.06	1096
2444.85	1080
2447.63	1092
2450.41	1082
2453.19	1136
2455.97	1138
2458.75	1092
2461.52	1168
2464.3	1146
2467.07	1118
2469.85	1152
2472.62	1080
2475.39	1158
2478.16	1076
2480.94	1112
2483.7	1100
2486.47	1136
2489.24	1152
2492	1090
2494.77	1098
2497.53	1092
2500.3	1082
2503.06	1124
2505.82	1132
2508.58	1140
2511.34	1114
2514.1	1106
2516.85	1156
2519.61	1066
2522.37	1102
2525.12	1112
2527.87	1108
2530.63	1162
2533.38	1126
2536.13	1106
2538.88	1056
2541.62	1128
2544.37	1122
2547.12	1078
2549.86	1152
2552.61	1088
2555.35	1144
2558.09	1140
2560.84	1102
2563.57	1092
2566.32	1150
2569.05	1122
2571.79	1100
2574.53	1186
2577.26	1146
2580	1148
2582.73	1148
2585.46	1172
2588.19	1154
2590.93	1172
2593.66	1152
2596.39	1136
2599.11	1164
2601.84	1192
2604.56	1162
2607.29	1210
2610.01	1182
2612.74	1134
2615.46	1138
2618.18	1152
2620.9	1212
2623.62	1188
2626.34	1202
2629.05	1162
2631.77	1190
2634.48	1170
2637.2	1214
2639.91	1212
2642.62	1200
2645.33	1232
2648.05	1216
2650.75	1254
2653.46	1224
2656.17	1234
2658.88	1280
2661.58	1264
2664.29	1256
2666.99	1300
2669.69	1248
2672.39	1234
2675.09	1262
2677.79	1232
2680.49	1272
2683.19	1296
2685.89	1280
2688.58	1258
2691.28	1258
2693.97	1272
2696.67	1294
2699.36	1320
2702.05	1290
2704.74	1338
2707.43	1322
2710.12	1252
2712.8	1284
2715.49	1312
2718.17	1316
2720.86	1276
2723.54	1242
2726.22	1268
2728.91	1262
2731.59	1286
2734.27	1268
2736.95	1230
2739.62	1260
2742.3	1274
2744.98	1290
2747.65	1242
2750.33	1238
2753	1272
2755.67	1288
2758.34	1248
2761.01	1244
2763.68	1276
2766.35	1286
2769.02	1256
2771.68	1320
2774.35	1268
2777.01	1264
2779.68	1280
2782.34	1282
2785	1238
2787.66	1262
2790.32	1260
2792.98	1226
2795.64	1320
2798.3	1286
2800.95	1256
2803.61	1290
2806.26	1250
2808.91	1252
2811.57	1294
2814.22	1232
2816.87	1306
2819.52	1278
2822.17	1292
2824.81	1262
2827.46	1320
2830.11	1322
2832.75	1284
2835.39	1268
2838.04	1334
2840.68	1326
2843.32	1346
2845.96	1338
2848.6	1320
2851.24	1386
2853.88	1394
2856.51	1394
2859.15	1376
2861.78	1368
2864.42	1364
2867.05	1362
2869.68	1356
2872.31	1372
2874.94	1384
2877.57	1422
2880.2	1402
2882.82	1394
2885.45	1394
2888.08	1404
2890.7	1430
2893.33	1392
2895.95	1394
2898.57	1430
2901.19	1408
2903.81	1448
2906.43	1410
2909.05	1390
2911.66	1450
2914.28	1428
2916.89	1408
2919.51	1380.08
2922.12	1466.25
2924.73	1415.69
2927.35	1506.33
2929.96	1417.56
2932.57	1411.62
2935.17	1419.69
2937.78	1418.42
2940.39	1423.13
2943	1428.36
2945.6	1427.15
2948.2	1391.54
2950.81	1406.18
2953.41	1421.27
2956.01	1437.29
2958.61	1418.28
2961.21	1420.66
2963.81	1401.65
2966.41	1417.44
2969.01	1400.85
2971.6	1428.73
2974.2	1388.68
2976.79	1405.16
2979.39	1401.29
2981.98	1384.9
2984.57	1391.16
2987.16	1400.28
2989.75	1399.08
2992.34	1411.99
2994.93	1387.69
2997.51	1428.32
3000.1	1439.97
3002.68	1451.66
3005.27	1436.48
3007.85	1416.91
3010.43	1396.25
3013.01	1430.87
3015.59	1441.12
3018.18	1428.61
3020.75	1430.84
3023.33	1422.4
3025.91	1440.3
3028.48	1445.31
3031.06	1432.36
3033.64	1458.16
3036.21	1448.94
3038.78	1471.18
3041.35	1474.48
3043.92	1462.01
3046.49	1490.77
3048.11	1448
3050.69	1492
3053.27	1526
3055.85	1470
3058.43	1450
3061.01	1484
3063.58	1490
3066.16	1468
3068.73	1446
3071.31	1444
3073.88	1488
3076.45	1480
3079.02	1484
3081.59	1494
3084.16	1460
3086.73	1480
3089.29	1484
3091.86	1468
3094.43	1512
3096.99	1484
3099.55	1526
3102.12	1478
3104.68	1498
3107.24	1534
3109.8	1504
3112.36	1550
3114.92	1532
3117.48	1602
3120.03	1534
3122.59	1516
3125.14	1544
3127.7	1564
3130.25	1528
3132.8	1562
3135.35	1568
3137.9	1590
3140.45	1596
3143	1542
3145.55	1562
3148.1	1554
3150.64	1548
3153.19	1562
3155.73	1624
3158.28	1590
3160.82	1560
3163.36	1582
3165.9	1580
3168.44	1568
3170.98	1626
3173.52	1616
3176.06	1642
3178.59	1638
3181.13	1624
3183.66	1636
3186.2	1608
3188.73	1666
3191.26	1642
3193.79	1608
3196.32	1588
3198.85	1616
3201.38	1622
3203.91	1666
3206.44	1614
3208.96	1618
3211.49	1660
3214.01	1634
3216.54	1636
3219.06	1644
3221.58	1664
3224.1	1648
3226.62	1624
3229.14	1660
3231.66	1654
3234.18	1680
3236.69	1666
3239.21	1628
3241.72	1640
3244.24	1654
3246.75	1666
3249.26	1634
3251.78	1718
3254.29	1696
3256.8	1694
3259.3	1680
3261.81	1632
3264.32	1698
3266.83	1668
3269.33	1702
3271.84	1684
3274.34	1656
3276.84	1698
3279.35	1712
3281.85	1678
3284.35	1732
3286.85	1734
3289.35	1706
3291.84	1694
3294.34	1734
3296.84	1786
3299.33	1756
3301.83	1766
3304.32	1798
3306.81	1740
3309.3	1752
3311.79	1750
3314.29	1784
3316.77	1768
3319.26	1800
3321.75	1776
3324.24	1766
3326.72	1780
3329.21	1798
3331.69	1802
3334.18	1812
3336.66	1790
3339.14	1858
3341.62	1762
3344.1	1818
3346.58	1796
3349.06	1822
3351.54	1838
3354.01	1832
3356.49	1890
3358.96	1820
3361.44	1792
3363.91	1820
3366.38	1798
3368.85	1818
3371.33	1866
3373.8	1818
3376.26	1828
3378.73	1874
3381.2	1838
3383.67	1816
3386.13	1826
3388.6	1836
3391.06	1844
3393.52	1838
3395.99	1858
3398.45	1846
3400.91	1860
3403.37	1924
3405.83	1922
3408.29	1886
3410.74	1874
3413.2	1888
3415.66	1938
3418.11	1888
3420.56	1940
3423.02	1894
3425.47	1916
3427.92	1920
3430.37	1966
3432.82	1928
3435.27	1984
3437.72	1928
3440.17	1980
3442.61	1978
3445.06	2008
3447.51	1994
3449.95	1964
3452.39	2002
3454.83	2022
3457.28	1954
3459.72	1992
3462.16	2060
3464.6	1990
3467.04	2066
3469.47	2016
3471.91	2082
3474.34	2044
3476.78	2038
3479.21	2058
3481.65	2040
3484.08	2100
3486.51	2062
3488.94	2048
3491.37	2084
3493.8	2046
3496.23	2078
3498.66	2062
3501.09	2044
3503.51	2030
3505.94	2034
3508.36	2060
3510.79	1998
3513.21	1992
3515.63	2054
3518.05	2074
3520.47	2026
3522.89	2096
3525.31	2026
3527.73	2094
3530.14	2048
3532.56	2002
3534.98	2024
3537.39	2058
3539.81	2074
3542.22	2064
3544.63	2126
3547.04	2066
3549.45	2104
3551.86	2048
3554.27	2086
3556.68	2118
3559.09	2088
3561.49	2128
3563.9	2070
3566.3	2108
3568.71	2134
3571.11	2092
3573.51	2158
3575.92	2156
3578.32	2152
3580.72	2184
3583.12	2100
3585.51	2158
3587.91	2156
3590.31	2164
3592.71	2146
3595.1	2192
3597.49	2214
3599.89	2154
3602.28	2150
3604.67	2220
3607.06	2214
3609.45	2194
3611.84	2216
3614.23	2242
3616.62	2196
3619.01	2266
3621.39	2254
3623.78	2266
3626.17	2274
3628.55	2196
3630.93	2264
3633.31	2256
3635.7	2240
3638.08	2232
3640.46	2274
3642.84	2240
3645.22	2260
3647.59	2304
3649.97	2260
3652.35	2248
3654.72	2214
3657.1	2260
3659.47	2306
3661.84	2290
3664.21	2270
3666.59	2232
3668.96	2276
3671.33	2224
3673.69	2222
3676.06	2246
3678.43	2316
3680.8	2226
3683.16	2254
3685.53	2304
3687.89	2290
3690.25	2280
3692.62	2278
3694.98	2262
3697.34	2226
3699.7	2258
3702.06	2284
3704.42	2276
3706.78	2288
3709.13	2336
3711.49	2230
3713.85	2370
3716.2	2278
3718.56	2378
3720.91	2326
3723.26	2370
3725.61	2374
3727.96	2366
3730.31	2352
3732.66	2398
3735.01	2366
3737.36	2394
3739.7	2440
3742.05	2412
3744.4	2432
3746.74	2426
3749.09	2366
3751.43	2380
3753.77	2416
3756.11	2478
3758.45	2466
3760.79	2464
3763.13	2426
3765.47	2480
3767.81	2452
3770.14	2456
3772.48	2474
3774.82	2398
3777.15	2514
3779.48	2436
3781.82	2406
3784.15	2506
3786.48	2454
3788.81	2536
3791.14	2424
3793.47	2494
3795.8	2470
3798.13	2482
3800.45	2454
3802.78	2444
3805.1	2432
3807.43	2450
3809.75	2420
3812.07	2482
3814.4	2470
3816.72	2462
3819.04	2486
3821.36	2468
3823.68	2452
3826	2442
3828.31	2472
3830.63	2442
3832.95	2450
3835.26	2444
3837.58	2498
3839.89	2496
3842.2	2410
3844.51	2522
3846.83	2514
3849.14	2530
3851.45	2492
3853.76	2472
3856.06	2494
3858.37	2472
3860.68	2498
3862.98	2502
3865.29	2500
3867.59	2510
3869.9	2550
3872.2	2574
3874.5	2596
3876.8	2530
3879.1	2526
3881.4	2584
3883.7	2558
3886	2588
3888.3	2552
3890.6	2650
3892.89	2630
3895.19	2630
3897.48	2612
3899.78	2626
3902.07	2670
3904.36	2708
3906.65	2642
3908.94	2672
3911.23	2660
3913.52	2588
3915.81	2662
3918.1	2628
3920.39	2708
3922.67	2692
3924.96	2682
3927.24	2670
3929.53	2706
3931.81	2686
3934.09	2650
3936.38	2630
3938.66	2666
3940.94	2652
3943.22	2686
3945.5	2724
3947.77	2708
3950.05	2698
3952.33	2608
3954.6	2692
3956.88	2718
3959.15	2680
3961.43	2700
3963.7	2680
3965.97	2680
3968.24	2744
3970.51	2666
3972.78	2704
3975.05	2672
3977.32	2702
3979.59	2714
3981.85	2750
3984.12	2722
3986.39	2762
3988.65	2684
3990.91	2660
3993.18	2686
3995.44	2664
3997.7	2706
3999.96	2738