File: ploting_and_data_tools.ipynb/archivosraman/CdSe4_03.txt
#Acq. time (s)=	1
#Accumulations=	1
#Range (eV)=	2...1
#Windows=	11
#Autofocus=	Off
#AutoExposure=	Off
#Spike filter=	Off
#Delay time (s)=	0
#Binning=	1
#Readout mode=	Signal
#DeNoise=	Off
#ICS correction=	Off
#Dark correction=	Off
#Inst. Process=	Off
#Instrument=	LabRAM HR Evol
#Detector=	Syncerity OE
#Objective=	x100_VIS_LWD
#Grating=	600 (500nm)
#ND Filter=	1%
#Laser=	442nm_Notch
#Hole=	150.001
#Range=	Visible
#Project=	Paty
#Sample=
#Site=	15-06-22
#Title=	CdSe4
#Remark=
#Date=	15.06.2022 21:33
#Acquired=	15.06.2022 21:33:50
2.74975	28
2.7475	32
2.74525	32
2.743	28
2.74076	26
2.73852	36
2.73629	34
2.73406	32
2.73183	42
2.72961	26
2.72739	34
2.72517	24
2.72296	38
2.72075	28
2.71854	30
2.71634	24
2.71414	34
2.71195	30
2.70976	30
2.70757	38
2.70539	32
2.70321	34
2.70103	38
2.69886	34
2.69669	30
2.69452	36
2.69236	30
2.6902	34
2.68805	30
2.6859	36
2.68375	40
2.68161	40
2.67947	44
2.67733	34
2.6752	40
2.67307	30
2.67094	38
2.66882	42
2.6667	44
2.66458	34
2.66247	40
2.66036	46
2.65826	40
2.65615	34
2.65405	42
2.65196	34
2.64987	40
2.64778	40
2.64569	48
2.64361	48
2.64153	46
2.63946	44
2.63739	44
2.63532	52
2.63325	50
2.63119	48
2.62913	48
2.62708	58
2.62503	56
2.62298	54
2.62094	56
2.61889	54
2.61686	60
2.61482	62
2.61279	64
2.61076	68
2.60873	56
2.60671	68
2.60469	70
2.60268	72
2.60067	74
2.59866	62
2.59665	80
2.59465	84
2.59265	66
2.59065	92
2.58866	88
2.58667	98
2.58468	94
2.5827	92
2.58072	98
2.57874	90
2.57677	100
2.5748	106
2.57283	100
2.57086	104
2.5689	126
2.56694	134
2.56499	128
2.56304	130
2.56109	128
2.55914	142
2.5572	156
2.55526	152
2.55332	144
2.55139	166
2.54946	182
2.54753	174
2.5456	172
2.54368	174
2.54176	182
2.53985	198
2.53794	198
2.53603	210
2.53412	210
2.53222	222
2.53031	234
2.52842	250
2.52652	258
2.52463	284
2.52274	290
2.52085	274
2.51897	334
2.51709	320
2.51521	330
2.51334	324
2.51147	368
2.5096	380
2.50773	362
2.50587	394
2.50401	394
2.50216	402
2.5003	442
2.49845	452
2.4966	476
2.49476	474
2.49291	496
2.49107	488
2.48924	512
2.4874	544
2.48557	552
2.48374	556
2.48192	604.784
2.48009	631.499
2.47827	650.311
2.47646	686.147
2.47464	720.224
2.47283	751.281
2.47102	781.55
2.46922	808.017
2.46741	865.473
2.46561	901.062
2.46381	951.307
2.46202	1001.93
2.46023	1022.11
2.45844	1074.26
2.45665	1116.08
2.45493	1182
2.45314	1192
2.45136	1222
2.44957	1254
2.44779	1278
2.44601	1320
2.44424	1326
2.44247	1334
2.4407	1394
2.43893	1426
2.43716	1416
2.4354	1514
2.43364	1466
2.43188	1582
2.43013	1572
2.42838	1604
2.42663	1642
2.42488	1652
2.42314	1646
2.4214	1724
2.41966	1692
2.41792	1750
2.41619	1778
2.41446	1842
2.41273	1832
2.411	1896
2.40928	1900
2.40756	1936
2.40584	1984
2.40413	2010
2.40241	1966
2.4007	2002
2.39899	2002
2.39729	2074
2.39559	2094
2.39389	2086
2.39219	2050
2.39049	2076
2.3888	2116
2.38711	2154
2.38542	2138
2.38374	2130
2.38205	2190
2.38037	2194
2.37869	2180
2.37702	2266
2.37535	2246
2.37368	2238
2.37201	2216
2.37034	2240
2.36868	2232
2.36702	2222
2.36536	2200
2.3637	2236
2.36205	2184
2.3604	2230
2.35875	2210
2.3571	2228
2.35546	2178
2.35382	2166
2.35218	2160
2.35054	2198
2.34891	2130
2.34727	2134
2.34564	2120
2.34402	2100
2.34239	2080
2.34077	2070
2.33915	2012
2.33753	2026
2.33591	2016
2.3343	1954
2.33269	1948
2.33108	2008
2.32948	1942
2.32787	1926
2.32627	1886
2.32467	1904
2.32307	1830
2.32148	1804
2.31989	1792
2.3183	1774
2.31671	1832
2.31512	1784
2.31354	1762
2.31196	1754
2.31038	1728
2.3088	1712
2.30723	1734
2.30565	1650
2.30408	1636
2.30252	1616
2.30095	1628
2.29939	1588
2.29783	1632
2.29627	1602
2.29471	1606
2.29316	1584
2.29161	1580
2.29006	1524
2.28851	1534
2.28696	1508
2.28542	1526
2.28388	1504
2.28234	1466
2.2808	1492
2.27927	1478
2.27773	1454
2.2762	1432
2.27468	1468
2.27315	1450
2.27163	1386
2.27011	1430
2.26859	1402
2.26707	1462
2.26555	1400
2.26404	1370
2.26253	1368.6
2.26102	1368.52
2.25951	1332
2.25801	1323.35
2.25651	1356.58
2.25501	1371.28
2.25351	1340.78
2.25201	1316.26
2.25052	1322.68
2.24902	1313.17
2.24753	1309.72
2.24605	1268.86
2.24456	1278.18
2.24308	1296.55
2.2416	1248.59
2.24011	1242
2.23863	1256
2.23715	1248
2.23567	1210
2.23419	1206
2.23271	1206
2.23124	1188
2.22977	1230
2.2283	1164
2.22683	1240
2.22536	1170
2.2239	1176
2.22244	1178
2.22098	1106
2.21952	1146
2.21807	1118
2.21661	1130
2.21516	1118
2.21371	1106
2.21226	1118
2.21082	1128
2.20937	1102
2.20793	1074
2.20649	1118
2.20505	1112
2.20362	1084
2.20218	1066
2.20075	1108
2.19932	1064
2.19789	1048
2.19647	1064
2.19504	1050
2.19362	1048
2.1922	1088
2.19078	1082
2.18936	1064
2.18795	1032
2.18654	1050
2.18513	1004
2.18372	1064
2.18231	1006
2.18091	988
2.1795	1030
2.1781	996
2.1767	990
2.1753	1038
2.17391	970
2.17251	1008
2.17112	996
2.16973	1020
2.16834	1052
2.16696	1018
2.16557	1006
2.16419	960
2.16281	1008
2.16143	956
2.16005	1004
2.15868	1002
2.1573	986
2.15593	980
2.15456	994
2.1532	1006
2.15183	984
2.15046	952
2.1491	998
2.14774	990
2.14638	1028
2.14503	988
2.14367	958
2.14232	994
2.14097	984
2.13962	996
2.13827	998
2.13692	994
2.13558	1032
2.13423	1028
2.13289	1026
2.13155	986
2.13022	992
2.12888	1028
2.12755	956
2.12621	992
2.12488	980
2.12356	966
2.12223	1034
2.1209	1014
2.11958	1000
2.11826	992
2.11694	958
2.11562	968
2.1143	994
2.11299	998
2.11168	986
2.11037	978
2.10906	986
2.10775	984
2.10644	988
2.10514	988
2.10384	958
2.10253	1002
2.10123	1048
2.09994	1002
2.09864	1006
2.09735	988
2.09605	970
2.09476	980
2.09347	976
2.09219	964
2.0909	998
2.08962	1008
2.08834	1018
2.08705	990
2.08578	976
2.0845	992
2.08322	992
2.08195	988
2.08068	980
2.0794	987.568
2.07814	966.021
2.07687	970.572
2.0756	938.484
2.07434	957.314
2.07307	953.815
2.07181	953.212
2.07055	936.869
2.0693	941.649
2.06804	948.777
2.06679	935.992
2.06553	924.029
2.06428	906.36
2.06303	936.668
2.06178	921.373
2.06069	900
2.05944	924
2.05819	926
2.05694	924
2.05569	912
2.05445	958
2.05321	916
2.05196	930
2.05072	968
2.04949	924
2.04825	910
2.04701	930
2.04578	900
2.04455	896
2.04332	908
2.04209	914
2.04086	880
2.03964	904
2.03841	868
2.03719	902
2.03597	874
2.03475	874
2.03353	872
2.03232	868
2.0311	878
2.02989	852
2.02868	864
2.02747	864
2.02626	878
2.02505	846
2.02384	910
2.02264	890
2.02144	886
2.02024	876
2.01904	844
2.01784	906
2.01664	920
2.01544	896
2.01425	898
2.01306	918
2.01187	912
2.01068	916
2.00949	928
2.0083	940
2.00712	904
2.00594	924
2.00475	932
2.00357	912
2.0024	976
2.00122	924
2.00004	944
1.99887	938
1.99769	960
1.99652	980
1.99535	932
1.99418	954
1.99302	980
1.99185	936
1.99069	978
1.98952	960
1.98836	962
1.9872	982
1.98604	978
1.98488	1006
1.98373	1022
1.98257	1008
1.98142	996
1.98027	1016
1.97912	1012
1.97797	986
1.97682	1010
1.97568	1018
1.97453	992
1.97339	1000
1.97225	1022
1.97111	1006
1.96997	1064
1.96883	988
1.9677	1044
1.96656	1020
1.96543	1048
1.9643	1018
1.96316	1062
1.96204	1040
1.96091	986
1.95978	1024
1.95866	1028
1.95753	1016
1.95641	1094
1.95529	1032
1.95417	1026
1.95305	998
1.95193	1054
1.95082	1020
1.9497	1052
1.94859	1080
1.94748	1080
1.94637	1046
1.94526	1046
1.94415	1030
1.94305	1048
1.94194	1082
1.94084	1062
1.93974	1072
1.93864	1022
1.93754	1054
1.93644	1074
1.93534	1086
1.93425	1066
1.93315	1070
1.93206	1044
1.93097	1074
1.92988	1046
1.92879	1070
1.9277	1050
1.92662	1078
1.92553	1066
1.92445	1067.32
1.92337	1066.87
1.92228	1056.02
1.92121	1038.02
1.92013	1034.25
1.91905	1064.2
1.91797	1043.72
1.9169	1055.23
1.91583	1013.62
1.91475	1036.78
1.91368	1052.28
1.91261	1046.31
1.91155	1040.71
1.91048	1031.46
1.90946	1054
1.90839	1048
1.90732	1054
1.90626	1054
1.90519	1046
1.90413	1022
1.90306	1062
1.902	1074
1.90094	1024
1.89988	1030
1.89882	1022
1.89777	1092
1.89671	1020
1.89566	1026
1.8946	1056
1.89355	1066
1.8925	1008
1.89145	1010
1.8904	1018
1.88936	1060
1.88831	1034
1.88727	1036
1.88622	1020
1.88518	1016
1.88414	1026
1.8831	1034
1.88206	1036
1.88102	1010
1.87999	1058
1.87895	1036
1.87792	1042
1.87689	1038
1.87586	1028
1.87483	1040
1.8738	996
1.87277	1080
1.87174	1044
1.87072	1048
1.86969	1030
1.86867	1012
1.86765	1052
1.86663	1040
1.86561	1040
1.86459	1004
1.86357	990
1.86256	1032
1.86154	1052
1.86053	1032
1.85952	1038
1.85851	972
1.8575	988
1.85649	1026
1.85548	1000
1.85447	1008
1.85347	994
1.85247	1074
1.85146	1026
1.85046	1002
1.84946	1046
1.84846	1006
1.84746	998
1.84646	1006
1.84547	1020
1.84447	1004
1.84348	1006
1.84249	998
1.8415	982
1.84051	1042
1.83952	1042
1.83853	996
1.83754	982
1.83656	1006
1.83557	1012
1.83459	986
1.83361	960
1.83262	986
1.83164	928
1.83066	998
1.82969	970
1.82871	990
1.82773	994
1.82676	936
1.82579	970
1.82481	944
1.82384	948
1.82287	990
1.8219	992
1.82094	968
1.81997	960
1.819	946
1.81804	972
1.81708	946
1.81611	964
1.81515	946
1.81419	1000
1.81323	954
1.81227	956
1.81132	942
1.81036	946
1.80941	948
1.80845	948
1.8075	988
1.80655	896
1.8056	926
1.80465	964
1.8037	962
1.80275	898
1.80181	916
1.80086	926
1.79992	950
1.79897	934
1.79803	924
1.79709	912
1.79615	906
1.79521	884
1.79428	918
1.79334	920
1.7924	942
1.79147	906.315
1.79053	939.053
1.7896	885.66
1.78867	900.199
1.78774	907.797
1.78681	903.993
1.78588	880.996
1.78496	876.963
1.78403	878.645
1.7831	902.774
1.78218	879.677
1.78126	866.389
1.78033	864.735
1.77941	861.488
1.77851	872
1.77759	844
1.77667	860
1.77575	846
1.77483	858
1.77391	846
1.77299	854
1.77207	846
1.77115	870
1.77024	830
1.76932	818
1.76841	848
1.7675	838
1.76659	794
1.76568	814
1.76477	824
1.76386	852
1.76295	804
1.76204	776
1.76114	796
1.76023	810
1.75933	826
1.75843	794
1.75753	784
1.75662	812
1.75572	792
1.75483	794
1.75393	798
1.75303	766
1.75214	762
1.75124	762
1.75035	770
1.74945	736
1.74856	774
1.74767	758
1.74678	754
1.74589	758
1.74501	730
1.74412	748
1.74323	730
1.74235	712
1.74146	722
1.74058	740
1.7397	760
1.73882	726
1.73794	698
1.73706	692
1.73618	734
1.7353	736
1.73443	686
1.73355	718
1.73268	714
1.7318	684
1.73093	728
1.73006	694
1.72919	686
1.72832	690
1.72745	718
1.72658	704
1.72571	660
1.72485	686
1.72398	648
1.72312	668
1.72225	650
1.72139	654
1.72053	680
1.71967	620
1.71881	660
1.71795	656
1.71709	658
1.71624	636
1.71538	672
1.71453	624
1.71367	640
1.71282	660
1.71197	634
1.71112	584
1.71027	632
1.70942	610
1.70857	602
1.70772	614
1.70687	622
1.70603	584
1.70518	582
1.70434	574
1.7035	594
1.70265	614
1.70181	588
1.70097	566
1.70013	578
1.69929	564
1.69846	580
1.69762	566
1.69678	548
1.69595	552
1.69511	550
1.69428	560
1.69345	574
1.69262	518
1.69179	536
1.69096	508
1.69013	494
1.6893	502
1.68847	504
1.68765	536
1.68682	532
1.686	494
1.68517	516
1.68435	504
1.68353	494
1.68271	502
1.68189	498
1.68107	484
1.68025	482
1.67943	514
1.67861	482
1.6778	502
1.67698	484.029
1.67617	493.337
1.67536	491.251
1.67454	489.787
1.67373	489.188
1.67292	485.058
1.67211	484.077
1.6713	485.432
1.6705	479.942
1.66969	476.647
1.66888	476.395
1.66808	468.328
1.66727	474.05
1.66647	486.912
1.66566	461.64
1.6649	450
1.66409	436
1.66329	470
1.66249	482
1.66168	464
1.66088	460
1.66008	450
1.65928	446
1.65848	460
1.65768	464
1.65688	440
1.65608	428
1.65529	458
1.65449	434
1.6537	436
1.6529	426
1.65211	438
1.65132	436
1.65053	438
1.64973	412
1.64894	418
1.64816	426
1.64737	438
1.64658	434
1.64579	418
1.64501	412
1.64422	394
1.64344	402
1.64265	396
1.64187	404
1.64109	390
1.64031	386
1.63953	400
1.63875	382
1.63797	408
1.63719	386
1.63642	404
1.63564	392
1.63486	388
1.63409	388
1.63331	370
1.63254	382
1.63177	338
1.631	352
1.63023	368
1.62946	360
1.62869	354
1.62792	362
1.62715	354
1.62639	382
1.62562	352
1.62485	362
1.62409	324
1.62333	356
1.62256	334
1.6218	340
1.62104	358
1.62028	332
1.61952	302
1.61876	346
1.618	328
1.61724	346
1.61649	324
1.61573	346
1.61498	318
1.61422	330
1.61347	306
1.61271	322
1.61196	298
1.61121	314
1.61046	314
1.60971	296
1.60896	286
1.60821	314
1.60747	310
1.60672	292
1.60597	312
1.60523	316
1.60448	300
1.60374	278
1.603	308
1.60225	286
1.60151	278
1.60077	266
1.60003	248
1.59929	292
1.59855	292
1.59782	274
1.59708	276
1.59634	250
1.59561	276
1.59487	268
1.59414	248
1.5934	266
1.59267	252
1.59194	276
1.59121	264
1.59048	264
1.58975	238
1.58902	240
1.58829	254
1.58756	244
1.58684	244
1.58611	236
1.58538	230
1.58466	256
1.58394	254
1.58321	224
1.58249	220
1.58177	234
1.58105	228
1.58033	244
1.57961	228
1.57889	238
1.57817	216
1.57745	216
1.57674	238
1.57602	207.949
1.5753	209.034
1.57459	221.045
1.57388	218.74
1.57316	207.218
1.57245	208.267
1.57174	206.278
1.57103	209.139
1.57032	192.586
1.56961	205.057
1.5689	190.537
1.56819	192.012
1.56748	175.73
1.56678	187.183
1.56607	175.62
1.56544	180
1.56473	166
1.56402	190
1.56331	190
1.56261	164
1.5619	190
1.56119	174
1.56049	172
1.55979	172
1.55908	176
1.55838	182
1.55768	180
1.55698	158
1.55628	166
1.55558	176
1.55488	172
1.55418	162
1.55348	170
1.55278	152
1.55209	178
1.55139	146
1.5507	156
1.55	156
1.54931	144
1.54862	170
1.54792	148
1.54723	152
1.54654	138
1.54585	150
1.54516	126
1.54447	154
1.54378	144
1.5431	146
1.54241	132
1.54172	154
1.54104	134
1.54035	132
1.53967	146
1.53898	156
1.5383	134
1.53762	144
1.53694	146
1.53626	140
1.53558	144
1.5349	136
1.53422	128
1.53354	130
1.53286	138
1.53218	130
1.53151	140
1.53083	136
1.53016	126
1.52948	122
1.52881	130
1.52813	142
1.52746	114
1.52679	124
1.52612	116
1.52545	128
1.52478	108
1.52411	118
1.52344	120
1.52277	96
1.5221	118
1.52144	132
1.52077	138
1.52011	124
1.51944	104
1.51878	114
1.51811	108
1.51745	110
1.51679	102
1.51613	116
1.51547	102
1.51481	106
1.51415	118
1.51349	108
1.51283	110
1.51217	106
1.51151	106
1.51086	98
1.5102	110
1.50954	100
1.50889	98
1.50824	108
1.50758	116
1.50693	106
1.50628	106
1.50563	90
1.50497	94
1.50432	98
1.50367	114
1.50302	94
1.50238	100
1.50173	108
1.50108	104
1.50043	92
1.49979	86
1.49914	90
1.4985	86
1.49785	98
1.49721	90
1.49657	98
1.49592	104
1.49528	104
1.49464	96
1.494	94
1.49336	82
1.49272	96
1.49208	90
1.49144	98
1.49081	96
1.49017	94
1.48953	94
1.4889	88
1.48826	74
1.48763	88
1.48699	70.0297
1.48636	81.4962
1.48573	88.1302
1.4851	87.8137
1.48446	87.6591
1.48383	80.1594
1.4832	87.7843
1.48257	85.6193
1.48194	75.9539
1.48132	72.0877
1.48069	72.7616
1.48006	69.0794
1.47943	72.6854
1.47881	74.1976
1.47818	78.8143
1.47756	66
1.47694	82
1.47631	64
1.47568	54
1.47505	64
1.47443	60
1.4738	68
1.47318	74
1.47256	78
1.47193	72
1.47131	72
1.47069	60
1.47006	62
1.46944	58
1.46882	80
1.4682	56
1.46758	74
1.46696	66
1.46635	66
1.46573	62
1.46511	56
1.46449	58
1.46388	50
1.46326	58
1.46265	68
1.46203	56
1.46142	60
1.46081	66
1.46019	42
1.45958	36
1.45897	40
1.45836	48
1.45775	54
1.45714	52
1.45653	50
1.45592	46
1.45531	42
1.4547	44
1.4541	40
1.45349	48
1.45288	56
1.45228	46
1.45167	26
1.45107	26
1.45047	26
1.44986	30
1.44926	38
1.44866	28
1.44806	28
1.44746	26
1.44686	34
1.44626	34
1.44566	30
1.44506	18
1.44446	30
1.44386	28
1.44326	32
1.44267	32
1.44207	28
1.44148	28
1.44088	32
1.44029	30
1.43969	32
1.4391	24
1.43851	24
1.43791	32
1.43732	30
1.43673	28
1.43614	26
1.43555	32
1.43496	30
1.43437	32
1.43378	32
1.4332	30
1.43261	32
1.43202	28
1.43143	28
1.43085	32
1.43026	20
1.42968	32
1.42909	26
1.42851	28
1.42793	22
1.42734	28
1.42676	34
1.42618	38
1.4256	30
1.42502	28
1.42444	22
1.42386	22
1.42328	24
1.4227	30
1.42212	36
1.42155	32
1.42097	34
1.42039	36
1.41982	30
1.41924	20
1.41867	32
1.41809	26
1.41752	28
1.41695	22
1.41637	28
1.4158	32
1.41523	26
1.41466	30
1.41409	24
1.41352	24
1.41295	30
1.41238	28
1.41181	26
1.41124	26
1.41067	30
1.41011	30
1.40954	36
1.40897	36
1.40841	38
1.40784	41.9217
1.40728	39.2846
1.40672	39.9931
1.40615	39.5802
1.40559	41.2618
1.40503	46.6777
1.40446	137.128
1.4039	43.606
1.40334	43.7657
1.40278	41.9289
1.40222	42.389
1.40166	44.6703
1.4011	51.6733
1.40054	45.5745
1.39999	47.9505
1.39947	50
1.3989	50
1.39834	40
1.39779	54
1.39723	50
1.39667	48
1.39611	50
1.39555	46
1.395	46
1.39444	44
1.39388	38
1.39333	48
1.39277	52
1.39222	46
1.39166	44
1.39111	62
1.39056	48
1.39	44
1.38945	46
1.3889	50
1.38835	54
1.3878	48
1.38725	52
1.3867	50
1.38615	46
1.3856	38
1.38505	56
1.3845	50
1.38396	44
1.38341	44
1.38286	48
1.38232	52
1.38177	38
1.38123	40
1.38068	46
1.38014	44
1.3796	52
1.37905	48
1.37851	50
1.37797	38
1.37743	40
1.37688	40
1.37634	44
1.3758	38
1.37526	36
1.37472	40
1.37419	48
1.37365	48
1.37311	46
1.37257	38
1.37204	42
1.3715	44
1.37096	36
1.37043	46
1.36989	42
1.36936	38
1.36882	40
1.36829	50
1.36776	44
1.36722	36
1.36669	34
1.36616	54
1.36563	46
1.3651	38
1.36457	38
1.36404	42
1.36351	46
1.36298	42
1.36245	38
1.36192	40
1.36139	42
1.36087	48
1.36034	42
1.35981	38
1.35929	34
1.35876	42
1.35824	42
1.35771	46
1.35719	36
1.35667	42
1.35614	52
1.35562	46
1.3551	32
1.35458	40
1.35406	42
1.35353	42
1.35301	42
1.35249	38
1.35197	34
1.35146	40
1.35094	42
1.35042	52
1.3499	46
1.34938	36
1.34887	38
1.34835	40
1.34783	42
1.34732	40
1.3468	44
1.34629	40
1.34578	34
1.34526	42
1.34475	36
1.34424	42
1.34372	52
1.34321	40
1.3427	38
1.34219	32
1.34168	42
1.34117	36
1.34066	34
1.34015	38
1.33964	32
1.33913	38
1.33862	36
1.33812	30
1.33761	36
1.3371	34.0376
1.3366	42.8932
1.33609	37.3592
1.33558	34.1341
1.33508	32.0659
1.33457	38.368
1.33407	32.6795
1.33357	36.6747
1.33306	37.5935
1.33256	35.4034
1.33206	35.7639
1.33156	32
1.33105	34.6173
1.33055	38.3931
1.33005	37.0232
1.32959	36
1.32909	40
1.32859	38
1.32809	42
1.32758	42
1.32708	28
1.32658	34
1.32608	28
1.32558	46
1.32508	38
1.32458	32
1.32408	36
1.32358	38
1.32309	40
1.32259	42
1.32209	36
1.3216	26
1.3211	32
1.3206	36
1.32011	40
1.31961	34
1.31912	38
1.31862	44
1.31813	38
1.31764	32
1.31714	36
1.31665	36
1.31616	38
1.31567	40
1.31518	36
1.31468	28
1.31419	32
1.3137	34
1.31321	38
1.31272	36
1.31224	36
1.31175	36
1.31126	32
1.31077	38
1.31028	38
1.3098	42
1.30931	30
1.30882	36
1.30834	40
1.30785	34
1.30737	30
1.30688	36
1.3064	34
1.30592	40
1.30543	28
1.30495	36
1.30447	32
1.30399	38
1.3035	30
1.30302	34
1.30254	32
1.30206	34
1.30158	36
1.3011	36
1.30062	40
1.30014	36
1.30001	40