File: ploting_and_data_tools.ipynb/archivosraman/CdSe1_18.txt
#Acq. time (s)=	1
#Accumulations=	1
#Range (eV)=	2...1
#Windows=	11
#Autofocus=	Off
#AutoExposure=	Off
#Spike filter=	Off
#Delay time (s)=	0
#Binning=	1
#Readout mode=	Signal
#DeNoise=	Off
#ICS correction=	Off
#Dark correction=	Off
#Inst. Process=	Off
#Instrument=	LabRAM HR Evol
#Detector=	Syncerity OE
#Objective=	x100_VIS_LWD
#Grating=	600 (500nm)
#ND Filter=	1%
#Laser=	442nm_Notch
#Hole=	150.001
#Range=	Visible
#Project=	Paty
#Sample=
#Site=	15-06-22
#Title=	CdSe1
#Remark=
#Date=	15.06.2022 20:56
#Acquired=	15.06.2022 20:56:58
2.74975	34
2.7475	30
2.74525	38
2.743	46
2.74076	36
2.73852	28
2.73629	38
2.73406	36
2.73183	48
2.72961	40
2.72739	40
2.72517	38
2.72296	50
2.72075	46
2.71854	40
2.71634	40
2.71414	50
2.71195	48
2.70976	32
2.70757	44
2.70539	52
2.70321	44
2.70103	48
2.69886	48
2.69669	50
2.69452	44
2.69236	56
2.6902	52
2.68805	52
2.6859	58
2.68375	46
2.68161	58
2.67947	56
2.67733	54
2.6752	62
2.67307	62
2.67094	48
2.66882	64
2.6667	58
2.66458	68
2.66247	54
2.66036	70
2.65826	72
2.65615	66
2.65405	68
2.65196	82
2.64987	82
2.64778	80
2.64569	86
2.64361	82
2.64153	80
2.63946	90
2.63739	94
2.63532	96
2.63325	96
2.63119	100
2.62913	104
2.62708	104
2.62503	122
2.62298	120
2.62094	132
2.61889	114
2.61686	128
2.61482	142
2.61279	126
2.61076	126
2.60873	152
2.60671	164
2.60469	160
2.60268	158
2.60067	176
2.59866	178
2.59665	176
2.59465	186
2.59265	186
2.59065	192
2.58866	220
2.58667	220
2.58468	228
2.5827	240
2.58072	256
2.57874	282
2.57677	274
2.5748	286
2.57283	292
2.57086	298
2.5689	326
2.56694	352
2.56499	358
2.56304	378
2.56109	366
2.55914	408
2.5572	414
2.55526	486
2.55332	456
2.55139	470
2.54946	512
2.54753	502
2.5456	550
2.54368	550
2.54176	572
2.53985	616
2.53794	648
2.53603	672
2.53412	692
2.53222	724
2.53031	734
2.52842	766
2.52652	808
2.52463	846
2.52274	894
2.52085	926
2.51897	956
2.51709	948
2.51521	1036
2.51334	1040
2.51147	1132
2.5096	1156
2.50773	1154
2.50587	1258
2.50401	1252
2.50216	1302
2.5003	1404
2.49845	1416
2.4966	1486
2.49476	1538
2.49291	1606
2.49107	1658
2.48924	1694
2.4874	1712
2.48557	1780
2.48374	1908
2.48192	1950.53
2.48009	2016.08
2.47827	2035.22
2.47646	2071.39
2.47464	2169.86
2.47283	2196.21
2.47102	2284.31
2.46922	2350.51
2.46741	2405.47
2.46561	2447.29
2.46381	2515.02
2.46202	2610.72
2.46023	2712.09
2.45844	2713.08
2.45665	2867.27
2.45493	2824
2.45314	2948
2.45136	3046
2.44957	3134
2.44779	3146
2.44601	3282
2.44424	3380
2.44247	3322
2.4407	3458
2.43893	3530
2.43716	3658
2.4354	3744
2.43364	3790
2.43188	3774
2.43013	3938
2.42838	3942
2.42663	4064
2.42488	4152
2.42314	4208
2.4214	4236
2.41966	4396
2.41792	4418
2.41619	4568
2.41446	4526
2.41273	4556
2.411	4610
2.40928	4806
2.40756	4800
2.40584	4872
2.40413	4936
2.40241	4910
2.4007	5022
2.39899	5066
2.39729	5134
2.39559	5066
2.39389	5128
2.39219	5208
2.39049	5286
2.3888	5342
2.38711	5328
2.38542	5368
2.38374	5344
2.38205	5362
2.38037	5468
2.37869	5528
2.37702	5502
2.37535	5576
2.37368	5530
2.37201	5542
2.37034	5588
2.36868	5530
2.36702	5500
2.36536	5542
2.3637	5450
2.36205	5492
2.3604	5388
2.35875	5396
2.3571	5430
2.35546	5358
2.35382	5312
2.35218	5346
2.35054	5244
2.34891	5206
2.34727	5194
2.34564	5056
2.34402	5102
2.34239	5008
2.34077	4844
2.33915	4992
2.33753	4870
2.33591	4802
2.3343	4768
2.33269	4706
2.33108	4588
2.32948	4660
2.32787	4586
2.32627	4422
2.32467	4440
2.32307	4442
2.32148	4332
2.31989	4268
2.3183	4266
2.31671	4176
2.31512	4112
2.31354	4074
2.31196	4046
2.31038	3964
2.3088	3922
2.30723	3938
2.30565	3866
2.30408	3824
2.30252	3788
2.30095	3682
2.29939	3722
2.29783	3612
2.29627	3684
2.29471	3518
2.29316	3492
2.29161	3388
2.29006	3430
2.28851	3404
2.28696	3294
2.28542	3364
2.28388	3248
2.28234	3252
2.2808	3218
2.27927	3178
2.27773	3222
2.2762	3068
2.27468	3106
2.27315	2986
2.27163	2980
2.27011	2978
2.26859	2884
2.26707	2872
2.26555	2850
2.26404	2794
2.26253	2853.51
2.26102	2739.59
2.25951	2675.73
2.25801	2650.33
2.25651	2552.81
2.25501	2473.81
2.25351	2488.5
2.25201	2433
2.25052	2368.35
2.24902	2318.41
2.24753	2271.08
2.24605	2221.65
2.24456	2198.62
2.24308	2090.22
2.2416	2063.8
2.24011	1998
2.23863	2062
2.23715	2000
2.23567	1966
2.23419	1956
2.23271	1968
2.23124	1906
2.22977	1880
2.2283	1844
2.22683	1872
2.22536	1844
2.2239	1834
2.22244	1836
2.22098	1812
2.21952	1804
2.21807	1750
2.21661	1784
2.21516	1736
2.21371	1690
2.21226	1700
2.21082	1688
2.20937	1672
2.20793	1636
2.20649	1674
2.20505	1672
2.20362	1616
2.20218	1644
2.20075	1624
2.19932	1632
2.19789	1606
2.19647	1586
2.19504	1622
2.19362	1608
2.1922	1606
2.19078	1592
2.18936	1588
2.18795	1576
2.18654	1592
2.18513	1580
2.18372	1576
2.18231	1558
2.18091	1584
2.1795	1532
2.1781	1556
2.1767	1552
2.1753	1504
2.17391	1492
2.17251	1520
2.17112	1522
2.16973	1508
2.16834	1528
2.16696	1490
2.16557	1540
2.16419	1532
2.16281	1506
2.16143	1514
2.16005	1530
2.15868	1510
2.1573	1426
2.15593	1544
2.15456	1496
2.1532	1518
2.15183	1496
2.15046	1524
2.1491	1468
2.14774	1472
2.14638	1494
2.14503	1556
2.14367	1482
2.14232	1524
2.14097	1498
2.13962	1478
2.13827	1490
2.13692	1484
2.13558	1486
2.13423	1502
2.13289	1548
2.13155	1482
2.13022	1490
2.12888	1544
2.12755	1478
2.12621	1514
2.12488	1474
2.12356	1506
2.12223	1504
2.1209	1496
2.11958	1512
2.11826	1514
2.11694	1484
2.11562	1492
2.1143	1476
2.11299	1542
2.11168	1552
2.11037	1572
2.10906	1504
2.10775	1542
2.10644	1474
2.10514	1552
2.10384	1490
2.10253	1530
2.10123	1534
2.09994	1508
2.09864	1530
2.09735	1558
2.09605	1558
2.09476	1498
2.09347	1536
2.09219	1502
2.0909	1500
2.08962	1520
2.08834	1514
2.08705	1568
2.08578	1498
2.0845	1478
2.08322	1544
2.08195	1518
2.08068	1522
2.0794	1482.71
2.07814	1504.96
2.07687	1476.49
2.0756	1448.75
2.07434	1461.99
2.07307	1445.12
2.07181	1437.13
2.07055	1456.48
2.0693	1416.49
2.06804	1377.97
2.06679	1415.71
2.06553	1406.21
2.06428	1448.06
2.06303	1378.79
2.06178	1381.11
2.06069	1388
2.05944	1364
2.05819	1372
2.05694	1368
2.05569	1392
2.05445	1336
2.05321	1376
2.05196	1364
2.05072	1368
2.04949	1328
2.04825	1378
2.04701	1352
2.04578	1348
2.04455	1314
2.04332	1292
2.04209	1342
2.04086	1342
2.03964	1350
2.03841	1332
2.03719	1354
2.03597	1326
2.03475	1312
2.03353	1290
2.03232	1318
2.0311	1290
2.02989	1318
2.02868	1326
2.02747	1370
2.02626	1282
2.02505	1338
2.02384	1292
2.02264	1320
2.02144	1284
2.02024	1352
2.01904	1352
2.01784	1310
2.01664	1344
2.01544	1346
2.01425	1364
2.01306	1396
2.01187	1400
2.01068	1394
2.00949	1388
2.0083	1404
2.00712	1410
2.00594	1430
2.00475	1384
2.00357	1414
2.0024	1430
2.00122	1376
2.00004	1376
1.99887	1426
1.99769	1434
1.99652	1432
1.99535	1412
1.99418	1396
1.99302	1444
1.99185	1492
1.99069	1440
1.98952	1488
1.98836	1470
1.9872	1480
1.98604	1444
1.98488	1482
1.98373	1436
1.98257	1448
1.98142	1450
1.98027	1494
1.97912	1534
1.97797	1456
1.97682	1430
1.97568	1498
1.97453	1490
1.97339	1516
1.97225	1486
1.97111	1486
1.96997	1502
1.96883	1494
1.9677	1484
1.96656	1500
1.96543	1480
1.9643	1516
1.96316	1524
1.96204	1508
1.96091	1514
1.95978	1478
1.95866	1486
1.95753	1478
1.95641	1522
1.95529	1480
1.95417	1466
1.95305	1544
1.95193	1506
1.95082	1512
1.9497	1488
1.94859	1468
1.94748	1486
1.94637	1454
1.94526	1472
1.94415	1478
1.94305	1536
1.94194	1502
1.94084	1494
1.93974	1494
1.93864	1452
1.93754	1482
1.93644	1486
1.93534	1488
1.93425	1494
1.93315	1448
1.93206	1482
1.93097	1456
1.92988	1442
1.92879	1464
1.9277	1514
1.92662	1494
1.92553	1474
1.92445	1474.78
1.92337	1473.4
1.92228	1466.37
1.92121	1435.61
1.92013	1486.46
1.91905	1446.39
1.91797	1455.34
1.9169	1457.34
1.91583	1428.24
1.91475	1472.56
1.91368	1437.42
1.91261	1433.86
1.91155	1442.26
1.91048	1445.58
1.90946	1428
1.90839	1422
1.90732	1440
1.90626	1414
1.90519	1450
1.90413	1384
1.90306	1434
1.902	1448
1.90094	1412
1.89988	1428
1.89882	1408
1.89777	1424
1.89671	1400
1.89566	1410
1.8946	1414
1.89355	1398
1.8925	1382
1.89145	1394
1.8904	1366
1.88936	1384
1.88831	1380
1.88727	1402
1.88622	1386
1.88518	1356
1.88414	1374
1.8831	1360
1.88206	1348
1.88102	1384
1.87999	1342
1.87895	1382
1.87792	1376
1.87689	1370
1.87586	1382
1.87483	1348
1.8738	1320
1.87277	1332
1.87174	1340
1.87072	1346
1.86969	1324
1.86867	1348
1.86765	1350
1.86663	1306
1.86561	1308
1.86459	1344
1.86357	1352
1.86256	1304
1.86154	1274
1.86053	1336
1.85952	1316
1.85851	1312
1.8575	1298
1.85649	1272
1.85548	1268
1.85447	1282
1.85347	1258
1.85247	1250
1.85146	1292
1.85046	1264
1.84946	1230
1.84846	1292
1.84746	1252
1.84646	1212
1.84547	1246
1.84447	1248
1.84348	1268
1.84249	1270
1.8415	1264
1.84051	1206
1.83952	1274
1.83853	1234
1.83754	1228
1.83656	1230
1.83557	1186
1.83459	1194
1.83361	1244
1.83262	1230
1.83164	1178
1.83066	1198
1.82969	1208
1.82871	1246
1.82773	1138
1.82676	1196
1.82579	1202
1.82481	1202
1.82384	1212
1.82287	1208
1.8219	1158
1.82094	1230
1.81997	1212
1.819	1172
1.81804	1184
1.81708	1156
1.81611	1168
1.81515	1186
1.81419	1144
1.81323	1154
1.81227	1160
1.81132	1132
1.81036	1140
1.80941	1140
1.80845	1126
1.8075	1138
1.80655	1070
1.8056	1130
1.80465	1132
1.8037	1078
1.80275	1100
1.80181	1088
1.80086	1050
1.79992	1052
1.79897	1078
1.79803	1082
1.79709	1092
1.79615	1080
1.79521	1056
1.79428	1056
1.79334	1082
1.7924	1072
1.79147	1035.69
1.79053	1078.32
1.7896	1030.8
1.78867	1018.64
1.78774	1050.88
1.78681	1019.8
1.78588	990.112
1.78496	1001.27
1.78403	1012.96
1.7831	982.745
1.78218	982.76
1.78126	1001.96
1.78033	975.235
1.77941	967.901
1.77851	972
1.77759	946
1.77667	954
1.77575	964
1.77483	936
1.77391	948
1.77299	936
1.77207	940
1.77115	906
1.77024	898
1.76932	918
1.76841	952
1.7675	886
1.76659	914
1.76568	916
1.76477	912
1.76386	864
1.76295	886
1.76204	876
1.76114	884
1.76023	894
1.75933	888
1.75843	878
1.75753	912
1.75662	832
1.75572	870
1.75483	844
1.75393	878
1.75303	838
1.75214	840
1.75124	810
1.75035	834
1.74945	796
1.74856	802
1.74767	838
1.74678	822
1.74589	804
1.74501	786
1.74412	802
1.74323	830
1.74235	776
1.74146	786
1.74058	790
1.7397	794
1.73882	748
1.73794	758
1.73706	736
1.73618	764
1.7353	764
1.73443	774
1.73355	752
1.73268	728
1.7318	744
1.73093	758
1.73006	720
1.72919	744
1.72832	728
1.72745	726
1.72658	744
1.72571	720
1.72485	688
1.72398	680
1.72312	704
1.72225	700
1.72139	694
1.72053	704
1.71967	692
1.71881	676
1.71795	668
1.71709	672
1.71624	644
1.71538	692
1.71453	664
1.71367	670
1.71282	672
1.71197	646
1.71112	648
1.71027	608
1.70942	626
1.70857	644
1.70772	616
1.70687	630
1.70603	608
1.70518	614
1.70434	604
1.7035	636
1.70265	628
1.70181	604
1.70097	572
1.70013	572
1.69929	592
1.69846	620
1.69762	574
1.69678	564
1.69595	570
1.69511	572
1.69428	564
1.69345	544
1.69262	556
1.69179	506
1.69096	534
1.69013	526
1.6893	522
1.68847	502
1.68765	512
1.68682	530
1.686	512
1.68517	506
1.68435	518
1.68353	488
1.68271	502
1.68189	490
1.68107	448
1.68025	528
1.67943	512
1.67861	480
1.6778	492
1.67698	498
1.67617	464.042
1.67536	472.248
1.67454	494.837
1.67373	484.286
1.67292	481.033
1.67211	473.984
1.6713	462.316
1.6705	486.321
1.66969	495.557
1.66888	470.34
1.66808	470.18
1.66727	462.341
1.66647	456.485
1.66566	440.974
1.6649	428
1.66409	480
1.66329	452
1.66249	456
1.66168	442
1.66088	430
1.66008	428
1.65928	430
1.65848	438
1.65768	444
1.65688	410
1.65608	422
1.65529	442
1.65449	432
1.6537	430
1.6529	406
1.65211	414
1.65132	418
1.65053	404
1.64973	440
1.64894	422
1.64816	414
1.64737	378
1.64658	416
1.64579	384
1.64501	408
1.64422	384
1.64344	398
1.64265	386
1.64187	396
1.64109	372
1.64031	378
1.63953	400
1.63875	384
1.63797	362
1.63719	378
1.63642	370
1.63564	372
1.63486	372
1.63409	358
1.63331	352
1.63254	350
1.63177	344
1.631	346
1.63023	358
1.62946	356
1.62869	330
1.62792	328
1.62715	322
1.62639	352
1.62562	330
1.62485	350
1.62409	330
1.62333	312
1.62256	310
1.6218	314
1.62104	304
1.62028	312
1.61952	318
1.61876	316
1.618	310
1.61724	312
1.61649	322
1.61573	300
1.61498	308
1.61422	298
1.61347	286
1.61271	274
1.61196	292
1.61121	308
1.61046	270
1.60971	302
1.60896	276
1.60821	282
1.60747	292
1.60672	270
1.60597	260
1.60523	264
1.60448	272
1.60374	262
1.603	280
1.60225	254
1.60151	266
1.60077	274
1.60003	256
1.59929	254
1.59855	242
1.59782	258
1.59708	246
1.59634	240
1.59561	250
1.59487	250
1.59414	240
1.5934	248
1.59267	232
1.59194	240
1.59121	242
1.59048	246
1.58975	220
1.58902	234
1.58829	222
1.58756	228
1.58684	236
1.58611	220
1.58538	212
1.58466	222
1.58394	214
1.58321	220
1.58249	204
1.58177	206
1.58105	204
1.58033	200
1.57961	204
1.57889	228
1.57817	186
1.57745	200
1.57674	198
1.57602	205.853
1.5753	192.629
1.57459	189.651
1.57388	184.82
1.57316	192.416
1.57245	195.492
1.57174	179.292
1.57103	183.825
1.57032	177.169
1.56961	188.396
1.5689	173.423
1.56819	164.197
1.56748	184.096
1.56678	165.332
1.56607	174.18
1.56544	144
1.56473	150
1.56402	172
1.56331	164
1.56261	182
1.5619	152
1.56119	154
1.56049	166
1.55979	158
1.55908	156
1.55838	148
1.55768	162
1.55698	158
1.55628	148
1.55558	158
1.55488	140
1.55418	160
1.55348	142
1.55278	148
1.55209	132
1.55139	160
1.5507	148
1.55	148
1.54931	134
1.54862	146
1.54792	150
1.54723	150
1.54654	136
1.54585	138
1.54516	138
1.54447	112
1.54378	116
1.5431	126
1.54241	126
1.54172	130
1.54104	120
1.54035	118
1.53967	134
1.53898	126
1.5383	142
1.53762	118
1.53694	112
1.53626	122
1.53558	124
1.5349	128
1.53422	122
1.53354	110
1.53286	122
1.53218	120
1.53151	118
1.53083	116
1.53016	128
1.52948	112
1.52881	108
1.52813	120
1.52746	106
1.52679	112
1.52612	114
1.52545	120
1.52478	114
1.52411	108
1.52344	114
1.52277	120
1.5221	108
1.52144	118
1.52077	104
1.52011	114
1.51944	114
1.51878	108
1.51811	100
1.51745	104
1.51679	106
1.51613	108
1.51547	114
1.51481	100
1.51415	108
1.51349	112
1.51283	98
1.51217	96
1.51151	98
1.51086	108
1.5102	96
1.50954	88
1.50889	92
1.50824	96
1.50758	100
1.50693	96
1.50628	94
1.50563	90
1.50497	92
1.50432	88
1.50367	88
1.50302	88
1.50238	92
1.50173	82
1.50108	90
1.50043	86
1.49979	100
1.49914	90
1.4985	86
1.49785	84
1.49721	92
1.49657	96
1.49592	86
1.49528	78
1.49464	80
1.494	80
1.49336	80
1.49272	76
1.49208	80
1.49144	86
1.49081	78
1.49017	96
1.48953	86
1.4889	74
1.48826	74
1.48763	86
1.48699	69.9703
1.48636	77.3542
1.48573	67.3612
1.4851	68.9181
1.48446	80.1618
1.48383	76.7235
1.4832	69.5497
1.48257	71.2602
1.48194	74.3741
1.48132	61.2634
1.48069	61.8683
1.48006	66.5342
1.47943	69.4272
1.47881	74.0525
1.47818	68.6176
1.47756	64
1.47694	72
1.47631	72
1.47568	62
1.47505	56
1.47443	54
1.4738	66
1.47318	70
1.47256	78
1.47193	60
1.47131	62
1.47069	56
1.47006	66
1.46944	68
1.46882	56
1.4682	58
1.46758	74
1.46696	64
1.46635	70
1.46573	52
1.46511	52
1.46449	54
1.46388	48
1.46326	48
1.46265	50
1.46203	58
1.46142	58
1.46081	60
1.46019	50
1.45958	58
1.45897	58
1.45836	42
1.45775	48
1.45714	52
1.45653	50
1.45592	50
1.45531	34
1.4547	44
1.4541	34
1.45349	42
1.45288	42
1.45228	36
1.45167	34
1.45107	32
1.45047	24
1.44986	34
1.44926	30
1.44866	30
1.44806	22
1.44746	26
1.44686	20
1.44626	34
1.44566	26
1.44506	36
1.44446	26
1.44386	36
1.44326	24
1.44267	28
1.44207	34
1.44148	36
1.44088	26
1.44029	34
1.43969	30
1.4391	30
1.43851	32
1.43791	26
1.43732	30
1.43673	30
1.43614	28
1.43555	32
1.43496	32
1.43437	28
1.43378	32
1.4332	32
1.43261	22
1.43202	30
1.43143	22
1.43085	36
1.43026	30
1.42968	26
1.42909	32
1.42851	28
1.42793	34
1.42734	30
1.42676	30
1.42618	26
1.4256	28
1.42502	28
1.42444	26
1.42386	24
1.42328	26
1.4227	26
1.42212	38
1.42155	30
1.42097	24
1.42039	32
1.41982	20
1.41924	36
1.41867	28
1.41809	34
1.41752	30
1.41695	38
1.41637	28
1.4158	26
1.41523	28
1.41466	28
1.41409	24
1.41352	36
1.41295	24
1.41238	30
1.41181	30
1.41124	34
1.41067	30
1.41011	36
1.40954	22
1.40897	36
1.40841	34
1.40784	37.993
1.40728	36.2834
1.40672	34.5708
1.40615	40.646
1.40559	36.7349
1.40503	37.7159
1.40446	138.946
1.4039	40.9406
1.40334	41.6971
1.40278	37.9738
1.40222	40
1.40166	46.4044
1.4011	40.6535
1.40054	39.4761
1.39999	36.1485
1.39947	34
1.3989	44
1.39834	34
1.39779	40
1.39723	52
1.39667	36
1.39611	46
1.39555	42
1.395	52
1.39444	42
1.39388	42
1.39333	48
1.39277	46
1.39222	48
1.39166	40
1.39111	40
1.39056	44
1.39	40
1.38945	44
1.3889	46
1.38835	42
1.3878	44
1.38725	40
1.3867	44
1.38615	36
1.3856	44
1.38505	40
1.3845	50
1.38396	32
1.38341	42
1.38286	44
1.38232	48
1.38177	52
1.38123	42
1.38068	44
1.38014	42
1.3796	48
1.37905	34
1.37851	36
1.37797	46
1.37743	32
1.37688	38
1.37634	36
1.3758	34
1.37526	46
1.37472	38
1.37419	40
1.37365	38
1.37311	34
1.37257	46
1.37204	34
1.3715	48
1.37096	36
1.37043	38
1.36989	46
1.36936	50
1.36882	36
1.36829	38
1.36776	40
1.36722	40
1.36669	38
1.36616	36
1.36563	46
1.3651	42
1.36457	38
1.36404	34
1.36351	36
1.36298	48
1.36245	40
1.36192	40
1.36139	40
1.36087	38
1.36034	42
1.35981	46
1.35929	36
1.35876	36
1.35824	42
1.35771	38
1.35719	34
1.35667	32
1.35614	38
1.35562	44
1.3551	44
1.35458	42
1.35406	30
1.35353	34
1.35301	42
1.35249	42
1.35197	42
1.35146	30
1.35094	38
1.35042	32
1.3499	36
1.34938	38
1.34887	38
1.34835	32
1.34783	34
1.34732	38
1.3468	42
1.34629	36
1.34578	34
1.34526	34
1.34475	42
1.34424	32
1.34372	38
1.34321	26
1.3427	40
1.34219	28
1.34168	34
1.34117	28
1.34066	34
1.34015	38
1.33964	38
1.33913	34
1.33862	32
1.33812	36
1.33761	34
1.3371	34.0329
1.3366	31.8494
1.33609	34.1856
1.33558	32.9573
1.33508	35.0388
1.33457	39.0522
1.33407	38.5651
1.33357	33
1.33306	30.0808
1.33256	33.0088
1.33206	31.0148
1.33156	36.4619
1.33105	35.2361
1.33055	31.1908
1.33005	33.0376
1.32959	32
1.32909	26
1.32859	38
1.32809	32
1.32758	34
1.32708	40
1.32658	42
1.32608	36
1.32558	30
1.32508	36
1.32458	36
1.32408	32
1.32358	32
1.32309	34
1.32259	38
1.32209	36
1.3216	40
1.3211	32
1.3206	30
1.32011	32
1.31961	36
1.31912	32
1.31862	38
1.31813	38
1.31764	36
1.31714	34
1.31665	34
1.31616	32
1.31567	32
1.31518	36
1.31468	34
1.31419	36
1.3137	34
1.31321	40
1.31272	34
1.31224	40
1.31175	36
1.31126	38
1.31077	34
1.31028	38
1.3098	38
1.30931	32
1.30882	40
1.30834	34
1.30785	34
1.30737	40
1.30688	40
1.3064	44
1.30592	28
1.30543	34
1.30495	38
1.30447	36
1.30399	34
1.3035	32
1.30302	34
1.30254	52
1.30206	38
1.30158	38
1.3011	38
1.30062	40
1.30014	28
1.30001	30