File: ploting_and_data_tools.ipynb/archivosraman/CdSe1_07.txt
#Acq. time (s)=	2
#Accumulations=	1
#Range (eV)=	2...1
#Windows=	11
#Autofocus=	Off
#AutoExposure=	Off
#Spike filter=	Off
#Delay time (s)=	0
#Binning=	1
#Readout mode=	Signal
#DeNoise=	Off
#ICS correction=	Off
#Dark correction=	Off
#Inst. Process=	Off
#Instrument=	LabRAM HR Evol
#Detector=	Syncerity OE
#Objective=	x10_VIS
#Grating=	600 (500nm)
#ND Filter=	25%
#Laser=	442nm_Notch
#Hole=	100.021
#Range=	Visible
#Project=	Paty
#Sample=
#Site=	15-06-22
#Title=	CdSe1
#Remark=
#Date=	15.06.2022 20:06
#Acquired=	15.06.2022 20:06:23
2.74975	26
2.7475	28
2.74525	30
2.743	32
2.74076	32
2.73852	24
2.73629	22
2.73406	26
2.73183	28
2.72961	26
2.72739	30
2.72517	28
2.72296	22
2.72075	24
2.71854	38
2.71634	28
2.71414	32
2.71195	32
2.70976	28
2.70757	22
2.70539	32
2.70321	32
2.70103	32
2.69886	28
2.69669	24
2.69452	34
2.69236	26
2.6902	34
2.68805	34
2.6859	26
2.68375	34
2.68161	30
2.67947	32
2.67733	32
2.6752	34
2.67307	32
2.67094	26
2.66882	30
2.6667	28
2.66458	38
2.66247	30
2.66036	26
2.65826	38
2.65615	32
2.65405	30
2.65196	32
2.64987	38
2.64778	38
2.64569	32
2.64361	28
2.64153	36
2.63946	24
2.63739	38
2.63532	42
2.63325	26
2.63119	32
2.62913	30
2.62708	32
2.62503	38
2.62298	34
2.62094	28
2.61889	30
2.61686	36
2.61482	40
2.61279	34
2.61076	32
2.60873	30
2.60671	32
2.60469	36
2.60268	42
2.60067	32
2.59866	44
2.59665	42
2.59465	38
2.59265	34
2.59065	34
2.58866	36
2.58667	32
2.58468	38
2.5827	36
2.58072	42
2.57874	38
2.57677	40
2.5748	36
2.57283	42
2.57086	32
2.5689	42
2.56694	46
2.56499	40
2.56304	46
2.56109	52
2.55914	50
2.5572	42
2.55526	46
2.55332	48
2.55139	52
2.54946	50
2.54753	56
2.5456	52
2.54368	52
2.54176	58
2.53985	46
2.53794	54
2.53603	60
2.53412	50
2.53222	68
2.53031	66
2.52842	60
2.52652	62
2.52463	58
2.52274	64
2.52085	76
2.51897	60
2.51709	72
2.51521	82
2.51334	64
2.51147	82
2.5096	70
2.50773	80
2.50587	78
2.50401	78
2.50216	82
2.5003	84
2.49845	96
2.4966	88
2.49476	88
2.49291	90
2.49107	90
2.48924	96
2.4874	100
2.48557	96
2.48374	92
2.48192	102.53
2.48009	113.944
2.47827	115.144
2.47646	116.653
2.47464	124.343
2.47283	123.487
2.47102	137.309
2.46922	133.588
2.46741	138.715
2.46561	144.559
2.46381	142.581
2.46202	148.722
2.46023	159.925
2.45844	161.703
2.45665	166.198
2.45493	162
2.45314	168
2.45136	178
2.44957	196
2.44779	184
2.44601	200
2.44424	176
2.44247	200
2.4407	214
2.43893	204
2.43716	202
2.4354	212
2.43364	224
2.43188	210
2.43013	230
2.42838	226
2.42663	236
2.42488	228
2.42314	250
2.4214	244
2.41966	234
2.41792	254
2.41619	242
2.41446	264
2.41273	276
2.411	264
2.40928	288
2.40756	288
2.40584	266
2.40413	272
2.40241	280
2.4007	270
2.39899	266
2.39729	284
2.39559	274
2.39389	302
2.39219	288
2.39049	268
2.3888	304
2.38711	298
2.38542	276
2.38374	296
2.38205	256
2.38037	316
2.37869	296
2.37702	316
2.37535	284
2.37368	296
2.37201	294
2.37034	318
2.36868	300
2.36702	312
2.36536	314
2.3637	318
2.36205	298
2.3604	298
2.35875	298
2.3571	302
2.35546	304
2.35382	274
2.35218	310
2.35054	266
2.34891	290
2.34727	286
2.34564	262
2.34402	282
2.34239	284
2.34077	260
2.33915	274
2.33753	278
2.33591	272
2.3343	244
2.33269	246
2.33108	266
2.32948	260
2.32787	238
2.32627	230
2.32467	240
2.32307	254
2.32148	248
2.31989	250
2.3183	242
2.31671	222
2.31512	234
2.31354	222
2.31196	234
2.31038	220
2.3088	208
2.30723	226
2.30565	204
2.30408	226
2.30252	238
2.30095	216
2.29939	210
2.29783	208
2.29627	196
2.29471	228
2.29316	192
2.29161	206
2.29006	208
2.28851	186
2.28696	190
2.28542	180
2.28388	184
2.28234	200
2.2808	190
2.27927	192
2.27773	154
2.2762	170
2.27468	170
2.27315	180
2.27163	202
2.27011	174
2.26859	170
2.26707	172
2.26555	172
2.26404	178
2.26253	175.851
2.26102	165.42
2.25951	159.272
2.25801	167.398
2.25651	163.417
2.25501	154.35
2.25351	157.121
2.25201	153.017
2.25052	153.44
2.24902	158.075
2.24753	153.053
2.24605	146.982
2.24456	148.838
2.24308	148.655
2.2416	155.86
2.24011	142
2.23863	154
2.23715	152
2.23567	142
2.23419	138
2.23271	148
2.23124	140
2.22977	144
2.2283	132
2.22683	136
2.22536	134
2.2239	136
2.22244	142
2.22098	136
2.21952	126
2.21807	144
2.21661	134
2.21516	136
2.21371	120
2.21226	136
2.21082	124
2.20937	142
2.20793	128
2.20649	136
2.20505	144
2.20362	134
2.20218	120
2.20075	128
2.19932	128
2.19789	128
2.19647	126
2.19504	122
2.19362	114
2.1922	130
2.19078	122
2.18936	136
2.18795	112
2.18654	120
2.18513	118
2.18372	116
2.18231	124
2.18091	128
2.1795	120
2.1781	122
2.1767	122
2.1753	132
2.17391	112
2.17251	132
2.17112	124
2.16973	126
2.16834	126
2.16696	136
2.16557	126
2.16419	124
2.16281	128
2.16143	114
2.16005	110
2.15868	122
2.1573	126
2.15593	128
2.15456	122
2.1532	122
2.15183	124
2.15046	132
2.1491	130
2.14774	118
2.14638	126
2.14503	132
2.14367	114
2.14232	134
2.14097	134
2.13962	128
2.13827	136
2.13692	116
2.13558	122
2.13423	122
2.13289	134
2.13155	128
2.13022	120
2.12888	124
2.12755	124
2.12621	116
2.12488	118
2.12356	130
2.12223	126
2.1209	110
2.11958	118
2.11826	132
2.11694	132
2.11562	132
2.1143	120
2.11299	124
2.11168	122
2.11037	138
2.10906	132
2.10775	124
2.10644	134
2.10514	132
2.10384	140
2.10253	132
2.10123	116
2.09994	124
2.09864	138
2.09735	136
2.09605	130
2.09476	128
2.09347	138
2.09219	120
2.0909	118
2.08962	130
2.08834	132
2.08705	128
2.08578	134
2.0845	126
2.08322	142
2.08195	130
2.08068	138
2.0794	129.898
2.07814	119.249
2.07687	136.647
2.0756	131.055
2.07434	131.568
2.07307	126.825
2.07181	126.254
2.07055	129.808
2.0693	122.316
2.06804	128.061
2.06679	126.808
2.06553	131.624
2.06428	128.083
2.06303	122.827
2.06178	128.058
2.06069	142
2.05944	134
2.05819	132
2.05694	122
2.05569	138
2.05445	126
2.05321	130
2.05196	128
2.05072	130
2.04949	134
2.04825	136
2.04701	134
2.04578	132
2.04455	114
2.04332	128
2.04209	124
2.04086	140
2.03964	124
2.03841	126
2.03719	134
2.03597	120
2.03475	130
2.03353	132
2.03232	134
2.0311	130
2.02989	124
2.02868	124
2.02747	126
2.02626	126
2.02505	130
2.02384	148
2.02264	132
2.02144	122
2.02024	134
2.01904	132
2.01784	122
2.01664	134
2.01544	138
2.01425	116
2.01306	150
2.01187	140
2.01068	120
2.00949	144
2.0083	136
2.00712	144
2.00594	134
2.00475	132
2.00357	142
2.0024	142
2.00122	138
2.00004	144
1.99887	142
1.99769	134
1.99652	144
1.99535	152
1.99418	136
1.99302	144
1.99185	136
1.99069	140
1.98952	154
1.98836	144
1.9872	150
1.98604	152
1.98488	138
1.98373	142
1.98257	152
1.98142	142
1.98027	132
1.97912	140
1.97797	164
1.97682	150
1.97568	146
1.97453	146
1.97339	148
1.97225	156
1.97111	140
1.96997	142
1.96883	156
1.9677	142
1.96656	158
1.96543	144
1.9643	146
1.96316	140
1.96204	156
1.96091	142
1.95978	160
1.95866	148
1.95753	150
1.95641	156
1.95529	162
1.95417	146
1.95305	168
1.95193	162
1.95082	184
1.9497	176
1.94859	152
1.94748	166
1.94637	138
1.94526	164
1.94415	168
1.94305	148
1.94194	146
1.94084	160
1.93974	172
1.93864	152
1.93754	152
1.93644	160
1.93534	158
1.93425	160
1.93315	156
1.93206	158
1.93097	146
1.92988	146
1.92879	166
1.9277	170
1.92662	178
1.92553	160
1.92445	175.422
1.92337	173.092
1.92228	160.588
1.92121	151.839
1.92013	160.108
1.91905	152.04
1.91797	174.517
1.9169	165.407
1.91583	159.773
1.91475	163.941
1.91368	166.117
1.91261	168.222
1.91155	166.941
1.91048	163.917
1.90946	158
1.90839	164
1.90732	166
1.90626	178
1.90519	158
1.90413	158
1.90306	178
1.902	168
1.90094	160
1.89988	176
1.89882	172
1.89777	168
1.89671	164
1.89566	178
1.8946	170
1.89355	176
1.8925	182
1.89145	182
1.8904	172
1.88936	160
1.88831	162
1.88727	164
1.88622	172
1.88518	194
1.88414	164
1.8831	172
1.88206	164
1.88102	162
1.87999	190
1.87895	176
1.87792	170
1.87689	168
1.87586	166
1.87483	170
1.8738	168
1.87277	162
1.87174	166
1.87072	174
1.86969	168
1.86867	168
1.86765	168
1.86663	160
1.86561	180
1.86459	178
1.86357	176
1.86256	178
1.86154	172
1.86053	172
1.85952	180
1.85851	160
1.8575	226
1.85649	204
1.85548	184
1.85447	162
1.85347	188
1.85247	168
1.85146	178
1.85046	166
1.84946	176
1.84846	168
1.84746	168
1.84646	176
1.84547	178
1.84447	186
1.84348	172
1.84249	184
1.8415	174
1.84051	158
1.83952	190
1.83853	182
1.83754	172
1.83656	168
1.83557	166
1.83459	158
1.83361	156
1.83262	180
1.83164	164
1.83066	166
1.82969	164
1.82871	172
1.82773	164
1.82676	188
1.82579	168
1.82481	172
1.82384	190
1.82287	166
1.8219	184
1.82094	154
1.81997	168
1.819	174
1.81804	180
1.81708	172
1.81611	162
1.81515	168
1.81419	174
1.81323	174
1.81227	170
1.81132	166
1.81036	172
1.80941	174
1.80845	166
1.8075	162
1.80655	176
1.8056	172
1.80465	158
1.8037	162
1.80275	158
1.80181	180
1.80086	162
1.79992	178
1.79897	156
1.79803	162
1.79709	160
1.79615	164
1.79521	164
1.79428	156
1.79334	164
1.7924	168
1.79147	173.383
1.79053	160.715
1.7896	167.564
1.78867	176.881
1.78774	172.675
1.78681	158.667
1.78588	156.704
1.78496	165.983
1.78403	153.295
1.7831	163.588
1.78218	171.083
1.78126	156.295
1.78033	167.201
1.77941	164.142
1.77851	156
1.77759	172
1.77667	160
1.77575	168
1.77483	170
1.77391	178
1.77299	170
1.77207	168
1.77115	164
1.77024	164
1.76932	164
1.76841	166
1.7675	148
1.76659	150
1.76568	178
1.76477	152
1.76386	170
1.76295	158
1.76204	152
1.76114	158
1.76023	178
1.75933	154
1.75843	160
1.75753	154
1.75662	158
1.75572	192
1.75483	158
1.75393	164
1.75303	152
1.75214	160
1.75124	152
1.75035	152
1.74945	148
1.74856	156
1.74767	142
1.74678	146
1.74589	152
1.74501	160
1.74412	156
1.74323	148
1.74235	146
1.74146	148
1.74058	156
1.7397	150
1.73882	150
1.73794	140
1.73706	158
1.73618	144
1.7353	130
1.73443	152
1.73355	152
1.73268	152
1.7318	142
1.73093	158
1.73006	162
1.72919	140
1.72832	142
1.72745	148
1.72658	142
1.72571	148
1.72485	136
1.72398	146
1.72312	148
1.72225	146
1.72139	158
1.72053	122
1.71967	140
1.71881	134
1.71795	144
1.71709	130
1.71624	142
1.71538	134
1.71453	128
1.71367	174
1.71282	154
1.71197	138
1.71112	128
1.71027	126
1.70942	142
1.70857	126
1.70772	146
1.70687	136
1.70603	134
1.70518	146
1.70434	122
1.7035	182
1.70265	170
1.70181	120
1.70097	132
1.70013	128
1.69929	132
1.69846	134
1.69762	118
1.69678	128
1.69595	142
1.69511	134
1.69428	136
1.69345	134
1.69262	118
1.69179	130
1.69096	116
1.69013	124
1.6893	126
1.68847	118
1.68765	116
1.68682	134
1.686	126
1.68517	116
1.68435	118
1.68353	130
1.68271	124
1.68189	114
1.68107	120
1.68025	118
1.67943	134
1.67861	108
1.6778	124
1.67698	110.155
1.67617	129.952
1.67536	114.596
1.67454	120.533
1.67373	108.892
1.67292	122.772
1.67211	123.369
1.6713	127.16
1.6705	119.484
1.66969	118.931
1.66888	112.372
1.66808	123.485
1.66727	119.141
1.66647	114.206
1.66566	127.717
1.6649	124
1.66409	116
1.66329	130
1.66249	120
1.66168	124
1.66088	104
1.66008	114
1.65928	118
1.65848	108
1.65768	106
1.65688	120
1.65608	120
1.65529	110
1.65449	120
1.6537	124
1.6529	112
1.65211	116
1.65132	108
1.65053	120
1.64973	112
1.64894	104
1.64816	120
1.64737	104
1.64658	112
1.64579	106
1.64501	110
1.64422	118
1.64344	108
1.64265	116
1.64187	114
1.64109	102
1.64031	102
1.63953	108
1.63875	110
1.63797	108
1.63719	120
1.63642	108
1.63564	104
1.63486	102
1.63409	116
1.63331	106
1.63254	104
1.63177	104
1.631	96
1.63023	96
1.62946	96
1.62869	116
1.62792	118
1.62715	102
1.62639	90
1.62562	116
1.62485	100
1.62409	104
1.62333	110
1.62256	108
1.6218	102
1.62104	96
1.62028	102
1.61952	94
1.61876	98
1.618	102
1.61724	114
1.61649	98
1.61573	90
1.61498	94
1.61422	100
1.61347	100
1.61271	96
1.61196	110
1.61121	92
1.61046	88
1.60971	92
1.60896	96
1.60821	94
1.60747	94
1.60672	96
1.60597	90
1.60523	92
1.60448	96
1.60374	90
1.603	100
1.60225	88
1.60151	90
1.60077	92
1.60003	90
1.59929	88
1.59855	96
1.59782	84
1.59708	84
1.59634	96
1.59561	92
1.59487	94
1.59414	92
1.5934	76
1.59267	78
1.59194	86
1.59121	88
1.59048	76
1.58975	80
1.58902	86
1.58829	80
1.58756	74
1.58684	88
1.58611	82
1.58538	82
1.58466	78
1.58394	84
1.58321	84
1.58249	84
1.58177	78
1.58105	74
1.58033	82
1.57961	82
1.57889	62
1.57817	66
1.57745	96
1.57674	80
1.57602	82.0083
1.5753	77.6308
1.57459	68.1635
1.57388	66.5545
1.57316	75.218
1.57245	82.3759
1.57174	72.5661
1.57103	74.3601
1.57032	65.1814
1.56961	79.8792
1.5689	71.9455
1.56819	73.6907
1.56748	72.9004
1.56678	68.911
1.56607	76.9583
1.56544	60
1.56473	62
1.56402	82
1.56331	58
1.56261	66
1.5619	70
1.56119	66
1.56049	70
1.55979	66
1.55908	70
1.55838	76
1.55768	78
1.55698	64
1.55628	66
1.55558	68
1.55488	66
1.55418	62
1.55348	66
1.55278	60
1.55209	66
1.55139	60
1.5507	76
1.55	66
1.54931	68
1.54862	60
1.54792	58
1.54723	66
1.54654	72
1.54585	60
1.54516	64
1.54447	64
1.54378	56
1.5431	60
1.54241	64
1.54172	58
1.54104	60
1.54035	58
1.53967	60
1.53898	70
1.5383	66
1.53762	70
1.53694	64
1.53626	74
1.53558	64
1.5349	72
1.53422	56
1.53354	70
1.53286	68
1.53218	58
1.53151	68
1.53083	62
1.53016	60
1.52948	66
1.52881	68
1.52813	68
1.52746	58
1.52679	52
1.52612	70
1.52545	68
1.52478	52
1.52411	60
1.52344	78
1.52277	74
1.5221	64
1.52144	60
1.52077	56
1.52011	58
1.51944	60
1.51878	64
1.51811	60
1.51745	60
1.51679	60
1.51613	66
1.51547	56
1.51481	58
1.51415	58
1.51349	56
1.51283	54
1.51217	46
1.51151	52
1.51086	56
1.5102	50
1.50954	60
1.50889	56
1.50824	62
1.50758	60
1.50693	58
1.50628	58
1.50563	56
1.50497	56
1.50432	50
1.50367	52
1.50302	56
1.50238	58
1.50173	50
1.50108	50
1.50043	60
1.49979	60
1.49914	56
1.4985	56
1.49785	60
1.49721	50
1.49657	54
1.49592	50
1.49528	56
1.49464	50
1.494	52
1.49336	48
1.49272	52
1.49208	58
1.49144	46
1.49081	46
1.49017	48
1.48953	44
1.4889	46
1.48826	44
1.48763	46
1.48699	55.9703
1.48636	55.593
1.48573	51.3612
1.4851	52.9667
1.48446	51.7766
1.48383	44.3725
1.4832	50.3758
1.48257	46.0396
1.48194	48.0407
1.48132	50.8363
1.48069	46.5384
1.48006	44.995
1.47943	46.3587
1.47881	45.6333
1.47818	44.7166
1.47756	54
1.47694	50
1.47631	46
1.47568	52
1.47505	40
1.47443	42
1.4738	44
1.47318	38
1.47256	42
1.47193	42
1.47131	44
1.47069	42
1.47006	46
1.46944	40
1.46882	40
1.4682	46
1.46758	42
1.46696	38
1.46635	44
1.46573	38
1.46511	44
1.46449	44
1.46388	38
1.46326	36
1.46265	40
1.46203	40
1.46142	50
1.46081	38
1.46019	40
1.45958	40
1.45897	42
1.45836	32
1.45775	38
1.45714	36
1.45653	40
1.45592	40
1.45531	36
1.4547	34
1.4541	36
1.45349	42
1.45288	34
1.45228	42
1.45167	32
1.45107	32
1.45047	28
1.44986	30
1.44926	28
1.44866	30
1.44806	30
1.44746	38
1.44686	26
1.44626	36
1.44566	26
1.44506	28
1.44446	34
1.44386	32
1.44326	28
1.44267	28
1.44207	28
1.44148	30
1.44088	36
1.44029	34
1.43969	32
1.4391	26
1.43851	26
1.43791	34
1.43732	26
1.43673	28
1.43614	28
1.43555	28
1.43496	20
1.43437	32
1.43378	16
1.4332	34
1.43261	28
1.43202	28
1.43143	28
1.43085	34
1.43026	32
1.42968	32
1.42909	26
1.42851	22
1.42793	32
1.42734	30
1.42676	34
1.42618	24
1.4256	20
1.42502	24
1.42444	36
1.42386	24
1.42328	30
1.4227	30
1.42212	22
1.42155	30
1.42097	28
1.42039	28
1.41982	24
1.41924	28
1.41867	28
1.41809	26
1.41752	24
1.41695	24
1.41637	28
1.4158	22
1.41523	32
1.41466	28
1.41409	30
1.41352	30
1.41295	34
1.41238	28
1.41181	22
1.41124	26
1.41067	36
1.41011	34
1.40954	34
1.40897	24
1.40841	30
1.40784	32.0073
1.40728	37.7166
1.40672	33.718
1.40615	32.0154
1.40559	45.3053
1.40503	41.5149
1.40446	1709.41
1.4039	82.4837
1.40334	43.728
1.40278	41.7985
1.40222	36.5097
1.40166	41.374
1.4011	40.3599
1.40054	37.0594
1.39999	34.868
1.39947	32
1.3989	36
1.39834	48
1.39779	34
1.39723	44
1.39667	42
1.39611	38
1.39555	42
1.395	38
1.39444	38
1.39388	36
1.39333	46
1.39277	38
1.39222	32
1.39166	40
1.39111	42
1.39056	38
1.39	50
1.38945	38
1.3889	30
1.38835	42
1.3878	34
1.38725	46
1.3867	32
1.38615	38
1.3856	34
1.38505	34
1.3845	36
1.38396	38
1.38341	38
1.38286	40
1.38232	42
1.38177	46
1.38123	38
1.38068	34
1.38014	44
1.3796	36
1.37905	44
1.37851	52
1.37797	30
1.37743	44
1.37688	42
1.37634	38
1.3758	36
1.37526	38
1.37472	40
1.37419	44
1.37365	46
1.37311	34
1.37257	36
1.37204	38
1.3715	48
1.37096	44
1.37043	36
1.36989	30
1.36936	40
1.36882	34
1.36829	42
1.36776	40
1.36722	32
1.36669	44
1.36616	40
1.36563	44
1.3651	34
1.36457	42
1.36404	40
1.36351	32
1.36298	44
1.36245	34
1.36192	30
1.36139	32
1.36087	38
1.36034	32
1.35981	38
1.35929	38
1.35876	42
1.35824	40
1.35771	36
1.35719	36
1.35667	32
1.35614	30
1.35562	42
1.3551	36
1.35458	32
1.35406	34
1.35353	44
1.35301	40
1.35249	36
1.35197	34
1.35146	26
1.35094	42
1.35042	30
1.3499	38
1.34938	32
1.34887	34
1.34835	32
1.34783	36
1.34732	34
1.3468	32
1.34629	28
1.34578	46
1.34526	40
1.34475	38
1.34424	36
1.34372	38
1.34321	32
1.3427	36
1.34219	42
1.34168	30
1.34117	32
1.34066	38
1.34015	32
1.33964	34
1.33913	36
1.33862	34
1.33812	32
1.33761	36
1.3371	30.1832
1.3366	32.704
1.33609	24.2427
1.33558	36.1748
1.33508	34.2892
1.33457	30.1757
1.33407	38.8097
1.33357	34.8501
1.33306	31.5857
1.33256	37.6978
1.33206	32.6587
1.33156	31.3689
1.33105	28.6173
1.33055	29.0826
1.33005	31.3529
1.32959	40
1.32909	24
1.32859	30
1.32809	34
1.32758	36
1.32708	32
1.32658	38
1.32608	30
1.32558	40
1.32508	32
1.32458	36
1.32408	22
1.32358	36
1.32309	30
1.32259	36
1.32209	42
1.3216	28
1.3211	30
1.3206	32
1.32011	32
1.31961	36
1.31912	32
1.31862	30
1.31813	32
1.31764	40
1.31714	32
1.31665	36
1.31616	32
1.31567	30
1.31518	26
1.31468	38
1.31419	32
1.3137	34
1.31321	26
1.31272	42
1.31224	38
1.31175	28
1.31126	38
1.31077	30
1.31028	38
1.3098	34
1.30931	40
1.30882	36
1.30834	36
1.30785	38
1.30737	32
1.30688	34
1.3064	38
1.30592	36
1.30543	34
1.30495	36
1.30447	44
1.30399	32
1.3035	38
1.30302	34
1.30254	28
1.30206	36
1.30158	28
1.3011	28
1.30062	40
1.30014	36
1.30001	36