File: ploting_and_data_tools.ipynb/archivosraman/CdSe1_02.txt
#Acq. time (s)=	2
#Accumulations=	10
#Range (eV)=	2...1
#Windows=	11
#Autofocus=	Off
#AutoExposure=	Off
#Spike filter=	Multiple accum.
#Delay time (s)=	0
#Binning=	1
#Readout mode=	Signal
#DeNoise=	Off
#ICS correction=	Off
#Dark correction=	Off
#Inst. Process=	Off
#Instrument=	LabRAM HR Evol
#Detector=	Syncerity OE
#Objective=	x10_VIS
#Grating=	600 (500nm)
#ND Filter=	3.2%
#Laser=	442nm_Notch
#Hole=	70.0087
#Range=	Visible
#Project=	Paty
#Sample=
#Site=	15-06-22
#Title=	CdSe1
#Remark=
#Date=	15.06.2022 19:21
#Acquired=	15.06.2022 19:21:04
2.79565	20.4444
2.79332	23.1111
2.79099	25.5556
2.78867	23.3333
2.78635	24.2222
2.78404	26.4444
2.78173	27.1111
2.77942	28
2.77711	24
2.77482	26.6667
2.77252	28.4444
2.77023	29.3333
2.76794	32.6667
2.76566	27.3333
2.76338	27.7778
2.7611	30.8889
2.75883	29.3333
2.75656	31.1111
2.7543	25.1111
2.75204	31.5556
2.74978	28.4444
2.74753	28.8889
2.74528	27.7778
2.74303	29.3333
2.74079	30
2.73855	29.3333
2.73632	31.3333
2.73409	28.6667
2.73186	31.3333
2.72964	30.2222
2.72742	30.4444
2.7252	32
2.72299	28.2222
2.72078	30.6667
2.71858	32.6667
2.71638	33.5556
2.71418	35.1111
2.71199	28.6667
2.7098	30
2.70761	33.1111
2.70543	33.3333
2.70325	32.2222
2.70108	35.3333
2.6989	30.6667
2.69674	34.6667
2.69457	33.7778
2.69241	36.2222
2.69025	36.2222
2.6881	36.4444
2.68595	36.6667
2.6838	36.6667
2.68166	35.7778
2.67952	38.8889
2.67739	38
2.67525	37.1111
2.67312	37.7778
2.671	37.7778
2.66888	38.4444
2.66676	40.6667
2.66464	39.7778
2.66253	37.3333
2.66042	43.7778
2.65832	40
2.65622	43.1111
2.65412	43.7778
2.65203	45.7778
2.64994	46.2222
2.64785	47.5556
2.64576	43.3333
2.64368	48.6667
2.64161	52.2222
2.63953	49.7778
2.63746	47.7778
2.63539	50
2.63333	49.3333
2.63127	57.3333
2.62921	53.5556
2.62716	58.2222
2.62511	56.4444
2.62306	54.4444
2.62102	56.6667
2.61898	56.2222
2.61694	60.4444
2.61491	65.1111
2.61287	63.1111
2.61085	63.7778
2.60882	67.5556
2.6068	65.3333
2.60478	72.6667
2.60277	71.3333
2.60076	71.3333
2.59875	74.2222
2.59675	75.1111
2.59474	80.2222
2.59275	79.3333
2.59075	86.2222
2.58876	85.1111
2.58677	88.2222
2.58478	86.8889
2.5828	94.2222
2.58082	92.4444
2.57885	98.6667
2.57687	100.222
2.5749	103.111
2.57294	105.333
2.57097	110.667
2.56901	115.778
2.56706	114.667
2.5651	119.333
2.56315	127.556
2.5612	122.667
2.55926	131.333
2.55731	133.111
2.55538	140.667
2.55344	146.444
2.55151	155.556
2.54958	158.444
2.54765	159.111
2.54573	159.333
2.54381	166.667
2.54189	172.222
2.53997	172.889
2.53806	181.778
2.53615	190.889
2.53425	194.222
2.53235	198.222
2.53045	204
2.52855	211.111
2.52666	222.222
2.52476	227.778
2.52288	234.444
2.52099	240.667
2.51911	243.864
2.51723	254.366
2.51535	254.925
2.51348	262.744
2.51161	266.761
2.50974	272.042
2.50788	283.596
2.50602	286.54
2.50416	292.861
2.5023	301.197
2.50045	304.745
2.4986	318.039
2.49675	319.2
2.49491	329.277
2.49307	339.947
2.49147	340.222
2.48963	359.556
2.48778	370.889
2.48595	364.667
2.48411	378
2.48228	388.889
2.48045	395.778
2.47862	414
2.4768	417.556
2.47498	432
2.47316	450.444
2.47134	458.889
2.46953	464.667
2.46772	471.333
2.46591	491.333
2.46411	500.222
2.46231	513.778
2.46051	518.444
2.45871	539.778
2.45692	550
2.45513	574.222
2.45334	561.333
2.45155	575.556
2.44977	588.667
2.44799	606.667
2.44621	605.556
2.44444	617.111
2.44266	622.889
2.44089	633.111
2.43913	649.556
2.43736	647.333
2.4356	682.889
2.43384	677.333
2.43209	686.222
2.43033	701.333
2.42858	716.889
2.42683	716
2.42509	710.667
2.42334	729.556
2.4216	748.444
2.41986	747.556
2.41813	754.222
2.4164	763.111
2.41467	777.778
2.41294	779.556
2.41121	781.333
2.40949	793.111
2.40777	790.667
2.40605	802.667
2.40434	803.556
2.40263	817.111
2.40092	818.889
2.39921	827.111
2.3975	817.333
2.3958	838.889
2.3941	844.222
2.3924	854.444
2.39071	848.667
2.38902	853.333
2.38733	852.889
2.38564	859.333
2.38396	868.444
2.38227	861.333
2.38059	865.778
2.37892	874.667
2.37724	872.222
2.37557	873.556
2.3739	876
2.37223	876.222
2.37057	891.556
2.3689	889.111
2.36724	886.667
2.36559	881.333
2.36393	873.333
2.36228	883.333
2.36063	876
2.35898	860.444
2.35733	854.667
2.35569	862.667
2.35405	854.667
2.35241	863.333
2.35077	853.778
2.34914	841.333
2.34751	830.667
2.34588	837.111
2.34425	830.222
2.34263	834.889
2.34101	826.889
2.33939	828.222
2.33777	822.667
2.33615	795.333
2.33454	812.667
2.33293	794
2.33132	792.222
2.32972	800.444
2.32811	791.333
2.32651	776.667
2.32492	788.667
2.32332	768.667
2.32172	759.556
2.32013	766.667
2.31854	776.444
2.31696	763.778
2.31537	760
2.31379	762.889
2.31221	742.889
2.31063	754.889
2.30905	736
2.30748	735.333
2.30591	738.444
2.30434	743.778
2.30277	742.444
2.30121	732.444
2.29965	733.778
2.29809	728
2.29653	744.222
2.29497	734
2.29342	728.084
2.29187	713.096
2.29032	715.572
2.28877	719.319
2.28723	711.41
2.28568	709.955
2.28414	712.881
2.2826	708.657
2.28107	704.743
2.27954	702.927
2.278	699.604
2.27647	698.669
2.27495	702.347
2.27342	696.955
2.2719	701.973
2.27047	695.333
2.26894	701.333
2.26742	700.222
2.2659	699.333
2.26438	696.889
2.26286	696.667
2.26135	696.444
2.25983	705.111
2.25832	700.222
2.25681	700.222
2.25531	701.778
2.2538	704.222
2.2523	713.111
2.2508	708
2.2493	709.333
2.24781	712.445
2.24631	709.333
2.24482	711.111
2.24333	730.889
2.24184	724
2.24036	717.778
2.23887	720.444
2.23739	733.556
2.23591	726.222
2.23444	732.667
2.23296	739.778
2.23149	737.778
2.23002	741.556
2.22855	741.333
2.22708	748.444
2.22561	745.111
2.22415	752
2.22269	743.556
2.22123	743.556
2.21977	751.111
2.21832	768.222
2.21687	759.556
2.21541	766
2.21397	775.778
2.21252	783.111
2.21107	789.333
2.20963	773.556
2.20819	784.667
2.20675	785.555
2.20531	797.111
2.20388	800.667
2.20244	806.444
2.20101	798.667
2.19958	810.889
2.19815	828.889
2.19673	823.778
2.1953	827.556
2.19388	824.444
2.19246	850.667
2.19104	860.444
2.18963	844.889
2.18821	860
2.1868	862.667
2.18539	864.667
2.18398	882
2.18258	878
2.18117	886.444
2.17977	882.444
2.17837	903.111
2.17697	897.778
2.17557	913.556
2.17418	922.222
2.17278	929.333
2.17139	920.667
2.17	955.333
2.16862	945.556
2.16723	951.111
2.16585	952.444
2.16446	955.111
2.16308	966
2.1617	978.667
2.16033	973.111
2.15895	1008.67
2.15758	1003.56
2.15621	1017.11
2.15484	1012
2.15347	1019.78
2.15211	1034.67
2.15074	1037.33
2.14938	1042.44
2.14802	1040.67
2.14666	1062.22
2.14531	1058.22
2.14395	1069.78
2.1426	1089.11
2.14125	1096.89
2.1399	1105.11
2.13855	1110.22
2.13721	1114.44
2.13586	1129.33
2.13452	1119.33
2.13318	1120.44
2.13184	1152.67
2.1305	1148.22
2.12917	1153.78
2.12784	1160.44
2.1265	1172.67
2.12518	1170.22
2.12385	1195.78
2.12252	1166.67
2.1212	1184
2.11987	1205.11
2.11855	1221.33
2.11723	1232.67
2.11592	1213.33
2.1146	1228.22
2.11329	1255.56
2.11197	1270.22
2.11066	1273.11
2.10935	1264.89
2.10805	1292.67
2.10674	1292
2.10544	1290.43
2.10414	1282.15
2.10284	1281.37
2.10154	1277.56
2.10024	1277.18
2.09894	1264.82
2.09765	1261.75
2.09636	1273.41
2.09507	1263.96
2.09378	1255.52
2.09249	1252
2.09121	1254.86
2.08993	1235.11
2.08864	1214.17
2.08753	1223.33
2.08624	1227.78
2.08496	1245.56
2.08368	1234.44
2.0824	1244.22
2.08112	1260.22
2.07984	1260.67
2.07857	1246.89
2.0773	1256.89
2.07603	1263.33
2.07476	1265.56
2.07349	1270.22
2.07222	1274.67
2.07096	1284.89
2.06969	1286.67
2.06843	1299.56
2.06717	1292
2.06591	1290.67
2.06466	1302.22
2.0634	1301.33
2.06215	1302
2.0609	1313.11
2.05965	1303.56
2.0584	1304.22
2.05715	1296.22
2.0559	1342.89
2.05466	1320.22
2.05342	1328.89
2.05218	1308.67
2.05094	1320.67
2.0497	1307.78
2.04846	1311.33
2.04723	1304.22
2.046	1298.22
2.04476	1312.22
2.04354	1310
2.04231	1302.22
2.04108	1305.56
2.03985	1298.67
2.03863	1307.11
2.03741	1311.78
2.03619	1317.11
2.03497	1318.89
2.03375	1322.67
2.03254	1321.11
2.03132	1310.22
2.03011	1325.33
2.0289	1325.33
2.02769	1335.56
2.02648	1331.33
2.02527	1325.11
2.02407	1335.33
2.02286	1343.78
2.02166	1332.67
2.02046	1357.78
2.01926	1330.89
2.01806	1356.67
2.01687	1373.11
2.01567	1384.67
2.01448	1373.78
2.01329	1379.33
2.0121	1397.78
2.01091	1405.33
2.00972	1392
2.00854	1402
2.00735	1395.56
2.00617	1417.33
2.00499	1419.11
2.00381	1423.11
2.00263	1434.44
2.00145	1430.67
2.00028	1439.11
1.9991	1434
1.99793	1456.22
1.99676	1439.56
1.99559	1440.89
1.99442	1436.89
1.99325	1446.67
1.99209	1446.67
1.99092	1429.11
1.98976	1464.67
1.9886	1452.44
1.98744	1469.11
1.98628	1475.11
1.98513	1464.44
1.98397	1467.78
1.98282	1481.33
1.98166	1481.33
1.98051	1470
1.97936	1487.56
1.97822	1483.33
1.97707	1494
1.97592	1470.89
1.97478	1493.33
1.97364	1501.78
1.9725	1508.44
1.97136	1473.33
1.97022	1487.33
1.96908	1503.56
1.96795	1488.89
1.96681	1499.11
1.96568	1496.22
1.96455	1484.22
1.96342	1484.22
1.96229	1496.22
1.96116	1492
1.96004	1490.89
1.95891	1490.22
1.95779	1485.78
1.95667	1498.22
1.95555	1477.33
1.95443	1491.11
1.95331	1492.67
1.95219	1492.22
1.95108	1489.78
1.94996	1492.67
1.94885	1458
1.94774	1475.56
1.94663	1467.25
1.94552	1480.29
1.94442	1471.02
1.94331	1481.71
1.94221	1461.91
1.9411	1477.37
1.94	1469.41
1.9389	1469.48
1.9378	1457.1
1.93671	1462.78
1.93561	1458.43
1.93452	1461.72
1.93342	1450.12
1.93233	1445.59
1.9313	1454.67
1.9302	1442.22
1.92911	1453.33
1.92802	1446.67
1.92693	1457.78
1.92584	1434
1.92475	1442
1.92366	1434.89
1.92258	1428
1.92149	1409.33
1.92041	1412
1.91933	1420.67
1.91825	1402.67
1.91717	1405.11
1.91609	1393.56
1.91501	1398.67
1.91394	1381.56
1.91286	1392.89
1.91179	1388
1.91072	1378.67
1.90965	1362
1.90858	1361.78
1.90751	1354.44
1.90644	1355.78
1.90538	1336
1.90432	1344.44
1.90325	1321.33
1.90219	1337.11
1.90113	1326.89
1.90007	1318.44
1.89901	1321.33
1.89796	1297.33
1.8969	1294.67
1.89585	1284.44
1.8948	1282.44
1.89374	1261.56
1.89269	1278.89
1.89164	1260.67
1.8906	1268.89
1.88955	1258.44
1.88851	1248.67
1.88746	1254.89
1.88642	1246.44
1.88538	1219.11
1.88434	1222.67
1.8833	1202.89
1.88226	1197.11
1.88122	1210.67
1.88019	1168.89
1.87915	1185.78
1.87812	1182
1.87709	1162.67
1.87606	1174.22
1.87503	1148.22
1.874	1167.78
1.87297	1145.56
1.87194	1119.33
1.87092	1135.78
1.8699	1112.67
1.86887	1114.22
1.86785	1106.89
1.86683	1098.89
1.86581	1092.22
1.8648	1072.67
1.86378	1067.11
1.86276	1070.89
1.86175	1060.67
1.86074	1042.44
1.85973	1054.44
1.85872	1040.89
1.85771	1032
1.8567	1053.11
1.85569	1036.67
1.85468	1011.56
1.85368	1001.78
1.85268	997.556
1.85167	1007.33
1.85067	1004.67
1.84967	976.889
1.84867	993.111
1.84768	981.333
1.84668	951.333
1.84568	985.111
1.84469	953.333
1.8437	940.222
1.8427	951.333
1.84171	930.444
1.84072	929.556
1.83974	928.667
1.83875	918.889
1.83776	912
1.83678	898.667
1.83579	898.444
1.83481	893.778
1.83383	877.778
1.83285	878.444
1.83187	877.333
1.83089	861.111
1.82991	848.667
1.82893	856.667
1.82796	846.667
1.82699	837.111
1.82601	837.556
1.82504	826.445
1.82407	830
1.8231	812.444
1.82213	812.889
1.82116	804.222
1.8202	788.222
1.81923	790
1.81827	793.556
1.81731	788.444
1.81634	758.667
1.81538	773.111
1.81442	766.222
1.81347	754.667
1.81251	759.111
1.81155	728.391
1.8106	727.443
1.80964	729.299
1.80869	724.891
1.80774	719.75
1.80679	709.364
1.80584	708.414
1.80489	700.854
1.80394	705.411
1.80299	693.654
1.80205	688.434
1.8011	677.572
1.80016	674.024
1.79922	664.07
1.79827	664.8
1.79739	663.778
1.79645	661.778
1.7955	645.333
1.79456	641.556
1.79362	640
1.79268	626.667
1.79174	617.111
1.7908	620.222
1.78987	604.889
1.78893	600.444
1.788	606.222
1.78706	596
1.78613	591.333
1.7852	588.889
1.78427	589.556
1.78334	570.889
1.78241	574.222
1.78148	566.889
1.78056	562.889
1.77963	564.444
1.77871	547.333
1.77778	552.444
1.77686	539.778
1.77594	536.889
1.77502	536.222
1.7741	524.444
1.77318	514.222
1.77227	521.556
1.77135	504.444
1.77043	508.889
1.76952	513.333
1.76861	494.222
1.76769	492.889
1.76678	498.889
1.76587	497.778
1.76496	480.444
1.76406	470.444
1.76315	472.889
1.76224	477.111
1.76134	468.667
1.76043	462.667
1.75953	457.556
1.75863	456.667
1.75773	450
1.75683	446.667
1.75593	446
1.75503	440.222
1.75413	434.667
1.75324	430.222
1.75234	430.667
1.75145	420.444
1.75055	411.333
1.74966	413.333
1.74877	413.333
1.74788	413.333
1.74699	400.889
1.7461	396
1.74521	382.667
1.74433	383.333
1.74344	380.444
1.74256	378.444
1.74167	375.778
1.74079	378.444
1.73991	371.778
1.73903	370
1.73815	363.333
1.73727	365.556
1.73639	351.556
1.73551	357.778
1.73464	356.222
1.73376	346.444
1.73289	351.111
1.73202	337.333
1.73114	331.111
1.73027	335.111
1.7294	337.778
1.72853	323.778
1.72767	319.778
1.7268	322.222
1.72593	321.778
1.72507	320.222
1.7242	318.889
1.72334	316
1.72247	306
1.72161	302.444
1.72075	307.778
1.71989	305.333
1.71903	300.889
1.71817	300.444
1.71732	301.333
1.71646	291.556
1.71561	292.444
1.71475	290
1.7139	290
1.71305	286
1.71219	278.222
1.71134	278.667
1.71049	277.778
1.70964	269.556
1.7088	277.333
1.70795	270
1.7071	262.222
1.70626	260.222
1.70541	258.222
1.70457	259.111
1.70373	258.222
1.70288	252.222
1.70204	252.444
1.7012	254.444
1.70036	242
1.69953	245.778
1.69869	249.333
1.69785	243.556
1.69702	248.222
1.69618	244.222
1.69535	235.778
1.69452	240.222
1.69368	235.982
1.69285	232.082
1.69202	224.513
1.69119	233.329
1.69037	228.593
1.68954	223.628
1.68871	223.796
1.68789	221.818
1.68706	215.75
1.68624	220.432
1.68541	215.209
1.68459	215.107
1.68377	210.106
1.68295	205.984
1.68213	212.123
1.6814	208
1.68058	215.333
1.67975	213.556
1.67893	209.556
1.67811	210.222
1.6773	204.222
1.67648	209.556
1.67566	207.778
1.67484	206.444
1.67403	205.111
1.67321	188.444
1.6724	207.333
1.67159	199.111
1.67078	199.778
1.66996	202.667
1.66915	199.333
1.66834	197.111
1.66754	200.222
1.66673	201.778
1.66592	200
1.66511	194.889
1.66431	192.222
1.6635	194.222
1.6627	196.222
1.6619	189.556
1.6611	186.222
1.6603	186.444
1.6595	190.444
1.6587	188.444
1.6579	188.667
1.6571	181.556
1.6563	186.889
1.65551	186.667
1.65471	185.333
1.65392	178.667
1.65312	181.333
1.65233	176
1.65154	180.889
1.65075	180.889
1.64996	168.667
1.64917	177.556
1.64838	177.556
1.64759	175.556
1.6468	175.778
1.64602	171.556
1.64523	171.111
1.64445	170.444
1.64366	170.444
1.64288	174.222
1.6421	169.111
1.64131	169.778
1.64053	169.111
1.63975	170.667
1.63898	167.778
1.6382	162
1.63742	168
1.63664	159.333
1.63587	162.667
1.63509	159.778
1.63432	164
1.63354	160.444
1.63277	164
1.632	158.222
1.63123	155.111
1.63046	156.444
1.62969	155.556
1.62892	159.778
1.62815	154
1.62738	150.222
1.62662	148.667
1.62585	147.556
1.62509	145.333
1.62432	145.333
1.62356	145.111
1.6228	145.556
1.62204	145.556
1.62127	145.333
1.62051	146.444
1.61975	141.778
1.619	145.333
1.61824	144.667
1.61748	140.222
1.61672	144
1.61597	141.111
1.61521	133.556
1.61446	138.222
1.61371	136
1.61295	135.556
1.6122	132.222
1.61145	134.444
1.6107	130.889
1.60995	128.889
1.6092	135.111
1.60846	134.667
1.60771	128.222
1.60696	130
1.60622	130.667
1.60547	125.778
1.60473	128.667
1.60398	125.778
1.60324	126.444
1.6025	124.667
1.60176	127.333
1.60102	126.222
1.60028	120.444
1.59954	125.778
1.5988	120.889
1.59806	114.667
1.59733	119.333
1.59659	115.556
1.59586	113.778
1.59512	111.778
1.59439	115.333
1.59365	114.667
1.59292	117.111
1.59219	108.889
1.59146	114.444
1.59073	111.206
1.59	109.452
1.58927	105.75
1.58854	107.41
1.58782	106.236
1.58709	106.545
1.58636	106.028
1.58564	103.908
1.58492	105.185
1.58419	104.797
1.58347	100.414
1.58275	98.1282
1.58203	97.7246
1.58131	98.41
1.58059	95.2451
1.57987	96.6667
1.57915	96.8889
1.57843	96.6667
1.57771	96.4444
1.57699	94.8889
1.57627	93.3333
1.57555	94
1.57483	90
1.57411	95.1111
1.57339	95.5556
1.57268	94.4444
1.57196	94.2222
1.57125	90.2222
1.57054	92
1.56982	92.6667
1.56911	92.4445
1.5684	90.2222
1.56769	90.2222
1.56698	94.2222
1.56627	90.8889
1.56556	85.7778
1.56485	85.7778
1.56414	86.6667
1.56343	84
1.56273	87.3333
1.56202	86.2222
1.56132	87.1111
1.56061	86.8889
1.55991	80.2222
1.55921	81.3333
1.5585	85.5555
1.5578	87.1111
1.5571	81.5556
1.5564	82.4444
1.5557	82.8889
1.555	82.8889
1.55431	81.1111
1.55361	82.2222
1.55291	76.8889
1.55222	79.5556
1.55152	81.7778
1.55083	78.8889
1.55013	79.7778
1.54944	80.4444
1.54875	77.3333
1.54805	78.2222
1.54736	77.5556
1.54667	75.7778
1.54598	77.3333
1.54529	79.7778
1.54461	79.7778
1.54392	77.1111
1.54323	75.1111
1.54254	77.7778
1.54186	76.2222
1.54117	77.5556
1.54049	76.6667
1.5398	74.2222
1.53912	73.3333
1.53844	70.4444
1.53776	76.6667
1.53707	76.2222
1.53639	72.8889
1.53571	74.4444
1.53503	73.1111
1.53436	69.7778
1.53368	70.2222
1.533	74.8889
1.53232	77.5556
1.53165	66.8889
1.53097	71.1111
1.5303	73.5556
1.52962	68.4444
1.52895	71.7778
1.52828	68
1.52761	66.6667
1.52693	71.3333
1.52626	65.3333
1.52559	69.7778
1.52492	66.6667
1.52426	68
1.52359	69.1111
1.52292	67.3333
1.52225	68.6667
1.52159	62.8889
1.52092	65.7778
1.52026	63.5556
1.51959	65.1111
1.51893	68
1.51826	68
1.5176	67.5556
1.51694	61.5556
1.51628	63.3333
1.51562	60.6667
1.51496	62.8889
1.5143	65.3333
1.51364	64.4444
1.51298	65.1111
1.51232	61.7778
1.51167	64
1.51101	61.5556
1.51036	61.3333
1.5097	60
1.50905	59.5556
1.50839	61.5556
1.50774	60.6667
1.50709	65.3333
1.50644	58.4444
1.50578	62.6667
1.50513	59.3333
1.50448	58.6667
1.50384	61.3333
1.50319	58
1.50254	53.7778
1.50189	60.8889
1.50124	60.4444
1.5006	62
1.49995	57.8499
1.49931	55.0706
1.49866	53.2871
1.49802	55.1713
1.49738	55.0988
1.49673	58.7318
1.49609	55.8339
1.49545	54.6101
1.49481	58.4179
1.49417	56.5447
1.49353	53.3537
1.49289	52.774
1.49225	53.1877
1.49162	51.4705
1.49104	51.5556
1.4904	54.6667
1.48976	54.8889
1.48912	52
1.48848	54.8889
1.48784	52.4444
1.48721	50.6667
1.48657	42.4444
1.48593	50.2222
1.4853	52.4444
1.48466	50.4444
1.48403	54
1.48339	55.3333
1.48276	51.1111
1.48213	50.2222
1.4815	49.7778
1.48087	46.6667
1.48024	50.4444
1.47961	51.7778
1.47898	53.5556
1.47835	52
1.47772	49.7778
1.47709	46.6667
1.47646	46
1.47584	42.2222
1.47521	45.7778
1.47459	44.2222
1.47396	46.4444
1.47334	46.4444
1.47271	50.4444
1.47209	49.5556
1.47147	46.6667
1.47084	42.8889
1.47022	43.1111
1.4696	46.6667
1.46898	42.6667
1.46836	46
1.46774	47.7778
1.46712	44.2222
1.46651	46
1.46589	43.1111
1.46527	40.6667
1.46466	40.6667
1.46404	41.5556
1.46342	36
1.46281	47.5556
1.4622	44.6667
1.46158	47.5556
1.46097	38.2222
1.46036	37.5556
1.45975	36.6667
1.45913	34
1.45852	31.7778
1.45791	37.1111
1.4573	42
1.4567	38.6667
1.45609	35.3333
1.45548	33.7778
1.45487	31.7778
1.45427	30.2222
1.45366	32.6667
1.45305	32.2222
1.45245	34.2222
1.45184	30.2222
1.45124	26.2222
1.45064	30.2222
1.45003	30.2222
1.44943	27.5556
1.44883	25.3333
1.44823	26.8889
1.44763	26.6667
1.44703	27.3333
1.44643	26.2222
1.44583	25.1111
1.44523	27.7778
1.44463	24.2222
1.44404	28.4444
1.44344	27.5556
1.44284	29.1111
1.44225	27.7778
1.44165	27.5556
1.44106	23.5556
1.44046	25.7778
1.43987	26.6667
1.43928	24.4444
1.43868	24
1.43809	25.7778
1.4375	29.5556
1.43691	25.1111
1.43632	26.4444
1.43573	28
1.43514	25.1111
1.43455	25.5556
1.43397	28
1.43338	28.8889
1.43279	26.2222
1.4322	26.4444
1.43162	26.8889
1.43103	24.8889
1.43045	26
1.42986	25.1111
1.42928	24.6667
1.4287	24
1.42811	24.4444
1.42753	27.1111
1.42695	24.2222
1.42637	26.4444
1.42579	26.4444
1.42521	27.1111
1.42463	25.7778
1.42405	20.8889
1.42347	24.8889
1.42289	24.4444
1.42231	24.8889
1.42174	26.4444
1.42116	23.7778
1.42059	28
1.42001	26.6667
1.41943	28.4462
1.41886	24.4002
1.41829	26.3805
1.41771	23.8194
1.41714	25.7012
1.41657	25.5405
1.416	23.4797
1.41542	25.3925
1.41485	22.5649
1.41428	23.424
1.41371	24.7421
1.41315	25.3271
1.41258	26.1844
1.41201	23.1342
1.41145	23.7778
1.41088	26.8889
1.41031	23.7778
1.40974	25.7778
1.40917	28
1.4086	30.6667
1.40804	27.7778
1.40747	30
1.4069	28.8889
1.40633	32.4444
1.40577	37.5556
1.4052	36.2222
1.40464	38.6667
1.40407	39.1111
1.40351	35.3333
1.40295	32.4444
1.40238	35.5556
1.40182	37.3333
1.40126	38
1.4007	35.5556
1.40013	34.6667
1.39957	34.4444
1.39901	39.3333
1.39845	35.7778
1.3979	37.5556
1.39734	36
1.39678	39.5556
1.39622	38.4444
1.39566	38.8889
1.39511	34
1.39455	42.2222
1.394	34.6667
1.39344	37.5556
1.39289	36.4444
1.39233	41.3333
1.39178	36.2222
1.39122	37.1111
1.39067	40.2222
1.39012	38.4444
1.38957	38
1.38902	39.3333
1.38847	38
1.38792	38.8889
1.38737	38
1.38682	40
1.38627	40
1.38572	36.4444
1.38517	36.4444
1.38462	36.2222
1.38408	40.4444
1.38353	38.2222
1.38298	40
1.38244	36.6667
1.38189	36.8889
1.38135	35.5556
1.38081	36.6667
1.38026	42.4444
1.37972	39.5556
1.37918	36.4444
1.37863	35.1111
1.37809	36
1.37755	36
1.37701	38.4444
1.37647	36
1.37593	38.6667
1.37539	38.4444
1.37485	39.3333
1.37431	37.3333
1.37378	36.8889
1.37324	35.5556
1.3727	37.1111
1.37216	36.8889
1.37163	35.7778
1.37109	33.3333
1.37056	35.7778
1.37002	36.8889
1.36949	37.1111
1.36896	38.6667
1.36842	34.8889
1.36789	35.1111
1.36736	35.5556
1.36683	37.3333
1.36629	35.5556
1.36576	39.3333
1.36523	35.7778
1.3647	38.8889
1.36417	39.7778
1.36364	34.4444
1.36312	34.2222
1.36259	35.7778
1.36206	34.4444
1.36153	33.1111
1.36101	32.6667
1.36048	35.7778
1.35995	34
1.35943	35.5556
1.3589	31.3333
1.35838	35.3333
1.35785	34.6667
1.35733	33.7778
1.35681	33.3333
1.35628	33.3333
1.35576	34.6667
1.35524	34.6667
1.35472	35.3333
1.3542	31.5556
1.35368	36.2222
1.35316	36
1.35264	32.2222
1.35212	32.6667
1.3516	34.4444
1.35108	36
1.35056	32.6667
1.35005	34.8889
1.34953	33.3333
1.34901	34.4444
1.3485	32.4444
1.34798	33.1111
1.34747	30.8848
1.34695	32.0839
1.34644	34.2676
1.34593	34.724
1.34541	32.6149
1.3449	32.095
1.34439	31.7301
1.34387	32.2196
1.34336	33.5078
1.34285	33.116
1.34234	30.8211
1.34183	33.7948
1.34132	30.9447
1.34081	31.4858
1.34036	31.5556
1.33985	34
1.33934	31.1111
1.33883	31.5556
1.33832	34
1.33781	31.3333
1.3373	30.2222
1.33679	30.6667
1.33628	33.7778
1.33577	32.4444
1.33527	33.1111
1.33476	33.1111
1.33425	28.2222
1.33375	32
1.33324	32
1.33273	30
1.33223	30.6667
1.33172	30.6667
1.33122	32.8889
1.33072	32.8889
1.33021	33.3333
1.32971	36
1.32921	31.3333
1.3287	31.5556
1.3282	33.1111
1.3277	30.8889
1.3272	33.3333
1.3267	31.5556
1.3262	33.5556
1.3257	35.1111
1.3252	34.4444
1.3247	30.4444
1.3242	32.2222
1.3237	29.7778
1.32321	33.7778
1.32271	36
1.32221	31.1111
1.32172	31.7778
1.32122	31.5556
1.32072	30.2222
1.32023	32.4444
1.31973	33.3333
1.31924	30.8889
1.31875	30.6667
1.31825	33.5556
1.31776	32
1.31727	33.7778
1.31677	29.5556
1.31628	31.3333
1.31579	29.1111
1.3153	32.4444
1.31481	33.1111
1.31432	28.6667
1.31383	29.3333
1.31334	32.6667
1.31285	33.3333
1.31236	31.1111
1.31187	34.2222
1.31139	32.4444
1.3109	32
1.31041	31.3333
1.30993	34.6667
1.30944	32.2222
1.30895	34.2222
1.30847	31.1111
1.30798	31.5556
1.3075	31.1111
1.30702	32.4444
1.30653	32
1.30605	34.6667
1.30557	32.6667
1.30508	32.4444
1.3046	32.8889
1.30412	27.1111
1.30364	34
1.30316	31.7778
1.30268	32
1.3022	31.3333
1.30172	31.7778
1.30124	29.3333
1.30076	28.8889
1.30028	29.7778
1.30001	30