File: ploting_and_data_tools.ipynb/archivosraman/CdSe3_02.txt
#Acq. time (s)=	1
#Accumulations=	1
#Range (eV)=	2...1
#Windows=	11
#Autofocus=	Off
#AutoExposure=	Off
#Spike filter=	Off
#Delay time (s)=	0
#Binning=	1
#Readout mode=	Signal
#DeNoise=	Off
#ICS correction=	Off
#Dark correction=	Off
#Inst. Process=	Off
#Instrument=	LabRAM HR Evol
#Detector=	Syncerity OE
#Objective=	x100_VIS_LWD
#Grating=	600 (500nm)
#ND Filter=	1%
#Laser=	442nm_Notch
#Hole=	150.001
#Range=	Visible
#Project=	Paty
#Sample=
#Site=	15-06-22
#Title=	CdSe3
#Remark=
#Date=	15.06.2022 21:19
#Acquired=	15.06.2022 21:19:08
2.74975	32
2.7475	36
2.74525	30
2.743	26
2.74076	26
2.73852	32
2.73629	34
2.73406	32
2.73183	28
2.72961	28
2.72739	34
2.72517	34
2.72296	46
2.72075	34
2.71854	28
2.71634	32
2.71414	40
2.71195	38
2.70976	36
2.70757	38
2.70539	36
2.70321	34
2.70103	40
2.69886	32
2.69669	32
2.69452	50
2.69236	38
2.6902	32
2.68805	40
2.6859	36
2.68375	34
2.68161	36
2.67947	30
2.67733	36
2.6752	48
2.67307	44
2.67094	36
2.66882	42
2.6667	38
2.66458	46
2.66247	42
2.66036	46
2.65826	52
2.65615	48
2.65405	38
2.65196	54
2.64987	46
2.64778	56
2.64569	48
2.64361	46
2.64153	50
2.63946	46
2.63739	48
2.63532	60
2.63325	48
2.63119	64
2.62913	60
2.62708	52
2.62503	66
2.62298	68
2.62094	62
2.61889	64
2.61686	62
2.61482	70
2.61279	64
2.61076	70
2.60873	78
2.60671	78
2.60469	80
2.60268	82
2.60067	88
2.59866	92
2.59665	82
2.59465	74
2.59265	86
2.59065	94
2.58866	92
2.58667	106
2.58468	102
2.5827	112
2.58072	116
2.57874	108
2.57677	116
2.5748	122
2.57283	120
2.57086	142
2.5689	134
2.56694	140
2.56499	150
2.56304	132
2.56109	140
2.55914	168
2.5572	180
2.55526	160
2.55332	182
2.55139	198
2.54946	194
2.54753	198
2.5456	224
2.54368	224
2.54176	224
2.53985	234
2.53794	248
2.53603	262
2.53412	260
2.53222	268
2.53031	272
2.52842	286
2.52652	284
2.52463	308
2.52274	318
2.52085	338
2.51897	330
2.51709	352
2.51521	368
2.51334	354
2.51147	384
2.5096	402
2.50773	410
2.50587	430
2.50401	448
2.50216	456
2.5003	464
2.49845	464
2.4966	528
2.49476	514
2.49291	510
2.49107	520
2.48924	580
2.4874	546
2.48557	606
2.48374	620
2.48192	618.41
2.48009	647.515
2.47827	618.849
2.47646	654.921
2.47464	671.769
2.47283	691.54
2.47102	690.074
2.46922	702.258
2.46741	704.83
2.46561	741.229
2.46381	747.918
2.46202	754.094
2.46023	747.995
2.45844	781.961
2.45665	791.857
2.45493	828
2.45314	814
2.45136	794
2.44957	844
2.44779	856
2.44601	858
2.44424	884
2.44247	926
2.4407	916
2.43893	944
2.43716	944
2.4354	952
2.43364	992
2.43188	960
2.43013	1014
2.42838	998
2.42663	1066
2.42488	1072
2.42314	1048
2.4214	1036
2.41966	1068
2.41792	1108
2.41619	1094
2.41446	1086
2.41273	1070
2.411	1092
2.40928	1096
2.40756	1124
2.40584	1110
2.40413	1110
2.40241	1150
2.4007	1190
2.39899	1108
2.39729	1134
2.39559	1156
2.39389	1138
2.39219	1164
2.39049	1158
2.3888	1136
2.38711	1150
2.38542	1152
2.38374	1132
2.38205	1138
2.38037	1158
2.37869	1154
2.37702	1184
2.37535	1158
2.37368	1156
2.37201	1154
2.37034	1144
2.36868	1146
2.36702	1160
2.36536	1106
2.3637	1138
2.36205	1096
2.3604	1076
2.35875	1096
2.3571	1036
2.35546	1044
2.35382	1032
2.35218	1048
2.35054	1036
2.34891	1026
2.34727	1000
2.34564	984
2.34402	974
2.34239	996
2.34077	954
2.33915	952
2.33753	946
2.33591	892
2.3343	874
2.33269	920
2.33108	856
2.32948	874
2.32787	862
2.32627	838
2.32467	834
2.32307	820
2.32148	814
2.31989	806
2.3183	782
2.31671	808
2.31512	774
2.31354	782
2.31196	754
2.31038	714
2.3088	726
2.30723	746
2.30565	748
2.30408	720
2.30252	706
2.30095	690
2.29939	714
2.29783	666
2.29627	702
2.29471	686
2.29316	676
2.29161	676
2.29006	708
2.28851	632
2.28696	640
2.28542	632
2.28388	640
2.28234	642
2.2808	608
2.27927	606
2.27773	604
2.2762	604
2.27468	610
2.27315	618
2.27163	586
2.27011	588
2.26859	586
2.26707	616
2.26555	600
2.26404	576
2.26253	578.76
2.26102	569.264
2.25951	538.145
2.25801	535.759
2.25651	554.367
2.25501	505.895
2.25351	512.595
2.25201	534.706
2.25052	516.364
2.24902	501.8
2.24753	504.203
2.24605	476.003
2.24456	473.251
2.24308	498.891
2.2416	474.662
2.24011	470
2.23863	448
2.23715	484
2.23567	468
2.23419	462
2.23271	462
2.23124	488
2.22977	468
2.2283	464
2.22683	450
2.22536	452
2.2239	460
2.22244	462
2.22098	454
2.21952	430
2.21807	454
2.21661	442
2.21516	472
2.21371	444
2.21226	438
2.21082	440
2.20937	448
2.20793	436
2.20649	456
2.20505	448
2.20362	412
2.20218	442
2.20075	434
2.19932	422
2.19789	432
2.19647	452
2.19504	430
2.19362	434
2.1922	434
2.19078	440
2.18936	438
2.18795	426
2.18654	434
2.18513	434
2.18372	432
2.18231	424
2.18091	418
2.1795	452
2.1781	422
2.1767	434
2.1753	442
2.17391	446
2.17251	440
2.17112	408
2.16973	438
2.16834	418
2.16696	462
2.16557	454
2.16419	434
2.16281	448
2.16143	440
2.16005	452
2.15868	444
2.1573	444
2.15593	430
2.15456	458
2.1532	440
2.15183	450
2.15046	456
2.1491	428
2.14774	420
2.14638	436
2.14503	438
2.14367	460
2.14232	430
2.14097	430
2.13962	470
2.13827	460
2.13692	438
2.13558	454
2.13423	464
2.13289	470
2.13155	452
2.13022	428
2.12888	434
2.12755	436
2.12621	476
2.12488	452
2.12356	446
2.12223	480
2.1209	460
2.11958	456
2.11826	480
2.11694	472
2.11562	436
2.1143	438
2.11299	466
2.11168	428
2.11037	448
2.10906	444
2.10775	478
2.10644	448
2.10514	458
2.10384	464
2.10253	454
2.10123	460
2.09994	442
2.09864	460
2.09735	432
2.09605	442
2.09476	456
2.09347	438
2.09219	446
2.0909	452
2.08962	450
2.08834	430
2.08705	456
2.08578	454
2.0845	444
2.08322	452
2.08195	428
2.08068	478
2.0794	427.825
2.07814	433.35
2.07687	449.925
2.0756	435.933
2.07434	446.229
2.07307	451.753
2.07181	429.446
2.07055	432.211
2.0693	428.833
2.06804	436.696
2.06679	405.6
2.06553	419.804
2.06428	426.227
2.06303	433.431
2.06178	423.341
2.06069	386
2.05944	428
2.05819	404
2.05694	410
2.05569	414
2.05445	412
2.05321	388
2.05196	422
2.05072	394
2.04949	424
2.04825	402
2.04701	382
2.04578	398
2.04455	424
2.04332	412
2.04209	382
2.04086	410
2.03964	372
2.03841	410
2.03719	414
2.03597	408
2.03475	390
2.03353	382
2.03232	404
2.0311	398
2.02989	388
2.02868	396
2.02747	388
2.02626	416
2.02505	412
2.02384	390
2.02264	384
2.02144	390
2.02024	396
2.01904	408
2.01784	382
2.01664	396
2.01544	396
2.01425	432
2.01306	404
2.01187	402
2.01068	400
2.00949	426
2.0083	404
2.00712	418
2.00594	394
2.00475	418
2.00357	406
2.0024	402
2.00122	418
2.00004	380
1.99887	422
1.99769	420
1.99652	398
1.99535	428
1.99418	406
1.99302	418
1.99185	452
1.99069	412
1.98952	414
1.98836	418
1.9872	412
1.98604	400
1.98488	400
1.98373	428
1.98257	444
1.98142	444
1.98027	410
1.97912	412
1.97797	416
1.97682	432
1.97568	418
1.97453	444
1.97339	436
1.97225	434
1.97111	434
1.96997	420
1.96883	424
1.9677	466
1.96656	434
1.96543	408
1.9643	440
1.96316	432
1.96204	440
1.96091	446
1.95978	428
1.95866	446
1.95753	432
1.95641	472
1.95529	422
1.95417	432
1.95305	410
1.95193	436
1.95082	422
1.9497	406
1.94859	424
1.94748	430
1.94637	438
1.94526	438
1.94415	442
1.94305	442
1.94194	452
1.94084	432
1.93974	422
1.93864	394
1.93754	412
1.93644	456
1.93534	442
1.93425	420
1.93315	386
1.93206	424
1.93097	428
1.92988	420
1.92879	444
1.9277	422
1.92662	422
1.92553	408
1.92445	407.427
1.92337	405.521
1.92228	420.663
1.92121	427.803
1.92013	422.028
1.91905	421.397
1.91797	422.583
1.9169	416.275
1.91583	424.259
1.91475	411.271
1.91368	412.314
1.91261	408.001
1.91155	406.265
1.91048	413.574
1.90946	412
1.90839	394
1.90732	432
1.90626	406
1.90519	406
1.90413	432
1.90306	406
1.902	412
1.90094	394
1.89988	380
1.89882	382
1.89777	388
1.89671	396
1.89566	394
1.8946	422
1.89355	386
1.8925	426
1.89145	418
1.8904	392
1.88936	388
1.88831	390
1.88727	380
1.88622	388
1.88518	384
1.88414	370
1.8831	390
1.88206	390
1.88102	364
1.87999	398
1.87895	392
1.87792	388
1.87689	382
1.87586	390
1.87483	392
1.8738	388
1.87277	382
1.87174	372
1.87072	382
1.86969	390
1.86867	388
1.86765	374
1.86663	386
1.86561	360
1.86459	374
1.86357	394
1.86256	388
1.86154	372
1.86053	364
1.85952	342
1.85851	370
1.8575	384
1.85649	364
1.85548	392
1.85447	368
1.85347	358
1.85247	394
1.85146	354
1.85046	340
1.84946	356
1.84846	356
1.84746	360
1.84646	364
1.84547	368
1.84447	366
1.84348	352
1.84249	346
1.8415	364
1.84051	334
1.83952	364
1.83853	348
1.83754	362
1.83656	344
1.83557	348
1.83459	348
1.83361	358
1.83262	356
1.83164	356
1.83066	360
1.82969	350
1.82871	340
1.82773	346
1.82676	352
1.82579	346
1.82481	330
1.82384	324
1.82287	330
1.8219	336
1.82094	334
1.81997	320
1.819	316
1.81804	344
1.81708	346
1.81611	344
1.81515	334
1.81419	322
1.81323	334
1.81227	326
1.81132	312
1.81036	318
1.80941	330
1.80845	328
1.8075	316
1.80655	322
1.8056	310
1.80465	324
1.8037	322
1.80275	310
1.80181	340
1.80086	310
1.79992	304
1.79897	294
1.79803	310
1.79709	306
1.79615	298
1.79521	320
1.79428	304
1.79334	304
1.7924	328
1.79147	316.637
1.79053	311.342
1.7896	296.723
1.78867	288.477
1.78774	294.908
1.78681	298.726
1.78588	288.735
1.78496	299.079
1.78403	294.944
1.7831	294.45
1.78218	302.96
1.78126	296.13
1.78033	298.312
1.77941	281.421
1.77851	280
1.77759	286
1.77667	272
1.77575	292
1.77483	274
1.77391	284
1.77299	286
1.77207	288
1.77115	286
1.77024	278
1.76932	270
1.76841	288
1.7675	292
1.76659	274
1.76568	290
1.76477	256
1.76386	266
1.76295	270
1.76204	262
1.76114	270
1.76023	266
1.75933	254
1.75843	250
1.75753	256
1.75662	260
1.75572	276
1.75483	266
1.75393	226
1.75303	246
1.75214	240
1.75124	266
1.75035	254
1.74945	246
1.74856	226
1.74767	230
1.74678	244
1.74589	254
1.74501	248
1.74412	238
1.74323	254
1.74235	228
1.74146	248
1.74058	236
1.7397	202
1.73882	226
1.73794	222
1.73706	246
1.73618	228
1.7353	230
1.73443	234
1.73355	238
1.73268	206
1.7318	238
1.73093	212
1.73006	214
1.72919	220
1.72832	212
1.72745	230
1.72658	226
1.72571	214
1.72485	224
1.72398	222
1.72312	210
1.72225	212
1.72139	208
1.72053	214
1.71967	214
1.71881	210
1.71795	204
1.71709	210
1.71624	192
1.71538	204
1.71453	204
1.71367	204
1.71282	194
1.71197	202
1.71112	174
1.71027	192
1.70942	196
1.70857	172
1.70772	192
1.70687	180
1.70603	176
1.70518	186
1.70434	184
1.7035	182
1.70265	182
1.70181	180
1.70097	180
1.70013	188
1.69929	176
1.69846	182
1.69762	166
1.69678	164
1.69595	158
1.69511	176
1.69428	180
1.69345	160
1.69262	166
1.69179	146
1.69096	158
1.69013	162
1.6893	158
1.68847	166
1.68765	138
1.68682	150
1.686	156
1.68517	166
1.68435	150
1.68353	162
1.68271	148
1.68189	144
1.68107	154
1.68025	150
1.67943	148
1.67861	136
1.6778	152
1.67698	140.019
1.67617	144.684
1.67536	151.041
1.67454	136.564
1.67373	150.834
1.67292	140.082
1.67211	141.992
1.6713	145.063
1.6705	138.646
1.66969	136.503
1.66888	145.23
1.66808	142.868
1.66727	137.245
1.66647	128.27
1.66566	151.642
1.6649	128
1.66409	130
1.66329	118
1.66249	116
1.66168	132
1.66088	124
1.66008	126
1.65928	120
1.65848	142
1.65768	138
1.65688	128
1.65608	128
1.65529	140
1.65449	124
1.6537	134
1.6529	122
1.65211	118
1.65132	128
1.65053	132
1.64973	116
1.64894	120
1.64816	124
1.64737	114
1.64658	128
1.64579	110
1.64501	130
1.64422	124
1.64344	136
1.64265	124
1.64187	132
1.64109	114
1.64031	122
1.63953	102
1.63875	112
1.63797	116
1.63719	112
1.63642	108
1.63564	114
1.63486	114
1.63409	100
1.63331	110
1.63254	106
1.63177	118
1.631	112
1.63023	94
1.62946	100
1.62869	110
1.62792	98
1.62715	96
1.62639	102
1.62562	96
1.62485	96
1.62409	114
1.62333	106
1.62256	90
1.6218	90
1.62104	90
1.62028	98
1.61952	90
1.61876	92
1.618	90
1.61724	110
1.61649	118
1.61573	98
1.61498	90
1.61422	82
1.61347	88
1.61271	94
1.61196	94
1.61121	102
1.61046	84
1.60971	90
1.60896	94
1.60821	86
1.60747	84
1.60672	88
1.60597	92
1.60523	96
1.60448	82
1.60374	84
1.603	88
1.60225	78
1.60151	88
1.60077	84
1.60003	86
1.59929	90
1.59855	92
1.59782	88
1.59708	84
1.59634	76
1.59561	86
1.59487	92
1.59414	82
1.5934	82
1.59267	70
1.59194	78
1.59121	72
1.59048	76
1.58975	82
1.58902	72
1.58829	78
1.58756	70
1.58684	70
1.58611	76
1.58538	70
1.58466	74
1.58394	78
1.58321	74
1.58249	84
1.58177	84
1.58105	78
1.58033	72
1.57961	64
1.57889	70
1.57817	66
1.57745	60
1.57674	64
1.57602	65.9719
1.5753	67.2949
1.57459	64.4227
1.57388	69.5696
1.57316	62.8019
1.57245	55.7699
1.57174	68.6337
1.57103	58.993
1.57032	65.2871
1.56961	57.0753
1.5689	59.2747
1.56819	62.0926
1.56748	56.4065
1.56678	56.5967
1.56607	51.9092
1.56544	64
1.56473	58
1.56402	62
1.56331	58
1.56261	68
1.5619	62
1.56119	60
1.56049	58
1.55979	48
1.55908	62
1.55838	62
1.55768	54
1.55698	54
1.55628	52
1.55558	56
1.55488	54
1.55418	58
1.55348	54
1.55278	54
1.55209	56
1.55139	58
1.5507	48
1.55	50
1.54931	44
1.54862	48
1.54792	56
1.54723	56
1.54654	62
1.54585	48
1.54516	58
1.54447	46
1.54378	54
1.5431	58
1.54241	48
1.54172	52
1.54104	60
1.54035	48
1.53967	54
1.53898	48
1.5383	56
1.53762	38
1.53694	44
1.53626	50
1.53558	52
1.5349	56
1.53422	48
1.53354	54
1.53286	42
1.53218	52
1.53151	48
1.53083	54
1.53016	50
1.52948	46
1.52881	48
1.52813	50
1.52746	52
1.52679	48
1.52612	46
1.52545	48
1.52478	40
1.52411	48
1.52344	34
1.52277	48
1.5221	50
1.52144	44
1.52077	50
1.52011	46
1.51944	44
1.51878	48
1.51811	42
1.51745	44
1.51679	46
1.51613	44
1.51547	40
1.51481	46
1.51415	50
1.51349	42
1.51283	44
1.51217	50
1.51151	50
1.51086	40
1.5102	38
1.50954	46
1.50889	50
1.50824	42
1.50758	40
1.50693	44
1.50628	36
1.50563	38
1.50497	38
1.50432	42
1.50367	46
1.50302	42
1.50238	48
1.50173	36
1.50108	44
1.50043	40
1.49979	34
1.49914	36
1.4985	40
1.49785	48
1.49721	34
1.49657	38
1.49592	36
1.49528	34
1.49464	40
1.494	36
1.49336	34
1.49272	40
1.49208	36
1.49144	38
1.49081	34
1.49017	34
1.48953	40
1.4889	30
1.48826	38
1.48763	38
1.48699	33.9901
1.48636	40.0902
1.48573	36.2404
1.4851	31.2772
1.48446	37.9608
1.48383	34.1173
1.4832	39.7843
1.48257	34.2404
1.48194	34.0407
1.48132	32.936
1.48069	37.3915
1.48006	34.2818
1.47943	37.3465
1.47881	35.6857
1.47818	33.6794
1.47756	38
1.47694	32
1.47631	34
1.47568	28
1.47505	36
1.47443	34
1.4738	36
1.47318	38
1.47256	36
1.47193	40
1.47131	34
1.47069	30
1.47006	36
1.46944	36
1.46882	34
1.4682	32
1.46758	40
1.46696	34
1.46635	42
1.46573	46
1.46511	28
1.46449	30
1.46388	28
1.46326	34
1.46265	30
1.46203	34
1.46142	34
1.46081	36
1.46019	40
1.45958	38
1.45897	28
1.45836	24
1.45775	28
1.45714	26
1.45653	36
1.45592	26
1.45531	34
1.4547	28
1.4541	34
1.45349	28
1.45288	28
1.45228	34
1.45167	34
1.45107	28
1.45047	30
1.44986	32
1.44926	24
1.44866	28
1.44806	28
1.44746	30
1.44686	34
1.44626	30
1.44566	32
1.44506	34
1.44446	30
1.44386	28
1.44326	34
1.44267	32
1.44207	26
1.44148	34
1.44088	30
1.44029	24
1.43969	26
1.4391	28
1.43851	30
1.43791	30
1.43732	26
1.43673	24
1.43614	26
1.43555	28
1.43496	24
1.43437	28
1.43378	28
1.4332	32
1.43261	36
1.43202	36
1.43143	18
1.43085	30
1.43026	32
1.42968	28
1.42909	34
1.42851	28
1.42793	26
1.42734	32
1.42676	34
1.42618	26
1.4256	30
1.42502	32
1.42444	30
1.42386	34
1.42328	24
1.4227	30
1.42212	30
1.42155	28
1.42097	32
1.42039	28
1.41982	24
1.41924	28
1.41867	30
1.41809	28
1.41752	28
1.41695	36
1.41637	34
1.4158	30
1.41523	32
1.41466	34
1.41409	18
1.41352	30
1.41295	26
1.41238	28
1.41181	32
1.41124	30
1.41067	28
1.41011	30
1.40954	26
1.40897	22
1.40841	28
1.40784	33.9333
1.40728	24.1485
1.40672	30.2854
1.40615	30.6921
1.40559	36.7008
1.40503	27.548
1.40446	123.215
1.4039	32.1527
1.40334	25.0878
1.40278	29.0746
1.40222	29.4229
1.40166	27.5956
1.4011	31.6401
1.40054	28.4458
1.39999	25.1322
1.39947	28
1.3989	30
1.39834	28
1.39779	30
1.39723	32
1.39667	30
1.39611	36
1.39555	28
1.395	26
1.39444	26
1.39388	32
1.39333	32
1.39277	36
1.39222	26
1.39166	28
1.39111	32
1.39056	32
1.39	32
1.38945	24
1.3889	28
1.38835	26
1.3878	36
1.38725	30
1.3867	30
1.38615	34
1.3856	34
1.38505	32
1.3845	26
1.38396	26
1.38341	28
1.38286	38
1.38232	30
1.38177	34
1.38123	32
1.38068	28
1.38014	32
1.3796	38
1.37905	26
1.37851	20
1.37797	28
1.37743	30
1.37688	30
1.37634	30
1.3758	26
1.37526	34
1.37472	34
1.37419	34
1.37365	28
1.37311	26
1.37257	28
1.37204	34
1.3715	36
1.37096	28
1.37043	30
1.36989	30
1.36936	26
1.36882	30
1.36829	32
1.36776	32
1.36722	32
1.36669	38
1.36616	22
1.36563	24
1.3651	36
1.36457	26
1.36404	32
1.36351	34
1.36298	36
1.36245	30
1.36192	36
1.36139	32
1.36087	36
1.36034	26
1.35981	28
1.35929	30
1.35876	40
1.35824	30
1.35771	30
1.35719	34
1.35667	28
1.35614	34
1.35562	24
1.3551	28
1.35458	32
1.35406	32
1.35353	28
1.35301	32
1.35249	28
1.35197	28
1.35146	36
1.35094	28
1.35042	26
1.3499	28
1.34938	28
1.34887	24
1.34835	32
1.34783	22
1.34732	26
1.3468	28
1.34629	28
1.34578	32
1.34526	30
1.34475	28
1.34424	28
1.34372	34
1.34321	28
1.3427	36
1.34219	28
1.34168	28
1.34117	36
1.34066	30
1.34015	26
1.33964	30
1.33913	30
1.33862	24
1.33812	34
1.33761	34
1.3371	29.9249
1.3366	25.9661
1.33609	24.0449
1.33558	33.1008
1.33508	33.4407
1.33457	28
1.33407	29.5652
1.33357	28
1.33306	31.5962
1.33256	26.3376
1.33206	30.2897
1.33156	27.4719
1.33105	30.1737
1.33055	28.9937
1.33005	24.7079
1.32959	30
1.32909	30
1.32859	26
1.32809	20
1.32758	26
1.32708	36
1.32658	32
1.32608	28
1.32558	24
1.32508	28
1.32458	32
1.32408	30
1.32358	30
1.32309	28
1.32259	28
1.32209	40
1.3216	36
1.3211	28
1.3206	26
1.32011	24
1.31961	32
1.31912	38
1.31862	36
1.31813	26
1.31764	40
1.31714	30
1.31665	28
1.31616	30
1.31567	24
1.31518	28
1.31468	30
1.31419	32
1.3137	32
1.31321	36
1.31272	34
1.31224	20
1.31175	32
1.31126	28
1.31077	32
1.31028	34
1.3098	26
1.30931	32
1.30882	34
1.30834	26
1.30785	28
1.30737	32
1.30688	32
1.3064	32
1.30592	28
1.30543	34
1.30495	34
1.30447	32
1.30399	34
1.3035	28
1.30302	40
1.30254	42
1.30206	36
1.30158	28
1.3011	38
1.30062	26
1.30014	38
1.30001	34