File: ploting_and_data_tools.ipynb/archivosraman/CdSe1_03.txt
#Acq. time (s)=	2
#Accumulations=	10
#Range (eV)=	2...1
#Windows=	11
#Autofocus=	Off
#AutoExposure=	Off
#Spike filter=	Multiple accum.
#Delay time (s)=	0
#Binning=	1
#Readout mode=	Signal
#DeNoise=	Off
#ICS correction=	Off
#Dark correction=	Off
#Inst. Process=	Off
#Instrument=	LabRAM HR Evol
#Detector=	Syncerity OE
#Objective=	x10_VIS
#Grating=	600 (500nm)
#ND Filter=	3.2%
#Laser=	442nm_Notch
#Hole=	70.0087
#Range=	Visible
#Project=	Paty
#Sample=
#Site=	15-06-22
#Title=	CdSe1
#Remark=
#Date=	15.06.2022 19:40
#Acquired=	15.06.2022 19:40:40
2.69985	29.5556
2.69767	28.4444
2.69551	28.4444
2.69334	26.4444
2.69118	28.8889
2.68902	27.5556
2.68687	28.4444
2.68472	28.6667
2.68257	28.2222
2.68043	28.8889
2.67829	30
2.67615	29.5556
2.67402	30.2222
2.67189	30
2.66977	31.3333
2.66764	29.1111
2.66553	30.4444
2.66341	29.5556
2.6613	34.4444
2.65919	33.5556
2.65709	31.5556
2.65499	33.1111
2.65289	33.3333
2.65079	36.4444
2.6487	32.6667
2.64661	34.8889
2.64453	34.8889
2.64245	33.3333
2.64037	37.5556
2.6383	33.7778
2.63623	36.6667
2.63416	34.2222
2.63209	34.8889
2.63003	36
2.62798	35.7778
2.62592	37.7778
2.62387	40.6667
2.62182	38.8889
2.61978	40.8889
2.61774	38.8889
2.6157	37.7778
2.61367	40.8889
2.61164	41.7778
2.60961	41.3333
2.60758	38.8889
2.60556	46.4444
2.60354	43.3333
2.60153	42.8889
2.59952	46.8889
2.59751	44.6667
2.5955	44.2222
2.5935	48.8889
2.5915	46.4444
2.58951	47.3333
2.58751	48
2.58553	50.8889
2.58354	51.1111
2.58156	52.6667
2.57958	51.5556
2.5776	56
2.57563	55.7778
2.57366	61.1111
2.57169	57.7778
2.56972	56.2222
2.56776	57.1111
2.56581	55.3333
2.56385	56.8889
2.5619	60
2.55995	63.1111
2.558	60.6667
2.55606	65.1111
2.55412	70.8889
2.55219	68.6667
2.55025	71.1111
2.54832	68.6667
2.5464	74.4445
2.54447	76
2.54255	74.6667
2.54063	82.2222
2.53872	80.2222
2.5368	82.2222
2.53489	82.2222
2.53299	84.8889
2.53108	85.7778
2.52918	82.4444
2.52729	89.1111
2.52539	91.1111
2.5235	93.7778
2.52161	96.8889
2.51973	98
2.51784	100.222
2.51596	105.556
2.51409	103.778
2.51221	103.556
2.51034	109.111
2.50847	111.333
2.50661	114.222
2.50475	119.556
2.50289	120
2.50103	119.556
2.49918	124.889
2.49733	129.111
2.49548	129.333
2.49363	130.667
2.49179	136.667
2.48995	139.556
2.48811	142
2.48628	146
2.48445	140.444
2.48262	145.111
2.4808	154
2.47897	153.111
2.47715	162.222
2.47534	157.333
2.47352	163.333
2.47171	164.667
2.4699	173.111
2.4681	175.556
2.46629	174
2.46449	180.444
2.46269	180.444
2.4609	186.222
2.45911	189.333
2.45732	191.111
2.45553	193.111
2.45375	200.667
2.45197	206.667
2.45019	207.778
2.44841	204.889
2.44664	209.556
2.44487	213.556
2.4431	218.222
2.44133	217.434
2.43957	228.832
2.43781	228.614
2.43605	229.226
2.4343	230.69
2.43255	236.142
2.4308	238.557
2.42905	243.255
2.42731	242.618
2.42557	245.146
2.42383	253.921
2.42209	251.687
2.42036	244.112
2.41863	257.867
2.41713	263.556
2.4154	266.222
2.41367	267.556
2.41194	270.889
2.41022	268.222
2.40849	279.556
2.40677	281.333
2.40505	270.889
2.40334	281.778
2.40163	280.667
2.39992	288.222
2.39821	276.667
2.3965	291.111
2.3948	291.111
2.3931	304.222
2.3914	290.667
2.38971	307.778
2.38801	300.444
2.38632	291.778
2.38464	308.667
2.38295	306.222
2.38127	306.444
2.37959	318.889
2.37791	314.444
2.37623	319.111
2.37456	311.333
2.37289	310.667
2.37122	310.667
2.36956	317.333
2.36789	312.667
2.36623	316.444
2.36457	315.333
2.36292	316.667
2.36126	316.667
2.35961	307.556
2.35796	314.667
2.35632	312.667
2.35467	314.667
2.35303	315.556
2.35139	312
2.34976	313.778
2.34812	313.556
2.34649	314.222
2.34486	320.889
2.34323	312
2.34161	313.778
2.33999	310.222
2.33837	316.667
2.33675	310.667
2.33513	311.111
2.33352	314.444
2.33191	305.778
2.3303	304.222
2.32869	302.444
2.32709	313.556
2.32549	309.333
2.32389	311.333
2.32229	309.778
2.32069	310
2.3191	306.667
2.31751	308
2.31592	311.556
2.31434	315.778
2.31275	312
2.31117	313.556
2.30959	315.111
2.30802	311.111
2.30644	319.333
2.30487	317.778
2.3033	321.333
2.30173	328
2.30017	326.889
2.2986	319.556
2.29704	320.222
2.29548	325.778
2.29393	321.333
2.29237	329.778
2.29082	333.333
2.28927	339.111
2.28772	328.222
2.28618	344.444
2.28463	328.889
2.28309	338.889
2.28155	356.667
2.28002	349.778
2.27848	348
2.27695	350
2.27542	364.889
2.27389	349.778
2.27236	352.444
2.27084	358.444
2.26932	364.222
2.2678	357.333
2.26628	364.444
2.26477	360.667
2.26325	379.111
2.26174	379.333
2.26023	370.222
2.25873	377.778
2.25722	383.333
2.25572	380.889
2.25422	395.556
2.25272	388.222
2.25122	385.556
2.24973	403.333
2.24824	404.444
2.24675	402.889
2.24526	406.667
2.24377	412.889
2.24229	417.333
2.24081	417.111
2.23933	421.333
2.23785	427.111
2.23637	424.222
2.2349	428.667
2.23343	438.667
2.23196	433.556
2.23049	434.889
2.22902	441.969
2.22756	440.82
2.2261	451.563
2.22464	449.884
2.22318	452.368
2.22173	450.048
2.22027	458.805
2.21882	456.203
2.21737	456.913
2.21593	456.095
2.21448	463.584
2.21304	454.65
2.21159	456.011
2.21016	463.746
2.20882	462.889
2.20738	461.778
2.20594	470.667
2.2045	470.889
2.20307	470.889
2.20163	475.778
2.2002	472.667
2.19877	475.333
2.19734	486.667
2.19591	482.222
2.19449	491.556
2.19307	501.333
2.19165	501.333
2.19023	508
2.18881	510
2.1874	517.778
2.18598	518.889
2.18457	520.889
2.18316	519.111
2.18176	530
2.18035	541.556
2.17895	541.778
2.17755	538.222
2.17615	543.778
2.17475	551.556
2.17335	565.333
2.17196	563.778
2.17057	560.889
2.16918	579.556
2.16779	581.333
2.1664	588.444
2.16502	585.556
2.16363	582
2.16225	600
2.16087	593.111
2.1595	611.111
2.15812	611.111
2.15675	610.444
2.15538	631.556
2.15401	632.667
2.15264	628.667
2.15127	642
2.14991	650.667
2.14854	645.556
2.14718	647.333
2.14582	665.556
2.14447	658.444
2.14311	664
2.14176	675.556
2.14041	694.444
2.13906	680.444
2.13771	693.111
2.13636	701.778
2.13502	695.111
2.13367	709.556
2.13233	719.778
2.13099	724.889
2.12966	733.556
2.12832	741.778
2.12699	744.889
2.12565	748.667
2.12432	747.778
2.12299	768.889
2.12167	752.444
2.12034	776.889
2.11902	785.333
2.1177	780
2.11638	802.222
2.11506	791.111
2.11374	800.444
2.11242	795.556
2.11111	810.444
2.1098	828.444
2.10849	824
2.10718	812.222
2.10588	826.667
2.10457	843.111
2.10327	846
2.10197	846.222
2.10067	857.778
2.09937	860.222
2.09807	861.333
2.09678	866
2.09549	872
2.09419	882
2.09291	880.222
2.09162	895.333
2.09033	907.778
2.08905	892.889
2.08776	916.444
2.08648	913.333
2.0852	913.333
2.08393	940.889
2.08265	922.667
2.08138	924.667
2.0801	925.111
2.07883	940.222
2.07756	942.667
2.07629	932.889
2.07503	932.667
2.07376	953.333
2.0725	953.778
2.07124	945.778
2.06998	950.222
2.06872	952.444
2.06746	940.222
2.06621	939.778
2.06496	949.111
2.0637	928
2.06245	942
2.06121	949.556
2.05996	958
2.05871	946.667
2.05747	956.667
2.05623	965.111
2.05499	965.111
2.05375	963.778
2.05251	958.222
2.05127	964.069
2.05004	966.093
2.04881	965.604
2.04758	971.806
2.04635	975.71
2.04512	971.221
2.04389	973.554
2.04267	975.654
2.04145	968.92
2.04022	957.419
2.039	963.336
2.03779	948.479
2.03657	959.779
2.03535	945.351
2.0343	960.667
2.03308	956.444
2.03186	949.111
2.03065	955.333
2.02943	954.889
2.02822	955.333
2.02701	956.889
2.0258	959.333
2.0246	963.111
2.02339	971.111
2.02218	967.333
2.02098	980.889
2.01978	974.222
2.01858	978.222
2.01738	985.556
2.01618	1002.44
2.01499	992.667
2.0138	997.556
2.0126	1003.33
2.01141	1010.44
2.01022	1002.89
2.00903	1017.11
2.00785	1036.67
2.00666	1030.44
2.00548	1043.11
2.0043	1015.78
2.00312	1059.78
2.00194	1060.67
2.00076	1049.33
1.99958	1065.11
1.99841	1053.11
1.99723	1077.78
1.99606	1076.22
1.99489	1079.56
1.99372	1096
1.99255	1094.22
1.99139	1100.22
1.99022	1098.22
1.98906	1098.89
1.9879	1105.11
1.98674	1116
1.98558	1114.67
1.98442	1117.11
1.98327	1124.89
1.98211	1122.89
1.98096	1142.22
1.97981	1128.67
1.97866	1134.44
1.97751	1133.33
1.97636	1124.44
1.97521	1135.33
1.97407	1134.67
1.97292	1155.33
1.97178	1162.67
1.97064	1135.11
1.9695	1156.89
1.96836	1152
1.96723	1159.78
1.96609	1166.22
1.96496	1156.44
1.96383	1164.89
1.9627	1144.89
1.96157	1154.22
1.96044	1168.44
1.95931	1155.33
1.95819	1174
1.95706	1159.56
1.95594	1155.78
1.95482	1152
1.9537	1181.56
1.95258	1160
1.95146	1158.22
1.95035	1154.44
1.94923	1155.56
1.94812	1165.11
1.94701	1161.11
1.9459	1167.33
1.94479	1153.78
1.94368	1175.56
1.94257	1152.44
1.94147	1154.22
1.94036	1162
1.93926	1162.44
1.93816	1147.33
1.93706	1145.56
1.93596	1139.33
1.93486	1142.89
1.93377	1132.44
1.93267	1140.44
1.93158	1132.67
1.93049	1147.33
1.9294	1129.33
1.92831	1121.11
1.92722	1119.11
1.92614	1122.44
1.92505	1115.11
1.92397	1108.89
1.92288	1107.11
1.9218	1119.11
1.92072	1099.78
1.91964	1111.78
1.91857	1106.89
1.91749	1108.67
1.91641	1100.89
1.91534	1086.67
1.91427	1093.78
1.9132	1075.33
1.91213	1088.44
1.91106	1063.56
1.90999	1074.67
1.90893	1070.89
1.90786	1068.22
1.9068	1062.44
1.90574	1051.78
1.90467	1035.33
1.90361	1051.11
1.90256	1045.11
1.9015	1034.44
1.90044	1020.67
1.89939	1016.96
1.89833	1029.36
1.89728	1018.3
1.89623	1021.04
1.89518	1008.86
1.89413	1008.53
1.89309	1005.8
1.89204	993.215
1.891	987.326
1.88995	982.826
1.88891	987.972
1.88787	968.902
1.88683	967.531
1.88579	955.778
1.88475	956.222
1.88371	970.667
1.88267	954.222
1.88163	953.333
1.8806	938.444
1.87956	918.667
1.87852	922.444
1.87749	924.667
1.87646	915.333
1.87543	919.778
1.8744	903.778
1.87337	903.333
1.87234	888.889
1.87131	898.667
1.87029	876.667
1.86926	891.333
1.86824	869.333
1.86722	868.667
1.8662	854.889
1.86518	861.333
1.86416	855.778
1.86314	838.222
1.86213	840.222
1.86111	841.333
1.8601	835.778
1.85908	823.333
1.85807	825.333
1.85706	843.111
1.85605	812.889
1.85505	803.778
1.85404	791.778
1.85303	790.667
1.85203	777.333
1.85103	777.778
1.85002	777.333
1.84902	769.778
1.84802	768.667
1.84703	751.333
1.84603	748.889
1.84503	748.445
1.84404	741.778
1.84304	730.667
1.84205	747.111
1.84106	722.444
1.84007	729.556
1.83908	702.667
1.83809	719.333
1.8371	702.444
1.83612	703.333
1.83513	692.444
1.83415	696.222
1.83316	676.667
1.83218	671.556
1.8312	679.333
1.83022	670.667
1.82924	672
1.82827	647.333
1.82729	650.222
1.82632	653.111
1.82534	646.445
1.82437	638.889
1.8234	635.778
1.82243	613.111
1.82146	620.222
1.82049	620.444
1.81952	613.778
1.81856	604.222
1.81759	588.667
1.81663	602
1.81567	598.444
1.8147	585.111
1.81374	578.667
1.81278	575.778
1.81183	560.667
1.81087	566.667
1.80991	558.889
1.80896	548.889
1.808	553.778
1.80705	529.333
1.8061	532.222
1.80515	530.444
1.8042	539.111
1.80325	527.111
1.8023	509.333
1.80135	521.778
1.80041	500.889
1.79946	500
1.79852	508
1.79758	487.778
1.79664	489.556
1.7957	482
1.79476	480
1.79382	473.111
1.79288	467.778
1.79195	461.778
1.79101	456
1.79008	451.111
1.78914	446
1.78821	448.889
1.78728	439.556
1.78635	432
1.78542	430.889
1.7845	424.222
1.78357	424.444
1.78264	417.333
1.78172	419.111
1.7808	423.556
1.77987	410.444
1.77895	395.778
1.77803	394.444
1.77711	388.222
1.77619	390.667
1.77528	381.778
1.77436	370.444
1.77344	381.333
1.77253	372.889
1.77162	366.667
1.7707	365.459
1.76979	358.774
1.76888	364.802
1.76797	353.982
1.76707	353.048
1.76616	343.968
1.76525	349.143
1.76435	339.92
1.76344	340.982
1.76254	333.644
1.76164	334.83
1.76074	331.075
1.75984	328.704
1.75894	328.408
1.75806	327.556
1.75716	311.778
1.75626	315.111
1.75536	334.889
1.75446	312.222
1.75356	298.222
1.75266	300
1.75177	292
1.75087	292.444
1.74998	292
1.74909	287.333
1.74819	280.222
1.7473	283.333
1.74641	286.667
1.74552	276
1.74464	266.222
1.74375	277.111
1.74286	262.222
1.74198	257.111
1.74109	257.556
1.74021	259.778
1.73933	248.444
1.73845	257.778
1.73756	245.556
1.73669	245.333
1.73581	239.778
1.73493	242.222
1.73405	234.444
1.73318	230.667
1.7323	227.556
1.73143	232.444
1.73055	222.444
1.72968	228.667
1.72881	221.778
1.72794	224.889
1.72707	218.444
1.7262	219.333
1.72534	215.111
1.72447	214.667
1.7236	210.667
1.72274	212.667
1.72188	204.444
1.72101	205.778
1.72015	202.889
1.71929	206
1.71843	205.111
1.71757	193.333
1.71671	199.333
1.71586	196.667
1.715	190.444
1.71415	192.667
1.71329	189.556
1.71244	187.333
1.71159	187.333
1.71073	182.667
1.70988	180.667
1.70903	177.556
1.70818	179.778
1.70734	172.889
1.70649	174
1.70564	173.333
1.7048	177.556
1.70395	171.111
1.70311	170
1.70227	167.556
1.70143	168
1.70059	165.778
1.69975	159.556
1.69891	165.778
1.69807	155.333
1.69723	162.444
1.69639	154
1.69556	153.778
1.69472	155.111
1.69389	152.667
1.69306	147.556
1.69223	150
1.6914	144.889
1.69057	147.333
1.68974	150
1.68891	145.111
1.68808	141.111
1.68725	138.222
1.68643	144
1.6856	141.333
1.68478	133.778
1.68396	138.889
1.68313	134.444
1.68231	135.778
1.68149	141.333
1.68067	142.889
1.67985	134.889
1.67904	130.444
1.67822	137.333
1.6774	136.222
1.67659	130
1.67577	133.556
1.67496	137.556
1.67415	130.444
1.67333	129.111
1.67252	132.222
1.67171	130.444
1.6709	133.333
1.67009	128
1.66929	129.778
1.66848	127.778
1.66767	129.556
1.66687	133.111
1.66607	129.778
1.66526	125.778
1.66446	124.444
1.66366	130
1.66286	134.222
1.66206	125.778
1.66126	128
1.66046	125.111
1.65966	127.333
1.65886	125.534
1.65807	123.795
1.65727	126.332
1.65648	119.616
1.65569	122.101
1.65489	121.683
1.6541	123.816
1.65331	119.858
1.65252	118.286
1.65173	119.345
1.65094	119.396
1.65015	115.571
1.64937	116.804
1.64858	111.567
1.6478	116.418
1.64705	113.556
1.64626	110.444
1.64547	116
1.64469	115.333
1.6439	113.333
1.64312	111.778
1.64233	117.778
1.64155	112.444
1.64077	110.222
1.63999	113.556
1.63921	107.111
1.63843	103.556
1.63765	112.444
1.63687	106.222
1.63609	109.333
1.63532	104.444
1.63454	108.444
1.63376	105.778
1.63299	105.333
1.63222	106.222
1.63144	104.222
1.63067	101.778
1.6299	103.556
1.62913	101.556
1.62836	102.444
1.62759	101.556
1.62682	98.6667
1.62606	99.3333
1.62529	97.7778
1.62453	99.3333
1.62376	98.4444
1.623	97.1111
1.62223	93.3333
1.62147	95.7778
1.62071	97.1111
1.61995	95.3333
1.61919	97.7778
1.61843	95.1111
1.61767	98.2222
1.61691	95.3333
1.61616	97.1111
1.6154	92.8889
1.61464	93.7778
1.61389	93.5556
1.61313	96.8889
1.61238	90.8889
1.61163	92.6667
1.61088	90.2222
1.61013	89.5556
1.60938	91.1111
1.60863	90.8889
1.60788	91.7778
1.60713	90
1.60638	89.1111
1.60564	95.3333
1.60489	87.5556
1.60415	87.5555
1.6034	84.2222
1.60266	85.1111
1.60192	86.4445
1.60117	86
1.60043	82.2222
1.59969	88.6667
1.59895	87.1111
1.59821	85.1111
1.59747	86.8889
1.59674	84.4444
1.596	80
1.59526	79.5556
1.59453	81.3333
1.59379	81.7778
1.59306	81.7778
1.59233	78
1.5916	80.4444
1.59086	82.2222
1.59013	77.5555
1.5894	78
1.58867	84.2222
1.58794	78.2222
1.58722	77.7778
1.58649	78.6667
1.58576	77.7778
1.58504	73.3333
1.58431	75.5556
1.58359	75.1111
1.58286	76.8889
1.58214	73.1111
1.58142	75.1111
1.5807	71.1111
1.57998	75.7778
1.57926	71.5556
1.57854	74.4444
1.57782	77.1111
1.5771	67.7778
1.57638	74.6667
1.57567	73.7778
1.57495	73.7778
1.57424	74
1.57352	71.3333
1.57281	70
1.5721	66.6667
1.57138	75.1111
1.57067	71.5556
1.56996	68.2222
1.56925	68
1.56854	68.6667
1.56783	72.6667
1.56713	68
1.56642	68.4444
1.56571	70.2222
1.56501	64.6667
1.5643	70.2222
1.5636	68
1.56289	68.2222
1.56219	66.8889
1.56149	66.2222
1.56079	65.1111
1.56008	70.3982
1.55938	64.8594
1.55868	65.1566
1.55799	62.566
1.55729	64.3793
1.55659	63.8909
1.55589	63.1475
1.5552	64.2758
1.5545	59.914
1.55381	63.8729
1.55311	60.5919
1.55242	62.1933
1.55173	62.7547
1.55103	63.2565
1.55034	60.3962
1.54971	60
1.54902	57.3333
1.54833	57.3333
1.54763	62.8889
1.54694	61.7778
1.54625	59.3333
1.54556	59.3333
1.54487	56.6667
1.54418	60.4444
1.54349	59.7778
1.5428	62.4444
1.54212	58.6667
1.54143	58.6667
1.54074	55.7778
1.54006	60
1.53937	58.4444
1.53869	56.6667
1.53801	58.4444
1.53732	60.4444
1.53664	59.3333
1.53596	59.5556
1.53528	60
1.5346	58.2222
1.53392	58.6667
1.53324	58.6667
1.53256	58.4444
1.53189	59.3333
1.53121	56.2222
1.53053	55.3333
1.52986	56.4444
1.52918	57.7778
1.52851	56.6667
1.52783	54.8889
1.52716	56.8889
1.52649	56
1.52582	60.2222
1.52515	56
1.52448	56.2222
1.52381	51.7778
1.52314	55.1111
1.52247	54.6667
1.5218	58.2222
1.52113	56
1.52047	54.6667
1.5198	54.8889
1.51914	53.7778
1.51847	53.3333
1.51781	55.7778
1.51715	54.4444
1.51648	52.6667
1.51582	59.3333
1.51516	56.6667
1.5145	55.3333
1.51384	52
1.51318	56.4444
1.51252	51.3333
1.51186	55.7778
1.5112	55.3333
1.51055	51.7778
1.50989	52.4444
1.50923	56.6667
1.50858	54
1.50793	51.1111
1.50727	53.1111
1.50662	54.2222
1.50597	51.7778
1.50531	47.7778
1.50466	48.2222
1.50401	52.2222
1.50336	50
1.50271	50.8889
1.50206	51.7778
1.50141	52.4444
1.50077	48.8889
1.50012	49.5556
1.49947	51.7778
1.49883	48.6667
1.49818	48
1.49754	47.3333
1.49689	49.5556
1.49625	52.6667
1.49561	51.3333
1.49496	47.7778
1.49432	47.5556
1.49368	44.4444
1.49304	49.5556
1.4924	46.8889
1.49176	44.4444
1.49112	47.1111
1.49049	49.5556
1.48985	46.6667
1.48921	47.3333
1.48858	44.4444
1.48794	48
1.48731	47.3333
1.48667	42.8889
1.48604	47.3333
1.4854	45.5556
1.48477	47.1111
1.48414	49.5556
1.48351	44.4444
1.48288	47.7778
1.48225	43.1111
1.48162	46.4444
1.48099	47.3333
1.48036	45.7778
1.47973	46
1.47911	46.2222
1.47848	46.6667
1.47785	48.4444
1.47723	43.7778
1.4766	44.6667
1.47598	41.5556
1.47535	40.4444
1.47473	41.7778
1.47411	41.1111
1.47349	42.4444
1.47287	42.6667
1.47224	44.8397
1.47162	40.9858
1.471	40.7248
1.47039	37.6751
1.46977	38.3966
1.46915	38.3144
1.46853	38.8826
1.46791	41.1545
1.4673	42.0381
1.46668	42.0789
1.46607	38.6835
1.46545	36.6758
1.46484	34.6859
1.46423	34.3099
1.46363	33.7778
1.46302	34.6667
1.4624	40.2222
1.46179	36.2222
1.46117	40
1.46056	37.1111
1.45995	34.2222
1.45934	29.3333
1.45872	32
1.45811	32.6667
1.4575	36.6667
1.45689	38
1.45628	33.5556
1.45567	32.2222
1.45506	31.5556
1.45446	28.8889
1.45385	33.7778
1.45324	33.5556
1.45264	32.6667
1.45203	31.5556
1.45142	28.2222
1.45082	25.1111
1.45022	25.7778
1.44961	28.4444
1.44901	26.8889
1.44841	23.5556
1.44781	25.3333
1.4472	26
1.4466	25.5556
1.446	23.7778
1.4454	26.6667
1.4448	27.7778
1.44421	24.4444
1.44361	25.3333
1.44301	26.2222
1.44241	27.3333
1.44182	24.8889
1.44122	28.4444
1.44063	26.8889
1.44003	26.4444
1.43944	25.5556
1.43884	26
1.43825	26.2222
1.43766	24.2222
1.43706	26.6667
1.43647	26.2222
1.43588	27.1111
1.43529	24.2222
1.4347	28.4444
1.43411	24.2222
1.43352	26.8889
1.43293	27.1111
1.43235	28.4444
1.43176	24.6667
1.43117	25.1111
1.43059	28.2222
1.43	27.7778
1.42942	27.1111
1.42883	26.4444
1.42825	24.2222
1.42766	26.4444
1.42708	26.8889
1.4265	27.5556
1.42592	26.8889
1.42533	26.4444
1.42475	25.3333
1.42417	25.5556
1.42359	24.6667
1.42301	27.7778
1.42244	27.3333
1.42186	25.3333
1.42128	28.2222
1.4207	24.2222
1.42012	27.1111
1.41955	24
1.41897	25.5556
1.4184	28
1.41782	26.2222
1.41725	28
1.41668	26.8889
1.4161	25.3333
1.41553	27.1111
1.41496	24.2222
1.41439	27.3333
1.41381	26.8889
1.41324	24.2222
1.41267	26
1.4121	25.3333
1.41154	26.6667
1.41097	25.1111
1.4104	24.4444
1.40983	27.7778
1.40926	27.7778
1.4087	30.6667
1.40813	29.5556
1.40757	30.4444
1.407	30.2222
1.40644	33.1111
1.40587	33.1111
1.40531	34.6667
1.40475	35.7778
1.40418	430.444
1.40362	33.5556
1.40306	31.7778
1.4025	35.3333
1.40194	36.4444
1.40138	33.7778
1.40082	33.7778
1.40026	36.2222
1.3997	37.7778
1.39914	33.5556
1.39859	34.6667
1.39803	33.7778
1.39747	34.6667
1.39692	36.8889
1.39636	36.2222
1.39581	33.3333
1.39525	31.3333
1.3947	36.8442
1.39415	34.5825
1.39359	35.4241
1.39304	36.7303
1.39249	35.5718
1.39194	34.6819
1.39139	32.6533
1.39084	34.4548
1.39029	34.479
1.38974	34.4872
1.38919	35.7422
1.38864	35.0475
1.38809	35.3887
1.38754	33.7644
1.38705	35.5556
1.3865	34.6667
1.38595	36
1.3854	35.3333
1.38485	37.7778
1.3843	36
1.38375	37.3333
1.38321	35.5556
1.38266	37.3333
1.38211	34.4444
1.38157	33.1111
1.38102	35.5556
1.38048	36.6667
1.37993	35.5556
1.37939	35.7778
1.37885	35.3333
1.3783	34.6667
1.37776	36
1.37722	35.5556
1.37668	36.2222
1.37614	36.4444
1.37559	36.6667
1.37505	34.2222
1.37452	31.5556
1.37398	35.7778
1.37344	35.5556
1.3729	36.4444
1.37236	36.2222
1.37182	35.3333
1.37129	36.2222
1.37075	39.3333
1.37022	37.1111
1.36968	36.4444
1.36914	34.6667
1.36861	39.3333
1.36808	38.4444
1.36754	34
1.36701	34.2222
1.36648	37.1111
1.36594	36
1.36541	37.1111
1.36488	35.5556
1.36435	32
1.36382	35.3333
1.36329	36.2222
1.36276	37.1111
1.36223	35.1111
1.3617	36.2222
1.36118	34.6667
1.36065	34.4444
1.36012	32.6667
1.35959	35.3333
1.35907	36.2222
1.35854	36.2222
1.35802	35.3333
1.35749	36.8889
1.35697	36.6667
1.35644	34
1.35592	34.8889
1.3554	35.5556
1.35488	33.7778
1.35435	38.4444
1.35383	35.1111
1.35331	34.2222
1.35279	32.2222
1.35227	36
1.35175	30
1.35123	34.8889
1.35071	36
1.35019	34.6667
1.34967	34.2222
1.34916	33.5556
1.34864	29.3333
1.34812	38
1.34761	33.1111
1.34709	34.2222
1.34657	34.8889
1.34606	34
1.34555	35.7778
1.34503	33.3333
1.34452	32.8889
1.344	33.5556
1.34349	33.3333
1.34298	33.7778
1.34247	35.3333
1.34196	33.3333
1.34144	30.8889
1.34093	34.6667
1.34042	32.8889
1.33991	33.7778
1.3394	32.4444
1.3389	34.8889
1.33839	33.1111
1.33788	32.6667
1.33737	33.1111
1.33686	33.3333
1.33636	31.5556
1.33585	32.4444
1.33535	32.8889
1.33484	32.8889
1.33434	30.6667
1.33383	31.5556
1.33333	28.6667
1.33282	33.5556
1.33232	31.1111
1.33182	31.5556
1.33132	31.3333
1.33081	29.7778
1.33031	31.7778
1.32981	26.8889
1.32931	31.1111
1.32881	28.8889
1.32831	33.7778
1.32781	31.7778
1.32731	32.2222
1.32681	31.1111
1.32631	32
1.32582	30.6667
1.32532	30.4349
1.32482	30.4561
1.32433	33.1124
1.32383	33.1622
1.32333	30.7086
1.32284	28.077
1.32234	30.2108
1.32185	30.343
1.32136	28.958
1.32086	29.5755
1.32037	29.1449
1.31988	28.7742
1.31939	30.9647
1.31889	28.2144
1.31843	29.3333
1.31793	29.7778
1.31744	27.5556
1.31695	26.8889
1.31645	32.6667
1.31596	27.3333
1.31547	32.2222
1.31498	28.2222
1.31449	30.2222
1.31399	32
1.3135	30.4444
1.31301	29.3333
1.31252	31.5556
1.31204	28.4444
1.31155	33.3333
1.31106	29.5556
1.31057	29.3333
1.31008	28.6667
1.30959	28.6667
1.30911	31.5556
1.30862	27.7778
1.30814	32
1.30765	31.5556
1.30717	29.1111
1.30668	29.3333
1.3062	32.8889
1.30571	28.6667
1.30523	28.6667
1.30475	29.3333
1.30426	30.2222
1.30378	33.5556
1.3033	27.1111
1.30282	30.6667
1.30234	29.1111
1.30185	30
1.30137	31.1111
1.30089	29.7778
1.30041	27.5556
1.3	32.2222