File: ploting_and_data_tools.ipynb/archivosraman/CdSe4_02.txt
#Acq. time (s)=	1
#Accumulations=	1
#Range (eV)=	2...1
#Windows=	11
#Autofocus=	Off
#AutoExposure=	Off
#Spike filter=	Off
#Delay time (s)=	0
#Binning=	1
#Readout mode=	Signal
#DeNoise=	Off
#ICS correction=	Off
#Dark correction=	Off
#Inst. Process=	Off
#Instrument=	LabRAM HR Evol
#Detector=	Syncerity OE
#Objective=	x100_VIS_LWD
#Grating=	600 (500nm)
#ND Filter=	1%
#Laser=	442nm_Notch
#Hole=	150.001
#Range=	Visible
#Project=	Paty
#Sample=
#Site=	15-06-22
#Title=	CdSe4
#Remark=
#Date=	15.06.2022 21:31
#Acquired=	15.06.2022 21:31:40
2.74975	22
2.7475	30
2.74525	28
2.743	28
2.74076	28
2.73852	32
2.73629	36
2.73406	34
2.73183	28
2.72961	32
2.72739	32
2.72517	28
2.72296	32
2.72075	28
2.71854	32
2.71634	32
2.71414	32
2.71195	36
2.70976	26
2.70757	38
2.70539	24
2.70321	36
2.70103	30
2.69886	36
2.69669	26
2.69452	32
2.69236	30
2.6902	30
2.68805	38
2.6859	32
2.68375	46
2.68161	34
2.67947	26
2.67733	36
2.6752	32
2.67307	36
2.67094	28
2.66882	26
2.6667	36
2.66458	28
2.66247	36
2.66036	36
2.65826	36
2.65615	38
2.65405	34
2.65196	36
2.64987	42
2.64778	32
2.64569	34
2.64361	42
2.64153	44
2.63946	38
2.63739	44
2.63532	28
2.63325	38
2.63119	36
2.62913	46
2.62708	48
2.62503	34
2.62298	40
2.62094	48
2.61889	42
2.61686	38
2.61482	50
2.61279	46
2.61076	48
2.60873	48
2.60671	42
2.60469	50
2.60268	48
2.60067	48
2.59866	56
2.59665	52
2.59465	58
2.59265	60
2.59065	56
2.58866	58
2.58667	60
2.58468	58
2.5827	70
2.58072	62
2.57874	58
2.57677	72
2.5748	78
2.57283	74
2.57086	80
2.5689	78
2.56694	72
2.56499	78
2.56304	90
2.56109	88
2.55914	108
2.5572	94
2.55526	88
2.55332	96
2.55139	102
2.54946	96
2.54753	110
2.5456	116
2.54368	106
2.54176	116
2.53985	120
2.53794	126
2.53603	124
2.53412	134
2.53222	122
2.53031	148
2.52842	148
2.52652	152
2.52463	154
2.52274	150
2.52085	164
2.51897	174
2.51709	188
2.51521	186
2.51334	186
2.51147	188
2.5096	194
2.50773	202
2.50587	190
2.50401	222
2.50216	208
2.5003	234
2.49845	248
2.4966	254
2.49476	234
2.49291	242
2.49107	278
2.48924	274
2.4874	282
2.48557	272
2.48374	284
2.48192	301.884
2.48009	296.955
2.47827	307.184
2.47646	319.814
2.47464	328.094
2.47283	345.563
2.47102	352.407
2.46922	345.449
2.46741	341.434
2.46561	363.652
2.46381	362.905
2.46202	350.82
2.46023	387.213
2.45844	402.22
2.45665	398.737
2.45493	390
2.45314	424
2.45136	444
2.44957	424
2.44779	420
2.44601	460
2.44424	448
2.44247	448
2.4407	470
2.43893	464
2.43716	496
2.4354	482
2.43364	498
2.43188	528
2.43013	482
2.42838	514
2.42663	520
2.42488	540
2.42314	530
2.4214	536
2.41966	528
2.41792	534
2.41619	526
2.41446	562
2.41273	552
2.411	560
2.40928	554
2.40756	542
2.40584	558
2.40413	556
2.40241	564
2.4007	564
2.39899	576
2.39729	548
2.39559	560
2.39389	572
2.39219	570
2.39049	576
2.3888	590
2.38711	538
2.38542	540
2.38374	562
2.38205	578
2.38037	516
2.37869	578
2.37702	578
2.37535	568
2.37368	546
2.37201	558
2.37034	524
2.36868	520
2.36702	516
2.36536	544
2.3637	502
2.36205	496
2.3604	514
2.35875	532
2.3571	492
2.35546	526
2.35382	512
2.35218	502
2.35054	512
2.34891	486
2.34727	498
2.34564	454
2.34402	478
2.34239	492
2.34077	458
2.33915	426
2.33753	464
2.33591	452
2.3343	416
2.33269	416
2.33108	432
2.32948	432
2.32787	406
2.32627	412
2.32467	372
2.32307	394
2.32148	376
2.31989	404
2.3183	386
2.31671	380
2.31512	382
2.31354	384
2.31196	366
2.31038	360
2.3088	368
2.30723	362
2.30565	354
2.30408	368
2.30252	330
2.30095	324
2.29939	318
2.29783	326
2.29627	320
2.29471	348
2.29316	320
2.29161	308
2.29006	334
2.28851	332
2.28696	322
2.28542	322
2.28388	304
2.28234	308
2.2808	286
2.27927	306
2.27773	294
2.2762	320
2.27468	312
2.27315	306
2.27163	296
2.27011	264
2.26859	280
2.26707	310
2.26555	302
2.26404	288
2.26253	283.875
2.26102	294.848
2.25951	277.146
2.25801	290.191
2.25651	287.844
2.25501	263.899
2.25351	274.941
2.25201	273.802
2.25052	268.88
2.24902	263.771
2.24753	266.523
2.24605	254.15
2.24456	261.866
2.24308	255.175
2.2416	240.33
2.24011	240
2.23863	238
2.23715	246
2.23567	274
2.23419	258
2.23271	236
2.23124	242
2.22977	254
2.2283	238
2.22683	230
2.22536	250
2.2239	246
2.22244	232
2.22098	228
2.21952	228
2.21807	218
2.21661	226
2.21516	226
2.21371	244
2.21226	244
2.21082	232
2.20937	236
2.20793	238
2.20649	210
2.20505	228
2.20362	232
2.20218	200
2.20075	242
2.19932	208
2.19789	240
2.19647	242
2.19504	228
2.19362	248
2.1922	224
2.19078	232
2.18936	214
2.18795	242
2.18654	208
2.18513	226
2.18372	208
2.18231	224
2.18091	206
2.1795	226
2.1781	224
2.1767	228
2.1753	210
2.17391	208
2.17251	234
2.17112	240
2.16973	226
2.16834	230
2.16696	218
2.16557	232
2.16419	222
2.16281	244
2.16143	242
2.16005	224
2.15868	246
2.1573	238
2.15593	212
2.15456	244
2.1532	222
2.15183	232
2.15046	222
2.1491	230
2.14774	226
2.14638	248
2.14503	218
2.14367	218
2.14232	222
2.14097	230
2.13962	240
2.13827	220
2.13692	224
2.13558	214
2.13423	216
2.13289	224
2.13155	222
2.13022	218
2.12888	214
2.12755	238
2.12621	234
2.12488	220
2.12356	216
2.12223	228
2.1209	220
2.11958	228
2.11826	226
2.11694	208
2.11562	222
2.1143	222
2.11299	208
2.11168	248
2.11037	216
2.10906	224
2.10775	226
2.10644	222
2.10514	222
2.10384	218
2.10253	222
2.10123	224
2.09994	216
2.09864	198
2.09735	226
2.09605	230
2.09476	214
2.09347	206
2.09219	218
2.0909	224
2.08962	204
2.08834	214
2.08705	222
2.08578	212
2.0845	214
2.08322	214
2.08195	230
2.08068	204
2.0794	213.718
2.07814	221.025
2.07687	205.903
2.0756	212.997
2.07434	212.153
2.07307	209.961
2.07181	206.726
2.07055	202.596
2.0693	199.071
2.06804	212.057
2.06679	189.819
2.06553	202.963
2.06428	198.515
2.06303	199.222
2.06178	202.72
2.06069	186
2.05944	204
2.05819	188
2.05694	204
2.05569	202
2.05445	188
2.05321	186
2.05196	186
2.05072	204
2.04949	186
2.04825	200
2.04701	198
2.04578	192
2.04455	190
2.04332	186
2.04209	190
2.04086	186
2.03964	190
2.03841	188
2.03719	198
2.03597	188
2.03475	184
2.03353	164
2.03232	186
2.0311	198
2.02989	176
2.02868	168
2.02747	168
2.02626	162
2.02505	196
2.02384	172
2.02264	184
2.02144	170
2.02024	186
2.01904	182
2.01784	190
2.01664	180
2.01544	186
2.01425	194
2.01306	192
2.01187	184
2.01068	192
2.00949	182
2.0083	204
2.00712	176
2.00594	204
2.00475	190
2.00357	186
2.0024	192
2.00122	194
2.00004	196
1.99887	194
1.99769	184
1.99652	200
1.99535	206
1.99418	190
1.99302	190
1.99185	194
1.99069	184
1.98952	172
1.98836	206
1.9872	202
1.98604	214
1.98488	186
1.98373	182
1.98257	208
1.98142	182
1.98027	190
1.97912	192
1.97797	196
1.97682	188
1.97568	190
1.97453	190
1.97339	204
1.97225	206
1.97111	188
1.96997	198
1.96883	186
1.9677	188
1.96656	190
1.96543	194
1.9643	202
1.96316	196
1.96204	180
1.96091	194
1.95978	184
1.95866	210
1.95753	204
1.95641	190
1.95529	176
1.95417	200
1.95305	194
1.95193	200
1.95082	184
1.9497	178
1.94859	182
1.94748	192
1.94637	186
1.94526	212
1.94415	196
1.94305	178
1.94194	194
1.94084	194
1.93974	180
1.93864	180
1.93754	192
1.93644	190
1.93534	178
1.93425	172
1.93315	188
1.93206	188
1.93097	196
1.92988	186
1.92879	184
1.9277	176
1.92662	184
1.92553	196
1.92445	183.971
1.92337	181.665
1.92228	174.396
1.92121	181.821
1.92013	185.291
1.91905	178.767
1.91797	179.633
1.9169	180.731
1.91583	188.143
1.91475	174.678
1.91368	192.049
1.91261	182.992
1.91155	165.185
1.91048	181.512
1.90946	186
1.90839	188
1.90732	172
1.90626	198
1.90519	178
1.90413	184
1.90306	178
1.902	172
1.90094	176
1.89988	186
1.89882	170
1.89777	174
1.89671	162
1.89566	184
1.8946	182
1.89355	162
1.8925	174
1.89145	170
1.8904	162
1.88936	166
1.88831	164
1.88727	162
1.88622	184
1.88518	168
1.88414	180
1.8831	164
1.88206	180
1.88102	180
1.87999	172
1.87895	156
1.87792	174
1.87689	170
1.87586	182
1.87483	148
1.8738	172
1.87277	170
1.87174	168
1.87072	176
1.86969	150
1.86867	154
1.86765	156
1.86663	168
1.86561	178
1.86459	162
1.86357	166
1.86256	148
1.86154	156
1.86053	146
1.85952	162
1.85851	170
1.8575	196
1.85649	152
1.85548	172
1.85447	162
1.85347	154
1.85247	160
1.85146	162
1.85046	142
1.84946	156
1.84846	150
1.84746	154
1.84646	144
1.84547	142
1.84447	142
1.84348	160
1.84249	154
1.8415	150
1.84051	148
1.83952	158
1.83853	170
1.83754	164
1.83656	170
1.83557	152
1.83459	160
1.83361	142
1.83262	154
1.83164	156
1.83066	150
1.82969	142
1.82871	138
1.82773	154
1.82676	154
1.82579	160
1.82481	152
1.82384	142
1.82287	158
1.8219	148
1.82094	140
1.81997	154
1.819	138
1.81804	138
1.81708	144
1.81611	138
1.81515	156
1.81419	136
1.81323	120
1.81227	148
1.81132	144
1.81036	136
1.80941	124
1.80845	134
1.8075	134
1.80655	136
1.8056	140
1.80465	136
1.8037	132
1.80275	126
1.80181	144
1.80086	128
1.79992	130
1.79897	136
1.79803	112
1.79709	140
1.79615	122
1.79521	130
1.79428	126
1.79334	140
1.7924	144
1.79147	137.629
1.79053	121.607
1.7896	115.025
1.78867	129.842
1.78774	122.337
1.78681	126.843
1.78588	128.949
1.78496	126.382
1.78403	129.791
1.7831	124.883
1.78218	122.201
1.78126	117.147
1.78033	117.728
1.77941	110.937
1.77851	126
1.77759	120
1.77667	126
1.77575	124
1.77483	124
1.77391	114
1.77299	106
1.77207	118
1.77115	106
1.77024	114
1.76932	120
1.76841	116
1.7675	114
1.76659	116
1.76568	114
1.76477	116
1.76386	116
1.76295	108
1.76204	108
1.76114	120
1.76023	120
1.75933	110
1.75843	120
1.75753	120
1.75662	102
1.75572	118
1.75483	98
1.75393	106
1.75303	114
1.75214	118
1.75124	108
1.75035	116
1.74945	104
1.74856	104
1.74767	102
1.74678	98
1.74589	100
1.74501	100
1.74412	110
1.74323	118
1.74235	104
1.74146	104
1.74058	96
1.7397	100
1.73882	112
1.73794	102
1.73706	96
1.73618	90
1.7353	108
1.73443	94
1.73355	92
1.73268	106
1.7318	86
1.73093	90
1.73006	106
1.72919	92
1.72832	90
1.72745	108
1.72658	96
1.72571	96
1.72485	88
1.72398	88
1.72312	98
1.72225	88
1.72139	88
1.72053	88
1.71967	86
1.71881	92
1.71795	94
1.71709	88
1.71624	84
1.71538	80
1.71453	84
1.71367	106
1.71282	88
1.71197	90
1.71112	84
1.71027	76
1.70942	86
1.70857	92
1.70772	82
1.70687	82
1.70603	86
1.70518	78
1.70434	78
1.7035	114
1.70265	96
1.70181	90
1.70097	78
1.70013	72
1.69929	74
1.69846	80
1.69762	80
1.69678	76
1.69595	64
1.69511	76
1.69428	70
1.69345	70
1.69262	86
1.69179	74
1.69096	74
1.69013	76
1.6893	84
1.68847	82
1.68765	70
1.68682	64
1.686	64
1.68517	76
1.68435	76
1.68353	70
1.68271	68
1.68189	68
1.68107	78
1.68025	80
1.67943	74
1.67861	70
1.6778	66
1.67698	72.0291
1.67617	66.5855
1.67536	71.8954
1.67454	78.4556
1.67373	74.3161
1.67292	64.9732
1.67211	67.0671
1.6713	70.6806
1.6705	66.9701
1.66969	60.3418
1.66888	70.6634
1.66808	73.6659
1.66727	66
1.66647	58.2733
1.66566	68.8919
1.6649	62
1.66409	60
1.66329	68
1.66249	60
1.66168	72
1.66088	68
1.66008	70
1.65928	66
1.65848	64
1.65768	66
1.65688	60
1.65608	64
1.65529	70
1.65449	58
1.6537	74
1.6529	60
1.65211	52
1.65132	64
1.65053	74
1.64973	62
1.64894	60
1.64816	62
1.64737	58
1.64658	64
1.64579	64
1.64501	64
1.64422	64
1.64344	56
1.64265	62
1.64187	56
1.64109	62
1.64031	54
1.63953	60
1.63875	64
1.63797	60
1.63719	54
1.63642	62
1.63564	60
1.63486	50
1.63409	58
1.63331	64
1.63254	58
1.63177	50
1.631	54
1.63023	60
1.62946	46
1.62869	58
1.62792	60
1.62715	68
1.62639	58
1.62562	60
1.62485	56
1.62409	52
1.62333	58
1.62256	48
1.6218	50
1.62104	56
1.62028	52
1.61952	60
1.61876	52
1.618	50
1.61724	54
1.61649	56
1.61573	48
1.61498	52
1.61422	58
1.61347	46
1.61271	54
1.61196	50
1.61121	44
1.61046	58
1.60971	42
1.60896	54
1.60821	54
1.60747	52
1.60672	58
1.60597	50
1.60523	56
1.60448	54
1.60374	52
1.603	44
1.60225	42
1.60151	48
1.60077	50
1.60003	54
1.59929	54
1.59855	42
1.59782	46
1.59708	50
1.59634	44
1.59561	42
1.59487	46
1.59414	54
1.5934	44
1.59267	38
1.59194	38
1.59121	50
1.59048	42
1.58975	46
1.58902	42
1.58829	40
1.58756	44
1.58684	46
1.58611	48
1.58538	42
1.58466	44
1.58394	42
1.58321	44
1.58249	48
1.58177	48
1.58105	38
1.58033	46
1.57961	46
1.57889	44
1.57817	44
1.57745	52
1.57674	36
1.57602	41.9885
1.5753	47.5156
1.57459	45.324
1.57388	41.5964
1.57316	49.6041
1.57245	35.5879
1.57174	44.4684
1.57103	39.0198
1.57032	38.1803
1.56961	30.9267
1.5689	39.0866
1.56819	38.737
1.56748	36.3267
1.56678	39.6312
1.56607	39.901
1.56544	42
1.56473	44
1.56402	42
1.56331	46
1.56261	40
1.5619	36
1.56119	34
1.56049	36
1.55979	38
1.55908	34
1.55838	26
1.55768	28
1.55698	52
1.55628	34
1.55558	40
1.55488	38
1.55418	38
1.55348	34
1.55278	36
1.55209	34
1.55139	40
1.5507	36
1.55	34
1.54931	28
1.54862	40
1.54792	40
1.54723	30
1.54654	38
1.54585	40
1.54516	30
1.54447	44
1.54378	40
1.5431	38
1.54241	36
1.54172	38
1.54104	36
1.54035	34
1.53967	40
1.53898	34
1.5383	32
1.53762	48
1.53694	42
1.53626	36
1.53558	32
1.5349	36
1.53422	34
1.53354	38
1.53286	38
1.53218	36
1.53151	42
1.53083	38
1.53016	32
1.52948	38
1.52881	44
1.52813	34
1.52746	42
1.52679	30
1.52612	44
1.52545	32
1.52478	34
1.52411	32
1.52344	38
1.52277	32
1.5221	38
1.52144	36
1.52077	38
1.52011	32
1.51944	36
1.51878	34
1.51811	32
1.51745	26
1.51679	34
1.51613	40
1.51547	24
1.51481	38
1.51415	38
1.51349	44
1.51283	36
1.51217	38
1.51151	36
1.51086	38
1.5102	44
1.50954	36
1.50889	34
1.50824	38
1.50758	38
1.50693	34
1.50628	30
1.50563	30
1.50497	32
1.50432	40
1.50367	28
1.50302	36
1.50238	30
1.50173	36
1.50108	38
1.50043	26
1.49979	26
1.49914	34
1.4985	34
1.49785	36
1.49721	28
1.49657	36
1.49592	26
1.49528	32
1.49464	30
1.494	36
1.49336	32
1.49272	28
1.49208	28
1.49144	32
1.49081	34
1.49017	30
1.48953	30
1.4889	28
1.48826	38
1.48763	28
1.48699	26.0297
1.48636	26.3938
1.48573	30.8147
1.4851	28.1197
1.48446	31.48
1.48383	30.703
1.4832	31.691
1.48257	27.7939
1.48194	31.1045
1.48132	30.6489
1.48069	28.9588
1.48006	28.8564
1.47943	29.3709
1.47881	29.6857
1.47818	28.3088
1.47756	28
1.47694	36
1.47631	28
1.47568	28
1.47505	32
1.47443	30
1.4738	38
1.47318	32
1.47256	30
1.47193	34
1.47131	34
1.47069	30
1.47006	34
1.46944	28
1.46882	36
1.4682	36
1.46758	34
1.46696	26
1.46635	30
1.46573	32
1.46511	26
1.46449	28
1.46388	38
1.46326	22
1.46265	26
1.46203	30
1.46142	34
1.46081	36
1.46019	30
1.45958	26
1.45897	30
1.45836	24
1.45775	30
1.45714	30
1.45653	36
1.45592	32
1.45531	34
1.4547	34
1.4541	28
1.45349	28
1.45288	26
1.45228	26
1.45167	24
1.45107	32
1.45047	26
1.44986	30
1.44926	30
1.44866	28
1.44806	24
1.44746	34
1.44686	36
1.44626	42
1.44566	26
1.44506	34
1.44446	26
1.44386	32
1.44326	26
1.44267	26
1.44207	28
1.44148	28
1.44088	32
1.44029	30
1.43969	36
1.4391	32
1.43851	32
1.43791	26
1.43732	32
1.43673	24
1.43614	28
1.43555	32
1.43496	34
1.43437	26
1.43378	30
1.4332	34
1.43261	28
1.43202	28
1.43143	32
1.43085	28
1.43026	26
1.42968	26
1.42909	20
1.42851	30
1.42793	34
1.42734	34
1.42676	32
1.42618	30
1.4256	32
1.42502	28
1.42444	34
1.42386	30
1.42328	32
1.4227	26
1.42212	28
1.42155	30
1.42097	28
1.42039	30
1.41982	28
1.41924	32
1.41867	22
1.41809	32
1.41752	36
1.41695	28
1.41637	22
1.4158	24
1.41523	26
1.41466	34
1.41409	24
1.41352	34
1.41295	28
1.41238	34
1.41181	36
1.41124	32
1.41067	32
1.41011	24
1.40954	24
1.40897	30
1.40841	36
1.40784	20.0396
1.40728	26.1213
1.40672	29.9983
1.40615	25.5743
1.40559	29.3922
1.40503	22.8703
1.40446	123.223
1.4039	31.1725
1.40334	27.2185
1.40278	29.8171
1.40222	26.5771
1.40166	28.0389
1.4011	27.4663
1.40054	28
1.39999	30.769
1.39947	32
1.3989	34
1.39834	34
1.39779	26
1.39723	38
1.39667	26
1.39611	28
1.39555	30
1.395	26
1.39444	30
1.39388	24
1.39333	30
1.39277	32
1.39222	32
1.39166	34
1.39111	28
1.39056	36
1.39	32
1.38945	28
1.3889	34
1.38835	32
1.3878	32
1.38725	32
1.3867	28
1.38615	38
1.3856	34
1.38505	30
1.3845	24
1.38396	22
1.38341	24
1.38286	26
1.38232	40
1.38177	28
1.38123	28
1.38068	34
1.38014	26
1.3796	30
1.37905	26
1.37851	30
1.37797	38
1.37743	30
1.37688	28
1.37634	32
1.3758	24
1.37526	34
1.37472	24
1.37419	30
1.37365	30
1.37311	30
1.37257	38
1.37204	28
1.3715	30
1.37096	30
1.37043	22
1.36989	28
1.36936	28
1.36882	28
1.36829	26
1.36776	32
1.36722	30
1.36669	34
1.36616	28
1.36563	26
1.3651	26
1.36457	30
1.36404	26
1.36351	24
1.36298	28
1.36245	30
1.36192	24
1.36139	26
1.36087	30
1.36034	24
1.35981	38
1.35929	24
1.35876	30
1.35824	36
1.35771	30
1.35719	22
1.35667	30
1.35614	30
1.35562	24
1.3551	36
1.35458	28
1.35406	28
1.35353	30
1.35301	32
1.35249	30
1.35197	30
1.35146	32
1.35094	22
1.35042	30
1.3499	26
1.34938	26
1.34887	30
1.34835	28
1.34783	32
1.34732	26
1.3468	24
1.34629	32
1.34578	28
1.34526	24
1.34475	24
1.34424	32
1.34372	30
1.34321	28
1.3427	32
1.34219	28
1.34168	24
1.34117	24
1.34066	28
1.34015	30
1.33964	22
1.33913	24
1.33862	30
1.33812	34
1.33761	28
1.3371	31.9249
1.3366	22.4367
1.33609	26.6915
1.33558	24.3669
1.33508	26.8623
1.33457	28
1.33407	29.1631
1.33357	23.8501
1.33306	31.8628
1.33256	26.2061
1.33206	26.6459
1.33156	25.2971
1.33105	24.2427
1.33055	31.6069
1.33005	28.6087
1.32959	32
1.32909	30
1.32859	28
1.32809	30
1.32758	30
1.32708	20
1.32658	20
1.32608	26
1.32558	34
1.32508	24
1.32458	28
1.32408	32
1.32358	26
1.32309	30
1.32259	28
1.32209	30
1.3216	28
1.3211	28
1.3206	30
1.32011	26
1.31961	28
1.31912	30
1.31862	28
1.31813	26
1.31764	26
1.31714	28
1.31665	26
1.31616	32
1.31567	26
1.31518	28
1.31468	34
1.31419	28
1.3137	28
1.31321	32
1.31272	26
1.31224	32
1.31175	30
1.31126	36
1.31077	24
1.31028	28
1.3098	24
1.30931	28
1.30882	34
1.30834	32
1.30785	30
1.30737	36
1.30688	32
1.3064	24
1.30592	32
1.30543	32
1.30495	34
1.30447	38
1.30399	30
1.3035	30
1.30302	28
1.30254	34
1.30206	30
1.30158	28
1.3011	28
1.30062	28
1.30014	28
1.30001	34