File: ploting_and_data_tools.ipynb/archivosraman/CdSe1_15.txt
#Acq. time (s)=	1
#Accumulations=	1
#Range (eV)=	2...1
#Windows=	11
#Autofocus=	Off
#AutoExposure=	Off
#Spike filter=	Off
#Delay time (s)=	0
#Binning=	1
#Readout mode=	Signal
#DeNoise=	Off
#ICS correction=	Off
#Dark correction=	Off
#Inst. Process=	Off
#Instrument=	LabRAM HR Evol
#Detector=	Syncerity OE
#Objective=	x100_VIS_LWD
#Grating=	600 (500nm)
#ND Filter=	1%
#Laser=	442nm_Notch
#Hole=	150.001
#Range=	Visible
#Project=	Paty
#Sample=
#Site=	15-06-22
#Title=	CdSe1
#Remark=
#Date=	15.06.2022 20:47
#Acquired=	15.06.2022 20:47:55
2.74975	28
2.7475	26
2.74525	34
2.743	36
2.74076	30
2.73852	28
2.73629	26
2.73406	26
2.73183	30
2.72961	38
2.72739	40
2.72517	34
2.72296	24
2.72075	24
2.71854	32
2.71634	34
2.71414	42
2.71195	34
2.70976	22
2.70757	26
2.70539	38
2.70321	30
2.70103	34
2.69886	38
2.69669	40
2.69452	34
2.69236	32
2.6902	34
2.68805	36
2.6859	32
2.68375	42
2.68161	38
2.67947	34
2.67733	42
2.6752	36
2.67307	30
2.67094	38
2.66882	36
2.6667	44
2.66458	40
2.66247	42
2.66036	38
2.65826	38
2.65615	44
2.65405	42
2.65196	40
2.64987	42
2.64778	46
2.64569	44
2.64361	40
2.64153	40
2.63946	46
2.63739	48
2.63532	50
2.63325	52
2.63119	50
2.62913	52
2.62708	56
2.62503	62
2.62298	54
2.62094	56
2.61889	62
2.61686	58
2.61482	56
2.61279	56
2.61076	72
2.60873	56
2.60671	60
2.60469	70
2.60268	74
2.60067	72
2.59866	84
2.59665	76
2.59465	86
2.59265	84
2.59065	82
2.58866	80
2.58667	94
2.58468	100
2.5827	96
2.58072	100
2.57874	98
2.57677	100
2.5748	112
2.57283	108
2.57086	114
2.5689	120
2.56694	126
2.56499	128
2.56304	136
2.56109	158
2.55914	136
2.5572	158
2.55526	164
2.55332	172
2.55139	184
2.54946	184
2.54753	176
2.5456	202
2.54368	194
2.54176	212
2.53985	204
2.53794	236
2.53603	224
2.53412	252
2.53222	240
2.53031	256
2.52842	272
2.52652	286
2.52463	292
2.52274	330
2.52085	304
2.51897	326
2.51709	360
2.51521	366
2.51334	368
2.51147	376
2.5096	400
2.50773	438
2.50587	430
2.50401	478
2.50216	454
2.5003	508
2.49845	518
2.4966	516
2.49476	590
2.49291	556
2.49107	560
2.48924	598
2.4874	626
2.48557	634
2.48374	646
2.48192	688.601
2.48009	738.068
2.47827	753.054
2.47646	801.85
2.47464	802.591
2.47283	870.284
2.47102	897.333
2.46922	927.417
2.46741	956.226
2.46561	1022.28
2.46381	1049.66
2.46202	1081.13
2.46023	1117.42
2.45844	1206.69
2.45665	1202.84
2.45493	1250
2.45314	1284
2.45136	1286
2.44957	1336
2.44779	1400
2.44601	1424
2.44424	1436
2.44247	1536
2.4407	1524
2.43893	1596
2.43716	1586
2.4354	1666
2.43364	1686
2.43188	1714
2.43013	1766
2.42838	1822
2.42663	1846
2.42488	1824
2.42314	1902
2.4214	1942
2.41966	1988
2.41792	1976
2.41619	1990
2.41446	2046
2.41273	2152
2.411	2068
2.40928	2150
2.40756	2192
2.40584	2244
2.40413	2220
2.40241	2294
2.4007	2322
2.39899	2330
2.39729	2420
2.39559	2364
2.39389	2412
2.39219	2464
2.39049	2422
2.3888	2476
2.38711	2496
2.38542	2586
2.38374	2548
2.38205	2570
2.38037	2606
2.37869	2590
2.37702	2624
2.37535	2604
2.37368	2730
2.37201	2684
2.37034	2606
2.36868	2692
2.36702	2700
2.36536	2654
2.3637	2636
2.36205	2592
2.3604	2602
2.35875	2632
2.3571	2632
2.35546	2628
2.35382	2584
2.35218	2566
2.35054	2610
2.34891	2582
2.34727	2500
2.34564	2482
2.34402	2508
2.34239	2524
2.34077	2420
2.33915	2450
2.33753	2468
2.33591	2386
2.3343	2328
2.33269	2364
2.33108	2270
2.32948	2344
2.32787	2300
2.32627	2238
2.32467	2252
2.32307	2170
2.32148	2232
2.31989	2136
2.3183	2126
2.31671	2106
2.31512	2046
2.31354	2066
2.31196	2048
2.31038	1934
2.3088	1998
2.30723	1968
2.30565	1904
2.30408	1960
2.30252	1860
2.30095	1900
2.29939	1876
2.29783	1856
2.29627	1774
2.29471	1788
2.29316	1790
2.29161	1760
2.29006	1738
2.28851	1744
2.28696	1684
2.28542	1642
2.28388	1756
2.28234	1632
2.2808	1616
2.27927	1570
2.27773	1526
2.2762	1574
2.27468	1554
2.27315	1500
2.27163	1498
2.27011	1448
2.26859	1462
2.26707	1482
2.26555	1426
2.26404	1440
2.26253	1407.58
2.26102	1409.74
2.25951	1392.91
2.25801	1329.44
2.25651	1308.97
2.25501	1288.6
2.25351	1279.23
2.25201	1270.13
2.25052	1230.13
2.24902	1207.39
2.24753	1217.12
2.24605	1197.37
2.24456	1177.77
2.24308	1147.75
2.2416	1090.96
2.24011	1122
2.23863	1130
2.23715	1086
2.23567	1090
2.23419	1062
2.23271	1044
2.23124	1050
2.22977	1000
2.2283	1002
2.22683	962
2.22536	956
2.2239	976
2.22244	980
2.22098	920
2.21952	980
2.21807	938
2.21661	914
2.21516	896
2.21371	914
2.21226	862
2.21082	884
2.20937	864
2.20793	848
2.20649	870
2.20505	816
2.20362	822
2.20218	820
2.20075	846
2.19932	818
2.19789	784
2.19647	798
2.19504	800
2.19362	814
2.1922	820
2.19078	806
2.18936	798
2.18795	778
2.18654	786
2.18513	772
2.18372	758
2.18231	774
2.18091	760
2.1795	748
2.1781	744
2.1767	746
2.1753	712
2.17391	752
2.17251	738
2.17112	762
2.16973	748
2.16834	712
2.16696	734
2.16557	700
2.16419	688
2.16281	704
2.16143	702
2.16005	676
2.15868	712
2.1573	704
2.15593	688
2.15456	710
2.1532	720
2.15183	712
2.15046	660
2.1491	682
2.14774	688
2.14638	714
2.14503	700
2.14367	696
2.14232	720
2.14097	692
2.13962	700
2.13827	670
2.13692	692
2.13558	672
2.13423	684
2.13289	664
2.13155	650
2.13022	696
2.12888	682
2.12755	710
2.12621	698
2.12488	724
2.12356	682
2.12223	684
2.1209	636
2.11958	708
2.11826	672
2.11694	668
2.11562	702
2.1143	672
2.11299	668
2.11168	688
2.11037	694
2.10906	686
2.10775	694
2.10644	686
2.10514	676
2.10384	672
2.10253	664
2.10123	720
2.09994	694
2.09864	690
2.09735	660
2.09605	684
2.09476	678
2.09347	670
2.09219	714
2.0909	708
2.08962	686
2.08834	666
2.08705	678
2.08578	696
2.0845	676
2.08322	676
2.08195	696
2.08068	710
2.0794	698.182
2.07814	662.622
2.07687	659.109
2.0756	653.577
2.07434	668.78
2.07307	641.7
2.07181	642.213
2.07055	656.255
2.0693	684.457
2.06804	656.611
2.06679	639.979
2.06553	650.465
2.06428	650.776
2.06303	649.676
2.06178	637.441
2.06069	644
2.05944	620
2.05819	650
2.05694	658
2.05569	632
2.05445	640
2.05321	636
2.05196	632
2.05072	636
2.04949	644
2.04825	624
2.04701	618
2.04578	620
2.04455	618
2.04332	630
2.04209	640
2.04086	626
2.03964	602
2.03841	586
2.03719	618
2.03597	586
2.03475	602
2.03353	618
2.03232	618
2.0311	634
2.02989	642
2.02868	608
2.02747	594
2.02626	596
2.02505	604
2.02384	624
2.02264	604
2.02144	590
2.02024	606
2.01904	650
2.01784	604
2.01664	636
2.01544	638
2.01425	614
2.01306	610
2.01187	636
2.01068	606
2.00949	654
2.0083	652
2.00712	622
2.00594	620
2.00475	676
2.00357	666
2.0024	656
2.00122	680
2.00004	652
1.99887	652
1.99769	634
1.99652	680
1.99535	650
1.99418	690
1.99302	666
1.99185	682
1.99069	662
1.98952	650
1.98836	644
1.9872	682
1.98604	668
1.98488	664
1.98373	688
1.98257	678
1.98142	648
1.98027	664
1.97912	678
1.97797	668
1.97682	724
1.97568	698
1.97453	698
1.97339	670
1.97225	672
1.97111	674
1.96997	720
1.96883	692
1.9677	718
1.96656	700
1.96543	678
1.9643	712
1.96316	716
1.96204	688
1.96091	714
1.95978	726
1.95866	688
1.95753	720
1.95641	706
1.95529	690
1.95417	696
1.95305	706
1.95193	712
1.95082	694
1.9497	700
1.94859	676
1.94748	700
1.94637	710
1.94526	728
1.94415	706
1.94305	690
1.94194	724
1.94084	698
1.93974	686
1.93864	706
1.93754	690
1.93644	702
1.93534	698
1.93425	710
1.93315	696
1.93206	698
1.93097	694
1.92988	676
1.92879	706
1.9277	672
1.92662	688
1.92553	696
1.92445	707.203
1.92337	718.386
1.92228	708.615
1.92121	693.427
1.92013	694.253
1.91905	704.113
1.91797	696.243
1.9169	682.794
1.91583	685.827
1.91475	711.63
1.91368	702.411
1.91261	706.606
1.91155	693.084
1.91048	656.936
1.90946	704
1.90839	706
1.90732	674
1.90626	716
1.90519	646
1.90413	648
1.90306	680
1.902	688
1.90094	690
1.89988	664
1.89882	692
1.89777	700
1.89671	702
1.89566	672
1.8946	674
1.89355	708
1.8925	672
1.89145	694
1.8904	666
1.88936	680
1.88831	678
1.88727	666
1.88622	662
1.88518	640
1.88414	672
1.8831	648
1.88206	652
1.88102	676
1.87999	670
1.87895	640
1.87792	670
1.87689	650
1.87586	640
1.87483	666
1.8738	672
1.87277	660
1.87174	656
1.87072	638
1.86969	628
1.86867	644
1.86765	644
1.86663	626
1.86561	640
1.86459	660
1.86357	668
1.86256	680
1.86154	634
1.86053	658
1.85952	624
1.85851	618
1.8575	656
1.85649	632
1.85548	660
1.85447	628
1.85347	612
1.85247	634
1.85146	664
1.85046	648
1.84946	648
1.84846	646
1.84746	668
1.84646	632
1.84547	628
1.84447	624
1.84348	610
1.84249	608
1.8415	620
1.84051	602
1.83952	634
1.83853	616
1.83754	616
1.83656	636
1.83557	626
1.83459	632
1.83361	634
1.83262	602
1.83164	590
1.83066	620
1.82969	606
1.82871	618
1.82773	616
1.82676	592
1.82579	614
1.82481	606
1.82384	594
1.82287	590
1.8219	596
1.82094	596
1.81997	580
1.819	598
1.81804	592
1.81708	608
1.81611	574
1.81515	576
1.81419	598
1.81323	598
1.81227	580
1.81132	566
1.81036	582
1.80941	568
1.80845	576
1.8075	574
1.80655	572
1.8056	592
1.80465	558
1.8037	570
1.80275	562
1.80181	570
1.80086	556
1.79992	574
1.79897	556
1.79803	542
1.79709	566
1.79615	548
1.79521	536
1.79428	548
1.79334	570
1.7924	546
1.79147	539.547
1.79053	557.781
1.7896	548.954
1.78867	530.44
1.78774	534.457
1.78681	524.302
1.78588	536.998
1.78496	527.416
1.78403	516.818
1.7831	510.98
1.78218	517.999
1.78126	501.186
1.78033	526.998
1.77941	507.953
1.77851	498
1.77759	514
1.77667	512
1.77575	494
1.77483	514
1.77391	496
1.77299	490
1.77207	508
1.77115	504
1.77024	484
1.76932	484
1.76841	502
1.7675	478
1.76659	472
1.76568	478
1.76477	480
1.76386	478
1.76295	482
1.76204	482
1.76114	478
1.76023	464
1.75933	492
1.75843	450
1.75753	456
1.75662	430
1.75572	476
1.75483	464
1.75393	448
1.75303	474
1.75214	464
1.75124	448
1.75035	442
1.74945	456
1.74856	452
1.74767	416
1.74678	448
1.74589	446
1.74501	446
1.74412	442
1.74323	438
1.74235	402
1.74146	424
1.74058	434
1.7397	420
1.73882	392
1.73794	408
1.73706	428
1.73618	414
1.7353	436
1.73443	404
1.73355	412
1.73268	404
1.7318	388
1.73093	390
1.73006	396
1.72919	410
1.72832	376
1.72745	396
1.72658	406
1.72571	396
1.72485	396
1.72398	384
1.72312	390
1.72225	382
1.72139	394
1.72053	356
1.71967	364
1.71881	360
1.71795	380
1.71709	344
1.71624	362
1.71538	358
1.71453	348
1.71367	390
1.71282	360
1.71197	360
1.71112	354
1.71027	330
1.70942	350
1.70857	344
1.70772	338
1.70687	346
1.70603	334
1.70518	336
1.70434	334
1.7035	352
1.70265	342
1.70181	328
1.70097	310
1.70013	328
1.69929	332
1.69846	308
1.69762	300
1.69678	318
1.69595	310
1.69511	314
1.69428	304
1.69345	304
1.69262	290
1.69179	304
1.69096	274
1.69013	310
1.6893	304
1.68847	278
1.68765	284
1.68682	262
1.686	280
1.68517	280
1.68435	288
1.68353	282
1.68271	264
1.68189	274
1.68107	284
1.68025	298
1.67943	274
1.67861	290
1.6778	290
1.67698	289.961
1.67617	264.853
1.67536	263.231
1.67454	262.495
1.67373	266.155
1.67292	260.101
1.67211	274.968
1.6713	269.228
1.6705	277.935
1.66969	271.513
1.66888	273.22
1.66808	266.019
1.66727	262.344
1.66647	261.14
1.66566	277.455
1.6649	258
1.66409	252
1.66329	258
1.66249	260
1.66168	254
1.66088	256
1.66008	254
1.65928	242
1.65848	236
1.65768	234
1.65688	256
1.65608	234
1.65529	256
1.65449	246
1.6537	256
1.6529	236
1.65211	236
1.65132	222
1.65053	218
1.64973	244
1.64894	242
1.64816	234
1.64737	228
1.64658	234
1.64579	242
1.64501	232
1.64422	248
1.64344	226
1.64265	218
1.64187	222
1.64109	210
1.64031	242
1.63953	210
1.63875	230
1.63797	212
1.63719	230
1.63642	216
1.63564	206
1.63486	218
1.63409	208
1.63331	202
1.63254	202
1.63177	214
1.631	202
1.63023	216
1.62946	196
1.62869	206
1.62792	206
1.62715	194
1.62639	210
1.62562	172
1.62485	202
1.62409	182
1.62333	200
1.62256	196
1.6218	188
1.62104	208
1.62028	176
1.61952	172
1.61876	174
1.618	184
1.61724	180
1.61649	184
1.61573	186
1.61498	178
1.61422	166
1.61347	196
1.61271	182
1.61196	198
1.61121	180
1.61046	180
1.60971	158
1.60896	176
1.60821	176
1.60747	156
1.60672	168
1.60597	162
1.60523	168
1.60448	162
1.60374	176
1.603	154
1.60225	166
1.60151	156
1.60077	174
1.60003	160
1.59929	166
1.59855	154
1.59782	170
1.59708	162
1.59634	150
1.59561	156
1.59487	148
1.59414	140
1.5934	156
1.59267	142
1.59194	142
1.59121	152
1.59048	156
1.58975	146
1.58902	160
1.58829	144
1.58756	140
1.58684	140
1.58611	132
1.58538	136
1.58466	116
1.58394	142
1.58321	136
1.58249	130
1.58177	132
1.58105	132
1.58033	120
1.57961	138
1.57889	138
1.57817	132
1.57745	124
1.57674	140
1.57602	123.987
1.5753	126.626
1.57459	122.903
1.57388	122.998
1.57316	118.218
1.57245	116.146
1.57174	120.44
1.57103	112.253
1.57032	120.415
1.56961	121.772
1.5689	115.017
1.56819	109.272
1.56748	109.96
1.56678	104.453
1.56607	106.164
1.56544	110
1.56473	104
1.56402	104
1.56331	104
1.56261	106
1.5619	94
1.56119	98
1.56049	88
1.55979	104
1.55908	98
1.55838	104
1.55768	102
1.55698	108
1.55628	106
1.55558	100
1.55488	104
1.55418	94
1.55348	90
1.55278	96
1.55209	90
1.55139	96
1.5507	100
1.55	90
1.54931	92
1.54862	86
1.54792	90
1.54723	88
1.54654	98
1.54585	92
1.54516	84
1.54447	76
1.54378	90
1.5431	92
1.54241	88
1.54172	84
1.54104	90
1.54035	80
1.53967	86
1.53898	86
1.5383	82
1.53762	92
1.53694	80
1.53626	74
1.53558	80
1.5349	80
1.53422	88
1.53354	76
1.53286	106
1.53218	82
1.53151	70
1.53083	82
1.53016	78
1.52948	80
1.52881	68
1.52813	82
1.52746	74
1.52679	80
1.52612	86
1.52545	74
1.52478	76
1.52411	82
1.52344	78
1.52277	86
1.5221	80
1.52144	86
1.52077	70
1.52011	68
1.51944	76
1.51878	72
1.51811	74
1.51745	80
1.51679	62
1.51613	66
1.51547	68
1.51481	72
1.51415	66
1.51349	66
1.51283	74
1.51217	68
1.51151	58
1.51086	64
1.5102	74
1.50954	60
1.50889	76
1.50824	66
1.50758	74
1.50693	64
1.50628	68
1.50563	78
1.50497	76
1.50432	66
1.50367	74
1.50302	70
1.50238	52
1.50173	66
1.50108	56
1.50043	58
1.49979	68
1.49914	62
1.4985	52
1.49785	58
1.49721	72
1.49657	56
1.49592	66
1.49528	46
1.49464	56
1.494	62
1.49336	48
1.49272	62
1.49208	66
1.49144	54
1.49081	56
1.49017	66
1.48953	62
1.4889	48
1.48826	60
1.48763	64
1.48699	50.0198
1.48636	53.6513
1.48573	56.2047
1.4851	53.2772
1.48446	59.0556
1.48383	59.1713
1.4832	53.4675
1.48257	50.0343
1.48194	46.6578
1.48132	46.9703
1.48069	50.8271
1.48006	51.1436
1.47943	45.9604
1.47881	55.876
1.47818	51.5804
1.47756	60
1.47694	46
1.47631	42
1.47568	50
1.47505	42
1.47443	46
1.4738	50
1.47318	42
1.47256	52
1.47193	50
1.47131	50
1.47069	44
1.47006	48
1.46944	50
1.46882	54
1.4682	50
1.46758	40
1.46696	54
1.46635	56
1.46573	36
1.46511	40
1.46449	38
1.46388	48
1.46326	44
1.46265	48
1.46203	44
1.46142	52
1.46081	40
1.46019	44
1.45958	42
1.45897	28
1.45836	40
1.45775	44
1.45714	42
1.45653	40
1.45592	30
1.45531	38
1.4547	32
1.4541	34
1.45349	32
1.45288	28
1.45228	34
1.45167	38
1.45107	32
1.45047	26
1.44986	24
1.44926	30
1.44866	26
1.44806	34
1.44746	28
1.44686	28
1.44626	32
1.44566	32
1.44506	26
1.44446	24
1.44386	28
1.44326	28
1.44267	32
1.44207	32
1.44148	32
1.44088	28
1.44029	28
1.43969	28
1.4391	34
1.43851	28
1.43791	28
1.43732	30
1.43673	28
1.43614	26
1.43555	24
1.43496	24
1.43437	32
1.43378	32
1.4332	32
1.43261	32
1.43202	30
1.43143	34
1.43085	30
1.43026	26
1.42968	26
1.42909	24
1.42851	26
1.42793	24
1.42734	22
1.42676	28
1.42618	40
1.4256	34
1.42502	24
1.42444	32
1.42386	24
1.42328	26
1.4227	24
1.42212	34
1.42155	22
1.42097	22
1.42039	26
1.41982	36
1.41924	34
1.41867	24
1.41809	28
1.41752	28
1.41695	36
1.41637	22
1.4158	30
1.41523	28
1.41466	26
1.41409	32
1.41352	26
1.41295	26
1.41238	24
1.41181	30
1.41124	28
1.41067	22
1.41011	34
1.40954	24
1.40897	32
1.40841	32
1.40784	28.0172
1.40728	34.2699
1.40672	32
1.40615	29.6203
1.40559	32
1.40503	38.3684
1.40446	136.663
1.4039	38.7879
1.40334	36.4403
1.40278	32.3582
1.40222	36.0674
1.40166	37.7396
1.4011	32.3599
1.40054	35.8321
1.39999	31.0989
1.39947	40
1.3989	36
1.39834	34
1.39779	46
1.39723	36
1.39667	30
1.39611	34
1.39555	34
1.395	36
1.39444	40
1.39388	28
1.39333	32
1.39277	46
1.39222	38
1.39166	42
1.39111	34
1.39056	42
1.39	32
1.38945	32
1.3889	34
1.38835	30
1.3878	36
1.38725	40
1.3867	36
1.38615	34
1.3856	34
1.38505	36
1.3845	36
1.38396	34
1.38341	36
1.38286	28
1.38232	40
1.38177	42
1.38123	38
1.38068	44
1.38014	36
1.3796	46
1.37905	40
1.37851	32
1.37797	38
1.37743	38
1.37688	44
1.37634	38
1.3758	36
1.37526	40
1.37472	34
1.37419	28
1.37365	36
1.37311	32
1.37257	42
1.37204	32
1.3715	40
1.37096	36
1.37043	26
1.36989	36
1.36936	42
1.36882	36
1.36829	34
1.36776	44
1.36722	40
1.36669	36
1.36616	26
1.36563	28
1.3651	42
1.36457	38
1.36404	32
1.36351	36
1.36298	36
1.36245	28
1.36192	34
1.36139	34
1.36087	42
1.36034	32
1.35981	40
1.35929	36
1.35876	32
1.35824	36
1.35771	38
1.35719	36
1.35667	32
1.35614	30
1.35562	28
1.3551	34
1.35458	26
1.35406	32
1.35353	36
1.35301	30
1.35249	32
1.35197	40
1.35146	34
1.35094	36
1.35042	34
1.3499	40
1.34938	34
1.34887	38
1.34835	36
1.34783	28
1.34732	28
1.3468	36
1.34629	36
1.34578	36
1.34526	34
1.34475	32
1.34424	34
1.34372	32
1.34321	32
1.3427	28
1.34219	32
1.34168	40
1.34117	32
1.34066	30
1.34015	28
1.33964	34
1.33913	38
1.33862	32
1.33812	32
1.33761	42
1.3371	30.1722
1.3366	29.8833
1.33609	32.7184
1.33558	30.3982
1.33508	31.7108
1.33457	31.9912
1.33407	32.7011
1.33357	32.075
1.33306	29.8628
1.33256	37.8331
1.33206	29.1717
1.33156	30.3127
1.33105	34.9612
1.33055	35.1781
1.33005	27.4985
1.32959	30
1.32909	32
1.32859	36
1.32809	32
1.32758	34
1.32708	28
1.32658	32
1.32608	32
1.32558	26
1.32508	32
1.32458	28
1.32408	32
1.32358	34
1.32309	30
1.32259	30
1.32209	34
1.3216	24
1.3211	36
1.3206	40
1.32011	30
1.31961	28
1.31912	38
1.31862	36
1.31813	30
1.31764	28
1.31714	30
1.31665	34
1.31616	46
1.31567	32
1.31518	30
1.31468	26
1.31419	30
1.3137	34
1.31321	38
1.31272	32
1.31224	30
1.31175	30
1.31126	40
1.31077	36
1.31028	36
1.3098	30
1.30931	32
1.30882	40
1.30834	32
1.30785	42
1.30737	28
1.30688	36
1.3064	24
1.30592	36
1.30543	32
1.30495	28
1.30447	30
1.30399	30
1.3035	36
1.30302	30
1.30254	28
1.30206	32
1.30158	28
1.3011	28
1.30062	38
1.30014	34
1.30001	36