File: Ploting/PR6S1E_01.txt
#Acq. time (s)=	5
#Accumulations=	2
#Range (cm-¹)=	200...3500
#Windows=	4
#Autofocus=	Off
#AutoExposure=	Off
#Spike filter=	Multiple accum.
#Delay time (s)=	0
#Binning=	1
#Readout mode=	Signal
#DeNoise=	Off
#ICS correction=	Off
#Dark correction=	Off
#Inst. Process=	Off
#Instrument=	LabRAM HR Evol
#Detector=	Syncerity OE
#Objective=	x100_VIS
#Grating=	600 (500nm)
#ND Filter=	100%
#Laser=	633nm_Edge
#Hole=	100.021
#Range=	Visible
#Project=	Pammela
#Sample=
#Site=	06-10-22
#Title=	PR6S1E
#Remark=
#Date=	06.10.2022 19:19
#Acquired=	06.10.2022 19:19:18
200.937	1334
204.737	1548
208.536	1948
212.332	2584
216.125	2492
219.917	1922
223.708	1406
227.496	1088
231.282	894
235.067	748
238.85	680
242.631	600
246.408	572
250.186	514
253.959	482
257.733	480
261.503	476
265.273	442
269.04	420
272.805	414
276.568	414
280.329	416
284.088	388
287.846	406
291.602	428
295.355	426
299.107	406
302.856	426
306.605	444
310.35	472
314.095	484
317.836	530
321.577	614
325.315	848
329.051	1122
332.786	890
336.518	858
340.249	744
343.978	476
347.705	430
351.43	410
355.154	388
358.874	400
362.594	382
366.311	398
370.027	408
373.74	408
377.452	406
381.163	460
384.87	572
388.576	1002
392.281	1180
395.983	608
399.684	458
403.383	408
407.08	414
410.774	746
414.467	472
418.157	390
421.847	406
425.534	362
429.221	400
432.904	386
436.585	390
440.265	352
443.943	392
447.619	378
451.294	448
454.966	504
458.637	644
462.307	1012
465.973	1114
469.638	748
473.302	548
476.963	462
480.622	420
484.28	420
487.936	412
491.59	398
495.242	402
498.892	444
502.541	1012
506.187	664
509.832	422
513.476	388
517.116	386
520.756	374
524.392	380
528.029	358
531.662	358
535.293	332
538.925	368
542.553	362
546.179	358
549.804	354
553.426	360
557.048	354
560.667	366
564.283	376
567.899	370
571.514	348
575.125	368
578.736	374
582.343	356
585.949	380
589.555	398
593.158	400
596.758	422
600.358	504
603.955	618
607.551	498
611.144	422
614.736	402
618.327	464
621.914	592
625.502	1004
629.086	990
632.67	630
636.25	512
639.83	546
643.407	644
646.983	1010
650.557	2458
654.129	1732
657.7	786
661.269	604
664.835	530
668.4	528
671.964	536
675.525	568
679.084	592
682.643	626
686.199	624
689.753	638
693.306	632
696.857	592
700.406	582
703.954	620
707.499	836
711.044	1376
714.585	628
718.126	528
721.663	546
725.201	556
728.735	556
732.268	590
735.801	550
739.33	512
742.858	500
746.384	482
749.909	464
753.43	422
756.952	432
760.471	406
763.988	396
767.504	406
771.018	414
774.531	404
778.041	400
781.549	464
785.056	506
788.561	690
792.064	1302
795.566	2758
799.066	2396
802.565	1122
806.061	754
809.556	640
813.048	566
816.54	570
820.029	634
823.518	664
827.004	666
830.488	726
833.971	1074
837.452	704
840.931	566
844.409	576
847.883	730
851.358	1066
854.831	2368
858.301	4040
861.769	1884
865.237	910
868.702	620
872.165	502
875.627	426
879.088	412
882.546	374
886.003	390
889.459	384
892.912	354
896.363	376
899.814	356
903.262	366
906.709	358
910.154	372
913.597	374
917.039	354
920.479	350
923.917	362
927.354	362
930.787	344
934.221	348
937.652	332
941.081	364
944.51	374
947.936	464
951.361	394
954.784	368
958.204	374
961.624	430
965.042	646
968.458	1140
971.873	742
975.286	478
978.697	416
982.106	388
985.514	390
988.92	384
992.325	388
995.727	402
999.128	394
1002.53	428
1005.93	456
1009.32	470
1012.72	530
1016.11	592
1019.5	524
1022.89	462
1026.28	434
1029.66	420
1033.05	424
1036.43	448
1039.81	438
1043.19	406
1046.57	404
1049.94	372
1053.32	356
1056.69	352
1060.06	324
1063.43	338
1066.8	338
1070.17	338
1073.53	346
1076.89	336
1080.26	348
1083.62	362
1086.97	342
1090.33	348
1093.69	358
1097.04	392
1100.39	534
1103.74	700
1107.09	556
1110.43	422
1113.78	364
1117.12	364
1120.46	378
1123.8	396
1127.14	370
1130.48	354
1133.81	338
1137.15	342
1140.48	346
1143.81	362
1147.14	370
1150.47	380
1153.79	400
1157.12	410
1160.44	488
1163.76	682
1167.08	2414
1170.39	2038
1173.71	634
1177.02	442
1180.34	426
1183.65	406
1186.96	424
1190.26	406
1193.57	426
1196.87	418
1200.18	426
1203.48	458
1206.78	506
1210.08	624
1213.37	740
1216.67	884
1219.96	1026
1223.25	1168
1226.54	1236
1229.83	1436
1233.12	2500
1236.4	4388
1239.69	3202
1242.97	1514
1246.25	966
1249.53	980
1252.8	1192
1256.08	1688
1259.35	1458
1262.63	854
1265.9	698
1269.17	806
1272.44	1202
1275.7	2006
1278.97	2866
1282.23	1734
1285.49	908.2
1288.75	700.825
1292.01	602.439
1295.27	579.599
1298.52	622.067
1301.77	635.947
1305.03	682.161
1308.28	716.759
1311.53	916.469
1314.77	1397.33
1318.02	2624.85
1321.26	5283.97
1324.5	6107.74
1327.75	4279.07
1330.99	2457.36
1334.22	1491.84
1337.46	1110.94
1340.69	928.256
1343.93	802.332
1347.16	726.125
1350.39	704.351
1353.62	737.663
1356.85	838.378
1360.07	1037.45
1363.29	1295.44
1366.52	1812.44
1369.74	2359.26
1372.96	2174
1376.17	1588.27
1379.39	1126.42
1382.6	874.146
1385.82	712.337
1389.03	619.894
1392.24	558.089
1395.44	530
1398.67	494
1401.89	468
1405.11	442
1408.33	440
1411.54	442
1414.76	436
1417.97	458
1421.18	476
1424.4	508
1427.6	520
1430.81	530
1434.02	564
1437.22	594
1440.43	636
1443.63	742
1446.83	784
1450.03	724
1453.22	642
1456.42	536
1459.61	490
1462.81	450
1466	422
1469.19	392
1472.38	386
1475.56	368
1478.75	356
1481.93	338
1485.11	326
1488.29	334
1491.47	338
1494.65	334
1497.83	376
1501	456
1504.17	692
1507.35	778
1510.52	526
1513.68	586
1516.85	544
1520.02	436
1523.18	396
1526.34	366
1529.5	376
1532.66	400
1535.82	414
1538.98	420
1542.13	472
1545.29	576
1548.44	700
1551.59	1036
1554.74	1562
1557.89	2182
1561.03	2324
1564.18	1864
1567.32	1366
1570.46	1006
1573.6	788
1576.74	658
1579.88	618
1583.02	584
1586.15	600
1589.28	626
1592.41	684
1595.54	876
1598.67	1158
1601.8	1638
1604.92	2460
1608.05	3920
1611.17	4102
1614.29	3472
1617.41	4434
1620.53	4274
1623.65	2404
1626.76	1424
1629.88	1186
1632.99	1220
1636.1	1494
1639.21	1916
1642.32	2620
1645.42	4078
1648.53	5088
1651.63	3426
1654.73	2264
1657.84	1696
1660.93	1118
1664.03	740
1667.13	618
1670.22	524
1673.32	446
1676.41	394
1679.5	378
1682.59	320
1685.68	298
1688.76	288
1691.85	288
1694.93	266
1698.01	276
1701.09	254
1704.17	232
1707.25	252
1710.32	250
1713.4	234
1716.47	234
1719.55	228
1722.62	228
1725.68	208
1728.75	238
1731.82	220
1734.88	228
1737.95	224
1741.01	226
1744.07	222
1747.13	210
1750.18	212
1753.24	218
1756.29	232
1759.35	218
1762.4	220
1765.45	228
1768.5	236
1771.55	216
1774.59	192
1777.64	206
1780.68	212
1783.72	206
1786.76	218
1789.8	198
1792.84	206
1795.88	198
1798.91	190
1801.94	194
1804.98	180
1808.01	212
1811.04	192
1814.06	190
1817.09	194
1820.12	202
1823.14	196
1826.16	192
1829.18	192
1832.2	194
1835.22	188
1838.24	204
1841.25	208
1844.26	200
1847.28	196
1850.29	208
1853.3	202
1856.31	178
1859.31	190
1862.32	182
1865.32	200
1868.32	192
1871.33	186
1874.33	174
1877.32	178
1880.32	196
1883.32	184
1886.31	186
1889.3	178
1892.29	180
1895.28	178
1898.27	190
1901.26	178
1904.25	196
1907.23	184
1910.21	184
1913.2	174
1916.18	166
1919.16	178
1922.13	186
1925.11	176
1928.08	170
1931.06	180
1934.03	166
1937	166
1939.97	174
1942.94	166
1945.91	194
1948.87	164
1951.83	170
1954.8	172
1957.76	170
1960.72	170
1963.68	172
1966.63	174
1969.59	162
1972.54	164
1975.5	160
1978.45	170
1981.4	152
1984.35	164
1987.3	166
1990.24	158
1993.19	168
1996.13	162
1999.07	158
2002.01	164
2004.95	162
2007.89	162
2010.83	166
2013.76	166
2016.7	164
2019.63	160
2022.56	170
2025.49	160
2028.42	172
2031.35	178
2034.27	154
2037.2	162
2040.12	160
2043.04	160
2045.96	166
2048.88	158
2051.8	162
2054.72	152
2057.63	158
2060.55	158
2063.46	156
2066.37	164
2069.28	150
2072.19	148
2075.1	158
2078	152
2080.91	158
2083.81	144
2086.71	152
2089.61	164
2092.51	166
2095.41	160
2098.31	144
2101.2	166
2104.1	142
2106.99	144
2109.88	142
2112.77	130
2115.66	144
2118.55	146
2121.43	146
2124.32	154
2127.2	144
2130.08	148
2132.96	136
2135.84	146
2138.72	126
2141.6	142
2144.47	140
2147.35	132
2150.22	130
2153.09	136
2155.96	134
2158.83	128
2161.7	134
2164.57	134
2167.43	136
2170.3	122
2173.16	132
2176.02	132
2178.88	126
2181.74	136
2184.59	142
2187.45	146
2190.3	142
2193.16	132
2196.01	142
2198.86	126
2201.71	134
2204.56	130
2207.41	136
2210.25	132
2213.1	130
2215.94	130
2218.78	130
2221.62	126
2224.46	123.87
2227.3	125.733
2230.14	125.65
2232.97	113.363
2235.8	128.318
2238.64	115.989
2241.47	116.343
2244.3	123.171
2247.13	124.089
2249.95	112.158
2252.78	114.565
2255.61	115.179
2258.43	121.009
2261.25	113.876
2264.07	118.058
2266.89	113.902
2269.71	112.609
2272.53	116.054
2275.34	116.138
2278.16	113.942
2280.97	111.292
2283.79	121.309
2286.6	113.291
2289.41	111.388
2292.22	113.634
2295.02	117.881
2297.83	124.625
2300.63	111.945
2303.44	113.346
2306.24	112.297
2309.04	108.367
2311.84	116.515
2314.64	101.994
2317.43	107.636
2320	98
2322.81	100
2325.62	112
2328.43	118
2331.23	114
2334.04	114
2336.84	104
2339.64	110
2342.44	118
2345.24	120
2348.04	100
2350.84	110
2353.63	104
2356.43	114
2359.22	110
2362.01	118
2364.8	98
2367.59	104
2370.38	108
2373.17	98
2375.95	112
2378.74	104
2381.52	102
2384.3	94
2387.08	108
2389.86	114
2392.64	112
2395.42	114
2398.2	108
2400.97	106
2403.74	106
2406.51	104
2409.29	100
2412.06	98
2414.82	100
2417.59	106
2420.36	104
2423.12	106
2425.89	102
2428.65	104
2431.41	108
2434.17	106
2436.93	112
2439.69	118
2442.44	104
2445.2	108
2447.95	114
2450.7	118
2453.45	126
2456.2	114
2458.95	132
2461.7	134
2464.45	132
2467.19	128
2469.94	130
2472.68	136
2475.42	132
2478.16	128
2480.9	126
2483.64	130
2486.37	138
2489.11	130
2491.85	118
2494.58	122
2497.31	110
2500.04	120
2502.77	112
2505.5	114
2508.23	110
2510.95	106
2513.68	118
2516.4	102
2519.12	106
2521.84	106
2524.56	104
2527.28	92
2530	98
2532.71	110
2535.43	104
2538.14	106
2540.86	110
2543.57	100
2546.28	98
2548.99	112
2551.7	112
2554.4	114
2557.11	116
2559.81	112
2562.52	102
2565.22	96
2567.92	100
2570.62	100
2573.32	94
2576.01	104
2578.71	96
2581.4	108
2584.1	110
2586.79	110
2589.48	112
2592.17	104
2594.86	106
2597.55	96
2600.23	114
2602.92	104
2605.6	104
2608.29	106
2610.97	100
2613.65	114
2616.33	102
2619.01	100
2621.68	94
2624.36	98
2627.04	104
2629.71	106
2632.38	112
2635.05	100
2637.72	98
2640.39	118
2643.06	104
2645.73	112
2648.39	104
2651.06	104
2653.72	104
2656.38	100
2659.04	100
2661.7	102
2664.36	92
2667.02	106
2669.67	100
2672.33	104
2674.98	102
2677.63	102
2680.29	104
2682.94	94
2685.58	104
2688.23	98
2690.88	108
2693.52	100
2696.17	102
2698.81	104
2701.45	108
2704.1	108
2706.74	102
2709.37	116
2712.01	104
2714.65	100
2717.28	104
2719.92	118
2722.55	102
2725.18	104
2727.81	110
2730.44	102
2733.07	102
2735.7	90
2738.32	94
2740.95	88
2743.57	102
2746.2	96
2748.82	88
2751.44	96
2754.06	82
2756.68	100
2759.29	98
2761.91	100
2764.52	98
2767.14	98
2769.75	98
2772.36	96
2774.97	96
2777.58	100
2780.19	96
2782.79	102
2785.4	102
2788	98
2790.61	98
2793.21	110
2795.81	98
2798.41	106
2801.01	86
2803.61	100
2806.2	98
2808.8	88
2811.39	98
2813.99	88
2816.58	98
2819.17	84
2821.76	92
2824.35	94
2826.93	98
2829.52	100
2832.11	106
2834.69	114
2837.27	108
2839.85	124
2842.44	124
2845.02	114
2847.59	122
2850.17	100
2852.75	122
2855.32	114
2857.9	114
2860.47	122
2863.04	114
2865.61	114
2868.18	120
2870.75	118
2873.32	120
2875.88	120
2878.45	132
2881.01	136
2883.58	140
2886.14	146
2888.7	160
2891.26	158
2893.82	160
2896.38	150
2898.93	164
2901.49	168
2904.04	192
2906.59	188
2909.15	226
2911.7	242
2914.25	250
2916.8	292
2919.34	332
2921.89	406
2924.43	494
2926.98	588
2929.52	684
2932.06	730
2934.6	658
2937.14	524
2939.68	420
2942.22	342
2944.76	292
2947.29	242
2949.83	206
2952.36	182
2954.89	170
2957.42	170
2959.95	166
2962.48	170
2965.01	154
2967.54	152
2970.06	160
2972.59	176
2975.11	164
2977.63	164
2980.15	168
2982.67	190
2985.19	188
2987.71	178
2990.23	180
2992.75	170
2995.26	158
2997.77	184
3000.29	186
3002.8	188
3005.31	180
3007.82	196
3010.33	208
3012.83	194
3015.34	168
3017.84	182
3020.35	172
3022.85	172
3025.35	172
3027.85	160
3030.35	184
3032.85	184
3035.35	194
3037.85	206
3040.34	236
3042.84	286
3045.33	329.905
3047.82	359.702
3050.31	385.961
3052.8	405.877
3055.29	424.835
3057.78	435.625
3060.27	468.576
3062.75	522.577
3065.24	532.484
3067.72	482.709
3070.2	431.671
3072.69	411.748
3075.17	394.63
3077.65	393.157
3080.12	332.373
3082.6	265.938
3085.08	224.134
3087.55	202.487
3090.03	186.967
3092.5	199.424
3094.97	205.567
3097.44	241.664
3099.91	280.05
3102.38	332.064
3104.85	291.878
3107.32	222.338
3109.78	180.603
3112.25	163.112
3114.71	150.893
3117.17	151.225
3119.64	147.503
3122.1	147.682
3124.56	148.38
3127.01	157.64
3128.88	152
3131.35	152
3133.82	158
3136.29	152
3138.76	150
3141.23	158
3143.69	160
3146.15	154
3148.62	162
3151.08	166
3153.54	162
3156	178
3158.46	172
3160.92	170
3163.37	172
3165.83	152
3168.28	174
3170.74	170
3173.19	148
3175.64	140
3178.09	144
3180.54	148
3182.99	138
3185.44	136
3187.89	132
3190.33	130
3192.77	120
3195.22	122
3197.66	140
3200.1	136
3202.54	130
3204.98	126
3207.42	120
3209.86	122
3212.29	128
3214.73	114
3217.16	122
3219.6	134
3222.03	120
3224.46	114
3226.89	120
3229.32	112
3231.75	122
3234.17	112
3236.6	102
3239.02	104
3241.45	98
3243.87	96
3246.29	102
3248.71	94
3251.13	94
3253.55	98
3255.97	80
3258.39	94
3260.8	84
3263.22	100
3265.63	92
3268.05	86
3270.46	80
3272.87	82
3275.28	86
3277.69	82
3280.1	88
3282.5	72
3284.91	86
3287.31	76
3289.72	80
3292.12	80
3294.52	74
3296.92	68
3299.32	76
3301.72	68
3304.12	64
3306.52	80
3308.91	74
3311.31	88
3313.7	86
3316.09	104
3318.48	92
3320.88	110
3323.27	106
3325.65	108
3328.04	118
3330.43	116
3332.81	102
3335.2	88
3337.58	82
3339.97	74
3342.35	78
3344.73	66
3347.11	58
3349.49	58
3351.87	58
3354.24	54
3356.62	54
3358.99	58
3361.37	58
3363.74	56
3366.11	56
3368.48	58
3370.85	54
3373.22	54
3375.59	56
3377.96	54
3380.32	54
3382.69	58
3385.05	50
3387.42	50
3389.78	56
3392.14	48
3394.5	58
3396.86	48
3399.22	54
3401.58	52
3403.93	40
3406.29	50
3408.64	44
3411	48
3413.35	52
3415.7	48
3418.05	34
3420.4	44
3422.75	42
3425.1	44
3427.44	48
3429.79	44
3432.13	48
3434.48	48
3436.82	42
3439.16	50
3441.5	48
3443.84	40
3446.18	48
3448.52	46
3450.85	44
3453.19	48
3455.52	42
3457.86	44
3460.19	40
3462.52	44
3464.86	46
3467.18	42
3469.51	38
3471.84	40
3474.17	44
3476.5	48
3478.82	32
3481.15	36
3483.47	40
3485.79	46
3488.11	42
3490.43	40
3492.75	44
3495.07	42
3497.39	38
3499.71	40