File: Ploting/test.txt
#Acq. time (s)=	3
#Accumulations=	2
#Range (eV)=	2...1
#Windows=	11
#Autofocus=	Off
#AutoExposure=	Off
#Spike filter=	Multiple accum.
#Delay time (s)=	0
#Binning=	1
#Readout mode=	Signal
#DeNoise=	Off
#ICS correction=	Off
#Dark correction=	Off
#Inst. Process=	Off
#Instrument=	LabRAM HR Evol
#Detector=	Syncerity OE
#Objective=	x10_VIS
#Grating=	600 (500nm)
#ND Filter=	3.2%
#Laser=	442nm_Notch
#Hole=	70.0087
#Range=	Visible
#Project=	Paty
#Sample=
#Site=	15-06-22
#Title=	CdSe1
#Remark=
#Date=	15.06.2022 19:18
#Acquired=	15.06.2022 19:18:49
2.79565	20
2.79332	24
2.79099	26
2.78867	26
2.78635	20
2.78404	30
2.78173	30
2.77942	32
2.77711	22
2.77482	34
2.77252	28
2.77023	34
2.76794	40
2.76566	32
2.76338	36
2.7611	36
2.75883	36
2.75656	40
2.7543	36
2.75204	34
2.74978	28
2.74753	34
2.74528	34
2.74303	40
2.74079	38
2.73855	38
2.73632	36
2.73409	44
2.73186	40
2.72964	40
2.72742	40
2.7252	40
2.72299	40
2.72078	44
2.71858	44
2.71638	46
2.71418	48
2.71199	48
2.7098	44
2.70761	40
2.70543	46
2.70325	50
2.70108	52
2.6989	50
2.69674	44
2.69457	48
2.69241	52
2.69025	56
2.6881	60
2.68595	56
2.6838	62
2.68166	56
2.67952	62
2.67739	64
2.67525	62
2.67312	70
2.671	68
2.66888	70
2.66676	58
2.66464	58
2.66253	66
2.66042	72
2.65832	68
2.65622	76
2.65412	78
2.65203	84
2.64994	86
2.64785	90
2.64576	82
2.64368	80
2.64161	88
2.63953	100
2.63746	100
2.63539	94
2.63333	94
2.63127	104
2.62921	104
2.62716	124
2.62511	122
2.62306	120
2.62102	114
2.61898	130
2.61694	122
2.61491	136
2.61287	128
2.61085	142
2.60882	150
2.6068	162
2.60478	164
2.60277	162
2.60076	166
2.59875	186
2.59675	186
2.59474	190
2.59275	190
2.59075	210
2.58876	196
2.58677	236
2.58478	228
2.5828	232
2.58082	252
2.57885	248
2.57687	262
2.5749	264
2.57294	292
2.57097	312
2.56901	294
2.56706	322
2.5651	326
2.56315	348
2.5612	360
2.55926	378
2.55731	376
2.55538	414
2.55344	392
2.55151	438
2.54958	436
2.54765	472
2.54573	474
2.54381	500
2.54189	538
2.53997	514
2.53806	548
2.53615	562
2.53425	598
2.53235	608
2.53045	630
2.52855	654
2.52666	672
2.52476	728
2.52288	722
2.52099	766
2.51911	771.667
2.51723	829.33
2.51535	829.281
2.51348	860.957
2.51161	878.248
2.50974	914.525
2.50788	917.138
2.50602	983.505
2.50416	1016.99
2.5023	1056.52
2.50045	1081.45
2.4986	1107.67
2.49675	1119.15
2.49491	1204.53
2.49307	1243.67
2.49147	1256
2.48963	1282
2.48778	1282
2.48595	1360
2.48411	1398
2.48228	1434
2.48045	1446
2.47862	1486
2.4768	1524
2.47498	1618
2.47316	1604
2.47134	1694
2.46953	1758
2.46772	1800
2.46591	1806
2.46411	1854
2.46231	1872
2.46051	1906
2.45871	2004
2.45692	2042
2.45513	2128
2.45334	2116
2.45155	2148
2.44977	2210
2.44799	2228
2.44621	2298
2.44444	2376
2.44266	2418
2.44089	2374
2.43913	2420
2.43736	2510
2.4356	2542
2.43384	2588
2.43209	2624
2.43033	2602
2.42858	2698
2.42683	2846
2.42509	2818
2.42334	2824
2.4216	2850
2.41986	2910
2.41813	2876
2.4164	2944
2.41467	2946
2.41294	2928
2.41121	3040
2.40949	3116
2.40777	3068
2.40605	3080
2.40434	3162
2.40263	3152
2.40092	3194
2.39921	3288
2.3975	3210
2.3958	3242
2.3941	3294
2.3924	3312
2.39071	3274
2.38902	3284
2.38733	3410
2.38564	3234
2.38396	3326
2.38227	3352
2.38059	3374
2.37892	3326
2.37724	3376
2.37557	3416
2.3739	3484
2.37223	3414
2.37057	3458
2.3689	3434
2.36724	3380
2.36559	3452
2.36393	3386
2.36228	3332
2.36063	3378
2.35898	3328
2.35733	3316
2.35569	3286
2.35405	3302
2.35241	3338
2.35077	3240
2.34914	3222
2.34751	3210
2.34588	3262
2.34425	3146
2.34263	3090
2.34101	3036
2.33939	3128
2.33777	3130
2.33615	3002
2.33454	3044
2.33293	3050
2.33132	2978
2.32972	2966
2.32811	2914
2.32651	2912
2.32492	2886
2.32332	2838
2.32172	2796
2.32013	2774
2.31854	2830
2.31696	2742
2.31537	2720
2.31379	2756
2.31221	2742
2.31063	2702
2.30905	2622
2.30748	2672
2.30591	2592
2.30434	2590
2.30277	2614
2.30121	2622
2.29965	2540
2.29809	2554
2.29653	2516
2.29497	2582
2.29342	2538.41
2.29187	2464.4
2.29032	2438.47
2.28877	2464.56
2.28723	2442.48
2.28568	2378.3
2.28414	2373.95
2.2826	2385.55
2.28107	2394.66
2.27954	2364.89
2.278	2340.26
2.27647	2317.11
2.27495	2301.7
2.27342	2318.65
2.2719	2295.66
2.27047	2260
2.26894	2270
2.26742	2268
2.2659	2206
2.26438	2250
2.26286	2232
2.26135	2238
2.25983	2224
2.25832	2254
2.25681	2230
2.25531	2176
2.2538	2186
2.2523	2184
2.2508	2220
2.2493	2110
2.24781	2134
2.24631	2196
2.24482	2116
2.24333	2078
2.24184	2146
2.24036	2166
2.23887	2102
2.23739	2192
2.23591	2096
2.23444	2094
2.23296	2168
2.23149	2082
2.23002	2138
2.22855	2112
2.22708	2110
2.22561	2098
2.22415	2150
2.22269	2088
2.22123	2150
2.21977	2120
2.21832	2120
2.21687	2076
2.21541	2114
2.21397	2094
2.21252	2096
2.21107	2080
2.20963	2060
2.20819	2120
2.20675	2120
2.20531	2144
2.20388	2140
2.20244	2102
2.20101	2116
2.19958	2174
2.19815	2154
2.19673	2108
2.1953	2178
2.19388	2132
2.19246	2190
2.19104	2180
2.18963	2162
2.18821	2144
2.1868	2186
2.18539	2174
2.18398	2160
2.18258	2150
2.18117	2250
2.17977	2190
2.17837	2204
2.17697	2182
2.17557	2228
2.17418	2234
2.17278	2280
2.17139	2304
2.17	2296
2.16862	2258
2.16723	2306
2.16585	2314
2.16446	2274
2.16308	2326
2.1617	2336
2.16033	2300
2.15895	2330
2.15758	2324
2.15621	2370
2.15484	2328
2.15347	2356
2.15211	2388
2.15074	2378
2.14938	2384
2.14802	2434
2.14666	2446
2.14531	2434
2.14395	2510
2.1426	2460
2.14125	2478
2.1399	2488
2.13855	2492
2.13721	2486
2.13586	2500
2.13452	2568
2.13318	2562
2.13184	2604
2.1305	2580
2.12917	2560
2.12784	2582
2.1265	2614
2.12518	2602
2.12385	2650
2.12252	2576
2.1212	2652
2.11987	2682
2.11855	2706
2.11723	2726
2.11592	2698
2.1146	2730
2.11329	2742
2.11197	2710
2.11066	2762
2.10935	2724
2.10805	2800
2.10674	2776
2.10544	2804.71
2.10414	2754.61
2.10284	2761.03
2.10154	2787.24
2.10024	2750.55
2.09894	2722.26
2.09765	2705.73
2.09636	2689.02
2.09507	2671.83
2.09378	2732.78
2.09249	2663.69
2.09121	2651.94
2.08993	2649.11
2.08864	2658.9
2.08753	2610
2.08624	2654
2.08496	2646
2.08368	2664
2.0824	2606
2.08112	2650
2.07984	2664
2.07857	2716
2.0773	2674
2.07603	2690
2.07476	2700
2.07349	2678
2.07222	2728
2.07096	2714
2.06969	2682
2.06843	2730
2.06717	2698
2.06591	2698
2.06466	2696
2.0634	2714
2.06215	2682
2.0609	2732
2.05965	2758
2.0584	2694
2.05715	2774
2.0559	2762
2.05466	2674
2.05342	2776
2.05218	2774
2.05094	2734
2.0497	2696
2.04846	2720
2.04723	2676
2.046	2692
2.04476	2768
2.04354	2718
2.04231	2714
2.04108	2658
2.03985	2704
2.03863	2682
2.03741	2668
2.03619	2770
2.03497	2716
2.03375	2714
2.03254	2714
2.03132	2732
2.03011	2692
2.0289	2746
2.02769	2768
2.02648	2726
2.02527	2730
2.02407	2770
2.02286	2754
2.02166	2802
2.02046	2774
2.01926	2760
2.01806	2806
2.01687	2818
2.01567	2846
2.01448	2804
2.01329	2766
2.0121	2818
2.01091	2838
2.00972	2866
2.00854	2868
2.00735	2854
2.00617	2884
2.00499	2934
2.00381	2888
2.00263	2900
2.00145	2876
2.00028	2996
1.9991	2954
1.99793	2884
1.99676	2968
1.99559	3014
1.99442	2944
1.99325	3016
1.99209	2958
1.99092	2946
1.98976	2966
1.9886	3000
1.98744	2976
1.98628	2976
1.98513	2984
1.98397	3016
1.98282	2998
1.98166	2986
1.98051	2988
1.97936	2996
1.97822	2978
1.97707	3012
1.97592	3052
1.97478	3056
1.97364	3040
1.9725	2978
1.97136	3016
1.97022	2974
1.96908	2960
1.96795	3008
1.96681	3012
1.96568	3072
1.96455	2968
1.96342	3004
1.96229	3056
1.96116	2966
1.96004	3066
1.95891	2936
1.95779	2998
1.95667	2986
1.95555	2984
1.95443	2974
1.95331	2980
1.95219	2964
1.95108	2986
1.94996	3010
1.94885	2912
1.94774	2950
1.94663	2972.13
1.94552	2883.86
1.94442	2949.56
1.94331	2966.91
1.94221	2928.05
1.9411	2910.99
1.94	2951.13
1.9389	2900.21
1.9378	2944.11
1.93671	2943.19
1.93561	2907
1.93452	2917.39
1.93342	2929.26
1.93233	2924.07
1.9313	2912
1.9302	2888
1.92911	2968
1.92802	2918
1.92693	2896
1.92584	2908
1.92475	2844
1.92366	2884
1.92258	2874
1.92149	2882
1.92041	2866
1.91933	2840
1.91825	2872
1.91717	2840
1.91609	2840
1.91501	2756
1.91394	2780
1.91286	2792
1.91179	2784
1.91072	2808
1.90965	2768
1.90858	2750
1.90751	2736
1.90644	2716
1.90538	2764
1.90432	2722
1.90325	2730
1.90219	2724
1.90113	2694
1.90007	2678
1.89901	2614
1.89796	2696
1.8969	2604
1.89585	2662
1.8948	2648
1.89374	2628
1.89269	2656
1.89164	2576
1.8906	2590
1.88955	2580
1.88851	2532
1.88746	2544
1.88642	2574
1.88538	2570
1.88434	2490
1.8833	2526
1.88226	2508
1.88122	2490
1.88019	2504
1.87915	2474
1.87812	2452
1.87709	2412
1.87606	2452
1.87503	2444
1.874	2462
1.87297	2376
1.87194	2398
1.87092	2338
1.8699	2422
1.86887	2372
1.86785	2318
1.86683	2334
1.86581	2354
1.8648	2326
1.86378	2308
1.86276	2292
1.86175	2284
1.86074	2260
1.85973	2274
1.85872	2264
1.85771	2210
1.8567	2238
1.85569	2220
1.85468	2158
1.85368	2194
1.85268	2198
1.85167	2158
1.85067	2180
1.84967	2172
1.84867	2182
1.84768	2112
1.84668	2136
1.84568	2098
1.84469	2040
1.8437	2052
1.8427	2076
1.84171	2112
1.84072	2070
1.83974	2030
1.83875	2026
1.83776	2022
1.83678	1990
1.83579	1974
1.83481	2008
1.83383	1966
1.83285	1994
1.83187	1930
1.83089	1982
1.82991	1942
1.82893	1854
1.82796	1892
1.82699	1874
1.82601	1910
1.82504	1852
1.82407	1838
1.8231	1852
1.82213	1836
1.82116	1852
1.8202	1746
1.81923	1830
1.81827	1774
1.81731	1786
1.81634	1752
1.81538	1734
1.81442	1716
1.81347	1778
1.81251	1748
1.81155	1734.46
1.8106	1721.1
1.80964	1691.61
1.80869	1677.51
1.80774	1693.88
1.80679	1668.09
1.80584	1656.59
1.80489	1658.63
1.80394	1693.13
1.80299	1661.09
1.80205	1639.17
1.8011	1644.71
1.80016	1609.13
1.79922	1626.41
1.79827	1608.53
1.79739	1594
1.79645	1614
1.7955	1538
1.79456	1586
1.79362	1534
1.79268	1482
1.79174	1490
1.7908	1540
1.78987	1534
1.78893	1492
1.788	1482
1.78706	1476
1.78613	1438
1.7852	1456
1.78427	1466
1.78334	1476
1.78241	1456
1.78148	1444
1.78056	1422
1.77963	1386
1.77871	1386
1.77778	1406
1.77686	1358
1.77594	1332
1.77502	1338
1.7741	1350
1.77318	1368
1.77227	1376
1.77135	1310
1.77043	1312
1.76952	1330
1.76861	1288
1.76769	1298
1.76678	1232
1.76587	1276
1.76496	1240
1.76406	1264
1.76315	1230
1.76224	1232
1.76134	1218
1.76043	1224
1.75953	1186
1.75863	1182
1.75773	1214
1.75683	1194
1.75593	1168
1.75503	1168
1.75413	1194
1.75324	1184
1.75234	1126
1.75145	1110
1.75055	1160
1.74966	1120
1.74877	1078
1.74788	1102
1.74699	1096
1.7461	1096
1.74521	1050
1.74433	1078
1.74344	1094
1.74256	1058
1.74167	1036
1.74079	1054
1.73991	1006
1.73903	990
1.73815	1018
1.73727	1014
1.73639	984
1.73551	1012
1.73464	984
1.73376	1006
1.73289	994
1.73202	948
1.73114	968
1.73027	932
1.7294	918
1.72853	922
1.72767	924
1.7268	908
1.72593	906
1.72507	896
1.7242	878
1.72334	880
1.72247	928
1.72161	858
1.72075	880
1.71989	898
1.71903	860
1.71817	873
1.71732	874
1.71646	796
1.71561	856
1.71475	836
1.7139	834
1.71305	810
1.71219	808
1.71134	804
1.71049	804
1.70964	800
1.7088	814
1.70795	778
1.7071	774
1.70626	758
1.70541	772
1.70457	762
1.70373	742
1.70288	750
1.70204	726
1.7012	688
1.70036	714
1.69953	710
1.69869	712
1.69785	734
1.69702	718
1.69618	684
1.69535	712
1.69452	688
1.69368	677.92
1.69285	676.637
1.69202	652.575
1.69119	659.783
1.69037	648.649
1.68954	653.413
1.68871	643.704
1.68789	639.741
1.68706	617.412
1.68624	619.557
1.68541	619.784
1.68459	620.883
1.68377	618.735
1.68295	614.541
1.68213	611.928
1.6814	630
1.68058	622
1.67975	626
1.67893	570
1.67811	634
1.6773	596
1.67648	592
1.67566	578
1.67484	622
1.67403	586
1.67321	584
1.6724	592
1.67159	582
1.67078	586
1.66996	578
1.66915	572
1.66834	588
1.66754	576
1.66673	564
1.66592	578
1.66511	570
1.66431	564
1.6635	576
1.6627	540
1.6619	526
1.6611	518
1.6603	546
1.6595	542
1.6587	546
1.6579	544
1.6571	526
1.6563	506
1.65551	520
1.65471	530
1.65392	522
1.65312	516
1.65233	516
1.65154	516
1.65075	502
1.64996	508
1.64917	510
1.64838	492
1.64759	494
1.6468	496
1.64602	506
1.64523	488
1.64445	490
1.64366	480
1.64288	476
1.6421	482
1.64131	458
1.64053	472
1.63975	460
1.63898	482
1.6382	464
1.63742	466
1.63664	466
1.63587	470
1.63509	462
1.63432	448
1.63354	450
1.63277	426
1.632	422
1.63123	434
1.63046	432
1.62969	406
1.62892	436
1.62815	428
1.62738	438
1.62662	414
1.62585	386
1.62509	394
1.62432	398
1.62356	398
1.6228	412
1.62204	384
1.62127	410
1.62051	402
1.61975	406
1.619	386
1.61824	376
1.61748	394
1.61672	378
1.61597	386
1.61521	386
1.61446	384
1.61371	346
1.61295	378
1.6122	376
1.61145	368
1.6107	346
1.60995	352
1.6092	334
1.60846	342
1.60771	354
1.60696	346
1.60622	336
1.60547	330
1.60473	336
1.60398	344
1.60324	330
1.6025	344
1.60176	340
1.60102	338
1.60028	320
1.59954	314
1.5988	322
1.59806	298
1.59733	312
1.59659	308
1.59586	308
1.59512	304
1.59439	294
1.59365	310
1.59292	292
1.59219	298
1.59146	296
1.59073	306.553
1.59	285.743
1.58927	273.394
1.58854	283.05
1.58782	275.409
1.58709	276.029
1.58636	275.524
1.58564	261.713
1.58492	267.712
1.58419	263.266
1.58347	260.026
1.58275	246.876
1.58203	254.205
1.58131	252.728
1.58059	241.965
1.57987	256
1.57915	252
1.57843	246
1.57771	240
1.57699	242
1.57627	244
1.57555	226
1.57483	234
1.57411	234
1.57339	236
1.57268	232
1.57196	216
1.57125	226
1.57054	226
1.56982	206
1.56911	232
1.5684	216
1.56769	208
1.56698	222
1.56627	202
1.56556	210
1.56485	208
1.56414	206
1.56343	192
1.56273	206
1.56202	202
1.56132	206
1.56061	202
1.55991	210
1.55921	192
1.5585	184
1.5578	202
1.5571	194
1.5564	198
1.5557	184
1.555	186
1.55431	188
1.55361	190
1.55291	182
1.55222	190
1.55152	182
1.55083	172
1.55013	184
1.54944	178
1.54875	176
1.54805	172
1.54736	170
1.54667	180
1.54598	170
1.54529	178
1.54461	178
1.54392	162
1.54323	164
1.54254	160
1.54186	174
1.54117	178
1.54049	178
1.5398	152
1.53912	156
1.53844	164
1.53776	180
1.53707	156
1.53639	176
1.53571	158
1.53503	150
1.53436	142
1.53368	158
1.533	162
1.53232	156
1.53165	158
1.53097	154
1.5303	154
1.52962	144
1.52895	154
1.52828	140
1.52761	154
1.52693	144
1.52626	140
1.52559	150
1.52492	142
1.52426	134
1.52359	144
1.52292	138
1.52225	142
1.52159	134
1.52092	136
1.52026	136
1.51959	148
1.51893	136
1.51826	140
1.5176	124
1.51694	134
1.51628	146
1.51562	126
1.51496	132
1.5143	134
1.51364	138
1.51298	120
1.51232	136
1.51167	128
1.51101	116
1.51036	116
1.5097	112
1.50905	120
1.50839	126
1.50774	118
1.50709	130
1.50644	138
1.50578	112
1.50513	122
1.50448	114
1.50384	126
1.50319	108
1.50254	114
1.50189	116
1.50124	128
1.5006	114
1.49995	113.293
1.49931	112.753
1.49866	107.535
1.49802	102.99
1.49738	109.426
1.49673	112.422
1.49609	107.792
1.49545	108.258
1.49481	108.883
1.49417	105.812
1.49353	104.776
1.49289	95.8424
1.49225	100.591
1.49162	98.0834
1.49104	92
1.4904	102
1.48976	108
1.48912	104
1.48848	88
1.48784	92
1.48721	100
1.48657	98
1.48593	92
1.4853	104
1.48466	92
1.48403	98
1.48339	98
1.48276	86
1.48213	80
1.4815	88
1.48087	90
1.48024	90
1.47961	90
1.47898	94
1.47835	90
1.47772	96
1.47709	90
1.47646	88
1.47584	80
1.47521	78
1.47459	78
1.47396	90
1.47334	92
1.47271	88
1.47209	84
1.47147	80
1.47084	76
1.47022	74
1.4696	76
1.46898	70
1.46836	66
1.46774	84
1.46712	88
1.46651	78
1.46589	74
1.46527	72
1.46466	62
1.46404	56
1.46342	72
1.46281	72
1.4622	76
1.46158	66
1.46097	72
1.46036	62
1.45975	58
1.45913	46
1.45852	48
1.45791	54
1.4573	50
1.4567	62
1.45609	52
1.45548	50
1.45487	34
1.45427	32
1.45366	36
1.45305	52
1.45245	40
1.45184	32
1.45124	36
1.45064	30
1.45003	24
1.44943	30
1.44883	32
1.44823	30
1.44763	24
1.44703	30
1.44643	28
1.44583	30
1.44523	22
1.44463	24
1.44404	24
1.44344	30
1.44284	28
1.44225	24
1.44165	26
1.44106	18
1.44046	32
1.43987	24
1.43928	30
1.43868	26
1.43809	34
1.4375	30
1.43691	24
1.43632	32
1.43573	28
1.43514	22
1.43455	28
1.43397	24
1.43338	30
1.43279	24
1.4322	24
1.43162	24
1.43103	30
1.43045	26
1.42986	22
1.42928	26
1.4287	28
1.42811	22
1.42753	26
1.42695	28
1.42637	30
1.42579	26
1.42521	24
1.42463	34
1.42405	28
1.42347	26
1.42289	30
1.42231	24
1.42174	26
1.42116	24
1.42059	26
1.42001	22
1.41943	27.8183
1.41886	22.5243
1.41829	25.6019
1.41771	20.859
1.41714	21.7786
1.41657	27.5593
1.416	24.6801
1.41542	24.1826
1.41485	24.4272
1.41428	25.7518
1.41371	27.0266
1.41315	25.6753
1.41258	26.8804
1.41201	24.508
1.41145	22
1.41088	20
1.41031	22
1.40974	28
1.40917	34
1.4086	42
1.40804	42
1.40747	40
1.4069	32
1.40633	36
1.40577	44
1.4052	48
1.40464	58
1.40407	58
1.40351	48
1.40295	54
1.40238	50
1.40182	46
1.40126	52
1.4007	48
1.40013	56
1.39957	54
1.39901	52
1.39845	58
1.3979	54
1.39734	54
1.39678	52
1.39622	52
1.39566	50
1.39511	56
1.39455	56
1.394	54
1.39344	60
1.39289	56
1.39233	56
1.39178	54
1.39122	58
1.39067	54
1.39012	46
1.38957	54
1.38902	58
1.38847	56
1.38792	58
1.38737	50
1.38682	48
1.38627	54
1.38572	58
1.38517	54
1.38462	58
1.38408	52
1.38353	58
1.38298	54
1.38244	56
1.38189	50
1.38135	50
1.38081	54
1.38026	60
1.37972	48
1.37918	50
1.37863	48
1.37809	50
1.37755	56
1.37701	44
1.37647	48
1.37593	54
1.37539	44
1.37485	52
1.37431	52
1.37378	42
1.37324	58
1.3727	52
1.37216	52
1.37163	54
1.37109	48
1.37056	48
1.37002	46
1.36949	50
1.36896	48
1.36842	42
1.36789	50
1.36736	54
1.36683	44
1.36629	46
1.36576	50
1.36523	50
1.3647	50
1.36417	44
1.36364	50
1.36312	48
1.36259	42
1.36206	40
1.36153	56
1.36101	48
1.36048	46
1.35995	46
1.35943	50
1.3589	42
1.35838	48
1.35785	42
1.35733	38
1.35681	48
1.35628	42
1.35576	48
1.35524	42
1.35472	42
1.3542	42
1.35368	44
1.35316	46
1.35264	44
1.35212	42
1.3516	46
1.35108	40
1.35056	42
1.35005	42
1.34953	40
1.34901	42
1.3485	40
1.34798	42
1.34747	41.7922
1.34695	38.3011
1.34644	46.2196
1.34593	47.88
1.34541	44.8437
1.3449	38.9905
1.34439	42.5943
1.34387	37.2233
1.34336	41.1701
1.34285	43.9221
1.34234	47.4296
1.34183	38.0998
1.34132	43.448
1.34081	47.4726
1.34036	38
1.33985	44
1.33934	42
1.33883	32
1.33832	48
1.33781	40
1.3373	38
1.33679	48
1.33628	44
1.33577	38
1.33527	40
1.33476	38
1.33425	40
1.33375	44
1.33324	46
1.33273	36
1.33223	48
1.33172	38
1.33122	46
1.33072	40
1.33021	32
1.32971	40
1.32921	40
1.3287	34
1.3282	38
1.3277	42
1.3272	36
1.3267	36
1.3262	44
1.3257	42
1.3252	48
1.3247	40
1.3242	40
1.3237	38
1.32321	46
1.32271	42
1.32221	40
1.32172	40
1.32122	42
1.32072	44
1.32023	40
1.31973	42
1.31924	38
1.31875	42
1.31825	32
1.31776	40
1.31727	44
1.31677	36
1.31628	36
1.31579	42
1.3153	46
1.31481	38
1.31432	34
1.31383	42
1.31334	32
1.31285	46
1.31236	44
1.31187	36
1.31139	38
1.3109	40
1.31041	40
1.30993	38
1.30944	34
1.30895	32
1.30847	42
1.30798	36
1.3075	36
1.30702	46
1.30653	44
1.30605	40
1.30557	38
1.30508	38
1.3046	40
1.30412	40
1.30364	38
1.30316	38
1.30268	38
1.3022	38
1.30172	38
1.30124	46
1.30076	42
1.30028	36
1.30001	32