File: Graficas/datosramana/CN-Sastre_08.txt
#Acq. time (s)=	20
#Accumulations=	2
#Range (cm-¹)=	50...4000
#Windows=	3
#Autofocus=	Off
#AutoExposure=	Off
#Spike filter=	Multiple accum.
#Delay time (s)=	0
#Binning=	1
#Readout mode=	Signal
#DeNoise=	Off
#ICS correction=	Off
#Dark correction=	Off
#Inst. Process=	Off
#Instrument=	LabRAM HR Evol
#Detector=	Syncerity OE
#Objective=	x100_VIS
#Grating=	600 (500nm)
#ND Filter=	100%
#Laser=	532nm_Edge
#Hole=	100.021
#Range=	Visible
#Project=	Omar
#Sample=
#Site=	21-09-22
#Title=	 CN-Sastre
#Remark=
#Date=	21.09.2022 13:05
#Acquired=	21.09.2022 13:05:14
51.0918	44
54.7807	46
58.4681	82
62.154	174
65.8385	312
69.5216	484
73.2032	806
76.8834	1144
80.5621	1448
84.2393	1706
87.9152	1928
91.5874	2026
95.2603	1946
98.9318	1926
102.602	1966
106.27	2084
109.936	2018
113.601	2044
117.266	1998
120.926	2024
124.588	1986
128.246	1936
131.904	1944
135.561	1940
139.215	1922
142.869	1902
146.52	1942
150.171	1900
153.819	1906
157.465	1888
161.112	1882
164.756	1864
168.398	1856
172.041	1816
175.68	1818
179.318	1812
182.955	1798
186.592	1778
190.225	1788
193.857	1796
197.488	1780
201.118	1750
204.746	1760
208.372	1754
211.997	1704
215.621	1722
219.243	1720
222.864	1670
226.483	1654
230.101	1658
233.718	1648
237.331	1702
240.945	1678
244.557	1682
248.168	1678
251.776	1660
255.384	1694
258.991	1652
262.594	1684
266.198	1702
269.799	1690
273.4	1668
277	1650
280.596	1664
284.193	1692
287.786	1678
291.378	1726
294.971	1706
298.561	1718
302.148	1654
305.737	1722
309.322	1726
312.906	1740
316.49	1750
320.071	1714
323.651	1706
327.229	1706
330.806	1708
334.381	1724
337.955	1688
341.528	1718
345.099	1754
348.669	1720
352.238	1720
355.805	1708
359.371	1778
362.935	1724
366.498	1760
370.06	1790
373.62	1764
377.177	1778
380.734	1790
384.29	1838
387.845	1802
391.396	1792
394.948	1836
398.499	1772
402.046	1806
405.594	1752
409.138	1790
412.683	1796
416.225	1800
419.768	1780
423.307	1784
426.844	1790
430.382	1804
433.917	1768
437.451	1814
440.985	1802
444.516	1830
448.045	1798
451.574	1786
455.102	1820
458.628	1812
462.152	1840
465.674	1812
469.196	1820
472.716	1756
476.234	1830
479.752	1776
483.268	1798
486.782	1772
490.295	1778
493.807	1754
497.316	1718
500.825	1778
504.333	1752
507.839	1714
511.344	1748
514.846	1770
518.349	1808
521.85	1792
525.347	1862
528.846	1856
532.341	1918
535.837	2058
539.329	2136
542.822	2204
546.312	2330
549.802	2346
553.289	2360
556.775	2360
560.261	2388
563.744	2398
567.226	2314
570.709	2334
574.188	2248
577.665	2266
581.142	2142
584.617	2140
588.091	2056
591.565	2036
595.036	1978
598.506	1952
601.974	1902
605.442	1840
608.905	1804
612.37	1794
615.833	1766
619.295	1700
622.755	1690
626.215	1634
629.67	1632
633.127	1632
636.582	1562
640.036	1582
643.487	1518
646.938	1540
650.386	1476
653.835	1462
657.282	1372
660.726	1360
664.171	1408
667.613	1342
671.053	1330
674.494	1298
677.931	1258
681.369	1224
684.804	1180
688.238	1196
691.67	1180
695.103	1134
698.533	1108
701.961	1136
705.389	1072
708.814	1076
712.239	1010
715.662	1026
719.084	1036
722.505	1024
725.924	972
729.342	1004
732.759	1010
736.174	994
739.589	990
742.999	1006
746.411	980
749.821	928
753.23	944
756.636	984
760.043	970
763.448	998
766.85	1036
770.252	1020
773.652	988
777.052	1054
780.448	1018
783.846	1044
787.24	1044
790.635	988
794.027	998
797.417	976
800.808	1004
804.196	1008
807.582	972
810.968	1000
814.354	942
817.736	918
821.118	958
824.498	886
827.877	878
831.254	872
834.631	814
838.006	816
841.38	856
844.752	850
848.123	806
851.493	824
854.86	784
858.228	772
861.594	786
864.959	794
868.321	820
871.683	792
875.044	806
878.402	816
881.761	820
885.116	828
888.472	842
891.825	842
895.179	804
898.529	840
901.88	864
905.228	892
908.575	924
911.922	886
915.266	880
918.609	962
921.951	954
925.293	968
928.633	962
931.97	1038
935.307	1062
938.642	1078
941.977	1118
945.31	1094
948.641	1120
951.972	1108
955.301	1160
958.629	1112
961.955	1100
965.279	1132
968.603	1106
971.926	1076
975.248	1092
978.566	1112
981.886	1114
985.204	1186
988.519	1180
991.834	1194
995.147	1176
998.46	1228
1001.77	1228
1005.08	1270
1008.39	1254
1011.7	1276
1015	1338
1018.3	1350
1021.61	1354
1024.91	1394
1028.21	1454
1031.51	1440
1034.81	1516
1038.1	1518
1041.4	1548
1044.69	1630
1047.99	1668
1051.28	1704
1054.57	1706
1057.86	1762
1061.14	1830
1064.43	1846
1067.72	1942
1071	1946
1074.28	1980
1077.57	2104
1080.84	2134
1084.12	2184
1087.4	2208
1090.68	2222
1093.95	2224
1097.22	2228
1100.5	2132
1103.77	2186
1107.04	2106
1110.31	2068
1113.58	2010
1116.84	1948
1120.1	1918
1123.37	1804
1126.63	1692
1129.89	1690
1133.15	1626
1136.41	1554
1139.67	1536
1142.92	1474
1146.18	1448
1149.43	1380
1152.68	1324
1155.93	1258
1159.18	1222
1162.43	1244
1165.68	1198
1168.93	1178
1172.17	1128
1175.41	1116
1178.66	1098
1181.9	1072
1185.14	1016
1188.37	1026
1191.61	1002
1194.85	972
1198.08	918
1201.31	928
1204.55	918
1207.78	924
1211.01	924
1214.24	882
1217.46	864
1220.69	862
1223.91	866
1227.14	842
1230.36	822
1233.58	816
1236.8	836
1240.02	824
1243.23	832
1246.45	818
1249.67	798
1252.88	814
1256.09	816
1259.3	814
1262.51	802
1265.72	794
1268.93	828
1272.13	842
1275.34	852
1278.54	870
1281.74	868
1284.94	868
1288.15	883
1291.34	898
1294.54	912
1297.74	934
1300.93	924
1304.12	928
1307.32	932
1310.51	970
1313.7	1000
1316.89	1024
1320.07	1012
1323.26	1046
1326.45	1058
1329.63	1104
1332.81	1154
1335.99	1160
1339.17	1218
1342.35	1186
1345.53	1200
1348.71	1180
1351.88	1228
1355.06	1166
1358.23	1152
1361.4	1148
1364.57	1138
1367.74	1110
1370.91	1078
1374.08	1026
1377.24	1030
1380.41	1000
1383.57	962
1386.73	968
1389.89	938
1393.05	928
1396.21	918
1399.37	920
1402.52	904
1405.68	880
1408.83	894
1411.98	910
1415.13	896
1418.29	860
1421.43	850
1424.58	846
1427.73	836
1430.87	858
1434.02	866
1437.16	858
1440.3	870
1443.44	858
1446.58	850
1449.72	864
1452.85	850
1455.99	838
1459.12	830
1462.26	802
1465.39	826
1468.52	836
1471.65	850
1474.78	822
1477.9	812
1481.03	858
1484.16	860
1487.28	836
1490.4	838
1493.52	848
1496.64	856
1499.76	854
1502.88	874
1506	866
1509.11	894
1512.22	850
1515.34	894
1518.45	884
1521.56	850
1524.67	866
1527.78	880
1530.88	906
1533.99	926
1537.09	924
1540.2	922
1543.3	928
1546.4	954
1549.5	968
1552.6	998
1555.7	1046
1558.79	1034
1561.89	1004
1564.98	1064
1568.08	1114
1571.17	1088
1574.26	1156
1577.35	1150
1580.43	1186
1583.52	1152
1586.61	1152
1589.69	1150
1592.77	1114
1595.86	1100
1598.94	1118
1602.02	1100
1605.1	1080
1608.18	1034.16
1611.25	1028.7
1614.33	1015.55
1617.4	966.921
1620.47	966.665
1623.55	930.409
1626.62	902.979
1629.69	862.701
1632.75	847.545
1635.82	856.869
1638.89	843.005
1641.95	791.935
1645.02	826.503
1648.08	814.81
1651.14	800.5
1654.2	798.175
1657.26	795.012
1660.32	808.018
1663.37	774.638
1666.43	767.784
1669.48	773.292
1672.54	770.477
1675.59	776.537
1678.64	780.118
1681.69	769.095
1684.74	750.011
1687.79	763.66
1690.83	767.992
1693.88	746.118
1696.92	751.03
1699.96	754.959
1703.01	764.924
1706.05	717.263
1709.09	725.2
1712.12	762.012
1715.16	749.808
1718.2	720.867
1721.23	756.574
1724.27	740.829
1727.3	697.546
1730.33	721.403
1733.36	729.7
1736.39	701.431
1739.42	725.482
1742.44	688.423
1745.47	738.883
1748.49	734.168
1751.52	702.377
1754.54	694.634
1757.56	696.042
1759.14	716
1762.18	680
1765.21	702
1768.24	724
1771.27	718
1774.3	676
1777.32	710
1780.35	674
1783.38	706
1786.4	716
1789.42	716
1792.44	700
1795.47	716
1798.48	716
1801.5	728
1804.52	690
1807.54	694
1810.55	714
1813.57	716
1816.58	712
1819.59	704
1822.6	706
1825.61	710
1828.62	722
1831.63	720
1834.63	720
1837.64	708
1840.64	708
1843.64	710
1846.64	708
1849.64	738
1852.64	728
1855.64	692
1858.64	704
1861.64	700
1864.63	708
1867.63	726
1870.62	720
1873.61	692
1876.6	722
1879.59	730
1882.58	732
1885.56	690
1888.55	724
1891.54	714
1894.52	708
1897.5	696
1900.48	722
1903.46	710
1906.44	714
1909.42	728
1912.4	738
1915.38	686
1918.35	738
1921.32	726
1924.3	716
1927.27	738
1930.24	718
1933.21	696
1936.18	720
1939.15	698
1942.11	718
1945.08	684
1948.04	720
1951	728
1953.97	726
1956.93	704
1959.89	694
1962.85	714
1965.8	720
1968.76	750
1971.71	696
1974.67	690
1977.62	724
1980.57	732
1983.53	730
1986.48	746
1989.42	726
1992.37	696
1995.32	712
1998.26	694
2001.21	730
2004.15	728
2007.09	708
2010.03	714
2012.98	736
2015.92	738
2018.85	702
2021.79	734
2024.73	740
2027.66	724
2030.59	754
2033.53	712
2036.46	722
2039.39	720
2042.32	738
2045.25	728
2048.17	718
2051.1	724
2054.02	744
2056.95	714
2059.87	696
2062.79	738
2065.71	732
2068.63	736
2071.55	724
2074.47	720
2077.39	758
2080.3	720
2083.22	728
2086.13	712
2089.04	736
2091.95	714
2094.86	736
2097.77	728
2100.68	740
2103.59	718
2106.49	708
2109.4	700
2112.3	712
2115.21	758
2118.11	722
2121.01	748
2123.91	716
2126.8	708
2129.7	734
2132.6	728
2135.49	712
2138.39	738
2141.28	660
2144.17	730
2147.06	718
2149.95	734
2152.84	718
2155.73	736
2158.62	714
2161.5	752
2164.39	732
2167.27	702
2170.15	710
2173.04	716
2175.92	710
2178.79	718
2181.67	730
2184.55	728
2187.43	722
2190.3	744
2193.18	726
2196.05	726
2198.92	712
2201.79	740
2204.66	716
2207.53	730
2210.4	714
2213.27	726
2216.13	710
2219	700
2221.86	694
2224.72	706
2227.59	714
2230.45	692
2233.31	712
2236.16	716
2239.02	724
2241.88	682
2244.73	722
2247.59	690
2250.44	706
2253.29	714
2256.15	706
2259	720
2261.84	714
2264.69	702
2267.54	688
2270.39	706
2273.23	690
2276.07	700
2278.92	710
2281.76	696
2284.6	682
2287.44	708
2290.28	750
2293.12	738
2295.95	728
2298.79	722
2301.62	706
2304.46	750
2307.29	744
2310.12	742
2312.95	700
2315.78	746
2318.61	750
2321.44	760
2324.27	744
2327.09	770
2329.92	780
2332.74	790
2335.56	772
2338.38	760
2341.2	770
2344.02	758
2346.84	802
2349.66	770
2352.48	782
2355.29	784
2358.11	772
2360.92	766
2363.73	794
2366.54	832
2369.35	812
2372.16	838
2374.97	850
2377.78	822
2380.58	814
2383.39	826
2386.19	834
2389	846
2391.8	846
2394.6	866
2397.4	828
2400.2	846
2403	836
2405.79	858
2408.59	864
2411.38	872
2414.18	888
2416.97	876
2419.76	874
2422.55	876
2425.34	894
2428.13	874
2430.92	864
2433.71	860
2436.49	876
2439.28	882
2442.06	872
2444.85	880
2447.63	858
2450.41	870
2453.19	898
2455.97	882
2458.75	868
2461.52	868
2464.3	846
2467.07	858
2469.85	856
2472.62	858
2475.39	872
2478.16	858
2480.94	890
2483.7	868
2486.47	866
2489.24	856
2492	830
2494.77	874
2497.53	872
2500.3	826
2503.06	844
2505.82	852
2508.58	854
2511.34	846
2514.1	868
2516.85	894
2519.61	868
2522.37	846
2525.12	890
2527.87	840
2530.63	880
2533.38	868
2536.13	866
2538.88	888
2541.62	868
2544.37	876
2547.12	864
2549.86	886
2552.61	836
2555.35	870
2558.09	906
2560.84	886
2563.57	872
2566.32	900
2569.05	896
2571.79	882
2574.53	850
2577.26	890
2580	886
2582.73	840
2585.46	900
2588.19	886
2590.93	874
2593.66	888
2596.39	868
2599.11	922
2601.84	902
2604.56	910
2607.29	908
2610.01	880
2612.74	888
2615.46	884
2618.18	884
2620.9	900
2623.62	914
2626.34	910
2629.05	918
2631.77	890
2634.48	878
2637.2	892
2639.91	928
2642.62	906
2645.33	938
2648.05	922
2650.75	932
2653.46	880
2656.17	902
2658.88	936
2661.58	924
2664.29	912
2666.99	924
2669.69	946
2672.39	922
2675.09	930
2677.79	930
2680.49	948
2683.19	950
2685.89	922
2688.58	934
2691.28	936
2693.97	938
2696.67	910
2699.36	922
2702.05	950
2704.74	902
2707.43	904
2710.12	900
2712.8	938
2715.49	968
2718.17	914
2720.86	904
2723.54	952
2726.22	944
2728.91	940
2731.59	938
2734.27	926
2736.95	954
2739.62	912
2742.3	972
2744.98	944
2747.65	948
2750.33	962
2753	946
2755.67	940
2758.34	982
2761.01	948
2763.68	972
2766.35	936
2769.02	982
2771.68	978
2774.35	958
2777.01	970
2779.68	948
2782.34	970
2785	1012
2787.66	986
2790.32	984
2792.98	962
2795.64	1022
2798.3	978
2800.95	1020
2803.61	1006
2806.26	988
2808.91	1008
2811.57	1016
2814.22	1004
2816.87	1010
2819.52	994
2822.17	1016
2824.81	992
2827.46	1032
2830.11	994
2832.75	1032
2835.39	1022
2838.04	1022
2840.68	1002
2843.32	1024
2845.96	1058
2848.6	1050
2851.24	1030
2853.88	1044
2856.51	1016
2859.15	1046
2861.78	1064
2864.42	1016
2867.05	1042
2869.68	1058
2872.31	1050
2874.94	1042
2877.57	1074
2880.2	1034
2882.82	1052
2885.45	1044
2888.08	1056
2890.7	1058
2893.33	1060
2895.95	1046
2898.57	1036
2901.19	1082
2903.81	1092
2906.43	1114
2909.05	1054
2911.66	1056
2914.28	1088
2916.89	1074
2919.51	1092.12
2922.12	1083.97
2924.73	1080.72
2927.35	1081.73
2929.96	1075.23
2932.57	1099.18
2935.17	1123.61
2937.78	1095.5
2940.39	1092.56
2943	1125.07
2945.6	1102.67
2948.2	1109.33
2950.81	1092.67
2953.41	1115.33
2956.01	1105.9
2958.61	1118.15
2961.21	1097.89
2963.81	1137.05
2966.41	1122.44
2969.01	1114
2971.6	1125.41
2974.2	1088.35
2976.79	1126.28
2979.39	1137.85
2981.98	1146.74
2984.57	1125.53
2987.16	1135.53
2989.75	1166.8
2992.34	1183.66
2994.93	1152.88
2997.51	1133.15
3000.1	1168.77
3002.68	1137.18
3005.27	1163.82
3007.85	1151.59
3010.43	1161.38
3013.01	1157.73
3015.59	1185.65
3018.18	1183.77
3020.75	1184.49
3023.33	1139.2
3025.91	1188.16
3028.48	1201.05
3031.06	1183.33
3033.64	1170.26
3036.21	1175.39
3038.78	1200.05
3041.35	1213.97
3043.92	1213.33
3046.49	1213.04
3048.11	1230
3050.69	1196
3053.27	1264
3055.85	1212
3058.43	1230
3061.01	1224
3063.58	1188
3066.16	1256
3068.73	1278
3071.31	1248
3073.88	1250
3076.45	1236
3079.02	1244
3081.59	1264
3084.16	1294
3086.73	1236
3089.29	1234
3091.86	1254
3094.43	1276
3096.99	1284
3099.55	1260
3102.12	1258
3104.68	1310
3107.24	1304
3109.8	1290
3112.36	1296
3114.92	1322
3117.48	1344
3120.03	1302
3122.59	1298
3125.14	1326
3127.7	1312
3130.25	1312
3132.8	1318
3135.35	1372
3137.9	1340
3140.45	1324
3143	1378
3145.55	1370
3148.1	1344
3150.64	1370
3153.19	1366
3155.73	1342
3158.28	1364
3160.82	1382
3163.36	1360
3165.9	1370
3168.44	1418
3170.98	1402
3173.52	1400
3176.06	1432
3178.59	1446
3181.13	1370
3183.66	1396
3186.2	1408
3188.73	1382
3191.26	1384
3193.79	1412
3196.32	1404
3198.85	1384
3201.38	1456
3203.91	1460
3206.44	1416
3208.96	1408
3211.49	1442
3214.01	1398
3216.54	1442
3219.06	1462
3221.58	1424
3224.1	1452
3226.62	1432
3229.14	1450
3231.66	1454
3234.18	1448
3236.69	1452
3239.21	1470
3241.72	1462
3244.24	1464
3246.75	1486
3249.26	1476
3251.78	1474
3254.29	1460
3256.8	1494
3259.3	1458
3261.81	1444
3264.32	1478
3266.83	1526
3269.33	1526
3271.84	1526
3274.34	1510
3276.84	1482
3279.35	1500
3281.85	1516
3284.35	1550
3286.85	1550
3289.35	1506
3291.84	1570
3294.34	1558
3296.84	1542
3299.33	1548
3301.83	1582
3304.32	1574
3306.81	1542
3309.3	1554
3311.79	1596
3314.29	1604
3316.77	1606
3319.26	1560
3321.75	1572
3324.24	1584
3326.72	1622
3329.21	1576
3331.69	1594
3334.18	1626
3336.66	1654
3339.14	1640
3341.62	1652
3344.1	1608
3346.58	1624
3349.06	1668
3351.54	1642
3354.01	1616
3356.49	1678
3358.96	1606
3361.44	1658
3363.91	1610
3366.38	1666
3368.85	1684
3371.33	1642
3373.8	1616
3376.26	1634
3378.73	1668
3381.2	1678
3383.67	1684
3386.13	1682
3388.6	1698
3391.06	1646
3393.52	1706
3395.99	1698
3398.45	1704
3400.91	1660
3403.37	1692
3405.83	1742
3408.29	1702
3410.74	1760
3413.2	1672
3415.66	1774
3418.11	1792
3420.56	1788
3423.02	1714
3425.47	1758
3427.92	1790
3430.37	1758
3432.82	1780
3435.27	1792
3437.72	1790
3440.17	1774
3442.61	1834
3445.06	1800
3447.51	1808
3449.95	1764
3452.39	1844
3454.83	1864
3457.28	1852
3459.72	1866
3462.16	1860
3464.6	1858
3467.04	1828
3469.47	1882
3471.91	1828
3474.34	1876
3476.78	1916
3479.21	1874
3481.65	1896
3484.08	1868
3486.51	1896
3488.94	1888
3491.37	1872
3493.8	1876
3496.23	1894
3498.66	1928
3501.09	1896
3503.51	1906
3505.94	1934
3508.36	1890
3510.79	1896
3513.21	1904
3515.63	1918
3518.05	1914
3520.47	1888
3522.89	1936
3525.31	1862
3527.73	1962
3530.14	1902
3532.56	1912
3534.98	1936
3537.39	1906
3539.81	1930
3542.22	1928
3544.63	1902
3547.04	1956
3549.45	1952
3551.86	1934
3554.27	1922
3556.68	1952
3559.09	1978
3561.49	1962
3563.9	1970
3566.3	1968
3568.71	1968
3571.11	2022
3573.51	1978
3575.92	1996
3578.32	1976
3580.72	2046
3583.12	2054
3585.51	1986
3587.91	2050
3590.31	2034
3592.71	2030
3595.1	2060
3597.49	2032
3599.89	2044
3602.28	2078
3604.67	2062
3607.06	2120
3609.45	2068
3611.84	2102
3614.23	2090
3616.62	2048
3619.01	2090
3621.39	2140
3623.78	2132
3626.17	2042
3628.55	2132
3630.93	2132
3633.31	2096
3635.7	2138
3638.08	2122
3640.46	2088
3642.84	2130
3645.22	2114
3647.59	2154
3649.97	2138
3652.35	2182
3654.72	2166
3657.1	2130
3659.47	2186
3661.84	2094
3664.21	2154
3666.59	2132
3668.96	2154
3671.33	2130
3673.69	2178
3676.06	2142
3678.43	2138
3680.8	2162
3683.16	2142
3685.53	2148
3687.89	2110
3690.25	2154
3692.62	2164
3694.98	2114
3697.34	2160
3699.7	2200
3702.06	2194
3704.42	2174
3706.78	2204
3709.13	2164
3711.49	2176
3713.85	2198
3716.2	2234
3718.56	2208
3720.91	2240
3723.26	2274
3725.61	2210
3727.96	2242
3730.31	2256
3732.66	2268
3735.01	2304
3737.36	2256
3739.7	2272
3742.05	2224
3744.4	2316
3746.74	2286
3749.09	2328
3751.43	2322
3753.77	2334
3756.11	2334
3758.45	2304
3760.79	2340
3763.13	2306
3765.47	2374
3767.81	2370
3770.14	2282
3772.48	2374
3774.82	2398
3777.15	2394
3779.48	2368
3781.82	2378
3784.15	2372
3786.48	2388
3788.81	2378
3791.14	2364
3793.47	2354
3795.8	2332
3798.13	2364
3800.45	2360
3802.78	2406
3805.1	2332
3807.43	2366
3809.75	2352
3812.07	2308
3814.4	2384
3816.72	2346
3819.04	2332
3821.36	2386
3823.68	2382
3826	2318
3828.31	2392
3830.63	2390
3832.95	2388
3835.26	2392
3837.58	2362
3839.89	2344
3842.2	2394
3844.51	2390
3846.83	2376
3849.14	2392
3851.45	2424
3853.76	2384
3856.06	2436
3858.37	2394
3860.68	2392
3862.98	2398
3865.29	2414
3867.59	2462
3869.9	2438
3872.2	2432
3874.5	2486
3876.8	2450
3879.1	2502
3881.4	2496
3883.7	2460
3886	2438
3888.3	2526
3890.6	2482
3892.89	2554
3895.19	2556
3897.48	2506
3899.78	2528
3902.07	2498
3904.36	2544
3906.65	2478
3908.94	2522
3911.23	2534
3913.52	2588
3915.81	2596
3918.1	2544
3920.39	2584
3922.67	2580
3924.96	2512
3927.24	2586
3929.53	2576
3931.81	2572
3934.09	2582
3936.38	2558
3938.66	2624
3940.94	2590
3943.22	2594
3945.5	2580
3947.77	2594
3950.05	2560
3952.33	2560
3954.6	2608
3956.88	2544
3959.15	2612
3961.43	2578
3963.7	2604
3965.97	2580
3968.24	2648
3970.51	2634
3972.78	2544
3975.05	2602
3977.32	2598
3979.59	2588
3981.85	2612
3984.12	2610
3986.39	2590
3988.65	2600
3990.91	2574
3993.18	2620
3995.44	2668
3997.7	2628
3999.96	2640