File: Graficas/datosramana/CN-Sastre_03.txt
#Acq. time (s)=	20
#Accumulations=	2
#Range (cm-¹)=	50...4000
#Windows=	3
#Autofocus=	Off
#AutoExposure=	Off
#Spike filter=	Multiple accum.
#Delay time (s)=	0
#Binning=	1
#Readout mode=	Signal
#DeNoise=	Off
#ICS correction=	Off
#Dark correction=	Off
#Inst. Process=	Off
#Instrument=	LabRAM HR Evol
#Detector=	Syncerity OE
#Objective=	x100_VIS
#Grating=	600 (500nm)
#ND Filter=	100%
#Laser=	532nm_Edge
#Hole=	100.021
#Range=	Visible
#Project=	Omar
#Sample=
#Site=	21-09-22
#Title=	 CN-Sastre
#Remark=
#Date=	21.09.2022 12:16
#Acquired=	21.09.2022 12:16:49
51.0918	36
54.7807	38
58.4681	72
62.154	156
65.8385	264
69.5216	418
73.2032	706
76.8834	970
80.5621	1210
84.2393	1526
87.9152	1596
91.5874	1708
95.2603	1664
98.9318	1686
102.602	1674
106.27	1788
109.936	1710
113.601	1754
117.266	1762
120.926	1736
124.588	1708
128.246	1684
131.904	1650
135.561	1664
139.215	1702
142.869	1710
146.52	1698
150.171	1646
153.819	1716
157.465	1668
161.112	1638
164.756	1638
168.398	1620
172.041	1608
175.68	1616
179.318	1596
182.955	1580
186.592	1566
190.225	1576
193.857	1584
197.488	1588
201.118	1546
204.746	1534
208.372	1478
211.997	1516
215.621	1528
219.243	1514
222.864	1524
226.483	1514
230.101	1436
233.718	1430
237.331	1466
240.945	1472
244.557	1478
248.168	1430
251.776	1480
255.384	1514
258.991	1552
262.594	1492
266.198	1510
269.799	1490
273.4	1516
277	1460
280.596	1472
284.193	1436
287.786	1480
291.378	1476
294.971	1534
298.561	1508
302.148	1512
305.737	1492
309.322	1536
312.906	1566
316.49	1532
320.071	1520
323.651	1522
327.229	1504
330.806	1524
334.381	1544
337.955	1544
341.528	1540
345.099	1534
348.669	1554
352.238	1540
355.805	1540
359.371	1562
362.935	1502
366.498	1540
370.06	1518
373.62	1572
377.177	1560
380.734	1604
384.29	1558
387.845	1566
391.396	1618
394.948	1592
398.499	1644
402.046	1578
405.594	1606
409.138	1582
412.683	1600
416.225	1554
419.768	1616
423.307	1600
426.844	1584
430.382	1574
433.917	1568
437.451	1594
440.985	1612
444.516	1600
448.045	1586
451.574	1588
455.102	1558
458.628	1626
462.152	1590
465.674	1608
469.196	1626
472.716	1590
476.234	1574
479.752	1592
483.268	1606
486.782	1542
490.295	1596
493.807	1528
497.316	1510
500.825	1548
504.333	1568
507.839	1550
511.344	1542
514.846	1520
518.349	1572
521.85	1522
525.347	1596
528.846	1652
532.341	1684
535.837	1794
539.329	1864
542.822	1920
546.312	1974
549.802	2024
553.289	2082
556.775	2120
560.261	2116
563.744	2122
567.226	2036
570.709	2058
574.188	1986
577.665	1966
581.142	1920
584.617	1922
588.091	1850
591.565	1804
595.036	1762
598.506	1752
601.974	1702
605.442	1642
608.905	1648
612.37	1626
615.833	1596
619.295	1554
622.755	1516
626.215	1424
629.67	1478
633.127	1440
636.582	1430
640.036	1390
643.487	1362
646.938	1378
650.386	1306
653.835	1310
657.282	1306
660.726	1248
664.171	1216
667.613	1160
671.053	1176
674.494	1130
677.931	1138
681.369	1050
684.804	1062
688.238	1042
691.67	1034
695.103	1010
698.533	1008
701.961	960
705.389	970
708.814	934
712.239	922
715.662	866
719.084	894
722.505	876
725.924	848
729.342	872
732.759	852
736.174	842
739.589	864
742.999	846
746.411	864
749.821	848
753.23	880
756.636	864
760.043	878
763.448	864
766.85	888
770.252	854
773.652	890
777.052	904
780.448	888
783.846	896
787.24	898
790.635	924
794.027	884
797.417	872
800.808	890
804.196	894
807.582	850
810.968	838
814.354	790
817.736	826
821.118	780
824.498	754
827.877	792
831.254	730
834.631	716
838.006	708
841.38	684
844.752	678
848.123	664
851.493	696
854.86	676
858.228	692
861.594	692
864.959	680
868.321	672
871.683	694
875.044	690
878.402	680
881.761	648
885.116	664
888.472	678
891.825	702
895.179	700
898.529	708
901.88	698
905.228	698
908.575	728
911.922	750
915.266	796
918.609	796
921.951	822
925.293	814
928.633	832
931.97	884
935.307	930
938.642	914
941.977	924
945.31	952
948.641	974
951.972	970
955.301	966
958.629	988
961.955	930
965.279	964
968.603	984
971.926	978
975.248	946
978.566	982
981.886	1056
985.204	1054
988.519	1048
991.834	1064
995.147	1042
998.46	1016
1001.77	1054
1005.08	1076
1008.39	1112
1011.7	1128
1015	1118
1018.3	1152
1021.61	1226
1024.91	1204
1028.21	1276
1031.51	1264
1034.81	1300
1038.1	1366
1041.4	1352
1044.69	1426
1047.99	1446
1051.28	1470
1054.57	1546
1057.86	1616
1061.14	1648
1064.43	1666
1067.72	1696
1071	1804
1074.28	1810
1077.57	1896
1080.84	1866
1084.12	1950
1087.4	1990
1090.68	1996
1093.95	2022
1097.22	1996
1100.5	2008
1103.77	2010
1107.04	1906
1110.31	1848
1113.58	1810
1116.84	1776
1120.1	1676
1123.37	1632
1126.63	1538
1129.89	1488
1133.15	1470
1136.41	1386
1139.67	1334
1142.92	1292
1146.18	1236
1149.43	1226
1152.68	1166
1155.93	1126
1159.18	1084
1162.43	1036
1165.68	1028
1168.93	986
1172.17	954
1175.41	936
1178.66	948
1181.9	840
1185.14	862
1188.37	866
1191.61	816
1194.85	798
1198.08	788
1201.31	788
1204.55	742
1207.78	696
1211.01	760
1214.24	696
1217.46	722
1220.69	690
1223.91	678
1227.14	672
1230.36	636
1233.58	656
1236.8	636
1240.02	646
1243.23	642
1246.45	636
1249.67	592
1252.88	622
1256.09	624
1259.3	618
1262.51	650
1265.72	582
1268.93	626
1272.13	628
1275.34	634
1278.54	622
1281.74	614
1284.94	626
1288.15	624
1291.34	648
1294.54	616
1297.74	620
1300.93	668
1304.12	648
1307.32	650
1310.51	650
1313.7	660
1316.89	632
1320.07	638
1323.26	678
1326.45	678
1329.63	622
1332.81	662
1335.99	672
1339.17	666
1342.35	682
1345.53	658
1348.71	674
1351.88	638
1355.06	714
1358.23	674
1361.4	650
1364.57	652
1367.74	660
1370.91	656
1374.08	638
1377.24	674
1380.41	632
1383.57	668
1386.73	662
1389.89	620
1393.05	644
1396.21	616
1399.37	622
1402.52	614
1405.68	644
1408.83	604
1411.98	614
1415.13	642
1418.29	654
1421.43	652
1424.58	626
1427.73	634
1430.87	636
1434.02	644
1437.16	664
1440.3	646
1443.44	628
1446.58	636
1449.72	648
1452.85	648
1455.99	638
1459.12	630
1462.26	652
1465.39	664
1468.52	650
1471.65	622
1474.78	588
1477.9	644
1481.03	638
1484.16	634
1487.28	618
1490.4	662
1493.52	648
1496.64	652
1499.76	658
1502.88	646
1506	636
1509.11	662
1512.22	648
1515.34	660
1518.45	658
1521.56	684
1524.67	644
1527.78	670
1530.88	684
1533.99	634
1537.09	670
1540.2	684
1543.3	624
1546.4	694
1549.5	708
1552.6	668
1555.7	672
1558.79	676
1561.89	692
1564.98	646
1568.08	690
1571.17	672
1574.26	670
1577.35	694
1580.43	662
1583.52	676
1586.61	692
1589.69	718
1592.77	692
1595.86	680
1598.94	682
1602.02	670
1605.1	694
1608.18	688.227
1611.25	647.288
1614.33	681.311
1617.4	603.654
1620.47	650.971
1623.55	654.604
1626.62	649.129
1629.69	630.899
1632.75	643.671
1635.82	636.078
1638.89	657.898
1641.95	618.802
1645.02	629.501
1648.08	638.746
1651.14	633.085
1654.2	630.506
1657.26	638.473
1660.32	633.79
1663.37	604.75
1666.43	620.82
1669.48	616.335
1672.54	598.72
1675.59	612.203
1678.64	604.276
1681.69	622.448
1684.74	605.591
1687.79	638.988
1690.83	605.352
1693.88	609.097
1696.92	611.931
1699.96	615.726
1703.01	602.513
1706.05	588.852
1709.09	594.323
1712.12	591.433
1715.16	583.339
1718.2	591.02
1721.23	588.631
1724.27	600.14
1727.3	595.487
1730.33	603.113
1733.36	589.392
1736.39	585.788
1739.42	596.805
1742.44	600.084
1745.47	571.648
1748.49	578.014
1751.52	564.868
1754.54	568.95
1757.56	593.321
1759.14	574
1762.18	568
1765.21	572
1768.24	568
1771.27	588
1774.3	590
1777.32	544
1780.35	566
1783.38	598
1786.4	564
1789.42	562
1792.44	560
1795.47	586
1798.48	580
1801.5	556
1804.52	570
1807.54	602
1810.55	568
1813.57	598
1816.58	580
1819.59	596
1822.6	586
1825.61	572
1828.62	562
1831.63	578
1834.63	588
1837.64	566
1840.64	554
1843.64	560
1846.64	572
1849.64	582
1852.64	564
1855.64	576
1858.64	568
1861.64	604
1864.63	558
1867.63	592
1870.62	600
1873.61	594
1876.6	606
1879.59	568
1882.58	580
1885.56	588
1888.55	586
1891.54	592
1894.52	590
1897.5	612
1900.48	588
1903.46	582
1906.44	592
1909.42	580
1912.4	590
1915.38	580
1918.35	570
1921.32	602
1924.3	576
1927.27	590
1930.24	564
1933.21	578
1936.18	582
1939.15	582
1942.11	600
1945.08	584
1948.04	578
1951	576
1953.97	596
1956.93	582
1959.89	572
1962.85	582
1965.8	580
1968.76	592
1971.71	572
1974.67	592
1977.62	580
1980.57	562
1983.53	578
1986.48	582
1989.42	604
1992.37	576
1995.32	582
1998.26	616
2001.21	596
2004.15	594
2007.09	586
2010.03	576
2012.98	570
2015.92	598
2018.85	586
2021.79	592
2024.73	608
2027.66	574
2030.59	564
2033.53	604
2036.46	588
2039.39	602
2042.32	560
2045.25	602
2048.17	602
2051.1	596
2054.02	596
2056.95	586
2059.87	596
2062.79	588
2065.71	608
2068.63	580
2071.55	596
2074.47	566
2077.39	592
2080.3	594
2083.22	598
2086.13	612
2089.04	600
2091.95	594
2094.86	562
2097.77	600
2100.68	594
2103.59	578
2106.49	606
2109.4	602
2112.3	600
2115.21	592
2118.11	586
2121.01	570
2123.91	606
2126.8	582
2129.7	604
2132.6	596
2135.49	584
2138.39	592
2141.28	590
2144.17	600
2147.06	582
2149.95	594
2152.84	598
2155.73	606
2158.62	610
2161.5	604
2164.39	592
2167.27	586
2170.15	608
2173.04	600
2175.92	618
2178.79	598
2181.67	618
2184.55	606
2187.43	602
2190.3	598
2193.18	582
2196.05	586
2198.92	598
2201.79	578
2204.66	580
2207.53	576
2210.4	588
2213.27	584
2216.13	588
2219	600
2221.86	578
2224.72	562
2227.59	588
2230.45	588
2233.31	578
2236.16	582
2239.02	576
2241.88	598
2244.73	558
2247.59	554
2250.44	600
2253.29	576
2256.15	598
2259	584
2261.84	578
2264.69	578
2267.54	594
2270.39	586
2273.23	602
2276.07	592
2278.92	594
2281.76	596
2284.6	612
2287.44	592
2290.28	592
2293.12	600
2295.95	608
2298.79	590
2301.62	608
2304.46	592
2307.29	592
2310.12	612
2312.95	608
2315.78	598
2318.61	634
2321.44	606
2324.27	628
2327.09	644
2329.92	638
2332.74	636
2335.56	636
2338.38	638
2341.2	666
2344.02	658
2346.84	654
2349.66	642
2352.48	624
2355.29	644
2358.11	674
2360.92	652
2363.73	640
2366.54	662
2369.35	690
2372.16	686
2374.97	718
2377.78	676
2380.58	690
2383.39	676
2386.19	686
2389	684
2391.8	688
2394.6	720
2397.4	722
2400.2	728
2403	714
2405.79	738
2408.59	742
2411.38	728
2414.18	732
2416.97	742
2419.76	718
2422.55	728
2425.34	762
2428.13	732
2430.92	750
2433.71	744
2436.49	726
2439.28	768
2442.06	744
2444.85	728
2447.63	714
2450.41	718
2453.19	770
2455.97	760
2458.75	744
2461.52	748
2464.3	744
2467.07	734
2469.85	710
2472.62	754
2475.39	742
2478.16	728
2480.94	730
2483.7	750
2486.47	744
2489.24	742
2492	742
2494.77	752
2497.53	736
2500.3	726
2503.06	732
2505.82	756
2508.58	750
2511.34	700
2514.1	732
2516.85	752
2519.61	732
2522.37	736
2525.12	738
2527.87	738
2530.63	726
2533.38	744
2536.13	748
2538.88	746
2541.62	736
2544.37	740
2547.12	726
2549.86	712
2552.61	718
2555.35	726
2558.09	734
2560.84	780
2563.57	724
2566.32	732
2569.05	744
2571.79	732
2574.53	738
2577.26	746
2580	738
2582.73	752
2585.46	720
2588.19	732
2590.93	712
2593.66	726
2596.39	732
2599.11	774
2601.84	750
2604.56	700
2607.29	788
2610.01	760
2612.74	788
2615.46	778
2618.18	746
2620.9	748
2623.62	762
2626.34	754
2629.05	760
2631.77	750
2634.48	762
2637.2	764
2639.91	746
2642.62	764
2645.33	778
2648.05	762
2650.75	772
2653.46	776
2656.17	782
2658.88	792
2661.58	772
2664.29	770
2666.99	782
2669.69	796
2672.39	778
2675.09	764
2677.79	780
2680.49	770
2683.19	768
2685.89	790
2688.58	782
2691.28	776
2693.97	802
2696.67	778
2699.36	794
2702.05	790
2704.74	766
2707.43	774
2710.12	778
2712.8	780
2715.49	786
2718.17	798
2720.86	786
2723.54	782
2726.22	792
2728.91	780
2731.59	796
2734.27	810
2736.95	798
2739.62	784
2742.3	796
2744.98	784
2747.65	768
2750.33	812
2753	816
2755.67	812
2758.34	826
2761.01	798
2763.68	838
2766.35	818
2769.02	812
2771.68	806
2774.35	848
2777.01	804
2779.68	800
2782.34	836
2785	816
2787.66	792
2790.32	820
2792.98	846
2795.64	840
2798.3	866
2800.95	860
2803.61	808
2806.26	852
2808.91	846
2811.57	808
2814.22	846
2816.87	838
2819.52	844
2822.17	874
2824.81	860
2827.46	844
2830.11	860
2832.75	832
2835.39	876
2838.04	866
2840.68	872
2843.32	876
2845.96	868
2848.6	862
2851.24	864
2853.88	872
2856.51	876
2859.15	882
2861.78	872
2864.42	912
2867.05	898
2869.68	904
2872.31	868
2874.94	908
2877.57	930
2880.2	914
2882.82	918
2885.45	916
2888.08	916
2890.7	890
2893.33	910
2895.95	910
2898.57	922
2901.19	954
2903.81	906
2906.43	904
2909.05	926
2911.66	886
2914.28	920
2916.89	924
2919.51	931.574
2922.12	916.334
2924.73	950.078
2927.35	922.569
2929.96	925.97
2932.57	952.246
2935.17	937.199
2937.78	952.113
2940.39	920.049
2943	960.279
2945.6	954.789
2948.2	938.151
2950.81	969.98
2953.41	967.217
2956.01	967.631
2958.61	952.327
2961.21	961.537
2963.81	931.97
2966.41	981.356
2969.01	965.565
2971.6	987.908
2974.2	975.751
2976.79	975.777
2979.39	973.418
2981.98	984.81
2984.57	986.741
2987.16	979.467
2989.75	992.288
2992.34	988.053
2994.93	977.711
2997.51	1008.26
3000.1	1003.44
3002.68	1001.27
3005.27	1009.91
3007.85	1016.53
3010.43	1010.41
3013.01	1016.95
3015.59	1008.29
3018.18	1027.12
3020.75	1026.85
3023.33	1019.88
3025.91	1041.08
3028.48	1051.99
3031.06	1032.24
3033.64	1045.37
3036.21	1033.38
3038.78	1040.17
3041.35	1052.46
3043.92	1050.85
3046.49	1040.15
3048.11	1052
3050.69	1072
3053.27	1068
3055.85	1046
3058.43	1064
3061.01	1050
3063.58	1068
3066.16	1104
3068.73	1084
3071.31	1070
3073.88	1078
3076.45	1076
3079.02	1104
3081.59	1076
3084.16	1082
3086.73	1090
3089.29	1108
3091.86	1106
3094.43	1118
3096.99	1130
3099.55	1140
3102.12	1112
3104.68	1130
3107.24	1112
3109.8	1088
3112.36	1120
3114.92	1138
3117.48	1160
3120.03	1126
3122.59	1104
3125.14	1180
3127.7	1128
3130.25	1180
3132.8	1138
3135.35	1106
3137.9	1170
3140.45	1220
3143	1182
3145.55	1184
3148.1	1188
3150.64	1178
3153.19	1204
3155.73	1196
3158.28	1192
3160.82	1208
3163.36	1162
3165.9	1218
3168.44	1196
3170.98	1256
3173.52	1250
3176.06	1186
3178.59	1212
3181.13	1242
3183.66	1248
3186.2	1212
3188.73	1250
3191.26	1258
3193.79	1242
3196.32	1222
3198.85	1214
3201.38	1248
3203.91	1242
3206.44	1250
3208.96	1252
3211.49	1256
3214.01	1230
3216.54	1252
3219.06	1250
3221.58	1298
3224.1	1274
3226.62	1302
3229.14	1288
3231.66	1302
3234.18	1308
3236.69	1300
3239.21	1236
3241.72	1272
3244.24	1320
3246.75	1278
3249.26	1312
3251.78	1292
3254.29	1314
3256.8	1328
3259.3	1322
3261.81	1332
3264.32	1338
3266.83	1356
3269.33	1340
3271.84	1316
3274.34	1328
3276.84	1354
3279.35	1318
3281.85	1370
3284.35	1336
3286.85	1348
3289.35	1368
3291.84	1384
3294.34	1344
3296.84	1380
3299.33	1380
3301.83	1402
3304.32	1366
3306.81	1380
3309.3	1396
3311.79	1392
3314.29	1398
3316.77	1408
3319.26	1418
3321.75	1412
3324.24	1450
3326.72	1424
3329.21	1480
3331.69	1414
3334.18	1434
3336.66	1442
3339.14	1470
3341.62	1486
3344.1	1446
3346.58	1472
3349.06	1436
3351.54	1466
3354.01	1480
3356.49	1498
3358.96	1454
3361.44	1496
3363.91	1502
3366.38	1446
3368.85	1474
3371.33	1466
3373.8	1446
3376.26	1468
3378.73	1518
3381.2	1520
3383.67	1484
3386.13	1522
3388.6	1512
3391.06	1514
3393.52	1514
3395.99	1512
3398.45	1508
3400.91	1490
3403.37	1524
3405.83	1540
3408.29	1536
3410.74	1546
3413.2	1548
3415.66	1548
3418.11	1558
3420.56	1530
3423.02	1556
3425.47	1558
3427.92	1612
3430.37	1550
3432.82	1518
3435.27	1610
3437.72	1616
3440.17	1620
3442.61	1574
3445.06	1618
3447.51	1616
3449.95	1660
3452.39	1622
3454.83	1644
3457.28	1658
3459.72	1638
3462.16	1684
3464.6	1642
3467.04	1628
3469.47	1662
3471.91	1712
3474.34	1656
3476.78	1692
3479.21	1724
3481.65	1696
3484.08	1696
3486.51	1684
3488.94	1684
3491.37	1674
3493.8	1696
3496.23	1718
3498.66	1714
3501.09	1694
3503.51	1710
3505.94	1692
3508.36	1688
3510.79	1680
3513.21	1706
3515.63	1690
3518.05	1702
3520.47	1718
3522.89	1738
3525.31	1694
3527.73	1684
3530.14	1714
3532.56	1690
3534.98	1714
3537.39	1740
3539.81	1718
3542.22	1752
3544.63	1740
3547.04	1700
3549.45	1734
3551.86	1728
3554.27	1744
3556.68	1766
3559.09	1742
3561.49	1750
3563.9	1798
3566.3	1752
3568.71	1794
3571.11	1764
3573.51	1794
3575.92	1806
3578.32	1814
3580.72	1816
3583.12	1788
3585.51	1820
3587.91	1864
3590.31	1864
3592.71	1838
3595.1	1838
3597.49	1892
3599.89	1858
3602.28	1878
3604.67	1878
3607.06	1868
3609.45	1832
3611.84	1870
3614.23	1854
3616.62	1892
3619.01	1878
3621.39	1916
3623.78	1894
3626.17	1902
3628.55	1906
3630.93	1906
3633.31	1922
3635.7	1922
3638.08	1890
3640.46	1934
3642.84	1886
3645.22	1884
3647.59	1890
3649.97	1934
3652.35	1920
3654.72	1924
3657.1	1958
3659.47	1918
3661.84	1886
3664.21	1928
3666.59	1934
3668.96	1906
3671.33	1930
3673.69	1912
3676.06	1966
3678.43	1938
3680.8	1942
3683.16	1924
3685.53	1968
3687.89	1972
3690.25	1948
3692.62	1972
3694.98	1948
3697.34	2004
3699.7	1972
3702.06	1936
3704.42	1994
3706.78	1954
3709.13	2004
3711.49	2016
3713.85	1978
3716.2	1970
3718.56	2022
3720.91	2006
3723.26	2028
3725.61	2022
3727.96	2026
3730.31	2026
3732.66	2018
3735.01	2060
3737.36	2094
3739.7	2044
3742.05	2064
3744.4	2066
3746.74	2086
3749.09	2048
3751.43	2104
3753.77	2104
3756.11	2100
3758.45	2122
3760.79	2132
3763.13	2082
3765.47	2126
3767.81	2080
3770.14	2116
3772.48	2166
3774.82	2130
3777.15	2122
3779.48	2130
3781.82	2120
3784.15	2164
3786.48	2138
3788.81	2164
3791.14	2150
3793.47	2162
3795.8	2152
3798.13	2136
3800.45	2198
3802.78	2148
3805.1	2142
3807.43	2154
3809.75	2150
3812.07	2134
3814.4	2158
3816.72	2158
3819.04	2112
3821.36	2178
3823.68	2180
3826	2166
3828.31	2126
3830.63	2142
3832.95	2160
3835.26	2152
3837.58	2142
3839.89	2132
3842.2	2182
3844.51	2144
3846.83	2148
3849.14	2170
3851.45	2140
3853.76	2176
3856.06	2176
3858.37	2200
3860.68	2200
3862.98	2238
3865.29	2184
3867.59	2230
3869.9	2262
3872.2	2246
3874.5	2244
3876.8	2268
3879.1	2268
3881.4	2272
3883.7	2238
3886	2288
3888.3	2262
3890.6	2266
3892.89	2318
3895.19	2298
3897.48	2254
3899.78	2294
3902.07	2294
3904.36	2302
3906.65	2318
3908.94	2350
3911.23	2378
3913.52	2332
3915.81	2332
3918.1	2334
3920.39	2336
3922.67	2426
3924.96	2312
3927.24	2354
3929.53	2402
3931.81	2354
3934.09	2298
3936.38	2394
3938.66	2358
3940.94	2352
3943.22	2380
3945.5	2390
3947.77	2382
3950.05	2354
3952.33	2378
3954.6	2368
3956.88	2384
3959.15	2368
3961.43	2380
3963.7	2366
3965.97	2330
3968.24	2382
3970.51	2360
3972.78	2358
3975.05	2334
3977.32	2338
3979.59	2354
3981.85	2346
3984.12	2338
3986.39	2394
3988.65	2342
3990.91	2382
3993.18	2372
3995.44	2332
3997.7	2376
3999.96	2366