File: Graficas/datosramana/CN-Sastre_10.txt
#Acq. time (s)=	20
#Accumulations=	2
#Range (cm-¹)=	50...4000
#Windows=	3
#Autofocus=	Off
#AutoExposure=	Off
#Spike filter=	Multiple accum.
#Delay time (s)=	0
#Binning=	1
#Readout mode=	Signal
#DeNoise=	Off
#ICS correction=	Off
#Dark correction=	Off
#Inst. Process=	Off
#Instrument=	LabRAM HR Evol
#Detector=	Syncerity OE
#Objective=	x100_VIS
#Grating=	600 (500nm)
#ND Filter=	100%
#Laser=	532nm_Edge
#Hole=	100.021
#Range=	Visible
#Project=	Omar
#Sample=
#Site=	21-09-22
#Title=	 CN-Sastre
#Remark=
#Date=	21.09.2022 13:22
#Acquired=	21.09.2022 13:22:45
51.0918	36
54.7807	54
58.4681	84
62.154	194
65.8385	312
69.5216	476
73.2032	854
76.8834	1176
80.5621	1514
84.2393	1810
87.9152	2020
91.5874	2098
95.2603	2040
98.9318	2034
102.602	2018
106.27	2092
109.936	2064
113.601	2096
117.266	2086
120.926	2076
124.588	2048
128.246	2028
131.904	1962
135.561	2002
139.215	2004
142.869	1932
146.52	1978
150.171	2008
153.819	1982
157.465	1944
161.112	1952
164.756	1908
168.398	1908
172.041	1952
175.68	1908
179.318	1894
182.955	1888
186.592	1856
190.225	1826
193.857	1846
197.488	1846
201.118	1842
204.746	1838
208.372	1788
211.997	1818
215.621	1778
219.243	1774
222.864	1728
226.483	1764
230.101	1696
233.718	1720
237.331	1638
240.945	1770
244.557	1694
248.168	1748
251.776	1710
255.384	1694
258.991	1740
262.594	1738
266.198	1686
269.799	1724
273.4	1722
277	1726
280.596	1636
284.193	1710
287.786	1712
291.378	1722
294.971	1732
298.561	1716
302.148	1718
305.737	1744
309.322	1750
312.906	1738
316.49	1758
320.071	1784
323.651	1750
327.229	1768
330.806	1804
334.381	1768
337.955	1784
341.528	1782
345.099	1818
348.669	1732
352.238	1782
355.805	1786
359.371	1792
362.935	1744
366.498	1740
370.06	1846
373.62	1848
377.177	1826
380.734	1864
384.29	1840
387.845	1872
391.396	1864
394.948	1848
398.499	1840
402.046	1838
405.594	1852
409.138	1898
412.683	1800
416.225	1814
419.768	1864
423.307	1870
426.844	1812
430.382	1846
433.917	1852
437.451	1860
440.985	1880
444.516	1880
448.045	1852
451.574	1878
455.102	1934
458.628	1880
462.152	1902
465.674	1898
469.196	1860
472.716	1860
476.234	1854
479.752	1870
483.268	1854
486.782	1826
490.295	1846
493.807	1832
497.316	1794
500.825	1844
504.333	1842
507.839	1782
511.344	1802
514.846	1826
518.349	1822
521.85	1852
525.347	1898
528.846	1998
532.341	2034
535.837	2076
539.329	2214
542.822	2282
546.312	2362
549.802	2436
553.289	2466
556.775	2530
560.261	2506
563.744	2492
567.226	2462
570.709	2448
574.188	2364
577.665	2324
581.142	2296
584.617	2192
588.091	2226
591.565	2042
595.036	2006
598.506	1992
601.974	2000
605.442	1918
608.905	1880
612.37	1836
615.833	1836
619.295	1764
622.755	1728
626.215	1712
629.67	1710
633.127	1690
636.582	1678
640.036	1598
643.487	1568
646.938	1508
650.386	1504
653.835	1498
657.282	1442
660.726	1454
664.171	1456
667.613	1414
671.053	1356
674.494	1318
677.931	1312
681.369	1306
684.804	1236
688.238	1206
691.67	1188
695.103	1138
698.533	1158
701.961	1136
705.389	1098
708.814	1078
712.239	1088
715.662	1082
719.084	1082
722.505	1022
725.924	1004
729.342	1030
732.759	1036
736.174	1018
739.589	1030
742.999	1006
746.411	1016
749.821	1022
753.23	1026
756.636	1044
760.043	978
763.448	1018
766.85	1048
770.252	1090
773.652	1054
777.052	1086
780.448	1070
783.846	1100
787.24	1070
790.635	1092
794.027	1030
797.417	1080
800.808	1010
804.196	1024
807.582	1008
810.968	1026
814.354	978
817.736	992
821.118	944
824.498	920
827.877	890
831.254	858
834.631	898
838.006	852
841.38	844
844.752	818
848.123	816
851.493	844
854.86	812
858.228	816
861.594	826
864.959	790
868.321	852
871.683	854
875.044	820
878.402	806
881.761	822
885.116	864
888.472	844
891.825	820
895.179	858
898.529	866
901.88	900
905.228	894
908.575	912
911.922	926
915.266	982
918.609	922
921.951	958
925.293	1026
928.633	1040
931.97	1050
935.307	1078
938.642	1106
941.977	1154
945.31	1132
948.641	1128
951.972	1146
955.301	1160
958.629	1130
961.955	1104
965.279	1128
968.603	1108
971.926	1152
975.248	1100
978.566	1164
981.886	1166
985.204	1208
988.519	1154
991.834	1272
995.147	1240
998.46	1228
1001.77	1254
1005.08	1234
1008.39	1304
1011.7	1280
1015	1350
1018.3	1368
1021.61	1416
1024.91	1424
1028.21	1468
1031.51	1500
1034.81	1556
1038.1	1536
1041.4	1664
1044.69	1644
1047.99	1644
1051.28	1692
1054.57	1742
1057.86	1836
1061.14	1838
1064.43	1928
1067.72	1934
1071	2036
1074.28	2090
1077.57	2124
1080.84	2206
1084.12	2228
1087.4	2240
1090.68	2266
1093.95	2292
1097.22	2254
1100.5	2254
1103.77	2218
1107.04	2136
1110.31	2140
1113.58	2010
1116.84	2026
1120.1	1896
1123.37	1856
1126.63	1776
1129.89	1748
1133.15	1626
1136.41	1612
1139.67	1466
1142.92	1452
1146.18	1398
1149.43	1390
1152.68	1296
1155.93	1320
1159.18	1266
1162.43	1230
1165.68	1184
1168.93	1150
1172.17	1140
1175.41	1092
1178.66	1082
1181.9	1054
1185.14	1036
1188.37	1010
1191.61	956
1194.85	950
1198.08	926
1201.31	944
1204.55	930
1207.78	872
1211.01	868
1214.24	854
1217.46	838
1220.69	844
1223.91	820
1227.14	794
1230.36	764
1233.58	852
1236.8	784
1240.02	782
1243.23	796
1246.45	788
1249.67	752
1252.88	756
1256.09	770
1259.3	780
1262.51	732
1265.72	798
1268.93	766
1272.13	746
1275.34	792
1278.54	740
1281.74	818
1284.94	804
1288.15	783
1291.34	776
1294.54	792
1297.74	806
1300.93	812
1304.12	762
1307.32	774
1310.51	780
1313.7	748
1316.89	776
1320.07	768
1323.26	766
1326.45	782
1329.63	800
1332.81	822
1335.99	804
1339.17	818
1342.35	832
1345.53	806
1348.71	816
1351.88	798
1355.06	794
1358.23	794
1361.4	804
1364.57	786
1367.74	772
1370.91	788
1374.08	778
1377.24	796
1380.41	772
1383.57	760
1386.73	824
1389.89	754
1393.05	784
1396.21	770
1399.37	770
1402.52	786
1405.68	808
1408.83	788
1411.98	824
1415.13	790
1418.29	788
1421.43	796
1424.58	830
1427.73	814
1430.87	788
1434.02	818
1437.16	844
1440.3	836
1443.44	812
1446.58	836
1449.72	818
1452.85	858
1455.99	814
1459.12	806
1462.26	804
1465.39	774
1468.52	808
1471.65	804
1474.78	806
1477.9	786
1481.03	790
1484.16	796
1487.28	766
1490.4	794
1493.52	816
1496.64	806
1499.76	830
1502.88	810
1506	796
1509.11	816
1512.22	836
1515.34	820
1518.45	786
1521.56	838
1524.67	830
1527.78	820
1530.88	802
1533.99	822
1537.09	802
1540.2	808
1543.3	810
1546.4	810
1549.5	806
1552.6	810
1555.7	862
1558.79	808
1561.89	818
1564.98	806
1568.08	806
1571.17	800
1574.26	822
1577.35	828
1580.43	826
1583.52	806
1586.61	838
1589.69	824
1592.77	846
1595.86	818
1598.94	814
1602.02	832
1605.1	842
1608.18	800.473
1611.25	812.184
1614.33	809.831
1617.4	813.768
1620.47	794.778
1623.55	794.5
1626.62	841.274
1629.69	769.88
1632.75	787.354
1635.82	793.809
1638.89	792.419
1641.95	781.114
1645.02	803.97
1648.08	778.001
1651.14	768.65
1654.2	765.344
1657.26	799.894
1660.32	793.643
1663.37	802.302
1666.43	778.696
1669.48	787.82
1672.54	788.814
1675.59	773.404
1678.64	767.782
1681.69	774.448
1684.74	770.709
1687.79	782.681
1690.83	753.469
1693.88	770.145
1696.92	762.608
1699.96	775.724
1703.01	756.569
1706.05	743.389
1709.09	761.275
1712.12	762.964
1715.16	756.082
1718.2	750.318
1721.23	741.178
1724.27	743.73
1727.3	762.643
1730.33	745.601
1733.36	718.716
1736.39	738.579
1739.42	731.243
1742.44	725.307
1745.47	710.527
1748.49	727.211
1751.52	705.56
1754.54	715.662
1757.56	737.429
1759.14	734
1762.18	710
1765.21	724
1768.24	702
1771.27	730
1774.3	722
1777.32	720
1780.35	732
1783.38	684
1786.4	706
1789.42	708
1792.44	736
1795.47	710
1798.48	712
1801.5	720
1804.52	730
1807.54	708
1810.55	718
1813.57	724
1816.58	718
1819.59	712
1822.6	728
1825.61	738
1828.62	714
1831.63	740
1834.63	732
1837.64	732
1840.64	714
1843.64	740
1846.64	690
1849.64	736
1852.64	744
1855.64	722
1858.64	698
1861.64	724
1864.63	700
1867.63	718
1870.62	746
1873.61	744
1876.6	720
1879.59	704
1882.58	746
1885.56	716
1888.55	744
1891.54	742
1894.52	740
1897.5	722
1900.48	720
1903.46	724
1906.44	708
1909.42	700
1912.4	744
1915.38	738
1918.35	716
1921.32	766
1924.3	730
1927.27	752
1930.24	708
1933.21	720
1936.18	722
1939.15	736
1942.11	740
1945.08	754
1948.04	724
1951	720
1953.97	726
1956.93	756
1959.89	718
1962.85	744
1965.8	710
1968.76	724
1971.71	726
1974.67	734
1977.62	696
1980.57	716
1983.53	710
1986.48	758
1989.42	734
1992.37	714
1995.32	728
1998.26	736
2001.21	700
2004.15	776
2007.09	716
2010.03	708
2012.98	750
2015.92	700
2018.85	758
2021.79	750
2024.73	720
2027.66	710
2030.59	726
2033.53	718
2036.46	754
2039.39	736
2042.32	740
2045.25	776
2048.17	728
2051.1	740
2054.02	730
2056.95	736
2059.87	718
2062.79	756
2065.71	758
2068.63	748
2071.55	740
2074.47	718
2077.39	720
2080.3	746
2083.22	742
2086.13	710
2089.04	734
2091.95	750
2094.86	752
2097.77	750
2100.68	706
2103.59	722
2106.49	702
2109.4	712
2112.3	748
2115.21	738
2118.11	736
2121.01	736
2123.91	746
2126.8	696
2129.7	700
2132.6	722
2135.49	720
2138.39	726
2141.28	708
2144.17	724
2147.06	754
2149.95	742
2152.84	742
2155.73	758
2158.62	726
2161.5	746
2164.39	750
2167.27	716
2170.15	730
2173.04	720
2175.92	756
2178.79	750
2181.67	752
2184.55	728
2187.43	742
2190.3	714
2193.18	686
2196.05	750
2198.92	762
2201.79	750
2204.66	718
2207.53	730
2210.4	718
2213.27	716
2216.13	736
2219	750
2221.86	722
2224.72	758
2227.59	730
2230.45	734
2233.31	730
2236.16	734
2239.02	734
2241.88	720
2244.73	722
2247.59	712
2250.44	750
2253.29	734
2256.15	740
2259	710
2261.84	730
2264.69	706
2267.54	690
2270.39	718
2273.23	716
2276.07	704
2278.92	730
2281.76	732
2284.6	716
2287.44	728
2290.28	748
2293.12	710
2295.95	732
2298.79	730
2301.62	738
2304.46	734
2307.29	712
2310.12	764
2312.95	738
2315.78	734
2318.61	738
2321.44	712
2324.27	762
2327.09	796
2329.92	798
2332.74	764
2335.56	770
2338.38	742
2341.2	790
2344.02	784
2346.84	782
2349.66	782
2352.48	816
2355.29	820
2358.11	810
2360.92	802
2363.73	812
2366.54	822
2369.35	814
2372.16	834
2374.97	830
2377.78	832
2380.58	834
2383.39	856
2386.19	870
2389	864
2391.8	836
2394.6	822
2397.4	884
2400.2	844
2403	846
2405.79	866
2408.59	834
2411.38	872
2414.18	868
2416.97	920
2419.76	864
2422.55	852
2425.34	874
2428.13	854
2430.92	886
2433.71	894
2436.49	874
2439.28	880
2442.06	880
2444.85	910
2447.63	860
2450.41	848
2453.19	898
2455.97	886
2458.75	882
2461.52	898
2464.3	854
2467.07	904
2469.85	872
2472.62	892
2475.39	902
2478.16	878
2480.94	864
2483.7	888
2486.47	888
2489.24	894
2492	838
2494.77	904
2497.53	884
2500.3	882
2503.06	886
2505.82	872
2508.58	888
2511.34	876
2514.1	864
2516.85	882
2519.61	870
2522.37	902
2525.12	890
2527.87	884
2530.63	862
2533.38	876
2536.13	852
2538.88	908
2541.62	880
2544.37	866
2547.12	886
2549.86	872
2552.61	872
2555.35	872
2558.09	870
2560.84	892
2563.57	866
2566.32	874
2569.05	920
2571.79	916
2574.53	896
2577.26	894
2580	888
2582.73	874
2585.46	914
2588.19	868
2590.93	860
2593.66	912
2596.39	908
2599.11	898
2601.84	894
2604.56	894
2607.29	884
2610.01	914
2612.74	904
2615.46	948
2618.18	886
2620.9	858
2623.62	920
2626.34	922
2629.05	944
2631.77	886
2634.48	948
2637.2	902
2639.91	908
2642.62	928
2645.33	874
2648.05	898
2650.75	928
2653.46	894
2656.17	944
2658.88	908
2661.58	922
2664.29	918
2666.99	914
2669.69	916
2672.39	934
2675.09	900
2677.79	912
2680.49	882
2683.19	948
2685.89	962
2688.58	902
2691.28	932
2693.97	884
2696.67	956
2699.36	922
2702.05	924
2704.74	886
2707.43	912
2710.12	876
2712.8	932
2715.49	968
2718.17	938
2720.86	962
2723.54	942
2726.22	928
2728.91	890
2731.59	944
2734.27	918
2736.95	966
2739.62	922
2742.3	954
2744.98	950
2747.65	974
2750.33	936
2753	984
2755.67	998
2758.34	974
2761.01	968
2763.68	942
2766.35	950
2769.02	958
2771.68	994
2774.35	966
2777.01	960
2779.68	964
2782.34	982
2785	982
2787.66	1020
2790.32	1004
2792.98	1008
2795.64	946
2798.3	1012
2800.95	1002
2803.61	1006
2806.26	986
2808.91	1012
2811.57	984
2814.22	962
2816.87	1046
2819.52	1024
2822.17	1022
2824.81	1020
2827.46	1016
2830.11	996
2832.75	1030
2835.39	1052
2838.04	1058
2840.68	1074
2843.32	1106
2845.96	1114
2848.6	1150
2851.24	1138
2853.88	1118
2856.51	1128
2859.15	1126
2861.78	1140
2864.42	1128
2867.05	1146
2869.68	1138
2872.31	1164
2874.94	1182
2877.57	1182
2880.2	1164
2882.82	1176
2885.45	1176
2888.08	1172
2890.7	1154
2893.33	1156
2895.95	1140
2898.57	1190
2901.19	1188
2903.81	1160
2906.43	1180
2909.05	1144
2911.66	1184
2914.28	1150
2916.89	1170
2919.51	1173.6
2922.12	1181.09
2924.73	1203.6
2927.35	1157.23
2929.96	1191.77
2932.57	1188.46
2935.17	1169.58
2937.78	1171.82
2940.39	1134.08
2943	1143.16
2945.6	1140.91
2948.2	1139.14
2950.81	1154.11
2953.41	1161.47
2956.01	1132.64
2958.61	1193.45
2961.21	1172.37
2963.81	1174.22
2966.41	1153.63
2969.01	1135.95
2971.6	1174.2
2974.2	1170.44
2976.79	1146.96
2979.39	1153.97
2981.98	1154.44
2984.57	1173.38
2987.16	1134.21
2989.75	1151.53
2992.34	1167.51
2994.93	1172.83
2997.51	1158.95
3000.1	1181.08
3002.68	1171.33
3005.27	1190.38
3007.85	1188.97
3010.43	1170.9
3013.01	1166.81
3015.59	1166.34
3018.18	1200.34
3020.75	1214.23
3023.33	1179.69
3025.91	1177.8
3028.48	1205.48
3031.06	1205.48
3033.64	1203.56
3036.21	1205.08
3038.78	1202.22
3041.35	1230.49
3043.92	1219.67
3046.49	1201.63
3048.11	1174
3050.69	1212
3053.27	1224
3055.85	1182
3058.43	1172
3061.01	1232
3063.58	1226
3066.16	1234
3068.73	1250
3071.31	1258
3073.88	1230
3076.45	1236
3079.02	1252
3081.59	1236
3084.16	1228
3086.73	1222
3089.29	1248
3091.86	1246
3094.43	1252
3096.99	1262
3099.55	1290
3102.12	1282
3104.68	1244
3107.24	1286
3109.8	1262
3112.36	1324
3114.92	1278
3117.48	1328
3120.03	1296
3122.59	1320
3125.14	1268
3127.7	1296
3130.25	1292
3132.8	1306
3135.35	1324
3137.9	1314
3140.45	1354
3143	1352
3145.55	1358
3148.1	1306
3150.64	1366
3153.19	1364
3155.73	1350
3158.28	1376
3160.82	1386
3163.36	1380
3165.9	1356
3168.44	1406
3170.98	1392
3173.52	1364
3176.06	1372
3178.59	1430
3181.13	1380
3183.66	1352
3186.2	1404
3188.73	1450
3191.26	1424
3193.79	1418
3196.32	1390
3198.85	1382
3201.38	1412
3203.91	1430
3206.44	1464
3208.96	1408
3211.49	1412
3214.01	1442
3216.54	1422
3219.06	1402
3221.58	1460
3224.1	1434
3226.62	1432
3229.14	1434
3231.66	1470
3234.18	1450
3236.69	1480
3239.21	1468
3241.72	1444
3244.24	1478
3246.75	1458
3249.26	1474
3251.78	1520
3254.29	1482
3256.8	1452
3259.3	1508
3261.81	1492
3264.32	1496
3266.83	1516
3269.33	1508
3271.84	1526
3274.34	1502
3276.84	1496
3279.35	1514
3281.85	1516
3284.35	1528
3286.85	1528
3289.35	1548
3291.84	1540
3294.34	1574
3296.84	1588
3299.33	1552
3301.83	1572
3304.32	1582
3306.81	1612
3309.3	1552
3311.79	1564
3314.29	1626
3316.77	1620
3319.26	1612
3321.75	1604
3324.24	1610
3326.72	1610
3329.21	1604
3331.69	1632
3334.18	1622
3336.66	1650
3339.14	1638
3341.62	1628
3344.1	1608
3346.58	1624
3349.06	1680
3351.54	1656
3354.01	1660
3356.49	1676
3358.96	1668
3361.44	1670
3363.91	1686
3366.38	1702
3368.85	1664
3371.33	1636
3373.8	1670
3376.26	1650
3378.73	1680
3381.2	1666
3383.67	1702
3386.13	1676
3388.6	1710
3391.06	1706
3393.52	1676
3395.99	1668
3398.45	1690
3400.91	1692
3403.37	1720
3405.83	1740
3408.29	1716
3410.74	1776
3413.2	1748
3415.66	1714
3418.11	1722
3420.56	1800
3423.02	1808
3425.47	1798
3427.92	1792
3430.37	1778
3432.82	1768
3435.27	1814
3437.72	1816
3440.17	1842
3442.61	1822
3445.06	1830
3447.51	1788
3449.95	1792
3452.39	1858
3454.83	1874
3457.28	1870
3459.72	1854
3462.16	1892
3464.6	1878
3467.04	1872
3469.47	1854
3471.91	1890
3474.34	1886
3476.78	1894
3479.21	1860
3481.65	1872
3484.08	1864
3486.51	1914
3488.94	1912
3491.37	1920
3493.8	1880
3496.23	1902
3498.66	1888
3501.09	1882
3503.51	1920
3505.94	1912
3508.36	1946
3510.79	1890
3513.21	1940
3515.63	1928
3518.05	1890
3520.47	1910
3522.89	1878
3525.31	1936
3527.73	1912
3530.14	1938
3532.56	1862
3534.98	1950
3537.39	1962
3539.81	1976
3542.22	1918
3544.63	1942
3547.04	1964
3549.45	1914
3551.86	1960
3554.27	1922
3556.68	1956
3559.09	1886
3561.49	1934
3563.9	1970
3566.3	1972
3568.71	1954
3571.11	2008
3573.51	1998
3575.92	2008
3578.32	1976
3580.72	2052
3583.12	2084
3585.51	2010
3587.91	1998
3590.31	2072
3592.71	2040
3595.1	2062
3597.49	2068
3599.89	2080
3602.28	2098
3604.67	2128
3607.06	2102
3609.45	2128
3611.84	2120
3614.23	2084
3616.62	2124
3619.01	2142
3621.39	2136
3623.78	2130
3626.17	2120
3628.55	2180
3630.93	2132
3633.31	2148
3635.7	2124
3638.08	2152
3640.46	2160
3642.84	2154
3645.22	2136
3647.59	2104
3649.97	2166
3652.35	2134
3654.72	2172
3657.1	2190
3659.47	2178
3661.84	2172
3664.21	2156
3666.59	2170
3668.96	2176
3671.33	2164
3673.69	2178
3676.06	2168
3678.43	2150
3680.8	2184
3683.16	2182
3685.53	2124
3687.89	2154
3690.25	2136
3692.62	2150
3694.98	2148
3697.34	2178
3699.7	2186
3702.06	2210
3704.42	2172
3706.78	2218
3709.13	2216
3711.49	2258
3713.85	2192
3716.2	2210
3718.56	2218
3720.91	2284
3723.26	2224
3725.61	2260
3727.96	2270
3730.31	2274
3732.66	2262
3735.01	2270
3737.36	2314
3739.7	2268
3742.05	2306
3744.4	2330
3746.74	2312
3749.09	2290
3751.43	2374
3753.77	2312
3756.11	2326
3758.45	2400
3760.79	2310
3763.13	2336
3765.47	2374
3767.81	2348
3770.14	2344
3772.48	2322
3774.82	2322
3777.15	2334
3779.48	2424
3781.82	2398
3784.15	2358
3786.48	2368
3788.81	2348
3791.14	2360
3793.47	2408
3795.8	2380
3798.13	2412
3800.45	2394
3802.78	2362
3805.1	2442
3807.43	2396
3809.75	2374
3812.07	2410
3814.4	2406
3816.72	2396
3819.04	2348
3821.36	2334
3823.68	2350
3826	2394
3828.31	2396
3830.63	2404
3832.95	2430
3835.26	2374
3837.58	2410
3839.89	2394
3842.2	2424
3844.51	2412
3846.83	2352
3849.14	2376
3851.45	2484
3853.76	2462
3856.06	2400
3858.37	2466
3860.68	2400
3862.98	2446
3865.29	2444
3867.59	2490
3869.9	2456
3872.2	2502
3874.5	2488
3876.8	2462
3879.1	2460
3881.4	2468
3883.7	2524
3886	2540
3888.3	2526
3890.6	2542
3892.89	2546
3895.19	2570
3897.48	2552
3899.78	2534
3902.07	2576
3904.36	2572
3906.65	2580
3908.94	2624
3911.23	2498
3913.52	2552
3915.81	2634
3918.1	2626
3920.39	2570
3922.67	2566
3924.96	2558
3927.24	2638
3929.53	2636
3931.81	2584
3934.09	2658
3936.38	2556
3938.66	2614
3940.94	2600
3943.22	2596
3945.5	2642
3947.77	2622
3950.05	2670
3952.33	2578
3954.6	2604
3956.88	2638
3959.15	2584
3961.43	2584
3963.7	2652
3965.97	2628
3968.24	2622
3970.51	2636
3972.78	2638
3975.05	2622
3977.32	2606
3979.59	2650
3981.85	2596
3984.12	2602
3986.39	2592
3988.65	2634
3990.91	2660
3993.18	2668
3995.44	2632
3997.7	2606
3999.96	2628