File: Graficas/datosramanb/CN-Sastre_18.txt
#Acq. time (s)=	20
#Accumulations=	2
#Range (cm-¹)=	50...4000
#Windows=	3
#Autofocus=	Off
#AutoExposure=	Off
#Spike filter=	Multiple accum.
#Delay time (s)=	0
#Binning=	1
#Readout mode=	Signal
#DeNoise=	Off
#ICS correction=	Off
#Dark correction=	Off
#Inst. Process=	Off
#Instrument=	LabRAM HR Evol
#Detector=	Syncerity OE
#Objective=	x100_VIS
#Grating=	600 (500nm)
#ND Filter=	100%
#Laser=	532nm_Edge
#Hole=	100.021
#Range=	Visible
#Project=	Omar
#Sample=
#Site=	21-09-22
#Title=	 CN-Sastre
#Remark=
#Date=	21.09.2022 14:14
#Acquired=	21.09.2022 14:14:03
51.0918	38
54.7807	52
58.4681	92
62.154	188
65.8385	300
69.5216	470
73.2032	826
76.8834	1078
80.5621	1360
84.2393	1568
87.9152	1782
91.5874	1834
95.2603	1734
98.9318	1698
102.602	1804
106.27	1882
109.936	1822
113.601	1794
117.266	1850
120.926	1824
124.588	1768
128.246	1742
131.904	1756
135.561	1746
139.215	1784
142.869	1746
146.52	1756
150.171	1774
153.819	1796
157.465	1710
161.112	1710
164.756	1760
168.398	1698
172.041	1672
175.68	1682
179.318	1658
182.955	1640
186.592	1692
190.225	1638
193.857	1650
197.488	1632
201.118	1590
204.746	1608
208.372	1620
211.997	1612
215.621	1564
219.243	1550
222.864	1548
226.483	1590
230.101	1556
233.718	1546
237.331	1566
240.945	1580
244.557	1532
248.168	1570
251.776	1542
255.384	1564
258.991	1554
262.594	1610
266.198	1572
269.799	1568
273.4	1550
277	1530
280.596	1540
284.193	1548
287.786	1594
291.378	1560
294.971	1572
298.561	1598
302.148	1586
305.737	1612
309.322	1580
312.906	1596
316.49	1602
320.071	1644
323.651	1598
327.229	1626
330.806	1630
334.381	1622
337.955	1594
341.528	1586
345.099	1624
348.669	1622
352.238	1638
355.805	1616
359.371	1626
362.935	1674
366.498	1652
370.06	1670
373.62	1652
377.177	1688
380.734	1654
384.29	1658
387.845	1722
391.396	1680
394.948	1648
398.499	1680
402.046	1690
405.594	1662
409.138	1636
412.683	1640
416.225	1696
419.768	1606
423.307	1646
426.844	1676
430.382	1660
433.917	1614
437.451	1678
440.985	1686
444.516	1706
448.045	1706
451.574	1718
455.102	1708
458.628	1672
462.152	1662
465.674	1692
469.196	1668
472.716	1652
476.234	1634
479.752	1668
483.268	1670
486.782	1642
490.295	1622
493.807	1602
497.316	1608
500.825	1626
504.333	1602
507.839	1596
511.344	1602
514.846	1624
518.349	1600
521.85	1644
525.347	1678
528.846	1728
532.341	1830
535.837	1886
539.329	1994
542.822	2106
546.312	2138
549.802	2208
553.289	2254
556.775	2250
560.261	2286
563.744	2264
567.226	2216
570.709	2156
574.188	2126
577.665	2100
581.142	2030
584.617	1962
588.091	1932
591.565	1926
595.036	1880
598.506	1862
601.974	1820
605.442	1724
608.905	1730
612.37	1676
615.833	1686
619.295	1630
622.755	1588
626.215	1536
629.67	1530
633.127	1506
636.582	1456
640.036	1446
643.487	1434
646.938	1408
650.386	1362
653.835	1306
657.282	1324
660.726	1258
664.171	1268
667.613	1254
671.053	1190
674.494	1186
677.931	1148
681.369	1150
684.804	1074
688.238	1024
691.67	1048
695.103	1016
698.533	968
701.961	982
705.389	922
708.814	898
712.239	900
715.662	854
719.084	878
722.505	844
725.924	856
729.342	806
732.759	856
736.174	874
739.589	814
742.999	848
746.411	818
749.821	834
753.23	842
756.636	878
760.043	836
763.448	892
766.85	912
770.252	880
773.652	920
777.052	882
780.448	920
783.846	916
787.24	856
790.635	890
794.027	914
797.417	866
800.808	892
804.196	864
807.582	824
810.968	818
814.354	796
817.736	786
821.118	748
824.498	750
827.877	720
831.254	740
834.631	702
838.006	640
841.38	672
844.752	640
848.123	642
851.493	654
854.86	628
858.228	652
861.594	644
864.959	626
868.321	650
871.683	646
875.044	652
878.402	674
881.761	630
885.116	648
888.472	664
891.825	672
895.179	694
898.529	650
901.88	708
905.228	732
908.575	728
911.922	700
915.266	772
918.609	792
921.951	776
925.293	780
928.633	844
931.97	854
935.307	858
938.642	916
941.977	952
945.31	898
948.641	946
951.972	980
955.301	1004
958.629	956
961.955	1002
965.279	968
968.603	968
971.926	952
975.248	996
978.566	988
981.886	1056
985.204	1022
988.519	1072
991.834	1070
995.147	1078
998.46	1066
1001.77	1080
1005.08	1094
1008.39	1102
1011.7	1148
1015	1126
1018.3	1202
1021.61	1242
1024.91	1234
1028.21	1290
1031.51	1324
1034.81	1342
1038.1	1426
1041.4	1442
1044.69	1482
1047.99	1550
1051.28	1562
1054.57	1632
1057.86	1684
1061.14	1706
1064.43	1734
1067.72	1810
1071	1850
1074.28	1934
1077.57	1974
1080.84	2020
1084.12	2050
1087.4	2066
1090.68	2110
1093.95	2116
1097.22	2122
1100.5	2084
1103.77	2042
1107.04	2008
1110.31	1930
1113.58	1906
1116.84	1756
1120.1	1738
1123.37	1692
1126.63	1524
1129.89	1482
1133.15	1460
1136.41	1398
1139.67	1374
1142.92	1322
1146.18	1246
1149.43	1220
1152.68	1162
1155.93	1152
1159.18	1078
1162.43	1084
1165.68	986
1168.93	976
1172.17	998
1175.41	948
1178.66	908
1181.9	854
1185.14	848
1188.37	776
1191.61	788
1194.85	802
1198.08	760
1201.31	720
1204.55	726
1207.78	718
1211.01	728
1214.24	710
1217.46	664
1220.69	644
1223.91	662
1227.14	566
1230.36	580
1233.58	618
1236.8	620
1240.02	600
1243.23	580
1246.45	586
1249.67	608
1252.88	598
1256.09	552
1259.3	590
1262.51	590
1265.72	600
1268.93	596
1272.13	578
1275.34	608
1278.54	598
1281.74	598
1284.94	580
1288.15	595
1291.34	588
1294.54	578
1297.74	586
1300.93	598
1304.12	634
1307.32	618
1310.51	586
1313.7	638
1316.89	640
1320.07	608
1323.26	636
1326.45	638
1329.63	610
1332.81	634
1335.99	662
1339.17	662
1342.35	664
1345.53	670
1348.71	642
1351.88	648
1355.06	646
1358.23	626
1361.4	620
1364.57	626
1367.74	628
1370.91	646
1374.08	608
1377.24	644
1380.41	586
1383.57	632
1386.73	628
1389.89	616
1393.05	590
1396.21	592
1399.37	588
1402.52	606
1405.68	606
1408.83	614
1411.98	572
1415.13	598
1418.29	592
1421.43	604
1424.58	610
1427.73	598
1430.87	606
1434.02	634
1437.16	624
1440.3	600
1443.44	600
1446.58	592
1449.72	614
1452.85	602
1455.99	596
1459.12	588
1462.26	582
1465.39	610
1468.52	598
1471.65	588
1474.78	616
1477.9	636
1481.03	602
1484.16	588
1487.28	610
1490.4	594
1493.52	616
1496.64	604
1499.76	616
1502.88	596
1506	644
1509.11	614
1512.22	624
1515.34	644
1518.45	636
1521.56	616
1524.67	626
1527.78	612
1530.88	614
1533.99	636
1537.09	612
1540.2	624
1543.3	628
1546.4	640
1549.5	630
1552.6	630
1555.7	640
1558.79	638
1561.89	636
1564.98	628
1568.08	670
1571.17	664
1574.26	658
1577.35	722
1580.43	650
1583.52	666
1586.61	672
1589.69	692
1592.77	670
1595.86	684
1598.94	638
1602.02	624
1605.1	648
1608.18	661.926
1611.25	668.53
1614.33	629.901
1617.4	625.032
1620.47	648.26
1623.55	608.175
1626.62	593.864
1629.69	631.671
1632.75	592.14
1635.82	611.921
1638.89	601.709
1641.95	616.669
1645.02	583.723
1648.08	598.354
1651.14	591.22
1654.2	585.831
1657.26	605.967
1660.32	579.208
1663.37	591.586
1666.43	604.053
1669.48	595.28
1672.54	590.987
1675.59	588.515
1678.64	569.382
1681.69	579.985
1684.74	568.003
1687.79	568.855
1690.83	566.129
1693.88	557.763
1696.92	574.152
1699.96	550.186
1703.01	577.938
1706.05	564.679
1709.09	569.117
1712.12	575.304
1715.16	556.945
1718.2	569.214
1721.23	554.477
1724.27	564.296
1727.3	562.496
1730.33	544.748
1733.36	539.096
1736.39	547.359
1739.42	532.287
1742.44	552.647
1745.47	551.732
1748.49	542.218
1751.52	540.017
1754.54	551.06
1757.56	522.186
1759.14	512
1762.18	528
1765.21	522
1768.24	540
1771.27	528
1774.3	528
1777.32	508
1780.35	510
1783.38	522
1786.4	554
1789.42	528
1792.44	542
1795.47	520
1798.48	518
1801.5	528
1804.52	534
1807.54	530
1810.55	540
1813.57	528
1816.58	508
1819.59	508
1822.6	550
1825.61	556
1828.62	552
1831.63	554
1834.63	548
1837.64	536
1840.64	546
1843.64	558
1846.64	558
1849.64	528
1852.64	542
1855.64	552
1858.64	544
1861.64	524
1864.63	528
1867.63	508
1870.62	534
1873.61	550
1876.6	550
1879.59	556
1882.58	544
1885.56	564
1888.55	538
1891.54	568
1894.52	560
1897.5	560
1900.48	548
1903.46	542
1906.44	548
1909.42	560
1912.4	556
1915.38	562
1918.35	574
1921.32	542
1924.3	550
1927.27	570
1930.24	554
1933.21	554
1936.18	536
1939.15	558
1942.11	588
1945.08	558
1948.04	536
1951	536
1953.97	538
1956.93	538
1959.89	540
1962.85	546
1965.8	554
1968.76	568
1971.71	562
1974.67	532
1977.62	532
1980.57	548
1983.53	552
1986.48	548
1989.42	544
1992.37	530
1995.32	540
1998.26	564
2001.21	536
2004.15	578
2007.09	534
2010.03	554
2012.98	558
2015.92	582
2018.85	560
2021.79	556
2024.73	574
2027.66	554
2030.59	560
2033.53	586
2036.46	544
2039.39	574
2042.32	554
2045.25	576
2048.17	576
2051.1	566
2054.02	594
2056.95	556
2059.87	566
2062.79	574
2065.71	568
2068.63	580
2071.55	584
2074.47	550
2077.39	578
2080.3	582
2083.22	578
2086.13	566
2089.04	586
2091.95	540
2094.86	570
2097.77	578
2100.68	562
2103.59	560
2106.49	574
2109.4	558
2112.3	562
2115.21	556
2118.11	570
2121.01	572
2123.91	556
2126.8	570
2129.7	568
2132.6	568
2135.49	558
2138.39	564
2141.28	554
2144.17	572
2147.06	540
2149.95	532
2152.84	538
2155.73	582
2158.62	558
2161.5	568
2164.39	568
2167.27	580
2170.15	566
2173.04	558
2175.92	586
2178.79	582
2181.67	584
2184.55	598
2187.43	570
2190.3	586
2193.18	590
2196.05	580
2198.92	576
2201.79	588
2204.66	568
2207.53	576
2210.4	534
2213.27	574
2216.13	586
2219	540
2221.86	560
2224.72	576
2227.59	570
2230.45	566
2233.31	574
2236.16	562
2239.02	568
2241.88	556
2244.73	564
2247.59	574
2250.44	550
2253.29	556
2256.15	554
2259	570
2261.84	566
2264.69	552
2267.54	570
2270.39	544
2273.23	560
2276.07	560
2278.92	586
2281.76	570
2284.6	582
2287.44	576
2290.28	592
2293.12	572
2295.95	582
2298.79	580
2301.62	588
2304.46	598
2307.29	598
2310.12	596
2312.95	610
2315.78	602
2318.61	624
2321.44	590
2324.27	616
2327.09	640
2329.92	618
2332.74	626
2335.56	624
2338.38	620
2341.2	624
2344.02	638
2346.84	648
2349.66	650
2352.48	644
2355.29	638
2358.11	652
2360.92	696
2363.73	674
2366.54	684
2369.35	664
2372.16	688
2374.97	680
2377.78	710
2380.58	716
2383.39	714
2386.19	704
2389	678
2391.8	686
2394.6	726
2397.4	706
2400.2	750
2403	732
2405.79	714
2408.59	712
2411.38	736
2414.18	698
2416.97	732
2419.76	738
2422.55	744
2425.34	740
2428.13	742
2430.92	734
2433.71	782
2436.49	738
2439.28	730
2442.06	748
2444.85	764
2447.63	746
2450.41	740
2453.19	766
2455.97	710
2458.75	716
2461.52	760
2464.3	746
2467.07	716
2469.85	718
2472.62	722
2475.39	738
2478.16	726
2480.94	750
2483.7	740
2486.47	722
2489.24	758
2492	716
2494.77	748
2497.53	746
2500.3	710
2503.06	704
2505.82	750
2508.58	730
2511.34	736
2514.1	734
2516.85	702
2519.61	754
2522.37	758
2525.12	752
2527.87	746
2530.63	770
2533.38	756
2536.13	768
2538.88	714
2541.62	722
2544.37	730
2547.12	720
2549.86	732
2552.61	754
2555.35	736
2558.09	746
2560.84	756
2563.57	748
2566.32	756
2569.05	752
2571.79	750
2574.53	734
2577.26	750
2580	748
2582.73	732
2585.46	716
2588.19	746
2590.93	766
2593.66	754
2596.39	780
2599.11	754
2601.84	766
2604.56	762
2607.29	758
2610.01	722
2612.74	762
2615.46	760
2618.18	788
2620.9	804
2623.62	748
2626.34	748
2629.05	782
2631.77	740
2634.48	782
2637.2	810
2639.91	796
2642.62	762
2645.33	764
2648.05	782
2650.75	780
2653.46	786
2656.17	794
2658.88	778
2661.58	784
2664.29	798
2666.99	786
2669.69	782
2672.39	790
2675.09	804
2677.79	796
2680.49	770
2683.19	814
2685.89	784
2688.58	774
2691.28	784
2693.97	806
2696.67	788
2699.36	774
2702.05	804
2704.74	784
2707.43	810
2710.12	808
2712.8	786
2715.49	806
2718.17	792
2720.86	812
2723.54	814
2726.22	804
2728.91	800
2731.59	836
2734.27	832
2736.95	838
2739.62	804
2742.3	788
2744.98	822
2747.65	842
2750.33	818
2753	788
2755.67	832
2758.34	844
2761.01	834
2763.68	820
2766.35	838
2769.02	852
2771.68	858
2774.35	848
2777.01	866
2779.68	856
2782.34	852
2785	828
2787.66	870
2790.32	848
2792.98	868
2795.64	822
2798.3	856
2800.95	870
2803.61	872
2806.26	862
2808.91	842
2811.57	900
2814.22	862
2816.87	892
2819.52	878
2822.17	878
2824.81	908
2827.46	894
2830.11	884
2832.75	888
2835.39	896
2838.04	920
2840.68	914
2843.32	890
2845.96	886
2848.6	912
2851.24	906
2853.88	904
2856.51	922
2859.15	900
2861.78	906
2864.42	902
2867.05	906
2869.68	928
2872.31	916
2874.94	912
2877.57	910
2880.2	960
2882.82	932
2885.45	964
2888.08	952
2890.7	956
2893.33	950
2895.95	970
2898.57	958
2901.19	968
2903.81	984
2906.43	968
2909.05	974
2911.66	950
2914.28	964
2916.89	930
2919.51	985.275
2922.12	948.698
2924.73	986.827
2927.35	993.081
2929.96	973.594
2932.57	1010.79
2935.17	962.756
2937.78	966.939
2940.39	988.789
2943	999.658
2945.6	979.872
2948.2	1001.53
2950.81	982.446
2953.41	1017.6
2956.01	970.852
2958.61	998.237
2961.21	995.685
2963.81	1020.88
2966.41	1018.62
2969.01	988.26
2971.6	994.835
2974.2	1024.22
2976.79	1006.59
2979.39	1010.47
2981.98	1028.86
2984.57	1016.83
2987.16	1040.17
2989.75	1051.48
2992.34	1047.04
2994.93	1030.68
2997.51	1066.27
3000.1	1064.39
3002.68	1038.47
3005.27	1058.36
3007.85	1040.81
3010.43	1050.36
3013.01	1055.48
3015.59	1057.63
3018.18	1063.25
3020.75	1090.69
3023.33	1087.25
3025.91	1075.39
3028.48	1070.17
3031.06	1088.04
3033.64	1085.46
3036.21	1080.24
3038.78	1101.07
3041.35	1111.36
3043.92	1112.37
3046.49	1101.06
3048.11	1138
3050.69	1148
3053.27	1128
3055.85	1094
3058.43	1132
3061.01	1132
3063.58	1138
3066.16	1140
3068.73	1106
3071.31	1142
3073.88	1110
3076.45	1142
3079.02	1134
3081.59	1126
3084.16	1152
3086.73	1172
3089.29	1160
3091.86	1162
3094.43	1160
3096.99	1166
3099.55	1190
3102.12	1156
3104.68	1222
3107.24	1174
3109.8	1204
3112.36	1194
3114.92	1172
3117.48	1186
3120.03	1206
3122.59	1200
3125.14	1184
3127.7	1194
3130.25	1246
3132.8	1220
3135.35	1252
3137.9	1250
3140.45	1266
3143	1256
3145.55	1236
3148.1	1284
3150.64	1272
3153.19	1234
3155.73	1288
3158.28	1260
3160.82	1272
3163.36	1258
3165.9	1324
3168.44	1264
3170.98	1308
3173.52	1306
3176.06	1336
3178.59	1338
3181.13	1284
3183.66	1306
3186.2	1316
3188.73	1344
3191.26	1340
3193.79	1338
3196.32	1322
3198.85	1344
3201.38	1322
3203.91	1336
3206.44	1334
3208.96	1330
3211.49	1324
3214.01	1360
3216.54	1356
3219.06	1354
3221.58	1334
3224.1	1342
3226.62	1386
3229.14	1322
3231.66	1354
3234.18	1386
3236.69	1358
3239.21	1380
3241.72	1380
3244.24	1364
3246.75	1368
3249.26	1416
3251.78	1366
3254.29	1358
3256.8	1412
3259.3	1386
3261.81	1450
3264.32	1408
3266.83	1436
3269.33	1444
3271.84	1446
3274.34	1448
3276.84	1444
3279.35	1442
3281.85	1482
3284.35	1452
3286.85	1480
3289.35	1482
3291.84	1478
3294.34	1480
3296.84	1462
3299.33	1506
3301.83	1548
3304.32	1506
3306.81	1536
3309.3	1480
3311.79	1564
3314.29	1514
3316.77	1496
3319.26	1526
3321.75	1562
3324.24	1580
3326.72	1526
3329.21	1562
3331.69	1574
3334.18	1568
3336.66	1558
3339.14	1570
3341.62	1566
3344.1	1582
3346.58	1580
3349.06	1538
3351.54	1588
3354.01	1590
3356.49	1578
3358.96	1534
3361.44	1590
3363.91	1578
3366.38	1604
3368.85	1634
3371.33	1620
3373.8	1598
3376.26	1642
3378.73	1626
3381.2	1652
3383.67	1588
3386.13	1646
3388.6	1620
3391.06	1618
3393.52	1650
3395.99	1626
3398.45	1652
3400.91	1670
3403.37	1670
3405.83	1640
3408.29	1628
3410.74	1684
3413.2	1696
3415.66	1696
3418.11	1680
3420.56	1634
3423.02	1720
3425.47	1730
3427.92	1718
3430.37	1682
3432.82	1710
3435.27	1756
3437.72	1760
3440.17	1738
3442.61	1798
3445.06	1776
3447.51	1790
3449.95	1776
3452.39	1766
3454.83	1814
3457.28	1824
3459.72	1806
3462.16	1812
3464.6	1856
3467.04	1832
3469.47	1814
3471.91	1828
3474.34	1792
3476.78	1856
3479.21	1786
3481.65	1818
3484.08	1874
3486.51	1836
3488.94	1852
3491.37	1848
3493.8	1850
3496.23	1856
3498.66	1858
3501.09	1862
3503.51	1862
3505.94	1836
3508.36	1846
3510.79	1856
3513.21	1858
3515.63	1874
3518.05	1878
3520.47	1882
3522.89	1850
3525.31	1894
3527.73	1874
3530.14	1868
3532.56	1840
3534.98	1866
3537.39	1880
3539.81	1900
3542.22	1878
3544.63	1912
3547.04	1904
3549.45	1876
3551.86	1934
3554.27	1864
3556.68	1892
3559.09	1922
3561.49	1942
3563.9	1910
3566.3	1894
3568.71	1928
3571.11	1956
3573.51	1976
3575.92	1954
3578.32	1970
3580.72	2010
3583.12	1980
3585.51	1984
3587.91	1944
3590.31	2008
3592.71	2046
3595.1	2060
3597.49	2070
3599.89	2072
3602.28	2044
3604.67	2020
3607.06	2064
3609.45	2028
3611.84	2032
3614.23	2094
3616.62	2048
3619.01	2070
3621.39	2090
3623.78	2136
3626.17	2086
3628.55	2102
3630.93	2112
3633.31	2064
3635.7	2094
3638.08	2126
3640.46	2114
3642.84	2128
3645.22	2108
3647.59	2152
3649.97	2060
3652.35	2072
3654.72	2152
3657.1	2100
3659.47	2114
3661.84	2136
3664.21	2156
3666.59	2124
3668.96	2134
3671.33	2144
3673.69	2130
3676.06	2122
3678.43	2156
3680.8	2108
3683.16	2070
3685.53	2120
3687.89	2152
3690.25	2110
3692.62	2134
3694.98	2170
3697.34	2168
3699.7	2152
3702.06	2158
3704.42	2128
3706.78	2150
3709.13	2188
3711.49	2196
3713.85	2196
3716.2	2232
3718.56	2190
3720.91	2236
3723.26	2212
3725.61	2254
3727.96	2200
3730.31	2230
3732.66	2296
3735.01	2270
3737.36	2256
3739.7	2244
3742.05	2276
3744.4	2246
3746.74	2288
3749.09	2314
3751.43	2276
3753.77	2324
3756.11	2360
3758.45	2322
3760.79	2314
3763.13	2346
3765.47	2384
3767.81	2342
3770.14	2358
3772.48	2380
3774.82	2350
3777.15	2354
3779.48	2414
3781.82	2318
3784.15	2384
3786.48	2366
3788.81	2368
3791.14	2406
3793.47	2416
3795.8	2388
3798.13	2338
3800.45	2386
3802.78	2374
3805.1	2352
3807.43	2374
3809.75	2364
3812.07	2372
3814.4	2392
3816.72	2380
3819.04	2392
3821.36	2320
3823.68	2322
3826	2386
3828.31	2378
3830.63	2360
3832.95	2396
3835.26	2362
3837.58	2392
3839.89	2430
3842.2	2386
3844.51	2466
3846.83	2388
3849.14	2388
3851.45	2452
3853.76	2414
3856.06	2426
3858.37	2466
3860.68	2454
3862.98	2460
3865.29	2402
3867.59	2466
3869.9	2442
3872.2	2492
3874.5	2506
3876.8	2522
3879.1	2470
3881.4	2484
3883.7	2534
3886	2510
3888.3	2504
3890.6	2492
3892.89	2490
3895.19	2574
3897.48	2580
3899.78	2534
3902.07	2554
3904.36	2586
3906.65	2532
3908.94	2598
3911.23	2526
3913.52	2602
3915.81	2558
3918.1	2584
3920.39	2618
3922.67	2578
3924.96	2658
3927.24	2598
3929.53	2592
3931.81	2674
3934.09	2646
3936.38	2606
3938.66	2608
3940.94	2622
3943.22	2644
3945.5	2590
3947.77	2594
3950.05	2614
3952.33	2570
3954.6	2614
3956.88	2662
3959.15	2606
3961.43	2602
3963.7	2648
3965.97	2604
3968.24	2606
3970.51	2602
3972.78	2614
3975.05	2582
3977.32	2658
3979.59	2650
3981.85	2648
3984.12	2646
3986.39	2692
3988.65	2624
3990.91	2650
3993.18	2672
3995.44	2726
3997.7	2662
3999.96	2630