File: Graficas/datosramanb/CN-Sastre_13.txt
#Acq. time (s)=	20
#Accumulations=	2
#Range (cm-¹)=	50...4000
#Windows=	3
#Autofocus=	Off
#AutoExposure=	Off
#Spike filter=	Multiple accum.
#Delay time (s)=	0
#Binning=	1
#Readout mode=	Signal
#DeNoise=	Off
#ICS correction=	Off
#Dark correction=	Off
#Inst. Process=	Off
#Instrument=	LabRAM HR Evol
#Detector=	Syncerity OE
#Objective=	x100_VIS
#Grating=	600 (500nm)
#ND Filter=	100%
#Laser=	532nm_Edge
#Hole=	100.021
#Range=	Visible
#Project=	Omar
#Sample=
#Site=	21-09-22
#Title=	 CN-Sastre
#Remark=
#Date=	21.09.2022 13:43
#Acquired=	21.09.2022 13:43:34
51.0918	38
54.7807	40
58.4681	92
62.154	190
65.8385	300
69.5216	466
73.2032	810
76.8834	1074
80.5621	1398
84.2393	1658
87.9152	1820
91.5874	1858
95.2603	1818
98.9318	1804
102.602	1824
106.27	1910
109.936	1894
113.601	1938
117.266	1890
120.926	1912
124.588	1804
128.246	1840
131.904	1814
135.561	1828
139.215	1826
142.869	1830
146.52	1842
150.171	1758
153.819	1820
157.465	1822
161.112	1824
164.756	1786
168.398	1840
172.041	1762
175.68	1696
179.318	1774
182.955	1782
186.592	1732
190.225	1742
193.857	1710
197.488	1718
201.118	1676
204.746	1656
208.372	1658
211.997	1650
215.621	1636
219.243	1652
222.864	1642
226.483	1598
230.101	1652
233.718	1638
237.331	1608
240.945	1672
244.557	1658
248.168	1672
251.776	1666
255.384	1658
258.991	1654
262.594	1646
266.198	1668
269.799	1660
273.4	1666
277	1674
280.596	1650
284.193	1648
287.786	1584
291.378	1632
294.971	1650
298.561	1636
302.148	1656
305.737	1636
309.322	1724
312.906	1690
316.49	1686
320.071	1686
323.651	1692
327.229	1748
330.806	1752
334.381	1730
337.955	1722
341.528	1678
345.099	1698
348.669	1678
352.238	1704
355.805	1724
359.371	1726
362.935	1730
366.498	1708
370.06	1754
373.62	1734
377.177	1730
380.734	1736
384.29	1756
387.845	1760
391.396	1808
394.948	1780
398.499	1754
402.046	1770
405.594	1764
409.138	1750
412.683	1758
416.225	1772
419.768	1772
423.307	1748
426.844	1698
430.382	1764
433.917	1754
437.451	1758
440.985	1788
444.516	1760
448.045	1742
451.574	1778
455.102	1812
458.628	1784
462.152	1780
465.674	1798
469.196	1774
472.716	1778
476.234	1778
479.752	1760
483.268	1712
486.782	1726
490.295	1712
493.807	1704
497.316	1732
500.825	1700
504.333	1678
507.839	1676
511.344	1694
514.846	1696
518.349	1740
521.85	1746
525.347	1774
528.846	1860
532.341	1906
535.837	1964
539.329	2124
542.822	2174
546.312	2274
549.802	2294
553.289	2356
556.775	2362
560.261	2348
563.744	2370
567.226	2338
570.709	2292
574.188	2206
577.665	2190
581.142	2164
584.617	2062
588.091	2070
591.565	2006
595.036	1994
598.506	1976
601.974	1878
605.442	1842
608.905	1780
612.37	1794
615.833	1756
619.295	1728
622.755	1696
626.215	1656
629.67	1634
633.127	1590
636.582	1544
640.036	1540
643.487	1518
646.938	1486
650.386	1484
653.835	1442
657.282	1404
660.726	1412
664.171	1350
667.613	1308
671.053	1304
674.494	1284
677.931	1262
681.369	1214
684.804	1178
688.238	1192
691.67	1140
695.103	1094
698.533	1060
701.961	1058
705.389	1050
708.814	998
712.239	1000
715.662	980
719.084	938
722.505	930
725.924	958
729.342	906
732.759	910
736.174	962
739.589	930
742.999	930
746.411	912
749.821	922
753.23	958
756.636	940
760.043	942
763.448	1000
766.85	990
770.252	1018
773.652	1024
777.052	1040
780.448	994
783.846	1028
787.24	1010
790.635	990
794.027	990
797.417	978
800.808	968
804.196	992
807.582	920
810.968	920
814.354	914
817.736	910
821.118	878
824.498	880
827.877	822
831.254	826
834.631	780
838.006	790
841.38	768
844.752	748
848.123	718
851.493	716
854.86	764
858.228	774
861.594	734
864.959	786
868.321	748
871.683	750
875.044	758
878.402	788
881.761	754
885.116	730
888.472	808
891.825	798
895.179	766
898.529	774
901.88	800
905.228	810
908.575	834
911.922	854
915.266	860
918.609	888
921.951	864
925.293	900
928.633	952
931.97	982
935.307	992
938.642	1046
941.977	1016
945.31	1084
948.641	1060
951.972	1122
955.301	1118
958.629	1090
961.955	1066
965.279	1090
968.603	1066
971.926	1060
975.248	1068
978.566	1076
981.886	1126
985.204	1150
988.519	1152
991.834	1178
995.147	1142
998.46	1208
1001.77	1184
1005.08	1244
1008.39	1208
1011.7	1272
1015	1306
1018.3	1336
1021.61	1310
1024.91	1376
1028.21	1446
1031.51	1404
1034.81	1482
1038.1	1546
1041.4	1514
1044.69	1584
1047.99	1710
1051.28	1654
1054.57	1770
1057.86	1776
1061.14	1814
1064.43	1886
1067.72	1976
1071	1972
1074.28	2086
1077.57	2134
1080.84	2162
1084.12	2210
1087.4	2244
1090.68	2286
1093.95	2290
1097.22	2194
1100.5	2260
1103.77	2174
1107.04	2148
1110.31	2118
1113.58	2008
1116.84	1914
1120.1	1872
1123.37	1846
1126.63	1716
1129.89	1670
1133.15	1626
1136.41	1508
1139.67	1500
1142.92	1448
1146.18	1352
1149.43	1314
1152.68	1314
1155.93	1278
1159.18	1192
1162.43	1182
1165.68	1066
1168.93	1120
1172.17	1070
1175.41	1092
1178.66	1036
1181.9	1006
1185.14	974
1188.37	976
1191.61	944
1194.85	878
1198.08	892
1201.31	814
1204.55	850
1207.78	780
1211.01	804
1214.24	814
1217.46	796
1220.69	780
1223.91	788
1227.14	742
1230.36	704
1233.58	724
1236.8	706
1240.02	712
1243.23	688
1246.45	702
1249.67	672
1252.88	692
1256.09	692
1259.3	670
1262.51	710
1265.72	724
1268.93	722
1272.13	696
1275.34	750
1278.54	702
1281.74	696
1284.94	694
1288.15	714
1291.34	698
1294.54	696
1297.74	680
1300.93	694
1304.12	686
1307.32	712
1310.51	692
1313.7	714
1316.89	694
1320.07	708
1323.26	710
1326.45	748
1329.63	718
1332.81	690
1335.99	696
1339.17	700
1342.35	706
1345.53	670
1348.71	708
1351.88	704
1355.06	692
1358.23	708
1361.4	688
1364.57	734
1367.74	686
1370.91	686
1374.08	734
1377.24	678
1380.41	694
1383.57	670
1386.73	720
1389.89	712
1393.05	672
1396.21	674
1399.37	722
1402.52	704
1405.68	712
1408.83	740
1411.98	714
1415.13	744
1418.29	720
1421.43	696
1424.58	698
1427.73	698
1430.87	698
1434.02	724
1437.16	724
1440.3	742
1443.44	714
1446.58	746
1449.72	736
1452.85	718
1455.99	782
1459.12	712
1462.26	712
1465.39	708
1468.52	716
1471.65	688
1474.78	742
1477.9	698
1481.03	732
1484.16	752
1487.28	768
1490.4	736
1493.52	732
1496.64	756
1499.76	744
1502.88	732
1506	730
1509.11	740
1512.22	768
1515.34	746
1518.45	740
1521.56	746
1524.67	760
1527.78	750
1530.88	748
1533.99	756
1537.09	750
1540.2	738
1543.3	758
1546.4	726
1549.5	764
1552.6	764
1555.7	754
1558.79	772
1561.89	754
1564.98	760
1568.08	750
1571.17	758
1574.26	790
1577.35	770
1580.43	742
1583.52	740
1586.61	752
1589.69	704
1592.77	748
1595.86	728
1598.94	730
1602.02	704
1605.1	728
1608.18	743.984
1611.25	741.477
1614.33	734.729
1617.4	745.496
1620.47	755.015
1623.55	739.978
1626.62	748.576
1629.69	694.801
1632.75	703.747
1635.82	724.117
1638.89	709.775
1641.95	731.38
1645.02	698.913
1648.08	717.011
1651.14	717.686
1654.2	702.912
1657.26	706.289
1660.32	708.135
1663.37	730.802
1666.43	701.736
1669.48	696.609
1672.54	734.98
1675.59	696.67
1678.64	699.859
1681.69	720.796
1684.74	682.691
1687.79	687.955
1690.83	698.102
1693.88	686.931
1696.92	716.31
1699.96	684.216
1703.01	701.385
1706.05	679.75
1709.09	687.238
1712.12	686.116
1715.16	685.718
1718.2	662.726
1721.23	680.249
1724.27	669.516
1727.3	675.086
1730.33	641.562
1733.36	668.723
1736.39	664.228
1739.42	662.768
1742.44	651.465
1745.47	647.703
1748.49	647.88
1751.52	649.053
1754.54	625.51
1757.56	637.285
1759.14	620
1762.18	620
1765.21	642
1768.24	644
1771.27	628
1774.3	630
1777.32	654
1780.35	634
1783.38	654
1786.4	620
1789.42	654
1792.44	620
1795.47	654
1798.48	638
1801.5	620
1804.52	618
1807.54	650
1810.55	640
1813.57	646
1816.58	648
1819.59	626
1822.6	662
1825.61	638
1828.62	640
1831.63	644
1834.63	642
1837.64	638
1840.64	636
1843.64	648
1846.64	632
1849.64	620
1852.64	630
1855.64	670
1858.64	646
1861.64	670
1864.63	652
1867.63	656
1870.62	644
1873.61	636
1876.6	630
1879.59	650
1882.58	646
1885.56	626
1888.55	670
1891.54	654
1894.52	664
1897.5	678
1900.48	636
1903.46	640
1906.44	674
1909.42	686
1912.4	670
1915.38	678
1918.35	642
1921.32	662
1924.3	636
1927.27	652
1930.24	680
1933.21	658
1936.18	660
1939.15	660
1942.11	664
1945.08	650
1948.04	660
1951	652
1953.97	662
1956.93	688
1959.89	660
1962.85	648
1965.8	658
1968.76	666
1971.71	656
1974.67	656
1977.62	660
1980.57	654
1983.53	630
1986.48	680
1989.42	642
1992.37	654
1995.32	710
1998.26	664
2001.21	696
2004.15	670
2007.09	640
2010.03	646
2012.98	678
2015.92	614
2018.85	668
2021.79	680
2024.73	672
2027.66	666
2030.59	634
2033.53	630
2036.46	670
2039.39	674
2042.32	666
2045.25	690
2048.17	674
2051.1	668
2054.02	666
2056.95	678
2059.87	670
2062.79	694
2065.71	684
2068.63	650
2071.55	648
2074.47	676
2077.39	668
2080.3	682
2083.22	688
2086.13	664
2089.04	692
2091.95	682
2094.86	654
2097.77	654
2100.68	674
2103.59	684
2106.49	674
2109.4	686
2112.3	684
2115.21	664
2118.11	666
2121.01	672
2123.91	678
2126.8	680
2129.7	662
2132.6	666
2135.49	690
2138.39	668
2141.28	662
2144.17	672
2147.06	690
2149.95	688
2152.84	670
2155.73	682
2158.62	698
2161.5	674
2164.39	648
2167.27	694
2170.15	680
2173.04	672
2175.92	652
2178.79	664
2181.67	684
2184.55	700
2187.43	670
2190.3	674
2193.18	690
2196.05	678
2198.92	704
2201.79	668
2204.66	662
2207.53	654
2210.4	656
2213.27	676
2216.13	678
2219	712
2221.86	674
2224.72	624
2227.59	672
2230.45	656
2233.31	660
2236.16	666
2239.02	658
2241.88	682
2244.73	670
2247.59	666
2250.44	652
2253.29	674
2256.15	662
2259	658
2261.84	682
2264.69	642
2267.54	690
2270.39	670
2273.23	692
2276.07	698
2278.92	666
2281.76	668
2284.6	688
2287.44	644
2290.28	674
2293.12	664
2295.95	658
2298.79	714
2301.62	700
2304.46	680
2307.29	698
2310.12	672
2312.95	662
2315.78	696
2318.61	702
2321.44	704
2324.27	736
2327.09	748
2329.92	740
2332.74	730
2335.56	694
2338.38	722
2341.2	720
2344.02	748
2346.84	756
2349.66	762
2352.48	736
2355.29	756
2358.11	768
2360.92	752
2363.73	780
2366.54	788
2369.35	760
2372.16	768
2374.97	764
2377.78	802
2380.58	798
2383.39	804
2386.19	800
2389	834
2391.8	820
2394.6	788
2397.4	836
2400.2	792
2403	844
2405.79	824
2408.59	816
2411.38	872
2414.18	840
2416.97	860
2419.76	856
2422.55	864
2425.34	878
2428.13	826
2430.92	882
2433.71	850
2436.49	858
2439.28	850
2442.06	846
2444.85	848
2447.63	850
2450.41	858
2453.19	858
2455.97	830
2458.75	830
2461.52	838
2464.3	874
2467.07	844
2469.85	824
2472.62	832
2475.39	864
2478.16	826
2480.94	844
2483.7	828
2486.47	816
2489.24	830
2492	864
2494.77	876
2497.53	850
2500.3	872
2503.06	846
2505.82	856
2508.58	846
2511.34	866
2514.1	834
2516.85	832
2519.61	844
2522.37	826
2525.12	840
2527.87	874
2530.63	848
2533.38	842
2536.13	848
2538.88	840
2541.62	868
2544.37	832
2547.12	822
2549.86	868
2552.61	850
2555.35	818
2558.09	868
2560.84	840
2563.57	862
2566.32	848
2569.05	840
2571.79	860
2574.53	866
2577.26	860
2580	852
2582.73	866
2585.46	856
2588.19	892
2590.93	852
2593.66	838
2596.39	868
2599.11	846
2601.84	850
2604.56	880
2607.29	910
2610.01	892
2612.74	874
2615.46	886
2618.18	892
2620.9	860
2623.62	882
2626.34	866
2629.05	872
2631.77	916
2634.48	854
2637.2	864
2639.91	842
2642.62	878
2645.33	868
2648.05	908
2650.75	870
2653.46	854
2656.17	864
2658.88	890
2661.58	882
2664.29	880
2666.99	888
2669.69	880
2672.39	862
2675.09	884
2677.79	890
2680.49	900
2683.19	910
2685.89	898
2688.58	900
2691.28	890
2693.97	918
2696.67	914
2699.36	910
2702.05	920
2704.74	848
2707.43	904
2710.12	916
2712.8	884
2715.49	894
2718.17	922
2720.86	918
2723.54	898
2726.22	948
2728.91	914
2731.59	950
2734.27	876
2736.95	932
2739.62	916
2742.3	898
2744.98	960
2747.65	936
2750.33	956
2753	938
2755.67	958
2758.34	952
2761.01	920
2763.68	950
2766.35	958
2769.02	988
2771.68	956
2774.35	962
2777.01	952
2779.68	936
2782.34	948
2785	976
2787.66	972
2790.32	948
2792.98	966
2795.64	970
2798.3	952
2800.95	984
2803.61	996
2806.26	960
2808.91	942
2811.57	962
2814.22	962
2816.87	1004
2819.52	1018
2822.17	1004
2824.81	994
2827.46	950
2830.11	990
2832.75	1022
2835.39	1032
2838.04	1022
2840.68	1028
2843.32	1038
2845.96	994
2848.6	1022
2851.24	1034
2853.88	1024
2856.51	1070
2859.15	1046
2861.78	1024
2864.42	1040
2867.05	1052
2869.68	1028
2872.31	1054
2874.94	1024
2877.57	1020
2880.2	1052
2882.82	1058
2885.45	1072
2888.08	1032
2890.7	1078
2893.33	1050
2895.95	1036
2898.57	1100
2901.19	1066
2903.81	1074
2906.43	1114
2909.05	1084
2911.66	1044
2914.28	1082
2916.89	1056
2919.51	1083.82
2922.12	1066.27
2924.73	1093.26
2927.35	1074.4
2929.96	1116.29
2932.57	1119.95
2935.17	1121.33
2937.78	1105.79
2940.39	1106.87
2943	1113.64
2945.6	1123.93
2948.2	1113.19
2950.81	1108.34
2953.41	1129.23
2956.01	1107.33
2958.61	1128.89
2961.21	1127.35
2963.81	1136
2966.41	1124.35
2969.01	1120.67
2971.6	1122.09
2974.2	1151.93
2976.79	1140.39
2979.39	1134.77
2981.98	1152.03
2984.57	1168.53
2987.16	1157.37
2989.75	1155.86
2992.34	1171.78
2994.93	1126.73
2997.51	1148.58
3000.1	1179.62
3002.68	1162.68
3005.27	1166.88
3007.85	1151.16
3010.43	1201.01
3013.01	1178.98
3015.59	1184.2
3018.18	1194.19
3020.75	1196.49
3023.33	1203.28
3025.91	1211.5
3028.48	1195.63
3031.06	1227.47
3033.64	1195.82
3036.21	1217.92
3038.78	1221.86
3041.35	1223.59
3043.92	1233.96
3046.49	1192.55
3048.11	1212
3050.69	1224
3053.27	1242
3055.85	1268
3058.43	1220
3061.01	1242
3063.58	1252
3066.16	1234
3068.73	1242
3071.31	1282
3073.88	1232
3076.45	1246
3079.02	1260
3081.59	1262
3084.16	1278
3086.73	1288
3089.29	1282
3091.86	1278
3094.43	1314
3096.99	1318
3099.55	1294
3102.12	1302
3104.68	1280
3107.24	1302
3109.8	1304
3112.36	1302
3114.92	1314
3117.48	1332
3120.03	1322
3122.59	1376
3125.14	1324
3127.7	1350
3130.25	1370
3132.8	1384
3135.35	1374
3137.9	1336
3140.45	1388
3143	1364
3145.55	1364
3148.1	1364
3150.64	1400
3153.19	1388
3155.73	1382
3158.28	1360
3160.82	1426
3163.36	1430
3165.9	1388
3168.44	1434
3170.98	1406
3173.52	1410
3176.06	1406
3178.59	1468
3181.13	1416
3183.66	1420
3186.2	1444
3188.73	1458
3191.26	1436
3193.79	1508
3196.32	1460
3198.85	1426
3201.38	1436
3203.91	1440
3206.44	1430
3208.96	1486
3211.49	1478
3214.01	1486
3216.54	1508
3219.06	1466
3221.58	1486
3224.1	1440
3226.62	1476
3229.14	1486
3231.66	1496
3234.18	1498
3236.69	1496
3239.21	1504
3241.72	1504
3244.24	1514
3246.75	1496
3249.26	1500
3251.78	1508
3254.29	1526
3256.8	1542
3259.3	1520
3261.81	1536
3264.32	1516
3266.83	1510
3269.33	1558
3271.84	1506
3274.34	1560
3276.84	1574
3279.35	1560
3281.85	1578
3284.35	1580
3286.85	1590
3289.35	1626
3291.84	1652
3294.34	1628
3296.84	1630
3299.33	1610
3301.83	1636
3304.32	1636
3306.81	1644
3309.3	1648
3311.79	1656
3314.29	1660
3316.77	1648
3319.26	1654
3321.75	1712
3324.24	1722
3326.72	1658
3329.21	1714
3331.69	1680
3334.18	1698
3336.66	1662
3339.14	1700
3341.62	1758
3344.1	1730
3346.58	1704
3349.06	1698
3351.54	1728
3354.01	1718
3356.49	1738
3358.96	1704
3361.44	1714
3363.91	1730
3366.38	1722
3368.85	1718
3371.33	1730
3373.8	1746
3376.26	1770
3378.73	1748
3381.2	1768
3383.67	1740
3386.13	1754
3388.6	1780
3391.06	1748
3393.52	1798
3395.99	1760
3398.45	1790
3400.91	1788
3403.37	1786
3405.83	1802
3408.29	1752
3410.74	1790
3413.2	1824
3415.66	1818
3418.11	1830
3420.56	1814
3423.02	1860
3425.47	1806
3427.92	1858
3430.37	1882
3432.82	1924
3435.27	1862
3437.72	1876
3440.17	1878
3442.61	1880
3445.06	1914
3447.51	1912
3449.95	1894
3452.39	1950
3454.83	1942
3457.28	1934
3459.72	1954
3462.16	1930
3464.6	1972
3467.04	1948
3469.47	1956
3471.91	1970
3474.34	1968
3476.78	1956
3479.21	1950
3481.65	2002
3484.08	1986
3486.51	2006
3488.94	1960
3491.37	2036
3493.8	1994
3496.23	1978
3498.66	2012
3501.09	1972
3503.51	1960
3505.94	2012
3508.36	2008
3510.79	1984
3513.21	1938
3515.63	1998
3518.05	1992
3520.47	1962
3522.89	2012
3525.31	1972
3527.73	2028
3530.14	1970
3532.56	2006
3534.98	2004
3537.39	2022
3539.81	2046
3542.22	2022
3544.63	2026
3547.04	2046
3549.45	2044
3551.86	2066
3554.27	2048
3556.68	2014
3559.09	2088
3561.49	2102
3563.9	2056
3566.3	2124
3568.71	2124
3571.11	2102
3573.51	2160
3575.92	2094
3578.32	2126
3580.72	2130
3583.12	2174
3585.51	2132
3587.91	2182
3590.31	2116
3592.71	2100
3595.1	2148
3597.49	2232
3599.89	2188
3602.28	2194
3604.67	2212
3607.06	2224
3609.45	2192
3611.84	2212
3614.23	2256
3616.62	2242
3619.01	2274
3621.39	2252
3623.78	2242
3626.17	2282
3628.55	2296
3630.93	2250
3633.31	2242
3635.7	2196
3638.08	2244
3640.46	2268
3642.84	2252
3645.22	2280
3647.59	2298
3649.97	2272
3652.35	2242
3654.72	2298
3657.1	2286
3659.47	2254
3661.84	2278
3664.21	2246
3666.59	2244
3668.96	2336
3671.33	2304
3673.69	2268
3676.06	2318
3678.43	2308
3680.8	2290
3683.16	2332
3685.53	2252
3687.89	2296
3690.25	2306
3692.62	2278
3694.98	2274
3697.34	2352
3699.7	2330
3702.06	2282
3704.42	2328
3706.78	2354
3709.13	2306
3711.49	2314
3713.85	2362
3716.2	2380
3718.56	2402
3720.91	2406
3723.26	2384
3725.61	2372
3727.96	2414
3730.31	2392
3732.66	2428
3735.01	2420
3737.36	2424
3739.7	2420
3742.05	2422
3744.4	2460
3746.74	2450
3749.09	2476
3751.43	2476
3753.77	2522
3756.11	2478
3758.45	2518
3760.79	2516
3763.13	2518
3765.47	2536
3767.81	2486
3770.14	2532
3772.48	2528
3774.82	2512
3777.15	2562
3779.48	2530
3781.82	2550
3784.15	2490
3786.48	2570
3788.81	2518
3791.14	2568
3793.47	2560
3795.8	2516
3798.13	2504
3800.45	2558
3802.78	2538
3805.1	2584
3807.43	2516
3809.75	2528
3812.07	2536
3814.4	2518
3816.72	2554
3819.04	2514
3821.36	2554
3823.68	2540
3826	2490
3828.31	2534
3830.63	2534
3832.95	2568
3835.26	2502
3837.58	2500
3839.89	2580
3842.2	2526
3844.51	2504
3846.83	2512
3849.14	2584
3851.45	2566
3853.76	2592
3856.06	2574
3858.37	2640
3860.68	2612
3862.98	2616
3865.29	2642
3867.59	2644
3869.9	2632
3872.2	2612
3874.5	2610
3876.8	2670
3879.1	2598
3881.4	2648
3883.7	2626
3886	2706
3888.3	2696
3890.6	2706
3892.89	2740
3895.19	2682
3897.48	2704
3899.78	2690
3902.07	2688
3904.36	2736
3906.65	2718
3908.94	2706
3911.23	2756
3913.52	2742
3915.81	2784
3918.1	2738
3920.39	2754
3922.67	2792
3924.96	2768
3927.24	2794
3929.53	2808
3931.81	2816
3934.09	2826
3936.38	2774
3938.66	2778
3940.94	2758
3943.22	2786
3945.5	2768
3947.77	2798
3950.05	2788
3952.33	2804
3954.6	2804
3956.88	2758
3959.15	2782
3961.43	2778
3963.7	2790
3965.97	2750
3968.24	2808
3970.51	2786
3972.78	2798
3975.05	2790
3977.32	2792
3979.59	2852
3981.85	2878
3984.12	2764
3986.39	2806
3988.65	2822
3990.91	2860
3993.18	2866
3995.44	2794
3997.7	2840
3999.96	2876