File: Graficas/datosramanb/CN-Sastre_11.txt
#Acq. time (s)=	20
#Accumulations=	2
#Range (cm-¹)=	50...4000
#Windows=	3
#Autofocus=	Off
#AutoExposure=	Off
#Spike filter=	Multiple accum.
#Delay time (s)=	0
#Binning=	1
#Readout mode=	Signal
#DeNoise=	Off
#ICS correction=	Off
#Dark correction=	Off
#Inst. Process=	Off
#Instrument=	LabRAM HR Evol
#Detector=	Syncerity OE
#Objective=	x100_VIS
#Grating=	600 (500nm)
#ND Filter=	100%
#Laser=	532nm_Edge
#Hole=	100.021
#Range=	Visible
#Project=	Omar
#Sample=
#Site=	21-09-22
#Title=	 CN-Sastre
#Remark=
#Date=	21.09.2022 13:29
#Acquired=	21.09.2022 13:29:12
51.0918	46
54.7807	48
58.4681	80
62.154	188
65.8385	316
69.5216	480
73.2032	832
76.8834	1152
80.5621	1450
84.2393	1698
87.9152	1882
91.5874	1980
95.2603	1884
98.9318	1910
102.602	1888
106.27	2032
109.936	1976
113.601	2058
117.266	2016
120.926	1936
124.588	1976
128.246	1986
131.904	1882
135.561	1914
139.215	1918
142.869	1910
146.52	1934
150.171	1906
153.819	1926
157.465	1872
161.112	1844
164.756	1852
168.398	1806
172.041	1834
175.68	1812
179.318	1788
182.955	1820
186.592	1778
190.225	1782
193.857	1768
197.488	1770
201.118	1736
204.746	1798
208.372	1748
211.997	1728
215.621	1698
219.243	1706
222.864	1664
226.483	1680
230.101	1638
233.718	1714
237.331	1662
240.945	1668
244.557	1672
248.168	1672
251.776	1674
255.384	1744
258.991	1742
262.594	1660
266.198	1712
269.799	1674
273.4	1650
277	1672
280.596	1690
284.193	1684
287.786	1718
291.378	1736
294.971	1686
298.561	1674
302.148	1692
305.737	1706
309.322	1738
312.906	1722
316.49	1762
320.071	1726
323.651	1750
327.229	1750
330.806	1736
334.381	1746
337.955	1752
341.528	1722
345.099	1730
348.669	1764
352.238	1728
355.805	1750
359.371	1764
362.935	1810
366.498	1800
370.06	1780
373.62	1808
377.177	1808
380.734	1810
384.29	1868
387.845	1796
391.396	1790
394.948	1828
398.499	1796
402.046	1794
405.594	1816
409.138	1824
412.683	1756
416.225	1780
419.768	1804
423.307	1802
426.844	1794
430.382	1780
433.917	1778
437.451	1772
440.985	1838
444.516	1860
448.045	1842
451.574	1850
455.102	1854
458.628	1838
462.152	1820
465.674	1838
469.196	1818
472.716	1812
476.234	1800
479.752	1772
483.268	1766
486.782	1782
490.295	1756
493.807	1780
497.316	1730
500.825	1740
504.333	1756
507.839	1712
511.344	1764
514.846	1744
518.349	1772
521.85	1804
525.347	1842
528.846	1906
532.341	1934
535.837	2070
539.329	2146
542.822	2214
546.312	2376
549.802	2392
553.289	2364
556.775	2374
560.261	2384
563.744	2408
567.226	2386
570.709	2332
574.188	2262
577.665	2244
581.142	2194
584.617	2180
588.091	2126
591.565	2062
595.036	1950
598.506	1976
601.974	1928
605.442	1872
608.905	1850
612.37	1816
615.833	1788
619.295	1728
622.755	1726
626.215	1658
629.67	1658
633.127	1648
636.582	1556
640.036	1560
643.487	1570
646.938	1520
650.386	1520
653.835	1474
657.282	1414
660.726	1406
664.171	1352
667.613	1326
671.053	1246
674.494	1288
677.931	1256
681.369	1230
684.804	1228
688.238	1214
691.67	1162
695.103	1108
698.533	1128
701.961	1068
705.389	1094
708.814	1082
712.239	1040
715.662	1008
719.084	1016
722.505	970
725.924	992
729.342	970
732.759	962
736.174	994
739.589	986
742.999	964
746.411	976
749.821	986
753.23	994
756.636	992
760.043	986
763.448	1046
766.85	1050
770.252	1006
773.652	996
777.052	1070
780.448	1038
783.846	1014
787.24	1048
790.635	1000
794.027	962
797.417	1030
800.808	1008
804.196	940
807.582	960
810.968	950
814.354	942
817.736	920
821.118	944
824.498	872
827.877	822
831.254	786
834.631	802
838.006	818
841.38	800
844.752	790
848.123	782
851.493	792
854.86	748
858.228	778
861.594	798
864.959	758
868.321	814
871.683	764
875.044	780
878.402	770
881.761	776
885.116	804
888.472	802
891.825	780
895.179	802
898.529	796
901.88	818
905.228	860
908.575	836
911.922	896
915.266	864
918.609	900
921.951	910
925.293	950
928.633	992
931.97	1062
935.307	1028
938.642	1072
941.977	1108
945.31	1082
948.641	1062
951.972	1116
955.301	1100
958.629	1104
961.955	1106
965.279	1096
968.603	1076
971.926	1088
975.248	1116
978.566	1108
981.886	1130
985.204	1192
988.519	1140
991.834	1168
995.147	1200
998.46	1244
1001.77	1226
1005.08	1252
1008.39	1280
1011.7	1228
1015	1300
1018.3	1310
1021.61	1310
1024.91	1360
1028.21	1436
1031.51	1456
1034.81	1482
1038.1	1558
1041.4	1568
1044.69	1620
1047.99	1678
1051.28	1740
1054.57	1728
1057.86	1776
1061.14	1864
1064.43	1918
1067.72	1970
1071	2020
1074.28	2058
1077.57	2190
1080.84	2202
1084.12	2228
1087.4	2252
1090.68	2238
1093.95	2326
1097.22	2268
1100.5	2206
1103.77	2226
1107.04	2128
1110.31	2098
1113.58	2050
1116.84	1986
1120.1	1912
1123.37	1820
1126.63	1718
1129.89	1660
1133.15	1606
1136.41	1546
1139.67	1476
1142.92	1476
1146.18	1428
1149.43	1376
1152.68	1304
1155.93	1288
1159.18	1180
1162.43	1180
1165.68	1172
1168.93	1144
1172.17	1098
1175.41	1066
1178.66	1036
1181.9	1004
1185.14	966
1188.37	976
1191.61	934
1194.85	936
1198.08	872
1201.31	876
1204.55	828
1207.78	826
1211.01	858
1214.24	858
1217.46	792
1220.69	790
1223.91	788
1227.14	798
1230.36	766
1233.58	714
1236.8	740
1240.02	752
1243.23	746
1246.45	736
1249.67	692
1252.88	728
1256.09	740
1259.3	738
1262.51	740
1265.72	712
1268.93	730
1272.13	714
1275.34	702
1278.54	714
1281.74	692
1284.94	750
1288.15	740
1291.34	728
1294.54	732
1297.74	708
1300.93	726
1304.12	748
1307.32	740
1310.51	764
1313.7	752
1316.89	734
1320.07	780
1323.26	762
1326.45	794
1329.63	762
1332.81	754
1335.99	800
1339.17	778
1342.35	780
1345.53	770
1348.71	812
1351.88	800
1355.06	774
1358.23	750
1361.4	788
1364.57	762
1367.74	780
1370.91	776
1374.08	720
1377.24	760
1380.41	726
1383.57	742
1386.73	704
1389.89	726
1393.05	724
1396.21	758
1399.37	748
1402.52	752
1405.68	742
1408.83	746
1411.98	760
1415.13	742
1418.29	746
1421.43	710
1424.58	728
1427.73	738
1430.87	766
1434.02	746
1437.16	740
1440.3	734
1443.44	738
1446.58	734
1449.72	742
1452.85	746
1455.99	766
1459.12	758
1462.26	760
1465.39	742
1468.52	704
1471.65	734
1474.78	726
1477.9	736
1481.03	730
1484.16	744
1487.28	752
1490.4	708
1493.52	772
1496.64	742
1499.76	774
1502.88	778
1506	772
1509.11	774
1512.22	782
1515.34	742
1518.45	776
1521.56	760
1524.67	748
1527.78	798
1530.88	788
1533.99	748
1537.09	756
1540.2	758
1543.3	774
1546.4	764
1549.5	748
1552.6	768
1555.7	776
1558.79	778
1561.89	776
1564.98	802
1568.08	770
1571.17	756
1574.26	770
1577.35	778
1580.43	778
1583.52	780
1586.61	798
1589.69	784
1592.77	810
1595.86	808
1598.94	812
1602.02	760
1605.1	764
1608.18	758.202
1611.25	786.811
1614.33	774.733
1617.4	792.514
1620.47	790.408
1623.55	763.231
1626.62	741.69
1629.69	710.062
1632.75	736.305
1635.82	730.198
1638.89	712.859
1641.95	745.865
1645.02	728.361
1648.08	738.397
1651.14	735.174
1654.2	722.584
1657.26	743.455
1660.32	733.923
1663.37	718.491
1666.43	707.896
1669.48	711.03
1672.54	706.233
1675.59	702.952
1678.64	710.159
1681.69	702.172
1684.74	715.255
1687.79	720.248
1690.83	694.183
1693.88	705.324
1696.92	707.219
1699.96	706.659
1703.01	691.316
1706.05	690.792
1709.09	698.462
1712.12	703.314
1715.16	722.077
1718.2	680.862
1721.23	677.195
1724.27	685.401
1727.3	690.138
1730.33	699.432
1733.36	702.295
1736.39	674.021
1739.42	675.658
1742.44	640.991
1745.47	677.494
1748.49	658.339
1751.52	660.099
1754.54	652.828
1757.56	653.211
1759.14	656
1762.18	646
1765.21	642
1768.24	662
1771.27	650
1774.3	616
1777.32	658
1780.35	670
1783.38	676
1786.4	652
1789.42	644
1792.44	642
1795.47	650
1798.48	672
1801.5	664
1804.52	650
1807.54	642
1810.55	678
1813.57	654
1816.58	656
1819.59	668
1822.6	638
1825.61	680
1828.62	676
1831.63	632
1834.63	656
1837.64	656
1840.64	636
1843.64	650
1846.64	664
1849.64	670
1852.64	662
1855.64	676
1858.64	678
1861.64	666
1864.63	676
1867.63	670
1870.62	630
1873.61	640
1876.6	652
1879.59	632
1882.58	642
1885.56	676
1888.55	668
1891.54	666
1894.52	684
1897.5	676
1900.48	664
1903.46	674
1906.44	648
1909.42	632
1912.4	692
1915.38	650
1918.35	672
1921.32	662
1924.3	658
1927.27	670
1930.24	670
1933.21	674
1936.18	688
1939.15	652
1942.11	678
1945.08	674
1948.04	668
1951	688
1953.97	666
1956.93	682
1959.89	692
1962.85	658
1965.8	668
1968.76	670
1971.71	670
1974.67	664
1977.62	672
1980.57	658
1983.53	684
1986.48	678
1989.42	644
1992.37	680
1995.32	686
1998.26	656
2001.21	672
2004.15	650
2007.09	658
2010.03	676
2012.98	666
2015.92	660
2018.85	638
2021.79	674
2024.73	670
2027.66	674
2030.59	682
2033.53	660
2036.46	690
2039.39	698
2042.32	680
2045.25	696
2048.17	668
2051.1	704
2054.02	678
2056.95	676
2059.87	682
2062.79	666
2065.71	688
2068.63	680
2071.55	676
2074.47	672
2077.39	676
2080.3	664
2083.22	664
2086.13	656
2089.04	672
2091.95	702
2094.86	672
2097.77	682
2100.68	694
2103.59	660
2106.49	674
2109.4	654
2112.3	682
2115.21	682
2118.11	660
2121.01	648
2123.91	680
2126.8	676
2129.7	670
2132.6	698
2135.49	652
2138.39	702
2141.28	676
2144.17	674
2147.06	680
2149.95	660
2152.84	684
2155.73	668
2158.62	672
2161.5	672
2164.39	670
2167.27	678
2170.15	704
2173.04	688
2175.92	690
2178.79	664
2181.67	684
2184.55	710
2187.43	668
2190.3	698
2193.18	682
2196.05	670
2198.92	706
2201.79	686
2204.66	684
2207.53	664
2210.4	680
2213.27	686
2216.13	650
2219	678
2221.86	676
2224.72	682
2227.59	662
2230.45	670
2233.31	688
2236.16	692
2239.02	654
2241.88	676
2244.73	652
2247.59	632
2250.44	664
2253.29	682
2256.15	656
2259	676
2261.84	664
2264.69	642
2267.54	656
2270.39	640
2273.23	684
2276.07	628
2278.92	666
2281.76	650
2284.6	688
2287.44	646
2290.28	688
2293.12	680
2295.95	704
2298.79	672
2301.62	692
2304.46	696
2307.29	680
2310.12	686
2312.95	694
2315.78	682
2318.61	710
2321.44	700
2324.27	672
2327.09	764
2329.92	752
2332.74	698
2335.56	722
2338.38	728
2341.2	738
2344.02	734
2346.84	712
2349.66	746
2352.48	756
2355.29	754
2358.11	778
2360.92	754
2363.73	734
2366.54	732
2369.35	754
2372.16	778
2374.97	790
2377.78	762
2380.58	758
2383.39	800
2386.19	770
2389	792
2391.8	810
2394.6	786
2397.4	764
2400.2	794
2403	816
2405.79	814
2408.59	838
2411.38	816
2414.18	810
2416.97	828
2419.76	824
2422.55	846
2425.34	810
2428.13	838
2430.92	824
2433.71	836
2436.49	860
2439.28	804
2442.06	800
2444.85	828
2447.63	840
2450.41	824
2453.19	834
2455.97	836
2458.75	868
2461.52	828
2464.3	800
2467.07	814
2469.85	838
2472.62	860
2475.39	834
2478.16	838
2480.94	834
2483.7	800
2486.47	826
2489.24	838
2492	836
2494.77	826
2497.53	808
2500.3	808
2503.06	836
2505.82	808
2508.58	848
2511.34	828
2514.1	784
2516.85	820
2519.61	840
2522.37	852
2525.12	826
2527.87	774
2530.63	806
2533.38	814
2536.13	836
2538.88	830
2541.62	816
2544.37	792
2547.12	814
2549.86	846
2552.61	820
2555.35	778
2558.09	826
2560.84	844
2563.57	816
2566.32	810
2569.05	814
2571.79	830
2574.53	800
2577.26	818
2580	836
2582.73	840
2585.46	858
2588.19	822
2590.93	830
2593.66	828
2596.39	814
2599.11	846
2601.84	820
2604.56	842
2607.29	846
2610.01	848
2612.74	842
2615.46	846
2618.18	838
2620.9	860
2623.62	840
2626.34	856
2629.05	874
2631.77	828
2634.48	870
2637.2	868
2639.91	878
2642.62	850
2645.33	878
2648.05	842
2650.75	886
2653.46	862
2656.17	866
2658.88	856
2661.58	894
2664.29	866
2666.99	878
2669.69	868
2672.39	848
2675.09	866
2677.79	886
2680.49	884
2683.19	846
2685.89	872
2688.58	850
2691.28	886
2693.97	862
2696.67	902
2699.36	840
2702.05	876
2704.74	870
2707.43	864
2710.12	876
2712.8	888
2715.49	856
2718.17	878
2720.86	864
2723.54	886
2726.22	882
2728.91	866
2731.59	894
2734.27	910
2736.95	906
2739.62	874
2742.3	866
2744.98	908
2747.65	884
2750.33	898
2753	874
2755.67	874
2758.34	910
2761.01	884
2763.68	926
2766.35	884
2769.02	938
2771.68	890
2774.35	914
2777.01	888
2779.68	944
2782.34	896
2785	936
2787.66	926
2790.32	902
2792.98	916
2795.64	892
2798.3	926
2800.95	926
2803.61	968
2806.26	944
2808.91	958
2811.57	948
2814.22	918
2816.87	954
2819.52	932
2822.17	958
2824.81	940
2827.46	936
2830.11	956
2832.75	968
2835.39	962
2838.04	966
2840.68	996
2843.32	984
2845.96	972
2848.6	968
2851.24	964
2853.88	992
2856.51	982
2859.15	990
2861.78	978
2864.42	982
2867.05	1020
2869.68	982
2872.31	1008
2874.94	1008
2877.57	994
2880.2	1026
2882.82	1004
2885.45	1016
2888.08	1016
2890.7	990
2893.33	992
2895.95	1010
2898.57	996
2901.19	1020
2903.81	1030
2906.43	1050
2909.05	1030
2911.66	1026
2914.28	1066
2916.89	1024
2919.51	1025.98
2922.12	1058.77
2924.73	1074.8
2927.35	1014.82
2929.96	1024.95
2932.57	1052.64
2935.17	1033.98
2937.78	1038.51
2940.39	1041.63
2943	1042.11
2945.6	1051.34
2948.2	1036.99
2950.81	1075.41
2953.41	1049.67
2956.01	1058.81
2958.61	1073.88
2961.21	1045.77
2963.81	1074.22
2966.41	1059.1
2969.01	1072.12
2971.6	1058.02
2974.2	1061.43
2976.79	1060.42
2979.39	1100.34
2981.98	1096.77
2984.57	1059.4
2987.16	1098.97
2989.75	1084.03
2992.34	1104.04
2994.93	1098.49
2997.51	1116.91
3000.1	1108.43
3002.68	1123.89
3005.27	1091.6
3007.85	1121.09
3010.43	1100.24
3013.01	1130.93
3015.59	1080.26
3018.18	1128.28
3020.75	1116.65
3023.33	1124.27
3025.91	1127.93
3028.48	1107.08
3031.06	1143.23
3033.64	1136.89
3036.21	1135.25
3038.78	1168.83
3041.35	1151.43
3043.92	1160.19
3046.49	1164.59
3048.11	1190
3050.69	1178
3053.27	1166
3055.85	1190
3058.43	1170
3061.01	1186
3063.58	1176
3066.16	1166
3068.73	1190
3071.31	1198
3073.88	1188
3076.45	1206
3079.02	1190
3081.59	1208
3084.16	1196
3086.73	1168
3089.29	1228
3091.86	1230
3094.43	1212
3096.99	1224
3099.55	1218
3102.12	1240
3104.68	1230
3107.24	1222
3109.8	1230
3112.36	1242
3114.92	1234
3117.48	1224
3120.03	1246
3122.59	1254
3125.14	1272
3127.7	1242
3130.25	1250
3132.8	1264
3135.35	1256
3137.9	1310
3140.45	1290
3143	1306
3145.55	1308
3148.1	1312
3150.64	1304
3153.19	1300
3155.73	1338
3158.28	1292
3160.82	1324
3163.36	1314
3165.9	1324
3168.44	1326
3170.98	1290
3173.52	1338
3176.06	1342
3178.59	1354
3181.13	1362
3183.66	1338
3186.2	1400
3188.73	1362
3191.26	1364
3193.79	1392
3196.32	1384
3198.85	1360
3201.38	1394
3203.91	1348
3206.44	1384
3208.96	1370
3211.49	1346
3214.01	1400
3216.54	1352
3219.06	1376
3221.58	1414
3224.1	1310
3226.62	1392
3229.14	1396
3231.66	1384
3234.18	1418
3236.69	1402
3239.21	1364
3241.72	1396
3244.24	1446
3246.75	1404
3249.26	1432
3251.78	1448
3254.29	1438
3256.8	1446
3259.3	1422
3261.81	1476
3264.32	1426
3266.83	1452
3269.33	1438
3271.84	1458
3274.34	1444
3276.84	1460
3279.35	1480
3281.85	1470
3284.35	1466
3286.85	1504
3289.35	1510
3291.84	1500
3294.34	1518
3296.84	1536
3299.33	1516
3301.83	1534
3304.32	1546
3306.81	1554
3309.3	1574
3311.79	1554
3314.29	1568
3316.77	1550
3319.26	1556
3321.75	1560
3324.24	1598
3326.72	1598
3329.21	1568
3331.69	1582
3334.18	1558
3336.66	1610
3339.14	1606
3341.62	1578
3344.1	1586
3346.58	1608
3349.06	1574
3351.54	1618
3354.01	1592
3356.49	1592
3358.96	1586
3361.44	1616
3363.91	1624
3366.38	1624
3368.85	1604
3371.33	1610
3373.8	1648
3376.26	1622
3378.73	1596
3381.2	1632
3383.67	1590
3386.13	1640
3388.6	1620
3391.06	1652
3393.52	1662
3395.99	1640
3398.45	1660
3400.91	1680
3403.37	1708
3405.83	1662
3408.29	1648
3410.74	1656
3413.2	1708
3415.66	1754
3418.11	1684
3420.56	1698
3423.02	1684
3425.47	1684
3427.92	1734
3430.37	1724
3432.82	1722
3435.27	1794
3437.72	1770
3440.17	1790
3442.61	1778
3445.06	1776
3447.51	1786
3449.95	1798
3452.39	1786
3454.83	1798
3457.28	1832
3459.72	1784
3462.16	1830
3464.6	1862
3467.04	1812
3469.47	1832
3471.91	1846
3474.34	1854
3476.78	1878
3479.21	1880
3481.65	1838
3484.08	1878
3486.51	1852
3488.94	1816
3491.37	1846
3493.8	1840
3496.23	1866
3498.66	1868
3501.09	1842
3503.51	1864
3505.94	1858
3508.36	1812
3510.79	1854
3513.21	1822
3515.63	1880
3518.05	1836
3520.47	1872
3522.89	1824
3525.31	1904
3527.73	1882
3530.14	1880
3532.56	1882
3534.98	1824
3537.39	1900
3539.81	1906
3542.22	1884
3544.63	1870
3547.04	1906
3549.45	1842
3551.86	1876
3554.27	1848
3556.68	1914
3559.09	1894
3561.49	1944
3563.9	1924
3566.3	1962
3568.71	1912
3571.11	1910
3573.51	2016
3575.92	1960
3578.32	1944
3580.72	1954
3583.12	2020
3585.51	2002
3587.91	2024
3590.31	2018
3592.71	1986
3595.1	2030
3597.49	2060
3599.89	2020
3602.28	2032
3604.67	2020
3607.06	2076
3609.45	2036
3611.84	2038
3614.23	2092
3616.62	2028
3619.01	2068
3621.39	2070
3623.78	2088
3626.17	2062
3628.55	2048
3630.93	2120
3633.31	2090
3635.7	2086
3638.08	2088
3640.46	2082
3642.84	2098
3645.22	2140
3647.59	2086
3649.97	2134
3652.35	2122
3654.72	2112
3657.1	2076
3659.47	2112
3661.84	2066
3664.21	2086
3666.59	2068
3668.96	2114
3671.33	2140
3673.69	2086
3676.06	2084
3678.43	2072
3680.8	2090
3683.16	2132
3685.53	2128
3687.89	2112
3690.25	2122
3692.62	2080
3694.98	2072
3697.34	2130
3699.7	2150
3702.06	2140
3704.42	2158
3706.78	2122
3709.13	2136
3711.49	2120
3713.85	2136
3716.2	2138
3718.56	2152
3720.91	2140
3723.26	2194
3725.61	2196
3727.96	2180
3730.31	2174
3732.66	2214
3735.01	2242
3737.36	2252
3739.7	2210
3742.05	2232
3744.4	2226
3746.74	2264
3749.09	2244
3751.43	2286
3753.77	2312
3756.11	2284
3758.45	2276
3760.79	2334
3763.13	2240
3765.47	2336
3767.81	2318
3770.14	2262
3772.48	2368
3774.82	2346
3777.15	2324
3779.48	2276
3781.82	2350
3784.15	2350
3786.48	2334
3788.81	2328
3791.14	2346
3793.47	2334
3795.8	2362
3798.13	2292
3800.45	2328
3802.78	2354
3805.1	2362
3807.43	2358
3809.75	2348
3812.07	2302
3814.4	2350
3816.72	2368
3819.04	2346
3821.36	2336
3823.68	2340
3826	2322
3828.31	2344
3830.63	2324
3832.95	2400
3835.26	2314
3837.58	2336
3839.89	2330
3842.2	2328
3844.51	2360
3846.83	2372
3849.14	2264
3851.45	2370
3853.76	2408
3856.06	2374
3858.37	2406
3860.68	2410
3862.98	2378
3865.29	2352
3867.59	2406
3869.9	2418
3872.2	2410
3874.5	2402
3876.8	2414
3879.1	2448
3881.4	2502
3883.7	2456
3886	2416
3888.3	2464
3890.6	2506
3892.89	2500
3895.19	2518
3897.48	2478
3899.78	2550
3902.07	2512
3904.36	2462
3906.65	2522
3908.94	2514
3911.23	2570
3913.52	2496
3915.81	2576
3918.1	2558
3920.39	2552
3922.67	2504
3924.96	2570
3927.24	2634
3929.53	2582
3931.81	2534
3934.09	2574
3936.38	2514
3938.66	2572
3940.94	2576
3943.22	2578
3945.5	2552
3947.77	2574
3950.05	2578
3952.33	2588
3954.6	2554
3956.88	2560
3959.15	2560
3961.43	2542
3963.7	2534
3965.97	2562
3968.24	2530
3970.51	2570
3972.78	2548
3975.05	2584
3977.32	2538
3979.59	2582
3981.85	2608
3984.12	2550
3986.39	2628
3988.65	2580
3990.91	2564
3993.18	2612
3995.44	2600
3997.7	2554
3999.96	2612