File: BaseLine/fil.txt
#Acq. time (s)=	20
#Accumulations=	2
#Range (cm-ï¿½)=	50...4000
#Windows=	3
#Autofocus=	Off
#AutoExposure=	Off
#Spike filter=	Multiple accum.
#Delay time (s)=	0
#Binning=	1
#Readout mode=	Signal
#DeNoise=	Off
#ICS correction=	Off
#Dark correction=	Off
#Inst. Process=	Off
#Instrument=	LabRAM HR Evol
#Detector=	Syncerity OE
#Objective=	x100_VIS
#Grating=	600 (500nm)
#ND Filter=	100%
#Laser=	532nm_Edge
#Hole=	100.021
#Range=	Visible
#Project=	Omar
#Sample=
#Site=	21-09-22
#Title=	 CN-Sastre
#Remark=
#Date=	21.09.2022 14:49
#Acquired=	21.09.2022 14:49:48
51.0918	44
54.7807	52
58.4681	90
62.154	192
65.8385	310
69.5216	476
73.2032	828
76.8834	1086
80.5621	1328
84.2393	1576
87.9152	1708
91.5874	1794
95.2603	1730
98.9318	1732
102.602	1766
106.27	1872
109.936	1808
113.601	1866
117.266	1788
120.926	1816
124.588	1760
128.246	1706
131.904	1738
135.561	1756
139.215	1702
142.869	1770
146.52	1736
150.171	1742
153.819	1734
157.465	1704
161.112	1700
164.756	1706
168.398	1690
172.041	1616
175.68	1690
179.318	1636
182.955	1610
186.592	1612
190.225	1672
193.857	1626
197.488	1582
201.118	1574
204.746	1610
208.372	1574
211.997	1564
215.621	1584
219.243	1506
222.864	1540
226.483	1560
230.101	1506
233.718	1492
237.331	1520
240.945	1504
244.557	1522
248.168	1542
251.776	1568
255.384	1562
258.991	1542
262.594	1506
266.198	1524
269.799	1556
273.4	1554
277	1520
280.596	1514
284.193	1532
287.786	1526
291.378	1528
294.971	1568
298.561	1556
302.148	1582
305.737	1536
309.322	1566
312.906	1548
316.49	1580
320.071	1566
323.651	1570
327.229	1602
330.806	1556
334.381	1564
337.955	1562
341.528	1574
345.099	1582
348.669	1572
352.238	1582
355.805	1580
359.371	1540
362.935	1584
366.498	1562
370.06	1594
373.62	1610
377.177	1592
380.734	1640
384.29	1556
387.845	1644
391.396	1676
394.948	1640
398.499	1566
402.046	1560
405.594	1682
409.138	1626
412.683	1630
416.225	1638
419.768	1640
423.307	1640
426.844	1644
430.382	1598
433.917	1598
437.451	1626
440.985	1700
444.516	1624
448.045	1630
451.574	1618
455.102	1622
458.628	1668
462.152	1622
465.674	1622
469.196	1660
472.716	1612
476.234	1660
479.752	1662
483.268	1604
486.782	1594
490.295	1618
493.807	1568
497.316	1582
500.825	1564
504.333	1470
507.839	1560
511.344	1584
514.846	1584
518.349	1590
521.85	1588
525.347	1664
528.846	1730
532.341	1802
535.837	1924
539.329	1982
542.822	2062
546.312	2120
549.802	2192
553.289	2222
556.775	2226
560.261	2218
563.744	2186
567.226	2132
570.709	2080
574.188	2064
577.665	2046
581.142	2036
584.617	1970
588.091	1900
591.565	1874
595.036	1784
598.506	1788
601.974	1750
605.442	1726
608.905	1690
612.37	1632
615.833	1572
619.295	1520
622.755	1542
626.215	1502
629.67	1498
633.127	1482
636.582	1406
640.036	1444
643.487	1380
646.938	1376
650.386	1308
653.835	1276
657.282	1270
660.726	1220
664.171	1184
667.613	1166
671.053	1166
674.494	1098
677.931	1092
681.369	1074
684.804	1004
688.238	1026
691.67	982
695.103	956
698.533	928
701.961	922
705.389	902
708.814	892
712.239	836
715.662	834
719.084	818
722.505	840
725.924	850
729.342	806
732.759	792
736.174	776
739.589	766
742.999	782
746.411	794
749.821	758
753.23	812
756.636	786
760.043	802
763.448	830
766.85	808
770.252	836
773.652	874
777.052	856
780.448	866
783.846	864
787.24	860
790.635	838
794.027	824
797.417	856
800.808	814
804.196	812
807.582	758
810.968	782
814.354	766
817.736	732
821.118	724
824.498	696
827.877	688
831.254	666
834.631	630
838.006	646
841.38	610
844.752	606
848.123	606
851.493	632
854.86	636
858.228	568
861.594	588
864.959	620
868.321	602
871.683	590
875.044	568
878.402	640
881.761	618
885.116	610
888.472	638
891.825	602
895.179	628
898.529	650
901.88	626
905.228	678
908.575	660
911.922	698
915.266	710
918.609	716
921.951	742
925.293	762
928.633	830
931.97	786
935.307	860
938.642	886
941.977	882
945.31	872
948.641	890
951.972	952
955.301	924
958.629	946
961.955	898
965.279	894
968.603	894
971.926	884
975.248	902
978.566	974
981.886	958
985.204	992
988.519	1012
991.834	1000
995.147	1002
998.46	1032
1001.77	1022
1005.08	1040
1008.39	1046
1011.7	1070
1015	1132
1018.3	1138
1021.61	1138
1024.91	1192
1028.21	1212
1031.51	1236
1034.81	1280
1038.1	1350
1041.4	1414
1044.69	1432
1047.99	1458
1051.28	1530
1054.57	1576
1057.86	1606
1061.14	1662
1064.43	1684
1067.72	1762
1071	1798
1074.28	1860
1077.57	1914
1080.84	1940
1084.12	2000
1087.4	2002
1090.68	2004
1093.95	2072
1097.22	2118
1100.5	2004
1103.77	1936
1107.04	1946
1110.31	1896
1113.58	1798
1116.84	1718
1120.1	1636
1123.37	1574
1126.63	1526
1129.89	1420
1133.15	1424
1136.41	1338
1139.67	1320
1142.92	1222
1146.18	1178
1149.43	1158
1152.68	1092
1155.93	1068
1159.18	1000
1162.43	1008
1165.68	972
1168.93	936
1172.17	904
1175.41	894
1178.66	852
1181.9	826
1185.14	784
1188.37	776
1191.61	776
1194.85	708
1198.08	700
1201.31	666
1204.55	654
1207.78	664
1211.01	600
1214.24	622
1217.46	612
1220.69	608
1223.91	582
1227.14	556
1230.36	552
1233.58	542
1236.8	596
1240.02	534
1243.23	550
1246.45	542
1249.67	580
1252.88	544
1256.09	560
1259.3	500
1262.51	540
1265.72	556
1268.93	544
1272.13	552
1275.34	556
1278.54	550
1281.74	530
1284.94	568
1288.15	561
1291.34	564
1294.54	552
1297.74	540
1300.93	556
1304.12	560
1307.32	570
1310.51	556
1313.7	596
1316.89	562
1320.07	578
1323.26	582
1326.45	596
1329.63	620
1332.81	582
1335.99	624
1339.17	594
1342.35	630
1345.53	630
1348.71	610
1351.88	612
1355.06	612
1358.23	602
1361.4	590
1364.57	584
1367.74	594
1370.91	554
1374.08	580
1377.24	568
1380.41	582
1383.57	572
1386.73	552
1389.89	586
1393.05	562
1396.21	538
1399.37	550
1402.52	572
1405.68	550
1408.83	558
1411.98	544
1415.13	534
1418.29	542
1421.43	568
1424.58	562
1427.73	554
1430.87	538
1434.02	540
1437.16	526
1440.3	500
1443.44	570
1446.58	578
1449.72	534
1452.85	514
1455.99	550
1459.12	534
1462.26	556
1465.39	540
1468.52	542
1471.65	544
1474.78	562
1477.9	562
1481.03	570
1484.16	574
1487.28	542
1490.4	562
1493.52	546
1496.64	584
1499.76	564
1502.88	562
1506	574
1509.11	580
1512.22	568
1515.34	550
1518.45	568
1521.56	576
1524.67	572
1527.78	560
1530.88	584
1533.99	572
1537.09	568
1540.2	572
1543.3	582
1546.4	598
1549.5	572
1552.6	610
1555.7	630
1558.79	590
1561.89	570
1564.98	588
1568.08	606
1571.17	608
1574.26	600
1577.35	602
1580.43	612
1583.52	610
1586.61	640
1589.69	612
1592.77	632
1595.86	600
1598.94	594
1602.02	598
1605.1	632
1608.18	582.923
1611.25	581.384
1614.33	573.41
1617.4	586.029
1620.47	573.967
1623.55	586.639
1626.62	557.007
1629.69	579.761
1632.75	556.504
1635.82	563.284
1638.89	544.461
1641.95	554.221
1645.02	535.07
1648.08	537.745
1651.14	547.744
1654.2	538.539
1657.26	538.178
1660.32	537.776
1663.37	539.345
1666.43	529.856
1669.48	547.821
1672.54	519.343
1675.59	504.501
1678.64	524.882
1681.69	521.578
1684.74	519.095
1687.79	512.69
1690.83	529.125
1693.88	519.341
1696.92	523.066
1699.96	510.496
1703.01	527.878
1706.05	516.431
1709.09	520.625
1712.12	532.67
1715.16	535.314
1718.2	526.324
1721.23	510.984
1724.27	511.259
1727.3	524.231
1730.33	521.175
1733.36	495.082
1736.39	492.21
1739.42	509.103
1742.44	504.365
1745.47	491.507
1748.49	479.162
1751.52	493.183
1754.54	497.988
1757.56	481.627
1759.14	496
1762.18	468
1765.21	494
1768.24	482
1771.27	500
1774.3	474
1777.32	474
1780.35	486
1783.38	508
1786.4	510
1789.42	492
1792.44	494
1795.47	496
1798.48	492
1801.5	512
1804.52	504
1807.54	500
1810.55	498
1813.57	472
1816.58	484
1819.59	498
1822.6	480
1825.61	498
1828.62	488
1831.63	508
1834.63	496
1837.64	514
1840.64	494
1843.64	494
1846.64	502
1849.64	468
1852.64	500
1855.64	510
1858.64	496
1861.64	504
1864.63	462
1867.63	502
1870.62	508
1873.61	494
1876.6	524
1879.59	514
1882.58	482
1885.56	516
1888.55	506
1891.54	486
1894.52	496
1897.5	492
1900.48	524
1903.46	498
1906.44	498
1909.42	516
1912.4	500
1915.38	500
1918.35	528
1921.32	496
1924.3	540
1927.27	506
1930.24	520
1933.21	522
1936.18	512
1939.15	510
1942.11	514
1945.08	510
1948.04	504
1951	496
1953.97	522
1956.93	492
1959.89	506
1962.85	516
1965.8	512
1968.76	478
1971.71	476
1974.67	502
1977.62	510
1980.57	508
1983.53	522
1986.48	490
1989.42	480
1992.37	506
1995.32	476
1998.26	502
2001.21	508
2004.15	508
2007.09	502
2010.03	496
2012.98	520
2015.92	508
2018.85	514
2021.79	510
2024.73	504
2027.66	528
2030.59	504
2033.53	524
2036.46	524
2039.39	506
2042.32	520
2045.25	530
2048.17	530
2051.1	520
2054.02	534
2056.95	530
2059.87	534
2062.79	530
2065.71	518
2068.63	518
2071.55	524
2074.47	516
2077.39	542
2080.3	514
2083.22	524
2086.13	502
2089.04	520
2091.95	498
2094.86	512
2097.77	510
2100.68	504
2103.59	538
2106.49	510
2109.4	530
2112.3	508
2115.21	522
2118.11	526
2121.01	530
2123.91	520
2126.8	532
2129.7	526
2132.6	518
2135.49	524
2138.39	508
2141.28	498
2144.17	540
2147.06	544
2149.95	544
2152.84	522
2155.73	526
2158.62	530
2161.5	522
2164.39	552
2167.27	524
2170.15	508
2173.04	526
2175.92	532
2178.79	530
2181.67	532
2184.55	518
2187.43	526
2190.3	522
2193.18	522
2196.05	558
2198.92	540
2201.79	548
2204.66	528
2207.53	500
2210.4	528
2213.27	520
2216.13	528
2219	498
2221.86	518
2224.72	496
2227.59	528
2230.45	516
2233.31	522
2236.16	508
2239.02	518
2241.88	534
2244.73	498
2247.59	532
2250.44	536
2253.29	488
2256.15	534
2259	514
2261.84	512
2264.69	514
2267.54	504
2270.39	528
2273.23	528
2276.07	536
2278.92	544
2281.76	526
2284.6	528
2287.44	528
2290.28	532
2293.12	540
2295.95	548
2298.79	532
2301.62	546
2304.46	538
2307.29	562
2310.12	534
2312.95	552
2315.78	556
2318.61	576
2321.44	556
2324.27	576
2327.09	616
2329.92	622
2332.74	588
2335.56	596
2338.38	548
2341.2	606
2344.02	588
2346.84	600
2349.66	602
2352.48	596
2355.29	612
2358.11	618
2360.92	618
2363.73	628
2366.54	650
2369.35	602
2372.16	650
2374.97	644
2377.78	658
2380.58	630
2383.39	682
2386.19	672
2389	676
2391.8	688
2394.6	668
2397.4	650
2400.2	694
2403	668
2405.79	706
2408.59	706
2411.38	704
2414.18	674
2416.97	676
2419.76	692
2422.55	688
2425.34	706
2428.13	712
2430.92	718
2433.71	696
2436.49	738
2439.28	706
2442.06	720
2444.85	708
2447.63	712
2450.41	716
2453.19	694
2455.97	704
2458.75	714
2461.52	714
2464.3	702
2467.07	700
2469.85	714
2472.62	704
2475.39	676
2478.16	698
2480.94	692
2483.7	698
2486.47	694
2489.24	678
2492	706
2494.77	668
2497.53	722
2500.3	712
2503.06	710
2505.82	692
2508.58	684
2511.34	706
2514.1	702
2516.85	700
2519.61	718
2522.37	722
2525.12	702
2527.87	702
2530.63	716
2533.38	736
2536.13	724
2538.88	704
2541.62	704
2544.37	702
2547.12	700
2549.86	698
2552.61	708
2555.35	714
2558.09	690
2560.84	704
2563.57	692
2566.32	694
2569.05	718
2571.79	734
2574.53	714
2577.26	686
2580	678
2582.73	700
2585.46	712
2588.19	710
2590.93	740
2593.66	726
2596.39	702
2599.11	716
2601.84	696
2604.56	698
2607.29	702
2610.01	710
2612.74	722
2615.46	710
2618.18	742
2620.9	706
2623.62	704
2626.34	734
2629.05	712
2631.77	724
2634.48	760
2637.2	742
2639.91	746
2642.62	778
2645.33	748
2648.05	754
2650.75	768
2653.46	764
2656.17	764
2658.88	750
2661.58	750
2664.29	764
2666.99	748
2669.69	774
2672.39	766
2675.09	734
2677.79	772
2680.49	764
2683.19	756
2685.89	770
2688.58	748
2691.28	762
2693.97	738
2696.67	764
2699.36	772
2702.05	766
2704.74	734
2707.43	754
2710.12	744
2712.8	762
2715.49	774
2718.17	770
2720.86	766
2723.54	776
2726.22	750
2728.91	790
2731.59	788
2734.27	768
2736.95	772
2739.62	764
2742.3	796
2744.98	778
2747.65	738
2750.33	760
2753	812
2755.67	786
2758.34	812
2761.01	784
2763.68	806
2766.35	836
2769.02	808
2771.68	828
2774.35	810
2777.01	794
2779.68	788
2782.34	802
2785	780
2787.66	820
2790.32	808
2792.98	840
2795.64	818
2798.3	824
2800.95	836
2803.61	850
2806.26	788
2808.91	844
2811.57	852
2814.22	824
2816.87	836
2819.52	830
2822.17	844
2824.81	868
2827.46	856
2830.11	848
2832.75	852
2835.39	826
2838.04	846
2840.68	868
2843.32	856
2845.96	898
2848.6	892
2851.24	860
2853.88	876
2856.51	848
2859.15	890
2861.78	896
2864.42	884
2867.05	918
2869.68	874
2872.31	930
2874.94	872
2877.57	916
2880.2	906
2882.82	898
2885.45	910
2888.08	908
2890.7	912
2893.33	930
2895.95	920
2898.57	940
2901.19	924
2903.81	924
2906.43	944
2909.05	926
2911.66	930
2914.28	950
2916.89	942
2919.51	967.372
2922.12	963.524
2924.73	936.931
2927.35	931.633
2929.96	928.426
2932.57	966.098
2935.17	954.769
2937.78	969.016
2940.39	944.693
2943	987.075
2945.6	954.966
2948.2	951.64
2950.81	975.029
2953.41	974.835
2956.01	964.727
2958.61	999.858
2961.21	962.577
2963.81	969.47
2966.41	980.617
2969.01	981.616
2971.6	971.305
2974.2	984.275
2976.79	996.554
2979.39	982.62
2981.98	989.012
2984.57	991.552
2987.16	991.983
2989.75	1001.8
2992.34	1030.73
2994.93	1010.09
2997.51	990.709
3000.1	1033.29
3002.68	1024.29
3005.27	1038.36
3007.85	1019.45
3010.43	1022.88
3013.01	1035.1
3015.59	1040
3018.18	1025.25
3020.75	1021.43
3023.33	1048.27
3025.91	1039.9
3028.48	1082.91
3031.06	1072.87
3033.64	1062.48
3036.21	1077.47
3038.78	1049.13
3041.35	1073.9
3043.92	1076.17
3046.49	1091.56
3048.11	1060
3050.69	1070
3053.27	1106
3055.85	1088
3058.43	1074
3061.01	1090
3063.58	1094
3066.16	1060
3068.73	1110
3071.31	1124
3073.88	1122
3076.45	1134
3079.02	1136
3081.59	1106
3084.16	1090
3086.73	1152
3089.29	1100
3091.86	1148
3094.43	1156
3096.99	1132
3099.55	1166
3102.12	1138
3104.68	1118
3107.24	1180
3109.8	1158
3112.36	1142
3114.92	1160
3117.48	1186
3120.03	1182
3122.59	1186
3125.14	1170
3127.7	1198
3130.25	1192
3132.8	1202
3135.35	1200
3137.9	1200
3140.45	1204
3143	1208
3145.55	1258
3148.1	1226
3150.64	1254
3153.19	1270
3155.73	1216
3158.28	1212
3160.82	1266
3163.36	1266
3165.9	1250
3168.44	1286
3170.98	1216
3173.52	1262
3176.06	1268
3178.59	1250
3181.13	1258
3183.66	1298
3186.2	1284
3188.73	1290
3191.26	1310
3193.79	1266
3196.32	1290
3198.85	1276
3201.38	1300
3203.91	1286
3206.44	1292
3208.96	1298
3211.49	1312
3214.01	1356
3216.54	1304
3219.06	1366
3221.58	1352
3224.1	1348
3226.62	1330
3229.14	1314
3231.66	1306
3234.18	1334
3236.69	1336
3239.21	1354
3241.72	1334
3244.24	1350
3246.75	1322
3249.26	1384
3251.78	1396
3254.29	1338
3256.8	1402
3259.3	1372
3261.81	1378
3264.32	1384
3266.83	1396
3269.33	1456
3271.84	1384
3274.34	1436
3276.84	1434
3279.35	1432
3281.85	1452
3284.35	1424
3286.85	1446
3289.35	1446
3291.84	1472
3294.34	1462
3296.84	1444
3299.33	1462
3301.83	1466
3304.32	1502
3306.81	1486
3309.3	1488
3311.79	1504
3314.29	1510
3316.77	1470
3319.26	1524
3321.75	1522
3324.24	1534
3326.72	1556
3329.21	1502
3331.69	1518
3334.18	1482
3336.66	1512
3339.14	1558
3341.62	1538
3344.1	1532
3346.58	1540
3349.06	1524
3351.54	1552
3354.01	1540
3356.49	1544
3358.96	1614
3361.44	1556
3363.91	1566
3366.38	1580
3368.85	1586
3371.33	1572
3373.8	1584
3376.26	1576
3378.73	1586
3381.2	1606
3383.67	1606
3386.13	1654
3388.6	1644
3391.06	1632
3393.52	1594
3395.99	1596
3398.45	1590
3400.91	1652
3403.37	1660
3405.83	1636
3408.29	1620
3410.74	1620
3413.2	1678
3415.66	1632
3418.11	1652
3420.56	1660
3423.02	1660
3425.47	1672
3427.92	1688
3430.37	1694
3432.82	1672
3435.27	1708
3437.72	1678
3440.17	1700
3442.61	1748
3445.06	1758
3447.51	1736
3449.95	1732
3452.39	1774
3454.83	1792
3457.28	1768
3459.72	1782
3462.16	1798
3464.6	1814
3467.04	1790
3469.47	1784
3471.91	1776
3474.34	1790
3476.78	1800
3479.21	1784
3481.65	1790
3484.08	1822
3486.51	1818
3488.94	1806
3491.37	1770
3493.8	1812
3496.23	1812
3498.66	1790
3501.09	1820
3503.51	1842
3505.94	1828
3508.36	1854
3510.79	1858
3513.21	1842
3515.63	1812
3518.05	1876
3520.47	1846
3522.89	1874
3525.31	1854
3527.73	1774
3530.14	1832
3532.56	1858
3534.98	1866
3537.39	1852
3539.81	1860
3542.22	1848
3544.63	1890
3547.04	1848
3549.45	1874
3551.86	1848
3554.27	1900
3556.68	1904
3559.09	1900
3561.49	1902
3563.9	1870
3566.3	1920
3568.71	1942
3571.11	1916
3573.51	1950
3575.92	1900
3578.32	1980
3580.72	1940
3583.12	1912
3585.51	1976
3587.91	1994
3590.31	1962
3592.71	1992
3595.1	2022
3597.49	1992
3599.89	2044
3602.28	1986
3604.67	2022
3607.06	2054
3609.45	2046
3611.84	2046
3614.23	2040
3616.62	2078
3619.01	2072
3621.39	2036
3623.78	2084
3626.17	2102
3628.55	2038
3630.93	2102
3633.31	2080
3635.7	2068
3638.08	2080
3640.46	2068
3642.84	2078
3645.22	2090
3647.59	2092
3649.97	2078
3652.35	2042
3654.72	2082
3657.1	2104
3659.47	2076
3661.84	2084
3664.21	2102
3666.59	2070
3668.96	2104
3671.33	2056
3673.69	2142
3676.06	2124
3678.43	2088
3680.8	2082
3683.16	2162
3685.53	2090
3687.89	2138
3690.25	2128
3692.62	2184
3694.98	2160
3697.34	2136
3699.7	2104
3702.06	2140
3704.42	2132
3706.78	2162
3709.13	2116
3711.49	2154
3713.85	2202
3716.2	2162
3718.56	2222
3720.91	2216
3723.26	2216
3725.61	2194
3727.96	2220
3730.31	2186
3732.66	2228
3735.01	2254
3737.36	2208
3739.7	2260
3742.05	2270
3744.4	2292
3746.74	2260
3749.09	2242
3751.43	2294
3753.77	2288
3756.11	2306
3758.45	2288
3760.79	2288
3763.13	2310
3765.47	2342
3767.81	2360
3770.14	2312
3772.48	2328
3774.82	2310
3777.15	2370
3779.48	2342
3781.82	2328
3784.15	2328
3786.48	2360
3788.81	2352
3791.14	2354
3793.47	2330
3795.8	2316
3798.13	2350
3800.45	2360
3802.78	2306
3805.1	2348
3807.43	2350
3809.75	2358
3812.07	2366
3814.4	2336
3816.72	2358
3819.04	2398
3821.36	2360
3823.68	2362
3826	2384
3828.31	2360
3830.63	2396
3832.95	2422
3835.26	2336
3837.58	2370
3839.89	2392
3842.2	2376
3844.51	2326
3846.83	2420
3849.14	2330
3851.45	2422
3853.76	2370
3856.06	2440
3858.37	2406
3860.68	2422
3862.98	2432
3865.29	2412
3867.59	2420
3869.9	2416
3872.2	2402
3874.5	2394
3876.8	2464
3879.1	2464
3881.4	2462
3883.7	2428
3886	2468
3888.3	2502
3890.6	2548
3892.89	2512
3895.19	2554
3897.48	2540
3899.78	2478
3902.07	2548
3904.36	2464
3906.65	2560
3908.94	2552
3911.23	2560
3913.52	2554
3915.81	2588
3918.1	2560
3920.39	2528
3922.67	2568
3924.96	2602
3927.24	2558
3929.53	2578
3931.81	2594
3934.09	2602
3936.38	2606
3938.66	2586
3940.94	2592
3943.22	2586
3945.5	2606
3947.77	2556
3950.05	2608
3952.33	2620
3954.6	2548
3956.88	2552
3959.15	2596
3961.43	2614
3963.7	2630
3965.97	2616
3968.24	2602
3970.51	2616
3972.78	2652
3975.05	2610
3977.32	2630
3979.59	2612
3981.85	2594
3984.12	2614
3986.39	2618
3988.65	2568
3990.91	2582
3993.18	2584
3995.44	2624
3997.7	2648
3999.96	2616