File: DataDrivenSE/datosramana/CN-Sastre_01.txt
#Acq. time (s)=	20
#Accumulations=	2
#Range (cm-¹)=	50...4000
#Windows=	3
#Autofocus=	Off
#AutoExposure=	Off
#Spike filter=	Multiple accum.
#Delay time (s)=	0
#Binning=	1
#Readout mode=	Signal
#DeNoise=	Off
#ICS correction=	Off
#Dark correction=	Off
#Inst. Process=	Off
#Instrument=	LabRAM HR Evol
#Detector=	Syncerity OE
#Objective=	x100_VIS
#Grating=	600 (500nm)
#ND Filter=	100%
#Laser=	532nm_Edge
#Hole=	100.021
#Range=	Visible
#Project=	Omar
#Sample=
#Site=	21-09-22
#Title=	 CN-Sastre
#Remark=
#Date=	21.09.2022 12:02
#Acquired=	21.09.2022 12:02:32
51.0918	40
54.7807	44
58.4681	64
62.154	110
65.8385	210
69.5216	328
73.2032	512
76.8834	748
80.5621	944
84.2393	1108
87.9152	1250
91.5874	1306
95.2603	1264
98.9318	1260
102.602	1292
106.27	1346
109.936	1320
113.601	1352
117.266	1300
120.926	1312
124.588	1310
128.246	1328
131.904	1272
135.561	1284
139.215	1240
142.869	1312
146.52	1250
150.171	1244
153.819	1304
157.465	1264
161.112	1266
164.756	1244
168.398	1202
172.041	1232
175.68	1240
179.318	1208
182.955	1230
186.592	1246
190.225	1212
193.857	1232
197.488	1182
201.118	1208
204.746	1188
208.372	1208
211.997	1204
215.621	1210
219.243	1194
222.864	1214
226.483	1160
230.101	1164
233.718	1168
237.331	1200
240.945	1160
244.557	1184
248.168	1198
251.776	1182
255.384	1142
258.991	1154
262.594	1196
266.198	1144
269.799	1178
273.4	1182
277	1198
280.596	1156
284.193	1184
287.786	1166
291.378	1176
294.971	1192
298.561	1184
302.148	1202
305.737	1206
309.322	1212
312.906	1232
316.49	1236
320.071	1256
323.651	1190
327.229	1226
330.806	1192
334.381	1256
337.955	1224
341.528	1236
345.099	1238
348.669	1236
352.238	1260
355.805	1230
359.371	1258
362.935	1258
366.498	1246
370.06	1228
373.62	1256
377.177	1240
380.734	1256
384.29	1290
387.845	1282
391.396	1266
394.948	1264
398.499	1270
402.046	1294
405.594	1264
409.138	1270
412.683	1290
416.225	1280
419.768	1228
423.307	1232
426.844	1288
430.382	1268
433.917	1288
437.451	1300
440.985	1314
444.516	1306
448.045	1260
451.574	1302
455.102	1302
458.628	1240
462.152	1292
465.674	1264
469.196	1308
472.716	1292
476.234	1292
479.752	1288
483.268	1260
486.782	1256
490.295	1242
493.807	1204
497.316	1228
500.825	1260
504.333	1238
507.839	1248
511.344	1228
514.846	1246
518.349	1226
521.85	1266
525.347	1298
528.846	1326
532.341	1382
535.837	1452
539.329	1568
542.822	1602
546.312	1594
549.802	1696
553.289	1694
556.775	1688
560.261	1658
563.744	1684
567.226	1660
570.709	1616
574.188	1578
577.665	1610
581.142	1518
584.617	1492
588.091	1492
591.565	1408
595.036	1386
598.506	1420
601.974	1366
605.442	1368
608.905	1306
612.37	1226
615.833	1264
619.295	1292
622.755	1208
626.215	1222
629.67	1250
633.127	1176
636.582	1148
640.036	1112
643.487	1124
646.938	1142
650.386	1108
653.835	1070
657.282	1022
660.726	1034
664.171	1014
667.613	978
671.053	972
674.494	934
677.931	896
681.369	924
684.804	882
688.238	854
691.67	904
695.103	848
698.533	826
701.961	788
705.389	800
708.814	790
712.239	750
715.662	768
719.084	748
722.505	784
725.924	752
729.342	728
732.759	746
736.174	716
739.589	712
742.999	752
746.411	724
749.821	732
753.23	746
756.636	738
760.043	784
763.448	764
766.85	778
770.252	752
773.652	800
777.052	788
780.448	782
783.846	802
787.24	782
790.635	806
794.027	752
797.417	760
800.808	734
804.196	768
807.582	740
810.968	728
814.354	700
817.736	698
821.118	692
824.498	704
827.877	638
831.254	648
834.631	632
838.006	642
841.38	610
844.752	608
848.123	616
851.493	626
854.86	608
858.228	640
861.594	614
864.959	626
868.321	622
871.683	586
875.044	620
878.402	588
881.761	622
885.116	644
888.472	626
891.825	600
895.179	622
898.529	648
901.88	646
905.228	656
908.575	664
911.922	704
915.266	664
918.609	712
921.951	714
925.293	774
928.633	760
931.97	804
935.307	760
938.642	776
941.977	812
945.31	832
948.641	862
951.972	858
955.301	852
958.629	838
961.955	862
965.279	812
968.603	846
971.926	792
975.248	844
978.566	868
981.886	832
985.204	912
988.519	884
991.834	880
995.147	922
998.46	876
1001.77	922
1005.08	932
1008.39	948
1011.7	976
1015	976
1018.3	1034
1021.61	1022
1024.91	990
1028.21	1090
1031.51	1120
1034.81	1130
1038.1	1170
1041.4	1188
1044.69	1206
1047.99	1204
1051.28	1274
1054.57	1262
1057.86	1314
1061.14	1336
1064.43	1396
1067.72	1422
1071	1498
1074.28	1516
1077.57	1570
1080.84	1610
1084.12	1636
1087.4	1614
1090.68	1626
1093.95	1602
1097.22	1636
1100.5	1590
1103.77	1616
1107.04	1554
1110.31	1532
1113.58	1470
1116.84	1406
1120.1	1350
1123.37	1340
1126.63	1248
1129.89	1248
1133.15	1170
1136.41	1136
1139.67	1092
1142.92	1078
1146.18	1022
1149.43	1034
1152.68	964
1155.93	954
1159.18	890
1162.43	938
1165.68	856
1168.93	828
1172.17	858
1175.41	798
1178.66	814
1181.9	790
1185.14	792
1188.37	772
1191.61	752
1194.85	754
1198.08	702
1201.31	714
1204.55	680
1207.78	658
1211.01	682
1214.24	642
1217.46	642
1220.69	638
1223.91	650
1227.14	596
1230.36	612
1233.58	580
1236.8	620
1240.02	604
1243.23	594
1246.45	616
1249.67	604
1252.88	584
1256.09	580
1259.3	608
1262.51	586
1265.72	584
1268.93	588
1272.13	602
1275.34	590
1278.54	602
1281.74	572
1284.94	590
1288.15	591
1291.34	594
1294.54	586
1297.74	584
1300.93	628
1304.12	604
1307.32	604
1310.51	622
1313.7	608
1316.89	578
1320.07	606
1323.26	590
1326.45	618
1329.63	634
1332.81	630
1335.99	608
1339.17	610
1342.35	594
1345.53	608
1348.71	608
1351.88	590
1355.06	630
1358.23	624
1361.4	632
1364.57	590
1367.74	620
1370.91	584
1374.08	594
1377.24	602
1380.41	610
1383.57	608
1386.73	618
1389.89	616
1393.05	594
1396.21	616
1399.37	612
1402.52	598
1405.68	578
1408.83	608
1411.98	618
1415.13	612
1418.29	628
1421.43	628
1424.58	604
1427.73	616
1430.87	632
1434.02	608
1437.16	606
1440.3	634
1443.44	598
1446.58	640
1449.72	620
1452.85	596
1455.99	646
1459.12	622
1462.26	628
1465.39	636
1468.52	624
1471.65	626
1474.78	624
1477.9	586
1481.03	614
1484.16	628
1487.28	616
1490.4	642
1493.52	622
1496.64	652
1499.76	636
1502.88	632
1506	616
1509.11	630
1512.22	640
1515.34	646
1518.45	624
1521.56	628
1524.67	652
1527.78	634
1530.88	632
1533.99	658
1537.09	636
1540.2	640
1543.3	636
1546.4	656
1549.5	638
1552.6	632
1555.7	682
1558.79	644
1561.89	658
1564.98	614
1568.08	650
1571.17	660
1574.26	650
1577.35	628
1580.43	652
1583.52	668
1586.61	600
1589.69	662
1592.77	662
1595.86	632
1598.94	614
1602.02	630
1605.1	650
1608.18	613.539
1611.25	649.873
1614.33	611.323
1617.4	637.95
1620.47	650.095
1623.55	622.02
1626.62	638.922
1629.69	667.891
1632.75	619.562
1635.82	635.111
1638.89	626.96
1641.95	634.547
1645.02	643.273
1648.08	629.954
1651.14	634.22
1654.2	630.897
1657.26	639.331
1660.32	631.542
1663.37	626.578
1666.43	620.51
1669.48	603.3
1672.54	628.016
1675.59	642.121
1678.64	634.485
1681.69	628.064
1684.74	646.521
1687.79	618.63
1690.83	635.608
1693.88	615.26
1696.92	634.611
1699.96	628.17
1703.01	639.187
1706.05	628.948
1709.09	633.347
1712.12	636.456
1715.16	634.369
1718.2	620.279
1721.23	618.438
1724.27	623.801
1727.3	633.454
1730.33	634.871
1733.36	608.353
1736.39	622.854
1739.42	620.261
1742.44	620.982
1745.47	610.187
1748.49	632.569
1751.52	602.675
1754.54	603.93
1757.56	621.073
1759.14	600
1762.18	624
1765.21	616
1768.24	650
1771.27	600
1774.3	600
1777.32	626
1780.35	620
1783.38	616
1786.4	614
1789.42	610
1792.44	628
1795.47	640
1798.48	608
1801.5	624
1804.52	628
1807.54	606
1810.55	584
1813.57	616
1816.58	614
1819.59	604
1822.6	664
1825.61	612
1828.62	606
1831.63	604
1834.63	624
1837.64	626
1840.64	648
1843.64	640
1846.64	618
1849.64	612
1852.64	606
1855.64	636
1858.64	612
1861.64	622
1864.63	656
1867.63	648
1870.62	624
1873.61	646
1876.6	630
1879.59	616
1882.58	630
1885.56	598
1888.55	612
1891.54	630
1894.52	614
1897.5	640
1900.48	660
1903.46	606
1906.44	612
1909.42	622
1912.4	584
1915.38	646
1918.35	622
1921.32	638
1924.3	638
1927.27	654
1930.24	640
1933.21	638
1936.18	642
1939.15	626
1942.11	634
1945.08	614
1948.04	624
1951	646
1953.97	634
1956.93	642
1959.89	634
1962.85	630
1965.8	638
1968.76	610
1971.71	620
1974.67	634
1977.62	648
1980.57	594
1983.53	612
1986.48	614
1989.42	642
1992.37	622
1995.32	642
1998.26	622
2001.21	628
2004.15	624
2007.09	614
2010.03	624
2012.98	658
2015.92	634
2018.85	630
2021.79	614
2024.73	634
2027.66	632
2030.59	646
2033.53	646
2036.46	640
2039.39	636
2042.32	646
2045.25	652
2048.17	646
2051.1	658
2054.02	664
2056.95	638
2059.87	672
2062.79	650
2065.71	644
2068.63	658
2071.55	666
2074.47	658
2077.39	644
2080.3	626
2083.22	632
2086.13	624
2089.04	620
2091.95	664
2094.86	646
2097.77	644
2100.68	648
2103.59	654
2106.49	614
2109.4	662
2112.3	640
2115.21	654
2118.11	652
2121.01	634
2123.91	642
2126.8	654
2129.7	642
2132.6	638
2135.49	672
2138.39	636
2141.28	636
2144.17	648
2147.06	646
2149.95	656
2152.84	646
2155.73	664
2158.62	656
2161.5	638
2164.39	662
2167.27	668
2170.15	650
2173.04	676
2175.92	638
2178.79	674
2181.67	670
2184.55	662
2187.43	648
2190.3	674
2193.18	636
2196.05	656
2198.92	646
2201.79	632
2204.66	662
2207.53	636
2210.4	644
2213.27	652
2216.13	642
2219	654
2221.86	652
2224.72	636
2227.59	634
2230.45	634
2233.31	636
2236.16	636
2239.02	634
2241.88	610
2244.73	632
2247.59	634
2250.44	648
2253.29	628
2256.15	642
2259	632
2261.84	630
2264.69	632
2267.54	624
2270.39	630
2273.23	640
2276.07	634
2278.92	642
2281.76	638
2284.6	654
2287.44	634
2290.28	660
2293.12	640
2295.95	658
2298.79	650
2301.62	624
2304.46	686
2307.29	650
2310.12	662
2312.95	678
2315.78	674
2318.61	680
2321.44	692
2324.27	646
2327.09	728
2329.92	740
2332.74	702
2335.56	698
2338.38	682
2341.2	698
2344.02	702
2346.84	730
2349.66	728
2352.48	730
2355.29	728
2358.11	748
2360.92	742
2363.73	768
2366.54	772
2369.35	772
2372.16	774
2374.97	760
2377.78	774
2380.58	760
2383.39	768
2386.19	784
2389	744
2391.8	784
2394.6	774
2397.4	772
2400.2	798
2403	804
2405.79	796
2408.59	802
2411.38	796
2414.18	786
2416.97	824
2419.76	788
2422.55	830
2425.34	812
2428.13	820
2430.92	818
2433.71	834
2436.49	822
2439.28	810
2442.06	788
2444.85	792
2447.63	806
2450.41	814
2453.19	806
2455.97	822
2458.75	792
2461.52	838
2464.3	830
2467.07	828
2469.85	810
2472.62	804
2475.39	778
2478.16	816
2480.94	816
2483.7	818
2486.47	836
2489.24	828
2492	850
2494.77	842
2497.53	836
2500.3	798
2503.06	802
2505.82	834
2508.58	814
2511.34	812
2514.1	830
2516.85	828
2519.61	826
2522.37	808
2525.12	826
2527.87	812
2530.63	826
2533.38	812
2536.13	814
2538.88	836
2541.62	800
2544.37	846
2547.12	812
2549.86	804
2552.61	832
2555.35	804
2558.09	828
2560.84	808
2563.57	810
2566.32	826
2569.05	844
2571.79	794
2574.53	818
2577.26	820
2580	832
2582.73	796
2585.46	834
2588.19	834
2590.93	782
2593.66	814
2596.39	836
2599.11	820
2601.84	810
2604.56	880
2607.29	832
2610.01	836
2612.74	826
2615.46	874
2618.18	868
2620.9	860
2623.62	862
2626.34	846
2629.05	844
2631.77	848
2634.48	828
2637.2	852
2639.91	866
2642.62	818
2645.33	856
2648.05	852
2650.75	884
2653.46	870
2656.17	824
2658.88	866
2661.58	864
2664.29	862
2666.99	850
2669.69	872
2672.39	876
2675.09	850
2677.79	870
2680.49	868
2683.19	880
2685.89	854
2688.58	856
2691.28	878
2693.97	874
2696.67	878
2699.36	852
2702.05	852
2704.74	846
2707.43	878
2710.12	878
2712.8	860
2715.49	880
2718.17	906
2720.86	868
2723.54	860
2726.22	888
2728.91	884
2731.59	892
2734.27	872
2736.95	880
2739.62	914
2742.3	856
2744.98	892
2747.65	868
2750.33	918
2753	918
2755.67	912
2758.34	938
2761.01	890
2763.68	896
2766.35	906
2769.02	890
2771.68	902
2774.35	912
2777.01	938
2779.68	920
2782.34	928
2785	916
2787.66	920
2790.32	944
2792.98	910
2795.64	938
2798.3	942
2800.95	936
2803.61	958
2806.26	964
2808.91	964
2811.57	960
2814.22	956
2816.87	954
2819.52	936
2822.17	978
2824.81	920
2827.46	980
2830.11	970
2832.75	982
2835.39	976
2838.04	980
2840.68	934
2843.32	1006
2845.96	984
2848.6	998
2851.24	990
2853.88	958
2856.51	970
2859.15	1000
2861.78	1000
2864.42	996
2867.05	976
2869.68	994
2872.31	1028
2874.94	1012
2877.57	1022
2880.2	1030
2882.82	1012
2885.45	1030
2888.08	1004
2890.7	1004
2893.33	1044
2895.95	1012
2898.57	1034
2901.19	1052
2903.81	1030
2906.43	1052
2909.05	1030
2911.66	1022
2914.28	1034
2916.89	1052
2919.51	1029.94
2922.12	1035.03
2924.73	1049.02
2927.35	1025.58
2929.96	1080.54
2932.57	1066.73
2935.17	1070.48
2937.78	1050.4
2940.39	1039.25
2943	1063.09
2945.6	1059.65
2948.2	1064.94
2950.81	1083.88
2953.41	1086.96
2956.01	1046.07
2958.61	1096.21
2961.21	1060.04
2963.81	1075.34
2966.41	1107.89
2969.01	1090.29
2971.6	1084.12
2974.2	1081.73
2976.79	1079.03
2979.39	1108.04
2981.98	1105.21
2984.57	1065.39
2987.16	1124.18
2989.75	1110.54
2992.34	1112.67
2994.93	1120.4
2997.51	1117.02
3000.1	1110.47
3002.68	1134.24
3005.27	1140.1
3007.85	1132.99
3010.43	1153.79
3013.01	1165.48
3015.59	1174.87
3018.18	1168.6
3020.75	1154.52
3023.33	1155.27
3025.91	1150.51
3028.48	1163.84
3031.06	1156.1
3033.64	1180.15
3036.21	1198.07
3038.78	1151.36
3041.35	1188.93
3043.92	1192.09
3046.49	1210.49
3048.11	1192
3050.69	1204
3053.27	1218
3055.85	1160
3058.43	1224
3061.01	1200
3063.58	1176
3066.16	1208
3068.73	1244
3071.31	1220
3073.88	1254
3076.45	1260
3079.02	1238
3081.59	1232
3084.16	1246
3086.73	1250
3089.29	1278
3091.86	1238
3094.43	1296
3096.99	1256
3099.55	1256
3102.12	1282
3104.68	1256
3107.24	1280
3109.8	1256
3112.36	1310
3114.92	1282
3117.48	1312
3120.03	1310
3122.59	1284
3125.14	1308
3127.7	1320
3130.25	1312
3132.8	1288
3135.35	1364
3137.9	1354
3140.45	1356
3143	1320
3145.55	1338
3148.1	1344
3150.64	1318
3153.19	1306
3155.73	1360
3158.28	1336
3160.82	1334
3163.36	1364
3165.9	1392
3168.44	1302
3170.98	1400
3173.52	1416
3176.06	1420
3178.59	1382
3181.13	1408
3183.66	1398
3186.2	1430
3188.73	1434
3191.26	1388
3193.79	1468
3196.32	1416
3198.85	1448
3201.38	1430
3203.91	1432
3206.44	1450
3208.96	1434
3211.49	1434
3214.01	1430
3216.54	1436
3219.06	1428
3221.58	1394
3224.1	1466
3226.62	1482
3229.14	1448
3231.66	1430
3234.18	1458
3236.69	1472
3239.21	1458
3241.72	1434
3244.24	1498
3246.75	1452
3249.26	1454
3251.78	1484
3254.29	1500
3256.8	1484
3259.3	1498
3261.81	1508
3264.32	1528
3266.83	1530
3269.33	1498
3271.84	1520
3274.34	1530
3276.84	1566
3279.35	1554
3281.85	1568
3284.35	1552
3286.85	1592
3289.35	1588
3291.84	1578
3294.34	1598
3296.84	1542
3299.33	1590
3301.83	1588
3304.32	1600
3306.81	1572
3309.3	1582
3311.79	1604
3314.29	1622
3316.77	1644
3319.26	1638
3321.75	1662
3324.24	1624
3326.72	1626
3329.21	1636
3331.69	1640
3334.18	1646
3336.66	1632
3339.14	1674
3341.62	1618
3344.1	1686
3346.58	1646
3349.06	1666
3351.54	1662
3354.01	1682
3356.49	1688
3358.96	1724
3361.44	1670
3363.91	1684
3366.38	1678
3368.85	1690
3371.33	1718
3373.8	1682
3376.26	1732
3378.73	1704
3381.2	1744
3383.67	1702
3386.13	1698
3388.6	1744
3391.06	1766
3393.52	1740
3395.99	1764
3398.45	1780
3400.91	1760
3403.37	1750
3405.83	1786
3408.29	1768
3410.74	1758
3413.2	1770
3415.66	1766
3418.11	1798
3420.56	1814
3423.02	1814
3425.47	1802
3427.92	1856
3430.37	1822
3432.82	1848
3435.27	1850
3437.72	1858
3440.17	1844
3442.61	1894
3445.06	1854
3447.51	1880
3449.95	1882
3452.39	1848
3454.83	1906
3457.28	1906
3459.72	1962
3462.16	1938
3464.6	1896
3467.04	1936
3469.47	1852
3471.91	1960
3474.34	1952
3476.78	1916
3479.21	1900
3481.65	1924
3484.08	1964
3486.51	1944
3488.94	1974
3491.37	1986
3493.8	1956
3496.23	1982
3498.66	1952
3501.09	1966
3503.51	1958
3505.94	1932
3508.36	1954
3510.79	1948
3513.21	1972
3515.63	1910
3518.05	1944
3520.47	1972
3522.89	1964
3525.31	1982
3527.73	1992
3530.14	1966
3532.56	1980
3534.98	1910
3537.39	1990
3539.81	1972
3542.22	1982
3544.63	1956
3547.04	1994
3549.45	1976
3551.86	1994
3554.27	2024
3556.68	2000
3559.09	2068
3561.49	1988
3563.9	1990
3566.3	2000
3568.71	2068
3571.11	2058
3573.51	2060
3575.92	2044
3578.32	2076
3580.72	2084
3583.12	2078
3585.51	2064
3587.91	2134
3590.31	2122
3592.71	2104
3595.1	2068
3597.49	2142
3599.89	2134
3602.28	2154
3604.67	2164
3607.06	2150
3609.45	2220
3611.84	2158
3614.23	2186
3616.62	2180
3619.01	2196
3621.39	2178
3623.78	2174
3626.17	2206
3628.55	2192
3630.93	2216
3633.31	2236
3635.7	2138
3638.08	2152
3640.46	2188
3642.84	2208
3645.22	2178
3647.59	2242
3649.97	2188
3652.35	2216
3654.72	2220
3657.1	2194
3659.47	2202
3661.84	2250
3664.21	2200
3666.59	2202
3668.96	2216
3671.33	2220
3673.69	2220
3676.06	2262
3678.43	2270
3680.8	2174
3683.16	2234
3685.53	2234
3687.89	2238
3690.25	2248
3692.62	2278
3694.98	2270
3697.34	2268
3699.7	2296
3702.06	2292
3704.42	2284
3706.78	2250
3709.13	2300
3711.49	2288
3713.85	2294
3716.2	2300
3718.56	2312
3720.91	2334
3723.26	2348
3725.61	2336
3727.96	2288
3730.31	2352
3732.66	2360
3735.01	2418
3737.36	2378
3739.7	2392
3742.05	2392
3744.4	2410
3746.74	2410
3749.09	2406
3751.43	2448
3753.77	2428
3756.11	2450
3758.45	2460
3760.79	2458
3763.13	2442
3765.47	2490
3767.81	2386
3770.14	2490
3772.48	2484
3774.82	2454
3777.15	2478
3779.48	2502
3781.82	2466
3784.15	2498
3786.48	2482
3788.81	2456
3791.14	2504
3793.47	2494
3795.8	2498
3798.13	2424
3800.45	2448
3802.78	2526
3805.1	2472
3807.43	2520
3809.75	2412
3812.07	2502
3814.4	2474
3816.72	2470
3819.04	2524
3821.36	2516
3823.68	2490
3826	2522
3828.31	2474
3830.63	2498
3832.95	2534
3835.26	2488
3837.58	2496
3839.89	2504
3842.2	2516
3844.51	2448
3846.83	2480
3849.14	2498
3851.45	2518
3853.76	2522
3856.06	2504
3858.37	2536
3860.68	2552
3862.98	2564
3865.29	2548
3867.59	2562
3869.9	2568
3872.2	2546
3874.5	2614
3876.8	2618
3879.1	2608
3881.4	2630
3883.7	2578
3886	2648
3888.3	2614
3890.6	2630
3892.89	2628
3895.19	2604
3897.48	2678
3899.78	2690
3902.07	2706
3904.36	2692
3906.65	2738
3908.94	2720
3911.23	2670
3913.52	2728
3915.81	2714
3918.1	2648
3920.39	2680
3922.67	2710
3924.96	2732
3927.24	2736
3929.53	2746
3931.81	2722
3934.09	2712
3936.38	2712
3938.66	2764
3940.94	2730
3943.22	2662
3945.5	2702
3947.77	2778
3950.05	2704
3952.33	2664
3954.6	2708
3956.88	2732
3959.15	2736
3961.43	2740
3963.7	2762
3965.97	2714
3968.24	2772
3970.51	2740
3972.78	2786
3975.05	2706
3977.32	2772
3979.59	2770
3981.85	2720
3984.12	2724
3986.39	2758
3988.65	2758
3990.91	2672
3993.18	2744
3995.44	2784
3997.7	2760
3999.96	2776