File: DataDrivenSE/datosramana/CN-Sastre_07.txt
#Acq. time (s)=	20
#Accumulations=	2
#Range (cm-¹)=	50...4000
#Windows=	3
#Autofocus=	Off
#AutoExposure=	Off
#Spike filter=	Multiple accum.
#Delay time (s)=	0
#Binning=	1
#Readout mode=	Signal
#DeNoise=	Off
#ICS correction=	Off
#Dark correction=	Off
#Inst. Process=	Off
#Instrument=	LabRAM HR Evol
#Detector=	Syncerity OE
#Objective=	x100_VIS
#Grating=	600 (500nm)
#ND Filter=	100%
#Laser=	532nm_Edge
#Hole=	100.021
#Range=	Visible
#Project=	Omar
#Sample=
#Site=	21-09-22
#Title=	 CN-Sastre
#Remark=
#Date=	21.09.2022 12:58
#Acquired=	21.09.2022 12:58:37
51.0918	52
54.7807	48
58.4681	76
62.154	172
65.8385	294
69.5216	438
73.2032	770
76.8834	1038
80.5621	1284
84.2393	1606
87.9152	1690
91.5874	1862
95.2603	1750
98.9318	1736
102.602	1768
106.27	1876
109.936	1846
113.601	1802
117.266	1838
120.926	1830
124.588	1764
128.246	1768
131.904	1712
135.561	1770
139.215	1720
142.869	1780
146.52	1650
150.171	1756
153.819	1788
157.465	1730
161.112	1658
164.756	1636
168.398	1652
172.041	1686
175.68	1630
179.318	1618
182.955	1646
186.592	1666
190.225	1628
193.857	1644
197.488	1594
201.118	1620
204.746	1610
208.372	1596
211.997	1586
215.621	1614
219.243	1548
222.864	1544
226.483	1514
230.101	1516
233.718	1588
237.331	1452
240.945	1556
244.557	1560
248.168	1516
251.776	1556
255.384	1532
258.991	1562
262.594	1582
266.198	1558
269.799	1564
273.4	1526
277	1536
280.596	1526
284.193	1540
287.786	1546
291.378	1578
294.971	1574
298.561	1536
302.148	1554
305.737	1598
309.322	1626
312.906	1566
316.49	1632
320.071	1560
323.651	1622
327.229	1636
330.806	1586
334.381	1646
337.955	1614
341.528	1564
345.099	1582
348.669	1604
352.238	1604
355.805	1648
359.371	1552
362.935	1632
366.498	1650
370.06	1644
373.62	1626
377.177	1680
380.734	1684
384.29	1680
387.845	1638
391.396	1706
394.948	1684
398.499	1702
402.046	1682
405.594	1598
409.138	1612
412.683	1646
416.225	1664
419.768	1632
423.307	1648
426.844	1630
430.382	1644
433.917	1610
437.451	1618
440.985	1714
444.516	1700
448.045	1656
451.574	1704
455.102	1682
458.628	1672
462.152	1660
465.674	1692
469.196	1692
472.716	1702
476.234	1642
479.752	1658
483.268	1682
486.782	1650
490.295	1572
493.807	1628
497.316	1592
500.825	1684
504.333	1618
507.839	1602
511.344	1610
514.846	1638
518.349	1580
521.85	1670
525.347	1742
528.846	1754
532.341	1850
535.837	1872
539.329	1900
542.822	2026
546.312	2110
549.802	2142
553.289	2172
556.775	2188
560.261	2186
563.744	2202
567.226	2142
570.709	2134
574.188	2056
577.665	2072
581.142	2016
584.617	1966
588.091	1934
591.565	1858
595.036	1892
598.506	1732
601.974	1796
605.442	1744
608.905	1700
612.37	1636
615.833	1620
619.295	1620
622.755	1590
626.215	1590
629.67	1486
633.127	1504
636.582	1492
640.036	1520
643.487	1398
646.938	1440
650.386	1388
653.835	1324
657.282	1334
660.726	1320
664.171	1272
667.613	1270
671.053	1246
674.494	1194
677.931	1182
681.369	1170
684.804	1130
688.238	1126
691.67	1080
695.103	1084
698.533	1060
701.961	1020
705.389	998
708.814	964
712.239	962
715.662	914
719.084	936
722.505	942
725.924	952
729.342	914
732.759	896
736.174	886
739.589	934
742.999	914
746.411	940
749.821	920
753.23	938
756.636	912
760.043	974
763.448	928
766.85	928
770.252	962
773.652	966
777.052	998
780.448	980
783.846	984
787.24	932
790.635	936
794.027	932
797.417	944
800.808	914
804.196	918
807.582	900
810.968	916
814.354	848
817.736	830
821.118	868
824.498	800
827.877	780
831.254	820
834.631	782
838.006	800
841.38	758
844.752	730
848.123	750
851.493	716
854.86	730
858.228	738
861.594	740
864.959	746
868.321	728
871.683	756
875.044	750
878.402	740
881.761	752
885.116	772
888.472	768
891.825	754
895.179	792
898.529	790
901.88	784
905.228	824
908.575	812
911.922	818
915.266	844
918.609	866
921.951	886
925.293	928
928.633	932
931.97	938
935.307	984
938.642	986
941.977	1022
945.31	1006
948.641	1022
951.972	1046
955.301	1038
958.629	1062
961.955	1038
965.279	1006
968.603	1008
971.926	1010
975.248	1044
978.566	1092
981.886	1064
985.204	1084
988.519	1098
991.834	1124
995.147	1122
998.46	1124
1001.77	1158
1005.08	1168
1008.39	1198
1011.7	1172
1015	1216
1018.3	1246
1021.61	1316
1024.91	1302
1028.21	1344
1031.51	1360
1034.81	1416
1038.1	1464
1041.4	1452
1044.69	1538
1047.99	1578
1051.28	1604
1054.57	1590
1057.86	1670
1061.14	1722
1064.43	1786
1067.72	1796
1071	1858
1074.28	1944
1077.57	1942
1080.84	2022
1084.12	2028
1087.4	2078
1090.68	2172
1093.95	2116
1097.22	2096
1100.5	2102
1103.77	2022
1107.04	2044
1110.31	1926
1113.58	1900
1116.84	1790
1120.1	1720
1123.37	1684
1126.63	1630
1129.89	1616
1133.15	1520
1136.41	1436
1139.67	1406
1142.92	1358
1146.18	1298
1149.43	1304
1152.68	1228
1155.93	1166
1159.18	1110
1162.43	1114
1165.68	1160
1168.93	1062
1172.17	1038
1175.41	1034
1178.66	984
1181.9	976
1185.14	928
1188.37	918
1191.61	918
1194.85	882
1198.08	890
1201.31	862
1204.55	814
1207.78	818
1211.01	804
1214.24	816
1217.46	828
1220.69	766
1223.91	738
1227.14	732
1230.36	738
1233.58	726
1236.8	730
1240.02	702
1243.23	730
1246.45	726
1249.67	714
1252.88	684
1256.09	676
1259.3	720
1262.51	712
1265.72	730
1268.93	748
1272.13	708
1275.34	728
1278.54	724
1281.74	714
1284.94	724
1288.15	732
1291.34	740
1294.54	754
1297.74	766
1300.93	752
1304.12	742
1307.32	726
1310.51	746
1313.7	706
1316.89	766
1320.07	766
1323.26	758
1326.45	776
1329.63	804
1332.81	800
1335.99	806
1339.17	806
1342.35	810
1345.53	794
1348.71	840
1351.88	822
1355.06	804
1358.23	812
1361.4	838
1364.57	850
1367.74	818
1370.91	812
1374.08	780
1377.24	786
1380.41	772
1383.57	730
1386.73	736
1389.89	796
1393.05	752
1396.21	720
1399.37	704
1402.52	748
1405.68	734
1408.83	744
1411.98	718
1415.13	730
1418.29	700
1421.43	774
1424.58	744
1427.73	754
1430.87	720
1434.02	744
1437.16	742
1440.3	744
1443.44	736
1446.58	736
1449.72	756
1452.85	782
1455.99	750
1459.12	748
1462.26	730
1465.39	726
1468.52	740
1471.65	728
1474.78	746
1477.9	756
1481.03	740
1484.16	746
1487.28	728
1490.4	758
1493.52	746
1496.64	742
1499.76	728
1502.88	758
1506	756
1509.11	752
1512.22	762
1515.34	744
1518.45	782
1521.56	742
1524.67	764
1527.78	774
1530.88	772
1533.99	760
1537.09	792
1540.2	772
1543.3	788
1546.4	772
1549.5	784
1552.6	798
1555.7	756
1558.79	794
1561.89	808
1564.98	772
1568.08	782
1571.17	806
1574.26	824
1577.35	800
1580.43	844
1583.52	832
1586.61	868
1589.69	826
1592.77	828
1595.86	834
1598.94	806
1602.02	828
1605.1	814
1608.18	799.746
1611.25	772.574
1614.33	814.817
1617.4	794.872
1620.47	784.318
1623.55	752.029
1626.62	756.791
1629.69	769.272
1632.75	741.037
1635.82	722.68
1638.89	733.16
1641.95	687.289
1645.02	688.301
1648.08	701.351
1651.14	691.003
1654.2	707.529
1657.26	723.73
1660.32	679.652
1663.37	690.31
1666.43	691.974
1669.48	710.97
1672.54	687.486
1675.59	669.487
1678.64	706.038
1681.69	683.143
1684.74	694.035
1687.79	675.109
1690.83	672.499
1693.88	673.374
1696.92	668.742
1699.96	663.909
1703.01	643.048
1706.05	653.141
1709.09	659.64
1712.12	658.409
1715.16	659.554
1718.2	648.055
1721.23	648.357
1724.27	643.685
1727.3	651.415
1730.33	607.107
1733.36	635.724
1736.39	642.269
1739.42	638.316
1742.44	625.486
1745.47	609.693
1748.49	627.602
1751.52	599.232
1754.54	640.87
1757.56	563.134
1759.14	618
1762.18	614
1765.21	582
1768.24	608
1771.27	624
1774.3	600
1777.32	576
1780.35	604
1783.38	616
1786.4	632
1789.42	610
1792.44	610
1795.47	634
1798.48	632
1801.5	636
1804.52	624
1807.54	556
1810.55	610
1813.57	598
1816.58	632
1819.59	610
1822.6	580
1825.61	576
1828.62	604
1831.63	604
1834.63	604
1837.64	592
1840.64	610
1843.64	646
1846.64	582
1849.64	624
1852.64	616
1855.64	598
1858.64	626
1861.64	604
1864.63	596
1867.63	582
1870.62	610
1873.61	588
1876.6	622
1879.59	626
1882.58	606
1885.56	594
1888.55	620
1891.54	618
1894.52	642
1897.5	610
1900.48	616
1903.46	618
1906.44	626
1909.42	612
1912.4	598
1915.38	650
1918.35	676
1921.32	620
1924.3	620
1927.27	634
1930.24	618
1933.21	608
1936.18	600
1939.15	594
1942.11	586
1945.08	632
1948.04	622
1951	618
1953.97	618
1956.93	606
1959.89	624
1962.85	606
1965.8	628
1968.76	610
1971.71	630
1974.67	618
1977.62	608
1980.57	610
1983.53	596
1986.48	626
1989.42	606
1992.37	610
1995.32	612
1998.26	632
2001.21	616
2004.15	632
2007.09	642
2010.03	602
2012.98	622
2015.92	594
2018.85	614
2021.79	634
2024.73	590
2027.66	618
2030.59	628
2033.53	618
2036.46	606
2039.39	630
2042.32	622
2045.25	646
2048.17	620
2051.1	638
2054.02	602
2056.95	616
2059.87	632
2062.79	600
2065.71	614
2068.63	606
2071.55	636
2074.47	628
2077.39	634
2080.3	620
2083.22	608
2086.13	652
2089.04	618
2091.95	628
2094.86	628
2097.77	642
2100.68	614
2103.59	584
2106.49	622
2109.4	612
2112.3	630
2115.21	610
2118.11	624
2121.01	632
2123.91	624
2126.8	626
2129.7	628
2132.6	622
2135.49	596
2138.39	614
2141.28	656
2144.17	622
2147.06	652
2149.95	638
2152.84	646
2155.73	620
2158.62	582
2161.5	638
2164.39	622
2167.27	664
2170.15	598
2173.04	618
2175.92	628
2178.79	626
2181.67	600
2184.55	624
2187.43	602
2190.3	600
2193.18	620
2196.05	630
2198.92	640
2201.79	630
2204.66	602
2207.53	612
2210.4	614
2213.27	624
2216.13	614
2219	614
2221.86	618
2224.72	618
2227.59	630
2230.45	594
2233.31	612
2236.16	612
2239.02	594
2241.88	602
2244.73	584
2247.59	610
2250.44	616
2253.29	594
2256.15	614
2259	614
2261.84	594
2264.69	608
2267.54	600
2270.39	626
2273.23	598
2276.07	612
2278.92	622
2281.76	642
2284.6	598
2287.44	612
2290.28	596
2293.12	602
2295.95	620
2298.79	626
2301.62	644
2304.46	620
2307.29	594
2310.12	644
2312.95	646
2315.78	610
2318.61	622
2321.44	638
2324.27	646
2327.09	640
2329.92	702
2332.74	646
2335.56	664
2338.38	664
2341.2	650
2344.02	650
2346.84	694
2349.66	656
2352.48	690
2355.29	666
2358.11	642
2360.92	668
2363.73	678
2366.54	690
2369.35	688
2372.16	680
2374.97	678
2377.78	676
2380.58	712
2383.39	736
2386.19	698
2389	716
2391.8	698
2394.6	696
2397.4	742
2400.2	726
2403	742
2405.79	714
2408.59	722
2411.38	738
2414.18	776
2416.97	732
2419.76	734
2422.55	746
2425.34	788
2428.13	758
2430.92	778
2433.71	748
2436.49	722
2439.28	784
2442.06	744
2444.85	756
2447.63	746
2450.41	774
2453.19	748
2455.97	724
2458.75	782
2461.52	752
2464.3	788
2467.07	788
2469.85	760
2472.62	748
2475.39	734
2478.16	754
2480.94	734
2483.7	762
2486.47	778
2489.24	772
2492	744
2494.77	734
2497.53	758
2500.3	758
2503.06	764
2505.82	740
2508.58	770
2511.34	720
2514.1	736
2516.85	730
2519.61	732
2522.37	738
2525.12	762
2527.87	760
2530.63	736
2533.38	722
2536.13	754
2538.88	748
2541.62	768
2544.37	758
2547.12	740
2549.86	750
2552.61	758
2555.35	742
2558.09	750
2560.84	724
2563.57	754
2566.32	756
2569.05	754
2571.79	756
2574.53	780
2577.26	752
2580	766
2582.73	708
2585.46	762
2588.19	744
2590.93	740
2593.66	766
2596.39	808
2599.11	810
2601.84	774
2604.56	736
2607.29	774
2610.01	798
2612.74	778
2615.46	744
2618.18	772
2620.9	780
2623.62	754
2626.34	792
2629.05	782
2631.77	780
2634.48	758
2637.2	790
2639.91	804
2642.62	800
2645.33	784
2648.05	788
2650.75	786
2653.46	802
2656.17	790
2658.88	792
2661.58	812
2664.29	820
2666.99	806
2669.69	818
2672.39	818
2675.09	808
2677.79	828
2680.49	854
2683.19	854
2685.89	832
2688.58	774
2691.28	790
2693.97	830
2696.67	816
2699.36	808
2702.05	826
2704.74	812
2707.43	812
2710.12	818
2712.8	828
2715.49	798
2718.17	820
2720.86	858
2723.54	812
2726.22	798
2728.91	828
2731.59	856
2734.27	850
2736.95	830
2739.62	814
2742.3	832
2744.98	830
2747.65	838
2750.33	824
2753	822
2755.67	826
2758.34	836
2761.01	822
2763.68	830
2766.35	840
2769.02	872
2771.68	832
2774.35	818
2777.01	866
2779.68	852
2782.34	886
2785	848
2787.66	864
2790.32	840
2792.98	852
2795.64	860
2798.3	848
2800.95	858
2803.61	856
2806.26	892
2808.91	846
2811.57	840
2814.22	874
2816.87	878
2819.52	908
2822.17	862
2824.81	860
2827.46	888
2830.11	866
2832.75	830
2835.39	878
2838.04	874
2840.68	872
2843.32	894
2845.96	902
2848.6	894
2851.24	936
2853.88	932
2856.51	928
2859.15	858
2861.78	914
2864.42	896
2867.05	896
2869.68	922
2872.31	944
2874.94	908
2877.57	878
2880.2	898
2882.82	936
2885.45	934
2888.08	942
2890.7	904
2893.33	940
2895.95	920
2898.57	930
2901.19	962
2903.81	922
2906.43	952
2909.05	906
2911.66	916
2914.28	932
2916.89	958
2919.51	927.743
2922.12	978.341
2924.73	979.804
2927.35	980.978
2929.96	948.178
2932.57	950.98
2935.17	982.662
2937.78	955.449
2940.39	942.343
2943	968.377
2945.6	973.856
2948.2	979.651
2950.81	995.909
2953.41	964.796
2956.01	967.642
2958.61	957.564
2961.21	980.868
2963.81	991.998
2966.41	975.415
2969.01	977.144
2971.6	977.456
2974.2	993.599
2976.79	964.686
2979.39	985.105
2981.98	985.875
2984.57	992.638
2987.16	983.584
2989.75	1008.97
2992.34	968.989
2994.93	986.547
2997.51	981.837
3000.1	996.913
3002.68	1001.16
3005.27	1017.4
3007.85	999.725
3010.43	1014.4
3013.01	1015.82
3015.59	991.132
3018.18	997.899
3020.75	1023.45
3023.33	1018.48
3025.91	1009.24
3028.48	1025.15
3031.06	1007.56
3033.64	1023.31
3036.21	1055.73
3038.78	1049.14
3041.35	1044.73
3043.92	1022.88
3046.49	1066.02
3048.11	1074
3050.69	1068
3053.27	1064
3055.85	1042
3058.43	1076
3061.01	1056
3063.58	1060
3066.16	1058
3068.73	1068
3071.31	1052
3073.88	1098
3076.45	1072
3079.02	1072
3081.59	1078
3084.16	1096
3086.73	1086
3089.29	1126
3091.86	1070
3094.43	1076
3096.99	1108
3099.55	1094
3102.12	1046
3104.68	1122
3107.24	1136
3109.8	1112
3112.36	1146
3114.92	1130
3117.48	1104
3120.03	1156
3122.59	1118
3125.14	1140
3127.7	1126
3130.25	1136
3132.8	1150
3135.35	1186
3137.9	1140
3140.45	1170
3143	1140
3145.55	1174
3148.1	1160
3150.64	1160
3153.19	1168
3155.73	1188
3158.28	1194
3160.82	1168
3163.36	1194
3165.9	1200
3168.44	1190
3170.98	1208
3173.52	1196
3176.06	1166
3178.59	1142
3181.13	1222
3183.66	1230
3186.2	1220
3188.73	1244
3191.26	1220
3193.79	1244
3196.32	1248
3198.85	1202
3201.38	1214
3203.91	1184
3206.44	1260
3208.96	1232
3211.49	1244
3214.01	1238
3216.54	1264
3219.06	1260
3221.58	1252
3224.1	1214
3226.62	1266
3229.14	1266
3231.66	1288
3234.18	1302
3236.69	1268
3239.21	1242
3241.72	1282
3244.24	1268
3246.75	1260
3249.26	1286
3251.78	1312
3254.29	1242
3256.8	1304
3259.3	1270
3261.81	1306
3264.32	1294
3266.83	1292
3269.33	1288
3271.84	1320
3274.34	1294
3276.84	1322
3279.35	1358
3281.85	1368
3284.35	1346
3286.85	1326
3289.35	1340
3291.84	1380
3294.34	1338
3296.84	1382
3299.33	1340
3301.83	1374
3304.32	1408
3306.81	1326
3309.3	1374
3311.79	1382
3314.29	1366
3316.77	1354
3319.26	1416
3321.75	1412
3324.24	1412
3326.72	1406
3329.21	1394
3331.69	1426
3334.18	1386
3336.66	1472
3339.14	1438
3341.62	1388
3344.1	1378
3346.58	1452
3349.06	1460
3351.54	1450
3354.01	1422
3356.49	1440
3358.96	1426
3361.44	1456
3363.91	1454
3366.38	1430
3368.85	1428
3371.33	1468
3373.8	1450
3376.26	1468
3378.73	1438
3381.2	1482
3383.67	1470
3386.13	1434
3388.6	1478
3391.06	1460
3393.52	1460
3395.99	1520
3398.45	1482
3400.91	1490
3403.37	1514
3405.83	1518
3408.29	1470
3410.74	1498
3413.2	1540
3415.66	1520
3418.11	1522
3420.56	1526
3423.02	1536
3425.47	1546
3427.92	1548
3430.37	1564
3432.82	1548
3435.27	1560
3437.72	1582
3440.17	1596
3442.61	1542
3445.06	1594
3447.51	1568
3449.95	1574
3452.39	1592
3454.83	1588
3457.28	1612
3459.72	1646
3462.16	1626
3464.6	1624
3467.04	1630
3469.47	1622
3471.91	1648
3474.34	1664
3476.78	1654
3479.21	1672
3481.65	1668
3484.08	1650
3486.51	1688
3488.94	1638
3491.37	1676
3493.8	1668
3496.23	1662
3498.66	1662
3501.09	1700
3503.51	1620
3505.94	1640
3508.36	1686
3510.79	1676
3513.21	1664
3515.63	1610
3518.05	1690
3520.47	1652
3522.89	1668
3525.31	1644
3527.73	1692
3530.14	1660
3532.56	1592
3534.98	1688
3537.39	1676
3539.81	1682
3542.22	1650
3544.63	1722
3547.04	1702
3549.45	1716
3551.86	1684
3554.27	1742
3556.68	1716
3559.09	1746
3561.49	1726
3563.9	1756
3566.3	1718
3568.71	1746
3571.11	1732
3573.51	1752
3575.92	1770
3578.32	1788
3580.72	1744
3583.12	1804
3585.51	1762
3587.91	1788
3590.31	1812
3592.71	1818
3595.1	1826
3597.49	1830
3599.89	1796
3602.28	1830
3604.67	1834
3607.06	1820
3609.45	1880
3611.84	1852
3614.23	1828
3616.62	1844
3619.01	1868
3621.39	1820
3623.78	1852
3626.17	1882
3628.55	1872
3630.93	1938
3633.31	1868
3635.7	1874
3638.08	1860
3640.46	1912
3642.84	1856
3645.22	1896
3647.59	1854
3649.97	1876
3652.35	1858
3654.72	1880
3657.1	1866
3659.47	1892
3661.84	1904
3664.21	1890
3666.59	1908
3668.96	1856
3671.33	1890
3673.69	1888
3676.06	1852
3678.43	1898
3680.8	1888
3683.16	1928
3685.53	1926
3687.89	1856
3690.25	1864
3692.62	1942
3694.98	1896
3697.34	1904
3699.7	1924
3702.06	1910
3704.42	1928
3706.78	1962
3709.13	1918
3711.49	1932
3713.85	1884
3716.2	1896
3718.56	1932
3720.91	1964
3723.26	1940
3725.61	1992
3727.96	2006
3730.31	1980
3732.66	1978
3735.01	2000
3737.36	2032
3739.7	2024
3742.05	2038
3744.4	2014
3746.74	1976
3749.09	1972
3751.43	2004
3753.77	2010
3756.11	2066
3758.45	2060
3760.79	2042
3763.13	2072
3765.47	2050
3767.81	2040
3770.14	2098
3772.48	2030
3774.82	2066
3777.15	2066
3779.48	2066
3781.82	2094
3784.15	2130
3786.48	2100
3788.81	2082
3791.14	2092
3793.47	2090
3795.8	2100
3798.13	2134
3800.45	2082
3802.78	2092
3805.1	2138
3807.43	2068
3809.75	2082
3812.07	2150
3814.4	2112
3816.72	2146
3819.04	2122
3821.36	2096
3823.68	2078
3826	2066
3828.31	2086
3830.63	2130
3832.95	2100
3835.26	2108
3837.58	2130
3839.89	2104
3842.2	2082
3844.51	2152
3846.83	2120
3849.14	2134
3851.45	2150
3853.76	2136
3856.06	2158
3858.37	2162
3860.68	2110
3862.98	2180
3865.29	2112
3867.59	2132
3869.9	2138
3872.2	2186
3874.5	2150
3876.8	2200
3879.1	2176
3881.4	2232
3883.7	2182
3886	2262
3888.3	2188
3890.6	2180
3892.89	2242
3895.19	2228
3897.48	2254
3899.78	2266
3902.07	2276
3904.36	2272
3906.65	2268
3908.94	2288
3911.23	2280
3913.52	2292
3915.81	2286
3918.1	2282
3920.39	2306
3922.67	2286
3924.96	2346
3927.24	2284
3929.53	2328
3931.81	2262
3934.09	2260
3936.38	2314
3938.66	2314
3940.94	2364
3943.22	2352
3945.5	2330
3947.77	2346
3950.05	2326
3952.33	2308
3954.6	2324
3956.88	2366
3959.15	2334
3961.43	2286
3963.7	2300
3965.97	2302
3968.24	2310
3970.51	2328
3972.78	2304
3975.05	2318
3977.32	2324
3979.59	2294
3981.85	2358
3984.12	2296
3986.39	2388
3988.65	2306
3990.91	2304
3993.18	2340
3995.44	2350
3997.7	2318
3999.96	2336