File: DataDrivenSE/datosramana/CN-Sastre_06.txt
#Acq. time (s)=	20
#Accumulations=	2
#Range (cm-¹)=	50...4000
#Windows=	3
#Autofocus=	Off
#AutoExposure=	Off
#Spike filter=	Multiple accum.
#Delay time (s)=	0
#Binning=	1
#Readout mode=	Signal
#DeNoise=	Off
#ICS correction=	Off
#Dark correction=	Off
#Inst. Process=	Off
#Instrument=	LabRAM HR Evol
#Detector=	Syncerity OE
#Objective=	x100_VIS
#Grating=	600 (500nm)
#ND Filter=	100%
#Laser=	532nm_Edge
#Hole=	100.021
#Range=	Visible
#Project=	Omar
#Sample=
#Site=	21-09-22
#Title=	 CN-Sastre
#Remark=
#Date=	21.09.2022 12:51
#Acquired=	21.09.2022 12:51:21
51.0918	36
54.7807	42
58.4681	72
62.154	142
65.8385	254
69.5216	406
73.2032	696
76.8834	966
80.5621	1214
84.2393	1474
87.9152	1570
91.5874	1638
95.2603	1584
98.9318	1584
102.602	1578
106.27	1678
109.936	1670
113.601	1604
117.266	1680
120.926	1636
124.588	1606
128.246	1574
131.904	1586
135.561	1576
139.215	1598
142.869	1552
146.52	1600
150.171	1586
153.819	1586
157.465	1562
161.112	1586
164.756	1548
168.398	1492
172.041	1526
175.68	1536
179.318	1516
182.955	1518
186.592	1510
190.225	1494
193.857	1476
197.488	1470
201.118	1460
204.746	1492
208.372	1442
211.997	1424
215.621	1428
219.243	1438
222.864	1408
226.483	1368
230.101	1420
233.718	1418
237.331	1400
240.945	1408
244.557	1400
248.168	1426
251.776	1430
255.384	1426
258.991	1430
262.594	1386
266.198	1394
269.799	1390
273.4	1414
277	1366
280.596	1386
284.193	1402
287.786	1422
291.378	1414
294.971	1388
298.561	1394
302.148	1360
305.737	1426
309.322	1400
312.906	1452
316.49	1456
320.071	1444
323.651	1448
327.229	1456
330.806	1426
334.381	1468
337.955	1448
341.528	1442
345.099	1442
348.669	1486
352.238	1444
355.805	1442
359.371	1442
362.935	1468
366.498	1428
370.06	1476
373.62	1470
377.177	1486
380.734	1480
384.29	1506
387.845	1530
391.396	1438
394.948	1514
398.499	1482
402.046	1506
405.594	1482
409.138	1490
412.683	1490
416.225	1452
419.768	1446
423.307	1492
426.844	1496
430.382	1458
433.917	1476
437.451	1460
440.985	1498
444.516	1498
448.045	1442
451.574	1492
455.102	1494
458.628	1512
462.152	1502
465.674	1478
469.196	1514
472.716	1456
476.234	1504
479.752	1490
483.268	1482
486.782	1482
490.295	1448
493.807	1432
497.316	1416
500.825	1392
504.333	1418
507.839	1440
511.344	1422
514.846	1414
518.349	1408
521.85	1462
525.347	1508
528.846	1564
532.341	1596
535.837	1674
539.329	1772
542.822	1850
546.312	1912
549.802	1898
553.289	1986
556.775	1962
560.261	1962
563.744	1940
567.226	1920
570.709	1884
574.188	1908
577.665	1824
581.142	1792
584.617	1728
588.091	1702
591.565	1666
595.036	1638
598.506	1620
601.974	1564
605.442	1544
608.905	1510
612.37	1536
615.833	1456
619.295	1438
622.755	1410
626.215	1426
629.67	1364
633.127	1334
636.582	1292
640.036	1300
643.487	1268
646.938	1224
650.386	1220
653.835	1228
657.282	1168
660.726	1182
664.171	1144
667.613	1132
671.053	1052
674.494	1026
677.931	1038
681.369	1024
684.804	954
688.238	954
691.67	918
695.103	934
698.533	910
701.961	874
705.389	850
708.814	828
712.239	814
715.662	812
719.084	768
722.505	776
725.924	786
729.342	774
732.759	770
736.174	760
739.589	776
742.999	762
746.411	768
749.821	766
753.23	792
756.636	790
760.043	788
763.448	770
766.85	780
770.252	822
773.652	816
777.052	816
780.448	838
783.846	864
787.24	848
790.635	824
794.027	776
797.417	832
800.808	796
804.196	772
807.582	760
810.968	770
814.354	732
817.736	722
821.118	702
824.498	690
827.877	664
831.254	676
834.631	656
838.006	646
841.38	634
844.752	614
848.123	636
851.493	602
854.86	590
858.228	626
861.594	576
864.959	572
868.321	588
871.683	602
875.044	608
878.402	638
881.761	630
885.116	620
888.472	606
891.825	636
895.179	598
898.529	626
901.88	632
905.228	690
908.575	672
911.922	688
915.266	678
918.609	730
921.951	730
925.293	740
928.633	740
931.97	788
935.307	830
938.642	806
941.977	800
945.31	876
948.641	856
951.972	866
955.301	866
958.629	876
961.955	856
965.279	868
968.603	890
971.926	894
975.248	854
978.566	898
981.886	890
985.204	898
988.519	952
991.834	978
995.147	960
998.46	990
1001.77	990
1005.08	992
1008.39	986
1011.7	1052
1015	1034
1018.3	1056
1021.61	1112
1024.91	1102
1028.21	1134
1031.51	1158
1034.81	1202
1038.1	1218
1041.4	1240
1044.69	1282
1047.99	1328
1051.28	1430
1054.57	1398
1057.86	1454
1061.14	1494
1064.43	1538
1067.72	1554
1071	1582
1074.28	1698
1077.57	1734
1080.84	1782
1084.12	1844
1087.4	1812
1090.68	1862
1093.95	1890
1097.22	1856
1100.5	1826
1103.77	1800
1107.04	1720
1110.31	1724
1113.58	1642
1116.84	1602
1120.1	1576
1123.37	1454
1126.63	1442
1129.89	1374
1133.15	1298
1136.41	1226
1139.67	1200
1142.92	1152
1146.18	1100
1149.43	1082
1152.68	1058
1155.93	996
1159.18	982
1162.43	934
1165.68	912
1168.93	872
1172.17	870
1175.41	834
1178.66	838
1181.9	804
1185.14	764
1188.37	736
1191.61	728
1194.85	686
1198.08	720
1201.31	712
1204.55	646
1207.78	624
1211.01	630
1214.24	610
1217.46	612
1220.69	604
1223.91	602
1227.14	574
1230.36	572
1233.58	566
1236.8	552
1240.02	554
1243.23	544
1246.45	538
1249.67	550
1252.88	552
1256.09	522
1259.3	572
1262.51	542
1265.72	540
1268.93	526
1272.13	560
1275.34	548
1278.54	542
1281.74	566
1284.94	550
1288.15	560
1291.34	556
1294.54	562
1297.74	570
1300.93	550
1304.12	560
1307.32	556
1310.51	590
1313.7	554
1316.89	562
1320.07	588
1323.26	578
1326.45	566
1329.63	572
1332.81	598
1335.99	582
1339.17	636
1342.35	588
1345.53	596
1348.71	588
1351.88	578
1355.06	626
1358.23	580
1361.4	606
1364.57	594
1367.74	584
1370.91	582
1374.08	582
1377.24	564
1380.41	576
1383.57	544
1386.73	550
1389.89	546
1393.05	562
1396.21	578
1399.37	534
1402.52	578
1405.68	556
1408.83	542
1411.98	578
1415.13	568
1418.29	570
1421.43	572
1424.58	536
1427.73	552
1430.87	568
1434.02	544
1437.16	578
1440.3	542
1443.44	548
1446.58	556
1449.72	526
1452.85	560
1455.99	552
1459.12	560
1462.26	572
1465.39	552
1468.52	558
1471.65	582
1474.78	576
1477.9	570
1481.03	556
1484.16	556
1487.28	534
1490.4	576
1493.52	588
1496.64	574
1499.76	568
1502.88	590
1506	560
1509.11	586
1512.22	564
1515.34	568
1518.45	590
1521.56	572
1524.67	580
1527.78	568
1530.88	578
1533.99	564
1537.09	572
1540.2	600
1543.3	582
1546.4	582
1549.5	606
1552.6	594
1555.7	604
1558.79	612
1561.89	600
1564.98	604
1568.08	618
1571.17	612
1574.26	620
1577.35	628
1580.43	592
1583.52	638
1586.61	640
1589.69	594
1592.77	608
1595.86	622
1598.94	628
1602.02	602
1605.1	604
1608.18	638.218
1611.25	603.06
1614.33	597.82
1617.4	559.982
1620.47	590.259
1623.55	561.395
1626.62	575.464
1629.69	572.572
1632.75	563.351
1635.82	556.748
1638.89	545.053
1641.95	574.523
1645.02	561.845
1648.08	551.355
1651.14	565.871
1654.2	552.61
1657.26	556.838
1660.32	543.036
1663.37	543.905
1666.43	554.143
1669.48	567.243
1672.54	531.537
1675.59	530.881
1678.64	546.526
1681.69	534.384
1684.74	538.433
1687.79	551.082
1690.83	539.301
1693.88	534.135
1696.92	530.337
1699.96	532.961
1703.01	544.181
1706.05	546.22
1709.09	534.875
1712.12	539.975
1715.16	545.137
1718.2	536.343
1721.23	547.327
1724.27	540.479
1727.3	537.721
1730.33	524.397
1733.36	534.455
1736.39	533.736
1739.42	510.989
1742.44	519.568
1745.47	521.897
1748.49	497.103
1751.52	521.997
1754.54	522.354
1757.56	530.849
1759.14	530
1762.18	496
1765.21	518
1768.24	518
1771.27	510
1774.3	512
1777.32	510
1780.35	510
1783.38	526
1786.4	522
1789.42	518
1792.44	514
1795.47	538
1798.48	512
1801.5	534
1804.52	522
1807.54	540
1810.55	508
1813.57	526
1816.58	506
1819.59	504
1822.6	492
1825.61	550
1828.62	516
1831.63	516
1834.63	504
1837.64	526
1840.64	480
1843.64	506
1846.64	522
1849.64	534
1852.64	514
1855.64	520
1858.64	544
1861.64	516
1864.63	522
1867.63	534
1870.62	506
1873.61	530
1876.6	526
1879.59	536
1882.58	532
1885.56	518
1888.55	518
1891.54	504
1894.52	542
1897.5	538
1900.48	534
1903.46	518
1906.44	520
1909.42	544
1912.4	552
1915.38	552
1918.35	546
1921.32	556
1924.3	554
1927.27	548
1930.24	498
1933.21	538
1936.18	546
1939.15	530
1942.11	530
1945.08	520
1948.04	544
1951	536
1953.97	500
1956.93	530
1959.89	544
1962.85	540
1965.8	514
1968.76	522
1971.71	512
1974.67	552
1977.62	518
1980.57	530
1983.53	526
1986.48	518
1989.42	542
1992.37	506
1995.32	532
1998.26	548
2001.21	546
2004.15	534
2007.09	536
2010.03	526
2012.98	558
2015.92	568
2018.85	542
2021.79	542
2024.73	546
2027.66	558
2030.59	538
2033.53	534
2036.46	562
2039.39	532
2042.32	524
2045.25	514
2048.17	556
2051.1	570
2054.02	544
2056.95	552
2059.87	558
2062.79	548
2065.71	538
2068.63	576
2071.55	550
2074.47	560
2077.39	534
2080.3	550
2083.22	562
2086.13	522
2089.04	572
2091.95	546
2094.86	522
2097.77	562
2100.68	504
2103.59	518
2106.49	528
2109.4	544
2112.3	522
2115.21	562
2118.11	534
2121.01	540
2123.91	546
2126.8	536
2129.7	528
2132.6	538
2135.49	548
2138.39	542
2141.28	566
2144.17	536
2147.06	546
2149.95	554
2152.84	542
2155.73	552
2158.62	556
2161.5	536
2164.39	538
2167.27	558
2170.15	538
2173.04	522
2175.92	542
2178.79	542
2181.67	534
2184.55	546
2187.43	538
2190.3	558
2193.18	538
2196.05	560
2198.92	536
2201.79	556
2204.66	554
2207.53	550
2210.4	544
2213.27	540
2216.13	534
2219	560
2221.86	518
2224.72	548
2227.59	528
2230.45	530
2233.31	546
2236.16	530
2239.02	538
2241.88	556
2244.73	540
2247.59	526
2250.44	530
2253.29	562
2256.15	548
2259	542
2261.84	552
2264.69	528
2267.54	540
2270.39	542
2273.23	554
2276.07	548
2278.92	548
2281.76	544
2284.6	534
2287.44	530
2290.28	568
2293.12	556
2295.95	558
2298.79	560
2301.62	528
2304.46	576
2307.29	546
2310.12	578
2312.95	570
2315.78	560
2318.61	572
2321.44	578
2324.27	586
2327.09	622
2329.92	632
2332.74	626
2335.56	594
2338.38	588
2341.2	588
2344.02	608
2346.84	610
2349.66	604
2352.48	580
2355.29	618
2358.11	620
2360.92	622
2363.73	624
2366.54	606
2369.35	652
2372.16	636
2374.97	622
2377.78	656
2380.58	658
2383.39	656
2386.19	666
2389	666
2391.8	670
2394.6	668
2397.4	660
2400.2	682
2403	666
2405.79	676
2408.59	700
2411.38	684
2414.18	712
2416.97	680
2419.76	660
2422.55	706
2425.34	656
2428.13	734
2430.92	722
2433.71	690
2436.49	700
2439.28	696
2442.06	692
2444.85	678
2447.63	684
2450.41	692
2453.19	716
2455.97	712
2458.75	704
2461.52	692
2464.3	698
2467.07	724
2469.85	680
2472.62	692
2475.39	632
2478.16	706
2480.94	718
2483.7	716
2486.47	690
2489.24	662
2492	698
2494.77	730
2497.53	684
2500.3	704
2503.06	686
2505.82	702
2508.58	684
2511.34	678
2514.1	690
2516.85	696
2519.61	722
2522.37	688
2525.12	710
2527.87	698
2530.63	690
2533.38	690
2536.13	722
2538.88	680
2541.62	690
2544.37	742
2547.12	688
2549.86	690
2552.61	710
2555.35	692
2558.09	714
2560.84	718
2563.57	724
2566.32	720
2569.05	688
2571.79	668
2574.53	694
2577.26	716
2580	696
2582.73	698
2585.46	700
2588.19	710
2590.93	718
2593.66	694
2596.39	738
2599.11	700
2601.84	686
2604.56	708
2607.29	682
2610.01	690
2612.74	744
2615.46	722
2618.18	736
2620.9	746
2623.62	706
2626.34	748
2629.05	720
2631.77	748
2634.48	720
2637.2	734
2639.91	750
2642.62	720
2645.33	736
2648.05	718
2650.75	752
2653.46	740
2656.17	728
2658.88	748
2661.58	786
2664.29	742
2666.99	768
2669.69	796
2672.39	734
2675.09	760
2677.79	746
2680.49	722
2683.19	770
2685.89	788
2688.58	766
2691.28	772
2693.97	760
2696.67	724
2699.36	730
2702.05	764
2704.74	744
2707.43	736
2710.12	766
2712.8	704
2715.49	788
2718.17	740
2720.86	722
2723.54	746
2726.22	790
2728.91	782
2731.59	758
2734.27	762
2736.95	784
2739.62	742
2742.3	746
2744.98	752
2747.65	780
2750.33	764
2753	784
2755.67	790
2758.34	776
2761.01	788
2763.68	806
2766.35	800
2769.02	780
2771.68	800
2774.35	806
2777.01	800
2779.68	768
2782.34	840
2785	808
2787.66	808
2790.32	790
2792.98	774
2795.64	820
2798.3	808
2800.95	780
2803.61	808
2806.26	780
2808.91	810
2811.57	826
2814.22	804
2816.87	840
2819.52	862
2822.17	852
2824.81	810
2827.46	858
2830.11	844
2832.75	852
2835.39	836
2838.04	862
2840.68	864
2843.32	880
2845.96	868
2848.6	838
2851.24	826
2853.88	858
2856.51	852
2859.15	858
2861.78	848
2864.42	860
2867.05	846
2869.68	864
2872.31	890
2874.94	866
2877.57	850
2880.2	862
2882.82	920
2885.45	882
2888.08	892
2890.7	898
2893.33	898
2895.95	860
2898.57	910
2901.19	888
2903.81	930
2906.43	898
2909.05	890
2911.66	930
2914.28	928
2916.89	906
2919.51	890.135
2922.12	896.554
2924.73	871.659
2927.35	924.812
2929.96	933.594
2932.57	936.535
2935.17	918.538
2937.78	938.013
2940.39	907.801
2943	922.59
2945.6	918.802
2948.2	906.636
2950.81	947.829
2953.41	915.275
2956.01	944.845
2958.61	941.426
2961.21	937.049
2963.81	948.253
2966.41	930.043
2969.01	938.269
2971.6	934.488
2974.2	960.62
2976.79	962.017
2979.39	947.93
2981.98	949.972
2984.57	965.85
2987.16	980.468
2989.75	966.848
2992.34	982.505
2994.93	974.611
2997.51	972.466
3000.1	962.754
3002.68	998.349
3005.27	976.451
3007.85	1002.24
3010.43	997.223
3013.01	992.127
3015.59	1003.34
3018.18	998.934
3020.75	990.417
3023.33	997.1
3025.91	999.049
3028.48	989.714
3031.06	1002.62
3033.64	1007.39
3036.21	1020.15
3038.78	1012.74
3041.35	1038.04
3043.92	1022.47
3046.49	1039.81
3048.11	998
3050.69	1052
3053.27	1070
3055.85	1020
3058.43	1050
3061.01	1044
3063.58	1016
3066.16	1080
3068.73	1094
3071.31	1056
3073.88	1076
3076.45	1064
3079.02	1090
3081.59	1094
3084.16	1062
3086.73	1104
3089.29	1104
3091.86	1078
3094.43	1086
3096.99	1100
3099.55	1070
3102.12	1108
3104.68	1122
3107.24	1106
3109.8	1100
3112.36	1128
3114.92	1098
3117.48	1122
3120.03	1110
3122.59	1168
3125.14	1124
3127.7	1108
3130.25	1138
3132.8	1138
3135.35	1134
3137.9	1160
3140.45	1160
3143	1198
3145.55	1180
3148.1	1178
3150.64	1188
3153.19	1202
3155.73	1192
3158.28	1210
3160.82	1192
3163.36	1188
3165.9	1190
3168.44	1196
3170.98	1198
3173.52	1194
3176.06	1202
3178.59	1198
3181.13	1238
3183.66	1226
3186.2	1216
3188.73	1210
3191.26	1238
3193.79	1222
3196.32	1230
3198.85	1244
3201.38	1262
3203.91	1246
3206.44	1240
3208.96	1268
3211.49	1280
3214.01	1244
3216.54	1234
3219.06	1266
3221.58	1272
3224.1	1226
3226.62	1244
3229.14	1274
3231.66	1254
3234.18	1252
3236.69	1276
3239.21	1258
3241.72	1280
3244.24	1262
3246.75	1310
3249.26	1318
3251.78	1308
3254.29	1258
3256.8	1336
3259.3	1286
3261.81	1314
3264.32	1330
3266.83	1316
3269.33	1338
3271.84	1334
3274.34	1334
3276.84	1332
3279.35	1290
3281.85	1364
3284.35	1326
3286.85	1338
3289.35	1352
3291.84	1402
3294.34	1376
3296.84	1378
3299.33	1362
3301.83	1414
3304.32	1390
3306.81	1408
3309.3	1404
3311.79	1366
3314.29	1442
3316.77	1472
3319.26	1434
3321.75	1392
3324.24	1450
3326.72	1422
3329.21	1410
3331.69	1418
3334.18	1430
3336.66	1456
3339.14	1462
3341.62	1484
3344.1	1476
3346.58	1496
3349.06	1436
3351.54	1464
3354.01	1486
3356.49	1438
3358.96	1474
3361.44	1446
3363.91	1492
3366.38	1476
3368.85	1452
3371.33	1468
3373.8	1522
3376.26	1520
3378.73	1510
3381.2	1500
3383.67	1486
3386.13	1510
3388.6	1470
3391.06	1498
3393.52	1502
3395.99	1524
3398.45	1538
3400.91	1556
3403.37	1494
3405.83	1554
3408.29	1596
3410.74	1562
3413.2	1514
3415.66	1570
3418.11	1556
3420.56	1592
3423.02	1576
3425.47	1590
3427.92	1586
3430.37	1590
3432.82	1588
3435.27	1584
3437.72	1618
3440.17	1640
3442.61	1650
3445.06	1630
3447.51	1614
3449.95	1634
3452.39	1642
3454.83	1672
3457.28	1662
3459.72	1660
3462.16	1670
3464.6	1706
3467.04	1722
3469.47	1680
3471.91	1670
3474.34	1728
3476.78	1734
3479.21	1672
3481.65	1702
3484.08	1706
3486.51	1684
3488.94	1714
3491.37	1728
3493.8	1690
3496.23	1722
3498.66	1732
3501.09	1684
3503.51	1730
3505.94	1716
3508.36	1672
3510.79	1730
3513.21	1718
3515.63	1742
3518.05	1706
3520.47	1704
3522.89	1718
3525.31	1706
3527.73	1724
3530.14	1726
3532.56	1700
3534.98	1700
3537.39	1746
3539.81	1762
3542.22	1734
3544.63	1762
3547.04	1782
3549.45	1760
3551.86	1744
3554.27	1798
3556.68	1784
3559.09	1784
3561.49	1786
3563.9	1768
3566.3	1756
3568.71	1826
3571.11	1796
3573.51	1810
3575.92	1828
3578.32	1744
3580.72	1850
3583.12	1816
3585.51	1804
3587.91	1840
3590.31	1860
3592.71	1862
3595.1	1802
3597.49	1844
3599.89	1874
3602.28	1908
3604.67	1878
3607.06	1910
3609.45	1898
3611.84	1910
3614.23	1928
3616.62	1904
3619.01	1946
3621.39	1922
3623.78	1938
3626.17	1954
3628.55	1946
3630.93	1942
3633.31	1922
3635.7	1912
3638.08	1908
3640.46	1908
3642.84	1946
3645.22	1950
3647.59	1880
3649.97	1978
3652.35	1920
3654.72	1936
3657.1	1956
3659.47	1950
3661.84	1958
3664.21	1928
3666.59	1922
3668.96	1924
3671.33	1938
3673.69	1930
3676.06	1980
3678.43	1992
3680.8	1990
3683.16	1932
3685.53	1952
3687.89	1976
3690.25	1978
3692.62	1898
3694.98	2032
3697.34	1984
3699.7	1974
3702.06	1940
3704.42	1978
3706.78	2010
3709.13	2006
3711.49	2010
3713.85	1976
3716.2	2038
3718.56	2002
3720.91	2018
3723.26	2018
3725.61	2038
3727.96	2102
3730.31	2034
3732.66	2050
3735.01	2046
3737.36	2116
3739.7	2052
3742.05	2066
3744.4	2122
3746.74	2130
3749.09	2134
3751.43	2164
3753.77	2138
3756.11	2168
3758.45	2124
3760.79	2096
3763.13	2122
3765.47	2160
3767.81	2190
3770.14	2156
3772.48	2176
3774.82	2162
3777.15	2160
3779.48	2176
3781.82	2178
3784.15	2210
3786.48	2202
3788.81	2192
3791.14	2178
3793.47	2190
3795.8	2240
3798.13	2206
3800.45	2214
3802.78	2148
3805.1	2208
3807.43	2192
3809.75	2166
3812.07	2182
3814.4	2186
3816.72	2164
3819.04	2186
3821.36	2154
3823.68	2212
3826	2160
3828.31	2204
3830.63	2194
3832.95	2188
3835.26	2180
3837.58	2198
3839.89	2200
3842.2	2250
3844.51	2236
3846.83	2256
3849.14	2254
3851.45	2220
3853.76	2294
3856.06	2212
3858.37	2206
3860.68	2194
3862.98	2242
3865.29	2298
3867.59	2256
3869.9	2280
3872.2	2218
3874.5	2278
3876.8	2240
3879.1	2284
3881.4	2258
3883.7	2280
3886	2270
3888.3	2342
3890.6	2288
3892.89	2374
3895.19	2318
3897.48	2326
3899.78	2346
3902.07	2356
3904.36	2374
3906.65	2370
3908.94	2378
3911.23	2352
3913.52	2366
3915.81	2382
3918.1	2406
3920.39	2376
3922.67	2400
3924.96	2368
3927.24	2400
3929.53	2416
3931.81	2414
3934.09	2354
3936.38	2330
3938.66	2390
3940.94	2386
3943.22	2384
3945.5	2404
3947.77	2352
3950.05	2382
3952.33	2374
3954.6	2412
3956.88	2410
3959.15	2398
3961.43	2400
3963.7	2400
3965.97	2392
3968.24	2416
3970.51	2416
3972.78	2418
3975.05	2394
3977.32	2444
3979.59	2416
3981.85	2406
3984.12	2342
3986.39	2412
3988.65	2410
3990.91	2446
3993.18	2454
3995.44	2370
3997.7	2436
3999.96	2420