File: DataDrivenSE/datosramana/CN-Sastre_04.txt
#Acq. time (s)=	20
#Accumulations=	2
#Range (cm-¹)=	50...4000
#Windows=	3
#Autofocus=	Off
#AutoExposure=	Off
#Spike filter=	Multiple accum.
#Delay time (s)=	0
#Binning=	1
#Readout mode=	Signal
#DeNoise=	Off
#ICS correction=	Off
#Dark correction=	Off
#Inst. Process=	Off
#Instrument=	LabRAM HR Evol
#Detector=	Syncerity OE
#Objective=	x100_VIS
#Grating=	600 (500nm)
#ND Filter=	100%
#Laser=	532nm_Edge
#Hole=	100.021
#Range=	Visible
#Project=	Omar
#Sample=
#Site=	21-09-22
#Title=	 CN-Sastre
#Remark=
#Date=	21.09.2022 12:38
#Acquired=	21.09.2022 12:38:52
51.0918	42
54.7807	46
58.4681	72
62.154	166
65.8385	268
69.5216	416
73.2032	734
76.8834	1064
80.5621	1312
84.2393	1618
87.9152	1746
91.5874	1870
95.2603	1790
98.9318	1814
102.602	1804
106.27	1896
109.936	1872
113.601	1916
117.266	1880
120.926	1888
124.588	1846
128.246	1830
131.904	1790
135.561	1812
139.215	1834
142.869	1802
146.52	1790
150.171	1796
153.819	1844
157.465	1806
161.112	1790
164.756	1728
168.398	1712
172.041	1712
175.68	1728
179.318	1690
182.955	1674
186.592	1714
190.225	1676
193.857	1700
197.488	1684
201.118	1626
204.746	1644
208.372	1660
211.997	1640
215.621	1626
219.243	1626
222.864	1566
226.483	1608
230.101	1552
233.718	1520
237.331	1592
240.945	1626
244.557	1624
248.168	1600
251.776	1600
255.384	1588
258.991	1604
262.594	1614
266.198	1598
269.799	1598
273.4	1592
277	1638
280.596	1594
284.193	1594
287.786	1596
291.378	1616
294.971	1594
298.561	1604
302.148	1656
305.737	1674
309.322	1624
312.906	1652
316.49	1646
320.071	1672
323.651	1642
327.229	1690
330.806	1636
334.381	1660
337.955	1674
341.528	1654
345.099	1664
348.669	1688
352.238	1676
355.805	1672
359.371	1654
362.935	1722
366.498	1706
370.06	1698
373.62	1706
377.177	1738
380.734	1750
384.29	1728
387.845	1774
391.396	1702
394.948	1744
398.499	1684
402.046	1744
405.594	1722
409.138	1738
412.683	1764
416.225	1746
419.768	1708
423.307	1738
426.844	1698
430.382	1682
433.917	1700
437.451	1726
440.985	1756
444.516	1722
448.045	1756
451.574	1776
455.102	1764
458.628	1758
462.152	1722
465.674	1744
469.196	1698
472.716	1744
476.234	1760
479.752	1750
483.268	1730
486.782	1698
490.295	1730
493.807	1684
497.316	1638
500.825	1696
504.333	1626
507.839	1660
511.344	1586
514.846	1650
518.349	1680
521.85	1756
525.347	1716
528.846	1756
532.341	1860
535.837	1968
539.329	2052
542.822	2086
546.312	2140
549.802	2264
553.289	2270
556.775	2346
560.261	2274
563.744	2288
567.226	2218
570.709	2172
574.188	2238
577.665	2166
581.142	2100
584.617	2042
588.091	2066
591.565	1896
595.036	1930
598.506	1904
601.974	1862
605.442	1794
608.905	1762
612.37	1710
615.833	1738
619.295	1676
622.755	1636
626.215	1668
629.67	1556
633.127	1554
636.582	1510
640.036	1532
643.487	1490
646.938	1468
650.386	1380
653.835	1364
657.282	1340
660.726	1320
664.171	1312
667.613	1308
671.053	1248
674.494	1240
677.931	1196
681.369	1158
684.804	1124
688.238	1108
691.67	1118
695.103	1048
698.533	1102
701.961	1030
705.389	1002
708.814	992
712.239	998
715.662	972
719.084	954
722.505	920
725.924	922
729.342	926
732.759	928
736.174	908
739.589	922
742.999	906
746.411	900
749.821	950
753.23	888
756.636	914
760.043	938
763.448	964
766.85	940
770.252	970
773.652	976
777.052	936
780.448	954
783.846	1010
787.24	986
790.635	966
794.027	960
797.417	992
800.808	926
804.196	924
807.582	908
810.968	944
814.354	874
817.736	862
821.118	828
824.498	862
827.877	838
831.254	774
834.631	766
838.006	770
841.38	722
844.752	740
848.123	748
851.493	726
854.86	742
858.228	734
861.594	720
864.959	730
868.321	748
871.683	726
875.044	718
878.402	734
881.761	716
885.116	764
888.472	734
891.825	750
895.179	740
898.529	810
901.88	772
905.228	794
908.575	788
911.922	836
915.266	846
918.609	840
921.951	882
925.293	896
928.633	960
931.97	978
935.307	968
938.642	992
941.977	1010
945.31	1012
948.641	1044
951.972	1026
955.301	1058
958.629	1064
961.955	1058
965.279	1050
968.603	1032
971.926	1088
975.248	1086
978.566	1090
981.886	1086
985.204	1118
988.519	1100
991.834	1122
995.147	1174
998.46	1138
1001.77	1180
1005.08	1180
1008.39	1230
1011.7	1234
1015	1182
1018.3	1252
1021.61	1272
1024.91	1278
1028.21	1372
1031.51	1314
1034.81	1430
1038.1	1490
1041.4	1498
1044.69	1520
1047.99	1628
1051.28	1606
1054.57	1656
1057.86	1738
1061.14	1770
1064.43	1860
1067.72	1840
1071	1914
1074.28	1984
1077.57	2010
1080.84	2078
1084.12	2172
1087.4	2158
1090.68	2176
1093.95	2156
1097.22	2200
1100.5	2162
1103.77	2096
1107.04	2102
1110.31	1974
1113.58	1982
1116.84	1892
1120.1	1838
1123.37	1752
1126.63	1658
1129.89	1622
1133.15	1566
1136.41	1530
1139.67	1406
1142.92	1372
1146.18	1350
1149.43	1296
1152.68	1278
1155.93	1206
1159.18	1192
1162.43	1122
1165.68	1110
1168.93	1086
1172.17	1078
1175.41	1026
1178.66	982
1181.9	952
1185.14	964
1188.37	904
1191.61	874
1194.85	870
1198.08	822
1201.31	814
1204.55	788
1207.78	770
1211.01	788
1214.24	752
1217.46	742
1220.69	744
1223.91	756
1227.14	720
1230.36	708
1233.58	700
1236.8	694
1240.02	702
1243.23	676
1246.45	692
1249.67	660
1252.88	696
1256.09	686
1259.3	658
1262.51	682
1265.72	676
1268.93	638
1272.13	638
1275.34	690
1278.54	664
1281.74	662
1284.94	706
1288.15	668
1291.34	674
1294.54	692
1297.74	678
1300.93	690
1304.12	660
1307.32	656
1310.51	650
1313.7	674
1316.89	684
1320.07	688
1323.26	672
1326.45	682
1329.63	678
1332.81	694
1335.99	688
1339.17	710
1342.35	696
1345.53	720
1348.71	696
1351.88	716
1355.06	684
1358.23	688
1361.4	690
1364.57	680
1367.74	714
1370.91	702
1374.08	684
1377.24	684
1380.41	658
1383.57	664
1386.73	672
1389.89	658
1393.05	662
1396.21	674
1399.37	664
1402.52	666
1405.68	710
1408.83	708
1411.98	700
1415.13	688
1418.29	706
1421.43	704
1424.58	672
1427.73	684
1430.87	688
1434.02	686
1437.16	714
1440.3	720
1443.44	664
1446.58	708
1449.72	706
1452.85	700
1455.99	678
1459.12	680
1462.26	696
1465.39	686
1468.52	698
1471.65	712
1474.78	676
1477.9	672
1481.03	716
1484.16	708
1487.28	720
1490.4	668
1493.52	726
1496.64	708
1499.76	700
1502.88	702
1506	714
1509.11	736
1512.22	716
1515.34	724
1518.45	696
1521.56	702
1524.67	724
1527.78	740
1530.88	698
1533.99	718
1537.09	698
1540.2	736
1543.3	700
1546.4	708
1549.5	702
1552.6	720
1555.7	732
1558.79	706
1561.89	746
1564.98	738
1568.08	694
1571.17	722
1574.26	734
1577.35	698
1580.43	712
1583.52	720
1586.61	700
1589.69	742
1592.77	724
1595.86	686
1598.94	666
1602.02	718
1605.1	734
1608.18	686.897
1611.25	729.493
1614.33	671.926
1617.4	717.44
1620.47	661.764
1623.55	714.611
1626.62	688.171
1629.69	697.572
1632.75	676.878
1635.82	684.064
1638.89	697.944
1641.95	710.27
1645.02	683.87
1648.08	682.655
1651.14	680.545
1654.2	672.26
1657.26	677.555
1660.32	665.935
1663.37	670.396
1666.43	654.342
1669.48	674.01
1672.54	676.263
1675.59	667.269
1678.64	665.862
1681.69	680.992
1684.74	669.852
1687.79	654.91
1690.83	669.534
1693.88	664.94
1696.92	648.685
1699.96	660.355
1703.01	663.981
1706.05	673.187
1709.09	655.07
1712.12	648.645
1715.16	660.796
1718.2	659.92
1721.23	658.192
1724.27	624.052
1727.3	637.281
1730.33	643.61
1733.36	642.67
1736.39	634.477
1739.42	657.566
1742.44	635.134
1745.47	640.004
1748.49	627.961
1751.52	617.834
1754.54	610.264
1757.56	630.594
1759.14	642
1762.18	638
1765.21	640
1768.24	640
1771.27	620
1774.3	620
1777.32	604
1780.35	642
1783.38	618
1786.4	614
1789.42	628
1792.44	642
1795.47	640
1798.48	640
1801.5	642
1804.52	620
1807.54	630
1810.55	594
1813.57	636
1816.58	614
1819.59	616
1822.6	642
1825.61	640
1828.62	630
1831.63	614
1834.63	622
1837.64	612
1840.64	646
1843.64	646
1846.64	636
1849.64	616
1852.64	646
1855.64	620
1858.64	630
1861.64	624
1864.63	616
1867.63	640
1870.62	622
1873.61	646
1876.6	600
1879.59	606
1882.58	598
1885.56	646
1888.55	632
1891.54	640
1894.52	650
1897.5	650
1900.48	624
1903.46	648
1906.44	644
1909.42	612
1912.4	638
1915.38	672
1918.35	638
1921.32	624
1924.3	658
1927.27	606
1930.24	638
1933.21	626
1936.18	656
1939.15	636
1942.11	654
1945.08	642
1948.04	636
1951	650
1953.97	632
1956.93	624
1959.89	644
1962.85	640
1965.8	644
1968.76	644
1971.71	636
1974.67	646
1977.62	642
1980.57	628
1983.53	640
1986.48	628
1989.42	626
1992.37	648
1995.32	640
1998.26	650
2001.21	654
2004.15	632
2007.09	652
2010.03	630
2012.98	650
2015.92	634
2018.85	656
2021.79	650
2024.73	634
2027.66	660
2030.59	634
2033.53	676
2036.46	654
2039.39	660
2042.32	638
2045.25	650
2048.17	654
2051.1	650
2054.02	658
2056.95	642
2059.87	654
2062.79	652
2065.71	618
2068.63	658
2071.55	650
2074.47	642
2077.39	630
2080.3	658
2083.22	612
2086.13	650
2089.04	674
2091.95	656
2094.86	658
2097.77	642
2100.68	650
2103.59	642
2106.49	648
2109.4	652
2112.3	658
2115.21	646
2118.11	664
2121.01	656
2123.91	670
2126.8	626
2129.7	642
2132.6	654
2135.49	668
2138.39	662
2141.28	642
2144.17	648
2147.06	656
2149.95	640
2152.84	660
2155.73	650
2158.62	658
2161.5	666
2164.39	648
2167.27	670
2170.15	648
2173.04	666
2175.92	650
2178.79	654
2181.67	660
2184.55	658
2187.43	616
2190.3	648
2193.18	652
2196.05	664
2198.92	642
2201.79	660
2204.66	658
2207.53	656
2210.4	630
2213.27	662
2216.13	634
2219	676
2221.86	624
2224.72	638
2227.59	644
2230.45	622
2233.31	640
2236.16	646
2239.02	602
2241.88	638
2244.73	612
2247.59	642
2250.44	648
2253.29	622
2256.15	624
2259	652
2261.84	646
2264.69	622
2267.54	622
2270.39	608
2273.23	646
2276.07	626
2278.92	634
2281.76	608
2284.6	646
2287.44	650
2290.28	646
2293.12	650
2295.95	664
2298.79	670
2301.62	652
2304.46	676
2307.29	680
2310.12	646
2312.95	680
2315.78	680
2318.61	644
2321.44	696
2324.27	686
2327.09	694
2329.92	712
2332.74	678
2335.56	690
2338.38	690
2341.2	706
2344.02	726
2346.84	704
2349.66	716
2352.48	692
2355.29	702
2358.11	740
2360.92	756
2363.73	754
2366.54	736
2369.35	746
2372.16	766
2374.97	764
2377.78	752
2380.58	756
2383.39	754
2386.19	796
2389	802
2391.8	776
2394.6	764
2397.4	780
2400.2	746
2403	778
2405.79	766
2408.59	798
2411.38	812
2414.18	782
2416.97	772
2419.76	780
2422.55	802
2425.34	808
2428.13	822
2430.92	842
2433.71	818
2436.49	788
2439.28	820
2442.06	816
2444.85	784
2447.63	828
2450.41	816
2453.19	850
2455.97	820
2458.75	794
2461.52	810
2464.3	814
2467.07	840
2469.85	774
2472.62	848
2475.39	806
2478.16	804
2480.94	776
2483.7	800
2486.47	808
2489.24	834
2492	826
2494.77	782
2497.53	822
2500.3	784
2503.06	826
2505.82	832
2508.58	810
2511.34	810
2514.1	804
2516.85	792
2519.61	824
2522.37	822
2525.12	808
2527.87	822
2530.63	802
2533.38	838
2536.13	832
2538.88	818
2541.62	822
2544.37	790
2547.12	838
2549.86	822
2552.61	808
2555.35	788
2558.09	802
2560.84	792
2563.57	832
2566.32	810
2569.05	832
2571.79	790
2574.53	812
2577.26	802
2580	800
2582.73	818
2585.46	828
2588.19	814
2590.93	814
2593.66	828
2596.39	812
2599.11	824
2601.84	824
2604.56	822
2607.29	826
2610.01	784
2612.74	842
2615.46	820
2618.18	800
2620.9	850
2623.62	858
2626.34	780
2629.05	828
2631.77	850
2634.48	826
2637.2	832
2639.91	846
2642.62	840
2645.33	826
2648.05	824
2650.75	854
2653.46	878
2656.17	818
2658.88	844
2661.58	862
2664.29	834
2666.99	846
2669.69	828
2672.39	806
2675.09	822
2677.79	844
2680.49	842
2683.19	846
2685.89	868
2688.58	830
2691.28	862
2693.97	840
2696.67	852
2699.36	864
2702.05	858
2704.74	834
2707.43	824
2710.12	846
2712.8	876
2715.49	844
2718.17	842
2720.86	842
2723.54	860
2726.22	854
2728.91	866
2731.59	840
2734.27	902
2736.95	880
2739.62	876
2742.3	894
2744.98	872
2747.65	882
2750.33	866
2753	856
2755.67	890
2758.34	886
2761.01	896
2763.68	896
2766.35	906
2769.02	906
2771.68	924
2774.35	890
2777.01	910
2779.68	902
2782.34	922
2785	920
2787.66	954
2790.32	924
2792.98	952
2795.64	918
2798.3	940
2800.95	926
2803.61	924
2806.26	916
2808.91	934
2811.57	934
2814.22	958
2816.87	926
2819.52	960
2822.17	952
2824.81	966
2827.46	962
2830.11	948
2832.75	928
2835.39	940
2838.04	962
2840.68	978
2843.32	954
2845.96	966
2848.6	970
2851.24	982
2853.88	956
2856.51	992
2859.15	1010
2861.78	996
2864.42	984
2867.05	974
2869.68	986
2872.31	982
2874.94	992
2877.57	996
2880.2	958
2882.82	990
2885.45	994
2888.08	1004
2890.7	976
2893.33	1002
2895.95	1046
2898.57	988
2901.19	994
2903.81	1016
2906.43	994
2909.05	1016
2911.66	1032
2914.28	1020
2916.89	1024
2919.51	1023.86
2922.12	1049.59
2924.73	1024.29
2927.35	1008.05
2929.96	1049.82
2932.57	1058.36
2935.17	1046.2
2937.78	1030.54
2940.39	1052.67
2943	1042.52
2945.6	1066.2
2948.2	1041.88
2950.81	1063.52
2953.41	1032.64
2956.01	1063.32
2958.61	1049.32
2961.21	1069.43
2963.81	1059.92
2966.41	1055.66
2969.01	1069.12
2971.6	1081.05
2974.2	1058.6
2976.79	1074.66
2979.39	1097.51
2981.98	1076.28
2984.57	1084.53
2987.16	1093.95
2989.75	1097.19
2992.34	1084.55
2994.93	1118.19
2997.51	1107.16
3000.1	1113.63
3002.68	1108.67
3005.27	1100.36
3007.85	1111.84
3010.43	1109.52
3013.01	1112.93
3015.59	1137.26
3018.18	1130.15
3020.75	1120.31
3023.33	1131.22
3025.91	1126.15
3028.48	1128.86
3031.06	1135.91
3033.64	1155.76
3036.21	1156.05
3038.78	1140.91
3041.35	1140.66
3043.92	1194.21
3046.49	1178.18
3048.11	1162
3050.69	1210
3053.27	1192
3055.85	1170
3058.43	1164
3061.01	1184
3063.58	1188
3066.16	1196
3068.73	1192
3071.31	1226
3073.88	1178
3076.45	1210
3079.02	1214
3081.59	1222
3084.16	1186
3086.73	1226
3089.29	1226
3091.86	1218
3094.43	1238
3096.99	1202
3099.55	1236
3102.12	1252
3104.68	1256
3107.24	1224
3109.8	1250
3112.36	1280
3114.92	1280
3117.48	1248
3120.03	1250
3122.59	1258
3125.14	1274
3127.7	1288
3130.25	1296
3132.8	1264
3135.35	1356
3137.9	1294
3140.45	1324
3143	1344
3145.55	1322
3148.1	1316
3150.64	1298
3153.19	1346
3155.73	1330
3158.28	1352
3160.82	1328
3163.36	1336
3165.9	1372
3168.44	1360
3170.98	1348
3173.52	1368
3176.06	1358
3178.59	1374
3181.13	1350
3183.66	1384
3186.2	1378
3188.73	1352
3191.26	1430
3193.79	1390
3196.32	1386
3198.85	1382
3201.38	1404
3203.91	1412
3206.44	1386
3208.96	1396
3211.49	1382
3214.01	1420
3216.54	1376
3219.06	1424
3221.58	1384
3224.1	1412
3226.62	1428
3229.14	1408
3231.66	1414
3234.18	1414
3236.69	1400
3239.21	1396
3241.72	1382
3244.24	1446
3246.75	1436
3249.26	1426
3251.78	1454
3254.29	1450
3256.8	1428
3259.3	1458
3261.81	1436
3264.32	1468
3266.83	1462
3269.33	1494
3271.84	1468
3274.34	1494
3276.84	1496
3279.35	1464
3281.85	1534
3284.35	1510
3286.85	1516
3289.35	1540
3291.84	1542
3294.34	1530
3296.84	1558
3299.33	1558
3301.83	1532
3304.32	1552
3306.81	1564
3309.3	1564
3311.79	1576
3314.29	1584
3316.77	1594
3319.26	1610
3321.75	1572
3324.24	1632
3326.72	1628
3329.21	1614
3331.69	1590
3334.18	1596
3336.66	1614
3339.14	1616
3341.62	1654
3344.1	1660
3346.58	1650
3349.06	1612
3351.54	1608
3354.01	1660
3356.49	1620
3358.96	1638
3361.44	1652
3363.91	1638
3366.38	1656
3368.85	1674
3371.33	1640
3373.8	1638
3376.26	1668
3378.73	1652
3381.2	1692
3383.67	1602
3386.13	1660
3388.6	1672
3391.06	1666
3393.52	1728
3395.99	1680
3398.45	1688
3400.91	1708
3403.37	1714
3405.83	1718
3408.29	1704
3410.74	1708
3413.2	1730
3415.66	1708
3418.11	1738
3420.56	1730
3423.02	1740
3425.47	1782
3427.92	1706
3430.37	1800
3432.82	1782
3435.27	1766
3437.72	1790
3440.17	1784
3442.61	1828
3445.06	1830
3447.51	1812
3449.95	1850
3452.39	1820
3454.83	1804
3457.28	1902
3459.72	1806
3462.16	1868
3464.6	1870
3467.04	1834
3469.47	1860
3471.91	1808
3474.34	1830
3476.78	1870
3479.21	1888
3481.65	1922
3484.08	1880
3486.51	1908
3488.94	1922
3491.37	1884
3493.8	1882
3496.23	1890
3498.66	1944
3501.09	1918
3503.51	1886
3505.94	1906
3508.36	1940
3510.79	1876
3513.21	1926
3515.63	1918
3518.05	1908
3520.47	1944
3522.89	1912
3525.31	1894
3527.73	1930
3530.14	1938
3532.56	1898
3534.98	1936
3537.39	1928
3539.81	1916
3542.22	1942
3544.63	1982
3547.04	1922
3549.45	1922
3551.86	1954
3554.27	1938
3556.68	1978
3559.09	1964
3561.49	1972
3563.9	1996
3566.3	1950
3568.71	1988
3571.11	1954
3573.51	1972
3575.92	2002
3578.32	2052
3580.72	1978
3583.12	2050
3585.51	1988
3587.91	2028
3590.31	2072
3592.71	2064
3595.1	2080
3597.49	2104
3599.89	2082
3602.28	2076
3604.67	2082
3607.06	2124
3609.45	2142
3611.84	2116
3614.23	2168
3616.62	2086
3619.01	2138
3621.39	2146
3623.78	2114
3626.17	2144
3628.55	2128
3630.93	2146
3633.31	2180
3635.7	2146
3638.08	2092
3640.46	2150
3642.84	2192
3645.22	2192
3647.59	2156
3649.97	2140
3652.35	2152
3654.72	2166
3657.1	2156
3659.47	2140
3661.84	2166
3664.21	2158
3666.59	2172
3668.96	2174
3671.33	2162
3673.69	2132
3676.06	2166
3678.43	2226
3680.8	2152
3683.16	2208
3685.53	2192
3687.89	2178
3690.25	2148
3692.62	2158
3694.98	2202
3697.34	2180
3699.7	2180
3702.06	2254
3704.42	2256
3706.78	2234
3709.13	2210
3711.49	2196
3713.85	2262
3716.2	2256
3718.56	2236
3720.91	2254
3723.26	2234
3725.61	2302
3727.96	2260
3730.31	2286
3732.66	2286
3735.01	2328
3737.36	2266
3739.7	2210
3742.05	2326
3744.4	2360
3746.74	2370
3749.09	2338
3751.43	2326
3753.77	2368
3756.11	2342
3758.45	2360
3760.79	2380
3763.13	2394
3765.47	2368
3767.81	2336
3770.14	2362
3772.48	2400
3774.82	2358
3777.15	2384
3779.48	2442
3781.82	2374
3784.15	2422
3786.48	2410
3788.81	2330
3791.14	2466
3793.47	2422
3795.8	2378
3798.13	2372
3800.45	2424
3802.78	2466
3805.1	2418
3807.43	2486
3809.75	2386
3812.07	2460
3814.4	2420
3816.72	2368
3819.04	2396
3821.36	2440
3823.68	2412
3826	2402
3828.31	2366
3830.63	2384
3832.95	2480
3835.26	2380
3837.58	2470
3839.89	2432
3842.2	2430
3844.51	2430
3846.83	2424
3849.14	2426
3851.45	2398
3853.76	2424
3856.06	2414
3858.37	2476
3860.68	2434
3862.98	2504
3865.29	2412
3867.59	2464
3869.9	2440
3872.2	2488
3874.5	2532
3876.8	2524
3879.1	2500
3881.4	2540
3883.7	2482
3886	2536
3888.3	2590
3890.6	2524
3892.89	2556
3895.19	2548
3897.48	2630
3899.78	2652
3902.07	2630
3904.36	2568
3906.65	2604
3908.94	2658
3911.23	2582
3913.52	2622
3915.81	2640
3918.1	2646
3920.39	2582
3922.67	2660
3924.96	2596
3927.24	2634
3929.53	2624
3931.81	2648
3934.09	2660
3936.38	2672
3938.66	2606
3940.94	2640
3943.22	2652
3945.5	2648
3947.77	2620
3950.05	2716
3952.33	2702
3954.6	2654
3956.88	2708
3959.15	2684
3961.43	2728
3963.7	2660
3965.97	2660
3968.24	2646
3970.51	2640
3972.78	2630
3975.05	2648
3977.32	2644
3979.59	2658
3981.85	2646
3984.12	2678
3986.39	2676
3988.65	2706
3990.91	2662
3993.18	2686
3995.44	2680
3997.7	2710
3999.96	2646