File: DataDrivenSE/datosramana/CN-Sastre_02.txt
#Acq. time (s)=	20
#Accumulations=	2
#Range (cm-¹)=	50...4000
#Windows=	3
#Autofocus=	Off
#AutoExposure=	Off
#Spike filter=	Multiple accum.
#Delay time (s)=	0
#Binning=	1
#Readout mode=	Signal
#DeNoise=	Off
#ICS correction=	Off
#Dark correction=	Off
#Inst. Process=	Off
#Instrument=	LabRAM HR Evol
#Detector=	Syncerity OE
#Objective=	x100_VIS
#Grating=	600 (500nm)
#ND Filter=	100%
#Laser=	532nm_Edge
#Hole=	100.021
#Range=	Visible
#Project=	Omar
#Sample=
#Site=	21-09-22
#Title=	 CN-Sastre
#Remark=
#Date=	21.09.2022 12:08
#Acquired=	21.09.2022 12:08:21
51.0918	46
54.7807	48
58.4681	74
62.154	172
65.8385	306
69.5216	436
73.2032	762
76.8834	1120
80.5621	1348
84.2393	1672
87.9152	1846
91.5874	1952
95.2603	1902
98.9318	1872
102.602	1858
106.27	1972
109.936	1944
113.601	1992
117.266	1944
120.926	1970
124.588	1918
128.246	1894
131.904	1882
135.561	1906
139.215	1934
142.869	1866
146.52	1882
150.171	1926
153.819	1870
157.465	1858
161.112	1860
164.756	1864
168.398	1842
172.041	1808
175.68	1792
179.318	1774
182.955	1752
186.592	1804
190.225	1796
193.857	1800
197.488	1786
201.118	1774
204.746	1748
208.372	1742
211.997	1728
215.621	1668
219.243	1648
222.864	1660
226.483	1688
230.101	1686
233.718	1638
237.331	1700
240.945	1676
244.557	1664
248.168	1698
251.776	1708
255.384	1706
258.991	1704
262.594	1724
266.198	1670
269.799	1736
273.4	1658
277	1686
280.596	1698
284.193	1686
287.786	1670
291.378	1706
294.971	1686
298.561	1696
302.148	1684
305.737	1706
309.322	1716
312.906	1770
316.49	1716
320.071	1748
323.651	1742
327.229	1754
330.806	1748
334.381	1766
337.955	1812
341.528	1734
345.099	1732
348.669	1748
352.238	1764
355.805	1786
359.371	1810
362.935	1782
366.498	1756
370.06	1784
373.62	1772
377.177	1808
380.734	1782
384.29	1798
387.845	1806
391.396	1800
394.948	1802
398.499	1786
402.046	1820
405.594	1802
409.138	1792
412.683	1786
416.225	1850
419.768	1778
423.307	1772
426.844	1780
430.382	1782
433.917	1814
437.451	1794
440.985	1754
444.516	1828
448.045	1836
451.574	1854
455.102	1800
458.628	1812
462.152	1820
465.674	1818
469.196	1860
472.716	1788
476.234	1822
479.752	1812
483.268	1776
486.782	1770
490.295	1762
493.807	1794
497.316	1764
500.825	1742
504.333	1752
507.839	1712
511.344	1684
514.846	1748
518.349	1752
521.85	1826
525.347	1788
528.846	1896
532.341	1924
535.837	1982
539.329	2122
542.822	2214
546.312	2282
549.802	2364
553.289	2410
556.775	2392
560.261	2414
563.744	2360
567.226	2350
570.709	2272
574.188	2280
577.665	2216
581.142	2182
584.617	2092
588.091	2128
591.565	2076
595.036	1996
598.506	2020
601.974	1970
605.442	1912
608.905	1846
612.37	1804
615.833	1808
619.295	1746
622.755	1694
626.215	1682
629.67	1658
633.127	1658
636.582	1610
640.036	1572
643.487	1560
646.938	1502
650.386	1522
653.835	1446
657.282	1396
660.726	1400
664.171	1376
667.613	1334
671.053	1318
674.494	1300
677.931	1266
681.369	1206
684.804	1172
688.238	1212
691.67	1108
695.103	1106
698.533	1088
701.961	1058
705.389	1044
708.814	978
712.239	990
715.662	974
719.084	976
722.505	948
725.924	944
729.342	944
732.759	940
736.174	920
739.589	932
742.999	918
746.411	946
749.821	926
753.23	956
756.636	958
760.043	940
763.448	936
766.85	992
770.252	994
773.652	952
777.052	992
780.448	966
783.846	988
787.24	976
790.635	992
794.027	980
797.417	1022
800.808	968
804.196	950
807.582	924
810.968	914
814.354	922
817.736	898
821.118	858
824.498	816
827.877	804
831.254	816
834.631	758
838.006	748
841.38	750
844.752	760
848.123	746
851.493	748
854.86	716
858.228	722
861.594	730
864.959	732
868.321	702
871.683	724
875.044	710
878.402	726
881.761	738
885.116	720
888.472	744
891.825	740
895.179	760
898.529	758
901.88	772
905.228	802
908.575	782
911.922	800
915.266	842
918.609	880
921.951	886
925.293	922
928.633	986
931.97	984
935.307	946
938.642	1026
941.977	1040
945.31	1084
948.641	1066
951.972	1038
955.301	1100
958.629	1068
961.955	1062
965.279	1074
968.603	1080
971.926	1048
975.248	1094
978.566	1104
981.886	1062
985.204	1108
988.519	1160
991.834	1194
995.147	1174
998.46	1208
1001.77	1174
1005.08	1190
1008.39	1236
1011.7	1244
1015	1264
1018.3	1250
1021.61	1282
1024.91	1382
1028.21	1360
1031.51	1400
1034.81	1486
1038.1	1494
1041.4	1500
1044.69	1562
1047.99	1668
1051.28	1660
1054.57	1716
1057.86	1772
1061.14	1796
1064.43	1880
1067.72	1874
1071	1968
1074.28	2098
1077.57	2070
1080.84	2116
1084.12	2176
1087.4	2250
1090.68	2270
1093.95	2282
1097.22	2192
1100.5	2188
1103.77	2170
1107.04	2164
1110.31	2128
1113.58	1994
1116.84	1910
1120.1	1852
1123.37	1810
1126.63	1754
1129.89	1656
1133.15	1576
1136.41	1534
1139.67	1464
1142.92	1428
1146.18	1350
1149.43	1288
1152.68	1274
1155.93	1246
1159.18	1218
1162.43	1150
1165.68	1120
1168.93	1076
1172.17	1052
1175.41	1030
1178.66	990
1181.9	958
1185.14	930
1188.37	934
1191.61	908
1194.85	860
1198.08	864
1201.31	790
1204.55	832
1207.78	792
1211.01	784
1214.24	722
1217.46	740
1220.69	726
1223.91	744
1227.14	706
1230.36	712
1233.58	688
1236.8	694
1240.02	714
1243.23	660
1246.45	660
1249.67	664
1252.88	674
1256.09	688
1259.3	636
1262.51	692
1265.72	652
1268.93	672
1272.13	664
1275.34	682
1278.54	680
1281.74	664
1284.94	662
1288.15	674
1291.34	636
1294.54	626
1297.74	678
1300.93	680
1304.12	650
1307.32	662
1310.51	634
1313.7	680
1316.89	652
1320.07	692
1323.26	690
1326.45	648
1329.63	670
1332.81	672
1335.99	690
1339.17	666
1342.35	702
1345.53	672
1348.71	696
1351.88	690
1355.06	646
1358.23	660
1361.4	682
1364.57	678
1367.74	684
1370.91	644
1374.08	718
1377.24	636
1380.41	678
1383.57	674
1386.73	672
1389.89	664
1393.05	690
1396.21	644
1399.37	674
1402.52	670
1405.68	658
1408.83	666
1411.98	676
1415.13	698
1418.29	710
1421.43	674
1424.58	670
1427.73	696
1430.87	706
1434.02	686
1437.16	692
1440.3	670
1443.44	670
1446.58	672
1449.72	658
1452.85	684
1455.99	678
1459.12	666
1462.26	670
1465.39	666
1468.52	664
1471.65	662
1474.78	670
1477.9	702
1481.03	688
1484.16	662
1487.28	660
1490.4	676
1493.52	664
1496.64	672
1499.76	706
1502.88	698
1506	694
1509.11	728
1512.22	706
1515.34	706
1518.45	698
1521.56	736
1524.67	734
1527.78	700
1530.88	696
1533.99	690
1537.09	724
1540.2	694
1543.3	684
1546.4	742
1549.5	654
1552.6	712
1555.7	734
1558.79	694
1561.89	672
1564.98	702
1568.08	702
1571.17	744
1574.26	704
1577.35	732
1580.43	710
1583.52	686
1586.61	690
1589.69	700
1592.77	682
1595.86	702
1598.94	734
1602.02	692
1605.1	718
1608.18	682.56
1611.25	691.782
1614.33	702.909
1617.4	680.029
1620.47	681.809
1623.55	700.75
1626.62	683.893
1629.69	663.162
1632.75	677.479
1635.82	661.323
1638.89	666.165
1641.95	664.079
1645.02	668.767
1648.08	667.956
1651.14	668.794
1654.2	653.914
1657.26	670.074
1660.32	656.629
1663.37	666.922
1666.43	690.041
1669.48	670.365
1672.54	659.594
1675.59	664.285
1678.64	641.497
1681.69	659.762
1684.74	658.659
1687.79	634.211
1690.83	646.438
1693.88	644.851
1696.92	645.746
1699.96	644.961
1703.01	661.8
1706.05	635.801
1709.09	645.782
1712.12	637.855
1715.16	647.568
1718.2	619.742
1721.23	623.457
1724.27	618.24
1727.3	613.107
1730.33	626.078
1733.36	614.44
1736.39	599.434
1739.42	611.39
1742.44	596.014
1745.47	604.5
1748.49	606.351
1751.52	616.316
1754.54	622.57
1757.56	598.03
1759.14	584
1762.18	592
1765.21	608
1768.24	594
1771.27	600
1774.3	616
1777.32	596
1780.35	606
1783.38	616
1786.4	602
1789.42	592
1792.44	580
1795.47	602
1798.48	610
1801.5	612
1804.52	618
1807.54	624
1810.55	586
1813.57	582
1816.58	590
1819.59	624
1822.6	634
1825.61	602
1828.62	590
1831.63	586
1834.63	580
1837.64	592
1840.64	624
1843.64	588
1846.64	592
1849.64	600
1852.64	612
1855.64	600
1858.64	586
1861.64	594
1864.63	560
1867.63	602
1870.62	604
1873.61	612
1876.6	616
1879.59	604
1882.58	594
1885.56	648
1888.55	618
1891.54	630
1894.52	610
1897.5	578
1900.48	618
1903.46	622
1906.44	610
1909.42	606
1912.4	630
1915.38	618
1918.35	638
1921.32	622
1924.3	650
1927.27	618
1930.24	620
1933.21	622
1936.18	614
1939.15	588
1942.11	576
1945.08	636
1948.04	630
1951	624
1953.97	640
1956.93	634
1959.89	620
1962.85	610
1965.8	608
1968.76	626
1971.71	592
1974.67	620
1977.62	622
1980.57	598
1983.53	614
1986.48	604
1989.42	620
1992.37	586
1995.32	598
1998.26	580
2001.21	640
2004.15	628
2007.09	634
2010.03	622
2012.98	602
2015.92	622
2018.85	622
2021.79	598
2024.73	608
2027.66	636
2030.59	602
2033.53	620
2036.46	612
2039.39	604
2042.32	636
2045.25	622
2048.17	616
2051.1	628
2054.02	610
2056.95	628
2059.87	610
2062.79	618
2065.71	626
2068.63	638
2071.55	624
2074.47	634
2077.39	612
2080.3	636
2083.22	656
2086.13	632
2089.04	634
2091.95	620
2094.86	608
2097.77	622
2100.68	610
2103.59	618
2106.49	640
2109.4	620
2112.3	632
2115.21	620
2118.11	634
2121.01	616
2123.91	628
2126.8	620
2129.7	604
2132.6	608
2135.49	620
2138.39	634
2141.28	634
2144.17	616
2147.06	626
2149.95	614
2152.84	606
2155.73	606
2158.62	652
2161.5	632
2164.39	638
2167.27	602
2170.15	616
2173.04	654
2175.92	630
2178.79	626
2181.67	634
2184.55	628
2187.43	666
2190.3	636
2193.18	650
2196.05	620
2198.92	636
2201.79	626
2204.66	622
2207.53	596
2210.4	610
2213.27	598
2216.13	626
2219	604
2221.86	616
2224.72	600
2227.59	642
2230.45	596
2233.31	612
2236.16	582
2239.02	600
2241.88	636
2244.73	630
2247.59	596
2250.44	626
2253.29	608
2256.15	630
2259	602
2261.84	600
2264.69	630
2267.54	616
2270.39	614
2273.23	618
2276.07	608
2278.92	618
2281.76	612
2284.6	640
2287.44	620
2290.28	638
2293.12	630
2295.95	622
2298.79	642
2301.62	632
2304.46	656
2307.29	616
2310.12	644
2312.95	652
2315.78	658
2318.61	644
2321.44	652
2324.27	662
2327.09	670
2329.92	722
2332.74	668
2335.56	668
2338.38	700
2341.2	664
2344.02	686
2346.84	668
2349.66	682
2352.48	724
2355.29	686
2358.11	710
2360.92	680
2363.73	718
2366.54	708
2369.35	728
2372.16	764
2374.97	726
2377.78	770
2380.58	726
2383.39	732
2386.19	756
2389	748
2391.8	738
2394.6	784
2397.4	762
2400.2	766
2403	734
2405.79	804
2408.59	754
2411.38	768
2414.18	782
2416.97	796
2419.76	784
2422.55	790
2425.34	806
2428.13	794
2430.92	780
2433.71	794
2436.49	776
2439.28	804
2442.06	782
2444.85	788
2447.63	762
2450.41	754
2453.19	796
2455.97	784
2458.75	804
2461.52	746
2464.3	774
2467.07	812
2469.85	784
2472.62	788
2475.39	796
2478.16	800
2480.94	778
2483.7	786
2486.47	792
2489.24	784
2492	786
2494.77	780
2497.53	802
2500.3	766
2503.06	770
2505.82	794
2508.58	774
2511.34	776
2514.1	794
2516.85	790
2519.61	766
2522.37	790
2525.12	774
2527.87	778
2530.63	800
2533.38	766
2536.13	750
2538.88	792
2541.62	772
2544.37	766
2547.12	778
2549.86	778
2552.61	760
2555.35	796
2558.09	798
2560.84	790
2563.57	772
2566.32	774
2569.05	770
2571.79	754
2574.53	780
2577.26	820
2580	812
2582.73	802
2585.46	796
2588.19	806
2590.93	780
2593.66	804
2596.39	798
2599.11	784
2601.84	798
2604.56	788
2607.29	822
2610.01	810
2612.74	832
2615.46	818
2618.18	798
2620.9	808
2623.62	820
2626.34	810
2629.05	816
2631.77	802
2634.48	832
2637.2	830
2639.91	820
2642.62	836
2645.33	788
2648.05	812
2650.75	806
2653.46	856
2656.17	812
2658.88	814
2661.58	840
2664.29	862
2666.99	826
2669.69	826
2672.39	810
2675.09	836
2677.79	830
2680.49	798
2683.19	832
2685.89	814
2688.58	780
2691.28	840
2693.97	826
2696.67	818
2699.36	828
2702.05	854
2704.74	834
2707.43	828
2710.12	794
2712.8	836
2715.49	840
2718.17	866
2720.86	834
2723.54	858
2726.22	826
2728.91	868
2731.59	842
2734.27	854
2736.95	884
2739.62	876
2742.3	832
2744.98	872
2747.65	858
2750.33	878
2753	890
2755.67	862
2758.34	876
2761.01	874
2763.68	866
2766.35	838
2769.02	886
2771.68	890
2774.35	894
2777.01	878
2779.68	864
2782.34	902
2785	894
2787.66	874
2790.32	900
2792.98	906
2795.64	884
2798.3	916
2800.95	914
2803.61	920
2806.26	912
2808.91	948
2811.57	900
2814.22	914
2816.87	924
2819.52	936
2822.17	928
2824.81	924
2827.46	896
2830.11	914
2832.75	964
2835.39	936
2838.04	914
2840.68	916
2843.32	958
2845.96	980
2848.6	950
2851.24	934
2853.88	996
2856.51	968
2859.15	964
2861.78	966
2864.42	928
2867.05	944
2869.68	948
2872.31	940
2874.94	950
2877.57	988
2880.2	958
2882.82	958
2885.45	964
2888.08	988
2890.7	972
2893.33	984
2895.95	978
2898.57	1000
2901.19	980
2903.81	980
2906.43	998
2909.05	958
2911.66	976
2914.28	978
2916.89	974
2919.51	1009.62
2922.12	1013.39
2924.73	1016.22
2927.35	981.435
2929.96	1003.48
2932.57	1017.36
2935.17	1001.58
2937.78	1023.08
2940.39	1036.49
2943	1021.5
2945.6	1037.78
2948.2	1044.4
2950.81	1048.32
2953.41	1023.63
2956.01	1042.34
2958.61	1042.4
2961.21	1047.18
2963.81	1037.27
2966.41	1037.76
2969.01	1062.6
2971.6	1039.5
2974.2	1083.35
2976.79	1059.49
2979.39	1058.2
2981.98	1073.62
2984.57	1077.85
2987.16	1081.49
2989.75	1070.3
2992.34	1093.08
2994.93	1086.28
2997.51	1074.04
3000.1	1069.86
3002.68	1099.86
3005.27	1099.69
3007.85	1076.56
3010.43	1064.3
3013.01	1097.88
3015.59	1107.09
3018.18	1135.18
3020.75	1113.56
3023.33	1102.89
3025.91	1108.54
3028.48	1123.41
3031.06	1137.49
3033.64	1129.45
3036.21	1131.64
3038.78	1100.52
3041.35	1150.2
3043.92	1140.75
3046.49	1132.37
3048.11	1156
3050.69	1174
3053.27	1144
3055.85	1150
3058.43	1164
3061.01	1178
3063.58	1190
3066.16	1176
3068.73	1190
3071.31	1190
3073.88	1164
3076.45	1158
3079.02	1170
3081.59	1222
3084.16	1164
3086.73	1198
3089.29	1236
3091.86	1208
3094.43	1190
3096.99	1198
3099.55	1210
3102.12	1236
3104.68	1196
3107.24	1232
3109.8	1234
3112.36	1182
3114.92	1216
3117.48	1236
3120.03	1250
3122.59	1236
3125.14	1284
3127.7	1278
3130.25	1224
3132.8	1294
3135.35	1270
3137.9	1234
3140.45	1258
3143	1296
3145.55	1310
3148.1	1322
3150.64	1306
3153.19	1308
3155.73	1294
3158.28	1322
3160.82	1320
3163.36	1318
3165.9	1342
3168.44	1320
3170.98	1348
3173.52	1352
3176.06	1364
3178.59	1360
3181.13	1324
3183.66	1362
3186.2	1352
3188.73	1326
3191.26	1358
3193.79	1356
3196.32	1340
3198.85	1342
3201.38	1364
3203.91	1384
3206.44	1372
3208.96	1364
3211.49	1370
3214.01	1382
3216.54	1398
3219.06	1390
3221.58	1422
3224.1	1406
3226.62	1346
3229.14	1404
3231.66	1396
3234.18	1398
3236.69	1388
3239.21	1366
3241.72	1418
3244.24	1432
3246.75	1436
3249.26	1436
3251.78	1430
3254.29	1412
3256.8	1380
3259.3	1434
3261.81	1414
3264.32	1474
3266.83	1414
3269.33	1432
3271.84	1440
3274.34	1450
3276.84	1492
3279.35	1494
3281.85	1508
3284.35	1510
3286.85	1498
3289.35	1534
3291.84	1512
3294.34	1508
3296.84	1494
3299.33	1580
3301.83	1572
3304.32	1554
3306.81	1566
3309.3	1564
3311.79	1538
3314.29	1552
3316.77	1542
3319.26	1596
3321.75	1510
3324.24	1586
3326.72	1572
3329.21	1576
3331.69	1612
3334.18	1586
3336.66	1600
3339.14	1600
3341.62	1570
3344.1	1652
3346.58	1592
3349.06	1638
3351.54	1580
3354.01	1614
3356.49	1636
3358.96	1640
3361.44	1620
3363.91	1628
3366.38	1582
3368.85	1664
3371.33	1638
3373.8	1646
3376.26	1706
3378.73	1618
3381.2	1640
3383.67	1656
3386.13	1690
3388.6	1688
3391.06	1658
3393.52	1680
3395.99	1710
3398.45	1640
3400.91	1666
3403.37	1650
3405.83	1704
3408.29	1706
3410.74	1762
3413.2	1688
3415.66	1698
3418.11	1746
3420.56	1764
3423.02	1762
3425.47	1754
3427.92	1768
3430.37	1728
3432.82	1772
3435.27	1798
3437.72	1746
3440.17	1788
3442.61	1792
3445.06	1770
3447.51	1784
3449.95	1830
3452.39	1832
3454.83	1858
3457.28	1840
3459.72	1822
3462.16	1792
3464.6	1850
3467.04	1852
3469.47	1856
3471.91	1864
3474.34	1880
3476.78	1876
3479.21	1912
3481.65	1888
3484.08	1880
3486.51	1890
3488.94	1882
3491.37	1896
3493.8	1930
3496.23	1886
3498.66	1902
3501.09	1860
3503.51	1844
3505.94	1922
3508.36	1882
3510.79	1922
3513.21	1902
3515.63	1856
3518.05	1880
3520.47	1858
3522.89	1892
3525.31	1922
3527.73	1886
3530.14	1910
3532.56	1886
3534.98	1916
3537.39	1934
3539.81	1870
3542.22	1922
3544.63	1954
3547.04	1946
3549.45	1912
3551.86	1946
3554.27	1956
3556.68	1944
3559.09	1972
3561.49	1958
3563.9	2008
3566.3	1960
3568.71	1960
3571.11	1956
3573.51	2008
3575.92	2038
3578.32	2004
3580.72	2010
3583.12	2012
3585.51	2024
3587.91	2022
3590.31	2056
3592.71	2044
3595.1	2046
3597.49	2088
3599.89	2074
3602.28	2096
3604.67	2080
3607.06	2136
3609.45	2078
3611.84	2106
3614.23	2134
3616.62	2160
3619.01	2134
3621.39	2102
3623.78	2132
3626.17	2138
3628.55	2144
3630.93	2152
3633.31	2116
3635.7	2194
3638.08	2132
3640.46	2162
3642.84	2168
3645.22	2120
3647.59	2166
3649.97	2178
3652.35	2224
3654.72	2166
3657.1	2180
3659.47	2132
3661.84	2180
3664.21	2192
3666.59	2174
3668.96	2152
3671.33	2170
3673.69	2166
3676.06	2152
3678.43	2136
3680.8	2192
3683.16	2236
3685.53	2188
3687.89	2178
3690.25	2186
3692.62	2210
3694.98	2210
3697.34	2220
3699.7	2252
3702.06	2250
3704.42	2206
3706.78	2210
3709.13	2256
3711.49	2242
3713.85	2224
3716.2	2250
3718.56	2224
3720.91	2274
3723.26	2256
3725.61	2274
3727.96	2262
3730.31	2280
3732.66	2276
3735.01	2308
3737.36	2328
3739.7	2354
3742.05	2322
3744.4	2318
3746.74	2348
3749.09	2318
3751.43	2366
3753.77	2370
3756.11	2344
3758.45	2350
3760.79	2378
3763.13	2384
3765.47	2372
3767.81	2396
3770.14	2402
3772.48	2458
3774.82	2406
3777.15	2388
3779.48	2406
3781.82	2442
3784.15	2438
3786.48	2396
3788.81	2448
3791.14	2424
3793.47	2406
3795.8	2368
3798.13	2384
3800.45	2426
3802.78	2462
3805.1	2452
3807.43	2458
3809.75	2434
3812.07	2470
3814.4	2452
3816.72	2386
3819.04	2438
3821.36	2468
3823.68	2426
3826	2434
3828.31	2416
3830.63	2422
3832.95	2424
3835.26	2442
3837.58	2422
3839.89	2426
3842.2	2416
3844.51	2482
3846.83	2400
3849.14	2468
3851.45	2464
3853.76	2486
3856.06	2478
3858.37	2554
3860.68	2522
3862.98	2462
3865.29	2512
3867.59	2492
3869.9	2452
3872.2	2544
3874.5	2532
3876.8	2478
3879.1	2546
3881.4	2554
3883.7	2536
3886	2518
3888.3	2534
3890.6	2586
3892.89	2538
3895.19	2626
3897.48	2632
3899.78	2608
3902.07	2582
3904.36	2576
3906.65	2596
3908.94	2634
3911.23	2634
3913.52	2636
3915.81	2660
3918.1	2654
3920.39	2628
3922.67	2632
3924.96	2668
3927.24	2662
3929.53	2664
3931.81	2636
3934.09	2708
3936.38	2652
3938.66	2656
3940.94	2634
3943.22	2710
3945.5	2674
3947.77	2696
3950.05	2700
3952.33	2704
3954.6	2660
3956.88	2664
3959.15	2678
3961.43	2736
3963.7	2732
3965.97	2670
3968.24	2658
3970.51	2674
3972.78	2686
3975.05	2694
3977.32	2634
3979.59	2696
3981.85	2678
3984.12	2710
3986.39	2676
3988.65	2624
3990.91	2708
3993.18	2636
3995.44	2702
3997.7	2722
3999.96	2778