File: DataDrivenSE/datosramana/CN-Sastre_09.txt
#Acq. time (s)=	20
#Accumulations=	2
#Range (cm-¹)=	50...4000
#Windows=	3
#Autofocus=	Off
#AutoExposure=	Off
#Spike filter=	Multiple accum.
#Delay time (s)=	0
#Binning=	1
#Readout mode=	Signal
#DeNoise=	Off
#ICS correction=	Off
#Dark correction=	Off
#Inst. Process=	Off
#Instrument=	LabRAM HR Evol
#Detector=	Syncerity OE
#Objective=	x100_VIS
#Grating=	600 (500nm)
#ND Filter=	100%
#Laser=	532nm_Edge
#Hole=	100.021
#Range=	Visible
#Project=	Omar
#Sample=
#Site=	21-09-22
#Title=	 CN-Sastre
#Remark=
#Date=	21.09.2022 13:11
#Acquired=	21.09.2022 13:11:01
51.0918	42
54.7807	44
58.4681	82
62.154	176
65.8385	290
69.5216	470
73.2032	808
76.8834	1116
80.5621	1406
84.2393	1650
87.9152	1836
91.5874	1982
95.2603	1872
98.9318	1906
102.602	1852
106.27	2004
109.936	1934
113.601	2014
117.266	1960
120.926	1926
124.588	1882
128.246	1900
131.904	1842
135.561	1874
139.215	1870
142.869	1874
146.52	1870
150.171	1836
153.819	1858
157.465	1848
161.112	1764
164.756	1834
168.398	1814
172.041	1768
175.68	1768
179.318	1800
182.955	1716
186.592	1740
190.225	1710
193.857	1724
197.488	1688
201.118	1722
204.746	1682
208.372	1660
211.997	1692
215.621	1654
219.243	1634
222.864	1644
226.483	1620
230.101	1636
233.718	1604
237.331	1610
240.945	1628
244.557	1602
248.168	1594
251.776	1644
255.384	1662
258.991	1634
262.594	1610
266.198	1632
269.799	1600
273.4	1614
277	1614
280.596	1596
284.193	1638
287.786	1626
291.378	1656
294.971	1606
298.561	1660
302.148	1612
305.737	1618
309.322	1652
312.906	1664
316.49	1648
320.071	1672
323.651	1662
327.229	1682
330.806	1638
334.381	1698
337.955	1694
341.528	1660
345.099	1662
348.669	1686
352.238	1714
355.805	1684
359.371	1700
362.935	1684
366.498	1686
370.06	1722
373.62	1698
377.177	1720
380.734	1704
384.29	1736
387.845	1736
391.396	1768
394.948	1754
398.499	1776
402.046	1722
405.594	1722
409.138	1752
412.683	1752
416.225	1734
419.768	1738
423.307	1750
426.844	1730
430.382	1726
433.917	1790
437.451	1768
440.985	1806
444.516	1764
448.045	1804
451.574	1786
455.102	1836
458.628	1828
462.152	1776
465.674	1832
469.196	1780
472.716	1728
476.234	1748
479.752	1774
483.268	1738
486.782	1718
490.295	1726
493.807	1688
497.316	1740
500.825	1686
504.333	1722
507.839	1694
511.344	1720
514.846	1674
518.349	1706
521.85	1776
525.347	1758
528.846	1824
532.341	1890
535.837	1986
539.329	2068
542.822	2122
546.312	2178
549.802	2286
553.289	2312
556.775	2406
560.261	2350
563.744	2346
567.226	2302
570.709	2214
574.188	2268
577.665	2156
581.142	2106
584.617	2094
588.091	2074
591.565	2008
595.036	1914
598.506	1952
601.974	1836
605.442	1814
608.905	1714
612.37	1742
615.833	1648
619.295	1636
622.755	1638
626.215	1584
629.67	1586
633.127	1576
636.582	1532
640.036	1448
643.487	1458
646.938	1466
650.386	1422
653.835	1396
657.282	1368
660.726	1352
664.171	1330
667.613	1312
671.053	1292
674.494	1280
677.931	1162
681.369	1180
684.804	1150
688.238	1112
691.67	1110
695.103	1062
698.533	1032
701.961	1028
705.389	1036
708.814	994
712.239	978
715.662	976
719.084	936
722.505	946
725.924	940
729.342	898
732.759	896
736.174	910
739.589	910
742.999	930
746.411	890
749.821	916
753.23	902
756.636	948
760.043	974
763.448	954
766.85	966
770.252	954
773.652	986
777.052	960
780.448	986
783.846	992
787.24	968
790.635	966
794.027	956
797.417	944
800.808	936
804.196	918
807.582	912
810.968	900
814.354	892
817.736	840
821.118	836
824.498	808
827.877	816
831.254	788
834.631	734
838.006	738
841.38	734
844.752	756
848.123	736
851.493	746
854.86	714
858.228	712
861.594	740
864.959	742
868.321	732
871.683	714
875.044	734
878.402	736
881.761	750
885.116	774
888.472	750
891.825	728
895.179	736
898.529	766
901.88	766
905.228	816
908.575	818
911.922	836
915.266	832
918.609	876
921.951	886
925.293	896
928.633	938
931.97	954
935.307	950
938.642	998
941.977	1012
945.31	1036
948.641	1002
951.972	1060
955.301	1006
958.629	1072
961.955	1040
965.279	1018
968.603	1034
971.926	1072
975.248	1034
978.566	1042
981.886	1064
985.204	1078
988.519	1084
991.834	1114
995.147	1116
998.46	1150
1001.77	1146
1005.08	1168
1008.39	1164
1011.7	1218
1015	1224
1018.3	1242
1021.61	1286
1024.91	1314
1028.21	1372
1031.51	1354
1034.81	1414
1038.1	1454
1041.4	1456
1044.69	1512
1047.99	1576
1051.28	1624
1054.57	1638
1057.86	1688
1061.14	1738
1064.43	1798
1067.72	1822
1071	1898
1074.28	1952
1077.57	1936
1080.84	2020
1084.12	2036
1087.4	2128
1090.68	2132
1093.95	2108
1097.22	2170
1100.5	2130
1103.77	2086
1107.04	2038
1110.31	1980
1113.58	1878
1116.84	1804
1120.1	1766
1123.37	1706
1126.63	1636
1129.89	1582
1133.15	1500
1136.41	1448
1139.67	1438
1142.92	1368
1146.18	1308
1149.43	1254
1152.68	1198
1155.93	1190
1159.18	1176
1162.43	1126
1165.68	1106
1168.93	1082
1172.17	1030
1175.41	1002
1178.66	994
1181.9	938
1185.14	946
1188.37	906
1191.61	908
1194.85	884
1198.08	840
1201.31	838
1204.55	810
1207.78	824
1211.01	764
1214.24	782
1217.46	748
1220.69	722
1223.91	726
1227.14	720
1230.36	708
1233.58	704
1236.8	684
1240.02	680
1243.23	700
1246.45	688
1249.67	692
1252.88	686
1256.09	676
1259.3	646
1262.51	674
1265.72	694
1268.93	700
1272.13	694
1275.34	686
1278.54	694
1281.74	714
1284.94	720
1288.15	697
1291.34	696
1294.54	694
1297.74	722
1300.93	750
1304.12	738
1307.32	712
1310.51	724
1313.7	718
1316.89	756
1320.07	754
1323.26	760
1326.45	742
1329.63	778
1332.81	772
1335.99	814
1339.17	794
1342.35	832
1345.53	814
1348.71	798
1351.88	812
1355.06	786
1358.23	810
1361.4	786
1364.57	804
1367.74	758
1370.91	778
1374.08	762
1377.24	752
1380.41	746
1383.57	728
1386.73	754
1389.89	726
1393.05	690
1396.21	720
1399.37	740
1402.52	714
1405.68	714
1408.83	732
1411.98	722
1415.13	676
1418.29	712
1421.43	690
1424.58	698
1427.73	720
1430.87	680
1434.02	698
1437.16	710
1440.3	714
1443.44	696
1446.58	706
1449.72	706
1452.85	680
1455.99	682
1459.12	728
1462.26	706
1465.39	674
1468.52	684
1471.65	706
1474.78	672
1477.9	700
1481.03	672
1484.16	728
1487.28	742
1490.4	730
1493.52	702
1496.64	720
1499.76	702
1502.88	750
1506	738
1509.11	720
1512.22	706
1515.34	740
1518.45	732
1521.56	756
1524.67	708
1527.78	716
1530.88	734
1533.99	734
1537.09	704
1540.2	720
1543.3	704
1546.4	732
1549.5	742
1552.6	732
1555.7	764
1558.79	768
1561.89	762
1564.98	774
1568.08	768
1571.17	774
1574.26	778
1577.35	804
1580.43	774
1583.52	786
1586.61	794
1589.69	786
1592.77	764
1595.86	772
1598.94	800
1602.02	780
1605.1	792
1608.18	790.746
1611.25	760.05
1614.33	744.318
1617.4	758.45
1620.47	734.707
1623.55	744.458
1626.62	751.046
1629.69	726.938
1632.75	729.281
1635.82	729.365
1638.89	737.151
1641.95	698.704
1645.02	694.414
1648.08	679.604
1651.14	706.452
1654.2	691.62
1657.26	689.059
1660.32	674.901
1663.37	679.776
1666.43	692.975
1669.48	680.145
1672.54	687.207
1675.59	690.977
1678.64	680.915
1681.69	668.344
1684.74	667.928
1687.79	695.045
1690.83	676.878
1693.88	681.619
1696.92	682.695
1699.96	686.182
1703.01	679.114
1706.05	668.329
1709.09	671.568
1712.12	673.495
1715.16	666.348
1718.2	671.958
1721.23	661.492
1724.27	666.055
1727.3	662.764
1730.33	648.786
1733.36	664.116
1736.39	666.519
1739.42	663.096
1742.44	635.912
1745.47	662.63
1748.49	654.679
1751.52	642.434
1754.54	652.95
1757.56	653.183
1759.14	668
1762.18	650
1765.21	664
1768.24	638
1771.27	622
1774.3	642
1777.32	636
1780.35	642
1783.38	642
1786.4	662
1789.42	660
1792.44	670
1795.47	652
1798.48	668
1801.5	666
1804.52	670
1807.54	660
1810.55	654
1813.57	650
1816.58	658
1819.59	648
1822.6	652
1825.61	660
1828.62	664
1831.63	642
1834.63	640
1837.64	644
1840.64	690
1843.64	666
1846.64	650
1849.64	662
1852.64	642
1855.64	670
1858.64	654
1861.64	660
1864.63	662
1867.63	660
1870.62	672
1873.61	652
1876.6	662
1879.59	640
1882.58	624
1885.56	666
1888.55	658
1891.54	688
1894.52	646
1897.5	668
1900.48	638
1903.46	642
1906.44	682
1909.42	646
1912.4	654
1915.38	662
1918.35	634
1921.32	670
1924.3	660
1927.27	654
1930.24	652
1933.21	644
1936.18	656
1939.15	670
1942.11	666
1945.08	672
1948.04	682
1951	682
1953.97	666
1956.93	642
1959.89	672
1962.85	658
1965.8	652
1968.76	648
1971.71	662
1974.67	656
1977.62	672
1980.57	664
1983.53	658
1986.48	658
1989.42	648
1992.37	668
1995.32	660
1998.26	656
2001.21	682
2004.15	650
2007.09	640
2010.03	640
2012.98	664
2015.92	632
2018.85	666
2021.79	666
2024.73	664
2027.66	662
2030.59	666
2033.53	678
2036.46	672
2039.39	648
2042.32	668
2045.25	664
2048.17	698
2051.1	688
2054.02	682
2056.95	670
2059.87	676
2062.79	654
2065.71	676
2068.63	650
2071.55	682
2074.47	658
2077.39	660
2080.3	636
2083.22	652
2086.13	666
2089.04	652
2091.95	658
2094.86	644
2097.77	654
2100.68	678
2103.59	654
2106.49	660
2109.4	688
2112.3	668
2115.21	678
2118.11	664
2121.01	660
2123.91	638
2126.8	652
2129.7	612
2132.6	660
2135.49	666
2138.39	648
2141.28	668
2144.17	668
2147.06	684
2149.95	650
2152.84	652
2155.73	636
2158.62	656
2161.5	692
2164.39	678
2167.27	672
2170.15	652
2173.04	676
2175.92	684
2178.79	670
2181.67	656
2184.55	672
2187.43	642
2190.3	688
2193.18	662
2196.05	660
2198.92	684
2201.79	666
2204.66	664
2207.53	656
2210.4	684
2213.27	654
2216.13	648
2219	666
2221.86	638
2224.72	638
2227.59	640
2230.45	660
2233.31	660
2236.16	674
2239.02	670
2241.88	648
2244.73	654
2247.59	652
2250.44	658
2253.29	640
2256.15	630
2259	652
2261.84	624
2264.69	648
2267.54	634
2270.39	632
2273.23	660
2276.07	672
2278.92	656
2281.76	644
2284.6	632
2287.44	670
2290.28	662
2293.12	662
2295.95	664
2298.79	634
2301.62	666
2304.46	678
2307.29	654
2310.12	684
2312.95	686
2315.78	666
2318.61	698
2321.44	690
2324.27	690
2327.09	732
2329.92	706
2332.74	702
2335.56	702
2338.38	720
2341.2	728
2344.02	712
2346.84	720
2349.66	740
2352.48	724
2355.29	712
2358.11	732
2360.92	748
2363.73	754
2366.54	746
2369.35	760
2372.16	756
2374.97	784
2377.78	760
2380.58	770
2383.39	750
2386.19	794
2389	768
2391.8	764
2394.6	768
2397.4	812
2400.2	794
2403	754
2405.79	796
2408.59	774
2411.38	822
2414.18	808
2416.97	814
2419.76	816
2422.55	830
2425.34	828
2428.13	836
2430.92	810
2433.71	806
2436.49	830
2439.28	852
2442.06	812
2444.85	808
2447.63	766
2450.41	824
2453.19	804
2455.97	794
2458.75	840
2461.52	804
2464.3	780
2467.07	792
2469.85	788
2472.62	836
2475.39	812
2478.16	790
2480.94	796
2483.7	806
2486.47	820
2489.24	796
2492	814
2494.77	816
2497.53	830
2500.3	820
2503.06	812
2505.82	792
2508.58	806
2511.34	816
2514.1	812
2516.85	820
2519.61	808
2522.37	826
2525.12	794
2527.87	812
2530.63	844
2533.38	832
2536.13	796
2538.88	804
2541.62	826
2544.37	810
2547.12	814
2549.86	788
2552.61	788
2555.35	794
2558.09	808
2560.84	812
2563.57	828
2566.32	814
2569.05	824
2571.79	816
2574.53	810
2577.26	804
2580	810
2582.73	836
2585.46	820
2588.19	836
2590.93	816
2593.66	834
2596.39	802
2599.11	826
2601.84	838
2604.56	834
2607.29	834
2610.01	794
2612.74	822
2615.46	804
2618.18	830
2620.9	808
2623.62	842
2626.34	818
2629.05	838
2631.77	824
2634.48	878
2637.2	852
2639.91	858
2642.62	852
2645.33	846
2648.05	842
2650.75	852
2653.46	852
2656.17	860
2658.88	856
2661.58	872
2664.29	858
2666.99	844
2669.69	874
2672.39	850
2675.09	862
2677.79	864
2680.49	860
2683.19	846
2685.89	880
2688.58	878
2691.28	862
2693.97	848
2696.67	836
2699.36	848
2702.05	852
2704.74	864
2707.43	856
2710.12	862
2712.8	854
2715.49	892
2718.17	868
2720.86	880
2723.54	854
2726.22	882
2728.91	872
2731.59	854
2734.27	866
2736.95	880
2739.62	872
2742.3	840
2744.98	866
2747.65	872
2750.33	904
2753	864
2755.67	870
2758.34	916
2761.01	890
2763.68	894
2766.35	898
2769.02	892
2771.68	886
2774.35	920
2777.01	918
2779.68	900
2782.34	880
2785	906
2787.66	930
2790.32	922
2792.98	928
2795.64	914
2798.3	900
2800.95	918
2803.61	910
2806.26	926
2808.91	926
2811.57	932
2814.22	892
2816.87	934
2819.52	910
2822.17	946
2824.81	944
2827.46	960
2830.11	908
2832.75	912
2835.39	932
2838.04	950
2840.68	940
2843.32	960
2845.96	938
2848.6	938
2851.24	952
2853.88	962
2856.51	972
2859.15	976
2861.78	990
2864.42	992
2867.05	970
2869.68	1006
2872.31	960
2874.94	972
2877.57	978
2880.2	1002
2882.82	986
2885.45	988
2888.08	1004
2890.7	1014
2893.33	1004
2895.95	1008
2898.57	982
2901.19	1034
2903.81	1002
2906.43	998
2909.05	1018
2911.66	1032
2914.28	1026
2916.89	996
2919.51	1008.03
2922.12	1023.28
2924.73	1000.1
2927.35	1016.33
2929.96	1035.88
2932.57	1034.69
2935.17	1037.92
2937.78	1047.77
2940.39	1032.7
2943	1025.44
2945.6	1063.4
2948.2	1027.36
2950.81	1037.52
2953.41	1044.53
2956.01	1058.89
2958.61	1031
2961.21	1055.47
2963.81	1031.61
2966.41	1051.74
2969.01	1049.48
2971.6	1056.42
2974.2	1067.75
2976.79	1071.52
2979.39	1070.25
2981.98	1083.85
2984.57	1084.27
2987.16	1089.02
2989.75	1082.94
2992.34	1105.47
2994.93	1098.94
2997.51	1094.46
3000.1	1104.76
3002.68	1095.41
3005.27	1108.2
3007.85	1108.85
3010.43	1119.68
3013.01	1092.9
3015.59	1117.01
3018.18	1112.46
3020.75	1118.3
3023.33	1144.26
3025.91	1144.06
3028.48	1116.78
3031.06	1128.6
3033.64	1169.84
3036.21	1134.02
3038.78	1158.71
3041.35	1138.5
3043.92	1171.84
3046.49	1176.75
3048.11	1166
3050.69	1166
3053.27	1126
3055.85	1156
3058.43	1134
3061.01	1132
3063.58	1162
3066.16	1190
3068.73	1172
3071.31	1228
3073.88	1184
3076.45	1192
3079.02	1198
3081.59	1172
3084.16	1200
3086.73	1194
3089.29	1214
3091.86	1230
3094.43	1200
3096.99	1216
3099.55	1246
3102.12	1246
3104.68	1218
3107.24	1242
3109.8	1262
3112.36	1278
3114.92	1238
3117.48	1230
3120.03	1248
3122.59	1230
3125.14	1236
3127.7	1262
3130.25	1278
3132.8	1308
3135.35	1312
3137.9	1284
3140.45	1294
3143	1318
3145.55	1276
3148.1	1308
3150.64	1304
3153.19	1284
3155.73	1328
3158.28	1294
3160.82	1350
3163.36	1322
3165.9	1316
3168.44	1364
3170.98	1316
3173.52	1346
3176.06	1364
3178.59	1362
3181.13	1326
3183.66	1338
3186.2	1394
3188.73	1350
3191.26	1366
3193.79	1372
3196.32	1364
3198.85	1364
3201.38	1380
3203.91	1378
3206.44	1358
3208.96	1376
3211.49	1358
3214.01	1388
3216.54	1382
3219.06	1336
3221.58	1350
3224.1	1350
3226.62	1370
3229.14	1380
3231.66	1366
3234.18	1368
3236.69	1372
3239.21	1420
3241.72	1400
3244.24	1402
3246.75	1426
3249.26	1418
3251.78	1434
3254.29	1422
3256.8	1440
3259.3	1392
3261.81	1446
3264.32	1426
3266.83	1470
3269.33	1438
3271.84	1428
3274.34	1450
3276.84	1488
3279.35	1450
3281.85	1466
3284.35	1412
3286.85	1482
3289.35	1508
3291.84	1498
3294.34	1490
3296.84	1488
3299.33	1516
3301.83	1550
3304.32	1500
3306.81	1528
3309.3	1580
3311.79	1546
3314.29	1524
3316.77	1536
3319.26	1554
3321.75	1564
3324.24	1550
3326.72	1516
3329.21	1598
3331.69	1550
3334.18	1588
3336.66	1590
3339.14	1570
3341.62	1568
3344.1	1584
3346.58	1624
3349.06	1564
3351.54	1564
3354.01	1584
3356.49	1580
3358.96	1600
3361.44	1584
3363.91	1596
3366.38	1620
3368.85	1628
3371.33	1568
3373.8	1570
3376.26	1626
3378.73	1630
3381.2	1632
3383.67	1622
3386.13	1598
3388.6	1610
3391.06	1568
3393.52	1606
3395.99	1598
3398.45	1632
3400.91	1618
3403.37	1668
3405.83	1622
3408.29	1652
3410.74	1680
3413.2	1708
3415.66	1706
3418.11	1660
3420.56	1728
3423.02	1704
3425.47	1732
3427.92	1738
3430.37	1744
3432.82	1742
3435.27	1766
3437.72	1770
3440.17	1772
3442.61	1762
3445.06	1784
3447.51	1768
3449.95	1784
3452.39	1800
3454.83	1768
3457.28	1780
3459.72	1794
3462.16	1804
3464.6	1808
3467.04	1790
3469.47	1806
3471.91	1764
3474.34	1868
3476.78	1822
3479.21	1808
3481.65	1800
3484.08	1820
3486.51	1822
3488.94	1816
3491.37	1792
3493.8	1804
3496.23	1838
3498.66	1810
3501.09	1844
3503.51	1840
3505.94	1812
3508.36	1856
3510.79	1848
3513.21	1782
3515.63	1790
3518.05	1852
3520.47	1854
3522.89	1818
3525.31	1840
3527.73	1838
3530.14	1880
3532.56	1876
3534.98	1864
3537.39	1838
3539.81	1828
3542.22	1868
3544.63	1862
3547.04	1890
3549.45	1862
3551.86	1872
3554.27	1884
3556.68	1878
3559.09	1894
3561.49	1876
3563.9	1896
3566.3	1900
3568.71	1926
3571.11	1902
3573.51	1904
3575.92	1918
3578.32	1936
3580.72	1972
3583.12	1914
3585.51	1994
3587.91	2002
3590.31	1996
3592.71	1946
3595.1	1958
3597.49	1992
3599.89	2006
3602.28	2042
3604.67	2006
3607.06	2004
3609.45	1938
3611.84	2062
3614.23	2060
3616.62	2040
3619.01	2012
3621.39	2110
3623.78	1998
3626.17	2080
3628.55	2036
3630.93	2070
3633.31	2058
3635.7	2070
3638.08	2116
3640.46	2044
3642.84	2080
3645.22	2080
3647.59	2066
3649.97	2146
3652.35	2092
3654.72	2098
3657.1	2040
3659.47	2050
3661.84	2118
3664.21	2082
3666.59	2070
3668.96	2048
3671.33	2108
3673.69	2082
3676.06	2086
3678.43	2106
3680.8	2092
3683.16	2108
3685.53	2092
3687.89	2098
3690.25	2104
3692.62	2100
3694.98	2124
3697.34	2080
3699.7	2090
3702.06	2136
3704.42	2066
3706.78	2120
3709.13	2112
3711.49	2116
3713.85	2110
3716.2	2132
3718.56	2084
3720.91	2126
3723.26	2194
3725.61	2144
3727.96	2190
3730.31	2166
3732.66	2148
3735.01	2230
3737.36	2242
3739.7	2230
3742.05	2218
3744.4	2246
3746.74	2232
3749.09	2242
3751.43	2238
3753.77	2222
3756.11	2272
3758.45	2300
3760.79	2280
3763.13	2312
3765.47	2278
3767.81	2280
3770.14	2276
3772.48	2302
3774.82	2308
3777.15	2326
3779.48	2316
3781.82	2314
3784.15	2330
3786.48	2334
3788.81	2310
3791.14	2286
3793.47	2332
3795.8	2346
3798.13	2292
3800.45	2312
3802.78	2348
3805.1	2352
3807.43	2320
3809.75	2308
3812.07	2312
3814.4	2316
3816.72	2288
3819.04	2270
3821.36	2312
3823.68	2318
3826	2304
3828.31	2242
3830.63	2324
3832.95	2310
3835.26	2320
3837.58	2294
3839.89	2302
3842.2	2314
3844.51	2342
3846.83	2322
3849.14	2322
3851.45	2366
3853.76	2308
3856.06	2314
3858.37	2356
3860.68	2346
3862.98	2362
3865.29	2364
3867.59	2358
3869.9	2382
3872.2	2328
3874.5	2394
3876.8	2442
3879.1	2414
3881.4	2406
3883.7	2428
3886	2380
3888.3	2410
3890.6	2418
3892.89	2408
3895.19	2470
3897.48	2478
3899.78	2482
3902.07	2404
3904.36	2432
3906.65	2480
3908.94	2494
3911.23	2454
3913.52	2490
3915.81	2482
3918.1	2480
3920.39	2460
3922.67	2472
3924.96	2518
3927.24	2542
3929.53	2518
3931.81	2532
3934.09	2552
3936.38	2544
3938.66	2580
3940.94	2532
3943.22	2558
3945.5	2536
3947.77	2580
3950.05	2488
3952.33	2524
3954.6	2544
3956.88	2526
3959.15	2538
3961.43	2502
3963.7	2528
3965.97	2504
3968.24	2534
3970.51	2548
3972.78	2524
3975.05	2590
3977.32	2524
3979.59	2564
3981.85	2504
3984.12	2544
3986.39	2524
3988.65	2556
3990.91	2606
3993.18	2568
3995.44	2572
3997.7	2552
3999.96	2566