File: DataDrivenSE/datosramana/CN-Sastre_05.txt
#Acq. time (s)=	20
#Accumulations=	2
#Range (cm-¹)=	50...4000
#Windows=	3
#Autofocus=	Off
#AutoExposure=	Off
#Spike filter=	Multiple accum.
#Delay time (s)=	0
#Binning=	1
#Readout mode=	Signal
#DeNoise=	Off
#ICS correction=	Off
#Dark correction=	Off
#Inst. Process=	Off
#Instrument=	LabRAM HR Evol
#Detector=	Syncerity OE
#Objective=	x100_VIS
#Grating=	600 (500nm)
#ND Filter=	100%
#Laser=	532nm_Edge
#Hole=	100.021
#Range=	Visible
#Project=	Omar
#Sample=
#Site=	21-09-22
#Title=	 CN-Sastre
#Remark=
#Date=	21.09.2022 12:44
#Acquired=	21.09.2022 12:44:05
51.0918	34
54.7807	36
58.4681	52
62.154	114
65.8385	178
69.5216	282
73.2032	472
76.8834	642
80.5621	812
84.2393	970
87.9152	1052
91.5874	1116
95.2603	1058
98.9318	1066
102.602	1066
106.27	1150
109.936	1076
113.601	1074
117.266	1078
120.926	1058
124.588	1042
128.246	1032
131.904	1026
135.561	1020
139.215	1030
142.869	1002
146.52	1036
150.171	1020
153.819	1010
157.465	970
161.112	988
164.756	994
168.398	968
172.041	966
175.68	924
179.318	952
182.955	950
186.592	978
190.225	938
193.857	974
197.488	940
201.118	938
204.746	924
208.372	954
211.997	890
215.621	916
219.243	934
222.864	864
226.483	890
230.101	874
233.718	874
237.331	884
240.945	920
244.557	842
248.168	912
251.776	884
255.384	856
258.991	876
262.594	888
266.198	846
269.799	870
273.4	884
277	872
280.596	858
284.193	892
287.786	866
291.378	868
294.971	900
298.561	884
302.148	890
305.737	864
309.322	918
312.906	884
316.49	900
320.071	902
323.651	902
327.229	866
330.806	862
334.381	890
337.955	844
341.528	882
345.099	862
348.669	890
352.238	844
355.805	856
359.371	862
362.935	868
366.498	866
370.06	896
373.62	868
377.177	900
380.734	888
384.29	916
387.845	884
391.396	934
394.948	884
398.499	872
402.046	878
405.594	852
409.138	874
412.683	884
416.225	852
419.768	900
423.307	852
426.844	896
430.382	866
433.917	880
437.451	874
440.985	886
444.516	898
448.045	904
451.574	848
455.102	900
458.628	930
462.152	884
465.674	884
469.196	958
472.716	900
476.234	906
479.752	888
483.268	872
486.782	892
490.295	872
493.807	860
497.316	864
500.825	880
504.333	842
507.839	876
511.344	862
514.846	892
518.349	880
521.85	892
525.347	886
528.846	898
532.341	922
535.837	948
539.329	1024
542.822	1038
546.312	1056
549.802	1104
553.289	1104
556.775	1138
560.261	1126
563.744	1136
567.226	1130
570.709	1108
574.188	1076
577.665	1050
581.142	1082
584.617	1012
588.091	1016
591.565	962
595.036	982
598.506	958
601.974	928
605.442	960
608.905	912
612.37	906
615.833	866
619.295	908
622.755	848
626.215	864
629.67	836
633.127	842
636.582	836
640.036	842
643.487	820
646.938	816
650.386	818
653.835	830
657.282	828
660.726	800
664.171	772
667.613	756
671.053	742
674.494	698
677.931	702
681.369	664
684.804	652
688.238	632
691.67	610
695.103	566
698.533	588
701.961	582
705.389	550
708.814	524
712.239	508
715.662	500
719.084	524
722.505	532
725.924	520
729.342	504
732.759	518
736.174	498
739.589	532
742.999	500
746.411	462
749.821	520
753.23	502
756.636	526
760.043	516
763.448	544
766.85	530
770.252	506
773.652	528
777.052	558
780.448	532
783.846	556
787.24	534
790.635	540
794.027	526
797.417	496
800.808	520
804.196	502
807.582	488
810.968	504
814.354	486
817.736	498
821.118	480
824.498	474
827.877	472
831.254	432
834.631	440
838.006	414
841.38	440
844.752	412
848.123	422
851.493	404
854.86	388
858.228	444
861.594	436
864.959	408
868.321	408
871.683	412
875.044	416
878.402	422
881.761	418
885.116	408
888.472	418
891.825	426
895.179	450
898.529	406
901.88	426
905.228	456
908.575	436
911.922	468
915.266	480
918.609	478
921.951	476
925.293	460
928.633	492
931.97	490
935.307	512
938.642	506
941.977	548
945.31	530
948.641	538
951.972	516
955.301	556
958.629	510
961.955	556
965.279	516
968.603	510
971.926	540
975.248	532
978.566	542
981.886	568
985.204	596
988.519	586
991.834	564
995.147	554
998.46	588
1001.77	562
1005.08	576
1008.39	602
1011.7	622
1015	638
1018.3	626
1021.61	630
1024.91	672
1028.21	676
1031.51	690
1034.81	714
1038.1	688
1041.4	744
1044.69	768
1047.99	800
1051.28	816
1054.57	802
1057.86	826
1061.14	862
1064.43	900
1067.72	902
1071	918
1074.28	928
1077.57	946
1080.84	974
1084.12	1036
1087.4	992
1090.68	1016
1093.95	1048
1097.22	1036
1100.5	1036
1103.77	1032
1107.04	996
1110.31	920
1113.58	928
1116.84	894
1120.1	870
1123.37	840
1126.63	784
1129.89	796
1133.15	760
1136.41	724
1139.67	726
1142.92	696
1146.18	694
1149.43	672
1152.68	662
1155.93	652
1159.18	636
1162.43	576
1165.68	564
1168.93	550
1172.17	516
1175.41	560
1178.66	556
1181.9	510
1185.14	506
1188.37	512
1191.61	514
1194.85	508
1198.08	486
1201.31	466
1204.55	430
1207.78	434
1211.01	450
1214.24	450
1217.46	426
1220.69	432
1223.91	426
1227.14	414
1230.36	406
1233.58	418
1236.8	408
1240.02	394
1243.23	386
1246.45	438
1249.67	448
1252.88	424
1256.09	406
1259.3	408
1262.51	414
1265.72	424
1268.93	416
1272.13	420
1275.34	448
1278.54	440
1281.74	452
1284.94	474
1288.15	465
1291.34	468
1294.54	502
1297.74	466
1300.93	494
1304.12	492
1307.32	516
1310.51	536
1313.7	544
1316.89	556
1320.07	592
1323.26	618
1326.45	600
1329.63	650
1332.81	686
1335.99	676
1339.17	690
1342.35	702
1345.53	752
1348.71	704
1351.88	710
1355.06	704
1358.23	662
1361.4	698
1364.57	626
1367.74	636
1370.91	594
1374.08	562
1377.24	552
1380.41	532
1383.57	524
1386.73	522
1389.89	526
1393.05	502
1396.21	482
1399.37	476
1402.52	480
1405.68	456
1408.83	446
1411.98	448
1415.13	454
1418.29	460
1421.43	448
1424.58	436
1427.73	466
1430.87	440
1434.02	426
1437.16	464
1440.3	448
1443.44	434
1446.58	408
1449.72	416
1452.85	414
1455.99	442
1459.12	422
1462.26	420
1465.39	426
1468.52	430
1471.65	452
1474.78	428
1477.9	422
1481.03	446
1484.16	446
1487.28	430
1490.4	430
1493.52	426
1496.64	456
1499.76	442
1502.88	446
1506	432
1509.11	468
1512.22	476
1515.34	484
1518.45	474
1521.56	442
1524.67	450
1527.78	492
1530.88	490
1533.99	484
1537.09	510
1540.2	504
1543.3	528
1546.4	520
1549.5	574
1552.6	598
1555.7	600
1558.79	664
1561.89	674
1564.98	696
1568.08	712
1571.17	762
1574.26	772
1577.35	786
1580.43	762
1583.52	746
1586.61	726
1589.69	706
1592.77	690
1595.86	652
1598.94	626
1602.02	620
1605.1	612
1608.18	605.777
1611.25	578.394
1614.33	554.522
1617.4	521.507
1620.47	533.816
1623.55	501.828
1626.62	489.995
1629.69	472.048
1632.75	475.041
1635.82	472.114
1638.89	465.502
1641.95	455.105
1645.02	430.377
1648.08	412.445
1651.14	434.031
1654.2	443.569
1657.26	452.472
1660.32	436.827
1663.37	439.638
1666.43	448.376
1669.48	433.382
1672.54	445.51
1675.59	435.765
1678.64	435.941
1681.69	455.057
1684.74	459.612
1687.79	446.113
1690.83	459.019
1693.88	450.307
1696.92	454.726
1699.96	471.038
1703.01	473.539
1706.05	456.656
1709.09	457.585
1712.12	466.421
1715.16	462.023
1718.2	487.154
1721.23	456.183
1724.27	474.32
1727.3	458.034
1730.33	485.735
1733.36	480.974
1736.39	497.719
1739.42	466.989
1742.44	475.837
1745.47	484.546
1748.49	489.217
1751.52	502.461
1754.54	474.626
1757.56	493.476
1759.14	484
1762.18	496
1765.21	488
1768.24	508
1771.27	470
1774.3	488
1777.32	478
1780.35	484
1783.38	496
1786.4	498
1789.42	518
1792.44	504
1795.47	494
1798.48	508
1801.5	526
1804.52	518
1807.54	500
1810.55	526
1813.57	522
1816.58	518
1819.59	476
1822.6	478
1825.61	512
1828.62	496
1831.63	494
1834.63	488
1837.64	504
1840.64	494
1843.64	534
1846.64	500
1849.64	488
1852.64	502
1855.64	492
1858.64	510
1861.64	518
1864.63	476
1867.63	480
1870.62	520
1873.61	522
1876.6	506
1879.59	490
1882.58	470
1885.56	480
1888.55	472
1891.54	494
1894.52	490
1897.5	516
1900.48	508
1903.46	504
1906.44	516
1909.42	494
1912.4	514
1915.38	504
1918.35	534
1921.32	514
1924.3	502
1927.27	520
1930.24	510
1933.21	506
1936.18	484
1939.15	528
1942.11	500
1945.08	504
1948.04	510
1951	514
1953.97	520
1956.93	500
1959.89	502
1962.85	496
1965.8	488
1968.76	522
1971.71	512
1974.67	508
1977.62	488
1980.57	516
1983.53	480
1986.48	502
1989.42	478
1992.37	498
1995.32	494
1998.26	510
2001.21	506
2004.15	488
2007.09	490
2010.03	498
2012.98	508
2015.92	512
2018.85	482
2021.79	502
2024.73	512
2027.66	504
2030.59	498
2033.53	510
2036.46	506
2039.39	508
2042.32	526
2045.25	506
2048.17	532
2051.1	524
2054.02	514
2056.95	502
2059.87	504
2062.79	496
2065.71	514
2068.63	504
2071.55	504
2074.47	512
2077.39	514
2080.3	520
2083.22	506
2086.13	506
2089.04	514
2091.95	500
2094.86	484
2097.77	498
2100.68	522
2103.59	482
2106.49	498
2109.4	504
2112.3	520
2115.21	488
2118.11	506
2121.01	510
2123.91	514
2126.8	518
2129.7	494
2132.6	512
2135.49	498
2138.39	508
2141.28	516
2144.17	504
2147.06	486
2149.95	510
2152.84	500
2155.73	508
2158.62	492
2161.5	502
2164.39	496
2167.27	510
2170.15	512
2173.04	500
2175.92	480
2178.79	498
2181.67	504
2184.55	520
2187.43	524
2190.3	504
2193.18	518
2196.05	486
2198.92	500
2201.79	496
2204.66	498
2207.53	506
2210.4	500
2213.27	494
2216.13	504
2219	506
2221.86	472
2224.72	478
2227.59	482
2230.45	470
2233.31	486
2236.16	498
2239.02	484
2241.88	476
2244.73	472
2247.59	476
2250.44	480
2253.29	478
2256.15	494
2259	476
2261.84	486
2264.69	484
2267.54	496
2270.39	480
2273.23	480
2276.07	504
2278.92	488
2281.76	476
2284.6	496
2287.44	506
2290.28	520
2293.12	506
2295.95	466
2298.79	516
2301.62	506
2304.46	518
2307.29	518
2310.12	514
2312.95	504
2315.78	510
2318.61	502
2321.44	500
2324.27	508
2327.09	570
2329.92	562
2332.74	492
2335.56	484
2338.38	542
2341.2	536
2344.02	524
2346.84	532
2349.66	550
2352.48	548
2355.29	546
2358.11	560
2360.92	530
2363.73	572
2366.54	566
2369.35	576
2372.16	586
2374.97	576
2377.78	564
2380.58	582
2383.39	568
2386.19	558
2389	588
2391.8	564
2394.6	586
2397.4	570
2400.2	572
2403	574
2405.79	600
2408.59	560
2411.38	588
2414.18	580
2416.97	588
2419.76	574
2422.55	606
2425.34	574
2428.13	606
2430.92	608
2433.71	606
2436.49	578
2439.28	596
2442.06	604
2444.85	584
2447.63	614
2450.41	598
2453.19	582
2455.97	598
2458.75	564
2461.52	604
2464.3	598
2467.07	608
2469.85	586
2472.62	598
2475.39	596
2478.16	596
2480.94	564
2483.7	588
2486.47	614
2489.24	568
2492	604
2494.77	608
2497.53	596
2500.3	594
2503.06	590
2505.82	584
2508.58	606
2511.34	582
2514.1	602
2516.85	584
2519.61	584
2522.37	608
2525.12	586
2527.87	588
2530.63	590
2533.38	584
2536.13	594
2538.88	616
2541.62	602
2544.37	606
2547.12	616
2549.86	572
2552.61	612
2555.35	590
2558.09	562
2560.84	590
2563.57	624
2566.32	572
2569.05	600
2571.79	568
2574.53	598
2577.26	570
2580	592
2582.73	568
2585.46	628
2588.19	596
2590.93	588
2593.66	570
2596.39	564
2599.11	590
2601.84	588
2604.56	598
2607.29	572
2610.01	636
2612.74	590
2615.46	596
2618.18	612
2620.9	588
2623.62	602
2626.34	582
2629.05	596
2631.77	632
2634.48	626
2637.2	646
2639.91	634
2642.62	626
2645.33	620
2648.05	620
2650.75	632
2653.46	622
2656.17	638
2658.88	638
2661.58	648
2664.29	634
2666.99	658
2669.69	646
2672.39	638
2675.09	642
2677.79	670
2680.49	666
2683.19	670
2685.89	646
2688.58	664
2691.28	660
2693.97	706
2696.67	670
2699.36	668
2702.05	686
2704.74	670
2707.43	668
2710.12	660
2712.8	692
2715.49	672
2718.17	694
2720.86	692
2723.54	656
2726.22	646
2728.91	642
2731.59	692
2734.27	656
2736.95	660
2739.62	654
2742.3	614
2744.98	646
2747.65	654
2750.33	678
2753	664
2755.67	654
2758.34	674
2761.01	638
2763.68	652
2766.35	658
2769.02	646
2771.68	630
2774.35	662
2777.01	650
2779.68	624
2782.34	622
2785	668
2787.66	620
2790.32	680
2792.98	678
2795.64	648
2798.3	630
2800.95	638
2803.61	650
2806.26	682
2808.91	664
2811.57	662
2814.22	662
2816.87	644
2819.52	640
2822.17	684
2824.81	660
2827.46	676
2830.11	662
2832.75	672
2835.39	678
2838.04	700
2840.68	692
2843.32	674
2845.96	670
2848.6	670
2851.24	682
2853.88	680
2856.51	668
2859.15	674
2861.78	692
2864.42	720
2867.05	680
2869.68	678
2872.31	698
2874.94	684
2877.57	684
2880.2	724
2882.82	690
2885.45	700
2888.08	702
2890.7	698
2893.33	698
2895.95	674
2898.57	698
2901.19	708
2903.81	708
2906.43	696
2909.05	716
2911.66	718
2914.28	706
2916.89	700
2919.51	711.978
2922.12	736.361
2924.73	748.02
2927.35	725.995
2929.96	731.851
2932.57	702.395
2935.17	735.357
2937.78	681.507
2940.39	754.99
2943	733.244
2945.6	739.978
2948.2	725.069
2950.81	734.704
2953.41	718.324
2956.01	729.758
2958.61	745.567
2961.21	722.035
2963.81	732.89
2966.41	747.136
2969.01	758.052
2971.6	731.965
2974.2	743.124
2976.79	720.54
2979.39	747.578
2981.98	754.74
2984.57	745.023
2987.16	773.455
2989.75	766.182
2992.34	746.773
2994.93	748.255
2997.51	743.03
3000.1	745.415
3002.68	760.855
3005.27	767.98
3007.85	750.237
3010.43	757.257
3013.01	770.564
3015.59	755.222
3018.18	766.752
3020.75	765.746
3023.33	763.196
3025.91	758
3028.48	761.766
3031.06	773.594
3033.64	779.166
3036.21	793.935
3038.78	754.336
3041.35	780.455
3043.92	780.611
3046.49	779.478
3048.11	766
3050.69	782
3053.27	754
3055.85	786
3058.43	796
3061.01	800
3063.58	796
3066.16	786
3068.73	784
3071.31	788
3073.88	784
3076.45	814
3079.02	794
3081.59	830
3084.16	800
3086.73	814
3089.29	826
3091.86	830
3094.43	828
3096.99	804
3099.55	840
3102.12	792
3104.68	830
3107.24	816
3109.8	816
3112.36	826
3114.92	856
3117.48	840
3120.03	826
3122.59	826
3125.14	832
3127.7	818
3130.25	828
3132.8	866
3135.35	850
3137.9	842
3140.45	828
3143	894
3145.55	860
3148.1	876
3150.64	864
3153.19	864
3155.73	864
3158.28	864
3160.82	878
3163.36	890
3165.9	908
3168.44	882
3170.98	874
3173.52	890
3176.06	892
3178.59	886
3181.13	866
3183.66	896
3186.2	918
3188.73	898
3191.26	888
3193.79	872
3196.32	914
3198.85	898
3201.38	912
3203.91	918
3206.44	918
3208.96	912
3211.49	902
3214.01	918
3216.54	894
3219.06	900
3221.58	928
3224.1	920
3226.62	896
3229.14	914
3231.66	942
3234.18	914
3236.69	936
3239.21	926
3241.72	924
3244.24	934
3246.75	922
3249.26	928
3251.78	936
3254.29	944
3256.8	926
3259.3	906
3261.81	936
3264.32	962
3266.83	948
3269.33	950
3271.84	974
3274.34	952
3276.84	984
3279.35	962
3281.85	996
3284.35	928
3286.85	972
3289.35	978
3291.84	992
3294.34	996
3296.84	990
3299.33	970
3301.83	1006
3304.32	1022
3306.81	996
3309.3	968
3311.79	982
3314.29	990
3316.77	1016
3319.26	1010
3321.75	1046
3324.24	998
3326.72	1020
3329.21	1018
3331.69	1024
3334.18	1014
3336.66	1018
3339.14	1006
3341.62	1050
3344.1	1062
3346.58	1046
3349.06	1032
3351.54	1006
3354.01	1052
3356.49	1054
3358.96	1054
3361.44	1016
3363.91	1068
3366.38	1060
3368.85	1050
3371.33	1064
3373.8	1038
3376.26	1068
3378.73	1090
3381.2	1066
3383.67	1020
3386.13	1076
3388.6	1074
3391.06	1070
3393.52	1064
3395.99	1070
3398.45	1046
3400.91	1076
3403.37	1018
3405.83	1084
3408.29	1056
3410.74	1100
3413.2	1074
3415.66	1138
3418.11	1080
3420.56	1100
3423.02	1110
3425.47	1116
3427.92	1120
3430.37	1124
3432.82	1106
3435.27	1128
3437.72	1116
3440.17	1134
3442.61	1152
3445.06	1140
3447.51	1154
3449.95	1140
3452.39	1132
3454.83	1148
3457.28	1180
3459.72	1150
3462.16	1148
3464.6	1144
3467.04	1180
3469.47	1152
3471.91	1188
3474.34	1156
3476.78	1166
3479.21	1176
3481.65	1190
3484.08	1188
3486.51	1176
3488.94	1156
3491.37	1188
3493.8	1174
3496.23	1200
3498.66	1170
3501.09	1216
3503.51	1180
3505.94	1152
3508.36	1158
3510.79	1204
3513.21	1168
3515.63	1200
3518.05	1158
3520.47	1172
3522.89	1184
3525.31	1194
3527.73	1194
3530.14	1156
3532.56	1200
3534.98	1182
3537.39	1174
3539.81	1182
3542.22	1200
3544.63	1170
3547.04	1188
3549.45	1230
3551.86	1192
3554.27	1208
3556.68	1224
3559.09	1226
3561.49	1198
3563.9	1246
3566.3	1216
3568.71	1214
3571.11	1260
3573.51	1252
3575.92	1284
3578.32	1234
3580.72	1218
3583.12	1224
3585.51	1244
3587.91	1244
3590.31	1278
3592.71	1254
3595.1	1302
3597.49	1294
3599.89	1280
3602.28	1296
3604.67	1296
3607.06	1328
3609.45	1330
3611.84	1316
3614.23	1332
3616.62	1324
3619.01	1284
3621.39	1342
3623.78	1348
3626.17	1324
3628.55	1346
3630.93	1278
3633.31	1300
3635.7	1356
3638.08	1294
3640.46	1334
3642.84	1278
3645.22	1364
3647.59	1322
3649.97	1338
3652.35	1338
3654.72	1306
3657.1	1336
3659.47	1314
3661.84	1332
3664.21	1332
3666.59	1318
3668.96	1328
3671.33	1330
3673.69	1350
3676.06	1292
3678.43	1334
3680.8	1362
3683.16	1318
3685.53	1342
3687.89	1350
3690.25	1348
3692.62	1306
3694.98	1306
3697.34	1364
3699.7	1362
3702.06	1372
3704.42	1374
3706.78	1334
3709.13	1384
3711.49	1336
3713.85	1334
3716.2	1340
3718.56	1364
3720.91	1386
3723.26	1392
3725.61	1402
3727.96	1420
3730.31	1410
3732.66	1354
3735.01	1400
3737.36	1424
3739.7	1396
3742.05	1406
3744.4	1450
3746.74	1430
3749.09	1426
3751.43	1432
3753.77	1452
3756.11	1454
3758.45	1470
3760.79	1502
3763.13	1462
3765.47	1446
3767.81	1416
3770.14	1474
3772.48	1440
3774.82	1488
3777.15	1492
3779.48	1416
3781.82	1466
3784.15	1478
3786.48	1468
3788.81	1504
3791.14	1462
3793.47	1490
3795.8	1498
3798.13	1498
3800.45	1498
3802.78	1492
3805.1	1472
3807.43	1454
3809.75	1420
3812.07	1472
3814.4	1462
3816.72	1454
3819.04	1410
3821.36	1476
3823.68	1462
3826	1428
3828.31	1492
3830.63	1484
3832.95	1464
3835.26	1446
3837.58	1442
3839.89	1462
3842.2	1500
3844.51	1476
3846.83	1480
3849.14	1496
3851.45	1490
3853.76	1528
3856.06	1488
3858.37	1518
3860.68	1492
3862.98	1504
3865.29	1532
3867.59	1524
3869.9	1500
3872.2	1538
3874.5	1542
3876.8	1550
3879.1	1552
3881.4	1536
3883.7	1556
3886	1542
3888.3	1542
3890.6	1560
3892.89	1528
3895.19	1508
3897.48	1574
3899.78	1568
3902.07	1582
3904.36	1558
3906.65	1598
3908.94	1582
3911.23	1608
3913.52	1560
3915.81	1588
3918.1	1572
3920.39	1628
3922.67	1620
3924.96	1624
3927.24	1628
3929.53	1630
3931.81	1602
3934.09	1612
3936.38	1586
3938.66	1616
3940.94	1614
3943.22	1564
3945.5	1588
3947.77	1648
3950.05	1642
3952.33	1628
3954.6	1652
3956.88	1572
3959.15	1632
3961.43	1622
3963.7	1634
3965.97	1646
3968.24	1618
3970.51	1628
3972.78	1622
3975.05	1642
3977.32	1628
3979.59	1630
3981.85	1620
3984.12	1618
3986.39	1626
3988.65	1670
3990.91	1620
3993.18	1650
3995.44	1618
3997.7	1654
3999.96	1630